package kieranvs.avatar.generation;

import java.util.Random;

import kieranvs.avatar.mod_Avatar;
import kieranvs.avatar.bending.ElementManager;
import kieranvs.avatar.entity.EntityEarthMan;
import kieranvs.avatar.entity.EntityEarthWoman;
import kieranvs.avatar.util.GenerationUtils;
import cpw.mods.fml.common.IWorldGenerator;
import net.minecraft.block.Block;
import net.minecraft.entity.passive.EntityPig;
import net.minecraft.init.Blocks;
import net.minecraft.item.ItemStack;
import net.minecraft.tileentity.TileEntity;
import net.minecraft.tileentity.TileEntityChest;
import net.minecraft.world.World;
import net.minecraft.world.biome.BiomeGenBase;
import net.minecraft.world.chunk.IChunkProvider;
import net.minecraft.world.gen.feature.WorldGenerator;

public class WorldGenEarthKingdomHouseTwo implements IWorldGenerator {
	
	private static BiomeGenBase[] biomes = {BiomeGenBase.plains, BiomeGenBase.birchForest, BiomeGenBase.forest};
	
	@Override
	public void generate(Random random, int chunkX, int chunkZ, World world, IChunkProvider chunkGenerator, IChunkProvider chunkProvider) {
		int result[] = GenerationUtils.shouldSpawnHere(random, chunkX, chunkZ, world, 22, 3, 40, biomes);
		if(result[0] == 0){
			this.generate(world, result[1], result[2], result[3]);
			this.generateLoot(world, result[1], result[2], result[3], random);
			this.generateEntities(world, result[1], result[2], result[3], random);
		}
	}
	
	public void generateEntities(World world, int i, int j, int k, Random random) {
		int numM = random.nextInt(2) + 1;
		int numW = random.nextInt(2) + 1;
		
		for (int x = 0; x < numM; x++) {
			EntityEarthMan earthMan = new EntityEarthMan(world, i + 11, j + 2, k + 11, 11);
			earthMan.setPositionAndRotation(i + 11, j + 2, k + 11, 1.0F, 1.0F);
			world.spawnEntityInWorld(earthMan);
		}

		for (int x = 0; x < numW; x++) {
			EntityEarthWoman earthWoman = new EntityEarthWoman(world, i + 11, j + 2, k + 11, 11);
			earthWoman.setPositionAndRotation(i + 11, j + 2, k + 11, 1.0F, 1.0F);
			world.spawnEntityInWorld(earthWoman);
		}

	}	


	
	public void generateLoot(World world, int i, int j, int k, Random random){
		for(int x = i; x < i + 22; x++){
			for (int z = k; z < k + 22; z++) {
				for (int y = j; y < j + 14; y++) {
					TileEntity e = world.getTileEntity(x, y, z);
					if(e != null && e instanceof TileEntityChest){
						GenerationUtils.generateScrolls(random, (TileEntityChest) e, ElementManager.EARTH, 1);
						GenerationUtils.generateRandomMoney(random, (TileEntityChest) e, ElementManager.EARTH, 2);
						int ran = random.nextInt(10);
						for(int r = 0; r < random.nextInt(3); r++){
							switch (ran){
							case 1:
								((TileEntityChest) e).setInventorySlotContents(random.nextInt(27), new ItemStack(mod_Avatar.RiceGrainItem, random.nextInt(32), 0));	
								break;
							case 2:
								((TileEntityChest) e).setInventorySlotContents(random.nextInt(27), new ItemStack(mod_Avatar.RiceGrainItem, random.nextInt(32), 0));	
								break;
							case 3:
								((TileEntityChest) e).setInventorySlotContents(random.nextInt(27), new ItemStack(mod_Avatar.RiceBowlItem, 1, 0));	
								break;
							case 4:
								((TileEntityChest) e).setInventorySlotContents(random.nextInt(27), new ItemStack(mod_Avatar.CabbageItem, random.nextInt(16), 0));	
								break;
							}	
						}

					}
				}
			}
		}
	}

	public boolean generate(World world, int i, int j, int k) {
		
		world.setBlock(i + 6, j + 2, k + 10, Blocks.bed, 9, 0x02);
		world.setBlock(i + 7, j + 2, k + 10, Blocks.bed, 1, 0x02);
		world.setBlock(i + 14, j + 2, k + 6, Blocks.bed, 3, 0x02);
		world.setBlock(i + 15, j + 2, k + 6, Blocks.bed, 11, 0x02);
		
		world.setBlock(i + 0, j + 0, k + 0, Blocks.grass);
		world.setBlock(i + 0, j + 0, k + 1, Blocks.grass);
		world.setBlock(i + 0, j + 0, k + 2, Blocks.grass);
		world.setBlock(i + 0, j + 0, k + 3, Blocks.grass);
		world.setBlock(i + 0, j + 0, k + 4, Blocks.grass);
		world.setBlock(i + 0, j + 0, k + 5, Blocks.grass);
		world.setBlock(i + 0, j + 0, k + 6, Blocks.grass);
		world.setBlock(i + 0, j + 0, k + 7, Blocks.grass);
		world.setBlock(i + 0, j + 0, k + 8, Blocks.grass);
		world.setBlock(i + 0, j + 0, k + 9, Blocks.grass);
		world.setBlock(i + 0, j + 0, k + 10, Blocks.grass);
		world.setBlock(i + 0, j + 0, k + 11, Blocks.grass);
		world.setBlock(i + 0, j + 0, k + 12, Blocks.grass);
		world.setBlock(i + 0, j + 0, k + 13, Blocks.grass);
		world.setBlock(i + 0, j + 0, k + 14, Blocks.grass);
		world.setBlock(i + 0, j + 0, k + 15, Blocks.grass);
		world.setBlock(i + 0, j + 0, k + 16, Blocks.grass);
		world.setBlock(i + 0, j + 0, k + 17, Blocks.grass);
		world.setBlock(i + 0, j + 0, k + 18, Blocks.grass);
		world.setBlock(i + 0, j + 1, k + 0, Blocks.cobblestone_wall);
		world.setBlock(i + 0, j + 1, k + 1, Blocks.cobblestone_wall);
		world.setBlock(i + 0, j + 1, k + 2, Blocks.cobblestone_wall);
		world.setBlock(i + 0, j + 1, k + 3, Blocks.cobblestone_wall);
		world.setBlock(i + 0, j + 1, k + 4, Blocks.cobblestone_wall);
		world.setBlock(i + 0, j + 1, k + 5, Blocks.cobblestone_wall);
		world.setBlock(i + 0, j + 1, k + 6, Blocks.cobblestone_wall);
		world.setBlock(i + 0, j + 1, k + 7, Blocks.cobblestone_wall);
		world.setBlock(i + 0, j + 1, k + 8, Blocks.cobblestone_wall);
		world.setBlock(i + 0, j + 1, k + 9, Blocks.cobblestone_wall);
		world.setBlock(i + 0, j + 1, k + 10, Blocks.cobblestone_wall);
		world.setBlock(i + 0, j + 1, k + 11, Blocks.cobblestone_wall);
		world.setBlock(i + 0, j + 1, k + 12, Blocks.cobblestone_wall);
		world.setBlock(i + 0, j + 1, k + 13, Blocks.cobblestone_wall);
		world.setBlock(i + 0, j + 1, k + 14, Blocks.cobblestone_wall);
		world.setBlock(i + 0, j + 1, k + 15, Blocks.cobblestone_wall);
		world.setBlock(i + 0, j + 1, k + 16, Blocks.cobblestone_wall);
		world.setBlock(i + 0, j + 1, k + 17, Blocks.cobblestone_wall);
		world.setBlock(i + 0, j + 1, k + 18, Blocks.cobblestone_wall);
		world.setBlock(i + 0, j + 2, k + 0, Blocks.cobblestone_wall);
		world.setBlock(i + 0, j + 2, k + 1, Blocks.fence);
		world.setBlock(i + 0, j + 2, k + 2, Blocks.fence);
		world.setBlock(i + 0, j + 2, k + 3, Blocks.fence);
		world.setBlock(i + 0, j + 2, k + 4, Blocks.fence);
		world.setBlock(i + 0, j + 2, k + 5, Blocks.fence);
		world.setBlock(i + 0, j + 2, k + 6, Blocks.fence);
		world.setBlock(i + 0, j + 2, k + 7, Blocks.fence);
		world.setBlock(i + 0, j + 2, k + 8, Blocks.fence);
		world.setBlock(i + 0, j + 2, k + 9, Blocks.fence);
		world.setBlock(i + 0, j + 2, k + 10, Blocks.fence);
		world.setBlock(i + 0, j + 2, k + 11, Blocks.fence);
		world.setBlock(i + 0, j + 2, k + 12, Blocks.fence);
		world.setBlock(i + 0, j + 2, k + 13, Blocks.fence);
		world.setBlock(i + 0, j + 2, k + 14, Blocks.fence);
		world.setBlock(i + 0, j + 2, k + 15, Blocks.fence);
		world.setBlock(i + 0, j + 2, k + 16, Blocks.fence);
		world.setBlock(i + 0, j + 2, k + 17, Blocks.fence);
		world.setBlock(i + 0, j + 2, k + 18, Blocks.cobblestone_wall);
		world.setBlock(i + 0, j + 3, k + 0, Blocks.cobblestone_wall);
		world.setBlock(i + 0, j + 3, k + 1, Blocks.fence);
		world.setBlock(i + 0, j + 3, k + 17, Blocks.fence);
		world.setBlock(i + 0, j + 3, k + 18, Blocks.cobblestone_wall);
		world.setBlock(i + 0, j + 8, k + 1, Blocks.leaves, 1, 0x02);
		world.setBlock(i + 0, j + 8, k + 2, Blocks.leaves, 1, 0x02);
		world.setBlock(i + 0, j + 8, k + 3, Blocks.leaves, 1, 0x02);
		world.setBlock(i + 0, j + 10, k + 1, Blocks.leaves, 1, 0x02);
		world.setBlock(i + 0, j + 10, k + 2, Blocks.leaves, 1, 0x02);
		world.setBlock(i + 0, j + 10, k + 3, Blocks.leaves, 1, 0x02);
		world.setBlock(i + 1, j + 0, k + 0, Blocks.grass);
		world.setBlock(i + 1, j + 0, k + 1, Blocks.grass);
		world.setBlock(i + 1, j + 0, k + 2, Blocks.grass);
		world.setBlock(i + 1, j + 0, k + 3, Blocks.grass);
		world.setBlock(i + 1, j + 0, k + 4, Blocks.grass);
		world.setBlock(i + 1, j + 0, k + 5, Blocks.grass);
		world.setBlock(i + 1, j + 0, k + 6, Blocks.grass);
		world.setBlock(i + 1, j + 0, k + 7, Blocks.grass);
		world.setBlock(i + 1, j + 0, k + 8, Blocks.grass);
		world.setBlock(i + 1, j + 0, k + 9, Blocks.grass);
		world.setBlock(i + 1, j + 0, k + 10, Blocks.grass);
		world.setBlock(i + 1, j + 0, k + 11, Blocks.grass);
		world.setBlock(i + 1, j + 0, k + 12, Blocks.grass);
		world.setBlock(i + 1, j + 0, k + 13, Blocks.grass);
		world.setBlock(i + 1, j + 0, k + 14, Blocks.grass);
		world.setBlock(i + 1, j + 0, k + 15, Blocks.grass);
		world.setBlock(i + 1, j + 0, k + 16, Blocks.grass);
		world.setBlock(i + 1, j + 0, k + 17, Blocks.grass);
		world.setBlock(i + 1, j + 0, k + 18, Blocks.grass);
		world.setBlock(i + 1, j + 1, k + 0, Blocks.cobblestone_wall);
		world.setBlock(i + 1, j + 1, k + 18, Blocks.cobblestone_wall);
		world.setBlock(i + 1, j + 2, k + 0, Blocks.fence);
		world.setBlock(i + 1, j + 2, k + 18, Blocks.fence);
		world.setBlock(i + 1, j + 3, k + 0, Blocks.fence);
		world.setBlock(i + 1, j + 3, k + 18, Blocks.fence);
		world.setBlock(i + 1, j + 7, k + 2, Blocks.leaves, 1, 0x02);
		world.setBlock(i + 1, j + 8, k + 0, Blocks.leaves, 1, 0x02);
		world.setBlock(i + 1, j + 8, k + 1, Blocks.leaves, 1, 0x02);
		world.setBlock(i + 1, j + 8, k + 2, Blocks.leaves, 1, 0x02);
		world.setBlock(i + 1, j + 8, k + 3, Blocks.leaves, 1, 0x02);
		world.setBlock(i + 1, j + 8, k + 4, Blocks.leaves, 1, 0x02);
		world.setBlock(i + 1, j + 9, k + 2, Blocks.leaves, 1, 0x02);
		world.setBlock(i + 1, j + 10, k + 0, Blocks.leaves, 1, 0x02);
		world.setBlock(i + 1, j + 10, k + 1, Blocks.leaves, 1, 0x02);
		world.setBlock(i + 1, j + 10, k + 2, Blocks.leaves, 1, 0x02);
		world.setBlock(i + 1, j + 10, k + 3, Blocks.leaves, 1, 0x02);
		world.setBlock(i + 1, j + 10, k + 4, Blocks.leaves, 1, 0x02);
		world.setBlock(i + 1, j + 11, k + 2, Blocks.leaves, 1, 0x02);
		world.setBlock(i + 1, j + 13, k + 2, Blocks.leaves, 1, 0x02);
		world.setBlock(i + 2, j + 0, k + 0, Blocks.grass);
		world.setBlock(i + 2, j + 0, k + 1, Blocks.grass);
		world.setBlock(i + 2, j + 0, k + 2, Blocks.dirt);
		world.setBlock(i + 2, j + 0, k + 3, Blocks.grass);
		world.setBlock(i + 2, j + 0, k + 4, Blocks.grass);
		world.setBlock(i + 2, j + 0, k + 5, Blocks.grass);
		world.setBlock(i + 2, j + 0, k + 6, Blocks.grass);
		world.setBlock(i + 2, j + 0, k + 7, Blocks.grass);
		world.setBlock(i + 2, j + 0, k + 8, Blocks.grass);
		world.setBlock(i + 2, j + 0, k + 9, Blocks.grass);
		world.setBlock(i + 2, j + 0, k + 10, Blocks.grass);
		world.setBlock(i + 2, j + 0, k + 11, Blocks.grass);
		world.setBlock(i + 2, j + 0, k + 12, Blocks.grass);
		world.setBlock(i + 2, j + 0, k + 13, Blocks.grass);
		world.setBlock(i + 2, j + 0, k + 14, Blocks.farmland, 7, 0x02);
		world.setBlock(i + 2, j + 0, k + 15, Blocks.farmland, 7, 0x02);
		world.setBlock(i + 2, j + 0, k + 16, Blocks.farmland, 7, 0x02);
		world.setBlock(i + 2, j + 0, k + 17, Blocks.grass);
		world.setBlock(i + 2, j + 0, k + 18, Blocks.grass);
		world.setBlock(i + 2, j + 1, k + 0, Blocks.cobblestone_wall);
		world.setBlock(i + 2, j + 1, k + 2, Blocks.log, 1, 0x02);
		world.setBlock(i + 2, j + 1, k + 18, Blocks.cobblestone_wall);
		world.setBlock(i + 2, j + 2, k + 0, Blocks.fence);
		world.setBlock(i + 2, j + 2, k + 2, Blocks.log, 1, 0x02);
		world.setBlock(i + 2, j + 2, k + 18, Blocks.fence);
		world.setBlock(i + 2, j + 3, k + 2, Blocks.log, 1, 0x02);
		world.setBlock(i + 2, j + 4, k + 2, Blocks.log, 1, 0x02);
		world.setBlock(i + 2, j + 5, k + 2, Blocks.log, 1, 0x02);
		world.setBlock(i + 2, j + 6, k + 2, Blocks.log, 1, 0x02);
		world.setBlock(i + 2, j + 7, k + 1, Blocks.leaves, 1, 0x02);
		world.setBlock(i + 2, j + 7, k + 2, Blocks.log, 1, 0x02);
		world.setBlock(i + 2, j + 7, k + 3, Blocks.leaves, 1, 0x02);
		world.setBlock(i + 2, j + 8, k + 0, Blocks.leaves, 1, 0x02);
		world.setBlock(i + 2, j + 8, k + 1, Blocks.leaves, 1, 0x02);
		world.setBlock(i + 2, j + 8, k + 2, Blocks.log, 1, 0x02);
		world.setBlock(i + 2, j + 8, k + 3, Blocks.leaves, 1, 0x02);
		world.setBlock(i + 2, j + 8, k + 4, Blocks.leaves, 1, 0x02);
		world.setBlock(i + 2, j + 9, k + 1, Blocks.leaves, 1, 0x02);
		world.setBlock(i + 2, j + 9, k + 2, Blocks.log, 1, 0x02);
		world.setBlock(i + 2, j + 9, k + 3, Blocks.leaves, 1, 0x02);
		world.setBlock(i + 2, j + 10, k + 0, Blocks.leaves, 1, 0x02);
		world.setBlock(i + 2, j + 10, k + 1, Blocks.leaves, 1, 0x02);
		world.setBlock(i + 2, j + 10, k + 2, Blocks.log, 1, 0x02);
		world.setBlock(i + 2, j + 10, k + 3, Blocks.leaves, 1, 0x02);
		world.setBlock(i + 2, j + 10, k + 4, Blocks.leaves, 1, 0x02);
		world.setBlock(i + 2, j + 11, k + 1, Blocks.leaves, 1, 0x02);
		world.setBlock(i + 2, j + 11, k + 2, Blocks.log, 1, 0x02);
		world.setBlock(i + 2, j + 11, k + 3, Blocks.leaves, 1, 0x02);
		world.setBlock(i + 2, j + 12, k + 2, Blocks.log, 1, 0x02);
		world.setBlock(i + 2, j + 13, k + 1, Blocks.leaves, 1, 0x02);
		world.setBlock(i + 2, j + 13, k + 2, Blocks.leaves, 1, 0x02);
		world.setBlock(i + 2, j + 13, k + 3, Blocks.leaves, 1, 0x02);
		world.setBlock(i + 2, j + 14, k + 2, Blocks.leaves, 1, 0x02);
		world.setBlock(i + 3, j + 0, k + 0, Blocks.grass);
		world.setBlock(i + 3, j + 0, k + 1, Blocks.grass);
		world.setBlock(i + 3, j + 0, k + 2, Blocks.grass);
		world.setBlock(i + 3, j + 0, k + 3, Blocks.grass);
		world.setBlock(i + 3, j + 0, k + 4, Blocks.grass);
		world.setBlock(i + 3, j + 0, k + 5, Blocks.grass);
		world.setBlock(i + 3, j + 0, k + 6, Blocks.grass);
		world.setBlock(i + 3, j + 0, k + 7, Blocks.grass);
		world.setBlock(i + 3, j + 0, k + 8, Blocks.grass);
		world.setBlock(i + 3, j + 0, k + 9, Blocks.grass);
		world.setBlock(i + 3, j + 0, k + 10, Blocks.grass);
		world.setBlock(i + 3, j + 0, k + 11, Blocks.grass);
		world.setBlock(i + 3, j + 0, k + 12, Blocks.grass);
		world.setBlock(i + 3, j + 0, k + 13, Blocks.grass);
		world.setBlock(i + 3, j + 0, k + 14, Blocks.farmland, 7, 0x02);
		world.setBlock(i + 3, j + 0, k + 16, Blocks.farmland, 7, 0x02);
		world.setBlock(i + 3, j + 0, k + 17, Blocks.grass);
		world.setBlock(i + 3, j + 0, k + 18, Blocks.grass);
		world.setBlock(i + 3, j + 1, k + 0, Blocks.cobblestone_wall);
		world.setBlock(i + 3, j + 1, k + 18, Blocks.cobblestone_wall);
		world.setBlock(i + 3, j + 2, k + 0, Blocks.fence);
		world.setBlock(i + 3, j + 2, k + 18, Blocks.fence);
		world.setBlock(i + 3, j + 7, k + 2, Blocks.leaves, 1, 0x02);
		world.setBlock(i + 3, j + 8, k + 0, Blocks.leaves, 1, 0x02);
		world.setBlock(i + 3, j + 8, k + 1, Blocks.leaves, 1, 0x02);
		world.setBlock(i + 3, j + 8, k + 2, Blocks.leaves, 1, 0x02);
		world.setBlock(i + 3, j + 8, k + 3, Blocks.leaves, 1, 0x02);
		world.setBlock(i + 3, j + 8, k + 4, Blocks.leaves, 1, 0x02);
		world.setBlock(i + 3, j + 9, k + 2, Blocks.leaves, 1, 0x02);
		world.setBlock(i + 3, j + 9, k + 8, Blocks.fence);
		world.setBlock(i + 3, j + 10, k + 0, Blocks.leaves, 1, 0x02);
		world.setBlock(i + 3, j + 10, k + 1, Blocks.leaves, 1, 0x02);
		world.setBlock(i + 3, j + 10, k + 2, Blocks.leaves, 1, 0x02);
		world.setBlock(i + 3, j + 10, k + 3, Blocks.leaves, 1, 0x02);
		world.setBlock(i + 3, j + 10, k + 4, Blocks.leaves, 1, 0x02);
		world.setBlock(i + 3, j + 11, k + 2, Blocks.leaves, 1, 0x02);
		world.setBlock(i + 3, j + 13, k + 2, Blocks.leaves, 1, 0x02);
		world.setBlock(i + 4, j + 0, k + 0, Blocks.grass);
		world.setBlock(i + 4, j + 0, k + 1, Blocks.grass);
		world.setBlock(i + 4, j + 0, k + 2, Blocks.grass);
		world.setBlock(i + 4, j + 0, k + 3, Blocks.grass);
		world.setBlock(i + 4, j + 0, k + 4, Blocks.dirt);
		world.setBlock(i + 4, j + 0, k + 5, Blocks.dirt);
		world.setBlock(i + 4, j + 0, k + 6, Blocks.dirt);
		world.setBlock(i + 4, j + 0, k + 7, Blocks.dirt);
		world.setBlock(i + 4, j + 0, k + 8, Blocks.dirt);
		world.setBlock(i + 4, j + 0, k + 9, Blocks.dirt);
		world.setBlock(i + 4, j + 0, k + 10, Blocks.dirt);
		world.setBlock(i + 4, j + 0, k + 11, Blocks.dirt);
		world.setBlock(i + 4, j + 0, k + 12, Blocks.dirt);
		world.setBlock(i + 4, j + 0, k + 13, Blocks.grass);
		world.setBlock(i + 4, j + 0, k + 14, Blocks.farmland, 7, 0x02);
		world.setBlock(i + 4, j + 0, k + 15, Blocks.farmland, 7, 0x02);
		world.setBlock(i + 4, j + 0, k + 16, Blocks.farmland, 7, 0x02);
		world.setBlock(i + 4, j + 0, k + 17, Blocks.grass);
		world.setBlock(i + 4, j + 0, k + 18, Blocks.grass);
		world.setBlock(i + 4, j + 1, k + 0, Blocks.cobblestone_wall);
		world.setBlock(i + 4, j + 1, k + 4, Blocks.stonebrick);
		world.setBlock(i + 4, j + 1, k + 5, Blocks.stonebrick);
		world.setBlock(i + 4, j + 1, k + 6, Blocks.stonebrick);
		world.setBlock(i + 4, j + 1, k + 7, Blocks.stonebrick);
		world.setBlock(i + 4, j + 1, k + 8, Blocks.stonebrick);
		world.setBlock(i + 4, j + 1, k + 9, Blocks.stonebrick);
		world.setBlock(i + 4, j + 1, k + 10, Blocks.stonebrick);
		world.setBlock(i + 4, j + 1, k + 11, Blocks.stonebrick);
		world.setBlock(i + 4, j + 1, k + 12, Blocks.stonebrick);
		world.setBlock(i + 4, j + 1, k + 18, Blocks.cobblestone_wall);
		world.setBlock(i + 4, j + 2, k + 0, Blocks.fence);
		world.setBlock(i + 4, j + 2, k + 4, Blocks.fence);
		world.setBlock(i + 4, j + 2, k + 12, Blocks.fence);
		world.setBlock(i + 4, j + 2, k + 18, Blocks.fence);
		world.setBlock(i + 4, j + 3, k + 4, Blocks.fence);
		world.setBlock(i + 4, j + 3, k + 12, Blocks.fence);
		world.setBlock(i + 4, j + 4, k + 4, Blocks.fence);
		world.setBlock(i + 4, j + 4, k + 12, Blocks.fence);
		world.setBlock(i + 4, j + 5, k + 4, Blocks.fence);
		world.setBlock(i + 4, j + 5, k + 12, Blocks.fence);
		world.setBlock(i + 4, j + 6, k + 4, Blocks.wooden_slab, 1, 0x02);
		world.setBlock(i + 4, j + 6, k + 5, Blocks.wooden_slab, 1, 0x02);
		world.setBlock(i + 4, j + 6, k + 6, Blocks.wooden_slab, 1, 0x02);
		world.setBlock(i + 4, j + 6, k + 7, Blocks.wooden_slab, 1, 0x02);
		world.setBlock(i + 4, j + 6, k + 8, Blocks.wooden_slab, 1, 0x02);
		world.setBlock(i + 4, j + 6, k + 9, Blocks.wooden_slab, 1, 0x02);
		world.setBlock(i + 4, j + 6, k + 10, Blocks.wooden_slab, 1, 0x02);
		world.setBlock(i + 4, j + 6, k + 11, Blocks.wooden_slab, 1, 0x02);
		world.setBlock(i + 4, j + 6, k + 12, Blocks.wooden_slab, 1, 0x02);
		world.setBlock(i + 4, j + 8, k + 1, Blocks.leaves, 1, 0x02);
		world.setBlock(i + 4, j + 8, k + 2, Blocks.leaves, 1, 0x02);
		world.setBlock(i + 4, j + 8, k + 3, Blocks.leaves, 1, 0x02);
		world.setBlock(i + 4, j + 8, k + 8, Blocks.fence);
		world.setBlock(i + 4, j + 9, k + 8, Blocks.fence);
		world.setBlock(i + 4, j + 10, k + 1, Blocks.leaves, 1, 0x02);
		world.setBlock(i + 4, j + 10, k + 2, Blocks.leaves, 1, 0x02);
		world.setBlock(i + 4, j + 10, k + 3, Blocks.leaves, 1, 0x02);
		world.setBlock(i + 5, j + 0, k + 0, Blocks.grass);
		world.setBlock(i + 5, j + 0, k + 1, Blocks.grass);
		world.setBlock(i + 5, j + 0, k + 2, Blocks.grass);
		world.setBlock(i + 5, j + 0, k + 3, Blocks.grass);
		world.setBlock(i + 5, j + 0, k + 4, Blocks.dirt);
		world.setBlock(i + 5, j + 0, k + 5, Blocks.dirt);
		world.setBlock(i + 5, j + 0, k + 6, Blocks.dirt);
		world.setBlock(i + 5, j + 0, k + 7, Blocks.dirt);
		world.setBlock(i + 5, j + 0, k + 8, Blocks.dirt);
		world.setBlock(i + 5, j + 0, k + 9, Blocks.dirt);
		world.setBlock(i + 5, j + 0, k + 10, Blocks.dirt);
		world.setBlock(i + 5, j + 0, k + 11, Blocks.dirt);
		world.setBlock(i + 5, j + 0, k + 12, Blocks.dirt);
		world.setBlock(i + 5, j + 0, k + 13, Blocks.grass);
		world.setBlock(i + 5, j + 0, k + 14, Blocks.farmland, 7, 0x02);
		world.setBlock(i + 5, j + 0, k + 15, Blocks.farmland, 7, 0x02);
		world.setBlock(i + 5, j + 0, k + 16, Blocks.farmland, 7, 0x02);
		world.setBlock(i + 5, j + 0, k + 17, Blocks.grass);
		world.setBlock(i + 5, j + 0, k + 18, Blocks.grass);
		world.setBlock(i + 5, j + 1, k + 0, Blocks.cobblestone_wall);
		world.setBlock(i + 5, j + 1, k + 4, Blocks.stonebrick);
		world.setBlock(i + 5, j + 1, k + 5, Blocks.stonebrick);
		world.setBlock(i + 5, j + 1, k + 6, Blocks.stonebrick);
		world.setBlock(i + 5, j + 1, k + 7, Blocks.stonebrick);
		world.setBlock(i + 5, j + 1, k + 8, Blocks.stonebrick);
		world.setBlock(i + 5, j + 1, k + 9, Blocks.stonebrick);
		world.setBlock(i + 5, j + 1, k + 10, Blocks.stonebrick);
		world.setBlock(i + 5, j + 1, k + 11, Blocks.stonebrick);
		world.setBlock(i + 5, j + 1, k + 12, Blocks.stonebrick);
		world.setBlock(i + 5, j + 1, k + 18, Blocks.cobblestone_wall);
		world.setBlock(i + 5, j + 2, k + 0, Blocks.fence);
		world.setBlock(i + 5, j + 2, k + 5, Blocks.log, 1, 0x02);
		world.setBlock(i + 5, j + 2, k + 6, Blocks.wool);
		world.setBlock(i + 5, j + 2, k + 7, Blocks.wool);
		world.setBlock(i + 5, j + 2, k + 8, Blocks.wool);
		world.setBlock(i + 5, j + 2, k + 9, Blocks.wool);
		world.setBlock(i + 5, j + 2, k + 10, Blocks.wool);
		world.setBlock(i + 5, j + 2, k + 11, Blocks.log, 1, 0x02);
		world.setBlock(i + 5, j + 2, k + 18, Blocks.fence);
		world.setBlock(i + 5, j + 3, k + 5, Blocks.log, 1, 0x02);
		world.setBlock(i + 5, j + 3, k + 6, Blocks.wool);
		world.setBlock(i + 5, j + 3, k + 7, Blocks.wool);
		world.setBlock(i + 5, j + 3, k + 8, Blocks.wool);
		world.setBlock(i + 5, j + 3, k + 9, Blocks.wool);
		world.setBlock(i + 5, j + 3, k + 10, Blocks.wool);
		world.setBlock(i + 5, j + 3, k + 11, Blocks.log, 1, 0x02);
		world.setBlock(i + 5, j + 4, k + 5, Blocks.log, 1, 0x02);
		world.setBlock(i + 5, j + 4, k + 6, Blocks.wool);
		world.setBlock(i + 5, j + 4, k + 7, Blocks.wool);
		world.setBlock(i + 5, j + 4, k + 8, Blocks.wool);
		world.setBlock(i + 5, j + 4, k + 9, Blocks.wool);
		world.setBlock(i + 5, j + 4, k + 10, Blocks.wool);
		world.setBlock(i + 5, j + 4, k + 11, Blocks.log, 1, 0x02);
		world.setBlock(i + 5, j + 5, k + 5, Blocks.log, 1, 0x02);
		world.setBlock(i + 5, j + 5, k + 6, Blocks.log, 9, 0x02);
		world.setBlock(i + 5, j + 5, k + 7, Blocks.wool);
		world.setBlock(i + 5, j + 5, k + 8, Blocks.stone_stairs);
		world.setBlock(i + 5, j + 5, k + 9, Blocks.wool);
		world.setBlock(i + 5, j + 5, k + 10, Blocks.log, 9, 0x02);
		world.setBlock(i + 5, j + 5, k + 11, Blocks.log, 1, 0x02);
		world.setBlock(i + 5, j + 6, k + 4, Blocks.wooden_slab, 1, 0x02);
		world.setBlock(i + 5, j + 6, k + 5, Blocks.stonebrick, 2, 0x02);
		world.setBlock(i + 5, j + 6, k + 6, Blocks.log, 1, 0x02);
		world.setBlock(i + 5, j + 6, k + 7, Blocks.log, 9, 0x02);
		world.setBlock(i + 5, j + 6, k + 8, Blocks.fence);
		world.setBlock(i + 5, j + 6, k + 9, Blocks.log, 9, 0x02);
		world.setBlock(i + 5, j + 6, k + 10, Blocks.log, 1, 0x02);
		world.setBlock(i + 5, j + 6, k + 11, Blocks.stonebrick, 3, 0x02);
		world.setBlock(i + 5, j + 6, k + 12, Blocks.wooden_slab, 1, 0x02);
		world.setBlock(i + 5, j + 7, k + 6, Blocks.stonebrick, 2, 0x02);
		world.setBlock(i + 5, j + 7, k + 7, Blocks.log, 1, 0x02);
		world.setBlock(i + 5, j + 7, k + 8, Blocks.log, 9, 0x02);
		world.setBlock(i + 5, j + 7, k + 9, Blocks.log, 1, 0x02);
		world.setBlock(i + 5, j + 7, k + 10, Blocks.stonebrick, 3, 0x02);
		world.setBlock(i + 5, j + 8, k + 7, Blocks.stonebrick, 2, 0x02);
		world.setBlock(i + 5, j + 8, k + 8, Blocks.log, 1, 0x02);
		world.setBlock(i + 5, j + 8, k + 9, Blocks.stonebrick, 3, 0x02);
		world.setBlock(i + 5, j + 9, k + 8, Blocks.wooden_slab, 1, 0x02);
		world.setBlock(i + 6, j + 0, k + 0, Blocks.grass);
		world.setBlock(i + 6, j + 0, k + 1, Blocks.grass);
		world.setBlock(i + 6, j + 0, k + 2, Blocks.grass);
		world.setBlock(i + 6, j + 0, k + 3, Blocks.grass);
		world.setBlock(i + 6, j + 0, k + 4, Blocks.dirt);
		world.setBlock(i + 6, j + 0, k + 5, Blocks.dirt);
		world.setBlock(i + 6, j + 0, k + 6, Blocks.dirt);
		world.setBlock(i + 6, j + 0, k + 7, Blocks.dirt);
		world.setBlock(i + 6, j + 0, k + 8, Blocks.dirt);
		world.setBlock(i + 6, j + 0, k + 9, Blocks.dirt);
		world.setBlock(i + 6, j + 0, k + 10, Blocks.dirt);
		world.setBlock(i + 6, j + 0, k + 11, Blocks.dirt);
		world.setBlock(i + 6, j + 0, k + 12, Blocks.dirt);
		world.setBlock(i + 6, j + 0, k + 13, Blocks.grass);
		world.setBlock(i + 6, j + 0, k + 14, Blocks.farmland, 7, 0x02);
		world.setBlock(i + 6, j + 0, k + 16, Blocks.farmland, 7, 0x02);
		world.setBlock(i + 6, j + 0, k + 17, Blocks.grass);
		world.setBlock(i + 6, j + 0, k + 18, Blocks.grass);
		world.setBlock(i + 6, j + 1, k + 0, Blocks.cobblestone_wall);
		world.setBlock(i + 6, j + 1, k + 4, Blocks.stonebrick);
		world.setBlock(i + 6, j + 1, k + 5, Blocks.stonebrick);
		world.setBlock(i + 6, j + 1, k + 6, Blocks.planks, 1, 0x02);
		world.setBlock(i + 6, j + 1, k + 7, Blocks.planks, 1, 0x02);
		world.setBlock(i + 6, j + 1, k + 8, Blocks.planks, 1, 0x02);
		world.setBlock(i + 6, j + 1, k + 9, Blocks.planks, 1, 0x02);
		world.setBlock(i + 6, j + 1, k + 10, Blocks.planks, 1, 0x02);
		world.setBlock(i + 6, j + 1, k + 11, Blocks.stonebrick);
		world.setBlock(i + 6, j + 1, k + 12, Blocks.stonebrick);
		world.setBlock(i + 6, j + 1, k + 18, Blocks.cobblestone_wall);
		world.setBlock(i + 6, j + 2, k + 0, Blocks.fence);
		world.setBlock(i + 6, j + 2, k + 5, Blocks.wool);
		world.setBlock(i + 6, j + 2, k + 6, Blocks.crafting_table);
		world.setBlock(i + 6, j + 2, k + 7, Blocks.furnace, 5, 0x02);
		world.setBlock(i + 6, j + 2, k + 8, Blocks.fence);
		world.setBlock(i + 6, j + 2, k + 11, Blocks.wool);
		world.setBlock(i + 6, j + 2, k + 18, Blocks.fence);
		world.setBlock(i + 6, j + 3, k + 5, Blocks.wool);
		world.setBlock(i + 6, j + 3, k + 8, Blocks.fence);
		world.setBlock(i + 6, j + 3, k + 11, Blocks.wool);
		world.setBlock(i + 6, j + 4, k + 5, Blocks.wool);
		world.setBlock(i + 6, j + 4, k + 6, Blocks.fence);
		world.setBlock(i + 6, j + 4, k + 7, Blocks.fence);
		world.setBlock(i + 6, j + 4, k + 8, Blocks.fence);
		world.setBlock(i + 6, j + 4, k + 9, Blocks.fence);
		world.setBlock(i + 6, j + 4, k + 10, Blocks.fence);
		world.setBlock(i + 6, j + 4, k + 11, Blocks.wool);
		world.setBlock(i + 6, j + 5, k + 5, Blocks.log, 5, 0x02);
		world.setBlock(i + 6, j + 5, k + 6, Blocks.chest, 5, 0x02);
		world.setBlock(i + 6, j + 5, k + 7, Blocks.chest, 5, 0x02);
		world.setBlock(i + 6, j + 5, k + 9, Blocks.chest, 5, 0x02);
		world.setBlock(i + 6, j + 5, k + 10, Blocks.chest, 5, 0x02);
		world.setBlock(i + 6, j + 5, k + 11, Blocks.log, 5, 0x02);
		world.setBlock(i + 6, j + 6, k + 4, Blocks.wooden_slab, 1, 0x02);
		world.setBlock(i + 6, j + 6, k + 5, Blocks.stonebrick, 2, 0x02);
		world.setBlock(i + 6, j + 6, k + 11, Blocks.stonebrick, 3, 0x02);
		world.setBlock(i + 6, j + 6, k + 12, Blocks.wooden_slab, 1, 0x02);
		world.setBlock(i + 6, j + 7, k + 6, Blocks.stonebrick, 2, 0x02);
		world.setBlock(i + 6, j + 7, k + 10, Blocks.stonebrick, 3, 0x02);
		world.setBlock(i + 6, j + 8, k + 7, Blocks.stonebrick, 2, 0x02);
		world.setBlock(i + 6, j + 8, k + 9, Blocks.stonebrick, 3, 0x02);
		world.setBlock(i + 6, j + 9, k + 8, Blocks.wooden_slab, 1, 0x02);
		world.setBlock(i + 7, j + 0, k + 0, Blocks.grass);
		world.setBlock(i + 7, j + 0, k + 1, Blocks.grass);
		world.setBlock(i + 7, j + 0, k + 2, Blocks.grass);
		world.setBlock(i + 7, j + 0, k + 3, Blocks.grass);
		world.setBlock(i + 7, j + 0, k + 4, Blocks.dirt);
		world.setBlock(i + 7, j + 0, k + 5, Blocks.dirt);
		world.setBlock(i + 7, j + 0, k + 6, Blocks.dirt);
		world.setBlock(i + 7, j + 0, k + 7, Blocks.dirt);
		world.setBlock(i + 7, j + 0, k + 8, Blocks.dirt);
		world.setBlock(i + 7, j + 0, k + 9, Blocks.dirt);
		world.setBlock(i + 7, j + 0, k + 10, Blocks.dirt);
		world.setBlock(i + 7, j + 0, k + 11, Blocks.dirt);
		world.setBlock(i + 7, j + 0, k + 12, Blocks.dirt);
		world.setBlock(i + 7, j + 0, k + 13, Blocks.grass);
		world.setBlock(i + 7, j + 0, k + 14, Blocks.farmland, 7, 0x02);
		world.setBlock(i + 7, j + 0, k + 15, Blocks.farmland, 7, 0x02);
		world.setBlock(i + 7, j + 0, k + 16, Blocks.farmland, 7, 0x02);
		world.setBlock(i + 7, j + 0, k + 17, Blocks.grass);
		world.setBlock(i + 7, j + 0, k + 18, Blocks.grass);
		world.setBlock(i + 7, j + 1, k + 0, Blocks.cobblestone_wall);
		world.setBlock(i + 7, j + 1, k + 4, Blocks.stonebrick);
		world.setBlock(i + 7, j + 1, k + 5, Blocks.stonebrick);
		world.setBlock(i + 7, j + 1, k + 6, Blocks.planks, 1, 0x02);
		world.setBlock(i + 7, j + 1, k + 7, Blocks.planks, 2, 0x02);
		world.setBlock(i + 7, j + 1, k + 8, Blocks.planks, 2, 0x02);
		world.setBlock(i + 7, j + 1, k + 9, Blocks.planks, 2, 0x02);
		world.setBlock(i + 7, j + 1, k + 10, Blocks.planks, 1, 0x02);
		world.setBlock(i + 7, j + 1, k + 11, Blocks.stonebrick);
		world.setBlock(i + 7, j + 1, k + 12, Blocks.stonebrick);
		world.setBlock(i + 7, j + 1, k + 18, Blocks.cobblestone_wall);
		world.setBlock(i + 7, j + 2, k + 0, Blocks.fence);
		world.setBlock(i + 7, j + 2, k + 5, Blocks.wool);
		world.setBlock(i + 7, j + 2, k + 11, Blocks.wool);
		world.setBlock(i + 7, j + 2, k + 18, Blocks.fence);
		world.setBlock(i + 7, j + 3, k + 0, Blocks.fence);
		world.setBlock(i + 7, j + 3, k + 5, Blocks.wool);
		world.setBlock(i + 7, j + 3, k + 11, Blocks.wool);
		world.setBlock(i + 7, j + 3, k + 18, Blocks.fence);
		world.setBlock(i + 7, j + 4, k + 5, Blocks.wool);
		world.setBlock(i + 7, j + 4, k + 11, Blocks.wool);
		world.setBlock(i + 7, j + 5, k + 5, Blocks.log, 5, 0x02);
		world.setBlock(i + 7, j + 5, k + 11, Blocks.log, 5, 0x02);
		world.setBlock(i + 7, j + 6, k + 4, Blocks.wooden_slab, 1, 0x02);
		world.setBlock(i + 7, j + 6, k + 5, Blocks.stonebrick, 2, 0x02);
		world.setBlock(i + 7, j + 6, k + 11, Blocks.stonebrick, 3, 0x02);
		world.setBlock(i + 7, j + 6, k + 12, Blocks.wooden_slab, 1, 0x02);
		world.setBlock(i + 7, j + 7, k + 6, Blocks.stonebrick, 2, 0x02);
		world.setBlock(i + 7, j + 7, k + 10, Blocks.stonebrick, 3, 0x02);
		world.setBlock(i + 7, j + 8, k + 7, Blocks.stonebrick, 2, 0x02);
		world.setBlock(i + 7, j + 8, k + 9, Blocks.stonebrick, 3, 0x02);
		world.setBlock(i + 7, j + 9, k + 8, Blocks.wooden_slab, 1, 0x02);
		world.setBlock(i + 8, j + 0, k + 0, Blocks.grass);
		world.setBlock(i + 8, j + 0, k + 1, Blocks.grass);
		world.setBlock(i + 8, j + 0, k + 2, Blocks.grass);
		world.setBlock(i + 8, j + 0, k + 3, Blocks.grass);
		world.setBlock(i + 8, j + 0, k + 4, Blocks.dirt);
		world.setBlock(i + 8, j + 0, k + 5, Blocks.dirt);
		world.setBlock(i + 8, j + 0, k + 6, Blocks.dirt);
		world.setBlock(i + 8, j + 0, k + 7, Blocks.dirt);
		world.setBlock(i + 8, j + 0, k + 8, Blocks.dirt);
		world.setBlock(i + 8, j + 0, k + 9, Blocks.dirt);
		world.setBlock(i + 8, j + 0, k + 10, Blocks.dirt);
		world.setBlock(i + 8, j + 0, k + 11, Blocks.dirt);
		world.setBlock(i + 8, j + 0, k + 12, Blocks.dirt);
		world.setBlock(i + 8, j + 0, k + 13, Blocks.grass);
		world.setBlock(i + 8, j + 0, k + 14, Blocks.grass);
		world.setBlock(i + 8, j + 0, k + 15, Blocks.grass);
		world.setBlock(i + 8, j + 0, k + 16, Blocks.grass);
		world.setBlock(i + 8, j + 0, k + 17, Blocks.grass);
		world.setBlock(i + 8, j + 0, k + 18, Blocks.grass);
		world.setBlock(i + 8, j + 1, k + 0, Blocks.cobblestone_wall);
		world.setBlock(i + 8, j + 1, k + 4, Blocks.stonebrick);
		world.setBlock(i + 8, j + 1, k + 5, Blocks.stonebrick);
		world.setBlock(i + 8, j + 1, k + 6, Blocks.planks, 1, 0x02);
		world.setBlock(i + 8, j + 1, k + 7, Blocks.planks, 2, 0x02);
		world.setBlock(i + 8, j + 1, k + 8, Blocks.planks, 1, 0x02);
		world.setBlock(i + 8, j + 1, k + 9, Blocks.planks, 2, 0x02);
		world.setBlock(i + 8, j + 1, k + 10, Blocks.planks, 1, 0x02);
		world.setBlock(i + 8, j + 1, k + 11, Blocks.stonebrick);
		world.setBlock(i + 8, j + 1, k + 12, Blocks.stonebrick);
		world.setBlock(i + 8, j + 1, k + 18, Blocks.cobblestone_wall);
		world.setBlock(i + 8, j + 2, k + 0, Blocks.cobblestone_wall);
		world.setBlock(i + 8, j + 2, k + 5, Blocks.log, 1, 0x02);
		world.setBlock(i + 8, j + 2, k + 11, Blocks.log, 1, 0x02);
		world.setBlock(i + 8, j + 2, k + 18, Blocks.cobblestone_wall);
		world.setBlock(i + 8, j + 3, k + 0, Blocks.cobblestone_wall);
		world.setBlock(i + 8, j + 3, k + 5, Blocks.log, 1, 0x02);
		world.setBlock(i + 8, j + 3, k + 11, Blocks.log, 1, 0x02);
		world.setBlock(i + 8, j + 3, k + 18, Blocks.cobblestone_wall);
		world.setBlock(i + 8, j + 4, k + 0, Blocks.cobblestone_wall);
		world.setBlock(i + 8, j + 4, k + 5, Blocks.log, 1, 0x02);
		world.setBlock(i + 8, j + 4, k + 11, Blocks.log, 1, 0x02);
		world.setBlock(i + 8, j + 4, k + 18, Blocks.cobblestone_wall);
		world.setBlock(i + 8, j + 5, k + 5, Blocks.log, 1, 0x02);
		world.setBlock(i + 8, j + 5, k + 11, Blocks.log, 1, 0x02);
		world.setBlock(i + 8, j + 6, k + 4, Blocks.wooden_slab, 1, 0x02);
		world.setBlock(i + 8, j + 6, k + 5, Blocks.stonebrick, 2, 0x02);
		world.setBlock(i + 8, j + 6, k + 6, Blocks.fence);
		world.setBlock(i + 8, j + 6, k + 7, Blocks.fence);
		world.setBlock(i + 8, j + 6, k + 8, Blocks.fence);
		world.setBlock(i + 8, j + 6, k + 9, Blocks.fence);
		world.setBlock(i + 8, j + 6, k + 10, Blocks.fence);
		world.setBlock(i + 8, j + 6, k + 11, Blocks.stonebrick, 3, 0x02);
		world.setBlock(i + 8, j + 6, k + 12, Blocks.wooden_slab, 1, 0x02);
		world.setBlock(i + 8, j + 7, k + 6, Blocks.stonebrick, 2, 0x02);
		world.setBlock(i + 8, j + 7, k + 8, Blocks.fence);
		world.setBlock(i + 8, j + 7, k + 10, Blocks.stonebrick, 3, 0x02);
		world.setBlock(i + 8, j + 8, k + 7, Blocks.stonebrick, 2, 0x02);
		world.setBlock(i + 8, j + 8, k + 8, Blocks.fence);
		world.setBlock(i + 8, j + 8, k + 9, Blocks.stonebrick, 3, 0x02);
		world.setBlock(i + 8, j + 9, k + 8, Blocks.wooden_slab, 1, 0x02);
		world.setBlock(i + 9, j + 0, k + 0, Blocks.cobblestone);
		world.setBlock(i + 9, j + 0, k + 1, Blocks.cobblestone);
		world.setBlock(i + 9, j + 0, k + 2, Blocks.cobblestone);
		world.setBlock(i + 9, j + 0, k + 3, Blocks.cobblestone);
		world.setBlock(i + 9, j + 0, k + 4, Blocks.dirt);
		world.setBlock(i + 9, j + 0, k + 5, Blocks.dirt);
		world.setBlock(i + 9, j + 0, k + 6, Blocks.dirt);
		world.setBlock(i + 9, j + 0, k + 7, Blocks.dirt);
		world.setBlock(i + 9, j + 0, k + 8, Blocks.dirt);
		world.setBlock(i + 9, j + 0, k + 9, Blocks.dirt);
		world.setBlock(i + 9, j + 0, k + 10, Blocks.dirt);
		world.setBlock(i + 9, j + 0, k + 11, Blocks.dirt);
		world.setBlock(i + 9, j + 0, k + 12, Blocks.dirt);
		world.setBlock(i + 9, j + 0, k + 13, Blocks.cobblestone);
		world.setBlock(i + 9, j + 0, k + 14, Blocks.cobblestone);
		world.setBlock(i + 9, j + 0, k + 15, Blocks.cobblestone);
		world.setBlock(i + 9, j + 0, k + 16, Blocks.cobblestone);
		world.setBlock(i + 9, j + 0, k + 17, Blocks.cobblestone);
		world.setBlock(i + 9, j + 0, k + 18, Blocks.cobblestone);
		world.setBlock(i + 9, j + 1, k + 4, Blocks.stone_brick_stairs, 2, 0x02);
		world.setBlock(i + 9, j + 1, k + 5, Blocks.stonebrick);
		world.setBlock(i + 9, j + 1, k + 6, Blocks.planks, 1, 0x02);
		world.setBlock(i + 9, j + 1, k + 7, Blocks.planks, 2, 0x02);
		world.setBlock(i + 9, j + 1, k + 8, Blocks.planks, 1, 0x02);
		world.setBlock(i + 9, j + 1, k + 9, Blocks.planks, 2, 0x02);
		world.setBlock(i + 9, j + 1, k + 10, Blocks.planks, 1, 0x02);
		world.setBlock(i + 9, j + 1, k + 11, Blocks.stonebrick);
		world.setBlock(i + 9, j + 1, k + 12, Blocks.stone_brick_stairs, 3, 0x02);
		world.setBlock(i + 9, j + 2, k + 7, Blocks.stonebrick, 1, 0x02);
		world.setBlock(i + 9, j + 2, k + 8, Blocks.stonebrick, 1, 0x02);
		world.setBlock(i + 9, j + 2, k + 9, Blocks.stonebrick, 1, 0x02);
		world.setBlock(i + 9, j + 4, k + 0, Blocks.cobblestone_wall);
		world.setBlock(i + 9, j + 4, k + 5, Blocks.fence);
		world.setBlock(i + 9, j + 4, k + 11, Blocks.fence);
		world.setBlock(i + 9, j + 4, k + 18, Blocks.cobblestone_wall);
		world.setBlock(i + 9, j + 5, k + 0, Blocks.cobblestone_wall);
		world.setBlock(i + 9, j + 5, k + 5, Blocks.log, 5, 0x02);
		world.setBlock(i + 9, j + 5, k + 11, Blocks.log, 5, 0x02);
		world.setBlock(i + 9, j + 5, k + 18, Blocks.cobblestone_wall);
		world.setBlock(i + 9, j + 6, k + 4, Blocks.wooden_slab, 1, 0x02);
		world.setBlock(i + 9, j + 6, k + 5, Blocks.stonebrick, 2, 0x02);
		world.setBlock(i + 9, j + 6, k + 11, Blocks.stonebrick, 3, 0x02);
		world.setBlock(i + 9, j + 6, k + 12, Blocks.wooden_slab, 1, 0x02);
		world.setBlock(i + 9, j + 7, k + 6, Blocks.stonebrick, 2, 0x02);
		world.setBlock(i + 9, j + 7, k + 10, Blocks.stonebrick, 3, 0x02);
		world.setBlock(i + 9, j + 8, k + 7, Blocks.stonebrick, 2, 0x02);
		world.setBlock(i + 9, j + 8, k + 9, Blocks.stonebrick, 3, 0x02);
		world.setBlock(i + 9, j + 9, k + 8, Blocks.wooden_slab, 1, 0x02);
		world.setBlock(i + 10, j + 0, k + 0, Blocks.cobblestone);
		world.setBlock(i + 10, j + 0, k + 1, Blocks.stone_stairs, 2, 0x02);
		world.setBlock(i + 10, j + 0, k + 2, Blocks.stone_stairs, 2, 0x02);
		world.setBlock(i + 10, j + 0, k + 3, Blocks.cobblestone);
		world.setBlock(i + 10, j + 0, k + 4, Blocks.dirt);
		world.setBlock(i + 10, j + 0, k + 5, Blocks.dirt);
		world.setBlock(i + 10, j + 0, k + 6, Blocks.dirt);
		world.setBlock(i + 10, j + 0, k + 7, Blocks.dirt);
		world.setBlock(i + 10, j + 0, k + 8, Blocks.dirt);
		world.setBlock(i + 10, j + 0, k + 9, Blocks.dirt);
		world.setBlock(i + 10, j + 0, k + 10, Blocks.dirt);
		world.setBlock(i + 10, j + 0, k + 11, Blocks.dirt);
		world.setBlock(i + 10, j + 0, k + 12, Blocks.dirt);
		world.setBlock(i + 10, j + 0, k + 13, Blocks.cobblestone);
		world.setBlock(i + 10, j + 0, k + 14, Blocks.stone_stairs, 3, 0x02);
		world.setBlock(i + 10, j + 0, k + 15, Blocks.stone_stairs, 3, 0x02);
		world.setBlock(i + 10, j + 0, k + 16, Blocks.stone_stairs, 3, 0x02);
		world.setBlock(i + 10, j + 0, k + 17, Blocks.stone_stairs, 3, 0x02);
		world.setBlock(i + 10, j + 0, k + 18, Blocks.cobblestone);
		world.setBlock(i + 10, j + 1, k + 4, Blocks.stone_brick_stairs, 2, 0x02);
		world.setBlock(i + 10, j + 1, k + 5, Blocks.stonebrick);
		world.setBlock(i + 10, j + 1, k + 6, Blocks.planks, 1, 0x02);
		world.setBlock(i + 10, j + 1, k + 7, Blocks.planks, 2, 0x02);
		world.setBlock(i + 10, j + 1, k + 8, Blocks.planks, 1, 0x02);
		world.setBlock(i + 10, j + 1, k + 9, Blocks.planks, 2, 0x02);
		world.setBlock(i + 10, j + 1, k + 10, Blocks.planks, 1, 0x02);
		world.setBlock(i + 10, j + 1, k + 11, Blocks.stonebrick);
		world.setBlock(i + 10, j + 1, k + 12, Blocks.stone_brick_stairs, 3, 0x02);
		world.setBlock(i + 10, j + 5, k + 0, Blocks.cobblestone_wall);
		world.setBlock(i + 10, j + 5, k + 5, Blocks.log, 5, 0x02);
		world.setBlock(i + 10, j + 5, k + 11, Blocks.log, 5, 0x02);
		world.setBlock(i + 10, j + 5, k + 18, Blocks.cobblestone_wall);
		world.setBlock(i + 10, j + 6, k + 0, Blocks.cobblestone_wall);
		world.setBlock(i + 10, j + 6, k + 4, Blocks.wooden_slab, 1, 0x02);
		world.setBlock(i + 10, j + 6, k + 5, Blocks.stonebrick, 2, 0x02);
		world.setBlock(i + 10, j + 6, k + 11, Blocks.stonebrick, 3, 0x02);
		world.setBlock(i + 10, j + 6, k + 12, Blocks.wooden_slab, 1, 0x02);
		world.setBlock(i + 10, j + 6, k + 18, Blocks.cobblestone_wall);
		world.setBlock(i + 10, j + 7, k + 6, Blocks.stonebrick, 2, 0x02);
		world.setBlock(i + 10, j + 7, k + 10, Blocks.stonebrick, 3, 0x02);
		world.setBlock(i + 10, j + 8, k + 7, Blocks.stonebrick, 2, 0x02);
		world.setBlock(i + 10, j + 8, k + 9, Blocks.stonebrick, 3, 0x02);
		world.setBlock(i + 10, j + 9, k + 8, Blocks.wooden_slab, 1, 0x02);
		world.setBlock(i + 11, j + 0, k + 0, Blocks.cobblestone);
		world.setBlock(i + 11, j + 0, k + 1, Blocks.stone_stairs, 2, 0x02);
		world.setBlock(i + 11, j + 0, k + 2, Blocks.stone_stairs, 2, 0x02);
		world.setBlock(i + 11, j + 0, k + 3, Blocks.cobblestone);
		world.setBlock(i + 11, j + 0, k + 4, Blocks.dirt);
		world.setBlock(i + 11, j + 0, k + 5, Blocks.dirt);
		world.setBlock(i + 11, j + 0, k + 6, Blocks.dirt);
		world.setBlock(i + 11, j + 0, k + 7, Blocks.dirt);
		world.setBlock(i + 11, j + 0, k + 8, Blocks.dirt);
		world.setBlock(i + 11, j + 0, k + 9, Blocks.dirt);
		world.setBlock(i + 11, j + 0, k + 10, Blocks.dirt);
		world.setBlock(i + 11, j + 0, k + 11, Blocks.dirt);
		world.setBlock(i + 11, j + 0, k + 12, Blocks.dirt);
		world.setBlock(i + 11, j + 0, k + 13, Blocks.cobblestone);
		world.setBlock(i + 11, j + 0, k + 14, Blocks.stone_stairs, 3, 0x02);
		world.setBlock(i + 11, j + 0, k + 15, Blocks.stone_stairs, 3, 0x02);
		world.setBlock(i + 11, j + 0, k + 16, Blocks.stone_stairs, 3, 0x02);
		world.setBlock(i + 11, j + 0, k + 17, Blocks.stone_stairs, 3, 0x02);
		world.setBlock(i + 11, j + 0, k + 18, Blocks.cobblestone);
		world.setBlock(i + 11, j + 1, k + 4, Blocks.stone_brick_stairs, 2, 0x02);
		world.setBlock(i + 11, j + 1, k + 5, Blocks.stonebrick);
		world.setBlock(i + 11, j + 1, k + 6, Blocks.planks, 1, 0x02);
		world.setBlock(i + 11, j + 1, k + 7, Blocks.planks, 2, 0x02);
		world.setBlock(i + 11, j + 1, k + 8, Blocks.planks, 1, 0x02);
		world.setBlock(i + 11, j + 1, k + 9, Blocks.planks, 2, 0x02);
		world.setBlock(i + 11, j + 1, k + 10, Blocks.planks, 1, 0x02);
		world.setBlock(i + 11, j + 1, k + 11, Blocks.stonebrick);
		world.setBlock(i + 11, j + 1, k + 12, Blocks.stone_brick_stairs, 3, 0x02);
		world.setBlock(i + 11, j + 5, k + 0, Blocks.cobblestone_wall);
		world.setBlock(i + 11, j + 5, k + 5, Blocks.log, 5, 0x02);
		world.setBlock(i + 11, j + 5, k + 11, Blocks.log, 5, 0x02);
		world.setBlock(i + 11, j + 5, k + 18, Blocks.cobblestone_wall);
		world.setBlock(i + 11, j + 6, k + 0, Blocks.cobblestone_wall);
		world.setBlock(i + 11, j + 6, k + 4, Blocks.wooden_slab, 1, 0x02);
		world.setBlock(i + 11, j + 6, k + 5, Blocks.stonebrick, 2, 0x02);
		world.setBlock(i + 11, j + 6, k + 11, Blocks.stonebrick, 3, 0x02);
		world.setBlock(i + 11, j + 6, k + 12, Blocks.wooden_slab, 1, 0x02);
		world.setBlock(i + 11, j + 6, k + 18, Blocks.cobblestone_wall);
		world.setBlock(i + 11, j + 7, k + 6, Blocks.stonebrick, 2, 0x02);
		world.setBlock(i + 11, j + 7, k + 10, Blocks.stonebrick, 3, 0x02);
		world.setBlock(i + 11, j + 8, k + 7, Blocks.stonebrick, 2, 0x02);
		world.setBlock(i + 11, j + 8, k + 9, Blocks.stonebrick, 3, 0x02);
		world.setBlock(i + 11, j + 9, k + 8, Blocks.wooden_slab, 1, 0x02);
		world.setBlock(i + 12, j + 0, k + 0, Blocks.cobblestone);
		world.setBlock(i + 12, j + 0, k + 1, Blocks.cobblestone);
		world.setBlock(i + 12, j + 0, k + 2, Blocks.cobblestone);
		world.setBlock(i + 12, j + 0, k + 3, Blocks.cobblestone);
		world.setBlock(i + 12, j + 0, k + 4, Blocks.dirt);
		world.setBlock(i + 12, j + 0, k + 5, Blocks.dirt);
		world.setBlock(i + 12, j + 0, k + 6, Blocks.dirt);
		world.setBlock(i + 12, j + 0, k + 7, Blocks.dirt);
		world.setBlock(i + 12, j + 0, k + 8, Blocks.dirt);
		world.setBlock(i + 12, j + 0, k + 9, Blocks.dirt);
		world.setBlock(i + 12, j + 0, k + 10, Blocks.dirt);
		world.setBlock(i + 12, j + 0, k + 11, Blocks.dirt);
		world.setBlock(i + 12, j + 0, k + 12, Blocks.dirt);
		world.setBlock(i + 12, j + 0, k + 13, Blocks.cobblestone);
		world.setBlock(i + 12, j + 0, k + 14, Blocks.cobblestone);
		world.setBlock(i + 12, j + 0, k + 15, Blocks.cobblestone);
		world.setBlock(i + 12, j + 0, k + 16, Blocks.cobblestone);
		world.setBlock(i + 12, j + 0, k + 17, Blocks.cobblestone);
		world.setBlock(i + 12, j + 0, k + 18, Blocks.cobblestone);
		world.setBlock(i + 12, j + 1, k + 4, Blocks.stone_brick_stairs, 2, 0x02);
		world.setBlock(i + 12, j + 1, k + 5, Blocks.stonebrick);
		world.setBlock(i + 12, j + 1, k + 6, Blocks.planks, 1, 0x02);
		world.setBlock(i + 12, j + 1, k + 7, Blocks.planks, 2, 0x02);
		world.setBlock(i + 12, j + 1, k + 8, Blocks.planks, 1, 0x02);
		world.setBlock(i + 12, j + 1, k + 9, Blocks.planks, 2, 0x02);
		world.setBlock(i + 12, j + 1, k + 10, Blocks.planks, 1, 0x02);
		world.setBlock(i + 12, j + 1, k + 11, Blocks.stonebrick);
		world.setBlock(i + 12, j + 1, k + 12, Blocks.stone_brick_stairs, 3, 0x02);
		world.setBlock(i + 12, j + 2, k + 7, Blocks.stonebrick);
		world.setBlock(i + 12, j + 2, k + 8, Blocks.stonebrick);
		world.setBlock(i + 12, j + 2, k + 9, Blocks.stonebrick);
		world.setBlock(i + 12, j + 4, k + 0, Blocks.cobblestone_wall);
		world.setBlock(i + 12, j + 4, k + 5, Blocks.fence);
		world.setBlock(i + 12, j + 4, k + 11, Blocks.fence);
		world.setBlock(i + 12, j + 4, k + 18, Blocks.cobblestone_wall);
		world.setBlock(i + 12, j + 5, k + 0, Blocks.cobblestone_wall);
		world.setBlock(i + 12, j + 5, k + 5, Blocks.log, 5, 0x02);
		world.setBlock(i + 12, j + 5, k + 11, Blocks.log, 5, 0x02);
		world.setBlock(i + 12, j + 5, k + 18, Blocks.cobblestone_wall);
		world.setBlock(i + 12, j + 6, k + 4, Blocks.wooden_slab, 1, 0x02);
		world.setBlock(i + 12, j + 6, k + 5, Blocks.stonebrick, 2, 0x02);
		world.setBlock(i + 12, j + 6, k + 11, Blocks.stonebrick, 3, 0x02);
		world.setBlock(i + 12, j + 6, k + 12, Blocks.wooden_slab, 1, 0x02);
		world.setBlock(i + 12, j + 7, k + 6, Blocks.stonebrick, 2, 0x02);
		world.setBlock(i + 12, j + 7, k + 10, Blocks.stonebrick, 3, 0x02);
		world.setBlock(i + 12, j + 8, k + 7, Blocks.stonebrick, 2, 0x02);
		world.setBlock(i + 12, j + 8, k + 9, Blocks.stonebrick, 3, 0x02);
		world.setBlock(i + 12, j + 9, k + 8, Blocks.wooden_slab, 1, 0x02);
		world.setBlock(i + 13, j + 0, k + 0, Blocks.grass);
		world.setBlock(i + 13, j + 0, k + 1, Blocks.grass);
		world.setBlock(i + 13, j + 0, k + 2, Blocks.grass);
		world.setBlock(i + 13, j + 0, k + 3, Blocks.grass);
		world.setBlock(i + 13, j + 0, k + 4, Blocks.dirt);
		world.setBlock(i + 13, j + 0, k + 5, Blocks.dirt);
		world.setBlock(i + 13, j + 0, k + 6, Blocks.dirt);
		world.setBlock(i + 13, j + 0, k + 7, Blocks.dirt);
		world.setBlock(i + 13, j + 0, k + 8, Blocks.dirt);
		world.setBlock(i + 13, j + 0, k + 9, Blocks.dirt);
		world.setBlock(i + 13, j + 0, k + 10, Blocks.dirt);
		world.setBlock(i + 13, j + 0, k + 11, Blocks.dirt);
		world.setBlock(i + 13, j + 0, k + 12, Blocks.dirt);
		world.setBlock(i + 13, j + 0, k + 13, Blocks.grass);
		world.setBlock(i + 13, j + 0, k + 14, Blocks.grass);
		world.setBlock(i + 13, j + 0, k + 15, Blocks.grass);
		world.setBlock(i + 13, j + 0, k + 16, Blocks.grass);
		world.setBlock(i + 13, j + 0, k + 17, Blocks.grass);
		world.setBlock(i + 13, j + 0, k + 18, Blocks.grass);
		world.setBlock(i + 13, j + 1, k + 0, Blocks.cobblestone_wall);
		world.setBlock(i + 13, j + 1, k + 4, Blocks.stonebrick);
		world.setBlock(i + 13, j + 1, k + 5, Blocks.stonebrick);
		world.setBlock(i + 13, j + 1, k + 6, Blocks.planks, 1, 0x02);
		world.setBlock(i + 13, j + 1, k + 7, Blocks.planks, 2, 0x02);
		world.setBlock(i + 13, j + 1, k + 8, Blocks.planks, 1, 0x02);
		world.setBlock(i + 13, j + 1, k + 9, Blocks.planks, 2, 0x02);
		world.setBlock(i + 13, j + 1, k + 10, Blocks.planks, 1, 0x02);
		world.setBlock(i + 13, j + 1, k + 11, Blocks.stonebrick);
		world.setBlock(i + 13, j + 1, k + 12, Blocks.stonebrick);
		world.setBlock(i + 13, j + 1, k + 18, Blocks.cobblestone_wall);
		world.setBlock(i + 13, j + 2, k + 0, Blocks.cobblestone_wall);
		world.setBlock(i + 13, j + 2, k + 5, Blocks.log, 1, 0x02);
		world.setBlock(i + 13, j + 2, k + 11, Blocks.log, 1, 0x02);
		world.setBlock(i + 13, j + 2, k + 18, Blocks.cobblestone_wall);
		world.setBlock(i + 13, j + 3, k + 0, Blocks.cobblestone_wall);
		world.setBlock(i + 13, j + 3, k + 5, Blocks.log, 1, 0x02);
		world.setBlock(i + 13, j + 3, k + 11, Blocks.log, 1, 0x02);
		world.setBlock(i + 13, j + 3, k + 18, Blocks.cobblestone_wall);
		world.setBlock(i + 13, j + 4, k + 0, Blocks.cobblestone_wall);
		world.setBlock(i + 13, j + 4, k + 5, Blocks.log, 1, 0x02);
		world.setBlock(i + 13, j + 4, k + 11, Blocks.log, 1, 0x02);
		world.setBlock(i + 13, j + 4, k + 18, Blocks.cobblestone_wall);
		world.setBlock(i + 13, j + 5, k + 5, Blocks.log, 1, 0x02);
		world.setBlock(i + 13, j + 5, k + 11, Blocks.log, 1, 0x02);
		world.setBlock(i + 13, j + 6, k + 4, Blocks.wooden_slab, 1, 0x02);
		world.setBlock(i + 13, j + 6, k + 5, Blocks.stonebrick, 2, 0x02);
		world.setBlock(i + 13, j + 6, k + 6, Blocks.fence);
		world.setBlock(i + 13, j + 6, k + 7, Blocks.fence);
		world.setBlock(i + 13, j + 6, k + 8, Blocks.fence);
		world.setBlock(i + 13, j + 6, k + 9, Blocks.fence);
		world.setBlock(i + 13, j + 6, k + 10, Blocks.fence);
		world.setBlock(i + 13, j + 6, k + 11, Blocks.stonebrick, 3, 0x02);
		world.setBlock(i + 13, j + 6, k + 12, Blocks.wooden_slab, 1, 0x02);
		world.setBlock(i + 13, j + 7, k + 6, Blocks.stonebrick, 2, 0x02);
		world.setBlock(i + 13, j + 7, k + 8, Blocks.fence);
		world.setBlock(i + 13, j + 7, k + 10, Blocks.stonebrick, 3, 0x02);
		world.setBlock(i + 13, j + 8, k + 7, Blocks.stonebrick, 2, 0x02);
		world.setBlock(i + 13, j + 8, k + 8, Blocks.fence);
		world.setBlock(i + 13, j + 8, k + 9, Blocks.stonebrick, 3, 0x02);
		world.setBlock(i + 13, j + 9, k + 8, Blocks.wooden_slab, 1, 0x02);
		world.setBlock(i + 14, j + 0, k + 0, Blocks.grass);
		world.setBlock(i + 14, j + 0, k + 1, Blocks.grass);
		world.setBlock(i + 14, j + 0, k + 2, Blocks.grass);
		world.setBlock(i + 14, j + 0, k + 3, Blocks.grass);
		world.setBlock(i + 14, j + 0, k + 4, Blocks.dirt);
		world.setBlock(i + 14, j + 0, k + 5, Blocks.dirt);
		world.setBlock(i + 14, j + 0, k + 6, Blocks.dirt);
		world.setBlock(i + 14, j + 0, k + 7, Blocks.dirt);
		world.setBlock(i + 14, j + 0, k + 8, Blocks.dirt);
		world.setBlock(i + 14, j + 0, k + 9, Blocks.dirt);
		world.setBlock(i + 14, j + 0, k + 10, Blocks.dirt);
		world.setBlock(i + 14, j + 0, k + 11, Blocks.dirt);
		world.setBlock(i + 14, j + 0, k + 12, Blocks.dirt);
		world.setBlock(i + 14, j + 0, k + 13, Blocks.grass);
		world.setBlock(i + 14, j + 0, k + 14, Blocks.farmland, 7, 0x02);
		world.setBlock(i + 14, j + 0, k + 15, Blocks.farmland, 7, 0x02);
		world.setBlock(i + 14, j + 0, k + 16, Blocks.farmland, 7, 0x02);
		world.setBlock(i + 14, j + 0, k + 17, Blocks.grass);
		world.setBlock(i + 14, j + 0, k + 18, Blocks.grass);
		world.setBlock(i + 14, j + 1, k + 0, Blocks.cobblestone_wall);
		world.setBlock(i + 14, j + 1, k + 4, Blocks.stonebrick);
		world.setBlock(i + 14, j + 1, k + 5, Blocks.stonebrick);
		world.setBlock(i + 14, j + 1, k + 6, Blocks.planks, 1, 0x02);
		world.setBlock(i + 14, j + 1, k + 7, Blocks.planks, 2, 0x02);
		world.setBlock(i + 14, j + 1, k + 8, Blocks.planks, 2, 0x02);
		world.setBlock(i + 14, j + 1, k + 9, Blocks.planks, 2, 0x02);
		world.setBlock(i + 14, j + 1, k + 10, Blocks.planks, 1, 0x02);
		world.setBlock(i + 14, j + 1, k + 11, Blocks.stonebrick);
		world.setBlock(i + 14, j + 1, k + 12, Blocks.stonebrick);
		world.setBlock(i + 14, j + 1, k + 18, Blocks.cobblestone_wall);
		world.setBlock(i + 14, j + 2, k + 0, Blocks.fence);
		world.setBlock(i + 14, j + 2, k + 5, Blocks.wool);
		world.setBlock(i + 14, j + 2, k + 11, Blocks.wool);
		world.setBlock(i + 14, j + 2, k + 18, Blocks.fence);
		world.setBlock(i + 14, j + 3, k + 0, Blocks.fence);
		world.setBlock(i + 14, j + 3, k + 5, Blocks.wool);
		world.setBlock(i + 14, j + 3, k + 11, Blocks.wool);
		world.setBlock(i + 14, j + 3, k + 18, Blocks.fence);
		world.setBlock(i + 14, j + 4, k + 5, Blocks.wool);
		world.setBlock(i + 14, j + 4, k + 11, Blocks.wool);
		world.setBlock(i + 14, j + 5, k + 5, Blocks.log, 5, 0x02);
		world.setBlock(i + 14, j + 5, k + 11, Blocks.log, 5, 0x02);
		world.setBlock(i + 14, j + 6, k + 4, Blocks.wooden_slab, 1, 0x02);
		world.setBlock(i + 14, j + 6, k + 5, Blocks.stonebrick, 2, 0x02);
		world.setBlock(i + 14, j + 6, k + 11, Blocks.stonebrick, 3, 0x02);
		world.setBlock(i + 14, j + 6, k + 12, Blocks.wooden_slab, 1, 0x02);
		world.setBlock(i + 14, j + 7, k + 6, Blocks.stonebrick, 2, 0x02);
		world.setBlock(i + 14, j + 7, k + 10, Blocks.stonebrick, 3, 0x02);
		world.setBlock(i + 14, j + 8, k + 7, Blocks.stonebrick, 2, 0x02);
		world.setBlock(i + 14, j + 8, k + 9, Blocks.stonebrick, 3, 0x02);
		world.setBlock(i + 14, j + 9, k + 8, Blocks.wooden_slab, 1, 0x02);
		world.setBlock(i + 15, j + 0, k + 0, Blocks.grass);
		world.setBlock(i + 15, j + 0, k + 1, Blocks.grass);
		world.setBlock(i + 15, j + 0, k + 2, Blocks.grass);
		world.setBlock(i + 15, j + 0, k + 3, Blocks.grass);
		world.setBlock(i + 15, j + 0, k + 4, Blocks.dirt);
		world.setBlock(i + 15, j + 0, k + 5, Blocks.dirt);
		world.setBlock(i + 15, j + 0, k + 6, Blocks.dirt);
		world.setBlock(i + 15, j + 0, k + 7, Blocks.dirt);
		world.setBlock(i + 15, j + 0, k + 8, Blocks.dirt);
		world.setBlock(i + 15, j + 0, k + 9, Blocks.dirt);
		world.setBlock(i + 15, j + 0, k + 10, Blocks.dirt);
		world.setBlock(i + 15, j + 0, k + 11, Blocks.dirt);
		world.setBlock(i + 15, j + 0, k + 12, Blocks.dirt);
		world.setBlock(i + 15, j + 0, k + 13, Blocks.grass);
		world.setBlock(i + 15, j + 0, k + 14, Blocks.farmland, 7, 0x02);
		world.setBlock(i + 15, j + 0, k + 16, Blocks.farmland, 7, 0x02);
		world.setBlock(i + 15, j + 0, k + 17, Blocks.grass);
		world.setBlock(i + 15, j + 0, k + 18, Blocks.grass);
		world.setBlock(i + 15, j + 1, k + 0, Blocks.cobblestone_wall);
		world.setBlock(i + 15, j + 1, k + 4, Blocks.stonebrick);
		world.setBlock(i + 15, j + 1, k + 5, Blocks.stonebrick);
		world.setBlock(i + 15, j + 1, k + 6, Blocks.planks, 1, 0x02);
		world.setBlock(i + 15, j + 1, k + 7, Blocks.planks, 1, 0x02);
		world.setBlock(i + 15, j + 1, k + 8, Blocks.planks, 1, 0x02);
		world.setBlock(i + 15, j + 1, k + 9, Blocks.planks, 1, 0x02);
		world.setBlock(i + 15, j + 1, k + 10, Blocks.planks, 1, 0x02);
		world.setBlock(i + 15, j + 1, k + 11, Blocks.stonebrick);
		world.setBlock(i + 15, j + 1, k + 12, Blocks.stonebrick);
		world.setBlock(i + 15, j + 1, k + 18, Blocks.cobblestone_wall);
		world.setBlock(i + 15, j + 2, k + 0, Blocks.fence);
		world.setBlock(i + 15, j + 2, k + 5, Blocks.wool);
		world.setBlock(i + 15, j + 2, k + 8, Blocks.fence);
		world.setBlock(i + 15, j + 2, k + 9, Blocks.furnace, 4, 0x02);
		world.setBlock(i + 15, j + 2, k + 10, Blocks.crafting_table);
		world.setBlock(i + 15, j + 2, k + 11, Blocks.wool);
		world.setBlock(i + 15, j + 2, k + 18, Blocks.fence);
		world.setBlock(i + 15, j + 3, k + 5, Blocks.wool);
		world.setBlock(i + 15, j + 3, k + 8, Blocks.fence);
		world.setBlock(i + 15, j + 3, k + 11, Blocks.wool);
		world.setBlock(i + 15, j + 4, k + 5, Blocks.wool);
		world.setBlock(i + 15, j + 4, k + 6, Blocks.fence);
		world.setBlock(i + 15, j + 4, k + 7, Blocks.fence);
		world.setBlock(i + 15, j + 4, k + 8, Blocks.fence);
		world.setBlock(i + 15, j + 4, k + 9, Blocks.fence);
		world.setBlock(i + 15, j + 4, k + 10, Blocks.fence);
		world.setBlock(i + 15, j + 4, k + 11, Blocks.wool);
		world.setBlock(i + 15, j + 5, k + 5, Blocks.log, 5, 0x02);
		world.setBlock(i + 15, j + 5, k + 6, Blocks.chest, 4, 0x02);
		world.setBlock(i + 15, j + 5, k + 7, Blocks.chest, 4, 0x02);
		world.setBlock(i + 15, j + 5, k + 9, Blocks.chest, 4, 0x02);
		world.setBlock(i + 15, j + 5, k + 10, Blocks.chest, 4, 0x02);
		world.setBlock(i + 15, j + 5, k + 11, Blocks.log, 5, 0x02);
		world.setBlock(i + 15, j + 6, k + 4, Blocks.wooden_slab, 1, 0x02);
		world.setBlock(i + 15, j + 6, k + 5, Blocks.stonebrick, 2, 0x02);
		world.setBlock(i + 15, j + 6, k + 11, Blocks.stonebrick, 3, 0x02);
		world.setBlock(i + 15, j + 6, k + 12, Blocks.wooden_slab, 1, 0x02);
		world.setBlock(i + 15, j + 7, k + 6, Blocks.stonebrick, 2, 0x02);
		world.setBlock(i + 15, j + 7, k + 10, Blocks.stonebrick, 3, 0x02);
		world.setBlock(i + 15, j + 8, k + 7, Blocks.stonebrick, 2, 0x02);
		world.setBlock(i + 15, j + 8, k + 9, Blocks.stonebrick, 3, 0x02);
		world.setBlock(i + 15, j + 9, k + 8, Blocks.wooden_slab, 1, 0x02);
		world.setBlock(i + 16, j + 0, k + 0, Blocks.grass);
		world.setBlock(i + 16, j + 0, k + 1, Blocks.grass);
		world.setBlock(i + 16, j + 0, k + 2, Blocks.grass);
		world.setBlock(i + 16, j + 0, k + 3, Blocks.grass);
		world.setBlock(i + 16, j + 0, k + 4, Blocks.dirt);
		world.setBlock(i + 16, j + 0, k + 5, Blocks.dirt);
		world.setBlock(i + 16, j + 0, k + 6, Blocks.dirt);
		world.setBlock(i + 16, j + 0, k + 7, Blocks.dirt);
		world.setBlock(i + 16, j + 0, k + 8, Blocks.dirt);
		world.setBlock(i + 16, j + 0, k + 9, Blocks.dirt);
		world.setBlock(i + 16, j + 0, k + 10, Blocks.dirt);
		world.setBlock(i + 16, j + 0, k + 11, Blocks.dirt);
		world.setBlock(i + 16, j + 0, k + 12, Blocks.dirt);
		world.setBlock(i + 16, j + 0, k + 13, Blocks.grass);
		world.setBlock(i + 16, j + 0, k + 14, Blocks.farmland, 7, 0x02);
		world.setBlock(i + 16, j + 0, k + 15, Blocks.farmland, 7, 0x02);
		world.setBlock(i + 16, j + 0, k + 16, Blocks.farmland, 7, 0x02);
		world.setBlock(i + 16, j + 0, k + 17, Blocks.grass);
		world.setBlock(i + 16, j + 0, k + 18, Blocks.grass);
		world.setBlock(i + 16, j + 1, k + 0, Blocks.cobblestone_wall);
		world.setBlock(i + 16, j + 1, k + 4, Blocks.stonebrick);
		world.setBlock(i + 16, j + 1, k + 5, Blocks.stonebrick);
		world.setBlock(i + 16, j + 1, k + 6, Blocks.stonebrick);
		world.setBlock(i + 16, j + 1, k + 7, Blocks.stonebrick);
		world.setBlock(i + 16, j + 1, k + 8, Blocks.stonebrick);
		world.setBlock(i + 16, j + 1, k + 9, Blocks.stonebrick);
		world.setBlock(i + 16, j + 1, k + 10, Blocks.stonebrick);
		world.setBlock(i + 16, j + 1, k + 11, Blocks.stonebrick);
		world.setBlock(i + 16, j + 1, k + 12, Blocks.stonebrick);
		world.setBlock(i + 16, j + 1, k + 18, Blocks.cobblestone_wall);
		world.setBlock(i + 16, j + 2, k + 0, Blocks.fence);
		world.setBlock(i + 16, j + 2, k + 5, Blocks.log, 1, 0x02);
		world.setBlock(i + 16, j + 2, k + 6, Blocks.wool);
		world.setBlock(i + 16, j + 2, k + 7, Blocks.wool);
		world.setBlock(i + 16, j + 2, k + 8, Blocks.wool);
		world.setBlock(i + 16, j + 2, k + 9, Blocks.wool);
		world.setBlock(i + 16, j + 2, k + 10, Blocks.wool);
		world.setBlock(i + 16, j + 2, k + 11, Blocks.log, 1, 0x02);
		world.setBlock(i + 16, j + 2, k + 18, Blocks.fence);
		world.setBlock(i + 16, j + 3, k + 5, Blocks.log, 1, 0x02);
		world.setBlock(i + 16, j + 3, k + 6, Blocks.wool);
		world.setBlock(i + 16, j + 3, k + 7, Blocks.wool);
		world.setBlock(i + 16, j + 3, k + 8, Blocks.wool);
		world.setBlock(i + 16, j + 3, k + 9, Blocks.wool);
		world.setBlock(i + 16, j + 3, k + 10, Blocks.wool);
		world.setBlock(i + 16, j + 3, k + 11, Blocks.log, 1, 0x02);
		world.setBlock(i + 16, j + 4, k + 5, Blocks.log, 1, 0x02);
		world.setBlock(i + 16, j + 4, k + 6, Blocks.wool);
		world.setBlock(i + 16, j + 4, k + 7, Blocks.wool);
		world.setBlock(i + 16, j + 4, k + 8, Blocks.wool);
		world.setBlock(i + 16, j + 4, k + 9, Blocks.wool);
		world.setBlock(i + 16, j + 4, k + 10, Blocks.wool);
		world.setBlock(i + 16, j + 4, k + 11, Blocks.log, 1, 0x02);
		world.setBlock(i + 16, j + 5, k + 5, Blocks.log, 1, 0x02);
		world.setBlock(i + 16, j + 5, k + 6, Blocks.log, 9, 0x02);
		world.setBlock(i + 16, j + 5, k + 7, Blocks.wool);
		world.setBlock(i + 16, j + 5, k + 8, Blocks.stone_stairs);
		world.setBlock(i + 16, j + 5, k + 9, Blocks.wool);
		world.setBlock(i + 16, j + 5, k + 10, Blocks.log, 9, 0x02);
		world.setBlock(i + 16, j + 5, k + 11, Blocks.log, 1, 0x02);
		world.setBlock(i + 16, j + 6, k + 4, Blocks.wooden_slab, 1, 0x02);
		world.setBlock(i + 16, j + 6, k + 5, Blocks.stonebrick, 1, 0x02);
		world.setBlock(i + 16, j + 6, k + 6, Blocks.log, 1, 0x02);
		world.setBlock(i + 16, j + 6, k + 7, Blocks.log, 9, 0x02);
		world.setBlock(i + 16, j + 6, k + 8, Blocks.fence);
		world.setBlock(i + 16, j + 6, k + 9, Blocks.log, 9, 0x02);
		world.setBlock(i + 16, j + 6, k + 10, Blocks.log, 1, 0x02);
		world.setBlock(i + 16, j + 6, k + 11, Blocks.stonebrick, 1, 0x02);
		world.setBlock(i + 16, j + 6, k + 12, Blocks.wooden_slab, 1, 0x02);
		world.setBlock(i + 16, j + 7, k + 6, Blocks.stonebrick, 2, 0x02);
		world.setBlock(i + 16, j + 7, k + 7, Blocks.log, 1, 0x02);
		world.setBlock(i + 16, j + 7, k + 8, Blocks.log, 9, 0x02);
		world.setBlock(i + 16, j + 7, k + 9, Blocks.log, 1, 0x02);
		world.setBlock(i + 16, j + 7, k + 10, Blocks.stonebrick, 3, 0x02);
		world.setBlock(i + 16, j + 8, k + 7, Blocks.stonebrick, 2, 0x02);
		world.setBlock(i + 16, j + 8, k + 8, Blocks.log, 1, 0x02);
		world.setBlock(i + 16, j + 8, k + 9, Blocks.stonebrick, 3, 0x02);
		world.setBlock(i + 16, j + 9, k + 8, Blocks.wooden_slab, 1, 0x02);
		world.setBlock(i + 17, j + 0, k + 0, Blocks.grass);
		world.setBlock(i + 17, j + 0, k + 1, Blocks.grass);
		world.setBlock(i + 17, j + 0, k + 2, Blocks.grass);
		world.setBlock(i + 17, j + 0, k + 3, Blocks.grass);
		world.setBlock(i + 17, j + 0, k + 4, Blocks.dirt);
		world.setBlock(i + 17, j + 0, k + 5, Blocks.dirt);
		world.setBlock(i + 17, j + 0, k + 6, Blocks.dirt);
		world.setBlock(i + 17, j + 0, k + 7, Blocks.dirt);
		world.setBlock(i + 17, j + 0, k + 8, Blocks.dirt);
		world.setBlock(i + 17, j + 0, k + 9, Blocks.dirt);
		world.setBlock(i + 17, j + 0, k + 10, Blocks.dirt);
		world.setBlock(i + 17, j + 0, k + 11, Blocks.dirt);
		world.setBlock(i + 17, j + 0, k + 12, Blocks.dirt);
		world.setBlock(i + 17, j + 0, k + 13, Blocks.grass);
		world.setBlock(i + 17, j + 0, k + 14, Blocks.farmland, 7, 0x02);
		world.setBlock(i + 17, j + 0, k + 15, Blocks.farmland, 7, 0x02);
		world.setBlock(i + 17, j + 0, k + 16, Blocks.grass);
		world.setBlock(i + 17, j + 0, k + 17, Blocks.grass);
		world.setBlock(i + 17, j + 0, k + 18, Blocks.grass);
		world.setBlock(i + 17, j + 1, k + 0, Blocks.cobblestone_wall);
		world.setBlock(i + 17, j + 1, k + 4, Blocks.stonebrick);
		world.setBlock(i + 17, j + 1, k + 5, Blocks.stonebrick);
		world.setBlock(i + 17, j + 1, k + 6, Blocks.stonebrick);
		world.setBlock(i + 17, j + 1, k + 7, Blocks.stonebrick);
		world.setBlock(i + 17, j + 1, k + 8, Blocks.stonebrick);
		world.setBlock(i + 17, j + 1, k + 9, Blocks.stonebrick);
		world.setBlock(i + 17, j + 1, k + 10, Blocks.stonebrick);
		world.setBlock(i + 17, j + 1, k + 11, Blocks.stonebrick);
		world.setBlock(i + 17, j + 1, k + 12, Blocks.stonebrick);
		world.setBlock(i + 17, j + 1, k + 18, Blocks.cobblestone_wall);
		world.setBlock(i + 17, j + 2, k + 0, Blocks.fence);
		world.setBlock(i + 17, j + 2, k + 4, Blocks.fence);
		world.setBlock(i + 17, j + 2, k + 12, Blocks.fence);
		world.setBlock(i + 17, j + 2, k + 18, Blocks.fence);
		world.setBlock(i + 17, j + 3, k + 4, Blocks.fence);
		world.setBlock(i + 17, j + 3, k + 12, Blocks.fence);
		world.setBlock(i + 17, j + 4, k + 4, Blocks.fence);
		world.setBlock(i + 17, j + 4, k + 12, Blocks.fence);
		world.setBlock(i + 17, j + 5, k + 4, Blocks.fence);
		world.setBlock(i + 17, j + 5, k + 12, Blocks.fence);
		world.setBlock(i + 17, j + 6, k + 4, Blocks.wooden_slab, 1, 0x02);
		world.setBlock(i + 17, j + 6, k + 5, Blocks.wooden_slab, 1, 0x02);
		world.setBlock(i + 17, j + 6, k + 6, Blocks.wooden_slab, 1, 0x02);
		world.setBlock(i + 17, j + 6, k + 7, Blocks.wooden_slab, 1, 0x02);
		world.setBlock(i + 17, j + 6, k + 8, Blocks.wooden_slab, 1, 0x02);
		world.setBlock(i + 17, j + 6, k + 9, Blocks.wooden_slab, 1, 0x02);
		world.setBlock(i + 17, j + 6, k + 10, Blocks.wooden_slab, 1, 0x02);
		world.setBlock(i + 17, j + 6, k + 11, Blocks.wooden_slab, 1, 0x02);
		world.setBlock(i + 17, j + 6, k + 12, Blocks.wooden_slab, 1, 0x02);
		world.setBlock(i + 17, j + 7, k + 1, Blocks.leaves, 1, 0x02);
		world.setBlock(i + 17, j + 7, k + 2, Blocks.leaves, 1, 0x02);
		world.setBlock(i + 17, j + 7, k + 3, Blocks.leaves, 1, 0x02);
		world.setBlock(i + 17, j + 8, k + 8, Blocks.fence);
		world.setBlock(i + 17, j + 9, k + 1, Blocks.leaves, 1, 0x02);
		world.setBlock(i + 17, j + 9, k + 2, Blocks.leaves, 1, 0x02);
		world.setBlock(i + 17, j + 9, k + 3, Blocks.leaves, 1, 0x02);
		world.setBlock(i + 17, j + 9, k + 8, Blocks.fence);
		world.setBlock(i + 17, j + 11, k + 1, Blocks.leaves, 1, 0x02);
		world.setBlock(i + 17, j + 11, k + 2, Blocks.leaves, 1, 0x02);
		world.setBlock(i + 17, j + 11, k + 3, Blocks.leaves, 1, 0x02);
		world.setBlock(i + 18, j + 0, k + 0, Blocks.grass);
		world.setBlock(i + 18, j + 0, k + 1, Blocks.grass);
		world.setBlock(i + 18, j + 0, k + 2, Blocks.grass);
		world.setBlock(i + 18, j + 0, k + 3, Blocks.grass);
		world.setBlock(i + 18, j + 0, k + 4, Blocks.grass);
		world.setBlock(i + 18, j + 0, k + 5, Blocks.grass);
		world.setBlock(i + 18, j + 0, k + 6, Blocks.grass);
		world.setBlock(i + 18, j + 0, k + 7, Blocks.grass);
		world.setBlock(i + 18, j + 0, k + 8, Blocks.grass);
		world.setBlock(i + 18, j + 0, k + 9, Blocks.grass);
		world.setBlock(i + 18, j + 0, k + 10, Blocks.grass);
		world.setBlock(i + 18, j + 0, k + 11, Blocks.grass);
		world.setBlock(i + 18, j + 0, k + 12, Blocks.grass);
		world.setBlock(i + 18, j + 0, k + 13, Blocks.grass);
		world.setBlock(i + 18, j + 0, k + 14, Blocks.farmland, 7, 0x02);
		world.setBlock(i + 18, j + 0, k + 16, Blocks.farmland, 7, 0x02);
		world.setBlock(i + 18, j + 0, k + 17, Blocks.grass);
		world.setBlock(i + 18, j + 0, k + 18, Blocks.grass);
		world.setBlock(i + 18, j + 1, k + 0, Blocks.cobblestone_wall);
		world.setBlock(i + 18, j + 1, k + 18, Blocks.cobblestone_wall);
		world.setBlock(i + 18, j + 2, k + 0, Blocks.fence);
		world.setBlock(i + 18, j + 2, k + 18, Blocks.fence);
		world.setBlock(i + 18, j + 7, k + 0, Blocks.leaves, 1, 0x02);
		world.setBlock(i + 18, j + 7, k + 1, Blocks.leaves, 1, 0x02);
		world.setBlock(i + 18, j + 7, k + 2, Blocks.leaves, 1, 0x02);
		world.setBlock(i + 18, j + 7, k + 3, Blocks.leaves, 1, 0x02);
		world.setBlock(i + 18, j + 7, k + 4, Blocks.leaves, 1, 0x02);
		world.setBlock(i + 18, j + 8, k + 2, Blocks.leaves, 1, 0x02);
		world.setBlock(i + 18, j + 9, k + 0, Blocks.leaves, 1, 0x02);
		world.setBlock(i + 18, j + 9, k + 1, Blocks.leaves, 1, 0x02);
		world.setBlock(i + 18, j + 9, k + 2, Blocks.leaves, 1, 0x02);
		world.setBlock(i + 18, j + 9, k + 3, Blocks.leaves, 1, 0x02);
		world.setBlock(i + 18, j + 9, k + 4, Blocks.leaves, 1, 0x02);
		world.setBlock(i + 18, j + 9, k + 8, Blocks.fence);
		world.setBlock(i + 18, j + 10, k + 2, Blocks.leaves, 1, 0x02);
		world.setBlock(i + 18, j + 11, k + 0, Blocks.leaves, 1, 0x02);
		world.setBlock(i + 18, j + 11, k + 1, Blocks.leaves, 1, 0x02);
		world.setBlock(i + 18, j + 11, k + 2, Blocks.leaves, 1, 0x02);
		world.setBlock(i + 18, j + 11, k + 3, Blocks.leaves, 1, 0x02);
		world.setBlock(i + 18, j + 11, k + 4, Blocks.leaves, 1, 0x02);
		world.setBlock(i + 18, j + 12, k + 2, Blocks.leaves, 1, 0x02);
		world.setBlock(i + 18, j + 14, k + 2, Blocks.leaves, 1, 0x02);
		world.setBlock(i + 19, j + 0, k + 0, Blocks.grass);
		world.setBlock(i + 19, j + 0, k + 1, Blocks.grass);
		world.setBlock(i + 19, j + 0, k + 2, Blocks.dirt);
		world.setBlock(i + 19, j + 0, k + 3, Blocks.grass);
		world.setBlock(i + 19, j + 0, k + 4, Blocks.grass);
		world.setBlock(i + 19, j + 0, k + 5, Blocks.grass);
		world.setBlock(i + 19, j + 0, k + 6, Blocks.grass);
		world.setBlock(i + 19, j + 0, k + 7, Blocks.grass);
		world.setBlock(i + 19, j + 0, k + 8, Blocks.grass);
		world.setBlock(i + 19, j + 0, k + 9, Blocks.grass);
		world.setBlock(i + 19, j + 0, k + 10, Blocks.grass);
		world.setBlock(i + 19, j + 0, k + 11, Blocks.grass);
		world.setBlock(i + 19, j + 0, k + 12, Blocks.grass);
		world.setBlock(i + 19, j + 0, k + 13, Blocks.grass);
		world.setBlock(i + 19, j + 0, k + 14, Blocks.farmland, 7, 0x02);
		world.setBlock(i + 19, j + 0, k + 15, Blocks.farmland, 7, 0x02);
		world.setBlock(i + 19, j + 0, k + 16, Blocks.farmland, 7, 0x02);
		world.setBlock(i + 19, j + 0, k + 17, Blocks.grass);
		world.setBlock(i + 19, j + 0, k + 18, Blocks.grass);
		world.setBlock(i + 19, j + 1, k + 0, Blocks.cobblestone_wall);
		world.setBlock(i + 19, j + 1, k + 2, Blocks.log, 1, 0x02);
		world.setBlock(i + 19, j + 1, k + 18, Blocks.cobblestone_wall);
		world.setBlock(i + 19, j + 2, k + 0, Blocks.fence);
		world.setBlock(i + 19, j + 2, k + 2, Blocks.log, 1, 0x02);
		world.setBlock(i + 19, j + 2, k + 18, Blocks.fence);
		world.setBlock(i + 19, j + 3, k + 2, Blocks.log, 1, 0x02);
		world.setBlock(i + 19, j + 4, k + 2, Blocks.log, 1, 0x02);
		world.setBlock(i + 19, j + 5, k + 2, Blocks.log, 1, 0x02);
		world.setBlock(i + 19, j + 6, k + 2, Blocks.log, 1, 0x02);
		world.setBlock(i + 19, j + 7, k + 0, Blocks.leaves, 1, 0x02);
		world.setBlock(i + 19, j + 7, k + 1, Blocks.leaves, 1, 0x02);
		world.setBlock(i + 19, j + 7, k + 2, Blocks.log, 1, 0x02);
		world.setBlock(i + 19, j + 7, k + 3, Blocks.leaves, 1, 0x02);
		world.setBlock(i + 19, j + 7, k + 4, Blocks.leaves, 1, 0x02);
		world.setBlock(i + 19, j + 8, k + 1, Blocks.leaves, 1, 0x02);
		world.setBlock(i + 19, j + 8, k + 2, Blocks.log, 1, 0x02);
		world.setBlock(i + 19, j + 8, k + 3, Blocks.leaves, 1, 0x02);
		world.setBlock(i + 19, j + 9, k + 0, Blocks.leaves, 1, 0x02);
		world.setBlock(i + 19, j + 9, k + 1, Blocks.leaves, 1, 0x02);
		world.setBlock(i + 19, j + 9, k + 2, Blocks.log, 1, 0x02);
		world.setBlock(i + 19, j + 9, k + 3, Blocks.leaves, 1, 0x02);
		world.setBlock(i + 19, j + 9, k + 4, Blocks.leaves, 1, 0x02);
		world.setBlock(i + 19, j + 10, k + 1, Blocks.leaves, 1, 0x02);
		world.setBlock(i + 19, j + 10, k + 2, Blocks.log, 1, 0x02);
		world.setBlock(i + 19, j + 10, k + 3, Blocks.leaves, 1, 0x02);
		world.setBlock(i + 19, j + 11, k + 0, Blocks.leaves, 1, 0x02);
		world.setBlock(i + 19, j + 11, k + 1, Blocks.leaves, 1, 0x02);
		world.setBlock(i + 19, j + 11, k + 2, Blocks.log, 1, 0x02);
		world.setBlock(i + 19, j + 11, k + 3, Blocks.leaves, 1, 0x02);
		world.setBlock(i + 19, j + 11, k + 4, Blocks.leaves, 1, 0x02);
		world.setBlock(i + 19, j + 12, k + 1, Blocks.leaves, 1, 0x02);
		world.setBlock(i + 19, j + 12, k + 2, Blocks.log, 1, 0x02);
		world.setBlock(i + 19, j + 12, k + 3, Blocks.leaves, 1, 0x02);
		world.setBlock(i + 19, j + 13, k + 2, Blocks.leaves, 1, 0x02);
		world.setBlock(i + 19, j + 14, k + 1, Blocks.leaves, 1, 0x02);
		world.setBlock(i + 19, j + 14, k + 2, Blocks.leaves, 1, 0x02);
		world.setBlock(i + 19, j + 14, k + 3, Blocks.leaves, 1, 0x02);
		world.setBlock(i + 20, j + 0, k + 0, Blocks.grass);
		world.setBlock(i + 20, j + 0, k + 1, Blocks.grass);
		world.setBlock(i + 20, j + 0, k + 2, Blocks.grass);
		world.setBlock(i + 20, j + 0, k + 3, Blocks.grass);
		world.setBlock(i + 20, j + 0, k + 4, Blocks.grass);
		world.setBlock(i + 20, j + 0, k + 5, Blocks.grass);
		world.setBlock(i + 20, j + 0, k + 6, Blocks.grass);
		world.setBlock(i + 20, j + 0, k + 7, Blocks.grass);
		world.setBlock(i + 20, j + 0, k + 8, Blocks.grass);
		world.setBlock(i + 20, j + 0, k + 9, Blocks.grass);
		world.setBlock(i + 20, j + 0, k + 10, Blocks.grass);
		world.setBlock(i + 20, j + 0, k + 11, Blocks.grass);
		world.setBlock(i + 20, j + 0, k + 12, Blocks.grass);
		world.setBlock(i + 20, j + 0, k + 13, Blocks.grass);
		world.setBlock(i + 20, j + 0, k + 14, Blocks.grass);
		world.setBlock(i + 20, j + 0, k + 15, Blocks.grass);
		world.setBlock(i + 20, j + 0, k + 16, Blocks.grass);
		world.setBlock(i + 20, j + 0, k + 17, Blocks.grass);
		world.setBlock(i + 20, j + 0, k + 18, Blocks.grass);
		world.setBlock(i + 20, j + 1, k + 0, Blocks.cobblestone_wall);
		world.setBlock(i + 20, j + 1, k + 18, Blocks.cobblestone_wall);
		world.setBlock(i + 20, j + 2, k + 0, Blocks.fence);
		world.setBlock(i + 20, j + 2, k + 18, Blocks.fence);
		world.setBlock(i + 20, j + 3, k + 0, Blocks.fence);
		world.setBlock(i + 20, j + 3, k + 18, Blocks.fence);
		world.setBlock(i + 20, j + 7, k + 0, Blocks.leaves, 1, 0x02);
		world.setBlock(i + 20, j + 7, k + 1, Blocks.leaves, 1, 0x02);
		world.setBlock(i + 20, j + 7, k + 2, Blocks.leaves, 1, 0x02);
		world.setBlock(i + 20, j + 7, k + 3, Blocks.leaves, 1, 0x02);
		world.setBlock(i + 20, j + 7, k + 4, Blocks.leaves, 1, 0x02);
		world.setBlock(i + 20, j + 8, k + 2, Blocks.leaves, 1, 0x02);
		world.setBlock(i + 20, j + 9, k + 0, Blocks.leaves, 1, 0x02);
		world.setBlock(i + 20, j + 9, k + 1, Blocks.leaves, 1, 0x02);
		world.setBlock(i + 20, j + 9, k + 2, Blocks.leaves, 1, 0x02);
		world.setBlock(i + 20, j + 9, k + 3, Blocks.leaves, 1, 0x02);
		world.setBlock(i + 20, j + 9, k + 4, Blocks.leaves, 1, 0x02);
		world.setBlock(i + 20, j + 10, k + 2, Blocks.leaves, 1, 0x02);
		world.setBlock(i + 20, j + 11, k + 0, Blocks.leaves, 1, 0x02);
		world.setBlock(i + 20, j + 11, k + 1, Blocks.leaves, 1, 0x02);
		world.setBlock(i + 20, j + 11, k + 2, Blocks.leaves, 1, 0x02);
		world.setBlock(i + 20, j + 11, k + 3, Blocks.leaves, 1, 0x02);
		world.setBlock(i + 20, j + 11, k + 4, Blocks.leaves, 1, 0x02);
		world.setBlock(i + 20, j + 12, k + 2, Blocks.leaves, 1, 0x02);
		world.setBlock(i + 20, j + 14, k + 2, Blocks.leaves, 1, 0x02);
		world.setBlock(i + 21, j + 0, k + 0, Blocks.grass);
		world.setBlock(i + 21, j + 0, k + 1, Blocks.grass);
		world.setBlock(i + 21, j + 0, k + 2, Blocks.grass);
		world.setBlock(i + 21, j + 0, k + 3, Blocks.grass);
		world.setBlock(i + 21, j + 0, k + 4, Blocks.grass);
		world.setBlock(i + 21, j + 0, k + 5, Blocks.grass);
		world.setBlock(i + 21, j + 0, k + 6, Blocks.grass);
		world.setBlock(i + 21, j + 0, k + 7, Blocks.grass);
		world.setBlock(i + 21, j + 0, k + 8, Blocks.grass);
		world.setBlock(i + 21, j + 0, k + 9, Blocks.grass);
		world.setBlock(i + 21, j + 0, k + 10, Blocks.grass);
		world.setBlock(i + 21, j + 0, k + 11, Blocks.grass);
		world.setBlock(i + 21, j + 0, k + 12, Blocks.grass);
		world.setBlock(i + 21, j + 0, k + 13, Blocks.grass);
		world.setBlock(i + 21, j + 0, k + 14, Blocks.grass);
		world.setBlock(i + 21, j + 0, k + 15, Blocks.grass);
		world.setBlock(i + 21, j + 0, k + 16, Blocks.grass);
		world.setBlock(i + 21, j + 0, k + 17, Blocks.grass);
		world.setBlock(i + 21, j + 0, k + 18, Blocks.grass);
		world.setBlock(i + 21, j + 1, k + 0, Blocks.cobblestone_wall);
		world.setBlock(i + 21, j + 1, k + 1, Blocks.cobblestone_wall);
		world.setBlock(i + 21, j + 1, k + 2, Blocks.cobblestone_wall);
		world.setBlock(i + 21, j + 1, k + 3, Blocks.cobblestone_wall);
		world.setBlock(i + 21, j + 1, k + 4, Blocks.cobblestone_wall);
		world.setBlock(i + 21, j + 1, k + 5, Blocks.cobblestone_wall);
		world.setBlock(i + 21, j + 1, k + 6, Blocks.cobblestone_wall);
		world.setBlock(i + 21, j + 1, k + 7, Blocks.cobblestone_wall);
		world.setBlock(i + 21, j + 1, k + 8, Blocks.cobblestone_wall);
		world.setBlock(i + 21, j + 1, k + 9, Blocks.cobblestone_wall);
		world.setBlock(i + 21, j + 1, k + 10, Blocks.cobblestone_wall);
		world.setBlock(i + 21, j + 1, k + 11, Blocks.cobblestone_wall);
		world.setBlock(i + 21, j + 1, k + 12, Blocks.cobblestone_wall);
		world.setBlock(i + 21, j + 1, k + 13, Blocks.cobblestone_wall);
		world.setBlock(i + 21, j + 1, k + 14, Blocks.cobblestone_wall);
		world.setBlock(i + 21, j + 1, k + 15, Blocks.cobblestone_wall);
		world.setBlock(i + 21, j + 1, k + 16, Blocks.cobblestone_wall);
		world.setBlock(i + 21, j + 1, k + 17, Blocks.cobblestone_wall);
		world.setBlock(i + 21, j + 1, k + 18, Blocks.cobblestone_wall);
		world.setBlock(i + 21, j + 2, k + 0, Blocks.cobblestone_wall);
		world.setBlock(i + 21, j + 2, k + 1, Blocks.fence);
		world.setBlock(i + 21, j + 2, k + 2, Blocks.fence);
		world.setBlock(i + 21, j + 2, k + 3, Blocks.fence);
		world.setBlock(i + 21, j + 2, k + 4, Blocks.fence);
		world.setBlock(i + 21, j + 2, k + 5, Blocks.fence);
		world.setBlock(i + 21, j + 2, k + 6, Blocks.fence);
		world.setBlock(i + 21, j + 2, k + 7, Blocks.fence);
		world.setBlock(i + 21, j + 2, k + 8, Blocks.fence);
		world.setBlock(i + 21, j + 2, k + 9, Blocks.fence);
		world.setBlock(i + 21, j + 2, k + 10, Blocks.fence);
		world.setBlock(i + 21, j + 2, k + 11, Blocks.fence);
		world.setBlock(i + 21, j + 2, k + 12, Blocks.fence);
		world.setBlock(i + 21, j + 2, k + 13, Blocks.fence);
		world.setBlock(i + 21, j + 2, k + 14, Blocks.fence);
		world.setBlock(i + 21, j + 2, k + 15, Blocks.fence);
		world.setBlock(i + 21, j + 2, k + 16, Blocks.fence);
		world.setBlock(i + 21, j + 2, k + 17, Blocks.fence);
		world.setBlock(i + 21, j + 2, k + 18, Blocks.cobblestone_wall);
		world.setBlock(i + 21, j + 3, k + 0, Blocks.cobblestone_wall);
		world.setBlock(i + 21, j + 3, k + 1, Blocks.fence);
		world.setBlock(i + 21, j + 3, k + 17, Blocks.fence);
		world.setBlock(i + 21, j + 3, k + 18, Blocks.cobblestone_wall);
		world.setBlock(i + 21, j + 7, k + 1, Blocks.leaves, 1, 0x02);
		world.setBlock(i + 21, j + 7, k + 2, Blocks.leaves, 1, 0x02);
		world.setBlock(i + 21, j + 7, k + 3, Blocks.leaves, 1, 0x02);
		world.setBlock(i + 21, j + 9, k + 1, Blocks.leaves, 1, 0x02);
		world.setBlock(i + 21, j + 9, k + 2, Blocks.leaves, 1, 0x02);
		world.setBlock(i + 21, j + 9, k + 3, Blocks.leaves, 1, 0x02);
		world.setBlock(i + 21, j + 11, k + 1, Blocks.leaves, 1, 0x02);
		world.setBlock(i + 21, j + 11, k + 2, Blocks.leaves, 1, 0x02);
		world.setBlock(i + 21, j + 11, k + 3, Blocks.leaves, 1, 0x02);
		world.setBlock(i + 0, j + 4, k + 0, Blocks.torch, 5, 0x02);
		world.setBlock(i + 0, j + 4, k + 18, Blocks.torch, 5, 0x02);
		world.setBlock(i + 1, j + 1, k + 2, Blocks.tallgrass, 1, 0x02);
		world.setBlock(i + 1, j + 1, k + 3, Blocks.tallgrass, 1, 0x02);
		world.setBlock(i + 1, j + 1, k + 4, Blocks.tallgrass, 1, 0x02);
		world.setBlock(i + 1, j + 1, k + 5, Blocks.tallgrass, 1, 0x02);
		world.setBlock(i + 1, j + 1, k + 8, Blocks.tallgrass, 1, 0x02);
		world.setBlock(i + 1, j + 1, k + 9, Blocks.tallgrass, 1, 0x02);
		world.setBlock(i + 1, j + 1, k + 10, Blocks.yellow_flower);
		world.setBlock(i + 1, j + 1, k + 11, Blocks.yellow_flower);
		world.setBlock(i + 1, j + 1, k + 12, Blocks.tallgrass, 1, 0x02);
		world.setBlock(i + 1, j + 1, k + 14, Blocks.tallgrass, 1, 0x02);
		world.setBlock(i + 1, j + 1, k + 15, Blocks.tallgrass, 1, 0x02);
		world.setBlock(i + 1, j + 1, k + 16, Blocks.tallgrass, 1, 0x02);
		world.setBlock(i + 1, j + 1, k + 17, Blocks.tallgrass, 1, 0x02);
		world.setBlock(i + 2, j + 1, k + 1, Blocks.tallgrass, 1, 0x02);
		world.setBlock(i + 2, j + 1, k + 3, Blocks.tallgrass, 1, 0x02);
		world.setBlock(i + 2, j + 1, k + 4, Blocks.tallgrass, 1, 0x02);
		world.setBlock(i + 2, j + 1, k + 6, Blocks.tallgrass, 1, 0x02);
		world.setBlock(i + 2, j + 1, k + 7, Blocks.tallgrass, 1, 0x02);
		world.setBlock(i + 2, j + 1, k + 8, Blocks.tallgrass, 1, 0x02);
		world.setBlock(i + 2, j + 1, k + 9, Blocks.tallgrass, 1, 0x02);
		world.setBlock(i + 2, j + 1, k + 10, Blocks.tallgrass, 1, 0x02);
		world.setBlock(i + 2, j + 1, k + 11, Blocks.tallgrass, 1, 0x02);
		world.setBlock(i + 2, j + 1, k + 12, Blocks.tallgrass, 1, 0x02);
		world.setBlock(i + 2, j + 1, k + 13, Blocks.tallgrass, 1, 0x02);
		world.setBlock(i + 2, j + 1, k + 14, Blocks.wheat, 7, 0x02);
		world.setBlock(i + 2, j + 1, k + 15, Blocks.wheat, 7, 0x02);
		world.setBlock(i + 2, j + 1, k + 16, Blocks.wheat, 7, 0x02);
		world.setBlock(i + 2, j + 1, k + 17, Blocks.tallgrass, 1, 0x02);
		world.setBlock(i + 3, j + 0, k + 15, Blocks.water);
		world.setBlock(i + 3, j + 1, k + 1, Blocks.tallgrass, 1, 0x02);
		world.setBlock(i + 3, j + 1, k + 2, Blocks.tallgrass, 1, 0x02);
		world.setBlock(i + 3, j + 1, k + 3, Blocks.tallgrass, 1, 0x02);
		world.setBlock(i + 3, j + 1, k + 4, Blocks.tallgrass, 1, 0x02);
		world.setBlock(i + 3, j + 1, k + 5, Blocks.tallgrass, 1, 0x02);
		world.setBlock(i + 3, j + 1, k + 7, Blocks.tallgrass, 1, 0x02);
		world.setBlock(i + 3, j + 1, k + 8, Blocks.tallgrass, 1, 0x02);
		world.setBlock(i + 3, j + 1, k + 12, Blocks.tallgrass, 1, 0x02);
		world.setBlock(i + 3, j + 1, k + 13, Blocks.tallgrass, 1, 0x02);
		world.setBlock(i + 3, j + 1, k + 14, Blocks.wheat, 7, 0x02);
		world.setBlock(i + 3, j + 1, k + 16, Blocks.wheat, 7, 0x02);
		world.setBlock(i + 3, j + 1, k + 17, Blocks.tallgrass, 1, 0x02);
		world.setBlock(i + 4, j + 1, k + 1, Blocks.yellow_flower);
		world.setBlock(i + 4, j + 1, k + 2, Blocks.tallgrass, 1, 0x02);
		world.setBlock(i + 4, j + 1, k + 3, Blocks.tallgrass, 1, 0x02);
		world.setBlock(i + 4, j + 1, k + 13, Blocks.tallgrass, 1, 0x02);
		world.setBlock(i + 4, j + 1, k + 14, Blocks.wheat, 7, 0x02);
		world.setBlock(i + 4, j + 1, k + 15, Blocks.wheat, 7, 0x02);
		world.setBlock(i + 4, j + 1, k + 16, Blocks.wheat, 7, 0x02);
		world.setBlock(i + 4, j + 1, k + 17, Blocks.tallgrass, 1, 0x02);
		world.setBlock(i + 5, j + 1, k + 1, Blocks.tallgrass, 1, 0x02);
		world.setBlock(i + 5, j + 1, k + 2, Blocks.tallgrass, 1, 0x02);
		world.setBlock(i + 5, j + 1, k + 3, Blocks.tallgrass, 1, 0x02);
		world.setBlock(i + 5, j + 1, k + 13, Blocks.tallgrass, 1, 0x02);
		world.setBlock(i + 5, j + 1, k + 14, Blocks.wheat, 7, 0x02);
		world.setBlock(i + 5, j + 1, k + 15, Blocks.wheat, 7, 0x02);
		world.setBlock(i + 5, j + 1, k + 16, Blocks.wheat, 7, 0x02);
		world.setBlock(i + 5, j + 1, k + 17, Blocks.tallgrass, 1, 0x02);
		world.setBlock(i + 6, j + 0, k + 15, Blocks.water);
		world.setBlock(i + 6, j + 1, k + 1, Blocks.tallgrass, 1, 0x02);
		world.setBlock(i + 6, j + 1, k + 2, Blocks.tallgrass, 1, 0x02);
		world.setBlock(i + 6, j + 1, k + 3, Blocks.yellow_flower);
		world.setBlock(i + 6, j + 1, k + 13, Blocks.tallgrass, 1, 0x02);
		world.setBlock(i + 6, j + 1, k + 14, Blocks.wheat, 7, 0x02);
		world.setBlock(i + 6, j + 1, k + 16, Blocks.wheat, 7, 0x02);
		world.setBlock(i + 6, j + 1, k + 17, Blocks.tallgrass, 1, 0x02);
		world.setBlock(i + 7, j + 1, k + 1, Blocks.tallgrass, 1, 0x02);
		world.setBlock(i + 7, j + 1, k + 2, Blocks.tallgrass, 1, 0x02);
		world.setBlock(i + 7, j + 1, k + 3, Blocks.tallgrass, 1, 0x02);
		world.setBlock(i + 7, j + 1, k + 13, Blocks.tallgrass, 1, 0x02);
		world.setBlock(i + 7, j + 1, k + 14, Blocks.wheat, 7, 0x02);
		world.setBlock(i + 7, j + 1, k + 15, Blocks.wheat, 7, 0x02);
		world.setBlock(i + 7, j + 1, k + 16, Blocks.wheat, 7, 0x02);
		world.setBlock(i + 8, j + 1, k + 1, Blocks.tallgrass, 1, 0x02);
		world.setBlock(i + 8, j + 1, k + 2, Blocks.tallgrass, 1, 0x02);
		world.setBlock(i + 8, j + 1, k + 3, Blocks.tallgrass, 1, 0x02);
		world.setBlock(i + 8, j + 1, k + 13, Blocks.yellow_flower);
		world.setBlock(i + 8, j + 1, k + 14, Blocks.tallgrass, 1, 0x02);
		world.setBlock(i + 8, j + 1, k + 15, Blocks.tallgrass, 1, 0x02);
		world.setBlock(i + 8, j + 1, k + 16, Blocks.tallgrass, 1, 0x02);
		world.setBlock(i + 8, j + 5, k + 18, Blocks.torch, 5, 0x02);
		world.setBlock(i + 8, j + 7, k + 7, Blocks.torch, 5, 0x02);
		world.setBlock(i + 8, j + 7, k + 9, Blocks.torch, 5, 0x02);
		world.setBlock(i + 9, j + 2, k + 6, Blocks.wall_sign, 2, 0x02);
		world.setBlock(i + 9, j + 2, k + 10, Blocks.wall_sign, 3, 0x02);
		world.setBlock(i + 9, j + 6, k + 0, Blocks.torch, 5, 0x02);
		world.setBlock(i + 12, j + 2, k + 6, Blocks.wall_sign, 2, 0x02);
		world.setBlock(i + 12, j + 2, k + 10, Blocks.wall_sign, 3, 0x02);
		world.setBlock(i + 12, j + 6, k + 0, Blocks.torch, 5, 0x02);
		world.setBlock(i + 13, j + 1, k + 1, Blocks.tallgrass, 1, 0x02);
		world.setBlock(i + 13, j + 1, k + 2, Blocks.tallgrass, 1, 0x02);
		world.setBlock(i + 13, j + 1, k + 3, Blocks.yellow_flower);
		world.setBlock(i + 13, j + 1, k + 14, Blocks.tallgrass, 1, 0x02);
		world.setBlock(i + 13, j + 1, k + 15, Blocks.tallgrass, 1, 0x02);
		world.setBlock(i + 13, j + 1, k + 16, Blocks.tallgrass, 1, 0x02);
		world.setBlock(i + 13, j + 1, k + 17, Blocks.tallgrass, 1, 0x02);
		world.setBlock(i + 13, j + 5, k + 18, Blocks.torch, 5, 0x02);
		world.setBlock(i + 13, j + 7, k + 7, Blocks.torch, 5, 0x02);
		world.setBlock(i + 13, j + 7, k + 9, Blocks.torch, 5, 0x02);
		world.setBlock(i + 14, j + 1, k + 1, Blocks.tallgrass, 1, 0x02);
		world.setBlock(i + 14, j + 1, k + 2, Blocks.tallgrass, 1, 0x02);
		world.setBlock(i + 14, j + 1, k + 13, Blocks.tallgrass, 1, 0x02);
		world.setBlock(i + 14, j + 1, k + 14, Blocks.wheat, 7, 0x02);
		world.setBlock(i + 14, j + 1, k + 15, Blocks.wheat, 7, 0x02);
		world.setBlock(i + 14, j + 1, k + 16, Blocks.wheat, 7, 0x02);
		world.setBlock(i + 14, j + 1, k + 17, Blocks.tallgrass, 1, 0x02);
		world.setBlock(i + 15, j + 0, k + 15, Blocks.water);
		world.setBlock(i + 15, j + 1, k + 1, Blocks.tallgrass, 1, 0x02);
		world.setBlock(i + 15, j + 1, k + 2, Blocks.tallgrass, 1, 0x02);
		world.setBlock(i + 15, j + 1, k + 3, Blocks.tallgrass, 1, 0x02);
		world.setBlock(i + 15, j + 1, k + 14, Blocks.wheat, 7, 0x02);
		world.setBlock(i + 15, j + 1, k + 16, Blocks.wheat, 7, 0x02);
		world.setBlock(i + 15, j + 1, k + 17, Blocks.tallgrass, 1, 0x02);
		world.setBlock(i + 16, j + 1, k + 1, Blocks.red_flower);
		world.setBlock(i + 16, j + 1, k + 2, Blocks.tallgrass, 1, 0x02);
		world.setBlock(i + 16, j + 1, k + 3, Blocks.tallgrass, 1, 0x02);
		world.setBlock(i + 16, j + 1, k + 13, Blocks.yellow_flower);
		world.setBlock(i + 16, j + 1, k + 14, Blocks.wheat, 7, 0x02);
		world.setBlock(i + 16, j + 1, k + 15, Blocks.wheat, 7, 0x02);
		world.setBlock(i + 16, j + 1, k + 16, Blocks.wheat, 7, 0x02);
		world.setBlock(i + 17, j + 1, k + 1, Blocks.tallgrass, 1, 0x02);
		world.setBlock(i + 17, j + 1, k + 2, Blocks.tallgrass, 1, 0x02);
		world.setBlock(i + 17, j + 1, k + 3, Blocks.tallgrass, 1, 0x02);
		world.setBlock(i + 17, j + 1, k + 13, Blocks.tallgrass, 1, 0x02);
		world.setBlock(i + 17, j + 1, k + 14, Blocks.wheat, 7, 0x02);
		world.setBlock(i + 17, j + 1, k + 15, Blocks.wheat, 7, 0x02);
		world.setBlock(i + 18, j + 0, k + 15, Blocks.water);
		world.setBlock(i + 18, j + 1, k + 1, Blocks.tallgrass, 1, 0x02);
		world.setBlock(i + 18, j + 1, k + 2, Blocks.tallgrass, 1, 0x02);
		world.setBlock(i + 18, j + 1, k + 4, Blocks.tallgrass, 1, 0x02);
		world.setBlock(i + 18, j + 1, k + 6, Blocks.tallgrass, 1, 0x02);
		world.setBlock(i + 18, j + 1, k + 7, Blocks.tallgrass, 1, 0x02);
		world.setBlock(i + 18, j + 1, k + 8, Blocks.yellow_flower);
		world.setBlock(i + 18, j + 1, k + 9, Blocks.tallgrass, 1, 0x02);
		world.setBlock(i + 18, j + 1, k + 10, Blocks.tallgrass, 1, 0x02);
		world.setBlock(i + 18, j + 1, k + 11, Blocks.tallgrass, 1, 0x02);
		world.setBlock(i + 18, j + 1, k + 12, Blocks.tallgrass, 1, 0x02);
		world.setBlock(i + 18, j + 1, k + 13, Blocks.tallgrass, 1, 0x02);
		world.setBlock(i + 18, j + 1, k + 14, Blocks.wheat, 7, 0x02);
		world.setBlock(i + 18, j + 1, k + 16, Blocks.wheat, 7, 0x02);
		world.setBlock(i + 19, j + 1, k + 1, Blocks.tallgrass, 1, 0x02);
		world.setBlock(i + 19, j + 1, k + 3, Blocks.tallgrass, 1, 0x02);
		world.setBlock(i + 19, j + 1, k + 4, Blocks.tallgrass, 1, 0x02);
		world.setBlock(i + 19, j + 1, k + 6, Blocks.tallgrass, 1, 0x02);
		world.setBlock(i + 19, j + 1, k + 7, Blocks.tallgrass, 1, 0x02);
		world.setBlock(i + 19, j + 1, k + 8, Blocks.tallgrass, 1, 0x02);
		world.setBlock(i + 19, j + 1, k + 9, Blocks.tallgrass, 1, 0x02);
		world.setBlock(i + 19, j + 1, k + 10, Blocks.tallgrass, 1, 0x02);
		world.setBlock(i + 19, j + 1, k + 11, Blocks.tallgrass, 1, 0x02);
		world.setBlock(i + 19, j + 1, k + 12, Blocks.tallgrass, 1, 0x02);
		world.setBlock(i + 19, j + 1, k + 13, Blocks.tallgrass, 1, 0x02);
		world.setBlock(i + 19, j + 1, k + 14, Blocks.wheat, 7, 0x02);
		world.setBlock(i + 19, j + 1, k + 15, Blocks.wheat, 7, 0x02);
		world.setBlock(i + 19, j + 1, k + 16, Blocks.wheat, 7, 0x02);
		world.setBlock(i + 19, j + 1, k + 17, Blocks.red_flower);
		world.setBlock(i + 20, j + 1, k + 1, Blocks.tallgrass, 1, 0x02);
		world.setBlock(i + 20, j + 1, k + 2, Blocks.tallgrass, 1, 0x02);
		world.setBlock(i + 20, j + 1, k + 3, Blocks.tallgrass, 1, 0x02);
		world.setBlock(i + 20, j + 1, k + 5, Blocks.tallgrass, 1, 0x02);
		world.setBlock(i + 20, j + 1, k + 6, Blocks.tallgrass, 1, 0x02);
		world.setBlock(i + 20, j + 1, k + 7, Blocks.tallgrass, 1, 0x02);
		world.setBlock(i + 20, j + 1, k + 8, Blocks.red_flower);
		world.setBlock(i + 20, j + 1, k + 10, Blocks.tallgrass, 1, 0x02);
		world.setBlock(i + 20, j + 1, k + 12, Blocks.tallgrass, 1, 0x02);
		world.setBlock(i + 20, j + 1, k + 13, Blocks.tallgrass, 1, 0x02);
		world.setBlock(i + 20, j + 1, k + 14, Blocks.tallgrass, 1, 0x02);
		world.setBlock(i + 20, j + 1, k + 15, Blocks.tallgrass, 1, 0x02);
		world.setBlock(i + 20, j + 1, k + 17, Blocks.tallgrass, 1, 0x02);
		world.setBlock(i + 21, j + 4, k + 0, Blocks.torch, 5, 0x02);
		world.setBlock(i + 21, j + 4, k + 18, Blocks.torch, 5, 0x02);

		return true;
	}
}