package kieranvs.avatar.generation;

import java.util.Random;

import kieranvs.avatar.mod_Avatar;
import kieranvs.avatar.bending.ElementManager;
import kieranvs.avatar.entity.EntityEarthMan;
import kieranvs.avatar.entity.EntityEarthWoman;
import kieranvs.avatar.util.GenerationUtils;
import cpw.mods.fml.common.IWorldGenerator;
import net.minecraft.block.Block;
import net.minecraft.entity.passive.EntityPig;
import net.minecraft.init.Blocks;
import net.minecraft.item.ItemStack;
import net.minecraft.tileentity.TileEntity;
import net.minecraft.tileentity.TileEntityChest;
import net.minecraft.world.World;
import net.minecraft.world.biome.BiomeGenBase;
import net.minecraft.world.chunk.IChunkProvider;
import net.minecraft.world.gen.feature.WorldGenerator;

public class WorldGenEarthKingdomTower implements IWorldGenerator {
	
	private static BiomeGenBase[] biomes = {BiomeGenBase.plains, BiomeGenBase.birchForest, BiomeGenBase.forest};
	
	@Override
	public void generate(Random random, int chunkX, int chunkZ, World world, IChunkProvider chunkGenerator, IChunkProvider chunkProvider) {
		int result[] = GenerationUtils.shouldSpawnHere(random, chunkX, chunkZ, world, 12, 2, 40, biomes);
		if(result[0] == 0){
			this.generate(world, result[1], result[2], result[3]);
			this.generateLoot(world, result[1], result[2], result[3], random);
			this.generateEntities(world, result[1], result[2], result[3], random);
		}
	}
	
	public void generateEntities(World world, int i, int j, int k, Random random) {
		int numM = random.nextInt(2) + 1;

		for (int x = 0; x < numM; x++) {
			EntityEarthMan earthMan = new EntityEarthMan(world, i + 6, j + 4, k + 6, 11);
			earthMan.setPositionAndRotation(i + 7, j + 4, k + 7, 1.0F, 1.0F);
			world.spawnEntityInWorld(earthMan);
		}
	}	

	
	public void generateLoot(World world, int i, int j, int k, Random random){
		for(int x = i; x < i + 12; x++){
			for (int z = k; z < k + 12; z++) {
				for (int y = j; y < j + 18; y++) {
					TileEntity e = world.getTileEntity(x, y, z);
					if(e != null && e instanceof TileEntityChest){
						GenerationUtils.generateScrolls(random, (TileEntityChest) e, ElementManager.EARTH, 3);
						GenerationUtils.generateRandomMoney(random, (TileEntityChest) e, ElementManager.EARTH, 2);
					}
				}
			}
		}
	}


	public boolean generate(World world, int i, int j, int k) {
		world.setBlock(i + 0, j + 0, k + 0, Blocks.grass);
		world.setBlock(i + 0, j + 0, k + 1, Blocks.sandstone);
		world.setBlock(i + 0, j + 0, k + 2, Blocks.sandstone);
		world.setBlock(i + 0, j + 0, k + 3, Blocks.sandstone);
		world.setBlock(i + 0, j + 0, k + 4, Blocks.sandstone);
		world.setBlock(i + 0, j + 0, k + 5, Blocks.sandstone);
		world.setBlock(i + 0, j + 0, k + 6, Blocks.sandstone);
		world.setBlock(i + 0, j + 0, k + 7, Blocks.sandstone);
		world.setBlock(i + 0, j + 0, k + 8, Blocks.sandstone);
		world.setBlock(i + 0, j + 0, k + 9, Blocks.sandstone);
		world.setBlock(i + 0, j + 0, k + 10, Blocks.sandstone);
		world.setBlock(i + 0, j + 0, k + 11, Blocks.sandstone);
		world.setBlock(i + 0, j + 0, k + 12, Blocks.grass);
		world.setBlock(i + 1, j + 0, k + 0, Blocks.sandstone);
		world.setBlock(i + 1, j + 0, k + 1, Blocks.sandstone);
		world.setBlock(i + 1, j + 0, k + 2, Blocks.sandstone_stairs);
		world.setBlock(i + 1, j + 0, k + 3, Blocks.sandstone_stairs, 1, 0x02);
		world.setBlock(i + 1, j + 0, k + 4, Blocks.sandstone_stairs);
		world.setBlock(i + 1, j + 0, k + 5, Blocks.sandstone_stairs, 1, 0x02);
		world.setBlock(i + 1, j + 0, k + 6, Blocks.sandstone_stairs);
		world.setBlock(i + 1, j + 0, k + 7, Blocks.sandstone_stairs, 1, 0x02);
		world.setBlock(i + 1, j + 0, k + 8, Blocks.sandstone_stairs);
		world.setBlock(i + 1, j + 0, k + 9, Blocks.sandstone_stairs, 1, 0x02);
		world.setBlock(i + 1, j + 0, k + 10, Blocks.sandstone_stairs);
		world.setBlock(i + 1, j + 0, k + 11, Blocks.sandstone);
		world.setBlock(i + 1, j + 0, k + 12, Blocks.sandstone);
		world.setBlock(i + 2, j + 0, k + 0, Blocks.sandstone);
		world.setBlock(i + 2, j + 0, k + 1, Blocks.sandstone_stairs, 2, 0x02);
		world.setBlock(i + 2, j + 0, k + 2, Blocks.sandstone);
		world.setBlock(i + 2, j + 0, k + 3, Blocks.sandstone);
		world.setBlock(i + 2, j + 0, k + 4, Blocks.sandstone);
		world.setBlock(i + 2, j + 0, k + 5, Blocks.sandstone, 1, 0x02);
		world.setBlock(i + 2, j + 0, k + 6, Blocks.sandstone, 1, 0x02);
		world.setBlock(i + 2, j + 0, k + 7, Blocks.sandstone, 1, 0x02);
		world.setBlock(i + 2, j + 0, k + 8, Blocks.sandstone);
		world.setBlock(i + 2, j + 0, k + 9, Blocks.sandstone);
		world.setBlock(i + 2, j + 0, k + 10, Blocks.sandstone);
		world.setBlock(i + 2, j + 0, k + 11, Blocks.sandstone_stairs, 3, 0x02);
		world.setBlock(i + 2, j + 0, k + 12, Blocks.sandstone);
		world.setBlock(i + 2, j + 1, k + 5, Blocks.fence);
		world.setBlock(i + 2, j + 1, k + 7, Blocks.fence);
		world.setBlock(i + 2, j + 2, k + 5, Blocks.fence);
		world.setBlock(i + 2, j + 2, k + 7, Blocks.fence);
		world.setBlock(i + 2, j + 3, k + 5, Blocks.sandstone, 2, 0x02);
		world.setBlock(i + 2, j + 3, k + 7, Blocks.sandstone, 2, 0x02);
		world.setBlock(i + 2, j + 4, k + 5, Blocks.wool, 13, 0x02);
		world.setBlock(i + 2, j + 4, k + 6, Blocks.wool, 13, 0x02);
		world.setBlock(i + 2, j + 4, k + 7, Blocks.wool, 13, 0x02);
		world.setBlock(i + 2, j + 5, k + 5, Blocks.fence);
		world.setBlock(i + 2, j + 5, k + 7, Blocks.fence);
		world.setBlock(i + 2, j + 6, k + 5, Blocks.fence);
		world.setBlock(i + 2, j + 6, k + 7, Blocks.fence);
		world.setBlock(i + 2, j + 7, k + 5, Blocks.sandstone, 2, 0x02);
		world.setBlock(i + 2, j + 7, k + 7, Blocks.sandstone, 2, 0x02);
		world.setBlock(i + 2, j + 8, k + 5, Blocks.wool, 13, 0x02);
		world.setBlock(i + 2, j + 8, k + 6, Blocks.wool, 13, 0x02);
		world.setBlock(i + 2, j + 8, k + 7, Blocks.wool, 13, 0x02);
		world.setBlock(i + 2, j + 12, k + 5, Blocks.wool, 13, 0x02);
		world.setBlock(i + 2, j + 12, k + 6, Blocks.wool, 13, 0x02);
		world.setBlock(i + 2, j + 12, k + 7, Blocks.wool, 13, 0x02);
		world.setBlock(i + 2, j + 16, k + 5, Blocks.wool, 13, 0x02);
		world.setBlock(i + 2, j + 16, k + 6, Blocks.wool, 13, 0x02);
		world.setBlock(i + 2, j + 16, k + 7, Blocks.wool, 13, 0x02);
		world.setBlock(i + 3, j + 0, k + 0, Blocks.sandstone);
		world.setBlock(i + 3, j + 0, k + 1, Blocks.sandstone_stairs, 3, 0x02);
		world.setBlock(i + 3, j + 0, k + 2, Blocks.sandstone);
		world.setBlock(i + 3, j + 0, k + 3, Blocks.sandstone);
		world.setBlock(i + 3, j + 0, k + 4, Blocks.sandstone, 1, 0x02);
		world.setBlock(i + 3, j + 0, k + 5, Blocks.sandstone);
		world.setBlock(i + 3, j + 0, k + 6, Blocks.sandstone);
		world.setBlock(i + 3, j + 0, k + 7, Blocks.sandstone);
		world.setBlock(i + 3, j + 0, k + 8, Blocks.sandstone, 1, 0x02);
		world.setBlock(i + 3, j + 0, k + 9, Blocks.sandstone);
		world.setBlock(i + 3, j + 0, k + 10, Blocks.sandstone);
		world.setBlock(i + 3, j + 0, k + 11, Blocks.sandstone_stairs, 2, 0x02);
		world.setBlock(i + 3, j + 0, k + 12, Blocks.sandstone);
		world.setBlock(i + 3, j + 1, k + 4, Blocks.sandstone, 1, 0x02);
		world.setBlock(i + 3, j + 1, k + 8, Blocks.sandstone, 1, 0x02);
		world.setBlock(i + 3, j + 2, k + 4, Blocks.sandstone, 2, 0x02);
		world.setBlock(i + 3, j + 2, k + 8, Blocks.sandstone, 2, 0x02);
		world.setBlock(i + 3, j + 3, k + 4, Blocks.sandstone, 2, 0x02);
		world.setBlock(i + 3, j + 3, k + 8, Blocks.sandstone, 2, 0x02);
		world.setBlock(i + 3, j + 4, k + 4, Blocks.wool, 13, 0x02);
		world.setBlock(i + 3, j + 4, k + 5, Blocks.planks);
		world.setBlock(i + 3, j + 4, k + 6, Blocks.planks);
		world.setBlock(i + 3, j + 4, k + 7, Blocks.planks);
		world.setBlock(i + 3, j + 4, k + 8, Blocks.wool, 13, 0x02);
		world.setBlock(i + 3, j + 5, k + 4, Blocks.sandstone, 1, 0x02);
		world.setBlock(i + 3, j + 5, k + 8, Blocks.sandstone, 1, 0x02);
		world.setBlock(i + 3, j + 6, k + 4, Blocks.sandstone, 2, 0x02);
		world.setBlock(i + 3, j + 6, k + 8, Blocks.sandstone, 2, 0x02);
		world.setBlock(i + 3, j + 7, k + 4, Blocks.sandstone, 2, 0x02);
		world.setBlock(i + 3, j + 7, k + 8, Blocks.sandstone, 2, 0x02);
		world.setBlock(i + 3, j + 8, k + 4, Blocks.wool, 13, 0x02);
		world.setBlock(i + 3, j + 8, k + 5, Blocks.planks);
		world.setBlock(i + 3, j + 8, k + 6, Blocks.planks);
		world.setBlock(i + 3, j + 8, k + 7, Blocks.planks);
		world.setBlock(i + 3, j + 8, k + 8, Blocks.wool, 13, 0x02);
		world.setBlock(i + 3, j + 9, k + 5, Blocks.sandstone, 1, 0x02);
		world.setBlock(i + 3, j + 9, k + 6, Blocks.sandstone, 1, 0x02);
		world.setBlock(i + 3, j + 9, k + 7, Blocks.sandstone, 1, 0x02);
		world.setBlock(i + 3, j + 10, k + 5, Blocks.sandstone, 2, 0x02);
		world.setBlock(i + 3, j + 10, k + 6, Blocks.fence);
		world.setBlock(i + 3, j + 10, k + 7, Blocks.sandstone, 2, 0x02);
		world.setBlock(i + 3, j + 11, k + 5, Blocks.sandstone, 2, 0x02);
		world.setBlock(i + 3, j + 11, k + 6, Blocks.fence);
		world.setBlock(i + 3, j + 11, k + 7, Blocks.sandstone, 2, 0x02);
		world.setBlock(i + 3, j + 12, k + 4, Blocks.wool, 13, 0x02);
		world.setBlock(i + 3, j + 12, k + 5, Blocks.wool, 13, 0x02);
		world.setBlock(i + 3, j + 12, k + 6, Blocks.wool, 13, 0x02);
		world.setBlock(i + 3, j + 12, k + 7, Blocks.wool, 13, 0x02);
		world.setBlock(i + 3, j + 12, k + 8, Blocks.wool, 13, 0x02);
		world.setBlock(i + 3, j + 13, k + 5, Blocks.sandstone, 1, 0x02);
		world.setBlock(i + 3, j + 13, k + 6, Blocks.sandstone, 1, 0x02);
		world.setBlock(i + 3, j + 13, k + 7, Blocks.sandstone, 1, 0x02);
		world.setBlock(i + 3, j + 14, k + 5, Blocks.sandstone, 2, 0x02);
		world.setBlock(i + 3, j + 14, k + 6, Blocks.fence);
		world.setBlock(i + 3, j + 14, k + 7, Blocks.sandstone, 2, 0x02);
		world.setBlock(i + 3, j + 15, k + 5, Blocks.sandstone, 2, 0x02);
		world.setBlock(i + 3, j + 15, k + 6, Blocks.fence);
		world.setBlock(i + 3, j + 15, k + 7, Blocks.sandstone, 2, 0x02);
		world.setBlock(i + 3, j + 16, k + 4, Blocks.wool, 13, 0x02);
		world.setBlock(i + 3, j + 16, k + 5, Blocks.sandstone, 2, 0x02);
		world.setBlock(i + 3, j + 16, k + 6, Blocks.sandstone, 2, 0x02);
		world.setBlock(i + 3, j + 16, k + 7, Blocks.sandstone, 2, 0x02);
		world.setBlock(i + 3, j + 16, k + 8, Blocks.wool, 13, 0x02);
		world.setBlock(i + 4, j + 0, k + 0, Blocks.sandstone);
		world.setBlock(i + 4, j + 0, k + 1, Blocks.sandstone_stairs, 2, 0x02);
		world.setBlock(i + 4, j + 0, k + 2, Blocks.sandstone);
		world.setBlock(i + 4, j + 0, k + 3, Blocks.sandstone, 1, 0x02);
		world.setBlock(i + 4, j + 0, k + 4, Blocks.sandstone);
		world.setBlock(i + 4, j + 0, k + 5, Blocks.stone_brick_stairs, 1, 0x02);
		world.setBlock(i + 4, j + 0, k + 6, Blocks.stone_brick_stairs);
		world.setBlock(i + 4, j + 0, k + 7, Blocks.stone_brick_stairs, 1, 0x02);
		world.setBlock(i + 4, j + 0, k + 8, Blocks.sandstone);
		world.setBlock(i + 4, j + 0, k + 9, Blocks.sandstone, 1, 0x02);
		world.setBlock(i + 4, j + 0, k + 10, Blocks.sandstone);
		world.setBlock(i + 4, j + 0, k + 11, Blocks.sandstone_stairs, 3, 0x02);
		world.setBlock(i + 4, j + 0, k + 12, Blocks.sandstone);
		world.setBlock(i + 4, j + 1, k + 3, Blocks.sandstone, 1, 0x02);
		world.setBlock(i + 4, j + 1, k + 9, Blocks.sandstone, 1, 0x02);
		world.setBlock(i + 4, j + 2, k + 3, Blocks.sandstone, 2, 0x02);
		world.setBlock(i + 4, j + 2, k + 9, Blocks.sandstone, 2, 0x02);
		world.setBlock(i + 4, j + 3, k + 3, Blocks.sandstone, 2, 0x02);
		world.setBlock(i + 4, j + 3, k + 9, Blocks.sandstone, 2, 0x02);
		world.setBlock(i + 4, j + 4, k + 3, Blocks.wool, 13, 0x02);
		world.setBlock(i + 4, j + 4, k + 4, Blocks.planks);
		world.setBlock(i + 4, j + 4, k + 5, Blocks.planks);
		world.setBlock(i + 4, j + 4, k + 6, Blocks.planks);
		world.setBlock(i + 4, j + 4, k + 7, Blocks.planks);
		world.setBlock(i + 4, j + 4, k + 8, Blocks.planks);
		world.setBlock(i + 4, j + 4, k + 9, Blocks.wool, 13, 0x02);
		world.setBlock(i + 4, j + 5, k + 3, Blocks.sandstone, 1, 0x02);
		world.setBlock(i + 4, j + 5, k + 9, Blocks.sandstone, 1, 0x02);
		world.setBlock(i + 4, j + 6, k + 3, Blocks.sandstone, 2, 0x02);
		world.setBlock(i + 4, j + 6, k + 9, Blocks.sandstone, 2, 0x02);
		world.setBlock(i + 4, j + 7, k + 3, Blocks.sandstone, 2, 0x02);
		world.setBlock(i + 4, j + 7, k + 9, Blocks.sandstone, 2, 0x02);
		world.setBlock(i + 4, j + 8, k + 3, Blocks.wool, 13, 0x02);
		world.setBlock(i + 4, j + 8, k + 4, Blocks.planks);
		world.setBlock(i + 4, j + 8, k + 5, Blocks.planks);
		world.setBlock(i + 4, j + 8, k + 6, Blocks.planks);
		world.setBlock(i + 4, j + 8, k + 7, Blocks.planks);
		world.setBlock(i + 4, j + 8, k + 8, Blocks.planks);
		world.setBlock(i + 4, j + 8, k + 9, Blocks.wool, 13, 0x02);
		world.setBlock(i + 4, j + 9, k + 4, Blocks.sandstone, 1, 0x02);
		world.setBlock(i + 4, j + 9, k + 8, Blocks.sandstone, 1, 0x02);
		world.setBlock(i + 4, j + 10, k + 4, Blocks.sandstone, 2, 0x02);
		world.setBlock(i + 4, j + 10, k + 8, Blocks.sandstone, 2, 0x02);
		world.setBlock(i + 4, j + 11, k + 4, Blocks.sandstone, 2, 0x02);
		world.setBlock(i + 4, j + 11, k + 8, Blocks.sandstone, 2, 0x02);
		world.setBlock(i + 4, j + 12, k + 3, Blocks.wool, 13, 0x02);
		world.setBlock(i + 4, j + 12, k + 4, Blocks.wool, 13, 0x02);
		world.setBlock(i + 4, j + 12, k + 5, Blocks.planks);
		world.setBlock(i + 4, j + 12, k + 6, Blocks.planks);
		world.setBlock(i + 4, j + 12, k + 7, Blocks.planks);
		world.setBlock(i + 4, j + 12, k + 8, Blocks.wool, 13, 0x02);
		world.setBlock(i + 4, j + 12, k + 9, Blocks.wool, 13, 0x02);
		world.setBlock(i + 4, j + 13, k + 4, Blocks.sandstone, 1, 0x02);
		world.setBlock(i + 4, j + 13, k + 8, Blocks.sandstone, 1, 0x02);
		world.setBlock(i + 4, j + 14, k + 4, Blocks.sandstone, 2, 0x02);
		world.setBlock(i + 4, j + 14, k + 8, Blocks.sandstone, 2, 0x02);
		world.setBlock(i + 4, j + 15, k + 4, Blocks.sandstone, 2, 0x02);
		world.setBlock(i + 4, j + 15, k + 8, Blocks.sandstone, 2, 0x02);
		world.setBlock(i + 4, j + 16, k + 3, Blocks.wool, 13, 0x02);
		world.setBlock(i + 4, j + 16, k + 4, Blocks.sandstone, 2, 0x02);
		world.setBlock(i + 4, j + 16, k + 5, Blocks.stone_slab, 9, 0x02);
		world.setBlock(i + 4, j + 16, k + 6, Blocks.stone_slab, 9, 0x02);
		world.setBlock(i + 4, j + 16, k + 7, Blocks.stone_slab, 9, 0x02);
		world.setBlock(i + 4, j + 16, k + 8, Blocks.sandstone, 2, 0x02);
		world.setBlock(i + 4, j + 16, k + 9, Blocks.wool, 13, 0x02);
		world.setBlock(i + 5, j + 0, k + 0, Blocks.sandstone);
		world.setBlock(i + 5, j + 0, k + 1, Blocks.sandstone_stairs, 3, 0x02);
		world.setBlock(i + 5, j + 0, k + 2, Blocks.sandstone, 1, 0x02);
		world.setBlock(i + 5, j + 0, k + 3, Blocks.sandstone);
		world.setBlock(i + 5, j + 0, k + 4, Blocks.stone_brick_stairs, 3, 0x02);
		world.setBlock(i + 5, j + 0, k + 5, Blocks.glowstone);
		world.setBlock(i + 5, j + 0, k + 6, Blocks.sandstone);
		world.setBlock(i + 5, j + 0, k + 7, Blocks.glowstone);
		world.setBlock(i + 5, j + 0, k + 8, Blocks.stone_brick_stairs, 3, 0x02);
		world.setBlock(i + 5, j + 0, k + 9, Blocks.sandstone);
		world.setBlock(i + 5, j + 0, k + 10, Blocks.sandstone, 1, 0x02);
		world.setBlock(i + 5, j + 0, k + 11, Blocks.sandstone_stairs, 2, 0x02);
		world.setBlock(i + 5, j + 0, k + 12, Blocks.sandstone);
		world.setBlock(i + 5, j + 1, k + 2, Blocks.fence);
		world.setBlock(i + 5, j + 1, k + 10, Blocks.fence);
		world.setBlock(i + 5, j + 2, k + 2, Blocks.fence);
		world.setBlock(i + 5, j + 2, k + 10, Blocks.fence);
		world.setBlock(i + 5, j + 3, k + 2, Blocks.sandstone, 2, 0x02);
		world.setBlock(i + 5, j + 3, k + 10, Blocks.sandstone, 2, 0x02);
		world.setBlock(i + 5, j + 4, k + 2, Blocks.wool, 13, 0x02);
		world.setBlock(i + 5, j + 4, k + 3, Blocks.planks);
		world.setBlock(i + 5, j + 4, k + 4, Blocks.planks);
		world.setBlock(i + 5, j + 4, k + 5, Blocks.planks);
		world.setBlock(i + 5, j + 4, k + 7, Blocks.planks);
		world.setBlock(i + 5, j + 4, k + 8, Blocks.planks);
		world.setBlock(i + 5, j + 4, k + 9, Blocks.planks);
		world.setBlock(i + 5, j + 4, k + 10, Blocks.wool, 13, 0x02);
		world.setBlock(i + 5, j + 5, k + 2, Blocks.fence);
		world.setBlock(i + 5, j + 5, k + 10, Blocks.fence);
		world.setBlock(i + 5, j + 6, k + 2, Blocks.fence);
		world.setBlock(i + 5, j + 6, k + 10, Blocks.fence);
		world.setBlock(i + 5, j + 7, k + 2, Blocks.sandstone, 2, 0x02);
		world.setBlock(i + 5, j + 7, k + 10, Blocks.sandstone, 2, 0x02);
		world.setBlock(i + 5, j + 8, k + 2, Blocks.wool, 13, 0x02);
		world.setBlock(i + 5, j + 8, k + 3, Blocks.planks);
		world.setBlock(i + 5, j + 8, k + 4, Blocks.planks);
		world.setBlock(i + 5, j + 8, k + 5, Blocks.planks);
		world.setBlock(i + 5, j + 8, k + 7, Blocks.planks);
		world.setBlock(i + 5, j + 8, k + 8, Blocks.planks);
		world.setBlock(i + 5, j + 8, k + 9, Blocks.planks);
		world.setBlock(i + 5, j + 8, k + 10, Blocks.wool, 13, 0x02);
		world.setBlock(i + 5, j + 9, k + 3, Blocks.sandstone, 1, 0x02);
		world.setBlock(i + 5, j + 9, k + 9, Blocks.sandstone, 1, 0x02);
		world.setBlock(i + 5, j + 10, k + 3, Blocks.sandstone, 2, 0x02);
		world.setBlock(i + 5, j + 10, k + 9, Blocks.sandstone, 2, 0x02);
		world.setBlock(i + 5, j + 11, k + 3, Blocks.sandstone, 2, 0x02);
		world.setBlock(i + 5, j + 11, k + 9, Blocks.sandstone, 2, 0x02);
		world.setBlock(i + 5, j + 12, k + 2, Blocks.wool, 13, 0x02);
		world.setBlock(i + 5, j + 12, k + 3, Blocks.wool, 13, 0x02);
		world.setBlock(i + 5, j + 12, k + 4, Blocks.planks);
		world.setBlock(i + 5, j + 12, k + 5, Blocks.planks);
		world.setBlock(i + 5, j + 12, k + 7, Blocks.planks);
		world.setBlock(i + 5, j + 12, k + 8, Blocks.planks);
		world.setBlock(i + 5, j + 12, k + 9, Blocks.wool, 13, 0x02);
		world.setBlock(i + 5, j + 12, k + 10, Blocks.wool, 13, 0x02);
		world.setBlock(i + 5, j + 13, k + 3, Blocks.sandstone, 1, 0x02);
		world.setBlock(i + 5, j + 13, k + 9, Blocks.sandstone, 1, 0x02);
		world.setBlock(i + 5, j + 14, k + 3, Blocks.sandstone, 2, 0x02);
		world.setBlock(i + 5, j + 14, k + 9, Blocks.sandstone, 2, 0x02);
		world.setBlock(i + 5, j + 15, k + 3, Blocks.sandstone, 2, 0x02);
		world.setBlock(i + 5, j + 15, k + 9, Blocks.sandstone, 2, 0x02);
		world.setBlock(i + 5, j + 16, k + 2, Blocks.wool, 13, 0x02);
		world.setBlock(i + 5, j + 16, k + 3, Blocks.sandstone, 2, 0x02);
		world.setBlock(i + 5, j + 16, k + 4, Blocks.stone_slab, 9, 0x02);
		world.setBlock(i + 5, j + 16, k + 8, Blocks.stone_slab, 9, 0x02);
		world.setBlock(i + 5, j + 16, k + 9, Blocks.sandstone, 2, 0x02);
		world.setBlock(i + 5, j + 16, k + 10, Blocks.wool, 13, 0x02);
		world.setBlock(i + 5, j + 17, k + 5, Blocks.sandstone_stairs);
		world.setBlock(i + 5, j + 17, k + 6, Blocks.sandstone_stairs);
		world.setBlock(i + 5, j + 17, k + 7, Blocks.sandstone_stairs, 3, 0x02);
		world.setBlock(i + 6, j + 0, k + 0, Blocks.sandstone);
		world.setBlock(i + 6, j + 0, k + 1, Blocks.sandstone_stairs, 2, 0x02);
		world.setBlock(i + 6, j + 0, k + 2, Blocks.sandstone, 1, 0x02);
		world.setBlock(i + 6, j + 0, k + 3, Blocks.sandstone);
		world.setBlock(i + 6, j + 0, k + 4, Blocks.stone_brick_stairs, 3, 0x02);
		world.setBlock(i + 6, j + 0, k + 5, Blocks.sandstone);
		world.setBlock(i + 6, j + 0, k + 6, Blocks.sandstone, 2, 0x02);
		world.setBlock(i + 6, j + 0, k + 7, Blocks.sandstone);
		world.setBlock(i + 6, j + 0, k + 8, Blocks.stone_brick_stairs, 3, 0x02);
		world.setBlock(i + 6, j + 0, k + 9, Blocks.sandstone);
		world.setBlock(i + 6, j + 0, k + 10, Blocks.sandstone, 1, 0x02);
		world.setBlock(i + 6, j + 0, k + 11, Blocks.sandstone_stairs, 3, 0x02);
		world.setBlock(i + 6, j + 0, k + 12, Blocks.sandstone);
		world.setBlock(i + 6, j + 1, k + 6, Blocks.sandstone, 1, 0x02);
		world.setBlock(i + 6, j + 2, k + 6, Blocks.sandstone, 2, 0x02);
		world.setBlock(i + 6, j + 3, k + 6, Blocks.sandstone, 2, 0x02);
		world.setBlock(i + 6, j + 4, k + 2, Blocks.wool, 13, 0x02);
		world.setBlock(i + 6, j + 4, k + 3, Blocks.planks);
		world.setBlock(i + 6, j + 4, k + 4, Blocks.planks);
		world.setBlock(i + 6, j + 4, k + 6, Blocks.sandstone, 2, 0x02);
		world.setBlock(i + 6, j + 4, k + 8, Blocks.planks);
		world.setBlock(i + 6, j + 4, k + 9, Blocks.planks);
		world.setBlock(i + 6, j + 4, k + 10, Blocks.wool, 13, 0x02);
		world.setBlock(i + 6, j + 5, k + 6, Blocks.sandstone, 1, 0x02);
		world.setBlock(i + 6, j + 6, k + 6, Blocks.sandstone, 2, 0x02);
		world.setBlock(i + 6, j + 7, k + 6, Blocks.sandstone, 2, 0x02);
		world.setBlock(i + 6, j + 8, k + 2, Blocks.wool, 13, 0x02);
		world.setBlock(i + 6, j + 8, k + 3, Blocks.planks);
		world.setBlock(i + 6, j + 8, k + 4, Blocks.planks);
		world.setBlock(i + 6, j + 8, k + 6, Blocks.sandstone, 2, 0x02);
		world.setBlock(i + 6, j + 8, k + 8, Blocks.planks);
		world.setBlock(i + 6, j + 8, k + 9, Blocks.planks);
		world.setBlock(i + 6, j + 8, k + 10, Blocks.wool, 13, 0x02);
		world.setBlock(i + 6, j + 9, k + 3, Blocks.sandstone, 1, 0x02);
		world.setBlock(i + 6, j + 9, k + 6, Blocks.sandstone, 1, 0x02);
		world.setBlock(i + 6, j + 9, k + 9, Blocks.sandstone, 1, 0x02);
		world.setBlock(i + 6, j + 10, k + 3, Blocks.fence);
		world.setBlock(i + 6, j + 10, k + 6, Blocks.sandstone, 2, 0x02);
		world.setBlock(i + 6, j + 10, k + 9, Blocks.fence);
		world.setBlock(i + 6, j + 11, k + 3, Blocks.fence);
		world.setBlock(i + 6, j + 11, k + 6, Blocks.sandstone, 2, 0x02);
		world.setBlock(i + 6, j + 11, k + 9, Blocks.fence);
		world.setBlock(i + 6, j + 12, k + 2, Blocks.wool, 13, 0x02);
		world.setBlock(i + 6, j + 12, k + 3, Blocks.wool, 13, 0x02);
		world.setBlock(i + 6, j + 12, k + 4, Blocks.planks);
		world.setBlock(i + 6, j + 12, k + 6, Blocks.sandstone, 2, 0x02);
		world.setBlock(i + 6, j + 12, k + 8, Blocks.planks);
		world.setBlock(i + 6, j + 12, k + 9, Blocks.wool, 13, 0x02);
		world.setBlock(i + 6, j + 12, k + 10, Blocks.wool, 13, 0x02);
		world.setBlock(i + 6, j + 13, k + 3, Blocks.sandstone, 1, 0x02);
		world.setBlock(i + 6, j + 13, k + 6, Blocks.sandstone, 1, 0x02);
		world.setBlock(i + 6, j + 13, k + 9, Blocks.sandstone, 1, 0x02);
		world.setBlock(i + 6, j + 14, k + 3, Blocks.fence);
		world.setBlock(i + 6, j + 14, k + 9, Blocks.fence);
		world.setBlock(i + 6, j + 15, k + 3, Blocks.fence);
		world.setBlock(i + 6, j + 15, k + 9, Blocks.fence);
		world.setBlock(i + 6, j + 16, k + 2, Blocks.wool, 13, 0x02);
		world.setBlock(i + 6, j + 16, k + 3, Blocks.sandstone, 2, 0x02);
		world.setBlock(i + 6, j + 16, k + 4, Blocks.stone_slab, 9, 0x02);
		world.setBlock(i + 6, j + 16, k + 8, Blocks.stone_slab, 9, 0x02);
		world.setBlock(i + 6, j + 16, k + 9, Blocks.sandstone, 2, 0x02);
		world.setBlock(i + 6, j + 16, k + 10, Blocks.wool, 13, 0x02);
		world.setBlock(i + 6, j + 17, k + 5, Blocks.sandstone_stairs, 2, 0x02);
		world.setBlock(i + 6, j + 17, k + 7, Blocks.sandstone_stairs, 3, 0x02);
		world.setBlock(i + 6, j + 18, k + 6, Blocks.glowstone);
		world.setBlock(i + 7, j + 0, k + 0, Blocks.sandstone);
		world.setBlock(i + 7, j + 0, k + 1, Blocks.sandstone_stairs, 3, 0x02);
		world.setBlock(i + 7, j + 0, k + 2, Blocks.sandstone, 1, 0x02);
		world.setBlock(i + 7, j + 0, k + 3, Blocks.sandstone);
		world.setBlock(i + 7, j + 0, k + 4, Blocks.stone_brick_stairs, 3, 0x02);
		world.setBlock(i + 7, j + 0, k + 5, Blocks.glowstone);
		world.setBlock(i + 7, j + 0, k + 6, Blocks.sandstone);
		world.setBlock(i + 7, j + 0, k + 7, Blocks.glowstone);
		world.setBlock(i + 7, j + 0, k + 8, Blocks.stone_brick_stairs, 3, 0x02);
		world.setBlock(i + 7, j + 0, k + 9, Blocks.sandstone);
		world.setBlock(i + 7, j + 0, k + 10, Blocks.sandstone, 1, 0x02);
		world.setBlock(i + 7, j + 0, k + 11, Blocks.sandstone_stairs, 2, 0x02);
		world.setBlock(i + 7, j + 0, k + 12, Blocks.sandstone);
		world.setBlock(i + 7, j + 1, k + 2, Blocks.fence);
		world.setBlock(i + 7, j + 1, k + 10, Blocks.fence);
		world.setBlock(i + 7, j + 2, k + 2, Blocks.fence);
		world.setBlock(i + 7, j + 2, k + 10, Blocks.fence);
		world.setBlock(i + 7, j + 3, k + 2, Blocks.sandstone, 2, 0x02);
		world.setBlock(i + 7, j + 3, k + 10, Blocks.sandstone, 2, 0x02);
		world.setBlock(i + 7, j + 4, k + 2, Blocks.wool, 13, 0x02);
		world.setBlock(i + 7, j + 4, k + 3, Blocks.planks);
		world.setBlock(i + 7, j + 4, k + 4, Blocks.planks);
		world.setBlock(i + 7, j + 4, k + 5, Blocks.planks);
		world.setBlock(i + 7, j + 4, k + 7, Blocks.planks);
		world.setBlock(i + 7, j + 4, k + 8, Blocks.planks);
		world.setBlock(i + 7, j + 4, k + 9, Blocks.planks);
		world.setBlock(i + 7, j + 4, k + 10, Blocks.wool, 13, 0x02);
		world.setBlock(i + 7, j + 5, k + 2, Blocks.fence);
		world.setBlock(i + 7, j + 5, k + 10, Blocks.fence);
		world.setBlock(i + 7, j + 6, k + 2, Blocks.fence);
		world.setBlock(i + 7, j + 6, k + 10, Blocks.fence);
		world.setBlock(i + 7, j + 7, k + 2, Blocks.sandstone, 2, 0x02);
		world.setBlock(i + 7, j + 7, k + 10, Blocks.sandstone, 2, 0x02);
		world.setBlock(i + 7, j + 8, k + 2, Blocks.wool, 13, 0x02);
		world.setBlock(i + 7, j + 8, k + 3, Blocks.planks);
		world.setBlock(i + 7, j + 8, k + 4, Blocks.planks);
		world.setBlock(i + 7, j + 8, k + 5, Blocks.planks);
		world.setBlock(i + 7, j + 8, k + 7, Blocks.planks);
		world.setBlock(i + 7, j + 8, k + 8, Blocks.planks);
		world.setBlock(i + 7, j + 8, k + 9, Blocks.planks);
		world.setBlock(i + 7, j + 8, k + 10, Blocks.wool, 13, 0x02);
		world.setBlock(i + 7, j + 9, k + 3, Blocks.sandstone, 1, 0x02);
		world.setBlock(i + 7, j + 9, k + 9, Blocks.sandstone, 1, 0x02);
		world.setBlock(i + 7, j + 10, k + 3, Blocks.sandstone, 2, 0x02);
		world.setBlock(i + 7, j + 10, k + 9, Blocks.sandstone, 2, 0x02);
		world.setBlock(i + 7, j + 11, k + 3, Blocks.sandstone, 2, 0x02);
		world.setBlock(i + 7, j + 11, k + 9, Blocks.sandstone, 2, 0x02);
		world.setBlock(i + 7, j + 12, k + 2, Blocks.wool, 13, 0x02);
		world.setBlock(i + 7, j + 12, k + 3, Blocks.wool, 13, 0x02);
		world.setBlock(i + 7, j + 12, k + 4, Blocks.planks);
		world.setBlock(i + 7, j + 12, k + 5, Blocks.planks);
		world.setBlock(i + 7, j + 12, k + 7, Blocks.planks);
		world.setBlock(i + 7, j + 12, k + 8, Blocks.planks);
		world.setBlock(i + 7, j + 12, k + 9, Blocks.wool, 13, 0x02);
		world.setBlock(i + 7, j + 12, k + 10, Blocks.wool, 13, 0x02);
		world.setBlock(i + 7, j + 13, k + 3, Blocks.sandstone, 1, 0x02);
		world.setBlock(i + 7, j + 13, k + 9, Blocks.sandstone, 1, 0x02);
		world.setBlock(i + 7, j + 14, k + 3, Blocks.sandstone, 2, 0x02);
		world.setBlock(i + 7, j + 14, k + 9, Blocks.sandstone, 2, 0x02);
		world.setBlock(i + 7, j + 15, k + 3, Blocks.sandstone, 2, 0x02);
		world.setBlock(i + 7, j + 15, k + 9, Blocks.sandstone, 2, 0x02);
		world.setBlock(i + 7, j + 16, k + 2, Blocks.wool, 13, 0x02);
		world.setBlock(i + 7, j + 16, k + 3, Blocks.sandstone, 2, 0x02);
		world.setBlock(i + 7, j + 16, k + 4, Blocks.stone_slab, 9, 0x02);
		world.setBlock(i + 7, j + 16, k + 8, Blocks.stone_slab, 9, 0x02);
		world.setBlock(i + 7, j + 16, k + 9, Blocks.sandstone, 2, 0x02);
		world.setBlock(i + 7, j + 16, k + 10, Blocks.wool, 13, 0x02);
		world.setBlock(i + 7, j + 17, k + 5, Blocks.sandstone_stairs, 2, 0x02);
		world.setBlock(i + 7, j + 17, k + 6, Blocks.sandstone_stairs, 1, 0x02);
		world.setBlock(i + 7, j + 17, k + 7, Blocks.sandstone_stairs, 3, 0x02);
		world.setBlock(i + 8, j + 0, k + 0, Blocks.sandstone);
		world.setBlock(i + 8, j + 0, k + 1, Blocks.sandstone_stairs, 2, 0x02);
		world.setBlock(i + 8, j + 0, k + 2, Blocks.sandstone);
		world.setBlock(i + 8, j + 0, k + 3, Blocks.sandstone, 1, 0x02);
		world.setBlock(i + 8, j + 0, k + 4, Blocks.sandstone);
		world.setBlock(i + 8, j + 0, k + 5, Blocks.stone_brick_stairs);
		world.setBlock(i + 8, j + 0, k + 6, Blocks.stone_brick_stairs, 1, 0x02);
		world.setBlock(i + 8, j + 0, k + 7, Blocks.stone_brick_stairs);
		world.setBlock(i + 8, j + 0, k + 8, Blocks.sandstone);
		world.setBlock(i + 8, j + 0, k + 9, Blocks.sandstone, 1, 0x02);
		world.setBlock(i + 8, j + 0, k + 10, Blocks.sandstone);
		world.setBlock(i + 8, j + 0, k + 11, Blocks.sandstone_stairs, 3, 0x02);
		world.setBlock(i + 8, j + 0, k + 12, Blocks.sandstone);
		world.setBlock(i + 8, j + 1, k + 3, Blocks.sandstone, 1, 0x02);
		world.setBlock(i + 8, j + 1, k + 9, Blocks.sandstone, 1, 0x02);
		world.setBlock(i + 8, j + 2, k + 3, Blocks.sandstone, 2, 0x02);
		world.setBlock(i + 8, j + 2, k + 9, Blocks.sandstone, 2, 0x02);
		world.setBlock(i + 8, j + 3, k + 3, Blocks.sandstone, 2, 0x02);
		world.setBlock(i + 8, j + 3, k + 9, Blocks.sandstone, 2, 0x02);
		world.setBlock(i + 8, j + 4, k + 3, Blocks.wool, 13, 0x02);
		world.setBlock(i + 8, j + 4, k + 4, Blocks.planks);
		world.setBlock(i + 8, j + 4, k + 5, Blocks.planks);
		world.setBlock(i + 8, j + 4, k + 6, Blocks.planks);
		world.setBlock(i + 8, j + 4, k + 7, Blocks.planks);
		world.setBlock(i + 8, j + 4, k + 8, Blocks.planks);
		world.setBlock(i + 8, j + 4, k + 9, Blocks.wool, 13, 0x02);
		world.setBlock(i + 8, j + 5, k + 3, Blocks.sandstone, 1, 0x02);
		world.setBlock(i + 8, j + 5, k + 9, Blocks.sandstone, 1, 0x02);
		world.setBlock(i + 8, j + 6, k + 3, Blocks.sandstone, 2, 0x02);
		world.setBlock(i + 8, j + 6, k + 9, Blocks.sandstone, 2, 0x02);
		world.setBlock(i + 8, j + 7, k + 3, Blocks.sandstone, 2, 0x02);
		world.setBlock(i + 8, j + 7, k + 9, Blocks.sandstone, 2, 0x02);
		world.setBlock(i + 8, j + 8, k + 3, Blocks.wool, 13, 0x02);
		world.setBlock(i + 8, j + 8, k + 4, Blocks.planks);
		world.setBlock(i + 8, j + 8, k + 5, Blocks.planks);
		world.setBlock(i + 8, j + 8, k + 6, Blocks.planks);
		world.setBlock(i + 8, j + 8, k + 7, Blocks.planks);
		world.setBlock(i + 8, j + 8, k + 8, Blocks.planks);
		world.setBlock(i + 8, j + 8, k + 9, Blocks.wool, 13, 0x02);
		world.setBlock(i + 8, j + 9, k + 4, Blocks.sandstone, 1, 0x02);
		world.setBlock(i + 8, j + 9, k + 8, Blocks.sandstone, 1, 0x02);
		world.setBlock(i + 8, j + 10, k + 4, Blocks.sandstone, 2, 0x02);
		world.setBlock(i + 8, j + 10, k + 8, Blocks.sandstone, 2, 0x02);
		world.setBlock(i + 8, j + 11, k + 4, Blocks.sandstone, 2, 0x02);
		world.setBlock(i + 8, j + 11, k + 8, Blocks.sandstone, 2, 0x02);
		world.setBlock(i + 8, j + 12, k + 3, Blocks.wool, 13, 0x02);
		world.setBlock(i + 8, j + 12, k + 4, Blocks.wool, 13, 0x02);
		world.setBlock(i + 8, j + 12, k + 5, Blocks.planks);
		world.setBlock(i + 8, j + 12, k + 6, Blocks.planks);
		world.setBlock(i + 8, j + 12, k + 7, Blocks.planks);
		world.setBlock(i + 8, j + 12, k + 8, Blocks.wool, 13, 0x02);
		world.setBlock(i + 8, j + 12, k + 9, Blocks.wool, 13, 0x02);
		world.setBlock(i + 8, j + 13, k + 4, Blocks.sandstone, 1, 0x02);
		world.setBlock(i + 8, j + 13, k + 8, Blocks.sandstone, 1, 0x02);
		world.setBlock(i + 8, j + 14, k + 4, Blocks.sandstone, 2, 0x02);
		world.setBlock(i + 8, j + 14, k + 8, Blocks.sandstone, 2, 0x02);
		world.setBlock(i + 8, j + 15, k + 4, Blocks.sandstone, 2, 0x02);
		world.setBlock(i + 8, j + 15, k + 8, Blocks.sandstone, 2, 0x02);
		world.setBlock(i + 8, j + 16, k + 3, Blocks.wool, 13, 0x02);
		world.setBlock(i + 8, j + 16, k + 4, Blocks.sandstone, 2, 0x02);
		world.setBlock(i + 8, j + 16, k + 5, Blocks.stone_slab, 9, 0x02);
		world.setBlock(i + 8, j + 16, k + 6, Blocks.stone_slab, 9, 0x02);
		world.setBlock(i + 8, j + 16, k + 7, Blocks.stone_slab, 9, 0x02);
		world.setBlock(i + 8, j + 16, k + 8, Blocks.sandstone, 2, 0x02);
		world.setBlock(i + 8, j + 16, k + 9, Blocks.wool, 13, 0x02);
		world.setBlock(i + 9, j + 0, k + 0, Blocks.sandstone);
		world.setBlock(i + 9, j + 0, k + 1, Blocks.sandstone_stairs, 3, 0x02);
		world.setBlock(i + 9, j + 0, k + 2, Blocks.sandstone);
		world.setBlock(i + 9, j + 0, k + 3, Blocks.sandstone);
		world.setBlock(i + 9, j + 0, k + 4, Blocks.sandstone, 1, 0x02);
		world.setBlock(i + 9, j + 0, k + 5, Blocks.sandstone);
		world.setBlock(i + 9, j + 0, k + 6, Blocks.sandstone);
		world.setBlock(i + 9, j + 0, k + 7, Blocks.sandstone);
		world.setBlock(i + 9, j + 0, k + 8, Blocks.sandstone, 1, 0x02);
		world.setBlock(i + 9, j + 0, k + 9, Blocks.sandstone);
		world.setBlock(i + 9, j + 0, k + 10, Blocks.sandstone);
		world.setBlock(i + 9, j + 0, k + 11, Blocks.sandstone_stairs, 2, 0x02);
		world.setBlock(i + 9, j + 0, k + 12, Blocks.sandstone);
		world.setBlock(i + 9, j + 1, k + 4, Blocks.sandstone, 1, 0x02);
		world.setBlock(i + 9, j + 1, k + 8, Blocks.sandstone, 1, 0x02);
		world.setBlock(i + 9, j + 2, k + 4, Blocks.sandstone, 2, 0x02);
		world.setBlock(i + 9, j + 2, k + 8, Blocks.sandstone, 2, 0x02);
		world.setBlock(i + 9, j + 3, k + 4, Blocks.sandstone, 2, 0x02);
		world.setBlock(i + 9, j + 3, k + 8, Blocks.sandstone, 2, 0x02);
		world.setBlock(i + 9, j + 4, k + 4, Blocks.wool, 13, 0x02);
		world.setBlock(i + 9, j + 4, k + 5, Blocks.planks);
		world.setBlock(i + 9, j + 4, k + 6, Blocks.planks);
		world.setBlock(i + 9, j + 4, k + 7, Blocks.planks);
		world.setBlock(i + 9, j + 4, k + 8, Blocks.wool, 13, 0x02);
		world.setBlock(i + 9, j + 5, k + 4, Blocks.sandstone, 1, 0x02);
		world.setBlock(i + 9, j + 5, k + 8, Blocks.sandstone, 1, 0x02);
		world.setBlock(i + 9, j + 6, k + 4, Blocks.sandstone, 2, 0x02);
		world.setBlock(i + 9, j + 6, k + 8, Blocks.sandstone, 2, 0x02);
		world.setBlock(i + 9, j + 7, k + 4, Blocks.sandstone, 2, 0x02);
		world.setBlock(i + 9, j + 7, k + 8, Blocks.sandstone, 2, 0x02);
		world.setBlock(i + 9, j + 8, k + 4, Blocks.wool, 13, 0x02);
		world.setBlock(i + 9, j + 8, k + 5, Blocks.planks);
		world.setBlock(i + 9, j + 8, k + 6, Blocks.planks);
		world.setBlock(i + 9, j + 8, k + 7, Blocks.planks);
		world.setBlock(i + 9, j + 8, k + 8, Blocks.wool, 13, 0x02);
		world.setBlock(i + 9, j + 9, k + 5, Blocks.sandstone, 1, 0x02);
		world.setBlock(i + 9, j + 9, k + 6, Blocks.sandstone, 1, 0x02);
		world.setBlock(i + 9, j + 9, k + 7, Blocks.sandstone, 1, 0x02);
		world.setBlock(i + 9, j + 10, k + 5, Blocks.sandstone, 2, 0x02);
		world.setBlock(i + 9, j + 10, k + 6, Blocks.fence);
		world.setBlock(i + 9, j + 10, k + 7, Blocks.sandstone, 2, 0x02);
		world.setBlock(i + 9, j + 11, k + 5, Blocks.sandstone, 2, 0x02);
		world.setBlock(i + 9, j + 11, k + 6, Blocks.fence);
		world.setBlock(i + 9, j + 11, k + 7, Blocks.sandstone, 2, 0x02);
		world.setBlock(i + 9, j + 12, k + 4, Blocks.wool, 13, 0x02);
		world.setBlock(i + 9, j + 12, k + 5, Blocks.wool, 13, 0x02);
		world.setBlock(i + 9, j + 12, k + 6, Blocks.wool, 13, 0x02);
		world.setBlock(i + 9, j + 12, k + 7, Blocks.wool, 13, 0x02);
		world.setBlock(i + 9, j + 12, k + 8, Blocks.wool, 13, 0x02);
		world.setBlock(i + 9, j + 13, k + 5, Blocks.sandstone, 1, 0x02);
		world.setBlock(i + 9, j + 13, k + 6, Blocks.sandstone, 1, 0x02);
		world.setBlock(i + 9, j + 13, k + 7, Blocks.sandstone, 1, 0x02);
		world.setBlock(i + 9, j + 14, k + 5, Blocks.sandstone, 2, 0x02);
		world.setBlock(i + 9, j + 14, k + 6, Blocks.fence);
		world.setBlock(i + 9, j + 14, k + 7, Blocks.sandstone, 2, 0x02);
		world.setBlock(i + 9, j + 15, k + 5, Blocks.sandstone, 2, 0x02);
		world.setBlock(i + 9, j + 15, k + 6, Blocks.fence);
		world.setBlock(i + 9, j + 15, k + 7, Blocks.sandstone, 2, 0x02);
		world.setBlock(i + 9, j + 16, k + 4, Blocks.wool, 13, 0x02);
		world.setBlock(i + 9, j + 16, k + 5, Blocks.sandstone, 2, 0x02);
		world.setBlock(i + 9, j + 16, k + 6, Blocks.sandstone, 2, 0x02);
		world.setBlock(i + 9, j + 16, k + 7, Blocks.sandstone, 2, 0x02);
		world.setBlock(i + 9, j + 16, k + 8, Blocks.wool, 13, 0x02);
		world.setBlock(i + 10, j + 0, k + 0, Blocks.sandstone);
		world.setBlock(i + 10, j + 0, k + 1, Blocks.sandstone_stairs, 2, 0x02);
		world.setBlock(i + 10, j + 0, k + 2, Blocks.sandstone);
		world.setBlock(i + 10, j + 0, k + 3, Blocks.sandstone);
		world.setBlock(i + 10, j + 0, k + 4, Blocks.sandstone);
		world.setBlock(i + 10, j + 0, k + 5, Blocks.sandstone, 1, 0x02);
		world.setBlock(i + 10, j + 0, k + 6, Blocks.sandstone, 1, 0x02);
		world.setBlock(i + 10, j + 0, k + 7, Blocks.sandstone, 1, 0x02);
		world.setBlock(i + 10, j + 0, k + 8, Blocks.sandstone);
		world.setBlock(i + 10, j + 0, k + 9, Blocks.sandstone);
		world.setBlock(i + 10, j + 0, k + 10, Blocks.sandstone);
		world.setBlock(i + 10, j + 0, k + 11, Blocks.sandstone_stairs, 3, 0x02);
		world.setBlock(i + 10, j + 0, k + 12, Blocks.sandstone);
		world.setBlock(i + 10, j + 1, k + 4, Blocks.fence);
		world.setBlock(i + 10, j + 1, k + 7, Blocks.fence);
		world.setBlock(i + 10, j + 2, k + 4, Blocks.fence);
		world.setBlock(i + 10, j + 2, k + 7, Blocks.fence);
		world.setBlock(i + 10, j + 3, k + 5, Blocks.sandstone, 2, 0x02);
		world.setBlock(i + 10, j + 3, k + 7, Blocks.sandstone, 2, 0x02);
		world.setBlock(i + 10, j + 4, k + 5, Blocks.wool, 13, 0x02);
		world.setBlock(i + 10, j + 4, k + 6, Blocks.wool, 13, 0x02);
		world.setBlock(i + 10, j + 4, k + 7, Blocks.wool, 13, 0x02);
		world.setBlock(i + 10, j + 5, k + 5, Blocks.fence);
		world.setBlock(i + 10, j + 5, k + 7, Blocks.fence);
		world.setBlock(i + 10, j + 6, k + 5, Blocks.fence);
		world.setBlock(i + 10, j + 6, k + 7, Blocks.fence);
		world.setBlock(i + 10, j + 7, k + 5, Blocks.sandstone, 2, 0x02);
		world.setBlock(i + 10, j + 7, k + 7, Blocks.sandstone, 2, 0x02);
		world.setBlock(i + 10, j + 8, k + 5, Blocks.wool, 13, 0x02);
		world.setBlock(i + 10, j + 8, k + 6, Blocks.wool, 13, 0x02);
		world.setBlock(i + 10, j + 8, k + 7, Blocks.wool, 13, 0x02);
		world.setBlock(i + 10, j + 12, k + 5, Blocks.wool, 13, 0x02);
		world.setBlock(i + 10, j + 12, k + 6, Blocks.wool, 13, 0x02);
		world.setBlock(i + 10, j + 12, k + 7, Blocks.wool, 13, 0x02);
		world.setBlock(i + 10, j + 16, k + 5, Blocks.wool, 13, 0x02);
		world.setBlock(i + 10, j + 16, k + 6, Blocks.wool, 13, 0x02);
		world.setBlock(i + 10, j + 16, k + 7, Blocks.wool, 13, 0x02);
		world.setBlock(i + 11, j + 0, k + 0, Blocks.sandstone);
		world.setBlock(i + 11, j + 0, k + 1, Blocks.sandstone);
		world.setBlock(i + 11, j + 0, k + 2, Blocks.sandstone_stairs, 1, 0x02);
		world.setBlock(i + 11, j + 0, k + 3, Blocks.sandstone_stairs);
		world.setBlock(i + 11, j + 0, k + 4, Blocks.sandstone_stairs, 1, 0x02);
		world.setBlock(i + 11, j + 0, k + 5, Blocks.sandstone_stairs);
		world.setBlock(i + 11, j + 0, k + 6, Blocks.sandstone_stairs, 1, 0x02);
		world.setBlock(i + 11, j + 0, k + 7, Blocks.sandstone_stairs);
		world.setBlock(i + 11, j + 0, k + 8, Blocks.sandstone_stairs, 1, 0x02);
		world.setBlock(i + 11, j + 0, k + 9, Blocks.sandstone_stairs);
		world.setBlock(i + 11, j + 0, k + 10, Blocks.sandstone_stairs, 1, 0x02);
		world.setBlock(i + 11, j + 0, k + 11, Blocks.sandstone);
		world.setBlock(i + 11, j + 0, k + 12, Blocks.sandstone);
		world.setBlock(i + 12, j + 0, k + 0, Blocks.grass);
		world.setBlock(i + 12, j + 0, k + 1, Blocks.sandstone);
		world.setBlock(i + 12, j + 0, k + 2, Blocks.sandstone);
		world.setBlock(i + 12, j + 0, k + 3, Blocks.sandstone);
		world.setBlock(i + 12, j + 0, k + 4, Blocks.sandstone);
		world.setBlock(i + 12, j + 0, k + 5, Blocks.sandstone);
		world.setBlock(i + 12, j + 0, k + 6, Blocks.sandstone);
		world.setBlock(i + 12, j + 0, k + 7, Blocks.sandstone);
		world.setBlock(i + 12, j + 0, k + 8, Blocks.sandstone);
		world.setBlock(i + 12, j + 0, k + 9, Blocks.sandstone);
		world.setBlock(i + 12, j + 0, k + 10, Blocks.sandstone);
		world.setBlock(i + 12, j + 0, k + 11, Blocks.sandstone);
		world.setBlock(i + 12, j + 0, k + 12, Blocks.grass);
		world.setBlock(i + 4, j + 7, k + 4, Blocks.torch, 3, 0x02);
		world.setBlock(i + 4, j + 7, k + 8, Blocks.torch, 4, 0x02);
		world.setBlock(i + 4, j + 11, k + 5, Blocks.torch, 3, 0x02);
		world.setBlock(i + 4, j + 11, k + 7, Blocks.torch, 4, 0x02);
		world.setBlock(i + 5, j + 2, k + 6, Blocks.ladder, 4, 0x02);
		world.setBlock(i + 5, j + 3, k + 6, Blocks.ladder, 4, 0x02);
		world.setBlock(i + 5, j + 4, k + 6, Blocks.ladder, 4, 0x02);
		world.setBlock(i + 5, j + 5, k + 6, Blocks.ladder, 4, 0x02);
		world.setBlock(i + 5, j + 6, k + 6, Blocks.ladder, 4, 0x02);
		world.setBlock(i + 5, j + 7, k + 6, Blocks.ladder, 4, 0x02);
		world.setBlock(i + 5, j + 8, k + 6, Blocks.ladder, 4, 0x02);
		world.setBlock(i + 5, j + 9, k + 6, Blocks.ladder, 4, 0x02);
		world.setBlock(i + 5, j + 10, k + 6, Blocks.ladder, 4, 0x02);
		world.setBlock(i + 5, j + 11, k + 4, Blocks.torch, 1, 0x02);
		world.setBlock(i + 5, j + 11, k + 6, Blocks.ladder, 4, 0x02);
		world.setBlock(i + 5, j + 11, k + 8, Blocks.torch, 1, 0x02);
		world.setBlock(i + 5, j + 12, k + 6, Blocks.ladder, 4, 0x02);
		world.setBlock(i + 6, j + 2, k + 5, Blocks.ladder, 2, 0x02);;
		world.setBlock(i + 6, j + 2, k + 7, Blocks.ladder, 3, 0x02);
		world.setBlock(i + 6, j + 3, k + 5, Blocks.ladder, 2, 0x02);;
		world.setBlock(i + 6, j + 3, k + 7, Blocks.ladder, 3, 0x02);
		world.setBlock(i + 6, j + 4, k + 5, Blocks.ladder, 2, 0x02);;
		world.setBlock(i + 6, j + 4, k + 7, Blocks.ladder, 3, 0x02);
		world.setBlock(i + 6, j + 5, k + 5, Blocks.ladder, 2, 0x02);;
		world.setBlock(i + 6, j + 5, k + 7, Blocks.ladder, 3, 0x02);
		world.setBlock(i + 6, j + 6, k + 5, Blocks.ladder, 2, 0x02);;
		world.setBlock(i + 6, j + 6, k + 7, Blocks.ladder, 3, 0x02);
		world.setBlock(i + 6, j + 7, k + 5, Blocks.ladder, 2, 0x02);;
		world.setBlock(i + 6, j + 7, k + 7, Blocks.ladder, 3, 0x02);
		world.setBlock(i + 6, j + 8, k + 5, Blocks.ladder, 2, 0x02);;
		world.setBlock(i + 6, j + 8, k + 7, Blocks.ladder, 3, 0x02);
		world.setBlock(i + 6, j + 9, k + 5, Blocks.ladder, 2, 0x02);;
		world.setBlock(i + 6, j + 9, k + 7, Blocks.ladder, 3, 0x02);
		world.setBlock(i + 6, j + 10, k + 5, Blocks.ladder, 2, 0x02);;
		world.setBlock(i + 6, j + 10, k + 7, Blocks.ladder, 3, 0x02);
		world.setBlock(i + 6, j + 11, k + 5, Blocks.ladder, 2, 0x02);;
		world.setBlock(i + 6, j + 11, k + 7, Blocks.ladder, 3, 0x02);
		world.setBlock(i + 6, j + 12, k + 5, Blocks.ladder, 2, 0x02);;
		world.setBlock(i + 6, j + 12, k + 7, Blocks.ladder, 3, 0x02);
		world.setBlock(i + 7, j + 2, k + 6, Blocks.ladder, 5, 0x02);;
		world.setBlock(i + 7, j + 3, k + 6, Blocks.ladder, 5, 0x02);;
		world.setBlock(i + 7, j + 4, k + 6, Blocks.ladder, 5, 0x02);;
		world.setBlock(i + 7, j + 5, k + 6, Blocks.ladder, 5, 0x02);;
		world.setBlock(i + 7, j + 6, k + 6, Blocks.ladder, 5, 0x02);;
		world.setBlock(i + 7, j + 7, k + 6, Blocks.ladder, 5, 0x02);;
		world.setBlock(i + 7, j + 8, k + 6, Blocks.ladder, 5, 0x02);;
		world.setBlock(i + 7, j + 9, k + 6, Blocks.ladder, 5, 0x02);;
		world.setBlock(i + 7, j + 10, k + 6, Blocks.ladder, 5, 0x02);;
		world.setBlock(i + 7, j + 11, k + 4, Blocks.torch, 2, 0x02);
		world.setBlock(i + 7, j + 11, k + 6, Blocks.ladder, 5, 0x02);;
		world.setBlock(i + 7, j + 11, k + 8, Blocks.torch, 2, 0x02);
		world.setBlock(i + 7, j + 12, k + 6, Blocks.ladder, 5, 0x02);;
		world.setBlock(i + 8, j + 7, k + 4, Blocks.torch, 3, 0x02);
		world.setBlock(i + 8, j + 7, k + 8, Blocks.torch, 4, 0x02);
		world.setBlock(i + 8, j + 11, k + 5, Blocks.torch, 3, 0x02);
		world.setBlock(i + 8, j + 11, k + 7, Blocks.torch, 4, 0x02);

		return true;
	}
}