package kieranvs.avatar.generation;

import java.util.Random;

import kieranvs.avatar.mod_Avatar;
import kieranvs.avatar.bending.ElementManager;
import kieranvs.avatar.entity.EntityAirMan;
import kieranvs.avatar.entity.EntityAirWoman;
import kieranvs.avatar.util.GenerationUtils;

import net.minecraft.block.Block;
import net.minecraft.init.Blocks;
import net.minecraft.item.ItemStack;
import net.minecraft.tileentity.TileEntity;
import net.minecraft.tileentity.TileEntityChest;
import net.minecraft.world.World;
import net.minecraft.world.biome.BiomeGenBase;
import net.minecraft.world.chunk.IChunkProvider;

import cpw.mods.fml.common.IWorldGenerator;

public class WorldGenAirNomadTemple implements IWorldGenerator {
	
	private static BiomeGenBase[] biomes = {BiomeGenBase.extremeHills, BiomeGenBase.extremeHillsPlus, BiomeGenBase.stoneBeach};
	
	public void generate(Random random, int chunkX, int chunkZ, World world, IChunkProvider chunkGenerator, IChunkProvider chunkProvider) {
		int[] result = GenerationUtils.shouldSpawnHere(random, chunkX, chunkZ, world, 12, 3, 20, biomes);
		if(result[0] == 0){
			this.generate(world, result[1], result[2] - 5, result[3]);
			this.generateEntities(world, result[1], result[2] - 5, result[3], random);
		}
	}
	
	public void generateEntities(World world, int i, int j, int k, Random random) {
		int numW = random.nextInt(2) + 1;

		for (int x = 0; x < numW; x++) {
			EntityAirWoman airWoman = new EntityAirWoman(world, i + 6, j + 6, k + 6, 6);
			airWoman.setPositionAndRotation(i + 6, j + 6, k + 6, 1.0F, 1.0F);
			world.spawnEntityInWorld(airWoman);
		}

	}	

	public boolean generate(World world, int i, int j, int k) {

		for (int x = 0; x <= 12; x++) {
			for (int z = 0; z <= 12; z++) {
				for (int y = 0; y < 14; y++) {
					world.setBlock(i + x, j + y, k + z, Blocks.air);
				}
			}
		}

		world.setBlock(i + 0, j + 0, k + 0, Blocks.dirt);
		world.setBlock(i + 0, j + 0, k + 1, Blocks.dirt);
		world.setBlock(i + 0, j + 0, k + 2, Blocks.dirt);
		world.setBlock(i + 0, j + 0, k + 3, Blocks.dirt);
		world.setBlock(i + 0, j + 0, k + 4, Blocks.dirt);
		world.setBlock(i + 0, j + 0, k + 5, Blocks.dirt);
		world.setBlock(i + 0, j + 0, k + 6, Blocks.dirt);
		world.setBlock(i + 0, j + 0, k + 7, Blocks.dirt);
		world.setBlock(i + 0, j + 0, k + 8, Blocks.dirt);
		world.setBlock(i + 0, j + 0, k + 9, Blocks.dirt);
		world.setBlock(i + 0, j + 0, k + 10, Blocks.dirt);
		world.setBlock(i + 0, j + 0, k + 11, Blocks.dirt);
		world.setBlock(i + 0, j + 0, k + 12, Blocks.dirt);
		world.setBlock(i + 0, j + 1, k + 0, Blocks.dirt);
		world.setBlock(i + 0, j + 1, k + 1, Blocks.dirt);
		world.setBlock(i + 0, j + 1, k + 2, Blocks.dirt);
		world.setBlock(i + 0, j + 1, k + 3, Blocks.dirt);
		world.setBlock(i + 0, j + 1, k + 4, Blocks.dirt);
		world.setBlock(i + 0, j + 1, k + 5, Blocks.dirt);
		world.setBlock(i + 0, j + 1, k + 6, Blocks.dirt);
		world.setBlock(i + 0, j + 1, k + 7, Blocks.dirt);
		world.setBlock(i + 0, j + 1, k + 8, Blocks.dirt);
		world.setBlock(i + 0, j + 1, k + 9, Blocks.dirt);
		world.setBlock(i + 0, j + 1, k + 10, Blocks.dirt);
		world.setBlock(i + 0, j + 1, k + 11, Blocks.dirt);
		world.setBlock(i + 0, j + 1, k + 12, Blocks.dirt);
		world.setBlock(i + 0, j + 2, k + 0, Blocks.grass);
		world.setBlock(i + 0, j + 2, k + 1, Blocks.grass);
		world.setBlock(i + 0, j + 2, k + 2, Blocks.grass);
		world.setBlock(i + 0, j + 2, k + 3, Blocks.grass);
		world.setBlock(i + 0, j + 2, k + 4, Blocks.grass);
		world.setBlock(i + 0, j + 2, k + 5, Blocks.grass);
		world.setBlock(i + 0, j + 2, k + 6, Blocks.dirt);
		world.setBlock(i + 0, j + 2, k + 7, Blocks.dirt);
		world.setBlock(i + 0, j + 2, k + 8, Blocks.dirt);
		world.setBlock(i + 0, j + 2, k + 9, Blocks.dirt);
		world.setBlock(i + 0, j + 2, k + 10, Blocks.dirt);
		world.setBlock(i + 0, j + 2, k + 11, Blocks.dirt);
		world.setBlock(i + 0, j + 2, k + 12, Blocks.dirt);
		world.setBlock(i + 0, j + 3, k + 0, Blocks.dirt);
		world.setBlock(i + 0, j + 3, k + 1, Blocks.dirt);
		world.setBlock(i + 0, j + 3, k + 2, Blocks.dirt);
		world.setBlock(i + 0, j + 3, k + 3, Blocks.dirt);
		world.setBlock(i + 0, j + 3, k + 4, Blocks.dirt);
		world.setBlock(i + 0, j + 3, k + 5, Blocks.dirt);
		world.setBlock(i + 0, j + 3, k + 6, Blocks.dirt);
		world.setBlock(i + 0, j + 3, k + 7, Blocks.dirt);
		world.setBlock(i + 0, j + 3, k + 8, Blocks.dirt);
		world.setBlock(i + 0, j + 3, k + 9, Blocks.dirt);
		world.setBlock(i + 0, j + 3, k + 10, Blocks.dirt);
		world.setBlock(i + 0, j + 3, k + 11, Blocks.dirt);
		world.setBlock(i + 0, j + 3, k + 12, Blocks.dirt);
		world.setBlock(i + 0, j + 4, k + 0, Blocks.dirt);
		world.setBlock(i + 0, j + 4, k + 1, Blocks.dirt);
		world.setBlock(i + 0, j + 4, k + 2, Blocks.dirt);
		world.setBlock(i + 0, j + 4, k + 3, Blocks.dirt);
		world.setBlock(i + 0, j + 4, k + 4, Blocks.dirt);
		world.setBlock(i + 0, j + 4, k + 5, Blocks.dirt);
		world.setBlock(i + 0, j + 4, k + 6, Blocks.dirt);
		world.setBlock(i + 0, j + 4, k + 7, Blocks.dirt);
		world.setBlock(i + 0, j + 4, k + 8, Blocks.dirt);
		world.setBlock(i + 0, j + 4, k + 9, Blocks.dirt);
		world.setBlock(i + 0, j + 4, k + 10, Blocks.dirt);
		world.setBlock(i + 0, j + 4, k + 11, Blocks.dirt);
		world.setBlock(i + 0, j + 4, k + 12, Blocks.dirt);
		world.setBlock(i + 0, j + 5, k + 0, Blocks.grass);
		world.setBlock(i + 0, j + 5, k + 1, Blocks.grass);
		world.setBlock(i + 0, j + 5, k + 2, Blocks.grass);
		world.setBlock(i + 0, j + 5, k + 3, Blocks.grass);
		world.setBlock(i + 0, j + 5, k + 4, Blocks.nether_brick);
		world.setBlock(i + 0, j + 5, k + 5, Blocks.nether_brick);
		world.setBlock(i + 0, j + 5, k + 6, Blocks.nether_brick);
		world.setBlock(i + 0, j + 5, k + 7, Blocks.nether_brick);
		world.setBlock(i + 0, j + 5, k + 8, Blocks.nether_brick);
		world.setBlock(i + 0, j + 5, k + 9, Blocks.grass);
		world.setBlock(i + 0, j + 5, k + 10, Blocks.grass);
		world.setBlock(i + 0, j + 5, k + 11, Blocks.grass);
		world.setBlock(i + 0, j + 5, k + 12, Blocks.grass);
		world.setBlock(i + 0, j + 6, k + 4, Blocks.sandstone, 1, 0x02);
		world.setBlock(i + 0, j + 6, k + 8, Blocks.sandstone, 1, 0x02);
		world.setBlock(i + 0, j + 7, k + 4, Blocks.sandstone, 1, 0x02);
		world.setBlock(i + 0, j + 7, k + 8, Blocks.sandstone, 1, 0x02);
		world.setBlock(i + 0, j + 8, k + 4, Blocks.sandstone, 1, 0x02);
		world.setBlock(i + 0, j + 8, k + 8, Blocks.sandstone, 1, 0x02);
		world.setBlock(i + 0, j + 9, k + 4, Blocks.sandstone, 1, 0x02);
		world.setBlock(i + 0, j + 9, k + 8, Blocks.sandstone, 1, 0x02);
		world.setBlock(i + 0, j + 10, k + 1, Blocks.nether_brick_stairs, 2, 0x02);
		world.setBlock(i + 0, j + 10, k + 2, Blocks.nether_brick_stairs);
		world.setBlock(i + 0, j + 10, k + 3, Blocks.nether_brick_stairs);
		world.setBlock(i + 0, j + 10, k + 4, Blocks.sandstone, 1, 0x02);
		world.setBlock(i + 0, j + 10, k + 5, Blocks.nether_brick_stairs, 7, 0x02);
		world.setBlock(i + 0, j + 10, k + 7, Blocks.nether_brick_stairs, 6, 0x02);
		world.setBlock(i + 0, j + 10, k + 8, Blocks.sandstone, 1, 0x02);
		world.setBlock(i + 0, j + 10, k + 9, Blocks.nether_brick_stairs);
		world.setBlock(i + 0, j + 10, k + 10, Blocks.nether_brick_stairs);
		world.setBlock(i + 0, j + 10, k + 11, Blocks.nether_brick_stairs, 3, 0x02);
		world.setBlock(i + 0, j + 11, k + 5, Blocks.sandstone, 1, 0x02);
		world.setBlock(i + 0, j + 11, k + 6, mod_Avatar.AirNomadsBlock);
		world.setBlock(i + 0, j + 11, k + 7, Blocks.sandstone, 1, 0x02);
		world.setBlock(i + 0, j + 12, k + 6, Blocks.sandstone, 1, 0x02);
		world.setBlock(i + 1, j + 0, k + 0, Blocks.dirt);
		world.setBlock(i + 1, j + 0, k + 1, Blocks.dirt);
		world.setBlock(i + 1, j + 0, k + 2, Blocks.dirt);
		world.setBlock(i + 1, j + 0, k + 3, Blocks.dirt);
		world.setBlock(i + 1, j + 0, k + 4, Blocks.dirt);
		world.setBlock(i + 1, j + 0, k + 5, Blocks.dirt);
		world.setBlock(i + 1, j + 0, k + 6, Blocks.dirt);
		world.setBlock(i + 1, j + 0, k + 7, Blocks.dirt);
		world.setBlock(i + 1, j + 0, k + 8, Blocks.dirt);
		world.setBlock(i + 1, j + 0, k + 9, Blocks.dirt);
		world.setBlock(i + 1, j + 0, k + 10, Blocks.dirt);
		world.setBlock(i + 1, j + 0, k + 11, Blocks.dirt);
		world.setBlock(i + 1, j + 0, k + 12, Blocks.dirt);
		world.setBlock(i + 1, j + 1, k + 0, Blocks.dirt);
		world.setBlock(i + 1, j + 1, k + 1, Blocks.dirt);
		world.setBlock(i + 1, j + 1, k + 2, Blocks.dirt);
		world.setBlock(i + 1, j + 1, k + 3, Blocks.dirt);
		world.setBlock(i + 1, j + 1, k + 4, Blocks.dirt);
		world.setBlock(i + 1, j + 1, k + 5, Blocks.dirt);
		world.setBlock(i + 1, j + 1, k + 6, Blocks.dirt);
		world.setBlock(i + 1, j + 1, k + 7, Blocks.dirt);
		world.setBlock(i + 1, j + 1, k + 8, Blocks.dirt);
		world.setBlock(i + 1, j + 1, k + 9, Blocks.dirt);
		world.setBlock(i + 1, j + 1, k + 10, Blocks.dirt);
		world.setBlock(i + 1, j + 1, k + 11, Blocks.dirt);
		world.setBlock(i + 1, j + 1, k + 12, Blocks.dirt);
		world.setBlock(i + 1, j + 2, k + 0, Blocks.grass);
		world.setBlock(i + 1, j + 2, k + 1, Blocks.grass);
		world.setBlock(i + 1, j + 2, k + 2, Blocks.grass);
		world.setBlock(i + 1, j + 2, k + 3, Blocks.grass);
		world.setBlock(i + 1, j + 2, k + 4, Blocks.grass);
		world.setBlock(i + 1, j + 2, k + 5, Blocks.grass);
		world.setBlock(i + 1, j + 2, k + 6, Blocks.dirt);
		world.setBlock(i + 1, j + 2, k + 7, Blocks.dirt);
		world.setBlock(i + 1, j + 2, k + 8, Blocks.dirt);
		world.setBlock(i + 1, j + 2, k + 9, Blocks.dirt);
		world.setBlock(i + 1, j + 2, k + 10, Blocks.dirt);
		world.setBlock(i + 1, j + 2, k + 11, Blocks.dirt);
		world.setBlock(i + 1, j + 2, k + 12, Blocks.dirt);
		world.setBlock(i + 1, j + 3, k + 0, Blocks.dirt);
		world.setBlock(i + 1, j + 3, k + 1, Blocks.dirt);
		world.setBlock(i + 1, j + 3, k + 2, Blocks.dirt);
		world.setBlock(i + 1, j + 3, k + 3, Blocks.dirt);
		world.setBlock(i + 1, j + 3, k + 4, Blocks.dirt);
		world.setBlock(i + 1, j + 3, k + 5, Blocks.dirt);
		world.setBlock(i + 1, j + 3, k + 6, Blocks.dirt);
		world.setBlock(i + 1, j + 3, k + 7, Blocks.dirt);
		world.setBlock(i + 1, j + 3, k + 8, Blocks.dirt);
		world.setBlock(i + 1, j + 3, k + 9, Blocks.dirt);
		world.setBlock(i + 1, j + 3, k + 10, Blocks.dirt);
		world.setBlock(i + 1, j + 3, k + 11, Blocks.dirt);
		world.setBlock(i + 1, j + 3, k + 12, Blocks.dirt);
		world.setBlock(i + 1, j + 4, k + 0, Blocks.dirt);
		world.setBlock(i + 1, j + 4, k + 1, Blocks.dirt);
		world.setBlock(i + 1, j + 4, k + 2, Blocks.dirt);
		world.setBlock(i + 1, j + 4, k + 3, Blocks.dirt);
		world.setBlock(i + 1, j + 4, k + 4, Blocks.dirt);
		world.setBlock(i + 1, j + 4, k + 5, Blocks.dirt);
		world.setBlock(i + 1, j + 4, k + 6, Blocks.dirt);
		world.setBlock(i + 1, j + 4, k + 7, Blocks.dirt);
		world.setBlock(i + 1, j + 4, k + 8, Blocks.dirt);
		world.setBlock(i + 1, j + 4, k + 9, Blocks.dirt);
		world.setBlock(i + 1, j + 4, k + 10, Blocks.dirt);
		world.setBlock(i + 1, j + 4, k + 11, Blocks.dirt);
		world.setBlock(i + 1, j + 4, k + 12, Blocks.dirt);
		world.setBlock(i + 1, j + 5, k + 0, Blocks.grass);
		world.setBlock(i + 1, j + 5, k + 1, Blocks.grass);
		world.setBlock(i + 1, j + 5, k + 2, Blocks.nether_brick);
		world.setBlock(i + 1, j + 5, k + 3, Blocks.nether_brick);
		world.setBlock(i + 1, j + 5, k + 4, Blocks.nether_brick);
		world.setBlock(i + 1, j + 5, k + 5, Blocks.nether_brick);
		world.setBlock(i + 1, j + 5, k + 6, Blocks.nether_brick);
		world.setBlock(i + 1, j + 5, k + 7, Blocks.nether_brick);
		world.setBlock(i + 1, j + 5, k + 8, Blocks.sandstone, 2, 0x02);
		world.setBlock(i + 1, j + 5, k + 9, Blocks.nether_brick);
		world.setBlock(i + 1, j + 5, k + 10, Blocks.nether_brick);
		world.setBlock(i + 1, j + 5, k + 11, Blocks.grass);
		world.setBlock(i + 1, j + 5, k + 12, Blocks.grass);
		world.setBlock(i + 1, j + 10, k + 0, Blocks.nether_brick_stairs);
		world.setBlock(i + 1, j + 10, k + 1, Blocks.nether_brick_stairs, 2, 0x02);
		world.setBlock(i + 1, j + 10, k + 2, Blocks.nether_brick);
		world.setBlock(i + 1, j + 10, k + 3, Blocks.nether_brick);
		world.setBlock(i + 1, j + 10, k + 9, Blocks.nether_brick);
		world.setBlock(i + 1, j + 10, k + 10, Blocks.nether_brick);
		world.setBlock(i + 1, j + 10, k + 11, Blocks.nether_brick_stairs);
		world.setBlock(i + 1, j + 10, k + 12, Blocks.nether_brick_stairs);
		world.setBlock(i + 1, j + 11, k + 4, Blocks.sandstone, 2, 0x02);
		world.setBlock(i + 1, j + 11, k + 8, Blocks.sandstone, 2, 0x02);
		world.setBlock(i + 1, j + 12, k + 5, Blocks.sandstone, 2, 0x02);
		world.setBlock(i + 1, j + 12, k + 7, Blocks.sandstone, 2, 0x02);
		world.setBlock(i + 1, j + 13, k + 6, Blocks.sandstone, 2, 0x02);
		world.setBlock(i + 2, j + 0, k + 0, Blocks.dirt);
		world.setBlock(i + 2, j + 0, k + 1, Blocks.dirt);
		world.setBlock(i + 2, j + 0, k + 2, Blocks.dirt);
		world.setBlock(i + 2, j + 0, k + 3, Blocks.dirt);
		world.setBlock(i + 2, j + 0, k + 4, Blocks.dirt);
		world.setBlock(i + 2, j + 0, k + 5, Blocks.dirt);
		world.setBlock(i + 2, j + 0, k + 6, Blocks.dirt);
		world.setBlock(i + 2, j + 0, k + 7, Blocks.dirt);
		world.setBlock(i + 2, j + 0, k + 8, Blocks.dirt);
		world.setBlock(i + 2, j + 0, k + 9, Blocks.dirt);
		world.setBlock(i + 2, j + 0, k + 10, Blocks.dirt);
		world.setBlock(i + 2, j + 0, k + 11, Blocks.dirt);
		world.setBlock(i + 2, j + 0, k + 12, Blocks.dirt);
		world.setBlock(i + 2, j + 1, k + 0, Blocks.dirt);
		world.setBlock(i + 2, j + 1, k + 1, Blocks.dirt);
		world.setBlock(i + 2, j + 1, k + 2, Blocks.dirt);
		world.setBlock(i + 2, j + 1, k + 3, Blocks.dirt);
		world.setBlock(i + 2, j + 1, k + 4, Blocks.dirt);
		world.setBlock(i + 2, j + 1, k + 5, Blocks.dirt);
		world.setBlock(i + 2, j + 1, k + 6, Blocks.dirt);
		world.setBlock(i + 2, j + 1, k + 7, Blocks.dirt);
		world.setBlock(i + 2, j + 1, k + 8, Blocks.dirt);
		world.setBlock(i + 2, j + 1, k + 9, Blocks.dirt);
		world.setBlock(i + 2, j + 1, k + 10, Blocks.dirt);
		world.setBlock(i + 2, j + 1, k + 11, Blocks.dirt);
		world.setBlock(i + 2, j + 1, k + 12, Blocks.dirt);
		world.setBlock(i + 2, j + 2, k + 0, Blocks.grass);
		world.setBlock(i + 2, j + 2, k + 1, Blocks.grass);
		world.setBlock(i + 2, j + 2, k + 2, Blocks.grass);
		world.setBlock(i + 2, j + 2, k + 3, Blocks.grass);
		world.setBlock(i + 2, j + 2, k + 4, Blocks.grass);
		world.setBlock(i + 2, j + 2, k + 5, Blocks.grass);
		world.setBlock(i + 2, j + 2, k + 6, Blocks.dirt);
		world.setBlock(i + 2, j + 2, k + 7, Blocks.dirt);
		world.setBlock(i + 2, j + 2, k + 8, Blocks.dirt);
		world.setBlock(i + 2, j + 2, k + 9, Blocks.dirt);
		world.setBlock(i + 2, j + 2, k + 10, Blocks.dirt);
		world.setBlock(i + 2, j + 2, k + 11, Blocks.dirt);
		world.setBlock(i + 2, j + 2, k + 12, Blocks.dirt);
		world.setBlock(i + 2, j + 3, k + 0, Blocks.dirt);
		world.setBlock(i + 2, j + 3, k + 1, Blocks.dirt);
		world.setBlock(i + 2, j + 3, k + 2, Blocks.dirt);
		world.setBlock(i + 2, j + 3, k + 3, Blocks.dirt);
		world.setBlock(i + 2, j + 3, k + 4, Blocks.dirt);
		world.setBlock(i + 2, j + 3, k + 5, Blocks.dirt);
		world.setBlock(i + 2, j + 3, k + 6, Blocks.dirt);
		world.setBlock(i + 2, j + 3, k + 7, Blocks.dirt);
		world.setBlock(i + 2, j + 3, k + 8, Blocks.dirt);
		world.setBlock(i + 2, j + 3, k + 9, Blocks.dirt);
		world.setBlock(i + 2, j + 3, k + 10, Blocks.dirt);
		world.setBlock(i + 2, j + 3, k + 11, Blocks.dirt);
		world.setBlock(i + 2, j + 3, k + 12, Blocks.dirt);
		world.setBlock(i + 2, j + 4, k + 0, Blocks.dirt);
		world.setBlock(i + 2, j + 4, k + 1, Blocks.dirt);
		world.setBlock(i + 2, j + 4, k + 2, Blocks.dirt);
		world.setBlock(i + 2, j + 4, k + 3, Blocks.dirt);
		world.setBlock(i + 2, j + 4, k + 4, Blocks.dirt);
		world.setBlock(i + 2, j + 4, k + 5, Blocks.dirt);
		world.setBlock(i + 2, j + 4, k + 6, Blocks.dirt);
		world.setBlock(i + 2, j + 4, k + 7, Blocks.dirt);
		world.setBlock(i + 2, j + 4, k + 8, Blocks.dirt);
		world.setBlock(i + 2, j + 4, k + 9, Blocks.dirt);
		world.setBlock(i + 2, j + 4, k + 10, Blocks.dirt);
		world.setBlock(i + 2, j + 4, k + 11, Blocks.dirt);
		world.setBlock(i + 2, j + 4, k + 12, Blocks.dirt);
		world.setBlock(i + 2, j + 5, k + 0, Blocks.grass);
		world.setBlock(i + 2, j + 5, k + 1, Blocks.nether_brick);
		world.setBlock(i + 2, j + 5, k + 2, Blocks.nether_brick);
		world.setBlock(i + 2, j + 5, k + 3, Blocks.sandstone, 2, 0x02);
		world.setBlock(i + 2, j + 5, k + 4, Blocks.sandstone, 2, 0x02);
		world.setBlock(i + 2, j + 5, k + 5, Blocks.sandstone, 2, 0x02);
		world.setBlock(i + 2, j + 5, k + 6, Blocks.sandstone, 2, 0x02);
		world.setBlock(i + 2, j + 5, k + 7, Blocks.sandstone, 2, 0x02);
		world.setBlock(i + 2, j + 5, k + 8, Blocks.nether_brick);
		world.setBlock(i + 2, j + 5, k + 9, Blocks.sandstone, 2, 0x02);
		world.setBlock(i + 2, j + 5, k + 10, Blocks.sandstone, 2, 0x02);
		world.setBlock(i + 2, j + 5, k + 11, Blocks.nether_brick);
		world.setBlock(i + 2, j + 5, k + 12, Blocks.grass);
		world.setBlock(i + 2, j + 10, k + 0, Blocks.nether_brick_stairs, 2, 0x02);
		world.setBlock(i + 2, j + 10, k + 1, Blocks.nether_brick);
		world.setBlock(i + 2, j + 10, k + 2, Blocks.sandstone, 2, 0x02);
		world.setBlock(i + 2, j + 10, k + 3, Blocks.sandstone, 2, 0x02);
		world.setBlock(i + 2, j + 10, k + 9, Blocks.sandstone, 2, 0x02);
		world.setBlock(i + 2, j + 10, k + 10, Blocks.sandstone, 2, 0x02);
		world.setBlock(i + 2, j + 10, k + 11, Blocks.nether_brick);
		world.setBlock(i + 2, j + 10, k + 12, Blocks.nether_brick_stairs, 3, 0x02);
		world.setBlock(i + 2, j + 11, k + 4, Blocks.sandstone, 2, 0x02);
		world.setBlock(i + 2, j + 11, k + 8, Blocks.sandstone, 2, 0x02);
		world.setBlock(i + 2, j + 12, k + 5, Blocks.sandstone, 2, 0x02);
		world.setBlock(i + 2, j + 12, k + 7, Blocks.sandstone, 2, 0x02);
		world.setBlock(i + 2, j + 13, k + 6, Blocks.sandstone, 2, 0x02);
		world.setBlock(i + 3, j + 0, k + 0, Blocks.dirt);
		world.setBlock(i + 3, j + 0, k + 1, Blocks.dirt);
		world.setBlock(i + 3, j + 0, k + 2, Blocks.dirt);
		world.setBlock(i + 3, j + 0, k + 3, Blocks.dirt);
		world.setBlock(i + 3, j + 0, k + 4, Blocks.dirt);
		world.setBlock(i + 3, j + 0, k + 5, Blocks.dirt);
		world.setBlock(i + 3, j + 0, k + 6, Blocks.dirt);
		world.setBlock(i + 3, j + 0, k + 7, Blocks.dirt);
		world.setBlock(i + 3, j + 0, k + 8, Blocks.dirt);
		world.setBlock(i + 3, j + 0, k + 9, Blocks.dirt);
		world.setBlock(i + 3, j + 0, k + 10, Blocks.dirt);
		world.setBlock(i + 3, j + 0, k + 11, Blocks.dirt);
		world.setBlock(i + 3, j + 0, k + 12, Blocks.dirt);
		world.setBlock(i + 3, j + 1, k + 0, Blocks.dirt);
		world.setBlock(i + 3, j + 1, k + 1, Blocks.dirt);
		world.setBlock(i + 3, j + 1, k + 2, Blocks.dirt);
		world.setBlock(i + 3, j + 1, k + 3, Blocks.dirt);
		world.setBlock(i + 3, j + 1, k + 4, Blocks.dirt);
		world.setBlock(i + 3, j + 1, k + 5, Blocks.dirt);
		world.setBlock(i + 3, j + 1, k + 6, Blocks.dirt);
		world.setBlock(i + 3, j + 1, k + 7, Blocks.dirt);
		world.setBlock(i + 3, j + 1, k + 8, Blocks.dirt);
		world.setBlock(i + 3, j + 1, k + 9, Blocks.dirt);
		world.setBlock(i + 3, j + 1, k + 10, Blocks.dirt);
		world.setBlock(i + 3, j + 1, k + 11, Blocks.dirt);
		world.setBlock(i + 3, j + 1, k + 12, Blocks.dirt);
		world.setBlock(i + 3, j + 2, k + 0, Blocks.grass);
		world.setBlock(i + 3, j + 2, k + 1, Blocks.grass);
		world.setBlock(i + 3, j + 2, k + 2, Blocks.grass);
		world.setBlock(i + 3, j + 2, k + 3, Blocks.grass);
		world.setBlock(i + 3, j + 2, k + 4, Blocks.grass);
		world.setBlock(i + 3, j + 2, k + 5, Blocks.grass);
		world.setBlock(i + 3, j + 2, k + 6, Blocks.dirt);
		world.setBlock(i + 3, j + 2, k + 7, Blocks.dirt);
		world.setBlock(i + 3, j + 2, k + 8, Blocks.dirt);
		world.setBlock(i + 3, j + 2, k + 9, Blocks.dirt);
		world.setBlock(i + 3, j + 2, k + 10, Blocks.dirt);
		world.setBlock(i + 3, j + 2, k + 11, Blocks.dirt);
		world.setBlock(i + 3, j + 2, k + 12, Blocks.dirt);
		world.setBlock(i + 3, j + 3, k + 0, Blocks.dirt);
		world.setBlock(i + 3, j + 3, k + 1, Blocks.dirt);
		world.setBlock(i + 3, j + 3, k + 2, Blocks.dirt);
		world.setBlock(i + 3, j + 3, k + 3, Blocks.dirt);
		world.setBlock(i + 3, j + 3, k + 4, Blocks.dirt);
		world.setBlock(i + 3, j + 3, k + 5, Blocks.dirt);
		world.setBlock(i + 3, j + 3, k + 6, Blocks.dirt);
		world.setBlock(i + 3, j + 3, k + 7, Blocks.dirt);
		world.setBlock(i + 3, j + 3, k + 8, Blocks.dirt);
		world.setBlock(i + 3, j + 3, k + 9, Blocks.dirt);
		world.setBlock(i + 3, j + 3, k + 10, Blocks.dirt);
		world.setBlock(i + 3, j + 3, k + 11, Blocks.dirt);
		world.setBlock(i + 3, j + 3, k + 12, Blocks.dirt);
		world.setBlock(i + 3, j + 4, k + 0, Blocks.dirt);
		world.setBlock(i + 3, j + 4, k + 1, Blocks.dirt);
		world.setBlock(i + 3, j + 4, k + 2, Blocks.dirt);
		world.setBlock(i + 3, j + 4, k + 3, Blocks.dirt);
		world.setBlock(i + 3, j + 4, k + 4, Blocks.dirt);
		world.setBlock(i + 3, j + 4, k + 5, Blocks.dirt);
		world.setBlock(i + 3, j + 4, k + 6, Blocks.dirt);
		world.setBlock(i + 3, j + 4, k + 7, Blocks.dirt);
		world.setBlock(i + 3, j + 4, k + 8, Blocks.dirt);
		world.setBlock(i + 3, j + 4, k + 9, Blocks.dirt);
		world.setBlock(i + 3, j + 4, k + 10, Blocks.dirt);
		world.setBlock(i + 3, j + 4, k + 11, Blocks.dirt);
		world.setBlock(i + 3, j + 4, k + 12, Blocks.dirt);
		world.setBlock(i + 3, j + 5, k + 0, Blocks.grass);
		world.setBlock(i + 3, j + 5, k + 1, Blocks.nether_brick);
		world.setBlock(i + 3, j + 5, k + 2, Blocks.sandstone, 2, 0x02);
		world.setBlock(i + 3, j + 5, k + 3, Blocks.sandstone, 2, 0x02);
		world.setBlock(i + 3, j + 5, k + 4, Blocks.sandstone, 2, 0x02);
		world.setBlock(i + 3, j + 5, k + 5, Blocks.sandstone, 2, 0x02);
		world.setBlock(i + 3, j + 5, k + 6, Blocks.sandstone, 2, 0x02);
		world.setBlock(i + 3, j + 5, k + 7, Blocks.sandstone, 2, 0x02);
		world.setBlock(i + 3, j + 5, k + 8, Blocks.sandstone, 2, 0x02);
		world.setBlock(i + 3, j + 5, k + 9, Blocks.nether_brick);
		world.setBlock(i + 3, j + 5, k + 10, Blocks.sandstone, 2, 0x02);
		world.setBlock(i + 3, j + 5, k + 11, Blocks.nether_brick);
		world.setBlock(i + 3, j + 5, k + 12, Blocks.grass);
		world.setBlock(i + 3, j + 10, k + 0, Blocks.nether_brick_stairs, 2, 0x02);
		world.setBlock(i + 3, j + 10, k + 1, Blocks.nether_brick);
		world.setBlock(i + 3, j + 10, k + 2, Blocks.sandstone, 2, 0x02);
		world.setBlock(i + 3, j + 10, k + 10, Blocks.sandstone, 2, 0x02);
		world.setBlock(i + 3, j + 10, k + 11, Blocks.nether_brick);
		world.setBlock(i + 3, j + 10, k + 12, Blocks.nether_brick_stairs, 3, 0x02);
		world.setBlock(i + 3, j + 11, k + 3, Blocks.glowstone);
		world.setBlock(i + 3, j + 11, k + 4, Blocks.sandstone, 2, 0x02);
		world.setBlock(i + 3, j + 11, k + 8, Blocks.sandstone, 2, 0x02);
		world.setBlock(i + 3, j + 11, k + 9, Blocks.glowstone);
		world.setBlock(i + 3, j + 12, k + 5, Blocks.sandstone, 2, 0x02);
		world.setBlock(i + 3, j + 12, k + 7, Blocks.sandstone, 2, 0x02);
		world.setBlock(i + 3, j + 13, k + 6, Blocks.sandstone, 2, 0x02);
		world.setBlock(i + 4, j + 0, k + 0, Blocks.dirt);
		world.setBlock(i + 4, j + 0, k + 1, Blocks.dirt);
		world.setBlock(i + 4, j + 0, k + 2, Blocks.dirt);
		world.setBlock(i + 4, j + 0, k + 3, Blocks.dirt);
		world.setBlock(i + 4, j + 0, k + 4, Blocks.dirt);
		world.setBlock(i + 4, j + 0, k + 5, Blocks.dirt);
		world.setBlock(i + 4, j + 0, k + 6, Blocks.dirt);
		world.setBlock(i + 4, j + 0, k + 7, Blocks.dirt);
		world.setBlock(i + 4, j + 0, k + 8, Blocks.dirt);
		world.setBlock(i + 4, j + 0, k + 9, Blocks.dirt);
		world.setBlock(i + 4, j + 0, k + 10, Blocks.dirt);
		world.setBlock(i + 4, j + 0, k + 11, Blocks.dirt);
		world.setBlock(i + 4, j + 0, k + 12, Blocks.dirt);
		world.setBlock(i + 4, j + 1, k + 0, Blocks.dirt);
		world.setBlock(i + 4, j + 1, k + 1, Blocks.dirt);
		world.setBlock(i + 4, j + 1, k + 2, Blocks.dirt);
		world.setBlock(i + 4, j + 1, k + 3, Blocks.dirt);
		world.setBlock(i + 4, j + 1, k + 4, Blocks.dirt);
		world.setBlock(i + 4, j + 1, k + 5, Blocks.dirt);
		world.setBlock(i + 4, j + 1, k + 6, Blocks.dirt);
		world.setBlock(i + 4, j + 1, k + 7, Blocks.dirt);
		world.setBlock(i + 4, j + 1, k + 8, Blocks.dirt);
		world.setBlock(i + 4, j + 1, k + 9, Blocks.dirt);
		world.setBlock(i + 4, j + 1, k + 10, Blocks.dirt);
		world.setBlock(i + 4, j + 1, k + 11, Blocks.dirt);
		world.setBlock(i + 4, j + 1, k + 12, Blocks.dirt);
		world.setBlock(i + 4, j + 2, k + 0, Blocks.grass);
		world.setBlock(i + 4, j + 2, k + 1, Blocks.grass);
		world.setBlock(i + 4, j + 2, k + 2, Blocks.grass);
		world.setBlock(i + 4, j + 2, k + 3, Blocks.grass);
		world.setBlock(i + 4, j + 2, k + 4, Blocks.grass);
		world.setBlock(i + 4, j + 2, k + 5, Blocks.grass);
		world.setBlock(i + 4, j + 2, k + 6, Blocks.dirt);
		world.setBlock(i + 4, j + 2, k + 7, Blocks.dirt);
		world.setBlock(i + 4, j + 2, k + 8, Blocks.dirt);
		world.setBlock(i + 4, j + 2, k + 9, Blocks.dirt);
		world.setBlock(i + 4, j + 2, k + 10, Blocks.dirt);
		world.setBlock(i + 4, j + 2, k + 11, Blocks.dirt);
		world.setBlock(i + 4, j + 2, k + 12, Blocks.dirt);
		world.setBlock(i + 4, j + 3, k + 0, Blocks.dirt);
		world.setBlock(i + 4, j + 3, k + 1, Blocks.dirt);
		world.setBlock(i + 4, j + 3, k + 2, Blocks.dirt);
		world.setBlock(i + 4, j + 3, k + 3, Blocks.dirt);
		world.setBlock(i + 4, j + 3, k + 4, Blocks.dirt);
		world.setBlock(i + 4, j + 3, k + 5, Blocks.dirt);
		world.setBlock(i + 4, j + 3, k + 6, Blocks.dirt);
		world.setBlock(i + 4, j + 3, k + 7, Blocks.dirt);
		world.setBlock(i + 4, j + 3, k + 8, Blocks.dirt);
		world.setBlock(i + 4, j + 3, k + 9, Blocks.dirt);
		world.setBlock(i + 4, j + 3, k + 10, Blocks.dirt);
		world.setBlock(i + 4, j + 3, k + 11, Blocks.dirt);
		world.setBlock(i + 4, j + 3, k + 12, Blocks.dirt);
		world.setBlock(i + 4, j + 4, k + 0, Blocks.dirt);
		world.setBlock(i + 4, j + 4, k + 1, Blocks.dirt);
		world.setBlock(i + 4, j + 4, k + 2, Blocks.dirt);
		world.setBlock(i + 4, j + 4, k + 3, Blocks.dirt);
		world.setBlock(i + 4, j + 4, k + 4, Blocks.dirt);
		world.setBlock(i + 4, j + 4, k + 5, Blocks.dirt);
		world.setBlock(i + 4, j + 4, k + 6, Blocks.dirt);
		world.setBlock(i + 4, j + 4, k + 7, Blocks.dirt);
		world.setBlock(i + 4, j + 4, k + 8, Blocks.dirt);
		world.setBlock(i + 4, j + 4, k + 9, Blocks.dirt);
		world.setBlock(i + 4, j + 4, k + 10, Blocks.dirt);
		world.setBlock(i + 4, j + 4, k + 11, Blocks.dirt);
		world.setBlock(i + 4, j + 4, k + 12, Blocks.dirt);
		world.setBlock(i + 4, j + 5, k + 0, Blocks.nether_brick);
		world.setBlock(i + 4, j + 5, k + 1, Blocks.sandstone, 2, 0x02);
		world.setBlock(i + 4, j + 5, k + 2, Blocks.sandstone, 2, 0x02);
		world.setBlock(i + 4, j + 5, k + 3, Blocks.sandstone, 2, 0x02);
		world.setBlock(i + 4, j + 5, k + 4, Blocks.nether_brick);
		world.setBlock(i + 4, j + 5, k + 5, Blocks.nether_brick);
		world.setBlock(i + 4, j + 5, k + 6, Blocks.nether_brick);
		world.setBlock(i + 4, j + 5, k + 7, Blocks.sandstone, 2, 0x02);
		world.setBlock(i + 4, j + 5, k + 8, Blocks.sandstone, 2, 0x02);
		world.setBlock(i + 4, j + 5, k + 9, Blocks.sandstone, 2, 0x02);
		world.setBlock(i + 4, j + 5, k + 10, Blocks.nether_brick);
		world.setBlock(i + 4, j + 5, k + 11, Blocks.sandstone, 2, 0x02);
		world.setBlock(i + 4, j + 5, k + 12, Blocks.nether_brick);
		world.setBlock(i + 4, j + 6, k + 0, Blocks.sandstone, 1, 0x02);
		world.setBlock(i + 4, j + 6, k + 12, Blocks.sandstone, 1, 0x02);
		world.setBlock(i + 4, j + 7, k + 0, Blocks.sandstone, 1, 0x02);
		world.setBlock(i + 4, j + 7, k + 12, Blocks.sandstone, 1, 0x02);
		world.setBlock(i + 4, j + 8, k + 0, Blocks.sandstone, 1, 0x02);
		world.setBlock(i + 4, j + 8, k + 12, Blocks.sandstone, 1, 0x02);
		world.setBlock(i + 4, j + 9, k + 0, Blocks.sandstone, 1, 0x02);
		world.setBlock(i + 4, j + 9, k + 12, Blocks.sandstone, 1, 0x02);
		world.setBlock(i + 4, j + 10, k + 0, Blocks.sandstone, 1, 0x02);
		world.setBlock(i + 4, j + 10, k + 12, Blocks.sandstone, 1, 0x02);
		world.setBlock(i + 4, j + 11, k + 1, Blocks.sandstone, 2, 0x02);
		world.setBlock(i + 4, j + 11, k + 2, Blocks.sandstone, 2, 0x02);
		world.setBlock(i + 4, j + 11, k + 3, Blocks.sandstone, 2, 0x02);
		world.setBlock(i + 4, j + 11, k + 4, Blocks.sandstone, 2, 0x02);
		world.setBlock(i + 4, j + 11, k + 8, Blocks.sandstone, 2, 0x02);
		world.setBlock(i + 4, j + 11, k + 9, Blocks.sandstone, 2, 0x02);
		world.setBlock(i + 4, j + 11, k + 10, Blocks.sandstone, 2, 0x02);
		world.setBlock(i + 4, j + 11, k + 11, Blocks.sandstone, 2, 0x02);
		world.setBlock(i + 4, j + 12, k + 5, Blocks.sandstone, 2, 0x02);
		world.setBlock(i + 4, j + 12, k + 7, Blocks.sandstone, 2, 0x02);
		world.setBlock(i + 4, j + 13, k + 6, Blocks.sandstone, 2, 0x02);
		world.setBlock(i + 5, j + 0, k + 0, Blocks.dirt);
		world.setBlock(i + 5, j + 0, k + 1, Blocks.dirt);
		world.setBlock(i + 5, j + 0, k + 2, Blocks.dirt);
		world.setBlock(i + 5, j + 0, k + 3, Blocks.dirt);
		world.setBlock(i + 5, j + 0, k + 4, Blocks.dirt);
		world.setBlock(i + 5, j + 0, k + 5, Blocks.dirt);
		world.setBlock(i + 5, j + 0, k + 6, Blocks.dirt);
		world.setBlock(i + 5, j + 0, k + 7, Blocks.dirt);
		world.setBlock(i + 5, j + 0, k + 8, Blocks.dirt);
		world.setBlock(i + 5, j + 0, k + 9, Blocks.dirt);
		world.setBlock(i + 5, j + 0, k + 10, Blocks.dirt);
		world.setBlock(i + 5, j + 0, k + 11, Blocks.dirt);
		world.setBlock(i + 5, j + 0, k + 12, Blocks.dirt);
		world.setBlock(i + 5, j + 1, k + 0, Blocks.dirt);
		world.setBlock(i + 5, j + 1, k + 1, Blocks.dirt);
		world.setBlock(i + 5, j + 1, k + 2, Blocks.dirt);
		world.setBlock(i + 5, j + 1, k + 3, Blocks.dirt);
		world.setBlock(i + 5, j + 1, k + 4, Blocks.dirt);
		world.setBlock(i + 5, j + 1, k + 5, Blocks.dirt);
		world.setBlock(i + 5, j + 1, k + 6, Blocks.dirt);
		world.setBlock(i + 5, j + 1, k + 7, Blocks.dirt);
		world.setBlock(i + 5, j + 1, k + 8, Blocks.dirt);
		world.setBlock(i + 5, j + 1, k + 9, Blocks.dirt);
		world.setBlock(i + 5, j + 1, k + 10, Blocks.dirt);
		world.setBlock(i + 5, j + 1, k + 11, Blocks.dirt);
		world.setBlock(i + 5, j + 1, k + 12, Blocks.dirt);
		world.setBlock(i + 5, j + 2, k + 0, Blocks.grass);
		world.setBlock(i + 5, j + 2, k + 1, Blocks.grass);
		world.setBlock(i + 5, j + 2, k + 2, Blocks.grass);
		world.setBlock(i + 5, j + 2, k + 3, Blocks.grass);
		world.setBlock(i + 5, j + 2, k + 4, Blocks.grass);
		world.setBlock(i + 5, j + 2, k + 5, Blocks.grass);
		world.setBlock(i + 5, j + 2, k + 6, Blocks.dirt);
		world.setBlock(i + 5, j + 2, k + 7, Blocks.dirt);
		world.setBlock(i + 5, j + 2, k + 8, Blocks.dirt);
		world.setBlock(i + 5, j + 2, k + 9, Blocks.dirt);
		world.setBlock(i + 5, j + 2, k + 10, Blocks.dirt);
		world.setBlock(i + 5, j + 2, k + 11, Blocks.dirt);
		world.setBlock(i + 5, j + 2, k + 12, Blocks.dirt);
		world.setBlock(i + 5, j + 3, k + 0, Blocks.dirt);
		world.setBlock(i + 5, j + 3, k + 1, Blocks.dirt);
		world.setBlock(i + 5, j + 3, k + 2, Blocks.dirt);
		world.setBlock(i + 5, j + 3, k + 3, Blocks.dirt);
		world.setBlock(i + 5, j + 3, k + 4, Blocks.dirt);
		world.setBlock(i + 5, j + 3, k + 5, Blocks.dirt);
		world.setBlock(i + 5, j + 3, k + 6, Blocks.dirt);
		world.setBlock(i + 5, j + 3, k + 7, Blocks.dirt);
		world.setBlock(i + 5, j + 3, k + 8, Blocks.dirt);
		world.setBlock(i + 5, j + 3, k + 9, Blocks.dirt);
		world.setBlock(i + 5, j + 3, k + 10, Blocks.dirt);
		world.setBlock(i + 5, j + 3, k + 11, Blocks.dirt);
		world.setBlock(i + 5, j + 3, k + 12, Blocks.dirt);
		world.setBlock(i + 5, j + 4, k + 0, Blocks.dirt);
		world.setBlock(i + 5, j + 4, k + 1, Blocks.dirt);
		world.setBlock(i + 5, j + 4, k + 2, Blocks.dirt);
		world.setBlock(i + 5, j + 4, k + 3, Blocks.dirt);
		world.setBlock(i + 5, j + 4, k + 4, Blocks.dirt);
		world.setBlock(i + 5, j + 4, k + 5, Blocks.dirt);
		world.setBlock(i + 5, j + 4, k + 6, Blocks.dirt);
		world.setBlock(i + 5, j + 4, k + 7, Blocks.dirt);
		world.setBlock(i + 5, j + 4, k + 8, Blocks.dirt);
		world.setBlock(i + 5, j + 4, k + 9, Blocks.dirt);
		world.setBlock(i + 5, j + 4, k + 10, Blocks.dirt);
		world.setBlock(i + 5, j + 4, k + 11, Blocks.dirt);
		world.setBlock(i + 5, j + 4, k + 12, Blocks.dirt);
		world.setBlock(i + 5, j + 5, k + 0, Blocks.nether_brick);
		world.setBlock(i + 5, j + 5, k + 1, Blocks.sandstone, 2, 0x02);
		world.setBlock(i + 5, j + 5, k + 2, Blocks.sandstone, 2, 0x02);
		world.setBlock(i + 5, j + 5, k + 3, Blocks.nether_brick);
		world.setBlock(i + 5, j + 5, k + 4, Blocks.sandstone, 2, 0x02);
		world.setBlock(i + 5, j + 5, k + 5, Blocks.sandstone, 2, 0x02);
		world.setBlock(i + 5, j + 5, k + 6, Blocks.sandstone, 2, 0x02);
		world.setBlock(i + 5, j + 5, k + 7, Blocks.nether_brick);
		world.setBlock(i + 5, j + 5, k + 8, Blocks.sandstone, 2, 0x02);
		world.setBlock(i + 5, j + 5, k + 9, Blocks.sandstone, 2, 0x02);
		world.setBlock(i + 5, j + 5, k + 10, Blocks.nether_brick);
		world.setBlock(i + 5, j + 5, k + 11, Blocks.sandstone, 2, 0x02);
		world.setBlock(i + 5, j + 5, k + 12, Blocks.nether_brick);
		world.setBlock(i + 5, j + 10, k + 0, Blocks.nether_brick_stairs, 5, 0x02);
		world.setBlock(i + 5, j + 10, k + 12, Blocks.nether_brick_stairs, 5, 0x02);
		world.setBlock(i + 5, j + 11, k + 0, Blocks.sandstone, 1, 0x02);
		world.setBlock(i + 5, j + 11, k + 12, Blocks.sandstone, 1, 0x02);
		world.setBlock(i + 5, j + 12, k + 1, Blocks.sandstone, 2, 0x02);
		world.setBlock(i + 5, j + 12, k + 2, Blocks.sandstone, 2, 0x02);
		world.setBlock(i + 5, j + 12, k + 3, Blocks.sandstone, 2, 0x02);
		world.setBlock(i + 5, j + 12, k + 4, Blocks.sandstone, 2, 0x02);
		world.setBlock(i + 5, j + 12, k + 8, Blocks.sandstone, 2, 0x02);
		world.setBlock(i + 5, j + 12, k + 9, Blocks.sandstone, 2, 0x02);
		world.setBlock(i + 5, j + 12, k + 10, Blocks.sandstone, 2, 0x02);
		world.setBlock(i + 5, j + 12, k + 11, Blocks.sandstone, 2, 0x02);
		world.setBlock(i + 5, j + 13, k + 5, Blocks.sandstone, 2, 0x02);
		world.setBlock(i + 5, j + 13, k + 7, Blocks.sandstone, 2, 0x02);
		world.setBlock(i + 5, j + 14, k + 6, Blocks.sandstone, 2, 0x02);
		world.setBlock(i + 6, j + 0, k + 0, Blocks.dirt);
		world.setBlock(i + 6, j + 0, k + 1, Blocks.dirt);
		world.setBlock(i + 6, j + 0, k + 2, Blocks.dirt);
		world.setBlock(i + 6, j + 0, k + 3, Blocks.dirt);
		world.setBlock(i + 6, j + 0, k + 4, Blocks.dirt);
		world.setBlock(i + 6, j + 0, k + 5, Blocks.dirt);
		world.setBlock(i + 6, j + 0, k + 6, Blocks.dirt);
		world.setBlock(i + 6, j + 0, k + 7, Blocks.dirt);
		world.setBlock(i + 6, j + 0, k + 8, Blocks.dirt);
		world.setBlock(i + 6, j + 0, k + 9, Blocks.dirt);
		world.setBlock(i + 6, j + 0, k + 10, Blocks.dirt);
		world.setBlock(i + 6, j + 0, k + 11, Blocks.dirt);
		world.setBlock(i + 6, j + 0, k + 12, Blocks.dirt);
		world.setBlock(i + 6, j + 1, k + 0, Blocks.dirt);
		world.setBlock(i + 6, j + 1, k + 1, Blocks.dirt);
		world.setBlock(i + 6, j + 1, k + 2, Blocks.dirt);
		world.setBlock(i + 6, j + 1, k + 3, Blocks.dirt);
		world.setBlock(i + 6, j + 1, k + 4, Blocks.dirt);
		world.setBlock(i + 6, j + 1, k + 5, Blocks.dirt);
		world.setBlock(i + 6, j + 1, k + 6, Blocks.dirt);
		world.setBlock(i + 6, j + 1, k + 7, Blocks.dirt);
		world.setBlock(i + 6, j + 1, k + 8, Blocks.dirt);
		world.setBlock(i + 6, j + 1, k + 9, Blocks.dirt);
		world.setBlock(i + 6, j + 1, k + 10, Blocks.dirt);
		world.setBlock(i + 6, j + 1, k + 11, Blocks.dirt);
		world.setBlock(i + 6, j + 1, k + 12, Blocks.dirt);
		world.setBlock(i + 6, j + 2, k + 0, Blocks.grass);
		world.setBlock(i + 6, j + 2, k + 1, Blocks.grass);
		world.setBlock(i + 6, j + 2, k + 2, Blocks.grass);
		world.setBlock(i + 6, j + 2, k + 3, Blocks.grass);
		world.setBlock(i + 6, j + 2, k + 4, Blocks.grass);
		world.setBlock(i + 6, j + 2, k + 5, Blocks.grass);
		world.setBlock(i + 6, j + 2, k + 6, Blocks.dirt);
		world.setBlock(i + 6, j + 2, k + 7, Blocks.dirt);
		world.setBlock(i + 6, j + 2, k + 8, Blocks.dirt);
		world.setBlock(i + 6, j + 2, k + 9, Blocks.dirt);
		world.setBlock(i + 6, j + 2, k + 10, Blocks.dirt);
		world.setBlock(i + 6, j + 2, k + 11, Blocks.dirt);
		world.setBlock(i + 6, j + 2, k + 12, Blocks.dirt);
		world.setBlock(i + 6, j + 3, k + 0, Blocks.dirt);
		world.setBlock(i + 6, j + 3, k + 1, Blocks.dirt);
		world.setBlock(i + 6, j + 3, k + 2, Blocks.dirt);
		world.setBlock(i + 6, j + 3, k + 3, Blocks.dirt);
		world.setBlock(i + 6, j + 3, k + 4, Blocks.dirt);
		world.setBlock(i + 6, j + 3, k + 5, Blocks.dirt);
		world.setBlock(i + 6, j + 3, k + 6, Blocks.dirt);
		world.setBlock(i + 6, j + 3, k + 7, Blocks.dirt);
		world.setBlock(i + 6, j + 3, k + 8, Blocks.dirt);
		world.setBlock(i + 6, j + 3, k + 9, Blocks.dirt);
		world.setBlock(i + 6, j + 3, k + 10, Blocks.dirt);
		world.setBlock(i + 6, j + 3, k + 11, Blocks.dirt);
		world.setBlock(i + 6, j + 3, k + 12, Blocks.dirt);
		world.setBlock(i + 6, j + 4, k + 0, Blocks.dirt);
		world.setBlock(i + 6, j + 4, k + 1, Blocks.dirt);
		world.setBlock(i + 6, j + 4, k + 2, Blocks.dirt);
		world.setBlock(i + 6, j + 4, k + 3, Blocks.dirt);
		world.setBlock(i + 6, j + 4, k + 4, Blocks.dirt);
		world.setBlock(i + 6, j + 4, k + 5, Blocks.dirt);
		world.setBlock(i + 6, j + 4, k + 6, Blocks.dirt);
		world.setBlock(i + 6, j + 4, k + 7, Blocks.dirt);
		world.setBlock(i + 6, j + 4, k + 8, Blocks.dirt);
		world.setBlock(i + 6, j + 4, k + 9, Blocks.dirt);
		world.setBlock(i + 6, j + 4, k + 10, Blocks.dirt);
		world.setBlock(i + 6, j + 4, k + 11, Blocks.dirt);
		world.setBlock(i + 6, j + 4, k + 12, Blocks.dirt);
		world.setBlock(i + 6, j + 5, k + 0, Blocks.nether_brick);
		world.setBlock(i + 6, j + 5, k + 1, Blocks.sandstone, 2, 0x02);
		world.setBlock(i + 6, j + 5, k + 2, Blocks.sandstone, 2, 0x02);
		world.setBlock(i + 6, j + 5, k + 3, Blocks.nether_brick);
		world.setBlock(i + 6, j + 5, k + 4, Blocks.sandstone, 2, 0x02);
		world.setBlock(i + 6, j + 5, k + 5, Blocks.nether_brick);
		world.setBlock(i + 6, j + 5, k + 6, mod_Avatar.AirBlock);
		world.setBlock(i + 6, j + 5, k + 7, Blocks.nether_brick);
		world.setBlock(i + 6, j + 5, k + 8, Blocks.sandstone, 2, 0x02);
		world.setBlock(i + 6, j + 5, k + 9, Blocks.sandstone, 2, 0x02);
		world.setBlock(i + 6, j + 5, k + 10, Blocks.nether_brick);
		world.setBlock(i + 6, j + 5, k + 11, Blocks.sandstone, 2, 0x02);
		world.setBlock(i + 6, j + 5, k + 12, Blocks.nether_brick);
		world.setBlock(i + 6, j + 11, k + 0, mod_Avatar.AirNomadsBlock);
		world.setBlock(i + 6, j + 11, k + 12, mod_Avatar.AirNomadsBlock);
		world.setBlock(i + 6, j + 12, k + 0, Blocks.sandstone, 1, 0x02);
		world.setBlock(i + 6, j + 12, k + 12, Blocks.sandstone, 1, 0x02);
		world.setBlock(i + 6, j + 13, k + 1, Blocks.sandstone, 2, 0x02);
		world.setBlock(i + 6, j + 13, k + 2, Blocks.sandstone, 2, 0x02);
		world.setBlock(i + 6, j + 13, k + 3, Blocks.sandstone, 2, 0x02);
		world.setBlock(i + 6, j + 13, k + 4, Blocks.sandstone, 2, 0x02);
		world.setBlock(i + 6, j + 13, k + 8, Blocks.sandstone, 2, 0x02);
		world.setBlock(i + 6, j + 13, k + 9, Blocks.sandstone, 2, 0x02);
		world.setBlock(i + 6, j + 13, k + 10, Blocks.sandstone, 2, 0x02);
		world.setBlock(i + 6, j + 13, k + 11, Blocks.sandstone, 2, 0x02);
		world.setBlock(i + 6, j + 14, k + 5, Blocks.sandstone, 2, 0x02);
		world.setBlock(i + 6, j + 14, k + 7, Blocks.sandstone, 2, 0x02);
		world.setBlock(i + 7, j + 0, k + 0, Blocks.dirt);
		world.setBlock(i + 7, j + 0, k + 1, Blocks.dirt);
		world.setBlock(i + 7, j + 0, k + 2, Blocks.dirt);
		world.setBlock(i + 7, j + 0, k + 3, Blocks.dirt);
		world.setBlock(i + 7, j + 0, k + 4, Blocks.dirt);
		world.setBlock(i + 7, j + 0, k + 5, Blocks.dirt);
		world.setBlock(i + 7, j + 0, k + 6, Blocks.dirt);
		world.setBlock(i + 7, j + 0, k + 7, Blocks.dirt);
		world.setBlock(i + 7, j + 0, k + 8, Blocks.dirt);
		world.setBlock(i + 7, j + 0, k + 9, Blocks.dirt);
		world.setBlock(i + 7, j + 0, k + 10, Blocks.dirt);
		world.setBlock(i + 7, j + 0, k + 11, Blocks.dirt);
		world.setBlock(i + 7, j + 0, k + 12, Blocks.dirt);
		world.setBlock(i + 7, j + 1, k + 0, Blocks.dirt);
		world.setBlock(i + 7, j + 1, k + 1, Blocks.dirt);
		world.setBlock(i + 7, j + 1, k + 2, Blocks.dirt);
		world.setBlock(i + 7, j + 1, k + 3, Blocks.dirt);
		world.setBlock(i + 7, j + 1, k + 4, Blocks.dirt);
		world.setBlock(i + 7, j + 1, k + 5, Blocks.dirt);
		world.setBlock(i + 7, j + 1, k + 6, Blocks.dirt);
		world.setBlock(i + 7, j + 1, k + 7, Blocks.dirt);
		world.setBlock(i + 7, j + 1, k + 8, Blocks.dirt);
		world.setBlock(i + 7, j + 1, k + 9, Blocks.dirt);
		world.setBlock(i + 7, j + 1, k + 10, Blocks.dirt);
		world.setBlock(i + 7, j + 1, k + 11, Blocks.dirt);
		world.setBlock(i + 7, j + 1, k + 12, Blocks.dirt);
		world.setBlock(i + 7, j + 2, k + 0, Blocks.grass);
		world.setBlock(i + 7, j + 2, k + 1, Blocks.grass);
		world.setBlock(i + 7, j + 2, k + 2, Blocks.grass);
		world.setBlock(i + 7, j + 2, k + 3, Blocks.grass);
		world.setBlock(i + 7, j + 2, k + 4, Blocks.grass);
		world.setBlock(i + 7, j + 2, k + 5, Blocks.grass);
		world.setBlock(i + 7, j + 2, k + 6, Blocks.dirt);
		world.setBlock(i + 7, j + 2, k + 7, Blocks.dirt);
		world.setBlock(i + 7, j + 2, k + 8, Blocks.dirt);
		world.setBlock(i + 7, j + 2, k + 9, Blocks.dirt);
		world.setBlock(i + 7, j + 2, k + 10, Blocks.dirt);
		world.setBlock(i + 7, j + 2, k + 11, Blocks.dirt);
		world.setBlock(i + 7, j + 2, k + 12, Blocks.dirt);
		world.setBlock(i + 7, j + 3, k + 0, Blocks.dirt);
		world.setBlock(i + 7, j + 3, k + 1, Blocks.dirt);
		world.setBlock(i + 7, j + 3, k + 2, Blocks.dirt);
		world.setBlock(i + 7, j + 3, k + 3, Blocks.dirt);
		world.setBlock(i + 7, j + 3, k + 4, Blocks.dirt);
		world.setBlock(i + 7, j + 3, k + 5, Blocks.dirt);
		world.setBlock(i + 7, j + 3, k + 6, Blocks.dirt);
		world.setBlock(i + 7, j + 3, k + 7, Blocks.dirt);
		world.setBlock(i + 7, j + 3, k + 8, Blocks.dirt);
		world.setBlock(i + 7, j + 3, k + 9, Blocks.dirt);
		world.setBlock(i + 7, j + 3, k + 10, Blocks.dirt);
		world.setBlock(i + 7, j + 3, k + 11, Blocks.dirt);
		world.setBlock(i + 7, j + 3, k + 12, Blocks.dirt);
		world.setBlock(i + 7, j + 4, k + 0, Blocks.dirt);
		world.setBlock(i + 7, j + 4, k + 1, Blocks.dirt);
		world.setBlock(i + 7, j + 4, k + 2, Blocks.dirt);
		world.setBlock(i + 7, j + 4, k + 3, Blocks.dirt);
		world.setBlock(i + 7, j + 4, k + 4, Blocks.dirt);
		world.setBlock(i + 7, j + 4, k + 5, Blocks.dirt);
		world.setBlock(i + 7, j + 4, k + 6, Blocks.dirt);
		world.setBlock(i + 7, j + 4, k + 7, Blocks.dirt);
		world.setBlock(i + 7, j + 4, k + 8, Blocks.dirt);
		world.setBlock(i + 7, j + 4, k + 9, Blocks.dirt);
		world.setBlock(i + 7, j + 4, k + 10, Blocks.dirt);
		world.setBlock(i + 7, j + 4, k + 11, Blocks.dirt);
		world.setBlock(i + 7, j + 4, k + 12, Blocks.dirt);
		world.setBlock(i + 7, j + 5, k + 0, Blocks.nether_brick);
		world.setBlock(i + 7, j + 5, k + 1, Blocks.sandstone, 2, 0x02);
		world.setBlock(i + 7, j + 5, k + 2, Blocks.sandstone, 2, 0x02);
		world.setBlock(i + 7, j + 5, k + 3, Blocks.nether_brick);
		world.setBlock(i + 7, j + 5, k + 4, Blocks.sandstone, 2, 0x02);
		world.setBlock(i + 7, j + 5, k + 5, Blocks.sandstone, 2, 0x02);
		world.setBlock(i + 7, j + 5, k + 6, Blocks.nether_brick);
		world.setBlock(i + 7, j + 5, k + 7, Blocks.sandstone, 2, 0x02);
		world.setBlock(i + 7, j + 5, k + 8, Blocks.sandstone, 2, 0x02);
		world.setBlock(i + 7, j + 5, k + 9, Blocks.nether_brick);
		world.setBlock(i + 7, j + 5, k + 10, Blocks.sandstone, 2, 0x02);
		world.setBlock(i + 7, j + 5, k + 11, Blocks.sandstone, 2, 0x02);
		world.setBlock(i + 7, j + 5, k + 12, Blocks.nether_brick);
		world.setBlock(i + 7, j + 10, k + 0, Blocks.nether_brick_stairs, 4, 0x02);
		world.setBlock(i + 7, j + 10, k + 12, Blocks.nether_brick_stairs, 4, 0x02);
		world.setBlock(i + 7, j + 11, k + 0, Blocks.sandstone, 1, 0x02);
		world.setBlock(i + 7, j + 11, k + 12, Blocks.sandstone, 1, 0x02);
		world.setBlock(i + 7, j + 12, k + 1, Blocks.sandstone, 2, 0x02);
		world.setBlock(i + 7, j + 12, k + 2, Blocks.sandstone, 2, 0x02);
		world.setBlock(i + 7, j + 12, k + 3, Blocks.sandstone, 2, 0x02);
		world.setBlock(i + 7, j + 12, k + 4, Blocks.sandstone, 2, 0x02);
		world.setBlock(i + 7, j + 12, k + 8, Blocks.sandstone, 2, 0x02);
		world.setBlock(i + 7, j + 12, k + 9, Blocks.sandstone, 2, 0x02);
		world.setBlock(i + 7, j + 12, k + 10, Blocks.sandstone, 2, 0x02);
		world.setBlock(i + 7, j + 12, k + 11, Blocks.sandstone, 2, 0x02);
		world.setBlock(i + 7, j + 13, k + 5, Blocks.sandstone, 2, 0x02);
		world.setBlock(i + 7, j + 13, k + 7, Blocks.sandstone, 2, 0x02);
		world.setBlock(i + 7, j + 14, k + 6, Blocks.sandstone, 2, 0x02);
		world.setBlock(i + 8, j + 0, k + 0, Blocks.dirt);
		world.setBlock(i + 8, j + 0, k + 1, Blocks.dirt);
		world.setBlock(i + 8, j + 0, k + 2, Blocks.dirt);
		world.setBlock(i + 8, j + 0, k + 3, Blocks.dirt);
		world.setBlock(i + 8, j + 0, k + 4, Blocks.dirt);
		world.setBlock(i + 8, j + 0, k + 5, Blocks.dirt);
		world.setBlock(i + 8, j + 0, k + 6, Blocks.dirt);
		world.setBlock(i + 8, j + 0, k + 7, Blocks.dirt);
		world.setBlock(i + 8, j + 0, k + 8, Blocks.dirt);
		world.setBlock(i + 8, j + 0, k + 9, Blocks.dirt);
		world.setBlock(i + 8, j + 0, k + 10, Blocks.dirt);
		world.setBlock(i + 8, j + 0, k + 11, Blocks.dirt);
		world.setBlock(i + 8, j + 0, k + 12, Blocks.dirt);
		world.setBlock(i + 8, j + 1, k + 0, Blocks.dirt);
		world.setBlock(i + 8, j + 1, k + 1, Blocks.dirt);
		world.setBlock(i + 8, j + 1, k + 2, Blocks.dirt);
		world.setBlock(i + 8, j + 1, k + 3, Blocks.dirt);
		world.setBlock(i + 8, j + 1, k + 4, Blocks.dirt);
		world.setBlock(i + 8, j + 1, k + 5, Blocks.dirt);
		world.setBlock(i + 8, j + 1, k + 6, Blocks.dirt);
		world.setBlock(i + 8, j + 1, k + 7, Blocks.dirt);
		world.setBlock(i + 8, j + 1, k + 8, Blocks.dirt);
		world.setBlock(i + 8, j + 1, k + 9, Blocks.dirt);
		world.setBlock(i + 8, j + 1, k + 10, Blocks.dirt);
		world.setBlock(i + 8, j + 1, k + 11, Blocks.dirt);
		world.setBlock(i + 8, j + 1, k + 12, Blocks.dirt);
		world.setBlock(i + 8, j + 2, k + 0, Blocks.grass);
		world.setBlock(i + 8, j + 2, k + 1, Blocks.grass);
		world.setBlock(i + 8, j + 2, k + 2, Blocks.grass);
		world.setBlock(i + 8, j + 2, k + 3, Blocks.grass);
		world.setBlock(i + 8, j + 2, k + 4, Blocks.grass);
		world.setBlock(i + 8, j + 2, k + 5, Blocks.grass);
		world.setBlock(i + 8, j + 2, k + 6, Blocks.dirt);
		world.setBlock(i + 8, j + 2, k + 7, Blocks.dirt);
		world.setBlock(i + 8, j + 2, k + 8, Blocks.dirt);
		world.setBlock(i + 8, j + 2, k + 9, Blocks.dirt);
		world.setBlock(i + 8, j + 2, k + 10, Blocks.dirt);
		world.setBlock(i + 8, j + 2, k + 11, Blocks.dirt);
		world.setBlock(i + 8, j + 2, k + 12, Blocks.dirt);
		world.setBlock(i + 8, j + 3, k + 0, Blocks.dirt);
		world.setBlock(i + 8, j + 3, k + 1, Blocks.dirt);
		world.setBlock(i + 8, j + 3, k + 2, Blocks.dirt);
		world.setBlock(i + 8, j + 3, k + 3, Blocks.dirt);
		world.setBlock(i + 8, j + 3, k + 4, Blocks.dirt);
		world.setBlock(i + 8, j + 3, k + 5, Blocks.dirt);
		world.setBlock(i + 8, j + 3, k + 6, Blocks.dirt);
		world.setBlock(i + 8, j + 3, k + 7, Blocks.dirt);
		world.setBlock(i + 8, j + 3, k + 8, Blocks.dirt);
		world.setBlock(i + 8, j + 3, k + 9, Blocks.dirt);
		world.setBlock(i + 8, j + 3, k + 10, Blocks.dirt);
		world.setBlock(i + 8, j + 3, k + 11, Blocks.dirt);
		world.setBlock(i + 8, j + 3, k + 12, Blocks.dirt);
		world.setBlock(i + 8, j + 4, k + 0, Blocks.dirt);
		world.setBlock(i + 8, j + 4, k + 1, Blocks.dirt);
		world.setBlock(i + 8, j + 4, k + 2, Blocks.dirt);
		world.setBlock(i + 8, j + 4, k + 3, Blocks.dirt);
		world.setBlock(i + 8, j + 4, k + 4, Blocks.dirt);
		world.setBlock(i + 8, j + 4, k + 5, Blocks.dirt);
		world.setBlock(i + 8, j + 4, k + 6, Blocks.dirt);
		world.setBlock(i + 8, j + 4, k + 7, Blocks.dirt);
		world.setBlock(i + 8, j + 4, k + 8, Blocks.dirt);
		world.setBlock(i + 8, j + 4, k + 9, Blocks.dirt);
		world.setBlock(i + 8, j + 4, k + 10, Blocks.dirt);
		world.setBlock(i + 8, j + 4, k + 11, Blocks.dirt);
		world.setBlock(i + 8, j + 4, k + 12, Blocks.dirt);
		world.setBlock(i + 8, j + 5, k + 0, Blocks.nether_brick);
		world.setBlock(i + 8, j + 5, k + 1, Blocks.sandstone, 2, 0x02);
		world.setBlock(i + 8, j + 5, k + 2, Blocks.sandstone, 2, 0x02);
		world.setBlock(i + 8, j + 5, k + 3, Blocks.sandstone, 2, 0x02);
		world.setBlock(i + 8, j + 5, k + 4, Blocks.nether_brick);
		world.setBlock(i + 8, j + 5, k + 5, Blocks.sandstone, 2, 0x02);
		world.setBlock(i + 8, j + 5, k + 6, Blocks.sandstone, 2, 0x02);
		world.setBlock(i + 8, j + 5, k + 7, Blocks.sandstone, 2, 0x02);
		world.setBlock(i + 8, j + 5, k + 8, Blocks.nether_brick);
		world.setBlock(i + 8, j + 5, k + 9, Blocks.sandstone, 2, 0x02);
		world.setBlock(i + 8, j + 5, k + 10, Blocks.sandstone, 2, 0x02);
		world.setBlock(i + 8, j + 5, k + 11, Blocks.sandstone, 2, 0x02);
		world.setBlock(i + 8, j + 5, k + 12, Blocks.nether_brick);
		world.setBlock(i + 8, j + 6, k + 0, Blocks.sandstone, 1, 0x02);
		world.setBlock(i + 8, j + 6, k + 12, Blocks.sandstone, 1, 0x02);
		world.setBlock(i + 8, j + 7, k + 0, Blocks.sandstone, 1, 0x02);
		world.setBlock(i + 8, j + 7, k + 12, Blocks.sandstone, 1, 0x02);
		world.setBlock(i + 8, j + 8, k + 0, Blocks.sandstone, 1, 0x02);
		world.setBlock(i + 8, j + 8, k + 12, Blocks.sandstone, 1, 0x02);
		world.setBlock(i + 8, j + 9, k + 0, Blocks.sandstone, 1, 0x02);
		world.setBlock(i + 8, j + 9, k + 12, Blocks.sandstone, 1, 0x02);
		world.setBlock(i + 8, j + 10, k + 0, Blocks.sandstone, 1, 0x02);
		world.setBlock(i + 8, j + 10, k + 12, Blocks.sandstone, 1, 0x02);
		world.setBlock(i + 8, j + 11, k + 1, Blocks.sandstone, 2, 0x02);
		world.setBlock(i + 8, j + 11, k + 2, Blocks.sandstone, 2, 0x02);
		world.setBlock(i + 8, j + 11, k + 3, Blocks.sandstone, 2, 0x02);
		world.setBlock(i + 8, j + 11, k + 4, Blocks.sandstone, 2, 0x02);
		world.setBlock(i + 8, j + 11, k + 8, Blocks.sandstone, 2, 0x02);
		world.setBlock(i + 8, j + 11, k + 9, Blocks.sandstone, 2, 0x02);
		world.setBlock(i + 8, j + 11, k + 10, Blocks.sandstone, 2, 0x02);
		world.setBlock(i + 8, j + 11, k + 11, Blocks.sandstone, 2, 0x02);
		world.setBlock(i + 8, j + 12, k + 5, Blocks.sandstone, 2, 0x02);
		world.setBlock(i + 8, j + 12, k + 7, Blocks.sandstone, 2, 0x02);
		world.setBlock(i + 8, j + 13, k + 6, Blocks.sandstone, 2, 0x02);
		world.setBlock(i + 9, j + 0, k + 0, Blocks.dirt);
		world.setBlock(i + 9, j + 0, k + 1, Blocks.dirt);
		world.setBlock(i + 9, j + 0, k + 2, Blocks.dirt);
		world.setBlock(i + 9, j + 0, k + 3, Blocks.dirt);
		world.setBlock(i + 9, j + 0, k + 4, Blocks.dirt);
		world.setBlock(i + 9, j + 0, k + 5, Blocks.dirt);
		world.setBlock(i + 9, j + 0, k + 6, Blocks.dirt);
		world.setBlock(i + 9, j + 0, k + 7, Blocks.dirt);
		world.setBlock(i + 9, j + 0, k + 8, Blocks.dirt);
		world.setBlock(i + 9, j + 0, k + 9, Blocks.dirt);
		world.setBlock(i + 9, j + 0, k + 10, Blocks.dirt);
		world.setBlock(i + 9, j + 0, k + 11, Blocks.dirt);
		world.setBlock(i + 9, j + 0, k + 12, Blocks.dirt);
		world.setBlock(i + 9, j + 1, k + 0, Blocks.dirt);
		world.setBlock(i + 9, j + 1, k + 1, Blocks.dirt);
		world.setBlock(i + 9, j + 1, k + 2, Blocks.dirt);
		world.setBlock(i + 9, j + 1, k + 3, Blocks.dirt);
		world.setBlock(i + 9, j + 1, k + 4, Blocks.dirt);
		world.setBlock(i + 9, j + 1, k + 5, Blocks.dirt);
		world.setBlock(i + 9, j + 1, k + 6, Blocks.dirt);
		world.setBlock(i + 9, j + 1, k + 7, Blocks.dirt);
		world.setBlock(i + 9, j + 1, k + 8, Blocks.dirt);
		world.setBlock(i + 9, j + 1, k + 9, Blocks.dirt);
		world.setBlock(i + 9, j + 1, k + 10, Blocks.dirt);
		world.setBlock(i + 9, j + 1, k + 11, Blocks.dirt);
		world.setBlock(i + 9, j + 1, k + 12, Blocks.dirt);
		world.setBlock(i + 9, j + 2, k + 0, Blocks.grass);
		world.setBlock(i + 9, j + 2, k + 1, Blocks.grass);
		world.setBlock(i + 9, j + 2, k + 2, Blocks.grass);
		world.setBlock(i + 9, j + 2, k + 3, Blocks.grass);
		world.setBlock(i + 9, j + 2, k + 4, Blocks.grass);
		world.setBlock(i + 9, j + 2, k + 5, Blocks.grass);
		world.setBlock(i + 9, j + 2, k + 6, Blocks.dirt);
		world.setBlock(i + 9, j + 2, k + 7, Blocks.dirt);
		world.setBlock(i + 9, j + 2, k + 8, Blocks.dirt);
		world.setBlock(i + 9, j + 2, k + 9, Blocks.dirt);
		world.setBlock(i + 9, j + 2, k + 10, Blocks.dirt);
		world.setBlock(i + 9, j + 2, k + 11, Blocks.dirt);
		world.setBlock(i + 9, j + 2, k + 12, Blocks.dirt);
		world.setBlock(i + 9, j + 3, k + 0, Blocks.dirt);
		world.setBlock(i + 9, j + 3, k + 1, Blocks.dirt);
		world.setBlock(i + 9, j + 3, k + 2, Blocks.dirt);
		world.setBlock(i + 9, j + 3, k + 3, Blocks.dirt);
		world.setBlock(i + 9, j + 3, k + 4, Blocks.dirt);
		world.setBlock(i + 9, j + 3, k + 5, Blocks.dirt);
		world.setBlock(i + 9, j + 3, k + 6, Blocks.dirt);
		world.setBlock(i + 9, j + 3, k + 7, Blocks.dirt);
		world.setBlock(i + 9, j + 3, k + 8, Blocks.dirt);
		world.setBlock(i + 9, j + 3, k + 9, Blocks.dirt);
		world.setBlock(i + 9, j + 3, k + 10, Blocks.dirt);
		world.setBlock(i + 9, j + 3, k + 11, Blocks.dirt);
		world.setBlock(i + 9, j + 3, k + 12, Blocks.dirt);
		world.setBlock(i + 9, j + 4, k + 0, Blocks.dirt);
		world.setBlock(i + 9, j + 4, k + 1, Blocks.dirt);
		world.setBlock(i + 9, j + 4, k + 2, Blocks.dirt);
		world.setBlock(i + 9, j + 4, k + 3, Blocks.dirt);
		world.setBlock(i + 9, j + 4, k + 4, Blocks.dirt);
		world.setBlock(i + 9, j + 4, k + 5, Blocks.dirt);
		world.setBlock(i + 9, j + 4, k + 6, Blocks.dirt);
		world.setBlock(i + 9, j + 4, k + 7, Blocks.dirt);
		world.setBlock(i + 9, j + 4, k + 8, Blocks.dirt);
		world.setBlock(i + 9, j + 4, k + 9, Blocks.dirt);
		world.setBlock(i + 9, j + 4, k + 10, Blocks.dirt);
		world.setBlock(i + 9, j + 4, k + 11, Blocks.dirt);
		world.setBlock(i + 9, j + 4, k + 12, Blocks.dirt);
		world.setBlock(i + 9, j + 5, k + 0, Blocks.grass);
		world.setBlock(i + 9, j + 5, k + 1, Blocks.nether_brick);
		world.setBlock(i + 9, j + 5, k + 2, Blocks.sandstone, 2, 0x02);
		world.setBlock(i + 9, j + 5, k + 3, Blocks.sandstone, 2, 0x02);
		world.setBlock(i + 9, j + 5, k + 4, Blocks.sandstone, 2, 0x02);
		world.setBlock(i + 9, j + 5, k + 5, Blocks.nether_brick);
		world.setBlock(i + 9, j + 5, k + 6, Blocks.nether_brick);
		world.setBlock(i + 9, j + 5, k + 7, Blocks.nether_brick);
		world.setBlock(i + 9, j + 5, k + 8, Blocks.sandstone, 2, 0x02);
		world.setBlock(i + 9, j + 5, k + 9, Blocks.sandstone, 2, 0x02);
		world.setBlock(i + 9, j + 5, k + 10, Blocks.sandstone, 2, 0x02);
		world.setBlock(i + 9, j + 5, k + 11, Blocks.nether_brick);
		world.setBlock(i + 9, j + 5, k + 12, Blocks.grass);
		world.setBlock(i + 9, j + 10, k + 0, Blocks.nether_brick_stairs, 2, 0x02);
		world.setBlock(i + 9, j + 10, k + 1, Blocks.nether_brick);
		world.setBlock(i + 9, j + 10, k + 2, Blocks.sandstone, 2, 0x02);
		world.setBlock(i + 9, j + 10, k + 10, Blocks.sandstone, 2, 0x02);
		world.setBlock(i + 9, j + 10, k + 11, Blocks.nether_brick);
		world.setBlock(i + 9, j + 10, k + 12, Blocks.nether_brick_stairs, 3, 0x02);
		world.setBlock(i + 9, j + 11, k + 3, Blocks.glowstone);
		world.setBlock(i + 9, j + 11, k + 4, Blocks.sandstone, 2, 0x02);
		world.setBlock(i + 9, j + 11, k + 8, Blocks.sandstone, 2, 0x02);
		world.setBlock(i + 9, j + 11, k + 9, Blocks.glowstone);
		world.setBlock(i + 9, j + 12, k + 5, Blocks.sandstone, 2, 0x02);
		world.setBlock(i + 9, j + 12, k + 7, Blocks.sandstone, 2, 0x02);
		world.setBlock(i + 9, j + 13, k + 6, Blocks.sandstone, 2, 0x02);
		world.setBlock(i + 10, j + 0, k + 0, Blocks.dirt);
		world.setBlock(i + 10, j + 0, k + 1, Blocks.dirt);
		world.setBlock(i + 10, j + 0, k + 2, Blocks.dirt);
		world.setBlock(i + 10, j + 0, k + 3, Blocks.dirt);
		world.setBlock(i + 10, j + 0, k + 4, Blocks.dirt);
		world.setBlock(i + 10, j + 0, k + 5, Blocks.dirt);
		world.setBlock(i + 10, j + 0, k + 6, Blocks.dirt);
		world.setBlock(i + 10, j + 0, k + 7, Blocks.dirt);
		world.setBlock(i + 10, j + 0, k + 8, Blocks.dirt);
		world.setBlock(i + 10, j + 0, k + 9, Blocks.dirt);
		world.setBlock(i + 10, j + 0, k + 10, Blocks.dirt);
		world.setBlock(i + 10, j + 0, k + 11, Blocks.dirt);
		world.setBlock(i + 10, j + 0, k + 12, Blocks.dirt);
		world.setBlock(i + 10, j + 1, k + 0, Blocks.dirt);
		world.setBlock(i + 10, j + 1, k + 1, Blocks.dirt);
		world.setBlock(i + 10, j + 1, k + 2, Blocks.dirt);
		world.setBlock(i + 10, j + 1, k + 3, Blocks.dirt);
		world.setBlock(i + 10, j + 1, k + 4, Blocks.dirt);
		world.setBlock(i + 10, j + 1, k + 5, Blocks.dirt);
		world.setBlock(i + 10, j + 1, k + 6, Blocks.dirt);
		world.setBlock(i + 10, j + 1, k + 7, Blocks.dirt);
		world.setBlock(i + 10, j + 1, k + 8, Blocks.dirt);
		world.setBlock(i + 10, j + 1, k + 9, Blocks.dirt);
		world.setBlock(i + 10, j + 1, k + 10, Blocks.dirt);
		world.setBlock(i + 10, j + 1, k + 11, Blocks.dirt);
		world.setBlock(i + 10, j + 1, k + 12, Blocks.dirt);
		world.setBlock(i + 10, j + 2, k + 0, Blocks.grass);
		world.setBlock(i + 10, j + 2, k + 1, Blocks.grass);
		world.setBlock(i + 10, j + 2, k + 2, Blocks.grass);
		world.setBlock(i + 10, j + 2, k + 3, Blocks.grass);
		world.setBlock(i + 10, j + 2, k + 4, Blocks.grass);
		world.setBlock(i + 10, j + 2, k + 5, Blocks.grass);
		world.setBlock(i + 10, j + 2, k + 6, Blocks.dirt);
		world.setBlock(i + 10, j + 2, k + 7, Blocks.dirt);
		world.setBlock(i + 10, j + 2, k + 8, Blocks.dirt);
		world.setBlock(i + 10, j + 2, k + 9, Blocks.dirt);
		world.setBlock(i + 10, j + 2, k + 10, Blocks.dirt);
		world.setBlock(i + 10, j + 2, k + 11, Blocks.dirt);
		world.setBlock(i + 10, j + 2, k + 12, Blocks.dirt);
		world.setBlock(i + 10, j + 3, k + 0, Blocks.dirt);
		world.setBlock(i + 10, j + 3, k + 1, Blocks.dirt);
		world.setBlock(i + 10, j + 3, k + 2, Blocks.dirt);
		world.setBlock(i + 10, j + 3, k + 3, Blocks.dirt);
		world.setBlock(i + 10, j + 3, k + 4, Blocks.dirt);
		world.setBlock(i + 10, j + 3, k + 5, Blocks.dirt);
		world.setBlock(i + 10, j + 3, k + 6, Blocks.dirt);
		world.setBlock(i + 10, j + 3, k + 7, Blocks.dirt);
		world.setBlock(i + 10, j + 3, k + 8, Blocks.dirt);
		world.setBlock(i + 10, j + 3, k + 9, Blocks.dirt);
		world.setBlock(i + 10, j + 3, k + 10, Blocks.dirt);
		world.setBlock(i + 10, j + 3, k + 11, Blocks.dirt);
		world.setBlock(i + 10, j + 3, k + 12, Blocks.dirt);
		world.setBlock(i + 10, j + 4, k + 0, Blocks.dirt);
		world.setBlock(i + 10, j + 4, k + 1, Blocks.dirt);
		world.setBlock(i + 10, j + 4, k + 2, Blocks.dirt);
		world.setBlock(i + 10, j + 4, k + 3, Blocks.dirt);
		world.setBlock(i + 10, j + 4, k + 4, Blocks.dirt);
		world.setBlock(i + 10, j + 4, k + 5, Blocks.dirt);
		world.setBlock(i + 10, j + 4, k + 6, Blocks.dirt);
		world.setBlock(i + 10, j + 4, k + 7, Blocks.dirt);
		world.setBlock(i + 10, j + 4, k + 8, Blocks.dirt);
		world.setBlock(i + 10, j + 4, k + 9, Blocks.dirt);
		world.setBlock(i + 10, j + 4, k + 10, Blocks.dirt);
		world.setBlock(i + 10, j + 4, k + 11, Blocks.dirt);
		world.setBlock(i + 10, j + 4, k + 12, Blocks.dirt);
		world.setBlock(i + 10, j + 5, k + 0, Blocks.grass);
		world.setBlock(i + 10, j + 5, k + 1, Blocks.nether_brick);
		world.setBlock(i + 10, j + 5, k + 2, Blocks.sandstone, 2, 0x02);
		world.setBlock(i + 10, j + 5, k + 3, Blocks.sandstone, 2, 0x02);
		world.setBlock(i + 10, j + 5, k + 4, Blocks.sandstone, 2, 0x02);
		world.setBlock(i + 10, j + 5, k + 5, Blocks.sandstone, 2, 0x02);
		world.setBlock(i + 10, j + 5, k + 6, Blocks.sandstone, 2, 0x02);
		world.setBlock(i + 10, j + 5, k + 7, Blocks.sandstone, 2, 0x02);
		world.setBlock(i + 10, j + 5, k + 8, Blocks.sandstone, 2, 0x02);
		world.setBlock(i + 10, j + 5, k + 9, Blocks.sandstone, 2, 0x02);
		world.setBlock(i + 10, j + 5, k + 10, Blocks.sandstone, 2, 0x02);
		world.setBlock(i + 10, j + 5, k + 11, Blocks.nether_brick);
		world.setBlock(i + 10, j + 5, k + 12, Blocks.grass);
		world.setBlock(i + 10, j + 10, k + 0, Blocks.nether_brick_stairs, 2, 0x02);
		world.setBlock(i + 10, j + 10, k + 1, Blocks.nether_brick);
		world.setBlock(i + 10, j + 10, k + 2, Blocks.sandstone, 2, 0x02);
		world.setBlock(i + 10, j + 10, k + 3, Blocks.sandstone, 2, 0x02);
		world.setBlock(i + 10, j + 10, k + 9, Blocks.sandstone, 2, 0x02);
		world.setBlock(i + 10, j + 10, k + 10, Blocks.sandstone, 2, 0x02);
		world.setBlock(i + 10, j + 10, k + 11, Blocks.nether_brick);
		world.setBlock(i + 10, j + 10, k + 12, Blocks.nether_brick_stairs, 3, 0x02);
		world.setBlock(i + 10, j + 11, k + 4, Blocks.sandstone, 2, 0x02);
		world.setBlock(i + 10, j + 11, k + 8, Blocks.sandstone, 2, 0x02);
		world.setBlock(i + 10, j + 12, k + 5, Blocks.sandstone, 2, 0x02);
		world.setBlock(i + 10, j + 12, k + 7, Blocks.sandstone, 2, 0x02);
		world.setBlock(i + 10, j + 13, k + 6, Blocks.sandstone, 2, 0x02);
		world.setBlock(i + 11, j + 0, k + 0, Blocks.dirt);
		world.setBlock(i + 11, j + 0, k + 1, Blocks.dirt);
		world.setBlock(i + 11, j + 0, k + 2, Blocks.dirt);
		world.setBlock(i + 11, j + 0, k + 3, Blocks.dirt);
		world.setBlock(i + 11, j + 0, k + 4, Blocks.dirt);
		world.setBlock(i + 11, j + 0, k + 5, Blocks.dirt);
		world.setBlock(i + 11, j + 0, k + 6, Blocks.dirt);
		world.setBlock(i + 11, j + 0, k + 7, Blocks.dirt);
		world.setBlock(i + 11, j + 0, k + 8, Blocks.dirt);
		world.setBlock(i + 11, j + 0, k + 9, Blocks.dirt);
		world.setBlock(i + 11, j + 0, k + 10, Blocks.dirt);
		world.setBlock(i + 11, j + 0, k + 11, Blocks.dirt);
		world.setBlock(i + 11, j + 0, k + 12, Blocks.dirt);
		world.setBlock(i + 11, j + 1, k + 0, Blocks.dirt);
		world.setBlock(i + 11, j + 1, k + 1, Blocks.dirt);
		world.setBlock(i + 11, j + 1, k + 2, Blocks.dirt);
		world.setBlock(i + 11, j + 1, k + 3, Blocks.dirt);
		world.setBlock(i + 11, j + 1, k + 4, Blocks.dirt);
		world.setBlock(i + 11, j + 1, k + 5, Blocks.dirt);
		world.setBlock(i + 11, j + 1, k + 6, Blocks.dirt);
		world.setBlock(i + 11, j + 1, k + 7, Blocks.dirt);
		world.setBlock(i + 11, j + 1, k + 8, Blocks.dirt);
		world.setBlock(i + 11, j + 1, k + 9, Blocks.dirt);
		world.setBlock(i + 11, j + 1, k + 10, Blocks.dirt);
		world.setBlock(i + 11, j + 1, k + 11, Blocks.dirt);
		world.setBlock(i + 11, j + 1, k + 12, Blocks.dirt);
		world.setBlock(i + 11, j + 2, k + 0, Blocks.grass);
		world.setBlock(i + 11, j + 2, k + 1, Blocks.grass);
		world.setBlock(i + 11, j + 2, k + 2, Blocks.grass);
		world.setBlock(i + 11, j + 2, k + 3, Blocks.grass);
		world.setBlock(i + 11, j + 2, k + 4, Blocks.grass);
		world.setBlock(i + 11, j + 2, k + 5, Blocks.grass);
		world.setBlock(i + 11, j + 2, k + 6, Blocks.dirt);
		world.setBlock(i + 11, j + 2, k + 7, Blocks.dirt);
		world.setBlock(i + 11, j + 2, k + 8, Blocks.dirt);
		world.setBlock(i + 11, j + 2, k + 9, Blocks.dirt);
		world.setBlock(i + 11, j + 2, k + 10, Blocks.dirt);
		world.setBlock(i + 11, j + 2, k + 11, Blocks.dirt);
		world.setBlock(i + 11, j + 2, k + 12, Blocks.dirt);
		world.setBlock(i + 11, j + 3, k + 0, Blocks.dirt);
		world.setBlock(i + 11, j + 3, k + 1, Blocks.dirt);
		world.setBlock(i + 11, j + 3, k + 2, Blocks.dirt);
		world.setBlock(i + 11, j + 3, k + 3, Blocks.dirt);
		world.setBlock(i + 11, j + 3, k + 4, Blocks.dirt);
		world.setBlock(i + 11, j + 3, k + 5, Blocks.dirt);
		world.setBlock(i + 11, j + 3, k + 6, Blocks.dirt);
		world.setBlock(i + 11, j + 3, k + 7, Blocks.dirt);
		world.setBlock(i + 11, j + 3, k + 8, Blocks.dirt);
		world.setBlock(i + 11, j + 3, k + 9, Blocks.dirt);
		world.setBlock(i + 11, j + 3, k + 10, Blocks.dirt);
		world.setBlock(i + 11, j + 3, k + 11, Blocks.dirt);
		world.setBlock(i + 11, j + 3, k + 12, Blocks.dirt);
		world.setBlock(i + 11, j + 4, k + 0, Blocks.dirt);
		world.setBlock(i + 11, j + 4, k + 1, Blocks.dirt);
		world.setBlock(i + 11, j + 4, k + 2, Blocks.dirt);
		world.setBlock(i + 11, j + 4, k + 3, Blocks.dirt);
		world.setBlock(i + 11, j + 4, k + 4, Blocks.dirt);
		world.setBlock(i + 11, j + 4, k + 5, Blocks.dirt);
		world.setBlock(i + 11, j + 4, k + 6, Blocks.dirt);
		world.setBlock(i + 11, j + 4, k + 7, Blocks.dirt);
		world.setBlock(i + 11, j + 4, k + 8, Blocks.dirt);
		world.setBlock(i + 11, j + 4, k + 9, Blocks.dirt);
		world.setBlock(i + 11, j + 4, k + 10, Blocks.dirt);
		world.setBlock(i + 11, j + 4, k + 11, Blocks.dirt);
		world.setBlock(i + 11, j + 4, k + 12, Blocks.dirt);
		world.setBlock(i + 11, j + 5, k + 0, Blocks.grass);
		world.setBlock(i + 11, j + 5, k + 1, Blocks.grass);
		world.setBlock(i + 11, j + 5, k + 2, Blocks.nether_brick);
		world.setBlock(i + 11, j + 5, k + 3, Blocks.nether_brick);
		world.setBlock(i + 11, j + 5, k + 4, Blocks.sandstone, 2, 0x02);
		world.setBlock(i + 11, j + 5, k + 5, Blocks.sandstone, 2, 0x02);
		world.setBlock(i + 11, j + 5, k + 6, Blocks.sandstone, 2, 0x02);
		world.setBlock(i + 11, j + 5, k + 7, Blocks.sandstone, 2, 0x02);
		world.setBlock(i + 11, j + 5, k + 8, Blocks.sandstone, 2, 0x02);
		world.setBlock(i + 11, j + 5, k + 9, Blocks.nether_brick);
		world.setBlock(i + 11, j + 5, k + 10, Blocks.nether_brick);
		world.setBlock(i + 11, j + 5, k + 11, Blocks.grass);
		world.setBlock(i + 11, j + 5, k + 12, Blocks.grass);
		world.setBlock(i + 11, j + 10, k + 0, Blocks.nether_brick_stairs, 1, 0x02);
		world.setBlock(i + 11, j + 10, k + 1, Blocks.nether_brick_stairs, 1, 0x02);
		world.setBlock(i + 11, j + 10, k + 2, Blocks.nether_brick);
		world.setBlock(i + 11, j + 10, k + 3, Blocks.nether_brick);
		world.setBlock(i + 11, j + 10, k + 9, Blocks.nether_brick);
		world.setBlock(i + 11, j + 10, k + 10, Blocks.nether_brick);
		world.setBlock(i + 11, j + 10, k + 11, Blocks.nether_brick_stairs, 3, 0x02);
		world.setBlock(i + 11, j + 10, k + 12, Blocks.nether_brick_stairs, 1, 0x02);
		world.setBlock(i + 11, j + 11, k + 4, Blocks.sandstone, 2, 0x02);
		world.setBlock(i + 11, j + 11, k + 8, Blocks.sandstone, 2, 0x02);
		world.setBlock(i + 11, j + 12, k + 5, Blocks.sandstone, 2, 0x02);
		world.setBlock(i + 11, j + 12, k + 7, Blocks.sandstone, 2, 0x02);
		world.setBlock(i + 11, j + 13, k + 6, Blocks.sandstone, 2, 0x02);
		world.setBlock(i + 12, j + 0, k + 0, Blocks.dirt);
		world.setBlock(i + 12, j + 0, k + 1, Blocks.dirt);
		world.setBlock(i + 12, j + 0, k + 2, Blocks.dirt);
		world.setBlock(i + 12, j + 0, k + 3, Blocks.dirt);
		world.setBlock(i + 12, j + 0, k + 4, Blocks.dirt);
		world.setBlock(i + 12, j + 0, k + 5, Blocks.dirt);
		world.setBlock(i + 12, j + 0, k + 6, Blocks.dirt);
		world.setBlock(i + 12, j + 0, k + 7, Blocks.dirt);
		world.setBlock(i + 12, j + 0, k + 8, Blocks.dirt);
		world.setBlock(i + 12, j + 0, k + 9, Blocks.dirt);
		world.setBlock(i + 12, j + 0, k + 10, Blocks.dirt);
		world.setBlock(i + 12, j + 0, k + 11, Blocks.dirt);
		world.setBlock(i + 12, j + 0, k + 12, Blocks.dirt);
		world.setBlock(i + 12, j + 1, k + 0, Blocks.dirt);
		world.setBlock(i + 12, j + 1, k + 1, Blocks.dirt);
		world.setBlock(i + 12, j + 1, k + 2, Blocks.dirt);
		world.setBlock(i + 12, j + 1, k + 3, Blocks.dirt);
		world.setBlock(i + 12, j + 1, k + 4, Blocks.dirt);
		world.setBlock(i + 12, j + 1, k + 5, Blocks.dirt);
		world.setBlock(i + 12, j + 1, k + 6, Blocks.dirt);
		world.setBlock(i + 12, j + 1, k + 7, Blocks.dirt);
		world.setBlock(i + 12, j + 1, k + 8, Blocks.dirt);
		world.setBlock(i + 12, j + 1, k + 9, Blocks.dirt);
		world.setBlock(i + 12, j + 1, k + 10, Blocks.dirt);
		world.setBlock(i + 12, j + 1, k + 11, Blocks.dirt);
		world.setBlock(i + 12, j + 1, k + 12, Blocks.dirt);
		world.setBlock(i + 12, j + 2, k + 0, Blocks.grass);
		world.setBlock(i + 12, j + 2, k + 1, Blocks.grass);
		world.setBlock(i + 12, j + 2, k + 2, Blocks.grass);
		world.setBlock(i + 12, j + 2, k + 3, Blocks.grass);
		world.setBlock(i + 12, j + 2, k + 4, Blocks.grass);
		world.setBlock(i + 12, j + 2, k + 5, Blocks.grass);
		world.setBlock(i + 12, j + 2, k + 6, Blocks.dirt);
		world.setBlock(i + 12, j + 2, k + 7, Blocks.dirt);
		world.setBlock(i + 12, j + 2, k + 8, Blocks.dirt);
		world.setBlock(i + 12, j + 2, k + 9, Blocks.dirt);
		world.setBlock(i + 12, j + 2, k + 10, Blocks.dirt);
		world.setBlock(i + 12, j + 2, k + 11, Blocks.dirt);
		world.setBlock(i + 12, j + 2, k + 12, Blocks.dirt);
		world.setBlock(i + 12, j + 3, k + 0, Blocks.dirt);
		world.setBlock(i + 12, j + 3, k + 1, Blocks.dirt);
		world.setBlock(i + 12, j + 3, k + 2, Blocks.dirt);
		world.setBlock(i + 12, j + 3, k + 3, Blocks.dirt);
		world.setBlock(i + 12, j + 3, k + 4, Blocks.dirt);
		world.setBlock(i + 12, j + 3, k + 5, Blocks.dirt);
		world.setBlock(i + 12, j + 3, k + 6, Blocks.dirt);
		world.setBlock(i + 12, j + 3, k + 7, Blocks.dirt);
		world.setBlock(i + 12, j + 3, k + 8, Blocks.dirt);
		world.setBlock(i + 12, j + 3, k + 9, Blocks.dirt);
		world.setBlock(i + 12, j + 3, k + 10, Blocks.dirt);
		world.setBlock(i + 12, j + 3, k + 11, Blocks.dirt);
		world.setBlock(i + 12, j + 3, k + 12, Blocks.dirt);
		world.setBlock(i + 12, j + 4, k + 0, Blocks.dirt);
		world.setBlock(i + 12, j + 4, k + 1, Blocks.dirt);
		world.setBlock(i + 12, j + 4, k + 2, Blocks.dirt);
		world.setBlock(i + 12, j + 4, k + 3, Blocks.dirt);
		world.setBlock(i + 12, j + 4, k + 4, Blocks.dirt);
		world.setBlock(i + 12, j + 4, k + 5, Blocks.dirt);
		world.setBlock(i + 12, j + 4, k + 6, Blocks.dirt);
		world.setBlock(i + 12, j + 4, k + 7, Blocks.dirt);
		world.setBlock(i + 12, j + 4, k + 8, Blocks.dirt);
		world.setBlock(i + 12, j + 4, k + 9, Blocks.dirt);
		world.setBlock(i + 12, j + 4, k + 10, Blocks.dirt);
		world.setBlock(i + 12, j + 4, k + 11, Blocks.dirt);
		world.setBlock(i + 12, j + 4, k + 12, Blocks.dirt);
		world.setBlock(i + 12, j + 5, k + 0, Blocks.grass);
		world.setBlock(i + 12, j + 5, k + 1, Blocks.grass);
		world.setBlock(i + 12, j + 5, k + 2, Blocks.grass);
		world.setBlock(i + 12, j + 5, k + 3, Blocks.grass);
		world.setBlock(i + 12, j + 5, k + 4, Blocks.nether_brick);
		world.setBlock(i + 12, j + 5, k + 5, Blocks.nether_brick);
		world.setBlock(i + 12, j + 5, k + 6, Blocks.nether_brick);
		world.setBlock(i + 12, j + 5, k + 7, Blocks.nether_brick);
		world.setBlock(i + 12, j + 5, k + 8, Blocks.nether_brick);
		world.setBlock(i + 12, j + 5, k + 9, Blocks.grass);
		world.setBlock(i + 12, j + 5, k + 10, Blocks.grass);
		world.setBlock(i + 12, j + 5, k + 11, Blocks.grass);
		world.setBlock(i + 12, j + 5, k + 12, Blocks.grass);
		world.setBlock(i + 12, j + 6, k + 4, Blocks.sandstone, 1, 0x02);
		world.setBlock(i + 12, j + 6, k + 8, Blocks.sandstone, 1, 0x02);
		world.setBlock(i + 12, j + 7, k + 4, Blocks.sandstone, 1, 0x02);
		world.setBlock(i + 12, j + 7, k + 8, Blocks.sandstone, 1, 0x02);
		world.setBlock(i + 12, j + 8, k + 4, Blocks.sandstone, 1, 0x02);
		world.setBlock(i + 12, j + 8, k + 8, Blocks.sandstone, 1, 0x02);
		world.setBlock(i + 12, j + 9, k + 4, Blocks.sandstone, 1, 0x02);
		world.setBlock(i + 12, j + 9, k + 8, Blocks.sandstone, 1, 0x02);
		world.setBlock(i + 12, j + 10, k + 1, Blocks.nether_brick_stairs, 2, 0x02);
		world.setBlock(i + 12, j + 10, k + 2, Blocks.nether_brick_stairs, 1, 0x02);
		world.setBlock(i + 12, j + 10, k + 3, Blocks.nether_brick_stairs, 1, 0x02);
		world.setBlock(i + 12, j + 10, k + 4, Blocks.sandstone, 1, 0x02);
		world.setBlock(i + 12, j + 10, k + 5, Blocks.nether_brick_stairs, 7, 0x02);
		world.setBlock(i + 12, j + 10, k + 7, Blocks.nether_brick_stairs, 6, 0x02);
		world.setBlock(i + 12, j + 10, k + 8, Blocks.sandstone, 1, 0x02);
		world.setBlock(i + 12, j + 10, k + 9, Blocks.nether_brick_stairs, 1, 0x02);
		world.setBlock(i + 12, j + 10, k + 10, Blocks.nether_brick_stairs, 1, 0x02);
		world.setBlock(i + 12, j + 10, k + 11, Blocks.nether_brick_stairs, 3, 0x02);
		world.setBlock(i + 12, j + 11, k + 5, Blocks.sandstone, 1, 0x02);
		world.setBlock(i + 12, j + 11, k + 6, mod_Avatar.AirNomadsBlock);
		world.setBlock(i + 12, j + 11, k + 7, Blocks.sandstone, 1, 0x02);
		world.setBlock(i + 12, j + 12, k + 6, Blocks.sandstone, 1, 0x02);

		return true;
	}
}