package kieranvs.avatar.generation;

import java.util.Random;

import cpw.mods.fml.common.IWorldGenerator;
import kieranvs.avatar.mod_Avatar;
import kieranvs.avatar.bending.ElementManager;
import kieranvs.avatar.entity.EntityAirMan;
import kieranvs.avatar.entity.EntityFireMan;
import kieranvs.avatar.util.GenerationUtils;
import net.minecraft.block.Block;
import net.minecraft.init.Blocks;
import net.minecraft.item.ItemStack;
import net.minecraft.tileentity.TileEntity;
import net.minecraft.tileentity.TileEntityChest;
import net.minecraft.world.World;
import net.minecraft.world.biome.BiomeGenBase;
import net.minecraft.world.chunk.IChunkProvider;
import net.minecraft.world.gen.feature.WorldGenerator;

public class WorldGenFireNationTower implements IWorldGenerator {
	
	private static BiomeGenBase[] biomes = {BiomeGenBase.desert, BiomeGenBase.desertHills, BiomeGenBase.savanna, BiomeGenBase.savannaPlateau};
	
	@Override
	public void generate(Random random, int chunkX, int chunkZ, World world, IChunkProvider chunkGenerator, IChunkProvider chunkProvider) {
		int result[] = GenerationUtils.shouldSpawnHere(random, chunkX, chunkZ, world, 10, 2, 40, biomes);
		if(result[0] == 0){
			this.generate(world, result[1], result[2], result[3]);
			this.generateEntities(world, result[1], result[2] - 5, result[3], random);
			this.generateLoot(world, result[1], result[2], result[3], random);
		}
	}
	
	public void generateEntities(World world, int i, int j, int k, Random random) {
		int numM = random.nextInt(2) + 1;

		for (int x = 0; x < numM; x++) {
			EntityFireMan fireMan = new EntityFireMan(world, i + 5, j + 5, k + 5, 5);
			fireMan.setPositionAndRotation(i + 5, j + 5, k + 5, 1.0F, 1.0F);
			world.spawnEntityInWorld(fireMan);
		}
	}
	
	public void generateLoot(World world, int i, int j, int k, Random random){
		for(int x = i; x < i + 10; x++){
			for (int z = k; z < k + 10; z++) {
				for (int y = j; y < j + 23; y++) {
					TileEntity e = world.getTileEntity(x, y, z);
					if(e != null && e instanceof TileEntityChest){
						GenerationUtils.generateScrolls(random, (TileEntityChest) e, ElementManager.FIRE, 3);
						GenerationUtils.generateRandomMoney(random, (TileEntityChest) e, ElementManager.FIRE, 2);
					}
				}
			}
		}
	}


	public boolean generate(World world, int i, int j, int k) {
		world.setBlock(i + 5, j + 5, k + 2, Blocks.chest, 1, 0x02);
		world.setBlock(i + 2, j + 5, k + 5, Blocks.chest, 1, 0x02);
		world.setBlock(i + 5, j + 5, k + 8, Blocks.chest, 1, 0x02);
		world.setBlock(i + 8, j + 5, k + 5, Blocks.chest, 1, 0x02);
		
		world.setBlock(i + 0, j + 0, k + 4, Blocks.sandstone, 2, 0x02);
		world.setBlock(i + 0, j + 0, k + 5, Blocks.sandstone, 2, 0x02);
		world.setBlock(i + 0, j + 0, k + 6, Blocks.sandstone, 2, 0x02);
		world.setBlock(i + 0, j + 1, k + 3, Blocks.sandstone, 1, 0x02);
		world.setBlock(i + 0, j + 1, k + 7, Blocks.sandstone, 1, 0x02);
		world.setBlock(i + 0, j + 2, k + 3, Blocks.sandstone, 2, 0x02);
		world.setBlock(i + 0, j + 2, k + 7, Blocks.sandstone, 2, 0x02);
		world.setBlock(i + 0, j + 3, k + 3, Blocks.sandstone, 2, 0x02);
		world.setBlock(i + 0, j + 3, k + 4, Blocks.sandstone_stairs, 7, 0x02);
		world.setBlock(i + 0, j + 3, k + 6, Blocks.sandstone_stairs, 6, 0x02);
		world.setBlock(i + 0, j + 3, k + 7, Blocks.sandstone, 2, 0x02);
		world.setBlock(i + 0, j + 4, k + 3, Blocks.sandstone, 2, 0x02);
		world.setBlock(i + 0, j + 4, k + 4, Blocks.sandstone, 2, 0x02);
		world.setBlock(i + 0, j + 4, k + 5, Blocks.nether_brick);
		world.setBlock(i + 0, j + 4, k + 6, Blocks.sandstone, 2, 0x02);
		world.setBlock(i + 0, j + 4, k + 7, Blocks.sandstone, 2, 0x02);
		world.setBlock(i + 1, j + 0, k + 3, Blocks.wool, 14 , 0x02);
		world.setBlock(i + 1, j + 0, k + 4, Blocks.wool, 14 , 0x02);
		world.setBlock(i + 1, j + 0, k + 5, Blocks.wool, 14 , 0x02);
		world.setBlock(i + 1, j + 0, k + 6, Blocks.wool, 14 , 0x02);
		world.setBlock(i + 1, j + 0, k + 7, Blocks.wool, 14 , 0x02);
		world.setBlock(i + 1, j + 1, k + 2, Blocks.sandstone, 1, 0x02);
		world.setBlock(i + 1, j + 1, k + 8, Blocks.sandstone, 1, 0x02);
		world.setBlock(i + 1, j + 2, k + 2, Blocks.sandstone, 2, 0x02);
		world.setBlock(i + 1, j + 2, k + 8, Blocks.sandstone, 2, 0x02);
		world.setBlock(i + 1, j + 3, k + 2, Blocks.sandstone, 2, 0x02);
		world.setBlock(i + 1, j + 3, k + 8, Blocks.sandstone, 2, 0x02);
		world.setBlock(i + 1, j + 4, k + 2, Blocks.sandstone, 2, 0x02);
		world.setBlock(i + 1, j + 4, k + 3, Blocks.planks, 1, 0x02);
		world.setBlock(i + 1, j + 4, k + 4, Blocks.planks, 1, 0x02);
		world.setBlock(i + 1, j + 4, k + 5, Blocks.planks, 1, 0x02);
		world.setBlock(i + 1, j + 4, k + 6, Blocks.planks, 1, 0x02);
		world.setBlock(i + 1, j + 4, k + 7, Blocks.planks, 1, 0x02);
		world.setBlock(i + 1, j + 4, k + 8, Blocks.sandstone, 2, 0x02);
		world.setBlock(i + 1, j + 5, k + 3, Blocks.sandstone, 1, 0x02);
		world.setBlock(i + 1, j + 5, k + 4, Blocks.sandstone, 2, 0x02);
		world.setBlock(i + 1, j + 5, k + 5, Blocks.sandstone, 2, 0x02);
		world.setBlock(i + 1, j + 5, k + 6, Blocks.sandstone, 2, 0x02);
		world.setBlock(i + 1, j + 5, k + 7, Blocks.sandstone, 1, 0x02);
		world.setBlock(i + 1, j + 6, k + 3, Blocks.sandstone, 1, 0x02);
		world.setBlock(i + 1, j + 6, k + 4, Blocks.sandstone, 2, 0x02);
		world.setBlock(i + 1, j + 6, k + 6, Blocks.sandstone, 2, 0x02);
		world.setBlock(i + 1, j + 6, k + 7, Blocks.sandstone, 1, 0x02);
		world.setBlock(i + 1, j + 7, k + 3, Blocks.sandstone, 1, 0x02);
		world.setBlock(i + 1, j + 7, k + 4, Blocks.sandstone, 2, 0x02);
		world.setBlock(i + 1, j + 7, k + 6, Blocks.sandstone, 2, 0x02);
		world.setBlock(i + 1, j + 7, k + 7, Blocks.sandstone, 1, 0x02);
		world.setBlock(i + 1, j + 8, k + 3, Blocks.sandstone, 1, 0x02);
		world.setBlock(i + 1, j + 8, k + 4, Blocks.nether_brick);
		world.setBlock(i + 1, j + 8, k + 5, Blocks.nether_brick);
		world.setBlock(i + 1, j + 8, k + 6, Blocks.nether_brick);
		world.setBlock(i + 1, j + 8, k + 7, Blocks.sandstone, 1, 0x02);
		world.setBlock(i + 2, j + 0, k + 2, Blocks.glowstone);
		world.setBlock(i + 2, j + 0, k + 3, Blocks.wool, 14 , 0x02);
		world.setBlock(i + 2, j + 0, k + 4, Blocks.wool, 14 , 0x02);
		world.setBlock(i + 2, j + 0, k + 5, Blocks.wool, 14 , 0x02);
		world.setBlock(i + 2, j + 0, k + 6, Blocks.sandstone, 2, 0x02);
		world.setBlock(i + 2, j + 0, k + 7, Blocks.wool, 14 , 0x02);
		world.setBlock(i + 2, j + 0, k + 8, Blocks.glowstone);
		world.setBlock(i + 2, j + 1, k + 1, Blocks.sandstone, 1, 0x02);
		world.setBlock(i + 2, j + 1, k + 9, Blocks.sandstone, 1, 0x02);
		world.setBlock(i + 2, j + 2, k + 1, Blocks.sandstone, 2, 0x02);
		world.setBlock(i + 2, j + 2, k + 9, Blocks.sandstone, 2, 0x02);
		world.setBlock(i + 2, j + 3, k + 1, Blocks.sandstone, 2, 0x02);
		world.setBlock(i + 2, j + 3, k + 9, Blocks.sandstone, 2, 0x02);
		world.setBlock(i + 2, j + 4, k + 1, Blocks.sandstone, 2, 0x02);
		world.setBlock(i + 2, j + 4, k + 3, Blocks.planks, 1, 0x02);
		world.setBlock(i + 2, j + 4, k + 4, Blocks.planks, 1, 0x02);
		world.setBlock(i + 2, j + 4, k + 5, Blocks.planks, 1, 0x02);
		world.setBlock(i + 2, j + 4, k + 6, Blocks.planks, 1, 0x02);
		world.setBlock(i + 2, j + 4, k + 7, Blocks.planks, 1, 0x02);
		world.setBlock(i + 2, j + 4, k + 9, Blocks.sandstone, 2, 0x02);
		world.setBlock(i + 2, j + 8, k + 2, Blocks.sandstone, 1, 0x02);
		world.setBlock(i + 2, j + 8, k + 3, Blocks.planks, 1, 0x02);
		world.setBlock(i + 2, j + 8, k + 4, Blocks.planks, 1, 0x02);
		world.setBlock(i + 2, j + 8, k + 5, Blocks.planks, 1, 0x02);
		world.setBlock(i + 2, j + 8, k + 6, Blocks.planks, 1, 0x02);
		world.setBlock(i + 2, j + 8, k + 7, Blocks.planks, 1, 0x02);
		world.setBlock(i + 2, j + 8, k + 8, Blocks.sandstone, 1, 0x02);
		world.setBlock(i + 2, j + 9, k + 3, Blocks.sandstone, 2, 0x02);
		world.setBlock(i + 2, j + 9, k + 4, Blocks.sandstone, 1, 0x02);
		world.setBlock(i + 2, j + 9, k + 5, Blocks.sandstone, 2, 0x02);
		world.setBlock(i + 2, j + 9, k + 6, Blocks.sandstone, 1, 0x02);
		world.setBlock(i + 2, j + 9, k + 7, Blocks.sandstone, 2, 0x02);
		world.setBlock(i + 2, j + 10, k + 3, Blocks.sandstone, 2, 0x02);
		world.setBlock(i + 2, j + 10, k + 4, Blocks.sandstone, 1, 0x02);
		world.setBlock(i + 2, j + 10, k + 5, Blocks.fence);
		world.setBlock(i + 2, j + 10, k + 6, Blocks.sandstone, 1, 0x02);
		world.setBlock(i + 2, j + 10, k + 7, Blocks.sandstone, 2, 0x02);
		world.setBlock(i + 2, j + 11, k + 3, Blocks.sandstone, 2, 0x02);
		world.setBlock(i + 2, j + 11, k + 4, Blocks.sandstone, 1, 0x02);
		world.setBlock(i + 2, j + 11, k + 5, Blocks.fence);
		world.setBlock(i + 2, j + 11, k + 6, Blocks.sandstone, 1, 0x02);
		world.setBlock(i + 2, j + 11, k + 7, Blocks.sandstone, 2, 0x02);
		world.setBlock(i + 2, j + 12, k + 3, Blocks.sandstone, 2, 0x02);
		world.setBlock(i + 2, j + 12, k + 4, Blocks.nether_brick);
		world.setBlock(i + 2, j + 12, k + 5, Blocks.nether_brick);
		world.setBlock(i + 2, j + 12, k + 6, Blocks.nether_brick);
		world.setBlock(i + 2, j + 12, k + 7, Blocks.sandstone, 2, 0x02);
		world.setBlock(i + 3, j + 0, k + 1, Blocks.wool, 14 , 0x02);
		world.setBlock(i + 3, j + 0, k + 2, Blocks.wool, 14 , 0x02);
		world.setBlock(i + 3, j + 0, k + 3, Blocks.sandstone, 2, 0x02);
		world.setBlock(i + 3, j + 0, k + 4, Blocks.wool, 14 , 0x02);
		world.setBlock(i + 3, j + 0, k + 5, Blocks.wool, 14 , 0x02);
		world.setBlock(i + 3, j + 0, k + 6, Blocks.sandstone, 2, 0x02);
		world.setBlock(i + 3, j + 0, k + 7, Blocks.sandstone, 2, 0x02);
		world.setBlock(i + 3, j + 0, k + 8, Blocks.wool, 14 , 0x02);
		world.setBlock(i + 3, j + 0, k + 9, Blocks.wool, 14 , 0x02);
		world.setBlock(i + 3, j + 1, k + 0, Blocks.sandstone, 1, 0x02);
		world.setBlock(i + 3, j + 1, k + 10, Blocks.sandstone, 1, 0x02);
		world.setBlock(i + 3, j + 2, k + 0, Blocks.sandstone, 2, 0x02);
		world.setBlock(i + 3, j + 2, k + 10, Blocks.sandstone, 2, 0x02);
		world.setBlock(i + 3, j + 3, k + 0, Blocks.sandstone, 2, 0x02);
		world.setBlock(i + 3, j + 3, k + 10, Blocks.sandstone, 2, 0x02);
		world.setBlock(i + 3, j + 4, k + 0, Blocks.sandstone, 2, 0x02);
		world.setBlock(i + 3, j + 4, k + 1, Blocks.planks, 1, 0x02);
		world.setBlock(i + 3, j + 4, k + 2, Blocks.planks, 1, 0x02);
		world.setBlock(i + 3, j + 4, k + 3, Blocks.planks, 1, 0x02);
		world.setBlock(i + 3, j + 4, k + 4, Blocks.planks, 1, 0x02);
		world.setBlock(i + 3, j + 4, k + 5, Blocks.planks, 1, 0x02);
		world.setBlock(i + 3, j + 4, k + 6, Blocks.planks, 1, 0x02);
		world.setBlock(i + 3, j + 4, k + 7, Blocks.planks, 1, 0x02);
		world.setBlock(i + 3, j + 4, k + 8, Blocks.planks, 1, 0x02);
		world.setBlock(i + 3, j + 4, k + 9, Blocks.planks, 1, 0x02);
		world.setBlock(i + 3, j + 4, k + 10, Blocks.sandstone, 2, 0x02);
		world.setBlock(i + 3, j + 5, k + 1, Blocks.sandstone, 1, 0x02);
		world.setBlock(i + 3, j + 5, k + 9, Blocks.sandstone, 1, 0x02);
		world.setBlock(i + 3, j + 6, k + 1, Blocks.sandstone, 1, 0x02);
		world.setBlock(i + 3, j + 6, k + 9, Blocks.sandstone, 1, 0x02);
		world.setBlock(i + 3, j + 7, k + 1, Blocks.sandstone, 1, 0x02);
		world.setBlock(i + 3, j + 7, k + 9, Blocks.sandstone, 1, 0x02);
		world.setBlock(i + 3, j + 8, k + 1, Blocks.sandstone, 1, 0x02);
		world.setBlock(i + 3, j + 8, k + 2, Blocks.planks, 1, 0x02);
		world.setBlock(i + 3, j + 8, k + 3, Blocks.glowstone);
		world.setBlock(i + 3, j + 8, k + 4, Blocks.planks, 1, 0x02);
		world.setBlock(i + 3, j + 8, k + 5, Blocks.planks, 1, 0x02);
		world.setBlock(i + 3, j + 8, k + 6, Blocks.planks, 1, 0x02);
		world.setBlock(i + 3, j + 8, k + 7, Blocks.glowstone);
		world.setBlock(i + 3, j + 8, k + 8, Blocks.planks, 1, 0x02);
		world.setBlock(i + 3, j + 8, k + 9, Blocks.sandstone, 1, 0x02);
		world.setBlock(i + 3, j + 9, k + 2, Blocks.sandstone, 2, 0x02);
		world.setBlock(i + 3, j + 9, k + 8, Blocks.sandstone, 2, 0x02);
		world.setBlock(i + 3, j + 10, k + 2, Blocks.sandstone, 2, 0x02);
		world.setBlock(i + 3, j + 10, k + 8, Blocks.sandstone, 2, 0x02);
		world.setBlock(i + 3, j + 11, k + 2, Blocks.sandstone, 2, 0x02);
		world.setBlock(i + 3, j + 11, k + 8, Blocks.sandstone, 2, 0x02);
		world.setBlock(i + 3, j + 12, k + 2, Blocks.sandstone, 2, 0x02);
		world.setBlock(i + 3, j + 12, k + 3, Blocks.planks, 1, 0x02);
		world.setBlock(i + 3, j + 12, k + 4, Blocks.planks, 1, 0x02);
		world.setBlock(i + 3, j + 12, k + 5, Blocks.planks, 1, 0x02);
		world.setBlock(i + 3, j + 12, k + 6, Blocks.planks, 1, 0x02);
		world.setBlock(i + 3, j + 12, k + 7, Blocks.planks, 1, 0x02);
		world.setBlock(i + 3, j + 12, k + 8, Blocks.sandstone, 2, 0x02);
		world.setBlock(i + 3, j + 13, k + 3, Blocks.stone_slab, 1, 0x02);
		world.setBlock(i + 3, j + 13, k + 4, Blocks.sandstone, 1, 0x02);
		world.setBlock(i + 3, j + 13, k + 6, Blocks.sandstone, 1, 0x02);
		world.setBlock(i + 3, j + 13, k + 7, Blocks.stone_slab, 1, 0x02);
		world.setBlock(i + 3, j + 14, k + 4, Blocks.sandstone, 1, 0x02);
		world.setBlock(i + 3, j + 14, k + 6, Blocks.sandstone, 1, 0x02);
		world.setBlock(i + 3, j + 15, k + 4, Blocks.sandstone, 1, 0x02);
		world.setBlock(i + 3, j + 15, k + 5, mod_Avatar.FireNationBlock);
		world.setBlock(i + 3, j + 15, k + 6, Blocks.sandstone, 1, 0x02);
		world.setBlock(i + 3, j + 16, k + 4, Blocks.nether_brick);
		world.setBlock(i + 3, j + 16, k + 5, Blocks.nether_brick);
		world.setBlock(i + 3, j + 16, k + 6, Blocks.nether_brick);
		world.setBlock(i + 3, j + 20, k + 3, Blocks.sandstone_stairs, 6, 0x02);
		world.setBlock(i + 3, j + 20, k + 4, Blocks.sandstone_stairs, 4, 0x02);
		world.setBlock(i + 3, j + 20, k + 6, Blocks.sandstone_stairs, 4, 0x02);
		world.setBlock(i + 3, j + 20, k + 7, Blocks.sandstone_stairs, 4, 0x02);
		world.setBlock(i + 3, j + 21, k + 3, Blocks.nether_brick_stairs, 2, 0x02);
		world.setBlock(i + 3, j + 21, k + 4, Blocks.nether_brick_stairs);
		world.setBlock(i + 3, j + 21, k + 5, Blocks.nether_brick_stairs);
		world.setBlock(i + 3, j + 21, k + 6, Blocks.nether_brick_stairs);
		world.setBlock(i + 3, j + 21, k + 7, Blocks.nether_brick_stairs);
		world.setBlock(i + 4, j + 0, k + 0, Blocks.sandstone, 2, 0x02);
		world.setBlock(i + 4, j + 0, k + 1, Blocks.wool, 14 , 0x02);
		world.setBlock(i + 4, j + 0, k + 2, Blocks.sandstone, 2, 0x02);
		world.setBlock(i + 4, j + 0, k + 3, Blocks.wool, 14 , 0x02);
		world.setBlock(i + 4, j + 0, k + 4, Blocks.wool, 14 , 0x02);
		world.setBlock(i + 4, j + 0, k + 5, Blocks.wool, 14 , 0x02);
		world.setBlock(i + 4, j + 0, k + 6, Blocks.wool, 14 , 0x02);
		world.setBlock(i + 4, j + 0, k + 7, Blocks.sandstone, 2, 0x02);
		world.setBlock(i + 4, j + 0, k + 8, Blocks.sandstone, 2, 0x02);
		world.setBlock(i + 4, j + 0, k + 9, Blocks.wool, 14 , 0x02);
		world.setBlock(i + 4, j + 0, k + 10, Blocks.sandstone, 2, 0x02);
		world.setBlock(i + 4, j + 3, k + 0, Blocks.sandstone_stairs, 5, 0x02);
		world.setBlock(i + 4, j + 3, k + 10, Blocks.sandstone_stairs, 5, 0x02);
		world.setBlock(i + 4, j + 4, k + 0, Blocks.sandstone, 2, 0x02);
		world.setBlock(i + 4, j + 4, k + 1, Blocks.planks, 1, 0x02);
		world.setBlock(i + 4, j + 4, k + 2, Blocks.planks, 1, 0x02);
		world.setBlock(i + 4, j + 4, k + 3, Blocks.planks, 1, 0x02);
		world.setBlock(i + 4, j + 4, k + 4, Blocks.planks, 1, 0x02);
		world.setBlock(i + 4, j + 4, k + 5, Blocks.planks, 1, 0x02);
		world.setBlock(i + 4, j + 4, k + 6, Blocks.planks, 1, 0x02);
		world.setBlock(i + 4, j + 4, k + 7, Blocks.planks, 1, 0x02);
		world.setBlock(i + 4, j + 4, k + 8, Blocks.planks, 1, 0x02);
		world.setBlock(i + 4, j + 4, k + 9, Blocks.planks, 1, 0x02);
		world.setBlock(i + 4, j + 4, k + 10, Blocks.sandstone, 2, 0x02);
		world.setBlock(i + 4, j + 5, k + 1, Blocks.sandstone, 2, 0x02);
		world.setBlock(i + 4, j + 5, k + 9, Blocks.sandstone, 2, 0x02);
		world.setBlock(i + 4, j + 6, k + 1, Blocks.sandstone, 2, 0x02);
		world.setBlock(i + 4, j + 6, k + 9, Blocks.sandstone, 2, 0x02);
		world.setBlock(i + 4, j + 7, k + 1, Blocks.sandstone, 2, 0x02);
		world.setBlock(i + 4, j + 7, k + 9, Blocks.sandstone, 2, 0x02);
		world.setBlock(i + 4, j + 8, k + 1, Blocks.nether_brick);
		world.setBlock(i + 4, j + 8, k + 2, Blocks.planks, 1, 0x02);
		world.setBlock(i + 4, j + 8, k + 3, Blocks.planks, 1, 0x02);
		world.setBlock(i + 4, j + 8, k + 4, Blocks.planks, 1, 0x02);
		world.setBlock(i + 4, j + 8, k + 6, Blocks.planks, 1, 0x02);
		world.setBlock(i + 4, j + 8, k + 7, Blocks.planks, 1, 0x02);
		world.setBlock(i + 4, j + 8, k + 8, Blocks.planks, 1, 0x02);
		world.setBlock(i + 4, j + 8, k + 9, Blocks.nether_brick);
		world.setBlock(i + 4, j + 9, k + 2, Blocks.sandstone, 1, 0x02);
		world.setBlock(i + 4, j + 9, k + 8, Blocks.sandstone, 1, 0x02);
		world.setBlock(i + 4, j + 10, k + 2, Blocks.sandstone, 1, 0x02);
		world.setBlock(i + 4, j + 10, k + 8, Blocks.sandstone, 1, 0x02);
		world.setBlock(i + 4, j + 11, k + 2, Blocks.sandstone, 1, 0x02);
		world.setBlock(i + 4, j + 11, k + 8, Blocks.sandstone, 1, 0x02);
		world.setBlock(i + 4, j + 12, k + 2, Blocks.nether_brick);
		world.setBlock(i + 4, j + 12, k + 3, Blocks.planks, 1, 0x02);
		world.setBlock(i + 4, j + 12, k + 4, Blocks.planks, 1, 0x02);
		world.setBlock(i + 4, j + 12, k + 6, Blocks.planks, 1, 0x02);
		world.setBlock(i + 4, j + 12, k + 7, Blocks.planks, 1, 0x02);
		world.setBlock(i + 4, j + 12, k + 8, Blocks.nether_brick);
		world.setBlock(i + 4, j + 13, k + 3, Blocks.sandstone, 1, 0x02);
		world.setBlock(i + 4, j + 13, k + 7, Blocks.sandstone, 1, 0x02);
		world.setBlock(i + 4, j + 14, k + 3, Blocks.sandstone, 1, 0x02);
		world.setBlock(i + 4, j + 14, k + 7, Blocks.sandstone, 1, 0x02);
		world.setBlock(i + 4, j + 15, k + 3, Blocks.sandstone, 1, 0x02);
		world.setBlock(i + 4, j + 15, k + 7, Blocks.sandstone, 1, 0x02);
		world.setBlock(i + 4, j + 16, k + 3, Blocks.nether_brick);
		world.setBlock(i + 4, j + 16, k + 4, Blocks.planks, 1, 0x02);
		world.setBlock(i + 4, j + 16, k + 6, Blocks.planks, 1, 0x02);
		world.setBlock(i + 4, j + 16, k + 7, Blocks.nether_brick);
		world.setBlock(i + 4, j + 17, k + 4, Blocks.sandstone, 1, 0x02);
		world.setBlock(i + 4, j + 17, k + 6, Blocks.sandstone, 1, 0x02);
		world.setBlock(i + 4, j + 18, k + 4, Blocks.sandstone, 1, 0x02);
		world.setBlock(i + 4, j + 18, k + 6, Blocks.sandstone, 1, 0x02);
		world.setBlock(i + 4, j + 19, k + 4, Blocks.sandstone, 1, 0x02);
		world.setBlock(i + 4, j + 19, k + 6, Blocks.sandstone, 1, 0x02);
		world.setBlock(i + 4, j + 20, k + 3, Blocks.sandstone_stairs, 6, 0x02);
		world.setBlock(i + 4, j + 20, k + 4, Blocks.nether_brick);
		world.setBlock(i + 4, j + 20, k + 5, Blocks.nether_brick);
		world.setBlock(i + 4, j + 20, k + 6, Blocks.nether_brick);
		world.setBlock(i + 4, j + 20, k + 7, Blocks.sandstone_stairs, 7, 0x02);
		world.setBlock(i + 4, j + 21, k + 3, Blocks.nether_brick_stairs, 2, 0x02);
		world.setBlock(i + 4, j + 21, k + 7, Blocks.nether_brick_stairs, 3, 0x02);
		world.setBlock(i + 4, j + 22, k + 4, Blocks.sandstone_stairs);
		world.setBlock(i + 4, j + 22, k + 5, Blocks.sandstone_stairs);
		world.setBlock(i + 4, j + 22, k + 6, Blocks.sandstone_stairs, 3, 0x02);
		world.setBlock(i + 5, j + 0, k + 0, Blocks.sandstone, 2, 0x02);
		world.setBlock(i + 5, j + 0, k + 1, Blocks.wool, 14 , 0x02);
		world.setBlock(i + 5, j + 0, k + 2, Blocks.sandstone, 2, 0x02);
		world.setBlock(i + 5, j + 0, k + 3, Blocks.wool, 14 , 0x02);
		world.setBlock(i + 5, j + 0, k + 4, Blocks.wool, 14, 0x02);
		world.setBlock(i + 5, j + 0, k + 5, mod_Avatar.FireBlock);
		world.setBlock(i + 5, j + 0, k + 6, Blocks.wool, 14 , 0x02);
		world.setBlock(i + 5, j + 0, k + 7, Blocks.wool, 14 , 0x02);
		world.setBlock(i + 5, j + 0, k + 8, Blocks.sandstone, 2, 0x02);
		world.setBlock(i + 5, j + 0, k + 9, Blocks.wool, 14 , 0x02);
		world.setBlock(i + 5, j + 0, k + 10, Blocks.sandstone, 2, 0x02);
		world.setBlock(i + 5, j + 4, k + 0, Blocks.nether_brick);
		world.setBlock(i + 5, j + 4, k + 1, Blocks.planks, 1, 0x02);
		world.setBlock(i + 5, j + 4, k + 2, Blocks.planks, 1, 0x02);
		world.setBlock(i + 5, j + 4, k + 3, Blocks.planks, 1, 0x02);
		world.setBlock(i + 5, j + 4, k + 4, Blocks.planks, 1, 0x02);
		world.setBlock(i + 5, j + 4, k + 5, Blocks.planks, 1, 0x02);
		world.setBlock(i + 5, j + 4, k + 6, Blocks.planks, 1, 0x02);
		world.setBlock(i + 5, j + 4, k + 7, Blocks.planks, 1, 0x02);
		world.setBlock(i + 5, j + 4, k + 8, Blocks.planks, 1, 0x02);
		world.setBlock(i + 5, j + 4, k + 9, Blocks.planks, 1, 0x02);
		world.setBlock(i + 5, j + 4, k + 10, Blocks.nether_brick);
		world.setBlock(i + 5, j + 5, k + 1, Blocks.sandstone, 2, 0x02);
		world.setBlock(i + 5, j + 5, k + 5, Blocks.planks, 1, 0x02);
		world.setBlock(i + 5, j + 5, k + 9, Blocks.sandstone, 2, 0x02);
		world.setBlock(i + 5, j + 6, k + 1, Blocks.fence);
		world.setBlock(i + 5, j + 6, k + 5, Blocks.planks, 1, 0x02);
		world.setBlock(i + 5, j + 6, k + 9, Blocks.fence);
		world.setBlock(i + 5, j + 7, k + 1, Blocks.fence);
		world.setBlock(i + 5, j + 7, k + 5, Blocks.planks, 1, 0x02);
		world.setBlock(i + 5, j + 7, k + 9, Blocks.fence);
		world.setBlock(i + 5, j + 8, k + 1, Blocks.nether_brick);
		world.setBlock(i + 5, j + 8, k + 2, Blocks.planks, 1, 0x02);
		world.setBlock(i + 5, j + 8, k + 3, Blocks.planks, 1, 0x02);
		world.setBlock(i + 5, j + 8, k + 5, Blocks.planks, 1, 0x02);
		world.setBlock(i + 5, j + 8, k + 7, Blocks.planks, 1, 0x02);
		world.setBlock(i + 5, j + 8, k + 8, Blocks.planks, 1, 0x02);
		world.setBlock(i + 5, j + 8, k + 9, Blocks.nether_brick);
		world.setBlock(i + 5, j + 9, k + 2, Blocks.sandstone, 2, 0x02);
		world.setBlock(i + 5, j + 9, k + 5, Blocks.planks, 1, 0x02);
		world.setBlock(i + 5, j + 9, k + 8, Blocks.sandstone, 2, 0x02);
		world.setBlock(i + 5, j + 10, k + 2, Blocks.fence);
		world.setBlock(i + 5, j + 10, k + 5, Blocks.planks, 1, 0x02);
		world.setBlock(i + 5, j + 10, k + 8, Blocks.fence);
		world.setBlock(i + 5, j + 11, k + 2, Blocks.fence);
		world.setBlock(i + 5, j + 11, k + 5, Blocks.planks, 1, 0x02);
		world.setBlock(i + 5, j + 11, k + 8, Blocks.fence);
		world.setBlock(i + 5, j + 12, k + 2, Blocks.nether_brick);
		world.setBlock(i + 5, j + 12, k + 3, Blocks.planks, 1, 0x02);
		world.setBlock(i + 5, j + 12, k + 5, Blocks.planks, 1, 0x02);
		world.setBlock(i + 5, j + 12, k + 7, Blocks.planks, 1, 0x02);
		world.setBlock(i + 5, j + 12, k + 8, Blocks.nether_brick);
		world.setBlock(i + 5, j + 13, k + 5, Blocks.planks, 1, 0x02);
		world.setBlock(i + 5, j + 14, k + 5, Blocks.planks, 1, 0x02);
		world.setBlock(i + 5, j + 15, k + 3, mod_Avatar.FireNationBlock);
		world.setBlock(i + 5, j + 15, k + 5, Blocks.planks, 1, 0x02);
		world.setBlock(i + 5, j + 15, k + 7, mod_Avatar.FireNationBlock);
		world.setBlock(i + 5, j + 16, k + 3, Blocks.nether_brick);
		world.setBlock(i + 5, j + 16, k + 5, Blocks.planks, 1, 0x02);
		world.setBlock(i + 5, j + 16, k + 7, Blocks.nether_brick);
		world.setBlock(i + 5, j + 20, k + 4, Blocks.nether_brick);
		world.setBlock(i + 5, j + 20, k + 5, Blocks.glowstone);
		world.setBlock(i + 5, j + 20, k + 6, Blocks.nether_brick);
		world.setBlock(i + 5, j + 21, k + 3, Blocks.nether_brick_stairs, 2, 0x02);
		world.setBlock(i + 5, j + 21, k + 7, Blocks.nether_brick_stairs, 3, 0x02);
		world.setBlock(i + 5, j + 22, k + 4, Blocks.sandstone_stairs, 2, 0x02);
		world.setBlock(i + 5, j + 22, k + 6, Blocks.sandstone_stairs, 3, 0x02);
		world.setBlock(i + 5, j + 23, k + 5, Blocks.glowstone);
		world.setBlock(i + 6, j + 0, k + 0, Blocks.sandstone, 2, 0x02);
		world.setBlock(i + 6, j + 0, k + 1, Blocks.wool, 14 , 0x02);
		world.setBlock(i + 6, j + 0, k + 2, Blocks.sandstone, 2, 0x02);
		world.setBlock(i + 6, j + 0, k + 3, Blocks.wool, 14 , 0x02);
		world.setBlock(i + 6, j + 0, k + 4, Blocks.wool, 14 , 0x02);
		world.setBlock(i + 6, j + 0, k + 5, Blocks.sandstone, 2, 0x02);
		world.setBlock(i + 6, j + 0, k + 6, Blocks.wool, 14 , 0x02);
		world.setBlock(i + 6, j + 0, k + 7, Blocks.sandstone, 2, 0x02);
		world.setBlock(i + 6, j + 0, k + 8, Blocks.sandstone, 2, 0x02);
		world.setBlock(i + 6, j + 0, k + 9, Blocks.wool, 14 , 0x02);
		world.setBlock(i + 6, j + 0, k + 10, Blocks.sandstone, 2, 0x02);
		world.setBlock(i + 6, j + 3, k + 0, Blocks.sandstone_stairs, 4, 0x02);
		world.setBlock(i + 6, j + 3, k + 10, Blocks.sandstone_stairs, 4, 0x02);
		world.setBlock(i + 6, j + 4, k + 0, Blocks.sandstone, 2, 0x02);
		world.setBlock(i + 6, j + 4, k + 1, Blocks.planks, 1, 0x02);
		world.setBlock(i + 6, j + 4, k + 2, Blocks.planks, 1, 0x02);
		world.setBlock(i + 6, j + 4, k + 3, Blocks.planks, 1, 0x02);
		world.setBlock(i + 6, j + 4, k + 4, Blocks.planks, 1, 0x02);
		world.setBlock(i + 6, j + 4, k + 5, Blocks.planks, 1, 0x02);
		world.setBlock(i + 6, j + 4, k + 6, Blocks.planks, 1, 0x02);
		world.setBlock(i + 6, j + 4, k + 7, Blocks.planks, 1, 0x02);
		world.setBlock(i + 6, j + 4, k + 8, Blocks.planks, 1, 0x02);
		world.setBlock(i + 6, j + 4, k + 9, Blocks.planks, 1, 0x02);
		world.setBlock(i + 6, j + 4, k + 10, Blocks.sandstone, 2, 0x02);
		world.setBlock(i + 6, j + 5, k + 1, Blocks.sandstone, 2, 0x02);
		world.setBlock(i + 6, j + 5, k + 9, Blocks.sandstone, 2, 0x02);
		world.setBlock(i + 6, j + 6, k + 1, Blocks.sandstone, 2, 0x02);
		world.setBlock(i + 6, j + 6, k + 9, Blocks.sandstone, 2, 0x02);
		world.setBlock(i + 6, j + 7, k + 1, Blocks.sandstone, 2, 0x02);
		world.setBlock(i + 6, j + 7, k + 9, Blocks.sandstone, 2, 0x02);
		world.setBlock(i + 6, j + 8, k + 1, Blocks.nether_brick);
		world.setBlock(i + 6, j + 8, k + 2, Blocks.planks, 1, 0x02);
		world.setBlock(i + 6, j + 8, k + 3, Blocks.planks, 1, 0x02);
		world.setBlock(i + 6, j + 8, k + 4, Blocks.planks, 1, 0x02);
		world.setBlock(i + 6, j + 8, k + 6, Blocks.planks, 1, 0x02);
		world.setBlock(i + 6, j + 8, k + 7, Blocks.planks, 1, 0x02);
		world.setBlock(i + 6, j + 8, k + 8, Blocks.planks, 1, 0x02);
		world.setBlock(i + 6, j + 8, k + 9, Blocks.nether_brick);
		world.setBlock(i + 6, j + 9, k + 2, Blocks.sandstone, 1, 0x02);
		world.setBlock(i + 6, j + 9, k + 8, Blocks.sandstone, 1, 0x02);
		world.setBlock(i + 6, j + 10, k + 2, Blocks.sandstone, 1, 0x02);
		world.setBlock(i + 6, j + 10, k + 8, Blocks.sandstone, 1, 0x02);
		world.setBlock(i + 6, j + 11, k + 2, Blocks.sandstone, 1, 0x02);
		world.setBlock(i + 6, j + 11, k + 8, Blocks.sandstone, 1, 0x02);
		world.setBlock(i + 6, j + 12, k + 2, Blocks.nether_brick);
		world.setBlock(i + 6, j + 12, k + 3, Blocks.planks, 1, 0x02);
		world.setBlock(i + 6, j + 12, k + 4, Blocks.planks, 1, 0x02);
		world.setBlock(i + 6, j + 12, k + 6, Blocks.planks, 1, 0x02);
		world.setBlock(i + 6, j + 12, k + 7, Blocks.planks, 1, 0x02);
		world.setBlock(i + 6, j + 12, k + 8, Blocks.nether_brick);
		world.setBlock(i + 6, j + 13, k + 3, Blocks.sandstone, 1, 0x02);
		world.setBlock(i + 6, j + 13, k + 7, Blocks.sandstone, 1, 0x02);
		world.setBlock(i + 6, j + 14, k + 3, Blocks.sandstone, 1, 0x02);
		world.setBlock(i + 6, j + 14, k + 7, Blocks.sandstone, 1, 0x02);
		world.setBlock(i + 6, j + 15, k + 3, Blocks.sandstone, 1, 0x02);
		world.setBlock(i + 6, j + 15, k + 7, Blocks.sandstone, 1, 0x02);
		world.setBlock(i + 6, j + 16, k + 3, Blocks.nether_brick);
		world.setBlock(i + 6, j + 16, k + 4, Blocks.planks, 1, 0x02);
		world.setBlock(i + 6, j + 16, k + 6, Blocks.planks, 1, 0x02);
		world.setBlock(i + 6, j + 16, k + 7, Blocks.nether_brick);
		world.setBlock(i + 6, j + 17, k + 4, Blocks.sandstone, 1, 0x02);
		world.setBlock(i + 6, j + 17, k + 6, Blocks.sandstone, 1, 0x02);
		world.setBlock(i + 6, j + 18, k + 4, Blocks.sandstone, 1, 0x02);
		world.setBlock(i + 6, j + 18, k + 6, Blocks.sandstone, 1, 0x02);
		world.setBlock(i + 6, j + 19, k + 4, Blocks.sandstone, 1, 0x02);
		world.setBlock(i + 6, j + 19, k + 6, Blocks.sandstone, 1, 0x02);
		world.setBlock(i + 6, j + 20, k + 3, Blocks.sandstone_stairs, 6, 0x02);
		world.setBlock(i + 6, j + 20, k + 4, Blocks.nether_brick);
		world.setBlock(i + 6, j + 20, k + 5, Blocks.nether_brick);
		world.setBlock(i + 6, j + 20, k + 6, Blocks.nether_brick);
		world.setBlock(i + 6, j + 20, k + 7, Blocks.sandstone_stairs, 7, 0x02);
		world.setBlock(i + 6, j + 21, k + 3, Blocks.nether_brick_stairs, 2, 0x02);
		world.setBlock(i + 6, j + 21, k + 7, Blocks.nether_brick_stairs, 3, 0x02);
		world.setBlock(i + 6, j + 22, k + 4, Blocks.sandstone_stairs, 2, 0x02);
		world.setBlock(i + 6, j + 22, k + 5, Blocks.sandstone_stairs, 1, 0x02);
		world.setBlock(i + 6, j + 22, k + 6, Blocks.sandstone_stairs, 1, 0x02);
		world.setBlock(i + 7, j + 0, k + 1, Blocks.wool, 14 , 0x02);
		world.setBlock(i + 7, j + 0, k + 2, Blocks.wool, 14 , 0x02);
		world.setBlock(i + 7, j + 0, k + 3, Blocks.sandstone, 2, 0x02);
		world.setBlock(i + 7, j + 0, k + 4, Blocks.wool, 14 , 0x02);
		world.setBlock(i + 7, j + 0, k + 5, Blocks.sandstone, 2, 0x02);
		world.setBlock(i + 7, j + 0, k + 6, Blocks.wool, 14 , 0x02);
		world.setBlock(i + 7, j + 0, k + 7, Blocks.sandstone, 2, 0x02);
		world.setBlock(i + 7, j + 0, k + 8, Blocks.wool, 14 , 0x02);
		world.setBlock(i + 7, j + 0, k + 9, Blocks.wool, 14 , 0x02);
		world.setBlock(i + 7, j + 1, k + 0, Blocks.sandstone, 1, 0x02);
		world.setBlock(i + 7, j + 1, k + 10, Blocks.sandstone, 1, 0x02);
		world.setBlock(i + 7, j + 2, k + 0, Blocks.sandstone, 2, 0x02);
		world.setBlock(i + 7, j + 2, k + 10, Blocks.sandstone, 2, 0x02);
		world.setBlock(i + 7, j + 3, k + 0, Blocks.sandstone, 2, 0x02);
		world.setBlock(i + 7, j + 3, k + 10, Blocks.sandstone, 2, 0x02);
		world.setBlock(i + 7, j + 4, k + 0, Blocks.sandstone, 2, 0x02);
		world.setBlock(i + 7, j + 4, k + 1, Blocks.planks, 1, 0x02);
		world.setBlock(i + 7, j + 4, k + 2, Blocks.planks, 1, 0x02);
		world.setBlock(i + 7, j + 4, k + 3, Blocks.planks, 1, 0x02);
		world.setBlock(i + 7, j + 4, k + 4, Blocks.planks, 1, 0x02);
		world.setBlock(i + 7, j + 4, k + 5, Blocks.planks, 1, 0x02);
		world.setBlock(i + 7, j + 4, k + 6, Blocks.planks, 1, 0x02);
		world.setBlock(i + 7, j + 4, k + 7, Blocks.planks, 1, 0x02);
		world.setBlock(i + 7, j + 4, k + 8, Blocks.planks, 1, 0x02);
		world.setBlock(i + 7, j + 4, k + 9, Blocks.planks, 1, 0x02);
		world.setBlock(i + 7, j + 4, k + 10, Blocks.sandstone, 2, 0x02);
		world.setBlock(i + 7, j + 5, k + 1, Blocks.sandstone, 1, 0x02);
		world.setBlock(i + 7, j + 5, k + 9, Blocks.sandstone, 1, 0x02);
		world.setBlock(i + 7, j + 6, k + 1, Blocks.sandstone, 1, 0x02);
		world.setBlock(i + 7, j + 6, k + 9, Blocks.sandstone, 1, 0x02);
		world.setBlock(i + 7, j + 7, k + 1, Blocks.sandstone, 1, 0x02);
		world.setBlock(i + 7, j + 7, k + 9, Blocks.sandstone, 1, 0x02);
		world.setBlock(i + 7, j + 8, k + 1, Blocks.sandstone, 1, 0x02);
		world.setBlock(i + 7, j + 8, k + 2, Blocks.planks, 1, 0x02);
		world.setBlock(i + 7, j + 8, k + 3, Blocks.glowstone);
		world.setBlock(i + 7, j + 8, k + 4, Blocks.planks, 1, 0x02);
		world.setBlock(i + 7, j + 8, k + 5, Blocks.planks, 1, 0x02);
		world.setBlock(i + 7, j + 8, k + 6, Blocks.planks, 1, 0x02);
		world.setBlock(i + 7, j + 8, k + 7, Blocks.glowstone);
		world.setBlock(i + 7, j + 8, k + 8, Blocks.planks, 1, 0x02);
		world.setBlock(i + 7, j + 8, k + 9, Blocks.sandstone, 1, 0x02);
		world.setBlock(i + 7, j + 9, k + 2, Blocks.sandstone, 2, 0x02);
		world.setBlock(i + 7, j + 9, k + 8, Blocks.sandstone, 2, 0x02);
		world.setBlock(i + 7, j + 10, k + 2, Blocks.sandstone, 2, 0x02);
		world.setBlock(i + 7, j + 10, k + 8, Blocks.sandstone, 2, 0x02);
		world.setBlock(i + 7, j + 11, k + 2, Blocks.sandstone, 2, 0x02);
		world.setBlock(i + 7, j + 11, k + 8, Blocks.sandstone, 2, 0x02);
		world.setBlock(i + 7, j + 12, k + 2, Blocks.sandstone, 2, 0x02);
		world.setBlock(i + 7, j + 12, k + 3, Blocks.planks, 1, 0x02);
		world.setBlock(i + 7, j + 12, k + 4, Blocks.planks, 1, 0x02);
		world.setBlock(i + 7, j + 12, k + 5, Blocks.planks, 1, 0x02);
		world.setBlock(i + 7, j + 12, k + 6, Blocks.planks, 1, 0x02);
		world.setBlock(i + 7, j + 12, k + 7, Blocks.planks, 1, 0x02);
		world.setBlock(i + 7, j + 12, k + 8, Blocks.sandstone, 2, 0x02);
		world.setBlock(i + 7, j + 13, k + 3, Blocks.stone_slab, 1, 0x02);
		world.setBlock(i + 7, j + 13, k + 4, Blocks.sandstone, 1, 0x02);
		world.setBlock(i + 7, j + 13, k + 6, Blocks.sandstone, 1, 0x02);
		world.setBlock(i + 7, j + 13, k + 7, Blocks.stone_slab, 1, 0x02);
		world.setBlock(i + 7, j + 14, k + 4, Blocks.sandstone, 1, 0x02);
		world.setBlock(i + 7, j + 14, k + 6, Blocks.sandstone, 1, 0x02);
		world.setBlock(i + 7, j + 15, k + 4, Blocks.sandstone, 1, 0x02);
		world.setBlock(i + 7, j + 15, k + 5, mod_Avatar.FireNationBlock);
		world.setBlock(i + 7, j + 15, k + 6, Blocks.sandstone, 1, 0x02);
		world.setBlock(i + 7, j + 16, k + 4, Blocks.nether_brick);
		world.setBlock(i + 7, j + 16, k + 5, Blocks.nether_brick);
		world.setBlock(i + 7, j + 16, k + 6, Blocks.nether_brick);
		world.setBlock(i + 7, j + 20, k + 3, Blocks.sandstone_stairs, 5, 0x02);
		world.setBlock(i + 7, j + 20, k + 4, Blocks.sandstone_stairs, 5, 0x02);
		world.setBlock(i + 7, j + 20, k + 6, Blocks.sandstone_stairs, 5, 0x02);
		world.setBlock(i + 7, j + 20, k + 7, Blocks.sandstone_stairs, 7, 0x02);
		world.setBlock(i + 7, j + 21, k + 3, Blocks.nether_brick_stairs, 1, 0x02);
		world.setBlock(i + 7, j + 21, k + 4, Blocks.nether_brick_stairs, 1, 0x02);
		world.setBlock(i + 7, j + 21, k + 5, Blocks.nether_brick_stairs, 1, 0x02);
		world.setBlock(i + 7, j + 21, k + 6, Blocks.nether_brick_stairs, 1, 0x02);
		world.setBlock(i + 7, j + 21, k + 7, Blocks.nether_brick_stairs, 1, 0x02);
		world.setBlock(i + 8, j + 0, k + 2, Blocks.glowstone);
		world.setBlock(i + 8, j + 0, k + 3, Blocks.wool, 14 , 0x02);
		world.setBlock(i + 8, j + 0, k + 4, Blocks.sandstone, 2, 0x02);
		world.setBlock(i + 8, j + 0, k + 5, Blocks.sandstone, 2, 0x02);
		world.setBlock(i + 8, j + 0, k + 6, Blocks.sandstone, 2, 0x02);
		world.setBlock(i + 8, j + 0, k + 7, Blocks.wool, 14 , 0x02);
		world.setBlock(i + 8, j + 0, k + 8, Blocks.glowstone);
		world.setBlock(i + 8, j + 1, k + 1, Blocks.sandstone, 1, 0x02);
		world.setBlock(i + 8, j + 1, k + 9, Blocks.sandstone, 1, 0x02);
		world.setBlock(i + 8, j + 2, k + 1, Blocks.sandstone, 2, 0x02);
		world.setBlock(i + 8, j + 2, k + 9, Blocks.sandstone, 2, 0x02);
		world.setBlock(i + 8, j + 3, k + 1, Blocks.sandstone, 2, 0x02);
		world.setBlock(i + 8, j + 3, k + 9, Blocks.sandstone, 2, 0x02);
		world.setBlock(i + 8, j + 4, k + 1, Blocks.sandstone, 2, 0x02);
		world.setBlock(i + 8, j + 4, k + 3, Blocks.planks, 1, 0x02);
		world.setBlock(i + 8, j + 4, k + 4, Blocks.planks, 1, 0x02);
		world.setBlock(i + 8, j + 4, k + 5, Blocks.planks, 1, 0x02);
		world.setBlock(i + 8, j + 4, k + 6, Blocks.planks, 1, 0x02);
		world.setBlock(i + 8, j + 4, k + 7, Blocks.planks, 1, 0x02);
		world.setBlock(i + 8, j + 4, k + 9, Blocks.sandstone, 2, 0x02);
		world.setBlock(i + 8, j + 8, k + 2, Blocks.sandstone, 1, 0x02);
		world.setBlock(i + 8, j + 8, k + 3, Blocks.planks, 1, 0x02);
		world.setBlock(i + 8, j + 8, k + 4, Blocks.planks, 1, 0x02);
		world.setBlock(i + 8, j + 8, k + 5, Blocks.planks, 1, 0x02);
		world.setBlock(i + 8, j + 8, k + 6, Blocks.planks, 1, 0x02);
		world.setBlock(i + 8, j + 8, k + 7, Blocks.planks, 1, 0x02);
		world.setBlock(i + 8, j + 8, k + 8, Blocks.sandstone, 1, 0x02);
		world.setBlock(i + 8, j + 9, k + 3, Blocks.sandstone, 2, 0x02);
		world.setBlock(i + 8, j + 9, k + 4, Blocks.sandstone, 1, 0x02);
		world.setBlock(i + 8, j + 9, k + 5, Blocks.sandstone, 2, 0x02);
		world.setBlock(i + 8, j + 9, k + 6, Blocks.sandstone, 1, 0x02);
		world.setBlock(i + 8, j + 9, k + 7, Blocks.sandstone, 2, 0x02);
		world.setBlock(i + 8, j + 10, k + 3, Blocks.sandstone, 2, 0x02);
		world.setBlock(i + 8, j + 10, k + 4, Blocks.sandstone, 1, 0x02);
		world.setBlock(i + 8, j + 10, k + 5, Blocks.fence);
		world.setBlock(i + 8, j + 10, k + 6, Blocks.sandstone, 1, 0x02);
		world.setBlock(i + 8, j + 10, k + 7, Blocks.sandstone, 2, 0x02);
		world.setBlock(i + 8, j + 11, k + 3, Blocks.sandstone, 2, 0x02);
		world.setBlock(i + 8, j + 11, k + 4, Blocks.sandstone, 1, 0x02);
		world.setBlock(i + 8, j + 11, k + 5, Blocks.fence);
		world.setBlock(i + 8, j + 11, k + 6, Blocks.sandstone, 1, 0x02);
		world.setBlock(i + 8, j + 11, k + 7, Blocks.sandstone, 2, 0x02);
		world.setBlock(i + 8, j + 12, k + 3, Blocks.sandstone, 2, 0x02);
		world.setBlock(i + 8, j + 12, k + 4, Blocks.nether_brick);
		world.setBlock(i + 8, j + 12, k + 5, Blocks.nether_brick);
		world.setBlock(i + 8, j + 12, k + 6, Blocks.nether_brick);
		world.setBlock(i + 8, j + 12, k + 7, Blocks.sandstone, 2, 0x02);
		world.setBlock(i + 9, j + 0, k + 3, Blocks.wool, 14 , 0x02);
		world.setBlock(i + 9, j + 0, k + 4, Blocks.wool, 14 , 0x02);
		world.setBlock(i + 9, j + 0, k + 5, Blocks.wool, 14 , 0x02);
		world.setBlock(i + 9, j + 0, k + 6, Blocks.wool, 14 , 0x02);
		world.setBlock(i + 9, j + 0, k + 7, Blocks.wool, 14 , 0x02);
		world.setBlock(i + 9, j + 1, k + 2, Blocks.sandstone, 1, 0x02);
		world.setBlock(i + 9, j + 1, k + 8, Blocks.sandstone, 1, 0x02);
		world.setBlock(i + 9, j + 2, k + 2, Blocks.sandstone, 2, 0x02);
		world.setBlock(i + 9, j + 2, k + 8, Blocks.sandstone, 2, 0x02);
		world.setBlock(i + 9, j + 3, k + 2, Blocks.sandstone, 2, 0x02);
		world.setBlock(i + 9, j + 3, k + 8, Blocks.sandstone, 2, 0x02);
		world.setBlock(i + 9, j + 4, k + 2, Blocks.sandstone, 2, 0x02);
		world.setBlock(i + 9, j + 4, k + 3, Blocks.planks, 1, 0x02);
		world.setBlock(i + 9, j + 4, k + 4, Blocks.planks, 1, 0x02);
		world.setBlock(i + 9, j + 4, k + 5, Blocks.planks, 1, 0x02);
		world.setBlock(i + 9, j + 4, k + 6, Blocks.planks, 1, 0x02);
		world.setBlock(i + 9, j + 4, k + 7, Blocks.planks, 1, 0x02);
		world.setBlock(i + 9, j + 4, k + 8, Blocks.sandstone, 2, 0x02);
		world.setBlock(i + 9, j + 5, k + 3, Blocks.sandstone, 1, 0x02);
		world.setBlock(i + 9, j + 5, k + 4, Blocks.sandstone, 2, 0x02);
		world.setBlock(i + 9, j + 5, k + 5, Blocks.sandstone, 2, 0x02);
		world.setBlock(i + 9, j + 5, k + 6, Blocks.sandstone, 2, 0x02);
		world.setBlock(i + 9, j + 5, k + 7, Blocks.sandstone, 1, 0x02);
		world.setBlock(i + 9, j + 6, k + 3, Blocks.sandstone, 1, 0x02);
		world.setBlock(i + 9, j + 6, k + 4, Blocks.sandstone, 2, 0x02);
		world.setBlock(i + 9, j + 6, k + 5, Blocks.fence);
		world.setBlock(i + 9, j + 6, k + 6, Blocks.sandstone, 2, 0x02);
		world.setBlock(i + 9, j + 6, k + 7, Blocks.sandstone, 1, 0x02);
		world.setBlock(i + 9, j + 7, k + 3, Blocks.sandstone, 1, 0x02);
		world.setBlock(i + 9, j + 7, k + 4, Blocks.sandstone, 2, 0x02);
		world.setBlock(i + 9, j + 7, k + 5, Blocks.fence);
		world.setBlock(i + 9, j + 7, k + 6, Blocks.sandstone, 2, 0x02);
		world.setBlock(i + 9, j + 7, k + 7, Blocks.sandstone, 1, 0x02);
		world.setBlock(i + 9, j + 8, k + 3, Blocks.sandstone, 1, 0x02);
		world.setBlock(i + 9, j + 8, k + 4, Blocks.nether_brick);
		world.setBlock(i + 9, j + 8, k + 5, Blocks.nether_brick);
		world.setBlock(i + 9, j + 8, k + 6, Blocks.nether_brick);
		world.setBlock(i + 9, j + 8, k + 7, Blocks.sandstone, 1, 0x02);
		world.setBlock(i + 10, j + 0, k + 4, Blocks.sandstone, 2, 0x02);
		world.setBlock(i + 10, j + 0, k + 5, Blocks.sandstone, 2, 0x02);
		world.setBlock(i + 10, j + 0, k + 6, Blocks.sandstone, 2, 0x02);
		world.setBlock(i + 10, j + 1, k + 3, Blocks.sandstone, 1, 0x02);
		world.setBlock(i + 10, j + 1, k + 7, Blocks.sandstone, 1, 0x02);
		world.setBlock(i + 10, j + 2, k + 3, Blocks.sandstone, 2, 0x02);
		world.setBlock(i + 10, j + 2, k + 7, Blocks.sandstone, 2, 0x02);
		world.setBlock(i + 10, j + 3, k + 3, Blocks.sandstone, 2, 0x02);
		world.setBlock(i + 10, j + 3, k + 4, Blocks.sandstone_stairs, 7, 0x02);
		world.setBlock(i + 10, j + 3, k + 6, Blocks.sandstone_stairs, 6, 0x02);
		world.setBlock(i + 10, j + 3, k + 7, Blocks.sandstone, 2, 0x02);
		world.setBlock(i + 10, j + 4, k + 3, Blocks.sandstone, 2, 0x02);
		world.setBlock(i + 10, j + 4, k + 4, Blocks.sandstone, 2, 0x02);
		world.setBlock(i + 10, j + 4, k + 5, Blocks.nether_brick);
		world.setBlock(i + 10, j + 4, k + 6, Blocks.sandstone, 2, 0x02);
		world.setBlock(i + 10, j + 4, k + 7, Blocks.sandstone, 2, 0x02);
		world.setBlock(i + 0, j + 0, k + 0, Blocks.sand);
		world.setBlock(i + 0, j + 0, k + 1, Blocks.sand);
		world.setBlock(i + 0, j + 0, k + 2, Blocks.sand);
		world.setBlock(i + 0, j + 0, k + 3, Blocks.sand);
		world.setBlock(i + 0, j + 0, k + 7, Blocks.sand);
		world.setBlock(i + 0, j + 0, k + 8, Blocks.sand);
		world.setBlock(i + 0, j + 0, k + 9, Blocks.sand);
		world.setBlock(i + 0, j + 0, k + 10, Blocks.sand);
		world.setBlock(i + 1, j + 0, k + 0, Blocks.sand);
		world.setBlock(i + 1, j + 0, k + 1, Blocks.sand);
		world.setBlock(i + 1, j + 0, k + 2, Blocks.sand);
		world.setBlock(i + 1, j + 0, k + 8, Blocks.sand);
		world.setBlock(i + 1, j + 0, k + 9, Blocks.sand);
		world.setBlock(i + 1, j + 0, k + 10, Blocks.sand);
		world.setBlock(i + 2, j + 0, k + 0, Blocks.sand);
		world.setBlock(i + 2, j + 0, k + 1, Blocks.sand);
		world.setBlock(i + 2, j + 0, k + 9, Blocks.sand);
		world.setBlock(i + 2, j + 0, k + 10, Blocks.sand);
		world.setBlock(i + 2, j + 1, k + 2, Blocks.ladder, 3, 0x02);
		world.setBlock(i + 2, j + 1, k + 8, Blocks.ladder, 2, 0x02);
		world.setBlock(i + 2, j + 2, k + 2, Blocks.ladder, 3, 0x02);
		world.setBlock(i + 2, j + 2, k + 8, Blocks.ladder, 2, 0x02);
		world.setBlock(i + 2, j + 3, k + 2, Blocks.ladder, 3, 0x02);
		world.setBlock(i + 2, j + 3, k + 8, Blocks.ladder, 2, 0x02);
		world.setBlock(i + 2, j + 4, k + 2, Blocks.ladder, 3, 0x02);
		world.setBlock(i + 2, j + 4, k + 8, Blocks.ladder, 2, 0x02);
		world.setBlock(i + 3, j + 0, k + 0, Blocks.sand);
		world.setBlock(i + 3, j + 0, k + 10, Blocks.sand);
		world.setBlock(i + 4, j + 5, k + 5, Blocks.ladder, 4, 0x02);
		world.setBlock(i + 4, j + 6, k + 5, Blocks.ladder, 4, 0x02);
		world.setBlock(i + 4, j + 7, k + 5, Blocks.ladder, 4, 0x02);
		world.setBlock(i + 4, j + 8, k + 5, Blocks.ladder, 4, 0x02);
		world.setBlock(i + 4, j + 9, k + 5, Blocks.ladder, 4, 0x02);
		world.setBlock(i + 4, j + 10, k + 5, Blocks.ladder, 4, 0x02);
		world.setBlock(i + 4, j + 11, k + 5, Blocks.ladder, 4, 0x02);
		world.setBlock(i + 4, j + 12, k + 5, Blocks.ladder, 4, 0x02);
		world.setBlock(i + 4, j + 13, k + 5, Blocks.ladder, 4, 0x02);
		world.setBlock(i + 4, j + 14, k + 5, Blocks.ladder, 4, 0x02);
		world.setBlock(i + 4, j + 15, k + 4, Blocks.torch, 1, 0x02);
		world.setBlock(i + 4, j + 15, k + 5, Blocks.ladder, 4, 0x02);
		world.setBlock(i + 4, j + 15, k + 6, Blocks.torch, 1, 0x02);
		world.setBlock(i + 4, j + 16, k + 5, Blocks.ladder, 4, 0x02);
		world.setBlock(i + 5, j + 5, k + 4, Blocks.ladder, 2, 0x02);
		world.setBlock(i + 5, j + 5, k + 6, Blocks.ladder, 3, 0x02);
		world.setBlock(i + 5, j + 6, k + 4, Blocks.ladder, 2, 0x02);
		world.setBlock(i + 5, j + 6, k + 6, Blocks.ladder, 3, 0x02);
		world.setBlock(i + 5, j + 7, k + 4, Blocks.ladder, 2, 0x02);
		world.setBlock(i + 5, j + 7, k + 6, Blocks.ladder, 3, 0x02);
		world.setBlock(i + 5, j + 8, k + 4, Blocks.ladder, 2, 0x02);
		world.setBlock(i + 5, j + 8, k + 6, Blocks.ladder, 3, 0x02);
		world.setBlock(i + 5, j + 9, k + 4, Blocks.ladder, 2, 0x02);
		world.setBlock(i + 5, j + 9, k + 6, Blocks.ladder, 3, 0x02);
		world.setBlock(i + 5, j + 10, k + 4, Blocks.ladder, 2, 0x02);
		world.setBlock(i + 5, j + 10, k + 6, Blocks.ladder, 3, 0x02);
		world.setBlock(i + 5, j + 11, k + 4, Blocks.ladder, 2, 0x02);
		world.setBlock(i + 5, j + 11, k + 6, Blocks.ladder, 3, 0x02);
		world.setBlock(i + 5, j + 12, k + 4, Blocks.ladder, 2, 0x02);
		world.setBlock(i + 5, j + 12, k + 6, Blocks.ladder, 3, 0x02);
		world.setBlock(i + 5, j + 13, k + 4, Blocks.ladder, 2, 0x02);
		world.setBlock(i + 5, j + 13, k + 6, Blocks.ladder, 3, 0x02);
		world.setBlock(i + 5, j + 14, k + 4, Blocks.ladder, 2, 0x02);
		world.setBlock(i + 5, j + 14, k + 6, Blocks.ladder, 3, 0x02);
		world.setBlock(i + 5, j + 15, k + 4, Blocks.ladder, 2, 0x02);
		world.setBlock(i + 5, j + 15, k + 6, Blocks.ladder, 3, 0x02);
		world.setBlock(i + 5, j + 16, k + 4, Blocks.ladder, 2, 0x02);
		world.setBlock(i + 5, j + 16, k + 6, Blocks.ladder, 3, 0x02);
		world.setBlock(i + 6, j + 5, k + 5, Blocks.ladder, 5, 0x02);
		world.setBlock(i + 6, j + 6, k + 5, Blocks.ladder, 5, 0x02);
		world.setBlock(i + 6, j + 7, k + 5, Blocks.ladder, 5, 0x02);
		world.setBlock(i + 6, j + 8, k + 5, Blocks.ladder, 5, 0x02);
		world.setBlock(i + 6, j + 9, k + 5, Blocks.ladder, 5, 0x02);
		world.setBlock(i + 6, j + 10, k + 5, Blocks.ladder, 5, 0x02);
		world.setBlock(i + 6, j + 11, k + 5, Blocks.ladder, 5, 0x02);
		world.setBlock(i + 6, j + 12, k + 5, Blocks.ladder, 5, 0x02);
		world.setBlock(i + 6, j + 13, k + 5, Blocks.ladder, 5, 0x02);
		world.setBlock(i + 6, j + 14, k + 5, Blocks.ladder, 5, 0x02);
		world.setBlock(i + 6, j + 15, k + 4, Blocks.torch, 2, 0x02);
		world.setBlock(i + 6, j + 15, k + 5, Blocks.ladder, 5, 0x02);
		world.setBlock(i + 6, j + 15, k + 6, Blocks.torch, 2, 0x02);
		world.setBlock(i + 6, j + 16, k + 5, Blocks.ladder, 5, 0x02);
		world.setBlock(i + 7, j + 0, k + 0, Blocks.sand);
		world.setBlock(i + 7, j + 0, k + 10, Blocks.sand);
		world.setBlock(i + 8, j + 0, k + 0, Blocks.sand);
		world.setBlock(i + 8, j + 0, k + 1, Blocks.sand);
		world.setBlock(i + 8, j + 0, k + 9, Blocks.sand);
		world.setBlock(i + 8, j + 0, k + 10, Blocks.sand);
		world.setBlock(i + 8, j + 1, k + 2, Blocks.ladder, 3, 0x02);
		world.setBlock(i + 8, j + 1, k + 8, Blocks.ladder, 2, 0x02);
		world.setBlock(i + 8, j + 2, k + 2, Blocks.ladder, 3, 0x02);
		world.setBlock(i + 8, j + 2, k + 8, Blocks.ladder, 2, 0x02);
		world.setBlock(i + 8, j + 3, k + 2, Blocks.ladder, 3, 0x02);
		world.setBlock(i + 8, j + 3, k + 8, Blocks.ladder, 2, 0x02);
		world.setBlock(i + 8, j + 4, k + 2, Blocks.ladder, 3, 0x02);
		world.setBlock(i + 8, j + 4, k + 8, Blocks.ladder, 2, 0x02);
		world.setBlock(i + 9, j + 0, k + 0, Blocks.sand);
		world.setBlock(i + 9, j + 0, k + 1, Blocks.sand);
		world.setBlock(i + 9, j + 0, k + 2, Blocks.sand);
		world.setBlock(i + 9, j + 0, k + 8, Blocks.sand);
		world.setBlock(i + 9, j + 0, k + 9, Blocks.sand);
		world.setBlock(i + 9, j + 0, k + 10, Blocks.sand);
		world.setBlock(i + 10, j + 0, k + 0, Blocks.sand);
		world.setBlock(i + 10, j + 0, k + 1, Blocks.sand);
		world.setBlock(i + 10, j + 0, k + 2, Blocks.sand);
		world.setBlock(i + 10, j + 0, k + 3, Blocks.sand);
		world.setBlock(i + 10, j + 0, k + 7, Blocks.sand);
		world.setBlock(i + 10, j + 0, k + 8, Blocks.sand);
		world.setBlock(i + 10, j + 0, k + 9, Blocks.sand);
		world.setBlock(i + 10, j + 0, k + 10, Blocks.sand);

		return true;
	}
}