package kieranvs.avatar.generation;

import java.util.Random;

import kieranvs.avatar.mod_Avatar;
import kieranvs.avatar.bending.ElementManager;
import kieranvs.avatar.entity.EntityAirMan;
import kieranvs.avatar.entity.EntityAirWoman;
import kieranvs.avatar.entity.EntityBison;
import kieranvs.avatar.util.GenerationUtils;
import net.minecraft.block.Block;
import net.minecraft.init.Blocks;
import net.minecraft.item.ItemStack;
import net.minecraft.tileentity.TileEntity;
import net.minecraft.tileentity.TileEntityChest;
import net.minecraft.world.World;
import net.minecraft.world.biome.BiomeGenBase;
import net.minecraft.world.chunk.IChunkProvider;
import cpw.mods.fml.common.IWorldGenerator;

public class WorldGenAirNomadVillageOne implements IWorldGenerator {
	
	private static BiomeGenBase[] biomes = {BiomeGenBase.extremeHills, BiomeGenBase.extremeHillsPlus, BiomeGenBase.stoneBeach};
	
	public void generate(Random random, int chunkX, int chunkZ, World world, IChunkProvider chunkGenerator, IChunkProvider chunkProvider) {
		int[] result = GenerationUtils.shouldSpawnHere(random, chunkX, chunkZ, world, 20, 5, 8, biomes);
		if(result[0] == 0){
			this.masterGenerate(world, result[1], result[2] - 5, result[3]);
			this.generateEntities(world, result[1], result[2] - 5, result[3], random);
			this.generateLoot(world, result[1], result[2] - 5, result[3], random);
		}
	}
	
	public boolean masterGenerate(World world, int i, int j, int k) {
		
		generate(world, i, j, k);
		generate2(world, i, j, k);
		generate3(world, i, j, k);

		return true;
	}
	
	public void generateEntities(World world, int i, int j, int k, Random random) {
		int numM = random.nextInt(2) + 1;
		int numW = random.nextInt(4) + 1;

		for (int x = 0; x < numM; x++) {
			EntityAirMan airMan = new EntityAirMan(world, i + 10, j + 7, k + 10, 9);
			airMan.setPositionAndRotation(i + 7, j + 7, k + 7, 1.0F, 1.0F);
			world.spawnEntityInWorld(airMan);
		}

		for (int x = 0; x < numW; x++) {
			EntityAirWoman airWoman = new EntityAirWoman(world, i + 10, j + 7, k + 10, 9);
			airWoman.setPositionAndRotation(i + 7, j + 7, k + 7, 1.0F, 1.0F);
			world.spawnEntityInWorld(airWoman);
		}

	}	
	
	public void generateLoot(World world, int i, int j, int k, Random random){
		for(int x = i; x < i + 20; x++){
			for (int z = k; z < k + 20; z++) {
				for (int y = j; y < j + 23; y++) {
						TileEntity e = world.getTileEntity(x, y, z);
						if(e != null && e instanceof TileEntityChest){
							GenerationUtils.generateScrolls(random, (TileEntityChest) e, ElementManager.AIR, 3);
							int ran = random.nextInt(8);
							for(int r = 0; r < random.nextInt(5); r++){
								switch (ran){
								case 0:
									((TileEntityChest) e).setInventorySlotContents(random.nextInt(27), new ItemStack(GenerationUtils.gliders.get(random.nextInt(GenerationUtils.gliders.size())), 1, 0));
									break;
								case 1:
									((TileEntityChest) e).setInventorySlotContents(random.nextInt(27), new ItemStack(mod_Avatar.CustardTartItem, random.nextInt(2), 0));	
									break;
								case 2:
									((TileEntityChest) e).setInventorySlotContents(random.nextInt(27), new ItemStack(mod_Avatar.FruitPieItem, random.nextInt(5), 0));	
									break;
								case 3:
									((TileEntityChest) e).setInventorySlotContents(random.nextInt(27), new ItemStack(mod_Avatar.RiceGrainItem, random.nextInt(32), 0));	
									((TileEntityChest) e).setInventorySlotContents(random.nextInt(27), new ItemStack(GenerationUtils.gliders.get(random.nextInt(GenerationUtils.gliders.size())), 1, 0));
									break;
								case 4:
									((TileEntityChest) e).setInventorySlotContents(random.nextInt(27), new ItemStack(mod_Avatar.RiceGrainItem, random.nextInt(32), 0));	
									break;
								case 5:
									((TileEntityChest) e).setInventorySlotContents(random.nextInt(27), new ItemStack(mod_Avatar.RiceBowlItem, 1, 0));	
									break;
								case 6:
									((TileEntityChest) e).setInventorySlotContents(random.nextInt(27), new ItemStack(GenerationUtils.gliders.get(random.nextInt(GenerationUtils.gliders.size())), 1, 0));
									break;
								case 7:
									((TileEntityChest) e).setInventorySlotContents(random.nextInt(27), new ItemStack(mod_Avatar.MoonPeachItem, random.nextInt(16), 0));	
									break;
								}	
							}
							
						}
				}
			}
		}
	}

	public void generate(World world, int i, int j, int k) {

		for (int x = 0; x <= 20; x++) {
			for (int z = 0; z <= 20; z++) {
				for (int y = 0; y < 23; y++) {
					world.setBlock(i + x, j + y, k + z, Blocks.air);
				}
			}
		}

		world.setBlock(i + 0, j + 0, k + 0, Blocks.dirt);
		world.setBlock(i + 0, j + 0, k + 1, Blocks.dirt);
		world.setBlock(i + 0, j + 0, k + 2, Blocks.dirt);
		world.setBlock(i + 0, j + 0, k + 3, Blocks.dirt);
		world.setBlock(i + 0, j + 0, k + 4, Blocks.dirt);
		world.setBlock(i + 0, j + 0, k + 5, Blocks.dirt);
		world.setBlock(i + 0, j + 0, k + 6, Blocks.dirt);
		world.setBlock(i + 0, j + 0, k + 7, Blocks.dirt);
		world.setBlock(i + 0, j + 0, k + 8, Blocks.dirt);
		world.setBlock(i + 0, j + 0, k + 9, Blocks.dirt);
		world.setBlock(i + 0, j + 0, k + 10, Blocks.dirt);
		world.setBlock(i + 0, j + 0, k + 11, Blocks.dirt);
		world.setBlock(i + 0, j + 0, k + 12, Blocks.dirt);
		world.setBlock(i + 0, j + 0, k + 13, Blocks.dirt);
		world.setBlock(i + 0, j + 0, k + 14, Blocks.dirt);
		world.setBlock(i + 0, j + 0, k + 15, Blocks.dirt);
		world.setBlock(i + 0, j + 0, k + 16, Blocks.dirt);
		world.setBlock(i + 0, j + 0, k + 17, Blocks.dirt);
		world.setBlock(i + 0, j + 0, k + 18, Blocks.dirt);
		world.setBlock(i + 0, j + 0, k + 19, Blocks.dirt);
		world.setBlock(i + 0, j + 0, k + 20, Blocks.dirt);
		world.setBlock(i + 0, j + 1, k + 0, Blocks.dirt);
		world.setBlock(i + 0, j + 1, k + 1, Blocks.dirt);
		world.setBlock(i + 0, j + 1, k + 2, Blocks.dirt);
		world.setBlock(i + 0, j + 1, k + 3, Blocks.dirt);
		world.setBlock(i + 0, j + 1, k + 4, Blocks.dirt);
		world.setBlock(i + 0, j + 1, k + 5, Blocks.dirt);
		world.setBlock(i + 0, j + 1, k + 6, Blocks.dirt);
		world.setBlock(i + 0, j + 1, k + 7, Blocks.dirt);
		world.setBlock(i + 0, j + 1, k + 8, Blocks.dirt);
		world.setBlock(i + 0, j + 1, k + 9, Blocks.dirt);
		world.setBlock(i + 0, j + 1, k + 10, Blocks.dirt);
		world.setBlock(i + 0, j + 1, k + 11, Blocks.dirt);
		world.setBlock(i + 0, j + 1, k + 12, Blocks.dirt);
		world.setBlock(i + 0, j + 1, k + 13, Blocks.dirt);
		world.setBlock(i + 0, j + 1, k + 14, Blocks.dirt);
		world.setBlock(i + 0, j + 1, k + 15, Blocks.dirt);
		world.setBlock(i + 0, j + 1, k + 16, Blocks.dirt);
		world.setBlock(i + 0, j + 1, k + 17, Blocks.dirt);
		world.setBlock(i + 0, j + 1, k + 18, Blocks.dirt);
		world.setBlock(i + 0, j + 1, k + 19, Blocks.dirt);
		world.setBlock(i + 0, j + 1, k + 20, Blocks.dirt);
		world.setBlock(i + 0, j + 2, k + 0, Blocks.grass);
		world.setBlock(i + 0, j + 2, k + 1, Blocks.grass);
		world.setBlock(i + 0, j + 2, k + 2, Blocks.grass);
		world.setBlock(i + 0, j + 2, k + 3, Blocks.grass);
		world.setBlock(i + 0, j + 2, k + 4, Blocks.grass);
		world.setBlock(i + 0, j + 2, k + 5, Blocks.grass);
		world.setBlock(i + 0, j + 2, k + 6, Blocks.grass);
		world.setBlock(i + 0, j + 2, k + 7, Blocks.grass);
		world.setBlock(i + 0, j + 2, k + 8, Blocks.grass);
		world.setBlock(i + 0, j + 2, k + 9, Blocks.grass);
		world.setBlock(i + 0, j + 2, k + 10, Blocks.grass);
		world.setBlock(i + 0, j + 2, k + 11, Blocks.grass);
		world.setBlock(i + 0, j + 2, k + 12, Blocks.dirt);
		world.setBlock(i + 0, j + 2, k + 13, Blocks.dirt);
		world.setBlock(i + 0, j + 2, k + 14, Blocks.dirt);
		world.setBlock(i + 0, j + 2, k + 15, Blocks.dirt);
		world.setBlock(i + 0, j + 2, k + 16, Blocks.dirt);
		world.setBlock(i + 0, j + 2, k + 17, Blocks.dirt);
		world.setBlock(i + 0, j + 2, k + 18, Blocks.dirt);
		world.setBlock(i + 0, j + 2, k + 19, Blocks.dirt);
		world.setBlock(i + 0, j + 2, k + 20, Blocks.dirt);
		world.setBlock(i + 0, j + 3, k + 0, Blocks.dirt);
		world.setBlock(i + 0, j + 3, k + 1, Blocks.dirt);
		world.setBlock(i + 0, j + 3, k + 2, Blocks.dirt);
		world.setBlock(i + 0, j + 3, k + 3, Blocks.dirt);
		world.setBlock(i + 0, j + 3, k + 4, Blocks.dirt);
		world.setBlock(i + 0, j + 3, k + 5, Blocks.dirt);
		world.setBlock(i + 0, j + 3, k + 6, Blocks.dirt);
		world.setBlock(i + 0, j + 3, k + 7, Blocks.dirt);
		world.setBlock(i + 0, j + 3, k + 8, Blocks.dirt);
		world.setBlock(i + 0, j + 3, k + 9, Blocks.dirt);
		world.setBlock(i + 0, j + 3, k + 10, Blocks.dirt);
		world.setBlock(i + 0, j + 3, k + 11, Blocks.dirt);
		world.setBlock(i + 0, j + 3, k + 12, Blocks.dirt);
		world.setBlock(i + 0, j + 3, k + 13, Blocks.dirt);
		world.setBlock(i + 0, j + 3, k + 14, Blocks.dirt);
		world.setBlock(i + 0, j + 3, k + 15, Blocks.dirt);
		world.setBlock(i + 0, j + 3, k + 16, Blocks.dirt);
		world.setBlock(i + 0, j + 3, k + 17, Blocks.dirt);
		world.setBlock(i + 0, j + 3, k + 18, Blocks.dirt);
		world.setBlock(i + 0, j + 3, k + 19, Blocks.dirt);
		world.setBlock(i + 0, j + 3, k + 20, Blocks.dirt);
		world.setBlock(i + 0, j + 4, k + 0, Blocks.dirt);
		world.setBlock(i + 0, j + 4, k + 1, Blocks.dirt);
		world.setBlock(i + 0, j + 4, k + 2, Blocks.dirt);
		world.setBlock(i + 0, j + 4, k + 3, Blocks.dirt);
		world.setBlock(i + 0, j + 4, k + 4, Blocks.dirt);
		world.setBlock(i + 0, j + 4, k + 5, Blocks.dirt);
		world.setBlock(i + 0, j + 4, k + 6, Blocks.dirt);
		world.setBlock(i + 0, j + 4, k + 7, Blocks.dirt);
		world.setBlock(i + 0, j + 4, k + 8, Blocks.dirt);
		world.setBlock(i + 0, j + 4, k + 9, Blocks.dirt);
		world.setBlock(i + 0, j + 4, k + 10, Blocks.dirt);
		world.setBlock(i + 0, j + 4, k + 11, Blocks.dirt);
		world.setBlock(i + 0, j + 4, k + 12, Blocks.dirt);
		world.setBlock(i + 0, j + 4, k + 13, Blocks.dirt);
		world.setBlock(i + 0, j + 4, k + 14, Blocks.dirt);
		world.setBlock(i + 0, j + 4, k + 15, Blocks.dirt);
		world.setBlock(i + 0, j + 4, k + 16, Blocks.dirt);
		world.setBlock(i + 0, j + 4, k + 17, Blocks.dirt);
		world.setBlock(i + 0, j + 4, k + 18, Blocks.dirt);
		world.setBlock(i + 0, j + 4, k + 19, Blocks.dirt);
		world.setBlock(i + 0, j + 4, k + 20, Blocks.dirt);
		world.setBlock(i + 0, j + 5, k + 0, Blocks.dirt);
		world.setBlock(i + 0, j + 5, k + 1, Blocks.dirt);
		world.setBlock(i + 0, j + 5, k + 2, Blocks.dirt);
		world.setBlock(i + 0, j + 5, k + 3, Blocks.dirt);
		world.setBlock(i + 0, j + 5, k + 4, Blocks.dirt);
		world.setBlock(i + 0, j + 5, k + 5, Blocks.dirt);
		world.setBlock(i + 0, j + 5, k + 6, Blocks.dirt);
		world.setBlock(i + 0, j + 5, k + 7, Blocks.dirt);
		world.setBlock(i + 0, j + 5, k + 8, Blocks.dirt);
		world.setBlock(i + 0, j + 5, k + 9, Blocks.nether_brick);
		world.setBlock(i + 0, j + 5, k + 10, Blocks.nether_brick);
		world.setBlock(i + 0, j + 5, k + 11, Blocks.nether_brick);
		world.setBlock(i + 0, j + 5, k + 12, Blocks.grass);
		world.setBlock(i + 0, j + 5, k + 13, Blocks.grass);
		world.setBlock(i + 0, j + 5, k + 14, Blocks.grass);
		world.setBlock(i + 0, j + 5, k + 15, Blocks.grass);
		world.setBlock(i + 0, j + 5, k + 16, Blocks.grass);
		world.setBlock(i + 0, j + 5, k + 17, Blocks.grass);
		world.setBlock(i + 0, j + 5, k + 18, Blocks.grass);
		world.setBlock(i + 0, j + 5, k + 19, Blocks.grass);
		world.setBlock(i + 0, j + 5, k + 20, Blocks.grass);
		world.setBlock(i + 0, j + 6, k + 0, Blocks.birch_stairs, 2, 0x02);
		world.setBlock(i + 0, j + 6, k + 1, Blocks.birch_stairs);
		world.setBlock(i + 0, j + 6, k + 2, Blocks.birch_stairs);
		world.setBlock(i + 0, j + 6, k + 3, Blocks.birch_stairs);
		world.setBlock(i + 0, j + 6, k + 4, Blocks.birch_stairs);
		world.setBlock(i + 0, j + 6, k + 5, Blocks.birch_stairs);
		world.setBlock(i + 0, j + 6, k + 6, Blocks.birch_stairs);
		world.setBlock(i + 0, j + 6, k + 7, Blocks.birch_stairs);
		world.setBlock(i + 0, j + 6, k + 8, Blocks.birch_stairs);
		world.setBlock(i + 0, j + 6, k + 12, Blocks.cobblestone_wall, 1, 0x02);
		world.setBlock(i + 0, j + 6, k + 13, Blocks.cobblestone_wall, 1, 0x02);
		world.setBlock(i + 0, j + 6, k + 14, Blocks.cobblestone_wall, 1, 0x02);
		world.setBlock(i + 0, j + 6, k + 15, Blocks.cobblestone_wall, 1, 0x02);
		world.setBlock(i + 0, j + 6, k + 16, Blocks.cobblestone_wall, 1, 0x02);
		world.setBlock(i + 0, j + 6, k + 17, Blocks.cobblestone_wall, 1, 0x02);
		world.setBlock(i + 0, j + 6, k + 18, Blocks.cobblestone_wall, 1, 0x02);
		world.setBlock(i + 0, j + 6, k + 19, Blocks.cobblestone_wall, 1, 0x02);
		world.setBlock(i + 0, j + 6, k + 20, Blocks.cobblestone_wall, 1, 0x02);
		world.setBlock(i + 0, j + 8, k + 14, Blocks.leaves, 2, 0x02);
		world.setBlock(i + 0, j + 8, k + 15, Blocks.leaves, 2, 0x02);
		world.setBlock(i + 0, j + 8, k + 16, Blocks.leaves, 2, 0x02);
		world.setBlock(i + 0, j + 8, k + 17, Blocks.leaves, 2, 0x02);
		world.setBlock(i + 0, j + 8, k + 18, Blocks.leaves);
		world.setBlock(i + 0, j + 8, k + 19, Blocks.leaves);
		world.setBlock(i + 0, j + 9, k + 13, Blocks.leaves, 2, 0x02);
		world.setBlock(i + 0, j + 9, k + 14, Blocks.leaves, 2, 0x02);
		world.setBlock(i + 0, j + 9, k + 15, Blocks.leaves, 2, 0x02);
		world.setBlock(i + 0, j + 9, k + 16, Blocks.leaves, 2, 0x02);
		world.setBlock(i + 0, j + 9, k + 17, Blocks.leaves, 2, 0x02);
		world.setBlock(i + 0, j + 9, k + 18, Blocks.leaves);
		world.setBlock(i + 0, j + 9, k + 19, Blocks.leaves);
		world.setBlock(i + 0, j + 11, k + 0, Blocks.birch_stairs);
		world.setBlock(i + 0, j + 11, k + 1, Blocks.birch_stairs);
		world.setBlock(i + 0, j + 11, k + 2, Blocks.birch_stairs);
		world.setBlock(i + 0, j + 11, k + 3, Blocks.birch_stairs);
		world.setBlock(i + 0, j + 11, k + 4, Blocks.birch_stairs);
		world.setBlock(i + 0, j + 11, k + 5, Blocks.birch_stairs);
		world.setBlock(i + 0, j + 11, k + 6, Blocks.birch_stairs);
		world.setBlock(i + 0, j + 11, k + 7, Blocks.birch_stairs);
		world.setBlock(i + 0, j + 11, k + 8, Blocks.birch_stairs, 3, 0x02);
		world.setBlock(i + 0, j + 17, k + 0, Blocks.wooden_slab, 1, 0x02);
		world.setBlock(i + 0, j + 17, k + 1, Blocks.wooden_slab, 1, 0x02);
		world.setBlock(i + 0, j + 17, k + 2, Blocks.wooden_slab, 1, 0x02);
		world.setBlock(i + 0, j + 17, k + 3, Blocks.wooden_slab, 1, 0x02);
		world.setBlock(i + 0, j + 17, k + 4, Blocks.wooden_slab, 1, 0x02);
		world.setBlock(i + 0, j + 17, k + 5, Blocks.wooden_slab, 1, 0x02);
		world.setBlock(i + 0, j + 17, k + 6, Blocks.wooden_slab, 1, 0x02);
		world.setBlock(i + 1, j + 0, k + 0, Blocks.dirt);
		world.setBlock(i + 1, j + 0, k + 1, Blocks.dirt);
		world.setBlock(i + 1, j + 0, k + 2, Blocks.dirt);
		world.setBlock(i + 1, j + 0, k + 3, Blocks.dirt);
		world.setBlock(i + 1, j + 0, k + 4, Blocks.dirt);
		world.setBlock(i + 1, j + 0, k + 5, Blocks.dirt);
		world.setBlock(i + 1, j + 0, k + 6, Blocks.dirt);
		world.setBlock(i + 1, j + 0, k + 7, Blocks.dirt);
		world.setBlock(i + 1, j + 0, k + 8, Blocks.dirt);
		world.setBlock(i + 1, j + 0, k + 9, Blocks.dirt);
		world.setBlock(i + 1, j + 0, k + 10, Blocks.dirt);
		world.setBlock(i + 1, j + 0, k + 11, Blocks.dirt);
		world.setBlock(i + 1, j + 0, k + 12, Blocks.dirt);
		world.setBlock(i + 1, j + 0, k + 13, Blocks.dirt);
		world.setBlock(i + 1, j + 0, k + 14, Blocks.dirt);
		world.setBlock(i + 1, j + 0, k + 15, Blocks.dirt);
		world.setBlock(i + 1, j + 0, k + 16, Blocks.dirt);
		world.setBlock(i + 1, j + 0, k + 17, Blocks.dirt);
		world.setBlock(i + 1, j + 0, k + 18, Blocks.dirt);
		world.setBlock(i + 1, j + 0, k + 19, Blocks.dirt);
		world.setBlock(i + 1, j + 0, k + 20, Blocks.dirt);
		world.setBlock(i + 1, j + 1, k + 0, Blocks.dirt);
		world.setBlock(i + 1, j + 1, k + 1, Blocks.dirt);
		world.setBlock(i + 1, j + 1, k + 2, Blocks.dirt);
		world.setBlock(i + 1, j + 1, k + 3, Blocks.dirt);
		world.setBlock(i + 1, j + 1, k + 4, Blocks.dirt);
		world.setBlock(i + 1, j + 1, k + 5, Blocks.dirt);
		world.setBlock(i + 1, j + 1, k + 6, Blocks.dirt);
		world.setBlock(i + 1, j + 1, k + 7, Blocks.dirt);
		world.setBlock(i + 1, j + 1, k + 8, Blocks.dirt);
		world.setBlock(i + 1, j + 1, k + 9, Blocks.dirt);
		world.setBlock(i + 1, j + 1, k + 10, Blocks.dirt);
		world.setBlock(i + 1, j + 1, k + 11, Blocks.dirt);
		world.setBlock(i + 1, j + 1, k + 12, Blocks.dirt);
		world.setBlock(i + 1, j + 1, k + 13, Blocks.dirt);
		world.setBlock(i + 1, j + 1, k + 14, Blocks.dirt);
		world.setBlock(i + 1, j + 1, k + 15, Blocks.dirt);
		world.setBlock(i + 1, j + 1, k + 16, Blocks.dirt);
		world.setBlock(i + 1, j + 1, k + 17, Blocks.dirt);
		world.setBlock(i + 1, j + 1, k + 18, Blocks.dirt);
		world.setBlock(i + 1, j + 1, k + 19, Blocks.dirt);
		world.setBlock(i + 1, j + 1, k + 20, Blocks.dirt);
		world.setBlock(i + 1, j + 2, k + 0, Blocks.grass);
		world.setBlock(i + 1, j + 2, k + 1, Blocks.grass);
		world.setBlock(i + 1, j + 2, k + 2, Blocks.grass);
		world.setBlock(i + 1, j + 2, k + 3, Blocks.grass);
		world.setBlock(i + 1, j + 2, k + 4, Blocks.grass);
		world.setBlock(i + 1, j + 2, k + 5, Blocks.grass);
		world.setBlock(i + 1, j + 2, k + 6, Blocks.grass);
		world.setBlock(i + 1, j + 2, k + 7, Blocks.grass);
		world.setBlock(i + 1, j + 2, k + 8, Blocks.grass);
		world.setBlock(i + 1, j + 2, k + 9, Blocks.grass);
		world.setBlock(i + 1, j + 2, k + 10, Blocks.grass);
		world.setBlock(i + 1, j + 2, k + 11, Blocks.grass);
		world.setBlock(i + 1, j + 2, k + 12, Blocks.dirt);
		world.setBlock(i + 1, j + 2, k + 13, Blocks.dirt);
		world.setBlock(i + 1, j + 2, k + 14, Blocks.dirt);
		world.setBlock(i + 1, j + 2, k + 15, Blocks.dirt);
		world.setBlock(i + 1, j + 2, k + 16, Blocks.dirt);
		world.setBlock(i + 1, j + 2, k + 17, Blocks.dirt);
		world.setBlock(i + 1, j + 2, k + 18, Blocks.dirt);
		world.setBlock(i + 1, j + 2, k + 19, Blocks.dirt);
		world.setBlock(i + 1, j + 2, k + 20, Blocks.dirt);
		world.setBlock(i + 1, j + 3, k + 0, Blocks.dirt);
		world.setBlock(i + 1, j + 3, k + 1, Blocks.dirt);
		world.setBlock(i + 1, j + 3, k + 2, Blocks.dirt);
		world.setBlock(i + 1, j + 3, k + 3, Blocks.dirt);
		world.setBlock(i + 1, j + 3, k + 4, Blocks.dirt);
		world.setBlock(i + 1, j + 3, k + 5, Blocks.dirt);
		world.setBlock(i + 1, j + 3, k + 6, Blocks.dirt);
		world.setBlock(i + 1, j + 3, k + 7, Blocks.dirt);
		world.setBlock(i + 1, j + 3, k + 8, Blocks.dirt);
		world.setBlock(i + 1, j + 3, k + 9, Blocks.dirt);
		world.setBlock(i + 1, j + 3, k + 10, Blocks.dirt);
		world.setBlock(i + 1, j + 3, k + 11, Blocks.dirt);
		world.setBlock(i + 1, j + 3, k + 12, Blocks.dirt);
		world.setBlock(i + 1, j + 3, k + 13, Blocks.dirt);
		world.setBlock(i + 1, j + 3, k + 14, Blocks.dirt);
		world.setBlock(i + 1, j + 3, k + 15, Blocks.dirt);
		world.setBlock(i + 1, j + 3, k + 16, Blocks.dirt);
		world.setBlock(i + 1, j + 3, k + 17, Blocks.dirt);
		world.setBlock(i + 1, j + 3, k + 18, Blocks.dirt);
		world.setBlock(i + 1, j + 3, k + 19, Blocks.dirt);
		world.setBlock(i + 1, j + 3, k + 20, Blocks.dirt);
		world.setBlock(i + 1, j + 4, k + 0, Blocks.dirt);
		world.setBlock(i + 1, j + 4, k + 1, Blocks.dirt);
		world.setBlock(i + 1, j + 4, k + 2, Blocks.dirt);
		world.setBlock(i + 1, j + 4, k + 3, Blocks.dirt);
		world.setBlock(i + 1, j + 4, k + 4, Blocks.dirt);
		world.setBlock(i + 1, j + 4, k + 5, Blocks.dirt);
		world.setBlock(i + 1, j + 4, k + 6, Blocks.dirt);
		world.setBlock(i + 1, j + 4, k + 7, Blocks.dirt);
		world.setBlock(i + 1, j + 4, k + 8, Blocks.dirt);
		world.setBlock(i + 1, j + 4, k + 9, Blocks.dirt);
		world.setBlock(i + 1, j + 4, k + 10, Blocks.dirt);
		world.setBlock(i + 1, j + 4, k + 11, Blocks.dirt);
		world.setBlock(i + 1, j + 4, k + 12, Blocks.dirt);
		world.setBlock(i + 1, j + 4, k + 13, Blocks.dirt);
		world.setBlock(i + 1, j + 4, k + 14, Blocks.dirt);
		world.setBlock(i + 1, j + 4, k + 15, Blocks.dirt);
		world.setBlock(i + 1, j + 4, k + 16, Blocks.dirt);
		world.setBlock(i + 1, j + 4, k + 17, Blocks.dirt);
		world.setBlock(i + 1, j + 4, k + 18, Blocks.dirt);
		world.setBlock(i + 1, j + 4, k + 19, Blocks.dirt);
		world.setBlock(i + 1, j + 4, k + 20, Blocks.dirt);
		world.setBlock(i + 1, j + 5, k + 0, Blocks.dirt);
		world.setBlock(i + 1, j + 5, k + 1, Blocks.dirt);
		world.setBlock(i + 1, j + 5, k + 2, Blocks.dirt);
		world.setBlock(i + 1, j + 5, k + 3, Blocks.dirt);
		world.setBlock(i + 1, j + 5, k + 4, Blocks.dirt);
		world.setBlock(i + 1, j + 5, k + 5, Blocks.dirt);
		world.setBlock(i + 1, j + 5, k + 6, Blocks.dirt);
		world.setBlock(i + 1, j + 5, k + 7, Blocks.dirt);
		world.setBlock(i + 1, j + 5, k + 8, Blocks.dirt);
		world.setBlock(i + 1, j + 5, k + 9, Blocks.nether_brick);
		world.setBlock(i + 1, j + 5, k + 10, Blocks.sandstone, 2, 0x02);
		world.setBlock(i + 1, j + 5, k + 11, Blocks.nether_brick);
		world.setBlock(i + 1, j + 5, k + 12, Blocks.grass);
		world.setBlock(i + 1, j + 5, k + 13, Blocks.grass);
		world.setBlock(i + 1, j + 5, k + 14, Blocks.grass);
		world.setBlock(i + 1, j + 5, k + 15, Blocks.grass);
		world.setBlock(i + 1, j + 5, k + 16, Blocks.grass);
		world.setBlock(i + 1, j + 5, k + 17, Blocks.grass);
		world.setBlock(i + 1, j + 5, k + 18, Blocks.grass);
		world.setBlock(i + 1, j + 5, k + 19, Blocks.grass);
		world.setBlock(i + 1, j + 5, k + 20, Blocks.grass);
		world.setBlock(i + 1, j + 6, k + 0, Blocks.birch_stairs, 2, 0x02);
		world.setBlock(i + 1, j + 6, k + 1, Blocks.planks, 2, 0x02);
		world.setBlock(i + 1, j + 6, k + 2, Blocks.planks, 2, 0x02);
		world.setBlock(i + 1, j + 6, k + 3, Blocks.planks, 2, 0x02);
		world.setBlock(i + 1, j + 6, k + 4, Blocks.planks, 2, 0x02);
		world.setBlock(i + 1, j + 6, k + 5, Blocks.planks, 2, 0x02);
		world.setBlock(i + 1, j + 6, k + 6, Blocks.planks, 2, 0x02);
		world.setBlock(i + 1, j + 6, k + 7, Blocks.planks, 2, 0x02);
		world.setBlock(i + 1, j + 6, k + 8, Blocks.birch_stairs, 3, 0x02);
		world.setBlock(i + 1, j + 6, k + 12, Blocks.cobblestone_wall, 1, 0x02);
		world.setBlock(i + 1, j + 6, k + 20, Blocks.cobblestone_wall, 1, 0x02);
		world.setBlock(i + 1, j + 7, k + 1, Blocks.log, 1, 0x02);
		world.setBlock(i + 1, j + 7, k + 2, Blocks.cobblestone);
		world.setBlock(i + 1, j + 7, k + 3, Blocks.cobblestone);
		world.setBlock(i + 1, j + 7, k + 4, Blocks.cobblestone);
		world.setBlock(i + 1, j + 7, k + 5, Blocks.cobblestone);
		world.setBlock(i + 1, j + 7, k + 6, Blocks.cobblestone);
		world.setBlock(i + 1, j + 7, k + 7, Blocks.log, 1, 0x02);
		world.setBlock(i + 1, j + 8, k + 1, Blocks.log, 1, 0x02);
		world.setBlock(i + 1, j + 8, k + 2, Blocks.cobblestone);
		world.setBlock(i + 1, j + 8, k + 3, Blocks.glass_pane);
		world.setBlock(i + 1, j + 8, k + 4, Blocks.glass_pane);
		world.setBlock(i + 1, j + 8, k + 5, Blocks.glass_pane);
		world.setBlock(i + 1, j + 8, k + 6, Blocks.cobblestone);
		world.setBlock(i + 1, j + 8, k + 7, Blocks.log, 1, 0x02);
		world.setBlock(i + 1, j + 8, k + 13, Blocks.leaves, 2, 0x02);
		world.setBlock(i + 1, j + 8, k + 14, Blocks.leaves, 2, 0x02);
		world.setBlock(i + 1, j + 8, k + 15, Blocks.leaves, 2, 0x02);
		world.setBlock(i + 1, j + 8, k + 16, Blocks.leaves, 2, 0x02);
		world.setBlock(i + 1, j + 8, k + 17, Blocks.leaves, 2, 0x02);
		world.setBlock(i + 1, j + 8, k + 18, Blocks.leaves);
		world.setBlock(i + 1, j + 8, k + 19, Blocks.leaves);
		world.setBlock(i + 1, j + 8, k + 20, Blocks.leaves);
		world.setBlock(i + 1, j + 9, k + 1, Blocks.log, 1, 0x02);
		world.setBlock(i + 1, j + 9, k + 2, Blocks.cobblestone);
		world.setBlock(i + 1, j + 9, k + 3, Blocks.glass_pane);
		world.setBlock(i + 1, j + 9, k + 4, Blocks.glass_pane);
		world.setBlock(i + 1, j + 9, k + 5, Blocks.glass_pane);
		world.setBlock(i + 1, j + 9, k + 6, Blocks.cobblestone);
		world.setBlock(i + 1, j + 9, k + 7, Blocks.log, 1, 0x02);
		world.setBlock(i + 1, j + 9, k + 13, Blocks.leaves, 2, 0x02);
		world.setBlock(i + 1, j + 9, k + 14, Blocks.leaves, 2, 0x02);
		world.setBlock(i + 1, j + 9, k + 15, Blocks.leaves, 2, 0x02);
		world.setBlock(i + 1, j + 9, k + 16, Blocks.leaves, 2, 0x02);
		world.setBlock(i + 1, j + 9, k + 17, Blocks.leaves, 2, 0x02);
		world.setBlock(i + 1, j + 9, k + 18, Blocks.leaves);
		world.setBlock(i + 1, j + 9, k + 19, Blocks.leaves);
		world.setBlock(i + 1, j + 9, k + 20, Blocks.leaves);
		world.setBlock(i + 1, j + 10, k + 1, Blocks.log, 1, 0x02);
		world.setBlock(i + 1, j + 10, k + 2, Blocks.cobblestone);
		world.setBlock(i + 1, j + 10, k + 3, Blocks.cobblestone);
		world.setBlock(i + 1, j + 10, k + 4, Blocks.cobblestone);
		world.setBlock(i + 1, j + 10, k + 5, Blocks.cobblestone);
		world.setBlock(i + 1, j + 10, k + 6, Blocks.cobblestone);
		world.setBlock(i + 1, j + 10, k + 7, Blocks.log, 1, 0x02);
		world.setBlock(i + 1, j + 10, k + 14, Blocks.leaves, 2, 0x02);
		world.setBlock(i + 1, j + 10, k + 15, Blocks.leaves, 2, 0x02);
		world.setBlock(i + 1, j + 10, k + 16, Blocks.leaves, 2, 0x02);
		world.setBlock(i + 1, j + 10, k + 18, Blocks.leaves);
		world.setBlock(i + 1, j + 11, k + 0, Blocks.birch_stairs, 2, 0x02);
		world.setBlock(i + 1, j + 11, k + 1, Blocks.log, 1, 0x02);
		world.setBlock(i + 1, j + 11, k + 2, Blocks.log, 5, 0x02);
		world.setBlock(i + 1, j + 11, k + 3, Blocks.log, 5, 0x02);
		world.setBlock(i + 1, j + 11, k + 4, Blocks.log, 5, 0x02);
		world.setBlock(i + 1, j + 11, k + 5, Blocks.log, 5, 0x02);
		world.setBlock(i + 1, j + 11, k + 6, Blocks.log, 5, 0x02);
		world.setBlock(i + 1, j + 11, k + 7, Blocks.log, 1, 0x02);
		world.setBlock(i + 1, j + 11, k + 8, Blocks.birch_stairs, 3, 0x02);
		world.setBlock(i + 1, j + 11, k + 15, Blocks.leaves, 2, 0x02);
		world.setBlock(i + 1, j + 11, k + 18, Blocks.leaves);
		world.setBlock(i + 1, j + 12, k + 1, Blocks.log, 1, 0x02);
		world.setBlock(i + 1, j + 12, k + 2, Blocks.cobblestone);
		world.setBlock(i + 1, j + 12, k + 3, Blocks.cobblestone);
		world.setBlock(i + 1, j + 12, k + 4, Blocks.cobblestone);
		world.setBlock(i + 1, j + 12, k + 5, Blocks.log, 1, 0x02);
		world.setBlock(i + 1, j + 12, k + 6, Blocks.fence);
		world.setBlock(i + 1, j + 12, k + 7, Blocks.fence);
		world.setBlock(i + 1, j + 13, k + 1, Blocks.log, 1, 0x02);
		world.setBlock(i + 1, j + 13, k + 2, Blocks.cobblestone);
		world.setBlock(i + 1, j + 13, k + 3, Blocks.glass_pane);
		world.setBlock(i + 1, j + 13, k + 4, Blocks.cobblestone);
		world.setBlock(i + 1, j + 13, k + 5, Blocks.log, 1, 0x02);
		world.setBlock(i + 1, j + 14, k + 1, Blocks.log, 1, 0x02);
		world.setBlock(i + 1, j + 14, k + 2, Blocks.cobblestone);
		world.setBlock(i + 1, j + 14, k + 3, Blocks.glass_pane);
		world.setBlock(i + 1, j + 14, k + 4, Blocks.cobblestone);
		world.setBlock(i + 1, j + 14, k + 5, Blocks.log, 1, 0x02);
		world.setBlock(i + 1, j + 15, k + 1, Blocks.log, 1, 0x02);
		world.setBlock(i + 1, j + 15, k + 2, Blocks.cobblestone);
		world.setBlock(i + 1, j + 15, k + 3, Blocks.cobblestone);
		world.setBlock(i + 1, j + 15, k + 4, Blocks.cobblestone);
		world.setBlock(i + 1, j + 15, k + 5, Blocks.log, 1, 0x02);
		world.setBlock(i + 1, j + 16, k + 1, Blocks.log, 1, 0x02);
		world.setBlock(i + 1, j + 16, k + 2, Blocks.log, 5, 0x02);
		world.setBlock(i + 1, j + 16, k + 3, Blocks.log, 5, 0x02);
		world.setBlock(i + 1, j + 16, k + 4, Blocks.log, 5, 0x02);
		world.setBlock(i + 1, j + 16, k + 5, Blocks.log, 1, 0x02);
		world.setBlock(i + 1, j + 17, k + 0, Blocks.wooden_slab, 1, 0x02);
		world.setBlock(i + 1, j + 17, k + 1, Blocks.double_wooden_slab, 2, 0x02);
		world.setBlock(i + 1, j + 17, k + 2, Blocks.planks, 2, 0x02);
		world.setBlock(i + 1, j + 17, k + 3, Blocks.planks, 2, 0x02);
		world.setBlock(i + 1, j + 17, k + 4, Blocks.planks, 2, 0x02);
		world.setBlock(i + 1, j + 17, k + 5, Blocks.planks, 2, 0x02);
		world.setBlock(i + 1, j + 17, k + 6, Blocks.wooden_slab, 1, 0x02);
		world.setBlock(i + 2, j + 0, k + 0, Blocks.dirt);
		world.setBlock(i + 2, j + 0, k + 1, Blocks.dirt);
		world.setBlock(i + 2, j + 0, k + 2, Blocks.dirt);
		world.setBlock(i + 2, j + 0, k + 3, Blocks.dirt);
		world.setBlock(i + 2, j + 0, k + 4, Blocks.dirt);
		world.setBlock(i + 2, j + 0, k + 5, Blocks.dirt);
		world.setBlock(i + 2, j + 0, k + 6, Blocks.dirt);
		world.setBlock(i + 2, j + 0, k + 7, Blocks.dirt);
		world.setBlock(i + 2, j + 0, k + 8, Blocks.dirt);
		world.setBlock(i + 2, j + 0, k + 9, Blocks.dirt);
		world.setBlock(i + 2, j + 0, k + 10, Blocks.dirt);
		world.setBlock(i + 2, j + 0, k + 11, Blocks.dirt);
		world.setBlock(i + 2, j + 0, k + 12, Blocks.dirt);
		world.setBlock(i + 2, j + 0, k + 13, Blocks.dirt);
		world.setBlock(i + 2, j + 0, k + 14, Blocks.dirt);
		world.setBlock(i + 2, j + 0, k + 15, Blocks.dirt);
		world.setBlock(i + 2, j + 0, k + 16, Blocks.dirt);
		world.setBlock(i + 2, j + 0, k + 17, Blocks.dirt);
		world.setBlock(i + 2, j + 0, k + 18, Blocks.dirt);
		world.setBlock(i + 2, j + 0, k + 19, Blocks.dirt);
		world.setBlock(i + 2, j + 0, k + 20, Blocks.dirt);
		world.setBlock(i + 2, j + 1, k + 0, Blocks.dirt);
		world.setBlock(i + 2, j + 1, k + 1, Blocks.dirt);
		world.setBlock(i + 2, j + 1, k + 2, Blocks.dirt);
		world.setBlock(i + 2, j + 1, k + 3, Blocks.dirt);
		world.setBlock(i + 2, j + 1, k + 4, Blocks.dirt);
		world.setBlock(i + 2, j + 1, k + 5, Blocks.dirt);
		world.setBlock(i + 2, j + 1, k + 6, Blocks.dirt);
		world.setBlock(i + 2, j + 1, k + 7, Blocks.dirt);
		world.setBlock(i + 2, j + 1, k + 8, Blocks.dirt);
		world.setBlock(i + 2, j + 1, k + 9, Blocks.dirt);
		world.setBlock(i + 2, j + 1, k + 10, Blocks.dirt);
		world.setBlock(i + 2, j + 1, k + 11, Blocks.dirt);
		world.setBlock(i + 2, j + 1, k + 12, Blocks.dirt);
		world.setBlock(i + 2, j + 1, k + 13, Blocks.dirt);
		world.setBlock(i + 2, j + 1, k + 14, Blocks.dirt);
		world.setBlock(i + 2, j + 1, k + 15, Blocks.dirt);
		world.setBlock(i + 2, j + 1, k + 16, Blocks.dirt);
		world.setBlock(i + 2, j + 1, k + 17, Blocks.dirt);
		world.setBlock(i + 2, j + 1, k + 18, Blocks.dirt);
		world.setBlock(i + 2, j + 1, k + 19, Blocks.dirt);
		world.setBlock(i + 2, j + 1, k + 20, Blocks.dirt);
		world.setBlock(i + 2, j + 2, k + 0, Blocks.grass);
		world.setBlock(i + 2, j + 2, k + 1, Blocks.grass);
		world.setBlock(i + 2, j + 2, k + 2, Blocks.grass);
		world.setBlock(i + 2, j + 2, k + 3, Blocks.grass);
		world.setBlock(i + 2, j + 2, k + 4, Blocks.grass);
		world.setBlock(i + 2, j + 2, k + 5, Blocks.grass);
		world.setBlock(i + 2, j + 2, k + 6, Blocks.grass);
		world.setBlock(i + 2, j + 2, k + 7, Blocks.grass);
		world.setBlock(i + 2, j + 2, k + 8, Blocks.grass);
		world.setBlock(i + 2, j + 2, k + 9, Blocks.grass);
		world.setBlock(i + 2, j + 2, k + 10, Blocks.grass);
		world.setBlock(i + 2, j + 2, k + 11, Blocks.grass);
		world.setBlock(i + 2, j + 2, k + 12, Blocks.dirt);
		world.setBlock(i + 2, j + 2, k + 13, Blocks.dirt);
		world.setBlock(i + 2, j + 2, k + 14, Blocks.dirt);
		world.setBlock(i + 2, j + 2, k + 15, Blocks.dirt);
		world.setBlock(i + 2, j + 2, k + 16, Blocks.dirt);
		world.setBlock(i + 2, j + 2, k + 17, Blocks.dirt);
		world.setBlock(i + 2, j + 2, k + 18, Blocks.dirt);
		world.setBlock(i + 2, j + 2, k + 19, Blocks.dirt);
		world.setBlock(i + 2, j + 2, k + 20, Blocks.dirt);
		world.setBlock(i + 2, j + 3, k + 0, Blocks.dirt);
		world.setBlock(i + 2, j + 3, k + 1, Blocks.dirt);
		world.setBlock(i + 2, j + 3, k + 2, Blocks.dirt);
		world.setBlock(i + 2, j + 3, k + 3, Blocks.dirt);
		world.setBlock(i + 2, j + 3, k + 4, Blocks.dirt);
		world.setBlock(i + 2, j + 3, k + 5, Blocks.dirt);
		world.setBlock(i + 2, j + 3, k + 6, Blocks.dirt);
		world.setBlock(i + 2, j + 3, k + 7, Blocks.dirt);
		world.setBlock(i + 2, j + 3, k + 8, Blocks.dirt);
		world.setBlock(i + 2, j + 3, k + 9, Blocks.dirt);
		world.setBlock(i + 2, j + 3, k + 10, Blocks.dirt);
		world.setBlock(i + 2, j + 3, k + 11, Blocks.dirt);
		world.setBlock(i + 2, j + 3, k + 12, Blocks.dirt);
		world.setBlock(i + 2, j + 3, k + 13, Blocks.dirt);
		world.setBlock(i + 2, j + 3, k + 14, Blocks.dirt);
		world.setBlock(i + 2, j + 3, k + 15, Blocks.dirt);
		world.setBlock(i + 2, j + 3, k + 16, Blocks.dirt);
		world.setBlock(i + 2, j + 3, k + 17, Blocks.dirt);
		world.setBlock(i + 2, j + 3, k + 18, Blocks.dirt);
		world.setBlock(i + 2, j + 3, k + 19, Blocks.dirt);
		world.setBlock(i + 2, j + 3, k + 20, Blocks.dirt);
		world.setBlock(i + 2, j + 4, k + 0, Blocks.dirt);
		world.setBlock(i + 2, j + 4, k + 1, Blocks.dirt);
		world.setBlock(i + 2, j + 4, k + 2, Blocks.dirt);
		world.setBlock(i + 2, j + 4, k + 3, Blocks.dirt);
		world.setBlock(i + 2, j + 4, k + 4, Blocks.dirt);
		world.setBlock(i + 2, j + 4, k + 5, Blocks.dirt);
		world.setBlock(i + 2, j + 4, k + 6, Blocks.dirt);
		world.setBlock(i + 2, j + 4, k + 7, Blocks.dirt);
		world.setBlock(i + 2, j + 4, k + 8, Blocks.dirt);
		world.setBlock(i + 2, j + 4, k + 9, Blocks.dirt);
		world.setBlock(i + 2, j + 4, k + 10, Blocks.dirt);
		world.setBlock(i + 2, j + 4, k + 11, Blocks.dirt);
		world.setBlock(i + 2, j + 4, k + 12, Blocks.dirt);
		world.setBlock(i + 2, j + 4, k + 13, Blocks.dirt);
		world.setBlock(i + 2, j + 4, k + 14, Blocks.dirt);
		world.setBlock(i + 2, j + 4, k + 15, Blocks.dirt);
		world.setBlock(i + 2, j + 4, k + 16, Blocks.dirt);
		world.setBlock(i + 2, j + 4, k + 17, Blocks.dirt);
		world.setBlock(i + 2, j + 4, k + 18, Blocks.dirt);
		world.setBlock(i + 2, j + 4, k + 19, Blocks.dirt);
		world.setBlock(i + 2, j + 4, k + 20, Blocks.dirt);
		world.setBlock(i + 2, j + 5, k + 0, Blocks.dirt);
		world.setBlock(i + 2, j + 5, k + 1, Blocks.dirt);
		world.setBlock(i + 2, j + 5, k + 2, Blocks.dirt);
		world.setBlock(i + 2, j + 5, k + 3, Blocks.dirt);
		world.setBlock(i + 2, j + 5, k + 4, Blocks.dirt);
		world.setBlock(i + 2, j + 5, k + 5, Blocks.dirt);
		world.setBlock(i + 2, j + 5, k + 6, Blocks.dirt);
		world.setBlock(i + 2, j + 5, k + 7, Blocks.dirt);
		world.setBlock(i + 2, j + 5, k + 8, Blocks.dirt);
		world.setBlock(i + 2, j + 5, k + 9, Blocks.nether_brick);
		world.setBlock(i + 2, j + 5, k + 10, Blocks.sandstone, 2, 0x02);
		world.setBlock(i + 2, j + 5, k + 11, Blocks.nether_brick);
		world.setBlock(i + 2, j + 5, k + 12, Blocks.grass);
		world.setBlock(i + 2, j + 5, k + 13, Blocks.grass);
		world.setBlock(i + 2, j + 5, k + 14, Blocks.grass);
		world.setBlock(i + 2, j + 5, k + 15, Blocks.dirt);
		world.setBlock(i + 2, j + 5, k + 16, Blocks.grass);
		world.setBlock(i + 2, j + 5, k + 17, Blocks.grass);
		world.setBlock(i + 2, j + 5, k + 18, Blocks.dirt);
		world.setBlock(i + 2, j + 5, k + 19, Blocks.grass);
		world.setBlock(i + 2, j + 5, k + 20, Blocks.grass);
		world.setBlock(i + 2, j + 6, k + 0, Blocks.birch_stairs, 2, 0x02);
		world.setBlock(i + 2, j + 6, k + 1, Blocks.planks, 2, 0x02);
		world.setBlock(i + 2, j + 6, k + 2, Blocks.planks, 2, 0x02);
		world.setBlock(i + 2, j + 6, k + 3, Blocks.planks, 2, 0x02);
		world.setBlock(i + 2, j + 6, k + 4, Blocks.planks, 2, 0x02);
		world.setBlock(i + 2, j + 6, k + 5, Blocks.planks, 2, 0x02);
		world.setBlock(i + 2, j + 6, k + 6, Blocks.planks, 2, 0x02);
		world.setBlock(i + 2, j + 6, k + 7, Blocks.planks, 2, 0x02);
		world.setBlock(i + 2, j + 6, k + 8, Blocks.birch_stairs, 3, 0x02);
		world.setBlock(i + 2, j + 6, k + 12, Blocks.cobblestone_wall, 1, 0x02);
		world.setBlock(i + 2, j + 6, k + 15, Blocks.log, 2, 0x02);
		world.setBlock(i + 2, j + 6, k + 18, Blocks.log);
		world.setBlock(i + 2, j + 6, k + 20, Blocks.cobblestone_wall, 1, 0x02);
		world.setBlock(i + 2, j + 7, k + 1, Blocks.cobblestone);
		world.setBlock(i + 2, j + 7, k + 4, Blocks.furnace, 5, 0x02);
		world.setBlock(i + 2, j + 7, k + 5, Blocks.furnace, 5, 0x02);
		world.setBlock(i + 2, j + 7, k + 6, Blocks.crafting_table);
		world.setBlock(i + 2, j + 7, k + 7, Blocks.cobblestone);
		world.setBlock(i + 2, j + 7, k + 15, Blocks.log, 2, 0x02);
		world.setBlock(i + 2, j + 7, k + 18, Blocks.log);
		world.setBlock(i + 2, j + 8, k + 1, Blocks.cobblestone);
		world.setBlock(i + 2, j + 8, k + 7, Blocks.cobblestone);
		world.setBlock(i + 2, j + 8, k + 13, Blocks.leaves, 2, 0x02);
		world.setBlock(i + 2, j + 8, k + 14, Blocks.leaves, 2, 0x02);
		world.setBlock(i + 2, j + 8, k + 15, Blocks.log, 2, 0x02);
		world.setBlock(i + 2, j + 8, k + 16, Blocks.leaves, 2, 0x02);
		world.setBlock(i + 2, j + 8, k + 17, Blocks.leaves, 2, 0x02);
		world.setBlock(i + 2, j + 8, k + 18, Blocks.log);
		world.setBlock(i + 2, j + 8, k + 19, Blocks.leaves);
		world.setBlock(i + 2, j + 8, k + 20, Blocks.leaves);
		world.setBlock(i + 2, j + 9, k + 1, Blocks.cobblestone);
		world.setBlock(i + 2, j + 9, k + 7, Blocks.cobblestone);
		world.setBlock(i + 2, j + 9, k + 12, Blocks.leaves);
		world.setBlock(i + 2, j + 9, k + 13, Blocks.leaves, 2, 0x02);
		world.setBlock(i + 2, j + 9, k + 14, Blocks.leaves, 2, 0x02);
		world.setBlock(i + 2, j + 9, k + 15, Blocks.log, 2, 0x02);
		world.setBlock(i + 2, j + 9, k + 16, Blocks.leaves, 2, 0x02);
		world.setBlock(i + 2, j + 9, k + 17, Blocks.leaves, 2, 0x02);
		world.setBlock(i + 2, j + 9, k + 18, Blocks.log);
		world.setBlock(i + 2, j + 9, k + 19, Blocks.leaves);
		world.setBlock(i + 2, j + 9, k + 20, Blocks.leaves);
		world.setBlock(i + 2, j + 10, k + 1, Blocks.cobblestone);
		world.setBlock(i + 2, j + 10, k + 7, Blocks.cobblestone);
		world.setBlock(i + 2, j + 10, k + 11, Blocks.leaves);
		world.setBlock(i + 2, j + 10, k + 12, Blocks.leaves);
		world.setBlock(i + 2, j + 10, k + 13, Blocks.leaves);
		world.setBlock(i + 2, j + 10, k + 14, Blocks.leaves, 2, 0x02);
		world.setBlock(i + 2, j + 10, k + 15, Blocks.log, 2, 0x02);
		world.setBlock(i + 2, j + 10, k + 16, Blocks.leaves, 2, 0x02);
		world.setBlock(i + 2, j + 10, k + 17, Blocks.leaves);
		world.setBlock(i + 2, j + 10, k + 18, Blocks.log);
		world.setBlock(i + 2, j + 10, k + 19, Blocks.leaves);
		world.setBlock(i + 2, j + 11, k + 0, Blocks.birch_stairs, 2, 0x02);
		world.setBlock(i + 2, j + 11, k + 1, Blocks.log, 9, 0x02);
		world.setBlock(i + 2, j + 11, k + 3, Blocks.planks, 2, 0x02);
		world.setBlock(i + 2, j + 11, k + 4, Blocks.planks, 2, 0x02);
		world.setBlock(i + 2, j + 11, k + 5, Blocks.planks, 2, 0x02);
		world.setBlock(i + 2, j + 11, k + 6, Blocks.planks, 2, 0x02);
		world.setBlock(i + 2, j + 11, k + 7, Blocks.log, 9, 0x02);
		world.setBlock(i + 2, j + 11, k + 8, Blocks.birch_stairs, 3, 0x02);
		world.setBlock(i + 2, j + 11, k + 14, Blocks.leaves, 2, 0x02);
		world.setBlock(i + 2, j + 11, k + 15, Blocks.leaves, 2, 0x02);
		world.setBlock(i + 2, j + 11, k + 16, Blocks.leaves, 2, 0x02);
		world.setBlock(i + 2, j + 11, k + 17, Blocks.leaves);
		world.setBlock(i + 2, j + 11, k + 18, Blocks.leaves);
		world.setBlock(i + 2, j + 11, k + 19, Blocks.leaves);
		world.setBlock(i + 2, j + 12, k + 1, Blocks.cobblestone);
		world.setBlock(i + 2, j + 12, k + 4, Blocks.bed, 10, 0x02);
		world.setBlock(i + 2, j + 12, k + 5, Blocks.bed, 2, 0x02);
		world.setBlock(i + 2, j + 12, k + 7, Blocks.fence);
		world.setBlock(i + 2, j + 13, k + 1, Blocks.cobblestone);
		world.setBlock(i + 2, j + 14, k + 1, Blocks.cobblestone);
		world.setBlock(i + 2, j + 15, k + 1, Blocks.cobblestone);
		world.setBlock(i + 2, j + 15, k + 5, Blocks.spruce_stairs, 5, 0x02);
		world.setBlock(i + 2, j + 16, k + 1, Blocks.log, 9, 0x02);
		world.setBlock(i + 2, j + 16, k + 5, Blocks.log, 9, 0x02);
		world.setBlock(i + 2, j + 17, k + 0, Blocks.wooden_slab, 1, 0x02);
		world.setBlock(i + 2, j + 17, k + 1, Blocks.planks, 2, 0x02);
		world.setBlock(i + 2, j + 17, k + 5, Blocks.planks, 2, 0x02);
		world.setBlock(i + 2, j + 17, k + 6, Blocks.wooden_slab, 1, 0x02);
		world.setBlock(i + 2, j + 18, k + 2, Blocks.spruce_stairs, 2, 0x02);
		world.setBlock(i + 2, j + 18, k + 3, Blocks.spruce_stairs);
		world.setBlock(i + 2, j + 18, k + 4, Blocks.spruce_stairs);
		world.setBlock(i + 3, j + 0, k + 0, Blocks.dirt);
		world.setBlock(i + 3, j + 0, k + 1, Blocks.dirt);
		world.setBlock(i + 3, j + 0, k + 2, Blocks.dirt);
		world.setBlock(i + 3, j + 0, k + 3, Blocks.dirt);
		world.setBlock(i + 3, j + 0, k + 4, Blocks.dirt);
		world.setBlock(i + 3, j + 0, k + 5, Blocks.dirt);
		world.setBlock(i + 3, j + 0, k + 6, Blocks.dirt);
		world.setBlock(i + 3, j + 0, k + 7, Blocks.dirt);
		world.setBlock(i + 3, j + 0, k + 8, Blocks.dirt);
		world.setBlock(i + 3, j + 0, k + 9, Blocks.dirt);
		world.setBlock(i + 3, j + 0, k + 10, Blocks.dirt);
		world.setBlock(i + 3, j + 0, k + 11, Blocks.dirt);
		world.setBlock(i + 3, j + 0, k + 12, Blocks.dirt);
		world.setBlock(i + 3, j + 0, k + 13, Blocks.dirt);
		world.setBlock(i + 3, j + 0, k + 14, Blocks.dirt);
		world.setBlock(i + 3, j + 0, k + 15, Blocks.dirt);
		world.setBlock(i + 3, j + 0, k + 16, Blocks.dirt);
		world.setBlock(i + 3, j + 0, k + 17, Blocks.dirt);
		world.setBlock(i + 3, j + 0, k + 18, Blocks.dirt);
		world.setBlock(i + 3, j + 0, k + 19, Blocks.dirt);
		world.setBlock(i + 3, j + 0, k + 20, Blocks.dirt);
		world.setBlock(i + 3, j + 1, k + 0, Blocks.dirt);
		world.setBlock(i + 3, j + 1, k + 1, Blocks.dirt);
		world.setBlock(i + 3, j + 1, k + 2, Blocks.dirt);
		world.setBlock(i + 3, j + 1, k + 3, Blocks.dirt);
		world.setBlock(i + 3, j + 1, k + 4, Blocks.dirt);
		world.setBlock(i + 3, j + 1, k + 5, Blocks.dirt);
		world.setBlock(i + 3, j + 1, k + 6, Blocks.dirt);
		world.setBlock(i + 3, j + 1, k + 7, Blocks.dirt);
		world.setBlock(i + 3, j + 1, k + 8, Blocks.dirt);
		world.setBlock(i + 3, j + 1, k + 9, Blocks.dirt);
		world.setBlock(i + 3, j + 1, k + 10, Blocks.dirt);
		world.setBlock(i + 3, j + 1, k + 11, Blocks.dirt);
		world.setBlock(i + 3, j + 1, k + 12, Blocks.dirt);
		world.setBlock(i + 3, j + 1, k + 13, Blocks.dirt);
		world.setBlock(i + 3, j + 1, k + 14, Blocks.dirt);
		world.setBlock(i + 3, j + 1, k + 15, Blocks.dirt);
		world.setBlock(i + 3, j + 1, k + 16, Blocks.dirt);
		world.setBlock(i + 3, j + 1, k + 17, Blocks.dirt);
		world.setBlock(i + 3, j + 1, k + 18, Blocks.dirt);
		world.setBlock(i + 3, j + 1, k + 19, Blocks.dirt);
		world.setBlock(i + 3, j + 1, k + 20, Blocks.dirt);
		world.setBlock(i + 3, j + 2, k + 0, Blocks.grass);
		world.setBlock(i + 3, j + 2, k + 1, Blocks.grass);
		world.setBlock(i + 3, j + 2, k + 2, Blocks.grass);
		world.setBlock(i + 3, j + 2, k + 3, Blocks.grass);
		world.setBlock(i + 3, j + 2, k + 4, Blocks.grass);
		world.setBlock(i + 3, j + 2, k + 5, Blocks.grass);
		world.setBlock(i + 3, j + 2, k + 6, Blocks.grass);
		world.setBlock(i + 3, j + 2, k + 7, Blocks.grass);
		world.setBlock(i + 3, j + 2, k + 8, Blocks.grass);
		world.setBlock(i + 3, j + 2, k + 9, Blocks.grass);
		world.setBlock(i + 3, j + 2, k + 10, Blocks.grass);
		world.setBlock(i + 3, j + 2, k + 11, Blocks.grass);
		world.setBlock(i + 3, j + 2, k + 12, Blocks.dirt);
		world.setBlock(i + 3, j + 2, k + 13, Blocks.dirt);
		world.setBlock(i + 3, j + 2, k + 14, Blocks.dirt);
		world.setBlock(i + 3, j + 2, k + 15, Blocks.dirt);
		world.setBlock(i + 3, j + 2, k + 16, Blocks.dirt);
		world.setBlock(i + 3, j + 2, k + 17, Blocks.dirt);
		world.setBlock(i + 3, j + 2, k + 18, Blocks.dirt);
		world.setBlock(i + 3, j + 2, k + 19, Blocks.dirt);
		world.setBlock(i + 3, j + 2, k + 20, Blocks.dirt);
		world.setBlock(i + 3, j + 3, k + 0, Blocks.dirt);
		world.setBlock(i + 3, j + 3, k + 1, Blocks.dirt);
		world.setBlock(i + 3, j + 3, k + 2, Blocks.dirt);
		world.setBlock(i + 3, j + 3, k + 3, Blocks.dirt);
		world.setBlock(i + 3, j + 3, k + 4, Blocks.dirt);
		world.setBlock(i + 3, j + 3, k + 5, Blocks.dirt);
		world.setBlock(i + 3, j + 3, k + 6, Blocks.dirt);
		world.setBlock(i + 3, j + 3, k + 7, Blocks.dirt);
		world.setBlock(i + 3, j + 3, k + 8, Blocks.dirt);
		world.setBlock(i + 3, j + 3, k + 9, Blocks.dirt);
		world.setBlock(i + 3, j + 3, k + 10, Blocks.dirt);
		world.setBlock(i + 3, j + 3, k + 11, Blocks.dirt);
		world.setBlock(i + 3, j + 3, k + 12, Blocks.dirt);
		world.setBlock(i + 3, j + 3, k + 13, Blocks.dirt);
		world.setBlock(i + 3, j + 3, k + 14, Blocks.dirt);
		world.setBlock(i + 3, j + 3, k + 15, Blocks.dirt);
		world.setBlock(i + 3, j + 3, k + 16, Blocks.dirt);
		world.setBlock(i + 3, j + 3, k + 17, Blocks.dirt);
		world.setBlock(i + 3, j + 3, k + 18, Blocks.dirt);
		world.setBlock(i + 3, j + 3, k + 19, Blocks.dirt);
		world.setBlock(i + 3, j + 3, k + 20, Blocks.dirt);
		world.setBlock(i + 3, j + 4, k + 0, Blocks.dirt);
		world.setBlock(i + 3, j + 4, k + 1, Blocks.dirt);
		world.setBlock(i + 3, j + 4, k + 2, Blocks.dirt);
		world.setBlock(i + 3, j + 4, k + 3, Blocks.dirt);
		world.setBlock(i + 3, j + 4, k + 4, Blocks.dirt);
		world.setBlock(i + 3, j + 4, k + 5, Blocks.dirt);
		world.setBlock(i + 3, j + 4, k + 6, Blocks.dirt);
		world.setBlock(i + 3, j + 4, k + 7, Blocks.dirt);
		world.setBlock(i + 3, j + 4, k + 8, Blocks.dirt);
		world.setBlock(i + 3, j + 4, k + 9, Blocks.dirt);
		world.setBlock(i + 3, j + 4, k + 10, Blocks.dirt);
		world.setBlock(i + 3, j + 4, k + 11, Blocks.dirt);
		world.setBlock(i + 3, j + 4, k + 12, Blocks.dirt);
		world.setBlock(i + 3, j + 4, k + 13, Blocks.dirt);
		world.setBlock(i + 3, j + 4, k + 14, Blocks.dirt);
		world.setBlock(i + 3, j + 4, k + 15, Blocks.dirt);
		world.setBlock(i + 3, j + 4, k + 16, Blocks.dirt);
		world.setBlock(i + 3, j + 4, k + 17, Blocks.dirt);
		world.setBlock(i + 3, j + 4, k + 18, Blocks.dirt);
		world.setBlock(i + 3, j + 4, k + 19, Blocks.dirt);
		world.setBlock(i + 3, j + 4, k + 20, Blocks.dirt);
		world.setBlock(i + 3, j + 5, k + 0, Blocks.dirt);
		world.setBlock(i + 3, j + 5, k + 1, Blocks.dirt);
		world.setBlock(i + 3, j + 5, k + 2, Blocks.dirt);
		world.setBlock(i + 3, j + 5, k + 3, Blocks.dirt);
		world.setBlock(i + 3, j + 5, k + 4, Blocks.dirt);
		world.setBlock(i + 3, j + 5, k + 5, Blocks.dirt);
		world.setBlock(i + 3, j + 5, k + 6, Blocks.dirt);
		world.setBlock(i + 3, j + 5, k + 7, Blocks.dirt);
		world.setBlock(i + 3, j + 5, k + 8, Blocks.dirt);
		world.setBlock(i + 3, j + 5, k + 9, Blocks.nether_brick);
		world.setBlock(i + 3, j + 5, k + 10, Blocks.sandstone, 2, 0x02);
		world.setBlock(i + 3, j + 5, k + 11, Blocks.nether_brick);
		world.setBlock(i + 3, j + 5, k + 12, Blocks.grass);
		world.setBlock(i + 3, j + 5, k + 13, Blocks.grass);
		world.setBlock(i + 3, j + 5, k + 14, Blocks.grass);
		world.setBlock(i + 3, j + 5, k + 15, Blocks.grass);
		world.setBlock(i + 3, j + 5, k + 16, Blocks.grass);
		world.setBlock(i + 3, j + 5, k + 17, Blocks.grass);
		world.setBlock(i + 3, j + 5, k + 18, Blocks.grass);
		world.setBlock(i + 3, j + 5, k + 19, Blocks.grass);
		world.setBlock(i + 3, j + 5, k + 20, Blocks.grass);
		world.setBlock(i + 3, j + 6, k + 0, Blocks.birch_stairs, 2, 0x02);
		world.setBlock(i + 3, j + 6, k + 1, Blocks.planks, 2, 0x02);
		world.setBlock(i + 3, j + 6, k + 2, Blocks.planks, 2, 0x02);
		world.setBlock(i + 3, j + 6, k + 3, Blocks.planks, 2, 0x02);
		world.setBlock(i + 3, j + 6, k + 4, Blocks.planks, 2, 0x02);
		world.setBlock(i + 3, j + 6, k + 5, Blocks.planks, 2, 0x02);
		world.setBlock(i + 3, j + 6, k + 6, Blocks.planks, 2, 0x02);
		world.setBlock(i + 3, j + 6, k + 7, Blocks.planks, 2, 0x02);
		world.setBlock(i + 3, j + 6, k + 8, Blocks.birch_stairs, 3, 0x02);
		world.setBlock(i + 3, j + 6, k + 12, Blocks.cobblestone_wall, 1, 0x02);
		world.setBlock(i + 3, j + 6, k + 20, Blocks.cobblestone_wall, 1, 0x02);
		world.setBlock(i + 3, j + 7, k + 1, Blocks.cobblestone);
		world.setBlock(i + 3, j + 7, k + 7, Blocks.cobblestone);
		world.setBlock(i + 3, j + 8, k + 1, Blocks.glass_pane);
		world.setBlock(i + 3, j + 8, k + 7, Blocks.glass_pane);
		world.setBlock(i + 3, j + 8, k + 13, Blocks.leaves, 2, 0x02);
		world.setBlock(i + 3, j + 8, k + 14, Blocks.leaves, 2, 0x02);
		world.setBlock(i + 3, j + 8, k + 15, Blocks.leaves, 2, 0x02);
		world.setBlock(i + 3, j + 8, k + 16, Blocks.leaves, 2, 0x02);
		world.setBlock(i + 3, j + 8, k + 17, Blocks.leaves, 2, 0x02);
		world.setBlock(i + 3, j + 8, k + 18, Blocks.leaves);
		world.setBlock(i + 3, j + 8, k + 19, Blocks.leaves);
		world.setBlock(i + 3, j + 8, k + 20, Blocks.leaves);
		world.setBlock(i + 3, j + 9, k + 1, Blocks.glass_pane);
		world.setBlock(i + 3, j + 9, k + 7, Blocks.glass_pane);
		world.setBlock(i + 3, j + 9, k + 11, Blocks.leaves);
		world.setBlock(i + 3, j + 9, k + 12, Blocks.leaves);
		world.setBlock(i + 3, j + 9, k + 13, Blocks.leaves, 2, 0x02);
		world.setBlock(i + 3, j + 9, k + 14, Blocks.leaves, 2, 0x02);
		world.setBlock(i + 3, j + 9, k + 15, Blocks.leaves, 2, 0x02);
		world.setBlock(i + 3, j + 9, k + 16, Blocks.leaves, 2, 0x02);
		world.setBlock(i + 3, j + 9, k + 17, Blocks.leaves, 2, 0x02);
		world.setBlock(i + 3, j + 9, k + 18, Blocks.leaves);
		world.setBlock(i + 3, j + 9, k + 19, Blocks.leaves);
		world.setBlock(i + 3, j + 9, k + 20, Blocks.leaves);
		world.setBlock(i + 3, j + 10, k + 1, Blocks.cobblestone);
		world.setBlock(i + 3, j + 10, k + 7, Blocks.cobblestone);
		world.setBlock(i + 3, j + 10, k + 11, Blocks.leaves);
		world.setBlock(i + 3, j + 10, k + 12, Blocks.leaves);
		world.setBlock(i + 3, j + 10, k + 13, Blocks.leaves);
		world.setBlock(i + 3, j + 10, k + 14, Blocks.leaves, 2, 0x02);
		world.setBlock(i + 3, j + 10, k + 15, Blocks.leaves, 2, 0x02);
		world.setBlock(i + 3, j + 10, k + 16, Blocks.leaves, 2, 0x02);
		world.setBlock(i + 3, j + 10, k + 17, Blocks.leaves);
		world.setBlock(i + 3, j + 10, k + 18, Blocks.leaves);
		world.setBlock(i + 3, j + 11, k + 0, Blocks.birch_stairs, 2, 0x02);
		world.setBlock(i + 3, j + 11, k + 1, Blocks.log, 9, 0x02);
		world.setBlock(i + 3, j + 11, k + 2, Blocks.planks, 2, 0x02);
		world.setBlock(i + 3, j + 11, k + 3, Blocks.planks, 2, 0x02);
		world.setBlock(i + 3, j + 11, k + 4, Blocks.planks, 2, 0x02);
		world.setBlock(i + 3, j + 11, k + 5, Blocks.planks, 2, 0x02);
		world.setBlock(i + 3, j + 11, k + 6, Blocks.planks, 2, 0x02);
		world.setBlock(i + 3, j + 11, k + 7, Blocks.log, 9, 0x02);
		world.setBlock(i + 3, j + 11, k + 8, Blocks.birch_stairs, 3, 0x02);
		world.setBlock(i + 3, j + 11, k + 13, Blocks.leaves);
		world.setBlock(i + 3, j + 11, k + 15, Blocks.leaves, 2, 0x02);
		world.setBlock(i + 3, j + 11, k + 18, Blocks.leaves);
		world.setBlock(i + 3, j + 12, k + 1, Blocks.cobblestone);
		world.setBlock(i + 3, j + 12, k + 7, Blocks.fence);
		world.setBlock(i + 3, j + 12, k + 13, Blocks.leaves);
		world.setBlock(i + 3, j + 13, k + 1, Blocks.glass_pane);
		world.setBlock(i + 3, j + 14, k + 1, Blocks.glass_pane);
		world.setBlock(i + 3, j + 15, k + 1, Blocks.cobblestone);
		world.setBlock(i + 3, j + 15, k + 5, Blocks.wooden_slab, 9, 0x02);
		world.setBlock(i + 3, j + 16, k + 1, Blocks.log, 9, 0x02);
		world.setBlock(i + 3, j + 16, k + 5, Blocks.log, 9, 0x02);
		world.setBlock(i + 3, j + 17, k + 0, Blocks.wooden_slab, 1, 0x02);
		world.setBlock(i + 3, j + 17, k + 1, Blocks.planks, 2, 0x02);
		world.setBlock(i + 3, j + 17, k + 5, Blocks.planks, 2, 0x02);
		world.setBlock(i + 3, j + 17, k + 6, Blocks.wooden_slab, 1, 0x02);
		world.setBlock(i + 3, j + 18, k + 2, Blocks.spruce_stairs, 2, 0x02);
		world.setBlock(i + 3, j + 18, k + 3, Blocks.planks, 2, 0x02);
		world.setBlock(i + 3, j + 18, k + 4, Blocks.spruce_stairs, 3, 0x02);
		world.setBlock(i + 3, j + 19, k + 3, Blocks.fence);
		world.setBlock(i + 3, j + 20, k + 3, Blocks.fence);
		world.setBlock(i + 3, j + 21, k + 3, mod_Avatar.AirNomadsBlock);
		world.setBlock(i + 4, j + 0, k + 0, Blocks.dirt);
		world.setBlock(i + 4, j + 0, k + 1, Blocks.dirt);
		world.setBlock(i + 4, j + 0, k + 2, Blocks.dirt);
		world.setBlock(i + 4, j + 0, k + 3, Blocks.dirt);
		world.setBlock(i + 4, j + 0, k + 4, Blocks.dirt);
		world.setBlock(i + 4, j + 0, k + 5, Blocks.dirt);
		world.setBlock(i + 4, j + 0, k + 6, Blocks.dirt);
		world.setBlock(i + 4, j + 0, k + 7, Blocks.dirt);
		world.setBlock(i + 4, j + 0, k + 8, Blocks.dirt);
		world.setBlock(i + 4, j + 0, k + 9, Blocks.dirt);
		world.setBlock(i + 4, j + 0, k + 10, Blocks.dirt);
		world.setBlock(i + 4, j + 0, k + 11, Blocks.dirt);
		world.setBlock(i + 4, j + 0, k + 12, Blocks.dirt);
		world.setBlock(i + 4, j + 0, k + 13, Blocks.dirt);
		world.setBlock(i + 4, j + 0, k + 14, Blocks.dirt);
		world.setBlock(i + 4, j + 0, k + 15, Blocks.dirt);
		world.setBlock(i + 4, j + 0, k + 16, Blocks.dirt);
		world.setBlock(i + 4, j + 0, k + 17, Blocks.dirt);
		world.setBlock(i + 4, j + 0, k + 18, Blocks.dirt);
		world.setBlock(i + 4, j + 0, k + 19, Blocks.dirt);
		world.setBlock(i + 4, j + 0, k + 20, Blocks.dirt);
		world.setBlock(i + 4, j + 1, k + 0, Blocks.dirt);
		world.setBlock(i + 4, j + 1, k + 1, Blocks.dirt);
		world.setBlock(i + 4, j + 1, k + 2, Blocks.dirt);
		world.setBlock(i + 4, j + 1, k + 3, Blocks.dirt);
		world.setBlock(i + 4, j + 1, k + 4, Blocks.dirt);
		world.setBlock(i + 4, j + 1, k + 5, Blocks.dirt);
		world.setBlock(i + 4, j + 1, k + 6, Blocks.dirt);
		world.setBlock(i + 4, j + 1, k + 7, Blocks.dirt);
		world.setBlock(i + 4, j + 1, k + 8, Blocks.dirt);
		world.setBlock(i + 4, j + 1, k + 9, Blocks.dirt);
		world.setBlock(i + 4, j + 1, k + 10, Blocks.dirt);
		world.setBlock(i + 4, j + 1, k + 11, Blocks.dirt);
		world.setBlock(i + 4, j + 1, k + 12, Blocks.dirt);
		world.setBlock(i + 4, j + 1, k + 13, Blocks.dirt);
		world.setBlock(i + 4, j + 1, k + 14, Blocks.dirt);
		world.setBlock(i + 4, j + 1, k + 15, Blocks.dirt);
		world.setBlock(i + 4, j + 1, k + 16, Blocks.dirt);
		world.setBlock(i + 4, j + 1, k + 17, Blocks.dirt);
		world.setBlock(i + 4, j + 1, k + 18, Blocks.dirt);
		world.setBlock(i + 4, j + 1, k + 19, Blocks.dirt);
		world.setBlock(i + 4, j + 1, k + 20, Blocks.dirt);
		world.setBlock(i + 4, j + 2, k + 0, Blocks.grass);
		world.setBlock(i + 4, j + 2, k + 1, Blocks.grass);
		world.setBlock(i + 4, j + 2, k + 2, Blocks.grass);
		world.setBlock(i + 4, j + 2, k + 3, Blocks.grass);
		world.setBlock(i + 4, j + 2, k + 4, Blocks.grass);
		world.setBlock(i + 4, j + 2, k + 5, Blocks.grass);
		world.setBlock(i + 4, j + 2, k + 6, Blocks.grass);
		world.setBlock(i + 4, j + 2, k + 7, Blocks.grass);
		world.setBlock(i + 4, j + 2, k + 8, Blocks.grass);
		world.setBlock(i + 4, j + 2, k + 9, Blocks.grass);
		world.setBlock(i + 4, j + 2, k + 10, Blocks.grass);
		world.setBlock(i + 4, j + 2, k + 11, Blocks.grass);
		world.setBlock(i + 4, j + 2, k + 12, Blocks.dirt);
		world.setBlock(i + 4, j + 2, k + 13, Blocks.dirt);
		world.setBlock(i + 4, j + 2, k + 14, Blocks.dirt);
		world.setBlock(i + 4, j + 2, k + 15, Blocks.dirt);
		world.setBlock(i + 4, j + 2, k + 16, Blocks.dirt);
		world.setBlock(i + 4, j + 2, k + 17, Blocks.dirt);
		world.setBlock(i + 4, j + 2, k + 18, Blocks.dirt);
		world.setBlock(i + 4, j + 2, k + 19, Blocks.dirt);
		world.setBlock(i + 4, j + 2, k + 20, Blocks.dirt);
		world.setBlock(i + 4, j + 3, k + 0, Blocks.dirt);
		world.setBlock(i + 4, j + 3, k + 1, Blocks.dirt);
		world.setBlock(i + 4, j + 3, k + 2, Blocks.dirt);
		world.setBlock(i + 4, j + 3, k + 3, Blocks.dirt);
		world.setBlock(i + 4, j + 3, k + 4, Blocks.dirt);
		world.setBlock(i + 4, j + 3, k + 5, Blocks.dirt);
		world.setBlock(i + 4, j + 3, k + 6, Blocks.dirt);
		world.setBlock(i + 4, j + 3, k + 7, Blocks.dirt);
		world.setBlock(i + 4, j + 3, k + 8, Blocks.dirt);
		world.setBlock(i + 4, j + 3, k + 9, Blocks.dirt);
		world.setBlock(i + 4, j + 3, k + 10, Blocks.dirt);
		world.setBlock(i + 4, j + 3, k + 11, Blocks.dirt);
		world.setBlock(i + 4, j + 3, k + 12, Blocks.dirt);
		world.setBlock(i + 4, j + 3, k + 13, Blocks.dirt);
		world.setBlock(i + 4, j + 3, k + 14, Blocks.dirt);
		world.setBlock(i + 4, j + 3, k + 15, Blocks.dirt);
		world.setBlock(i + 4, j + 3, k + 16, Blocks.dirt);
		world.setBlock(i + 4, j + 3, k + 17, Blocks.dirt);
		world.setBlock(i + 4, j + 3, k + 18, Blocks.dirt);
		world.setBlock(i + 4, j + 3, k + 19, Blocks.dirt);
		world.setBlock(i + 4, j + 3, k + 20, Blocks.dirt);
		world.setBlock(i + 4, j + 4, k + 0, Blocks.dirt);
		world.setBlock(i + 4, j + 4, k + 1, Blocks.dirt);
		world.setBlock(i + 4, j + 4, k + 2, Blocks.dirt);
		world.setBlock(i + 4, j + 4, k + 3, Blocks.dirt);
		world.setBlock(i + 4, j + 4, k + 4, Blocks.dirt);
		world.setBlock(i + 4, j + 4, k + 5, Blocks.dirt);
		world.setBlock(i + 4, j + 4, k + 6, Blocks.dirt);
		world.setBlock(i + 4, j + 4, k + 7, Blocks.dirt);
		world.setBlock(i + 4, j + 4, k + 8, Blocks.dirt);
		world.setBlock(i + 4, j + 4, k + 9, Blocks.dirt);
		world.setBlock(i + 4, j + 4, k + 10, Blocks.dirt);
		world.setBlock(i + 4, j + 4, k + 11, Blocks.dirt);
		world.setBlock(i + 4, j + 4, k + 12, Blocks.dirt);
		world.setBlock(i + 4, j + 4, k + 13, Blocks.dirt);
		world.setBlock(i + 4, j + 4, k + 14, Blocks.dirt);
		world.setBlock(i + 4, j + 4, k + 15, Blocks.dirt);
		world.setBlock(i + 4, j + 4, k + 16, Blocks.dirt);
		world.setBlock(i + 4, j + 4, k + 17, Blocks.dirt);
		world.setBlock(i + 4, j + 4, k + 18, Blocks.dirt);
		world.setBlock(i + 4, j + 4, k + 19, Blocks.dirt);
		world.setBlock(i + 4, j + 4, k + 20, Blocks.dirt);
		world.setBlock(i + 4, j + 5, k + 0, Blocks.dirt);
		world.setBlock(i + 4, j + 5, k + 1, Blocks.dirt);
		world.setBlock(i + 4, j + 5, k + 2, Blocks.dirt);
		world.setBlock(i + 4, j + 5, k + 3, Blocks.dirt);
		world.setBlock(i + 4, j + 5, k + 4, Blocks.dirt);
		world.setBlock(i + 4, j + 5, k + 5, Blocks.dirt);
		world.setBlock(i + 4, j + 5, k + 6, Blocks.dirt);
		world.setBlock(i + 4, j + 5, k + 7, Blocks.dirt);
		world.setBlock(i + 4, j + 5, k + 8, Blocks.dirt);
		world.setBlock(i + 4, j + 5, k + 9, Blocks.nether_brick);
		world.setBlock(i + 4, j + 5, k + 10, Blocks.sandstone, 2, 0x02);
		world.setBlock(i + 4, j + 5, k + 11, Blocks.nether_brick);
		world.setBlock(i + 4, j + 5, k + 12, Blocks.grass);
		world.setBlock(i + 4, j + 5, k + 13, Blocks.dirt);
		world.setBlock(i + 4, j + 5, k + 14, Blocks.grass);
		world.setBlock(i + 4, j + 5, k + 18, Blocks.grass);
		world.setBlock(i + 4, j + 5, k + 19, Blocks.grass);
		world.setBlock(i + 4, j + 5, k + 20, Blocks.grass);
		world.setBlock(i + 4, j + 6, k + 0, Blocks.birch_stairs, 2, 0x02);
		world.setBlock(i + 4, j + 6, k + 1, Blocks.planks, 2, 0x02);
		world.setBlock(i + 4, j + 6, k + 2, Blocks.planks, 2, 0x02);
		world.setBlock(i + 4, j + 6, k + 3, Blocks.planks, 2, 0x02);
		world.setBlock(i + 4, j + 6, k + 4, Blocks.planks, 2, 0x02);
		world.setBlock(i + 4, j + 6, k + 5, Blocks.planks, 2, 0x02);
		world.setBlock(i + 4, j + 6, k + 6, Blocks.planks, 2, 0x02);
		world.setBlock(i + 4, j + 6, k + 7, Blocks.planks, 2, 0x02);
		world.setBlock(i + 4, j + 6, k + 8, Blocks.birch_stairs, 3, 0x02);
		world.setBlock(i + 4, j + 6, k + 12, Blocks.cobblestone_wall, 1, 0x02);
		world.setBlock(i + 4, j + 6, k + 13, Blocks.log);
		world.setBlock(i + 4, j + 6, k + 20, Blocks.cobblestone_wall, 1, 0x02);
		world.setBlock(i + 4, j + 7, k + 1, Blocks.cobblestone);
		world.setBlock(i + 4, j + 7, k + 7, Blocks.cobblestone);
		world.setBlock(i + 4, j + 7, k + 13, Blocks.log);
		world.setBlock(i + 4, j + 8, k + 1, Blocks.glass_pane);
		world.setBlock(i + 4, j + 8, k + 7, Blocks.cobblestone);
		world.setBlock(i + 4, j + 8, k + 13, Blocks.log);
		world.setBlock(i + 4, j + 8, k + 14, Blocks.leaves, 2, 0x02);
		world.setBlock(i + 4, j + 8, k + 15, Blocks.leaves, 2, 0x02);
		world.setBlock(i + 4, j + 8, k + 16, Blocks.leaves, 2, 0x02);
		world.setBlock(i + 4, j + 8, k + 17, Blocks.leaves);
		world.setBlock(i + 4, j + 8, k + 18, Blocks.leaves);
		world.setBlock(i + 4, j + 8, k + 19, Blocks.leaves);
		world.setBlock(i + 4, j + 9, k + 1, Blocks.glass_pane);
		world.setBlock(i + 4, j + 9, k + 7, Blocks.cobblestone);
		world.setBlock(i + 4, j + 9, k + 11, Blocks.leaves);
		world.setBlock(i + 4, j + 9, k + 12, Blocks.leaves);
		world.setBlock(i + 4, j + 9, k + 13, Blocks.log);
		world.setBlock(i + 4, j + 9, k + 14, Blocks.leaves, 2, 0x02);
		world.setBlock(i + 4, j + 9, k + 15, Blocks.leaves, 2, 0x02);
		world.setBlock(i + 4, j + 9, k + 16, Blocks.leaves, 2, 0x02);
		world.setBlock(i + 4, j + 9, k + 17, Blocks.leaves, 2, 0x02);
		world.setBlock(i + 4, j + 9, k + 18, Blocks.leaves, 2, 0x02);
		world.setBlock(i + 4, j + 9, k + 19, Blocks.leaves, 2, 0x02);
		world.setBlock(i + 4, j + 9, k + 20, Blocks.leaves, 2, 0x02);
		world.setBlock(i + 4, j + 10, k + 1, Blocks.cobblestone);
		world.setBlock(i + 4, j + 10, k + 7, Blocks.cobblestone);
		world.setBlock(i + 4, j + 10, k + 11, Blocks.leaves);
		world.setBlock(i + 4, j + 10, k + 12, Blocks.leaves);
		world.setBlock(i + 4, j + 10, k + 13, Blocks.log);
		world.setBlock(i + 4, j + 10, k + 14, Blocks.leaves);
		world.setBlock(i + 4, j + 10, k + 15, Blocks.leaves);
		world.setBlock(i + 4, j + 10, k + 17, Blocks.leaves, 2, 0x02);
		world.setBlock(i + 4, j + 10, k + 18, Blocks.leaves, 2, 0x02);
		world.setBlock(i + 4, j + 10, k + 19, Blocks.leaves, 2, 0x02);
		world.setBlock(i + 4, j + 10, k + 20, Blocks.leaves, 2, 0x02);
		world.setBlock(i + 4, j + 11, k + 0, Blocks.birch_stairs, 2, 0x02);
		world.setBlock(i + 4, j + 11, k + 1, Blocks.log, 9, 0x02);
		world.setBlock(i + 4, j + 11, k + 2, Blocks.planks, 2, 0x02);
		world.setBlock(i + 4, j + 11, k + 3, Blocks.planks, 2, 0x02);
		world.setBlock(i + 4, j + 11, k + 4, Blocks.planks, 2, 0x02);
		world.setBlock(i + 4, j + 11, k + 5, Blocks.planks, 2, 0x02);
		world.setBlock(i + 4, j + 11, k + 6, Blocks.planks, 2, 0x02);
		world.setBlock(i + 4, j + 11, k + 7, Blocks.log, 9, 0x02);
		world.setBlock(i + 4, j + 11, k + 8, Blocks.birch_stairs, 3, 0x02);
		world.setBlock(i + 4, j + 11, k + 12, Blocks.leaves);
		world.setBlock(i + 4, j + 11, k + 13, Blocks.log);
		world.setBlock(i + 4, j + 11, k + 14, Blocks.leaves);
		world.setBlock(i + 4, j + 12, k + 1, Blocks.cobblestone);
		world.setBlock(i + 4, j + 12, k + 2, Blocks.bed, 9, 0x02);
		world.setBlock(i + 4, j + 12, k + 7, Blocks.fence);
		world.setBlock(i + 4, j + 12, k + 12, Blocks.leaves);
		world.setBlock(i + 4, j + 12, k + 13, Blocks.leaves);
		world.setBlock(i + 4, j + 12, k + 14, Blocks.leaves);
		world.setBlock(i + 4, j + 13, k + 1, Blocks.cobblestone);
		world.setBlock(i + 4, j + 14, k + 1, Blocks.cobblestone);
		world.setBlock(i + 4, j + 15, k + 1, Blocks.cobblestone);
		world.setBlock(i + 4, j + 15, k + 5, Blocks.spruce_stairs, 4, 0x02);
		world.setBlock(i + 4, j + 16, k + 1, Blocks.log, 9, 0x02);
		world.setBlock(i + 4, j + 16, k + 5, Blocks.log, 9, 0x02);
		world.setBlock(i + 4, j + 17, k + 0, Blocks.wooden_slab, 1, 0x02);
		world.setBlock(i + 4, j + 17, k + 1, Blocks.planks, 2, 0x02);
		world.setBlock(i + 4, j + 17, k + 5, Blocks.planks, 2, 0x02);
		world.setBlock(i + 4, j + 17, k + 6, Blocks.wooden_slab, 1, 0x02);
		world.setBlock(i + 4, j + 18, k + 2, Blocks.spruce_stairs, 2, 0x02);
		world.setBlock(i + 4, j + 18, k + 3, Blocks.spruce_stairs, 1, 0x02);
		world.setBlock(i + 4, j + 18, k + 4, Blocks.spruce_stairs, 1, 0x02);
		world.setBlock(i + 5, j + 0, k + 0, Blocks.dirt);
		world.setBlock(i + 5, j + 0, k + 1, Blocks.dirt);
		world.setBlock(i + 5, j + 0, k + 2, Blocks.dirt);
		world.setBlock(i + 5, j + 0, k + 3, Blocks.dirt);
		world.setBlock(i + 5, j + 0, k + 4, Blocks.dirt);
		world.setBlock(i + 5, j + 0, k + 5, Blocks.dirt);
		world.setBlock(i + 5, j + 0, k + 6, Blocks.dirt);
		world.setBlock(i + 5, j + 0, k + 7, Blocks.dirt);
		world.setBlock(i + 5, j + 0, k + 8, Blocks.dirt);
		world.setBlock(i + 5, j + 0, k + 9, Blocks.dirt);
		world.setBlock(i + 5, j + 0, k + 10, Blocks.dirt);
		world.setBlock(i + 5, j + 0, k + 11, Blocks.dirt);
		world.setBlock(i + 5, j + 0, k + 12, Blocks.dirt);
		world.setBlock(i + 5, j + 0, k + 13, Blocks.dirt);
		world.setBlock(i + 5, j + 0, k + 14, Blocks.dirt);
		world.setBlock(i + 5, j + 0, k + 15, Blocks.dirt);
		world.setBlock(i + 5, j + 0, k + 16, Blocks.dirt);
		world.setBlock(i + 5, j + 0, k + 17, Blocks.dirt);
		world.setBlock(i + 5, j + 0, k + 18, Blocks.dirt);
		world.setBlock(i + 5, j + 0, k + 19, Blocks.dirt);
		world.setBlock(i + 5, j + 0, k + 20, Blocks.dirt);
		world.setBlock(i + 5, j + 1, k + 0, Blocks.dirt);
		world.setBlock(i + 5, j + 1, k + 1, Blocks.dirt);
		world.setBlock(i + 5, j + 1, k + 2, Blocks.dirt);
		world.setBlock(i + 5, j + 1, k + 3, Blocks.dirt);
		world.setBlock(i + 5, j + 1, k + 4, Blocks.dirt);
		world.setBlock(i + 5, j + 1, k + 5, Blocks.dirt);
		world.setBlock(i + 5, j + 1, k + 6, Blocks.dirt);
		world.setBlock(i + 5, j + 1, k + 7, Blocks.dirt);
		world.setBlock(i + 5, j + 1, k + 8, Blocks.dirt);
		world.setBlock(i + 5, j + 1, k + 9, Blocks.dirt);
		world.setBlock(i + 5, j + 1, k + 10, Blocks.dirt);
		world.setBlock(i + 5, j + 1, k + 11, Blocks.dirt);
		world.setBlock(i + 5, j + 1, k + 12, Blocks.dirt);
		world.setBlock(i + 5, j + 1, k + 13, Blocks.dirt);
		world.setBlock(i + 5, j + 1, k + 14, Blocks.dirt);
		world.setBlock(i + 5, j + 1, k + 15, Blocks.dirt);
		world.setBlock(i + 5, j + 1, k + 16, Blocks.dirt);
		world.setBlock(i + 5, j + 1, k + 17, Blocks.dirt);
		world.setBlock(i + 5, j + 1, k + 18, Blocks.dirt);
		world.setBlock(i + 5, j + 1, k + 19, Blocks.dirt);
		world.setBlock(i + 5, j + 1, k + 20, Blocks.dirt);
		world.setBlock(i + 5, j + 2, k + 0, Blocks.grass);
		world.setBlock(i + 5, j + 2, k + 1, Blocks.grass);
		world.setBlock(i + 5, j + 2, k + 2, Blocks.grass);
		world.setBlock(i + 5, j + 2, k + 3, Blocks.grass);
		world.setBlock(i + 5, j + 2, k + 4, Blocks.grass);
		world.setBlock(i + 5, j + 2, k + 5, Blocks.grass);
		world.setBlock(i + 5, j + 2, k + 6, Blocks.grass);
		world.setBlock(i + 5, j + 2, k + 7, Blocks.grass);
		world.setBlock(i + 5, j + 2, k + 8, Blocks.grass);
		world.setBlock(i + 5, j + 2, k + 9, Blocks.grass);
		world.setBlock(i + 5, j + 2, k + 10, Blocks.grass);
		world.setBlock(i + 5, j + 2, k + 11, Blocks.grass);
		world.setBlock(i + 5, j + 2, k + 12, Blocks.dirt);
		world.setBlock(i + 5, j + 2, k + 13, Blocks.dirt);
		world.setBlock(i + 5, j + 2, k + 14, Blocks.dirt);
		world.setBlock(i + 5, j + 2, k + 15, Blocks.dirt);
		world.setBlock(i + 5, j + 2, k + 16, Blocks.dirt);
		world.setBlock(i + 5, j + 2, k + 17, Blocks.dirt);
		world.setBlock(i + 5, j + 2, k + 18, Blocks.dirt);
		world.setBlock(i + 5, j + 2, k + 19, Blocks.dirt);
		world.setBlock(i + 5, j + 2, k + 20, Blocks.dirt);
		world.setBlock(i + 5, j + 3, k + 0, Blocks.dirt);
		world.setBlock(i + 5, j + 3, k + 1, Blocks.dirt);
		world.setBlock(i + 5, j + 3, k + 2, Blocks.dirt);
		world.setBlock(i + 5, j + 3, k + 3, Blocks.dirt);
		world.setBlock(i + 5, j + 3, k + 4, Blocks.dirt);
		world.setBlock(i + 5, j + 3, k + 5, Blocks.dirt);
		world.setBlock(i + 5, j + 3, k + 6, Blocks.dirt);
		world.setBlock(i + 5, j + 3, k + 7, Blocks.dirt);
		world.setBlock(i + 5, j + 3, k + 8, Blocks.dirt);
		world.setBlock(i + 5, j + 3, k + 9, Blocks.dirt);
		world.setBlock(i + 5, j + 3, k + 10, Blocks.dirt);
		world.setBlock(i + 5, j + 3, k + 11, Blocks.dirt);
		world.setBlock(i + 5, j + 3, k + 12, Blocks.dirt);
		world.setBlock(i + 5, j + 3, k + 13, Blocks.dirt);
		world.setBlock(i + 5, j + 3, k + 14, Blocks.dirt);
		world.setBlock(i + 5, j + 3, k + 15, Blocks.dirt);
		world.setBlock(i + 5, j + 3, k + 16, Blocks.dirt);
		world.setBlock(i + 5, j + 3, k + 17, Blocks.dirt);
		world.setBlock(i + 5, j + 3, k + 18, Blocks.dirt);
		world.setBlock(i + 5, j + 3, k + 19, Blocks.dirt);
		world.setBlock(i + 5, j + 3, k + 20, Blocks.dirt);
		world.setBlock(i + 5, j + 4, k + 0, Blocks.dirt);
		world.setBlock(i + 5, j + 4, k + 1, Blocks.dirt);
		world.setBlock(i + 5, j + 4, k + 2, Blocks.dirt);
		world.setBlock(i + 5, j + 4, k + 3, Blocks.dirt);
		world.setBlock(i + 5, j + 4, k + 4, Blocks.dirt);
		world.setBlock(i + 5, j + 4, k + 5, Blocks.dirt);
		world.setBlock(i + 5, j + 4, k + 6, Blocks.dirt);
		world.setBlock(i + 5, j + 4, k + 7, Blocks.dirt);
		world.setBlock(i + 5, j + 4, k + 8, Blocks.dirt);
		world.setBlock(i + 5, j + 4, k + 9, Blocks.dirt);
		world.setBlock(i + 5, j + 4, k + 10, Blocks.dirt);
		world.setBlock(i + 5, j + 4, k + 11, Blocks.dirt);
		world.setBlock(i + 5, j + 4, k + 12, Blocks.dirt);
		world.setBlock(i + 5, j + 4, k + 13, Blocks.dirt);
		world.setBlock(i + 5, j + 4, k + 14, Blocks.dirt);
		world.setBlock(i + 5, j + 4, k + 17, Blocks.dirt);
		world.setBlock(i + 5, j + 4, k + 18, Blocks.dirt);
		world.setBlock(i + 5, j + 4, k + 19, Blocks.dirt);
		world.setBlock(i + 5, j + 4, k + 20, Blocks.dirt);
		world.setBlock(i + 5, j + 5, k + 0, Blocks.dirt);
		world.setBlock(i + 5, j + 5, k + 1, Blocks.dirt);
		world.setBlock(i + 5, j + 5, k + 2, Blocks.dirt);
		world.setBlock(i + 5, j + 5, k + 3, Blocks.dirt);
		world.setBlock(i + 5, j + 5, k + 4, Blocks.dirt);
		world.setBlock(i + 5, j + 5, k + 5, Blocks.dirt);
		world.setBlock(i + 5, j + 5, k + 6, Blocks.dirt);
		world.setBlock(i + 5, j + 5, k + 7, Blocks.dirt);
		world.setBlock(i + 5, j + 5, k + 8, Blocks.dirt);
		world.setBlock(i + 5, j + 5, k + 9, Blocks.nether_brick);
		world.setBlock(i + 5, j + 5, k + 10, Blocks.sandstone, 2, 0x02);
		world.setBlock(i + 5, j + 5, k + 11, Blocks.nether_brick);
		world.setBlock(i + 5, j + 5, k + 12, Blocks.grass);
		world.setBlock(i + 5, j + 5, k + 13, Blocks.grass);
		world.setBlock(i + 5, j + 5, k + 18, Blocks.grass);
		world.setBlock(i + 5, j + 5, k + 19, Blocks.grass);
		world.setBlock(i + 5, j + 5, k + 20, Blocks.grass);
		world.setBlock(i + 5, j + 6, k + 0, Blocks.birch_stairs, 2, 0x02);
		world.setBlock(i + 5, j + 6, k + 1, Blocks.planks, 2, 0x02);
		world.setBlock(i + 5, j + 6, k + 2, Blocks.planks, 2, 0x02);
		world.setBlock(i + 5, j + 6, k + 3, Blocks.planks, 2, 0x02);
		world.setBlock(i + 5, j + 6, k + 4, Blocks.planks, 2, 0x02);
		world.setBlock(i + 5, j + 6, k + 5, Blocks.planks, 2, 0x02);
		world.setBlock(i + 5, j + 6, k + 6, Blocks.planks, 2, 0x02);
		world.setBlock(i + 5, j + 6, k + 7, Blocks.planks, 2, 0x02);
		world.setBlock(i + 5, j + 6, k + 8, Blocks.birch_stairs, 3, 0x02);
		world.setBlock(i + 5, j + 6, k + 12, Blocks.cobblestone_wall, 1, 0x02);
		world.setBlock(i + 5, j + 6, k + 20, Blocks.cobblestone_wall, 1, 0x02);
		world.setBlock(i + 5, j + 7, k + 1, Blocks.cobblestone);
		world.setBlock(i + 5, j + 7, k + 2, Blocks.chest, 3, 0x02);
		world.setBlock(i + 5, j + 7, k + 7, Blocks.log, 1, 0x02);
		world.setBlock(i + 5, j + 8, k + 1, Blocks.glass_pane);
		world.setBlock(i + 5, j + 8, k + 7, Blocks.log, 1, 0x02);
		world.setBlock(i + 5, j + 9, k + 1, Blocks.glass_pane);
		world.setBlock(i + 5, j + 9, k + 7, Blocks.log, 1, 0x02);
		world.setBlock(i + 5, j + 9, k + 11, Blocks.leaves);
		world.setBlock(i + 5, j + 9, k + 12, Blocks.leaves);
		world.setBlock(i + 5, j + 9, k + 13, Blocks.leaves);
		world.setBlock(i + 5, j + 9, k + 14, Blocks.leaves);
		world.setBlock(i + 5, j + 9, k + 15, Blocks.leaves);
		world.setBlock(i + 5, j + 9, k + 16, Blocks.leaves, 2, 0x02);
		world.setBlock(i + 5, j + 9, k + 17, Blocks.leaves, 2, 0x02);
		world.setBlock(i + 5, j + 9, k + 18, Blocks.leaves, 2, 0x02);
		world.setBlock(i + 5, j + 9, k + 19, Blocks.leaves, 2, 0x02);
		world.setBlock(i + 5, j + 9, k + 20, Blocks.leaves, 2, 0x02);
		world.setBlock(i + 5, j + 10, k + 1, Blocks.cobblestone);
		world.setBlock(i + 5, j + 10, k + 6, Blocks.birch_stairs, 6, 0x02);
		world.setBlock(i + 5, j + 10, k + 7, Blocks.log, 1, 0x02);
		world.setBlock(i + 5, j + 10, k + 11, Blocks.leaves);
		world.setBlock(i + 5, j + 10, k + 12, Blocks.leaves);
		world.setBlock(i + 5, j + 10, k + 13, Blocks.leaves);
		world.setBlock(i + 5, j + 10, k + 14, Blocks.leaves);
		world.setBlock(i + 5, j + 10, k + 15, Blocks.leaves);
		world.setBlock(i + 5, j + 10, k + 16, Blocks.leaves, 2, 0x02);
		world.setBlock(i + 5, j + 10, k + 17, Blocks.leaves, 2, 0x02);
		world.setBlock(i + 5, j + 10, k + 18, Blocks.leaves, 2, 0x02);
		world.setBlock(i + 5, j + 10, k + 19, Blocks.leaves, 2, 0x02);
		world.setBlock(i + 5, j + 10, k + 20, Blocks.leaves, 2, 0x02);
		world.setBlock(i + 5, j + 11, k + 0, Blocks.birch_stairs, 2, 0x02);
		world.setBlock(i + 5, j + 11, k + 1, Blocks.log, 9, 0x02);
		world.setBlock(i + 5, j + 11, k + 2, Blocks.planks, 2, 0x02);
		world.setBlock(i + 5, j + 11, k + 3, Blocks.planks, 2, 0x02);
		world.setBlock(i + 5, j + 11, k + 4, Blocks.planks, 2, 0x02);
		world.setBlock(i + 5, j + 11, k + 5, Blocks.planks, 2, 0x02);
		world.setBlock(i + 5, j + 11, k + 6, Blocks.log, 5, 0x02);
		world.setBlock(i + 5, j + 11, k + 7, Blocks.log, 1, 0x02);
		world.setBlock(i + 5, j + 11, k + 8, Blocks.birch_stairs, 3, 0x02);
		world.setBlock(i + 5, j + 11, k + 12, Blocks.leaves);
		world.setBlock(i + 5, j + 11, k + 13, Blocks.leaves);
		world.setBlock(i + 5, j + 11, k + 14, Blocks.leaves);
		world.setBlock(i + 5, j + 11, k + 17, Blocks.leaves, 2, 0x02);
		world.setBlock(i + 5, j + 11, k + 18, Blocks.leaves, 2, 0x02);
		world.setBlock(i + 5, j + 11, k + 19, Blocks.leaves, 2, 0x02);
		world.setBlock(i + 5, j + 12, k + 1, Blocks.log, 1, 0x02);
		world.setBlock(i + 5, j + 12, k + 2, Blocks.bed, 1, 0x02);
		world.setBlock(i + 5, j + 12, k + 5, Blocks.log, 1, 0x02);
		world.setBlock(i + 5, j + 12, k + 6, Blocks.fence);
		world.setBlock(i + 5, j + 12, k + 7, Blocks.fence);
		world.setBlock(i + 5, j + 12, k + 13, Blocks.leaves);
		world.setBlock(i + 5, j + 12, k + 18, Blocks.leaves, 2, 0x02);
		world.setBlock(i + 5, j + 13, k + 1, Blocks.log, 1, 0x02);
		world.setBlock(i + 5, j + 13, k + 5, Blocks.log, 1, 0x02);
		world.setBlock(i + 5, j + 14, k + 1, Blocks.log, 1, 0x02);
		world.setBlock(i + 5, j + 14, k + 5, Blocks.log, 1, 0x02);
		world.setBlock(i + 5, j + 15, k + 1, Blocks.log, 1, 0x02);
		world.setBlock(i + 5, j + 15, k + 2, Blocks.spruce_stairs, 7, 0x02);
		world.setBlock(i + 5, j + 15, k + 3, Blocks.wooden_slab, 9, 0x02);
		world.setBlock(i + 5, j + 15, k + 4, Blocks.spruce_stairs, 6, 0x02);
		world.setBlock(i + 5, j + 15, k + 5, Blocks.log, 1, 0x02);
		world.setBlock(i + 5, j + 16, k + 1, Blocks.log, 1, 0x02);
		world.setBlock(i + 5, j + 16, k + 2, Blocks.log, 5, 0x02);
		world.setBlock(i + 5, j + 16, k + 3, Blocks.log, 5, 0x02);
		world.setBlock(i + 5, j + 16, k + 4, Blocks.log, 5, 0x02);
		world.setBlock(i + 5, j + 16, k + 5, Blocks.log, 1, 0x02);
		world.setBlock(i + 5, j + 16, k + 6, Blocks.fence);
		world.setBlock(i + 5, j + 17, k + 0, Blocks.wooden_slab, 1, 0x02);
		world.setBlock(i + 5, j + 17, k + 1, Blocks.planks, 2, 0x02);
		world.setBlock(i + 5, j + 17, k + 2, Blocks.planks, 2, 0x02);
		world.setBlock(i + 5, j + 17, k + 3, Blocks.planks, 2, 0x02);
		world.setBlock(i + 5, j + 17, k + 4, Blocks.planks, 2, 0x02);
		world.setBlock(i + 5, j + 17, k + 5, Blocks.planks, 2, 0x02);
		world.setBlock(i + 5, j + 17, k + 6, Blocks.wooden_slab, 1, 0x02);
		world.setBlock(i + 6, j + 0, k + 0, Blocks.dirt);
		world.setBlock(i + 6, j + 0, k + 1, Blocks.dirt);
		world.setBlock(i + 6, j + 0, k + 2, Blocks.dirt);
		world.setBlock(i + 6, j + 0, k + 3, Blocks.dirt);
		world.setBlock(i + 6, j + 0, k + 4, Blocks.dirt);
		world.setBlock(i + 6, j + 0, k + 5, Blocks.dirt);
		world.setBlock(i + 6, j + 0, k + 6, Blocks.dirt);
		world.setBlock(i + 6, j + 0, k + 7, Blocks.dirt);
		world.setBlock(i + 6, j + 0, k + 8, Blocks.dirt);
		world.setBlock(i + 6, j + 0, k + 9, Blocks.dirt);
		world.setBlock(i + 6, j + 0, k + 10, Blocks.dirt);
		world.setBlock(i + 6, j + 0, k + 11, Blocks.dirt);
		world.setBlock(i + 6, j + 0, k + 12, Blocks.dirt);
		world.setBlock(i + 6, j + 0, k + 13, Blocks.dirt);
		world.setBlock(i + 6, j + 0, k + 14, Blocks.dirt);
		world.setBlock(i + 6, j + 0, k + 15, Blocks.dirt);
		world.setBlock(i + 6, j + 0, k + 16, Blocks.dirt);
		world.setBlock(i + 6, j + 0, k + 17, Blocks.dirt);
		world.setBlock(i + 6, j + 0, k + 18, Blocks.dirt);
		world.setBlock(i + 6, j + 0, k + 19, Blocks.dirt);
		world.setBlock(i + 6, j + 0, k + 20, Blocks.dirt);
		world.setBlock(i + 6, j + 1, k + 0, Blocks.dirt);
		world.setBlock(i + 6, j + 1, k + 1, Blocks.dirt);
		world.setBlock(i + 6, j + 1, k + 2, Blocks.dirt);
		world.setBlock(i + 6, j + 1, k + 3, Blocks.dirt);
		world.setBlock(i + 6, j + 1, k + 4, Blocks.dirt);
		world.setBlock(i + 6, j + 1, k + 5, Blocks.dirt);
		world.setBlock(i + 6, j + 1, k + 6, Blocks.dirt);
		world.setBlock(i + 6, j + 1, k + 7, Blocks.dirt);
		world.setBlock(i + 6, j + 1, k + 8, Blocks.dirt);
		world.setBlock(i + 6, j + 1, k + 9, Blocks.dirt);
		world.setBlock(i + 6, j + 1, k + 10, Blocks.dirt);
		world.setBlock(i + 6, j + 1, k + 11, Blocks.dirt);
		world.setBlock(i + 6, j + 1, k + 12, Blocks.dirt);
		world.setBlock(i + 6, j + 1, k + 13, Blocks.dirt);
		world.setBlock(i + 6, j + 1, k + 14, Blocks.dirt);
		world.setBlock(i + 6, j + 1, k + 15, Blocks.dirt);
		world.setBlock(i + 6, j + 1, k + 16, Blocks.dirt);
		world.setBlock(i + 6, j + 1, k + 17, Blocks.dirt);
		world.setBlock(i + 6, j + 1, k + 18, Blocks.dirt);
		world.setBlock(i + 6, j + 1, k + 19, Blocks.dirt);
		world.setBlock(i + 6, j + 1, k + 20, Blocks.dirt);
		world.setBlock(i + 6, j + 2, k + 0, Blocks.grass);
		world.setBlock(i + 6, j + 2, k + 1, Blocks.grass);
		world.setBlock(i + 6, j + 2, k + 2, Blocks.grass);
		world.setBlock(i + 6, j + 2, k + 3, Blocks.grass);
		world.setBlock(i + 6, j + 2, k + 4, Blocks.grass);
		world.setBlock(i + 6, j + 2, k + 5, Blocks.grass);
		world.setBlock(i + 6, j + 2, k + 6, Blocks.grass);
		world.setBlock(i + 6, j + 2, k + 7, Blocks.grass);
		world.setBlock(i + 6, j + 2, k + 8, Blocks.grass);
		world.setBlock(i + 6, j + 2, k + 9, Blocks.grass);
		world.setBlock(i + 6, j + 2, k + 10, Blocks.grass);
		world.setBlock(i + 6, j + 2, k + 11, Blocks.grass);
		world.setBlock(i + 6, j + 2, k + 12, Blocks.dirt);
		world.setBlock(i + 6, j + 2, k + 13, Blocks.dirt);
		world.setBlock(i + 6, j + 2, k + 14, Blocks.dirt);
		world.setBlock(i + 6, j + 2, k + 15, Blocks.dirt);
		world.setBlock(i + 6, j + 2, k + 16, Blocks.dirt);
		world.setBlock(i + 6, j + 2, k + 17, Blocks.dirt);
		world.setBlock(i + 6, j + 2, k + 18, Blocks.dirt);
		world.setBlock(i + 6, j + 2, k + 19, Blocks.dirt);
		world.setBlock(i + 6, j + 2, k + 20, Blocks.dirt);
		world.setBlock(i + 6, j + 3, k + 0, Blocks.dirt);
		world.setBlock(i + 6, j + 3, k + 1, Blocks.dirt);
		world.setBlock(i + 6, j + 3, k + 2, Blocks.dirt);
		world.setBlock(i + 6, j + 3, k + 3, Blocks.dirt);
		world.setBlock(i + 6, j + 3, k + 4, Blocks.dirt);
		world.setBlock(i + 6, j + 3, k + 5, Blocks.dirt);
		world.setBlock(i + 6, j + 3, k + 6, Blocks.dirt);
		world.setBlock(i + 6, j + 3, k + 7, Blocks.dirt);
		world.setBlock(i + 6, j + 3, k + 8, Blocks.dirt);
		world.setBlock(i + 6, j + 3, k + 9, Blocks.dirt);
		world.setBlock(i + 6, j + 3, k + 10, Blocks.dirt);
		world.setBlock(i + 6, j + 3, k + 11, Blocks.dirt);
		world.setBlock(i + 6, j + 3, k + 12, Blocks.dirt);
		world.setBlock(i + 6, j + 3, k + 13, Blocks.dirt);
		world.setBlock(i + 6, j + 3, k + 14, Blocks.dirt);
		world.setBlock(i + 6, j + 3, k + 15, Blocks.dirt);
		world.setBlock(i + 6, j + 3, k + 16, Blocks.dirt);
		world.setBlock(i + 6, j + 3, k + 17, Blocks.dirt);
		world.setBlock(i + 6, j + 3, k + 18, Blocks.dirt);
		world.setBlock(i + 6, j + 3, k + 19, Blocks.dirt);
		world.setBlock(i + 6, j + 3, k + 20, Blocks.dirt);
		world.setBlock(i + 6, j + 4, k + 0, Blocks.dirt);
		world.setBlock(i + 6, j + 4, k + 1, Blocks.dirt);
		world.setBlock(i + 6, j + 4, k + 2, Blocks.dirt);
		world.setBlock(i + 6, j + 4, k + 3, Blocks.dirt);
		world.setBlock(i + 6, j + 4, k + 4, Blocks.dirt);
		world.setBlock(i + 6, j + 4, k + 5, Blocks.dirt);
		world.setBlock(i + 6, j + 4, k + 6, Blocks.dirt);
		world.setBlock(i + 6, j + 4, k + 7, Blocks.dirt);
		world.setBlock(i + 6, j + 4, k + 8, Blocks.dirt);
		world.setBlock(i + 6, j + 4, k + 9, Blocks.dirt);
		world.setBlock(i + 6, j + 4, k + 10, Blocks.dirt);
		world.setBlock(i + 6, j + 4, k + 11, Blocks.dirt);
		world.setBlock(i + 6, j + 4, k + 12, Blocks.dirt);
		world.setBlock(i + 6, j + 4, k + 13, Blocks.dirt);
		world.setBlock(i + 6, j + 4, k + 14, Blocks.dirt);
		world.setBlock(i + 6, j + 4, k + 15, Blocks.dirt);
		world.setBlock(i + 6, j + 4, k + 16, Blocks.dirt);
		world.setBlock(i + 6, j + 4, k + 17, Blocks.dirt);
		world.setBlock(i + 6, j + 4, k + 18, Blocks.dirt);
		world.setBlock(i + 6, j + 4, k + 19, Blocks.dirt);
		world.setBlock(i + 6, j + 4, k + 20, Blocks.dirt);
		world.setBlock(i + 6, j + 5, k + 0, Blocks.dirt);
		world.setBlock(i + 6, j + 5, k + 1, Blocks.dirt);
		world.setBlock(i + 6, j + 5, k + 2, Blocks.dirt);
		world.setBlock(i + 6, j + 5, k + 3, Blocks.dirt);
		world.setBlock(i + 6, j + 5, k + 4, Blocks.dirt);
		world.setBlock(i + 6, j + 5, k + 5, Blocks.dirt);
		world.setBlock(i + 6, j + 5, k + 6, Blocks.dirt);
		world.setBlock(i + 6, j + 5, k + 7, Blocks.dirt);
		world.setBlock(i + 6, j + 5, k + 8, Blocks.dirt);
		world.setBlock(i + 6, j + 5, k + 9, Blocks.nether_brick);
		world.setBlock(i + 6, j + 5, k + 10, Blocks.nether_brick);
		world.setBlock(i + 6, j + 5, k + 11, Blocks.nether_brick);
		world.setBlock(i + 6, j + 5, k + 12, Blocks.grass);
		world.setBlock(i + 6, j + 5, k + 13, Blocks.grass);
		world.setBlock(i + 6, j + 5, k + 14, Blocks.grass);
		world.setBlock(i + 6, j + 5, k + 17, Blocks.grass);
		world.setBlock(i + 6, j + 5, k + 18, Blocks.dirt);
		world.setBlock(i + 6, j + 5, k + 19, Blocks.grass);
		world.setBlock(i + 6, j + 5, k + 20, Blocks.grass);
		world.setBlock(i + 6, j + 6, k + 0, Blocks.birch_stairs, 2, 0x02);
		world.setBlock(i + 6, j + 6, k + 1, Blocks.planks, 2, 0x02);
		world.setBlock(i + 6, j + 6, k + 2, Blocks.planks, 2, 0x02);
		world.setBlock(i + 6, j + 6, k + 3, Blocks.planks, 2, 0x02);
		world.setBlock(i + 6, j + 6, k + 4, Blocks.planks, 2, 0x02);
		world.setBlock(i + 6, j + 6, k + 5, Blocks.planks, 2, 0x02);
		world.setBlock(i + 6, j + 6, k + 6, Blocks.planks, 2, 0x02);
		world.setBlock(i + 6, j + 6, k + 7, Blocks.birch_stairs, 3, 0x02);
		world.setBlock(i + 6, j + 6, k + 8, Blocks.birch_stairs, 1, 0x02);
		world.setBlock(i + 6, j + 6, k + 12, Blocks.cobblestone_wall, 1, 0x02);
		world.setBlock(i + 6, j + 6, k + 18, Blocks.log, 2, 0x02);
		world.setBlock(i + 6, j + 6, k + 20, Blocks.cobblestone_wall, 1, 0x02);
		world.setBlock(i + 6, j + 7, k + 1, Blocks.cobblestone);
		world.setBlock(i + 6, j + 7, k + 2, Blocks.chest, 3, 0x02);
		world.setBlock(i + 6, j + 7, k + 12, Blocks.cobblestone_wall, 1, 0x02);
		world.setBlock(i + 6, j + 7, k + 18, Blocks.log, 2, 0x02);
		world.setBlock(i + 6, j + 8, k + 1, Blocks.cobblestone);
		world.setBlock(i + 6, j + 8, k + 12, Blocks.cobblestone_wall);
		world.setBlock(i + 6, j + 8, k + 18, Blocks.log, 2, 0x02);
		world.setBlock(i + 6, j + 9, k + 1, Blocks.cobblestone);
		world.setBlock(i + 6, j + 9, k + 8, mod_Avatar.AirNomadsBlock);
		world.setBlock(i + 6, j + 9, k + 11, Blocks.leaves);
		world.setBlock(i + 6, j + 9, k + 12, Blocks.cobblestone_wall);
		world.setBlock(i + 6, j + 9, k + 13, Blocks.leaves);
		world.setBlock(i + 6, j + 9, k + 14, Blocks.leaves);
		world.setBlock(i + 6, j + 9, k + 15, Blocks.leaves);
		world.setBlock(i + 6, j + 9, k + 16, Blocks.leaves, 2, 0x02);
		world.setBlock(i + 6, j + 9, k + 17, Blocks.leaves, 2, 0x02);
		world.setBlock(i + 6, j + 9, k + 18, Blocks.log, 2, 0x02);
		world.setBlock(i + 6, j + 9, k + 19, Blocks.leaves, 2, 0x02);
		world.setBlock(i + 6, j + 9, k + 20, Blocks.leaves, 2, 0x02);
		world.setBlock(i + 6, j + 10, k + 1, Blocks.cobblestone);
		world.setBlock(i + 6, j + 10, k + 5, Blocks.birch_stairs, 4, 0x02);
		world.setBlock(i + 6, j + 10, k + 8, Blocks.fence);
		world.setBlock(i + 6, j + 10, k + 12, Blocks.cobblestone_wall);
		world.setBlock(i + 6, j + 10, k + 13, Blocks.cobblestone_wall);
		world.setBlock(i + 6, j + 10, k + 14, Blocks.leaves);
		world.setBlock(i + 6, j + 10, k + 15, Blocks.leaves);
		world.setBlock(i + 6, j + 10, k + 16, Blocks.leaves, 2, 0x02);
		world.setBlock(i + 6, j + 10, k + 17, Blocks.leaves, 2, 0x02);
		world.setBlock(i + 6, j + 10, k + 18, Blocks.log, 2, 0x02);
		world.setBlock(i + 6, j + 10, k + 19, Blocks.leaves, 2, 0x02);
		world.setBlock(i + 6, j + 10, k + 20, Blocks.leaves, 2, 0x02);
		world.setBlock(i + 6, j + 11, k + 0, Blocks.birch_stairs, 2, 0x02);
		world.setBlock(i + 6, j + 11, k + 1, Blocks.log, 9, 0x02);
		world.setBlock(i + 6, j + 11, k + 2, Blocks.planks, 2, 0x02);
		world.setBlock(i + 6, j + 11, k + 3, Blocks.planks, 2, 0x02);
		world.setBlock(i + 6, j + 11, k + 4, Blocks.planks, 2, 0x02);
		world.setBlock(i + 6, j + 11, k + 5, Blocks.log, 9, 0x02);
		world.setBlock(i + 6, j + 11, k + 6, Blocks.birch_stairs, 1, 0x02);
		world.setBlock(i + 6, j + 11, k + 7, Blocks.birch_stairs, 1, 0x02);
		world.setBlock(i + 6, j + 11, k + 8, Blocks.birch_stairs, 1, 0x02);
		world.setBlock(i + 6, j + 11, k + 17, Blocks.leaves, 2, 0x02);
		world.setBlock(i + 6, j + 11, k + 18, Blocks.log, 2, 0x02);
		world.setBlock(i + 6, j + 11, k + 19, Blocks.leaves, 2, 0x02);
		world.setBlock(i + 6, j + 12, k + 1, Blocks.fence);
		world.setBlock(i + 6, j + 12, k + 5, Blocks.fence);
		world.setBlock(i + 6, j + 12, k + 17, Blocks.leaves, 2, 0x02);
		world.setBlock(i + 6, j + 12, k + 18, Blocks.leaves, 2, 0x02);
		world.setBlock(i + 6, j + 12, k + 19, Blocks.leaves, 2, 0x02);
		world.setBlock(i + 6, j + 15, k + 6, Blocks.glowstone);
		world.setBlock(i + 6, j + 16, k + 5, Blocks.fence);
		world.setBlock(i + 6, j + 16, k + 6, Blocks.fence);
		world.setBlock(i + 6, j + 17, k + 0, Blocks.wooden_slab, 1, 0x02);
		world.setBlock(i + 6, j + 17, k + 1, Blocks.wooden_slab, 1, 0x02);
		world.setBlock(i + 6, j + 17, k + 2, Blocks.wooden_slab, 1, 0x02);
		world.setBlock(i + 6, j + 17, k + 3, Blocks.wooden_slab, 1, 0x02);
		world.setBlock(i + 6, j + 17, k + 4, Blocks.wooden_slab, 1, 0x02);
		world.setBlock(i + 6, j + 17, k + 5, Blocks.wooden_slab, 1, 0x02);
		world.setBlock(i + 6, j + 17, k + 6, Blocks.wooden_slab, 1, 0x02);
		world.setBlock(i + 7, j + 0, k + 0, Blocks.dirt);
		world.setBlock(i + 7, j + 0, k + 1, Blocks.dirt);
		world.setBlock(i + 7, j + 0, k + 2, Blocks.dirt);
		world.setBlock(i + 7, j + 0, k + 3, Blocks.dirt);
		world.setBlock(i + 7, j + 0, k + 4, Blocks.dirt);
		world.setBlock(i + 7, j + 0, k + 5, Blocks.dirt);
		world.setBlock(i + 7, j + 0, k + 6, Blocks.dirt);
		world.setBlock(i + 7, j + 0, k + 7, Blocks.dirt);
		world.setBlock(i + 7, j + 0, k + 8, Blocks.dirt);
		world.setBlock(i + 7, j + 0, k + 9, Blocks.dirt);
		world.setBlock(i + 7, j + 0, k + 10, Blocks.dirt);
		world.setBlock(i + 7, j + 0, k + 11, Blocks.dirt);
		world.setBlock(i + 7, j + 0, k + 12, Blocks.dirt);
		world.setBlock(i + 7, j + 0, k + 13, Blocks.dirt);
		world.setBlock(i + 7, j + 0, k + 14, Blocks.dirt);
		world.setBlock(i + 7, j + 0, k + 15, Blocks.dirt);
		world.setBlock(i + 7, j + 0, k + 16, Blocks.dirt);
		world.setBlock(i + 7, j + 0, k + 17, Blocks.dirt);
		world.setBlock(i + 7, j + 0, k + 18, Blocks.dirt);
		world.setBlock(i + 7, j + 0, k + 19, Blocks.dirt);
		world.setBlock(i + 7, j + 0, k + 20, Blocks.dirt);
		world.setBlock(i + 7, j + 1, k + 0, Blocks.dirt);
		world.setBlock(i + 7, j + 1, k + 1, Blocks.dirt);
		world.setBlock(i + 7, j + 1, k + 2, Blocks.dirt);
		world.setBlock(i + 7, j + 1, k + 3, Blocks.dirt);
		world.setBlock(i + 7, j + 1, k + 4, Blocks.dirt);
		world.setBlock(i + 7, j + 1, k + 5, Blocks.dirt);
		world.setBlock(i + 7, j + 1, k + 6, Blocks.dirt);
		world.setBlock(i + 7, j + 1, k + 7, Blocks.dirt);
		world.setBlock(i + 7, j + 1, k + 8, Blocks.dirt);
		world.setBlock(i + 7, j + 1, k + 9, Blocks.dirt);
		world.setBlock(i + 7, j + 1, k + 10, Blocks.dirt);
		world.setBlock(i + 7, j + 1, k + 11, Blocks.dirt);
		world.setBlock(i + 7, j + 1, k + 12, Blocks.dirt);
		world.setBlock(i + 7, j + 1, k + 13, Blocks.dirt);
		world.setBlock(i + 7, j + 1, k + 14, Blocks.dirt);
		world.setBlock(i + 7, j + 1, k + 15, Blocks.dirt);
		world.setBlock(i + 7, j + 1, k + 16, Blocks.dirt);
		world.setBlock(i + 7, j + 1, k + 17, Blocks.dirt);
		world.setBlock(i + 7, j + 1, k + 18, Blocks.dirt);
		world.setBlock(i + 7, j + 1, k + 19, Blocks.dirt);
		world.setBlock(i + 7, j + 1, k + 20, Blocks.dirt);
		world.setBlock(i + 7, j + 2, k + 0, Blocks.grass);
		world.setBlock(i + 7, j + 2, k + 1, Blocks.grass);
		world.setBlock(i + 7, j + 2, k + 2, Blocks.grass);
		world.setBlock(i + 7, j + 2, k + 3, Blocks.grass);
		world.setBlock(i + 7, j + 2, k + 4, Blocks.grass);
		world.setBlock(i + 7, j + 2, k + 5, Blocks.grass);
		world.setBlock(i + 7, j + 2, k + 6, Blocks.grass);
		world.setBlock(i + 7, j + 2, k + 7, Blocks.grass);
		world.setBlock(i + 7, j + 2, k + 8, Blocks.grass);
		world.setBlock(i + 7, j + 2, k + 9, Blocks.grass);
		world.setBlock(i + 7, j + 2, k + 10, Blocks.grass);
		world.setBlock(i + 7, j + 2, k + 11, Blocks.grass);
		world.setBlock(i + 7, j + 2, k + 12, Blocks.dirt);
		world.setBlock(i + 7, j + 2, k + 13, Blocks.dirt);
		world.setBlock(i + 7, j + 2, k + 14, Blocks.dirt);
		world.setBlock(i + 7, j + 2, k + 15, Blocks.dirt);
		world.setBlock(i + 7, j + 2, k + 16, Blocks.dirt);
		world.setBlock(i + 7, j + 2, k + 17, Blocks.dirt);
		world.setBlock(i + 7, j + 2, k + 18, Blocks.dirt);
		world.setBlock(i + 7, j + 2, k + 19, Blocks.dirt);
		world.setBlock(i + 7, j + 2, k + 20, Blocks.dirt);
		world.setBlock(i + 7, j + 3, k + 0, Blocks.dirt);
		world.setBlock(i + 7, j + 3, k + 1, Blocks.dirt);
		world.setBlock(i + 7, j + 3, k + 2, Blocks.dirt);
		world.setBlock(i + 7, j + 3, k + 3, Blocks.dirt);
		world.setBlock(i + 7, j + 3, k + 4, Blocks.dirt);
		world.setBlock(i + 7, j + 3, k + 5, Blocks.dirt);
		world.setBlock(i + 7, j + 3, k + 6, Blocks.dirt);
		world.setBlock(i + 7, j + 3, k + 7, Blocks.dirt);
		world.setBlock(i + 7, j + 3, k + 8, Blocks.dirt);
		world.setBlock(i + 7, j + 3, k + 9, Blocks.dirt);
		world.setBlock(i + 7, j + 3, k + 10, Blocks.dirt);
		world.setBlock(i + 7, j + 3, k + 11, Blocks.dirt);
		world.setBlock(i + 7, j + 3, k + 12, Blocks.dirt);
		world.setBlock(i + 7, j + 3, k + 13, Blocks.dirt);
		world.setBlock(i + 7, j + 3, k + 14, Blocks.dirt);
		world.setBlock(i + 7, j + 3, k + 15, Blocks.dirt);
		world.setBlock(i + 7, j + 3, k + 16, Blocks.dirt);
		world.setBlock(i + 7, j + 3, k + 17, Blocks.dirt);
		world.setBlock(i + 7, j + 3, k + 18, Blocks.dirt);
		world.setBlock(i + 7, j + 3, k + 19, Blocks.dirt);
		world.setBlock(i + 7, j + 3, k + 20, Blocks.dirt);
		world.setBlock(i + 7, j + 4, k + 0, Blocks.dirt);
		world.setBlock(i + 7, j + 4, k + 1, Blocks.dirt);

	}

	public void generate2(World world, int i, int j, int k) {
		world.setBlock(i + 7, j + 4, k + 2, Blocks.dirt);
		world.setBlock(i + 7, j + 4, k + 3, Blocks.dirt);
		world.setBlock(i + 7, j + 4, k + 4, Blocks.dirt);
		world.setBlock(i + 7, j + 4, k + 5, Blocks.dirt);
		world.setBlock(i + 7, j + 4, k + 6, Blocks.dirt);
		world.setBlock(i + 7, j + 4, k + 7, Blocks.dirt);
		world.setBlock(i + 7, j + 4, k + 8, Blocks.dirt);
		world.setBlock(i + 7, j + 4, k + 9, Blocks.dirt);
		world.setBlock(i + 7, j + 4, k + 10, Blocks.dirt);
		world.setBlock(i + 7, j + 4, k + 11, Blocks.dirt);
		world.setBlock(i + 7, j + 4, k + 12, Blocks.dirt);
		world.setBlock(i + 7, j + 4, k + 13, Blocks.dirt);
		world.setBlock(i + 7, j + 4, k + 14, Blocks.dirt);
		world.setBlock(i + 7, j + 4, k + 15, Blocks.dirt);
		world.setBlock(i + 7, j + 4, k + 16, Blocks.dirt);
		world.setBlock(i + 7, j + 4, k + 17, Blocks.dirt);
		world.setBlock(i + 7, j + 4, k + 18, Blocks.dirt);
		world.setBlock(i + 7, j + 4, k + 19, Blocks.dirt);
		world.setBlock(i + 7, j + 4, k + 20, Blocks.dirt);
		world.setBlock(i + 7, j + 5, k + 0, Blocks.dirt);
		world.setBlock(i + 7, j + 5, k + 1, Blocks.dirt);
		world.setBlock(i + 7, j + 5, k + 2, Blocks.dirt);
		world.setBlock(i + 7, j + 5, k + 3, Blocks.dirt);
		world.setBlock(i + 7, j + 5, k + 4, Blocks.dirt);
		world.setBlock(i + 7, j + 5, k + 5, Blocks.dirt);
		world.setBlock(i + 7, j + 5, k + 6, Blocks.dirt);
		world.setBlock(i + 7, j + 5, k + 7, Blocks.dirt);
		world.setBlock(i + 7, j + 5, k + 8, Blocks.nether_brick);
		world.setBlock(i + 7, j + 5, k + 9, Blocks.sandstone, 2, 0x02);
		world.setBlock(i + 7, j + 5, k + 10, Blocks.sandstone, 2, 0x02);
		world.setBlock(i + 7, j + 5, k + 11, Blocks.sandstone, 2, 0x02);
		world.setBlock(i + 7, j + 5, k + 12, Blocks.nether_brick);
		world.setBlock(i + 7, j + 5, k + 13, Blocks.grass);
		world.setBlock(i + 7, j + 5, k + 14, Blocks.grass);
		world.setBlock(i + 7, j + 5, k + 15, Blocks.grass);
		world.setBlock(i + 7, j + 5, k + 16, Blocks.grass);
		world.setBlock(i + 7, j + 5, k + 17, Blocks.grass);
		world.setBlock(i + 7, j + 5, k + 18, Blocks.grass);
		world.setBlock(i + 7, j + 5, k + 19, Blocks.grass);
		world.setBlock(i + 7, j + 5, k + 20, Blocks.grass);
		world.setBlock(i + 7, j + 6, k + 0, Blocks.birch_stairs, 2, 0x02);
		world.setBlock(i + 7, j + 6, k + 1, Blocks.planks, 2, 0x02);
		world.setBlock(i + 7, j + 6, k + 2, Blocks.planks, 2, 0x02);
		world.setBlock(i + 7, j + 6, k + 3, Blocks.planks, 2, 0x02);
		world.setBlock(i + 7, j + 6, k + 4, Blocks.planks, 2, 0x02);
		world.setBlock(i + 7, j + 6, k + 5, Blocks.planks, 2, 0x02);
		world.setBlock(i + 7, j + 6, k + 6, Blocks.birch_stairs, 1, 0x02);
		world.setBlock(i + 7, j + 6, k + 7, Blocks.birch_stairs, 1, 0x02);
		world.setBlock(i + 7, j + 6, k + 20, Blocks.cobblestone_wall, 1, 0x02);
		world.setBlock(i + 7, j + 7, k + 1, Blocks.log, 1, 0x02);
		world.setBlock(i + 7, j + 7, k + 2, Blocks.cobblestone);
		world.setBlock(i + 7, j + 7, k + 3, Blocks.cobblestone);
		world.setBlock(i + 7, j + 7, k + 4, Blocks.cobblestone);
		world.setBlock(i + 7, j + 7, k + 5, Blocks.log, 1, 0x02);
		world.setBlock(i + 7, j + 8, k + 1, Blocks.log, 1, 0x02);
		world.setBlock(i + 7, j + 8, k + 2, Blocks.cobblestone);
		world.setBlock(i + 7, j + 8, k + 3, Blocks.glass_pane);
		world.setBlock(i + 7, j + 8, k + 4, Blocks.cobblestone);
		world.setBlock(i + 7, j + 8, k + 5, Blocks.log, 1, 0x02);
		world.setBlock(i + 7, j + 9, k + 1, Blocks.log, 1, 0x02);
		world.setBlock(i + 7, j + 9, k + 2, Blocks.cobblestone);
		world.setBlock(i + 7, j + 9, k + 3, Blocks.glass_pane);
		world.setBlock(i + 7, j + 9, k + 4, Blocks.cobblestone);
		world.setBlock(i + 7, j + 9, k + 5, Blocks.log, 1, 0x02);
		world.setBlock(i + 7, j + 9, k + 13, Blocks.glowstone);
		world.setBlock(i + 7, j + 9, k + 16, Blocks.leaves, 2, 0x02);
		world.setBlock(i + 7, j + 9, k + 17, Blocks.leaves, 2, 0x02);
		world.setBlock(i + 7, j + 9, k + 18, Blocks.leaves, 2, 0x02);
		world.setBlock(i + 7, j + 9, k + 19, Blocks.leaves, 2, 0x02);
		world.setBlock(i + 7, j + 9, k + 20, Blocks.leaves, 2, 0x02);
		world.setBlock(i + 7, j + 10, k + 1, Blocks.log, 1, 0x02);
		world.setBlock(i + 7, j + 10, k + 2, Blocks.cobblestone);
		world.setBlock(i + 7, j + 10, k + 3, Blocks.cobblestone);
		world.setBlock(i + 7, j + 10, k + 4, Blocks.cobblestone);
		world.setBlock(i + 7, j + 10, k + 5, Blocks.log, 1, 0x02);
		world.setBlock(i + 7, j + 10, k + 12, Blocks.cobblestone_wall);
		world.setBlock(i + 7, j + 10, k + 13, Blocks.cobblestone_wall);
		world.setBlock(i + 7, j + 10, k + 14, Blocks.cobblestone_wall);
		world.setBlock(i + 7, j + 10, k + 16, Blocks.leaves, 2, 0x02);
		world.setBlock(i + 7, j + 10, k + 17, Blocks.leaves, 2, 0x02);
		world.setBlock(i + 7, j + 10, k + 18, Blocks.leaves, 2, 0x02);
		world.setBlock(i + 7, j + 10, k + 19, Blocks.leaves, 2, 0x02);
		world.setBlock(i + 7, j + 10, k + 20, Blocks.leaves, 2, 0x02);
		world.setBlock(i + 7, j + 11, k + 0, Blocks.birch_stairs, 2, 0x02);
		world.setBlock(i + 7, j + 11, k + 1, Blocks.log, 1, 0x02);
		world.setBlock(i + 7, j + 11, k + 2, Blocks.log, 5, 0x02);
		world.setBlock(i + 7, j + 11, k + 3, Blocks.log, 5, 0x02);
		world.setBlock(i + 7, j + 11, k + 4, Blocks.log, 5, 0x02);
		world.setBlock(i + 7, j + 11, k + 5, Blocks.log, 1, 0x02);
		world.setBlock(i + 7, j + 11, k + 6, Blocks.birch_stairs, 3, 0x02);
		world.setBlock(i + 7, j + 11, k + 17, Blocks.leaves, 2, 0x02);
		world.setBlock(i + 7, j + 11, k + 18, Blocks.leaves, 2, 0x02);
		world.setBlock(i + 7, j + 12, k + 1, Blocks.fence);
		world.setBlock(i + 7, j + 12, k + 2, Blocks.fence);
		world.setBlock(i + 7, j + 12, k + 3, Blocks.fence);
		world.setBlock(i + 7, j + 12, k + 4, Blocks.fence);
		world.setBlock(i + 7, j + 12, k + 5, Blocks.fence);
		world.setBlock(i + 7, j + 12, k + 18, Blocks.leaves, 2, 0x02);
		world.setBlock(i + 8, j + 0, k + 0, Blocks.dirt);
		world.setBlock(i + 8, j + 0, k + 1, Blocks.dirt);
		world.setBlock(i + 8, j + 0, k + 2, Blocks.dirt);
		world.setBlock(i + 8, j + 0, k + 3, Blocks.dirt);
		world.setBlock(i + 8, j + 0, k + 4, Blocks.dirt);
		world.setBlock(i + 8, j + 0, k + 5, Blocks.dirt);
		world.setBlock(i + 8, j + 0, k + 6, Blocks.dirt);
		world.setBlock(i + 8, j + 0, k + 7, Blocks.dirt);
		world.setBlock(i + 8, j + 0, k + 8, Blocks.dirt);
		world.setBlock(i + 8, j + 0, k + 9, Blocks.dirt);
		world.setBlock(i + 8, j + 0, k + 10, Blocks.dirt);
		world.setBlock(i + 8, j + 0, k + 11, Blocks.dirt);
		world.setBlock(i + 8, j + 0, k + 12, Blocks.dirt);
		world.setBlock(i + 8, j + 0, k + 13, Blocks.dirt);
		world.setBlock(i + 8, j + 0, k + 14, Blocks.dirt);
		world.setBlock(i + 8, j + 0, k + 15, Blocks.dirt);
		world.setBlock(i + 8, j + 0, k + 16, Blocks.dirt);
		world.setBlock(i + 8, j + 0, k + 17, Blocks.dirt);
		world.setBlock(i + 8, j + 0, k + 18, Blocks.dirt);
		world.setBlock(i + 8, j + 0, k + 19, Blocks.dirt);
		world.setBlock(i + 8, j + 0, k + 20, Blocks.dirt);
		world.setBlock(i + 8, j + 1, k + 0, Blocks.dirt);
		world.setBlock(i + 8, j + 1, k + 1, Blocks.dirt);
		world.setBlock(i + 8, j + 1, k + 2, Blocks.dirt);
		world.setBlock(i + 8, j + 1, k + 3, Blocks.dirt);
		world.setBlock(i + 8, j + 1, k + 4, Blocks.dirt);
		world.setBlock(i + 8, j + 1, k + 5, Blocks.dirt);
		world.setBlock(i + 8, j + 1, k + 6, Blocks.dirt);
		world.setBlock(i + 8, j + 1, k + 7, Blocks.dirt);
		world.setBlock(i + 8, j + 1, k + 8, Blocks.dirt);
		world.setBlock(i + 8, j + 1, k + 9, Blocks.dirt);
		world.setBlock(i + 8, j + 1, k + 10, Blocks.dirt);
		world.setBlock(i + 8, j + 1, k + 11, Blocks.dirt);
		world.setBlock(i + 8, j + 1, k + 12, Blocks.dirt);
		world.setBlock(i + 8, j + 1, k + 13, Blocks.dirt);
		world.setBlock(i + 8, j + 1, k + 14, Blocks.dirt);
		world.setBlock(i + 8, j + 1, k + 15, Blocks.dirt);
		world.setBlock(i + 8, j + 1, k + 16, Blocks.dirt);
		world.setBlock(i + 8, j + 1, k + 17, Blocks.dirt);
		world.setBlock(i + 8, j + 1, k + 18, Blocks.dirt);
		world.setBlock(i + 8, j + 1, k + 19, Blocks.dirt);
		world.setBlock(i + 8, j + 1, k + 20, Blocks.dirt);
		world.setBlock(i + 8, j + 2, k + 0, Blocks.grass);
		world.setBlock(i + 8, j + 2, k + 1, Blocks.grass);
		world.setBlock(i + 8, j + 2, k + 2, Blocks.grass);
		world.setBlock(i + 8, j + 2, k + 3, Blocks.grass);
		world.setBlock(i + 8, j + 2, k + 4, Blocks.grass);
		world.setBlock(i + 8, j + 2, k + 5, Blocks.grass);
		world.setBlock(i + 8, j + 2, k + 6, Blocks.grass);
		world.setBlock(i + 8, j + 2, k + 7, Blocks.grass);
		world.setBlock(i + 8, j + 2, k + 8, Blocks.grass);
		world.setBlock(i + 8, j + 2, k + 9, Blocks.grass);
		world.setBlock(i + 8, j + 2, k + 10, Blocks.grass);
		world.setBlock(i + 8, j + 2, k + 11, Blocks.grass);
		world.setBlock(i + 8, j + 2, k + 12, Blocks.dirt);
		world.setBlock(i + 8, j + 2, k + 13, Blocks.dirt);
		world.setBlock(i + 8, j + 2, k + 14, Blocks.dirt);
		world.setBlock(i + 8, j + 2, k + 15, Blocks.dirt);
		world.setBlock(i + 8, j + 2, k + 16, Blocks.dirt);
		world.setBlock(i + 8, j + 2, k + 17, Blocks.dirt);
		world.setBlock(i + 8, j + 2, k + 18, Blocks.dirt);
		world.setBlock(i + 8, j + 2, k + 19, Blocks.dirt);
		world.setBlock(i + 8, j + 2, k + 20, Blocks.dirt);
		world.setBlock(i + 8, j + 3, k + 0, Blocks.dirt);
		world.setBlock(i + 8, j + 3, k + 1, Blocks.dirt);
