package kieranvs.avatar.generation;

import java.util.Random;

import kieranvs.avatar.mod_Avatar;
import kieranvs.avatar.bending.ElementManager;
import kieranvs.avatar.entity.EntityPolarBearDog;
import kieranvs.avatar.entity.EntityWaterMan;
import kieranvs.avatar.entity.EntityWaterWoman;
import kieranvs.avatar.util.GenerationUtils;
import net.minecraft.block.Block;
import net.minecraft.init.Blocks;
import net.minecraft.item.ItemStack;
import net.minecraft.tileentity.TileEntity;
import net.minecraft.tileentity.TileEntityChest;
import net.minecraft.world.World;
import net.minecraft.world.biome.BiomeGenBase;
import net.minecraft.world.chunk.IChunkProvider;
import cpw.mods.fml.common.IWorldGenerator;

public class WorldGenWaterNorthTribeVillage implements IWorldGenerator {
	
	private static BiomeGenBase[] biomes = {BiomeGenBase.icePlains, BiomeGenBase.coldTaiga, BiomeGenBase.icePlains, BiomeGenBase.frozenOcean, BiomeGenBase.iceMountains};
	
	public void generate(Random random, int chunkX, int chunkZ, World world, IChunkProvider chunkGenerator, IChunkProvider chunkProvider) {
		int[] result = GenerationUtils.shouldSpawnHere(random, chunkX, chunkZ, world, 32, 2, 25, biomes);
		if(result[0] == 0){
			this.masterGenerate(world, result[1], result[2] - 5, result[3]);
			this.generateEntities(world, result[1], result[2] - 5, result[3], random);
			this.generateLoot(world, result[1], result[2] - 5, result[3], random);
		}
	}

	public boolean masterGenerate(World world, int i, int j, int k) {
		
		generate(world, i, j, k);
		generate2(world, i, j, k);
		generate3(world, i, j, k);
		generate4(world, i, j, k);

		return true;
	}
	
	public void generateLoot(World world, int i, int j, int k, Random random){
		for(int x = i; x < i + 32; x++){
			for (int z = k; z < k + 32; z++) {
				for (int y = j; y < j + 15; y++) {
						TileEntity e = world.getTileEntity(x, y, z);
						if(e != null && e instanceof TileEntityChest){
							GenerationUtils.generateScrolls(random, (TileEntityChest) e, ElementManager.WATER, 2);
							GenerationUtils.generateRandomMoney(random, (TileEntityChest) e, ElementManager.WATER, 3);
							int ran = random.nextInt(10);
							for(int r = 0; r < random.nextInt(3); r++){
								switch (ran){
								case 1:
									((TileEntityChest) e).setInventorySlotContents(random.nextInt(27), new ItemStack(mod_Avatar.SeaPruneItem, random.nextInt(5), 0));	
									break;
								case 2:
									((TileEntityChest) e).setInventorySlotContents(random.nextInt(27), new ItemStack(mod_Avatar.SeaSquidItem, random.nextInt(5), 0));	
									break;
								case 3:
									((TileEntityChest) e).setInventorySlotContents(random.nextInt(27), new ItemStack(mod_Avatar.SeaSquidSoupItem, 1, 0));	
									break;
								case 4:
									((TileEntityChest) e).setInventorySlotContents(random.nextInt(27), new ItemStack(mod_Avatar.SeaweedBreadItem, random.nextInt(5), 0));	
									break;
								case 5:
									((TileEntityChest) e).setInventorySlotContents(random.nextInt(27), new ItemStack(mod_Avatar.SeaweedSoupItem, 1, 0));	
									break;
								}	
							}
							
						}
				}
			}
		}
	}

	public void generateEntities(World world, int i, int j, int k, Random random) {
		int numM = random.nextInt(3) + 1;
		int numW = random.nextInt(3) + 1;

		for (int x = 0; x < numM; x++) {
			EntityWaterMan waterMan = new EntityWaterMan(world, i + 16, j + 7, k + 16, 9);
			waterMan.setPositionAndRotation(i + 16, j + 7, k + 16, 1.0F, 1.0F);
			world.spawnEntityInWorld(waterMan);
		}

		for (int x = 0; x < numW; x++) {
			EntityWaterWoman waterWoman = new EntityWaterWoman(world, i + 16, j + 7, k + 16, 9);
			waterWoman.setPositionAndRotation(i + 16, j + 7, k + 16, 1.0F, 1.0F);
			world.spawnEntityInWorld(waterWoman);
		}

		EntityPolarBearDog polarDog = new EntityPolarBearDog(world);
		polarDog.setPositionAndRotation(i + 35, j + 7, k + 35, 1.0F, 1.0F);
		world.spawnEntityInWorld(polarDog);

	}

	public void generate(World world, int i, int j, int k) {

		for (int x = 0; x <= 32; x++) {
			for (int z = 0; z <= 32; z++) {
				for (int y = 0; y < 15; y++) {
					world.setBlock(i + x, j + y, k + z, Blocks.air);
				}
			}
		}

		world.setBlock(i + 7, j + 5, k + 7, Blocks.bed, 9, 0x02);
		world.setBlock(i + 8, j + 5, k + 7, Blocks.bed, 1, 0x02);
		world.setBlock(i + 7, j + 5, k + 24, Blocks.bed, 9, 0x02);
		world.setBlock(i + 8, j + 5, k + 24, Blocks.bed, 1, 0x02);
		world.setBlock(i + 7, j + 5, k + 25, Blocks.bed, 9, 0x02);
		world.setBlock(i + 8, j + 5, k + 25, Blocks.bed, 1, 0x02);
		
		
		world.setBlock(i + 0, j + 0, k + 0, Blocks.stone);
		world.setBlock(i + 0, j + 0, k + 1, Blocks.stone);
		world.setBlock(i + 0, j + 0, k + 2, Blocks.stone);
		world.setBlock(i + 0, j + 0, k + 3, Blocks.stone);
		world.setBlock(i + 0, j + 0, k + 4, Blocks.stone);
		world.setBlock(i + 0, j + 0, k + 5, Blocks.stone);
		world.setBlock(i + 0, j + 0, k + 6, Blocks.stone);
		world.setBlock(i + 0, j + 0, k + 7, Blocks.stone);
		world.setBlock(i + 0, j + 0, k + 8, Blocks.stone);
		world.setBlock(i + 0, j + 0, k + 9, Blocks.stone);
		world.setBlock(i + 0, j + 0, k + 10, Blocks.stone);
		world.setBlock(i + 0, j + 0, k + 11, Blocks.stone);
		world.setBlock(i + 0, j + 0, k + 12, Blocks.stone);
		world.setBlock(i + 0, j + 0, k + 13, Blocks.stone);
		world.setBlock(i + 0, j + 0, k + 14, Blocks.stone);
		world.setBlock(i + 0, j + 0, k + 15, Blocks.stone);
		world.setBlock(i + 0, j + 0, k + 16, Blocks.stone);
		world.setBlock(i + 0, j + 0, k + 17, Blocks.stone);
		world.setBlock(i + 0, j + 0, k + 18, Blocks.stone);
		world.setBlock(i + 0, j + 0, k + 19, Blocks.stone);
		world.setBlock(i + 0, j + 0, k + 20, Blocks.stone);
		world.setBlock(i + 0, j + 0, k + 21, Blocks.stone);
		world.setBlock(i + 0, j + 0, k + 22, Blocks.stone);
		world.setBlock(i + 0, j + 0, k + 23, Blocks.stone);
		world.setBlock(i + 0, j + 0, k + 24, Blocks.stone);
		world.setBlock(i + 0, j + 0, k + 25, Blocks.stone);
		world.setBlock(i + 0, j + 0, k + 26, Blocks.stone);
		world.setBlock(i + 0, j + 0, k + 27, Blocks.stone);
		world.setBlock(i + 0, j + 0, k + 28, Blocks.stone);
		world.setBlock(i + 0, j + 0, k + 29, Blocks.stone);
		world.setBlock(i + 0, j + 0, k + 30, Blocks.stone);
		world.setBlock(i + 0, j + 0, k + 31, Blocks.stone);
		world.setBlock(i + 0, j + 0, k + 32, Blocks.stone);
		world.setBlock(i + 0, j + 1, k + 0, Blocks.snow);
		world.setBlock(i + 0, j + 1, k + 1, Blocks.snow);
		world.setBlock(i + 0, j + 1, k + 2, Blocks.snow);
		world.setBlock(i + 0, j + 1, k + 3, Blocks.snow);
		world.setBlock(i + 0, j + 1, k + 4, Blocks.snow);
		world.setBlock(i + 0, j + 1, k + 5, Blocks.snow);
		world.setBlock(i + 0, j + 1, k + 6, Blocks.snow);
		world.setBlock(i + 0, j + 1, k + 7, Blocks.snow);
		world.setBlock(i + 0, j + 1, k + 8, Blocks.snow);
		world.setBlock(i + 0, j + 1, k + 9, Blocks.snow);
		world.setBlock(i + 0, j + 1, k + 10, Blocks.snow);
		world.setBlock(i + 0, j + 1, k + 11, Blocks.snow);
		world.setBlock(i + 0, j + 1, k + 12, Blocks.snow);
		world.setBlock(i + 0, j + 1, k + 13, Blocks.snow);
		world.setBlock(i + 0, j + 1, k + 14, Blocks.snow);
		world.setBlock(i + 0, j + 1, k + 15, Blocks.snow);
		world.setBlock(i + 0, j + 1, k + 16, Blocks.snow);
		world.setBlock(i + 0, j + 1, k + 17, Blocks.snow);
		world.setBlock(i + 0, j + 1, k + 18, Blocks.snow);
		world.setBlock(i + 0, j + 1, k + 19, Blocks.snow);
		world.setBlock(i + 0, j + 1, k + 20, Blocks.snow);
		world.setBlock(i + 0, j + 1, k + 21, Blocks.snow);
		world.setBlock(i + 0, j + 1, k + 22, Blocks.snow);
		world.setBlock(i + 0, j + 1, k + 23, Blocks.snow);
		world.setBlock(i + 0, j + 1, k + 24, Blocks.snow);
		world.setBlock(i + 0, j + 1, k + 25, Blocks.snow);
		world.setBlock(i + 0, j + 1, k + 26, Blocks.snow);
		world.setBlock(i + 0, j + 1, k + 27, Blocks.snow);
		world.setBlock(i + 0, j + 1, k + 28, Blocks.snow);
		world.setBlock(i + 0, j + 1, k + 29, Blocks.snow);
		world.setBlock(i + 0, j + 1, k + 30, Blocks.snow);
		world.setBlock(i + 0, j + 1, k + 31, Blocks.snow);
		world.setBlock(i + 0, j + 1, k + 32, Blocks.snow);
		world.setBlock(i + 0, j + 2, k + 0, Blocks.snow);
		world.setBlock(i + 0, j + 2, k + 1, Blocks.snow);
		world.setBlock(i + 0, j + 2, k + 2, Blocks.snow);
		world.setBlock(i + 0, j + 2, k + 3, Blocks.snow);
		world.setBlock(i + 0, j + 2, k + 4, Blocks.snow);
		world.setBlock(i + 0, j + 2, k + 5, Blocks.snow);
		world.setBlock(i + 0, j + 2, k + 6, Blocks.snow);
		world.setBlock(i + 0, j + 2, k + 7, Blocks.snow);
		world.setBlock(i + 0, j + 2, k + 8, Blocks.snow);
		world.setBlock(i + 0, j + 2, k + 9, Blocks.snow);
		world.setBlock(i + 0, j + 2, k + 10, Blocks.snow);
		world.setBlock(i + 0, j + 2, k + 11, Blocks.snow);
		world.setBlock(i + 0, j + 2, k + 12, Blocks.snow);
		world.setBlock(i + 0, j + 2, k + 13, Blocks.snow);
		world.setBlock(i + 0, j + 2, k + 14, Blocks.snow);
		world.setBlock(i + 0, j + 2, k + 15, Blocks.snow);
		world.setBlock(i + 0, j + 2, k + 16, Blocks.snow);
		world.setBlock(i + 0, j + 2, k + 17, Blocks.snow);
		world.setBlock(i + 0, j + 2, k + 18, Blocks.snow);
		world.setBlock(i + 0, j + 2, k + 19, Blocks.snow);
		world.setBlock(i + 0, j + 2, k + 20, Blocks.snow);
		world.setBlock(i + 0, j + 2, k + 21, Blocks.snow);
		world.setBlock(i + 0, j + 2, k + 22, Blocks.snow);
		world.setBlock(i + 0, j + 2, k + 23, Blocks.snow);
		world.setBlock(i + 0, j + 2, k + 24, Blocks.snow);
		world.setBlock(i + 0, j + 2, k + 25, Blocks.snow);
		world.setBlock(i + 0, j + 2, k + 26, Blocks.snow);
		world.setBlock(i + 0, j + 2, k + 27, Blocks.snow);
		world.setBlock(i + 0, j + 2, k + 28, Blocks.snow);
		world.setBlock(i + 0, j + 2, k + 29, Blocks.snow);
		world.setBlock(i + 0, j + 2, k + 30, Blocks.snow);
		world.setBlock(i + 0, j + 2, k + 31, Blocks.snow);
		world.setBlock(i + 0, j + 2, k + 32, Blocks.snow);
		world.setBlock(i + 0, j + 3, k + 0, Blocks.snow);
		world.setBlock(i + 0, j + 3, k + 1, Blocks.snow);
		world.setBlock(i + 0, j + 3, k + 2, Blocks.snow);
		world.setBlock(i + 0, j + 3, k + 3, Blocks.snow);
		world.setBlock(i + 0, j + 3, k + 4, Blocks.snow);
		world.setBlock(i + 0, j + 3, k + 5, Blocks.snow);
		world.setBlock(i + 0, j + 3, k + 6, Blocks.snow);
		world.setBlock(i + 0, j + 3, k + 7, Blocks.snow);
		world.setBlock(i + 0, j + 3, k + 8, Blocks.snow);
		world.setBlock(i + 0, j + 3, k + 9, Blocks.snow);
		world.setBlock(i + 0, j + 3, k + 10, Blocks.snow);
		world.setBlock(i + 0, j + 3, k + 11, Blocks.snow);
		world.setBlock(i + 0, j + 3, k + 12, Blocks.snow);
		world.setBlock(i + 0, j + 3, k + 13, Blocks.snow);
		world.setBlock(i + 0, j + 3, k + 14, Blocks.snow);
		world.setBlock(i + 0, j + 3, k + 15, Blocks.snow);
		world.setBlock(i + 0, j + 3, k + 16, Blocks.snow);
		world.setBlock(i + 0, j + 3, k + 17, Blocks.snow);
		world.setBlock(i + 0, j + 3, k + 18, Blocks.snow);
		world.setBlock(i + 0, j + 3, k + 19, Blocks.snow);
		world.setBlock(i + 0, j + 3, k + 20, Blocks.snow);
		world.setBlock(i + 0, j + 3, k + 21, Blocks.snow);
		world.setBlock(i + 0, j + 3, k + 22, Blocks.snow);
		world.setBlock(i + 0, j + 3, k + 23, Blocks.snow);
		world.setBlock(i + 0, j + 3, k + 24, Blocks.snow);
		world.setBlock(i + 0, j + 3, k + 25, Blocks.snow);
		world.setBlock(i + 0, j + 3, k + 26, Blocks.snow);
		world.setBlock(i + 0, j + 3, k + 27, Blocks.snow);
		world.setBlock(i + 0, j + 3, k + 28, Blocks.snow);
		world.setBlock(i + 0, j + 3, k + 29, Blocks.snow);
		world.setBlock(i + 0, j + 3, k + 30, Blocks.snow);
		world.setBlock(i + 0, j + 3, k + 31, Blocks.snow);
		world.setBlock(i + 0, j + 3, k + 32, Blocks.snow);
		world.setBlock(i + 0, j + 4, k + 0, Blocks.snow);
		world.setBlock(i + 0, j + 4, k + 1, Blocks.snow);
		world.setBlock(i + 0, j + 4, k + 2, Blocks.snow);
		world.setBlock(i + 0, j + 4, k + 3, Blocks.snow);
		world.setBlock(i + 0, j + 4, k + 4, Blocks.snow);
		world.setBlock(i + 0, j + 4, k + 5, Blocks.snow);
		world.setBlock(i + 0, j + 4, k + 6, Blocks.snow);
		world.setBlock(i + 0, j + 4, k + 7, Blocks.snow);
		world.setBlock(i + 0, j + 4, k + 8, Blocks.snow);
		world.setBlock(i + 0, j + 4, k + 9, Blocks.snow);
		world.setBlock(i + 0, j + 4, k + 10, Blocks.snow);
		world.setBlock(i + 0, j + 4, k + 11, Blocks.snow);
		world.setBlock(i + 0, j + 4, k + 12, Blocks.snow);
		world.setBlock(i + 0, j + 4, k + 13, Blocks.snow);
		world.setBlock(i + 0, j + 4, k + 14, Blocks.snow);
		world.setBlock(i + 0, j + 4, k + 15, Blocks.snow);
		world.setBlock(i + 0, j + 4, k + 16, Blocks.snow);
		world.setBlock(i + 0, j + 4, k + 17, Blocks.snow);
		world.setBlock(i + 0, j + 4, k + 18, Blocks.snow);
		world.setBlock(i + 0, j + 4, k + 19, Blocks.snow);
		world.setBlock(i + 0, j + 4, k + 20, Blocks.snow);
		world.setBlock(i + 0, j + 4, k + 21, Blocks.snow);
		world.setBlock(i + 0, j + 4, k + 22, Blocks.snow);
		world.setBlock(i + 0, j + 4, k + 23, Blocks.snow);
		world.setBlock(i + 0, j + 4, k + 24, Blocks.snow);
		world.setBlock(i + 0, j + 4, k + 25, Blocks.snow);
		world.setBlock(i + 0, j + 4, k + 26, Blocks.snow);
		world.setBlock(i + 0, j + 4, k + 27, Blocks.snow);
		world.setBlock(i + 0, j + 4, k + 28, Blocks.snow);
		world.setBlock(i + 0, j + 4, k + 29, Blocks.snow);
		world.setBlock(i + 0, j + 4, k + 30, Blocks.snow);
		world.setBlock(i + 0, j + 4, k + 31, Blocks.snow);
		world.setBlock(i + 0, j + 4, k + 32, Blocks.snow);
		world.setBlock(i + 0, j + 5, k + 12, Blocks.ice);
		world.setBlock(i + 0, j + 5, k + 13, Blocks.ice);
		world.setBlock(i + 0, j + 5, k + 14, Blocks.ice);
		world.setBlock(i + 0, j + 5, k + 15, Blocks.ice);
		world.setBlock(i + 0, j + 5, k + 16, Blocks.ice);
		world.setBlock(i + 0, j + 5, k + 17, Blocks.ice);
		world.setBlock(i + 0, j + 5, k + 18, Blocks.ice);
		world.setBlock(i + 0, j + 5, k + 19, Blocks.ice);
		world.setBlock(i + 0, j + 5, k + 20, Blocks.ice);
		world.setBlock(i + 0, j + 6, k + 12, Blocks.ice);
		world.setBlock(i + 0, j + 6, k + 13, Blocks.ice);
		world.setBlock(i + 0, j + 6, k + 14, Blocks.ice);
		world.setBlock(i + 0, j + 6, k + 15, Blocks.ice);
		world.setBlock(i + 0, j + 6, k + 16, Blocks.ice);
		world.setBlock(i + 0, j + 6, k + 17, Blocks.ice);
		world.setBlock(i + 0, j + 6, k + 18, Blocks.ice);
		world.setBlock(i + 0, j + 6, k + 19, Blocks.ice);
		world.setBlock(i + 0, j + 6, k + 20, Blocks.ice);
		world.setBlock(i + 0, j + 7, k + 12, Blocks.ice);
		world.setBlock(i + 0, j + 7, k + 13, Blocks.ice);
		world.setBlock(i + 0, j + 7, k + 14, Blocks.ice);
		world.setBlock(i + 0, j + 7, k + 15, Blocks.ice);
		world.setBlock(i + 0, j + 7, k + 16, Blocks.ice);
		world.setBlock(i + 0, j + 7, k + 17, Blocks.ice);
		world.setBlock(i + 0, j + 7, k + 18, Blocks.ice);
		world.setBlock(i + 0, j + 7, k + 19, Blocks.ice);
		world.setBlock(i + 0, j + 7, k + 20, Blocks.ice);
		world.setBlock(i + 0, j + 8, k + 12, Blocks.ice);
		world.setBlock(i + 0, j + 8, k + 13, Blocks.ice);
		world.setBlock(i + 0, j + 8, k + 14, Blocks.ice);
		world.setBlock(i + 0, j + 8, k + 15, Blocks.ice);
		world.setBlock(i + 0, j + 8, k + 16, Blocks.ice);
		world.setBlock(i + 0, j + 8, k + 17, Blocks.ice);
		world.setBlock(i + 0, j + 8, k + 18, Blocks.ice);
		world.setBlock(i + 0, j + 8, k + 19, Blocks.ice);
		world.setBlock(i + 0, j + 8, k + 20, Blocks.ice);
		world.setBlock(i + 1, j + 0, k + 0, Blocks.stone);
		world.setBlock(i + 1, j + 0, k + 1, Blocks.stone);
		world.setBlock(i + 1, j + 0, k + 2, Blocks.stone);
		world.setBlock(i + 1, j + 0, k + 3, Blocks.stone);
		world.setBlock(i + 1, j + 0, k + 4, Blocks.stone);
		world.setBlock(i + 1, j + 0, k + 5, Blocks.stone);
		world.setBlock(i + 1, j + 0, k + 6, Blocks.stone);
		world.setBlock(i + 1, j + 0, k + 7, Blocks.stone);
		world.setBlock(i + 1, j + 0, k + 8, Blocks.stone);
		world.setBlock(i + 1, j + 0, k + 9, Blocks.stone);
		world.setBlock(i + 1, j + 0, k + 10, Blocks.stone);
		world.setBlock(i + 1, j + 0, k + 11, Blocks.stone);
		world.setBlock(i + 1, j + 0, k + 12, Blocks.stone);
		world.setBlock(i + 1, j + 0, k + 13, Blocks.stone);
		world.setBlock(i + 1, j + 0, k + 14, Blocks.stone);
		world.setBlock(i + 1, j + 0, k + 15, Blocks.stone);
		world.setBlock(i + 1, j + 0, k + 16, Blocks.stone);
		world.setBlock(i + 1, j + 0, k + 17, Blocks.stone);
		world.setBlock(i + 1, j + 0, k + 18, Blocks.stone);
		world.setBlock(i + 1, j + 0, k + 19, Blocks.stone);
		world.setBlock(i + 1, j + 0, k + 20, Blocks.stone);
		world.setBlock(i + 1, j + 0, k + 21, Blocks.stone);
		world.setBlock(i + 1, j + 0, k + 22, Blocks.stone);
		world.setBlock(i + 1, j + 0, k + 23, Blocks.stone);
		world.setBlock(i + 1, j + 0, k + 24, Blocks.stone);
		world.setBlock(i + 1, j + 0, k + 25, Blocks.stone);
		world.setBlock(i + 1, j + 0, k + 26, Blocks.stone);
		world.setBlock(i + 1, j + 0, k + 27, Blocks.stone);
		world.setBlock(i + 1, j + 0, k + 28, Blocks.stone);
		world.setBlock(i + 1, j + 0, k + 29, Blocks.stone);
		world.setBlock(i + 1, j + 0, k + 30, Blocks.stone);
		world.setBlock(i + 1, j + 0, k + 31, Blocks.stone);
		world.setBlock(i + 1, j + 0, k + 32, Blocks.stone);
		world.setBlock(i + 1, j + 1, k + 0, Blocks.snow);
		world.setBlock(i + 1, j + 1, k + 1, Blocks.snow);
		world.setBlock(i + 1, j + 1, k + 2, Blocks.snow);
		world.setBlock(i + 1, j + 1, k + 3, Blocks.snow);
		world.setBlock(i + 1, j + 1, k + 4, Blocks.snow);
		world.setBlock(i + 1, j + 1, k + 5, Blocks.snow);
		world.setBlock(i + 1, j + 1, k + 6, Blocks.snow);
		world.setBlock(i + 1, j + 1, k + 7, Blocks.snow);
		world.setBlock(i + 1, j + 1, k + 8, Blocks.snow);
		world.setBlock(i + 1, j + 1, k + 9, Blocks.snow);
		world.setBlock(i + 1, j + 1, k + 10, Blocks.snow);
		world.setBlock(i + 1, j + 1, k + 11, Blocks.snow);
		world.setBlock(i + 1, j + 1, k + 12, Blocks.snow);
		world.setBlock(i + 1, j + 1, k + 13, Blocks.snow);
		world.setBlock(i + 1, j + 1, k + 14, Blocks.snow);
		world.setBlock(i + 1, j + 1, k + 15, Blocks.snow);
		world.setBlock(i + 1, j + 1, k + 16, Blocks.snow);
		world.setBlock(i + 1, j + 1, k + 17, Blocks.snow);
		world.setBlock(i + 1, j + 1, k + 18, Blocks.snow);
		world.setBlock(i + 1, j + 1, k + 19, Blocks.snow);
		world.setBlock(i + 1, j + 1, k + 20, Blocks.snow);
		world.setBlock(i + 1, j + 1, k + 21, Blocks.snow);
		world.setBlock(i + 1, j + 1, k + 22, Blocks.snow);
		world.setBlock(i + 1, j + 1, k + 23, Blocks.snow);
		world.setBlock(i + 1, j + 1, k + 24, Blocks.snow);
		world.setBlock(i + 1, j + 1, k + 25, Blocks.snow);
		world.setBlock(i + 1, j + 1, k + 26, Blocks.snow);
		world.setBlock(i + 1, j + 1, k + 27, Blocks.snow);
		world.setBlock(i + 1, j + 1, k + 28, Blocks.snow);
		world.setBlock(i + 1, j + 1, k + 29, Blocks.snow);
		world.setBlock(i + 1, j + 1, k + 30, Blocks.snow);
		world.setBlock(i + 1, j + 1, k + 31, Blocks.snow);
		world.setBlock(i + 1, j + 1, k + 32, Blocks.snow);
		world.setBlock(i + 1, j + 2, k + 0, Blocks.snow);
		world.setBlock(i + 1, j + 2, k + 1, Blocks.snow);
		world.setBlock(i + 1, j + 2, k + 2, Blocks.snow);
		world.setBlock(i + 1, j + 2, k + 3, Blocks.snow);
		world.setBlock(i + 1, j + 2, k + 4, Blocks.snow);
		world.setBlock(i + 1, j + 2, k + 5, Blocks.snow);
		world.setBlock(i + 1, j + 2, k + 6, Blocks.snow);
		world.setBlock(i + 1, j + 2, k + 7, Blocks.snow);
		world.setBlock(i + 1, j + 2, k + 8, Blocks.snow);
		world.setBlock(i + 1, j + 2, k + 9, Blocks.snow);
		world.setBlock(i + 1, j + 2, k + 10, Blocks.snow);
		world.setBlock(i + 1, j + 2, k + 11, Blocks.snow);
		world.setBlock(i + 1, j + 2, k + 12, Blocks.snow);
		world.setBlock(i + 1, j + 2, k + 13, Blocks.snow);
		world.setBlock(i + 1, j + 2, k + 14, Blocks.snow);
		world.setBlock(i + 1, j + 2, k + 15, Blocks.snow);
		world.setBlock(i + 1, j + 2, k + 16, Blocks.snow);
		world.setBlock(i + 1, j + 2, k + 17, Blocks.snow);
		world.setBlock(i + 1, j + 2, k + 18, Blocks.snow);
		world.setBlock(i + 1, j + 2, k + 19, Blocks.snow);
		world.setBlock(i + 1, j + 2, k + 20, Blocks.snow);
		world.setBlock(i + 1, j + 2, k + 21, Blocks.snow);
		world.setBlock(i + 1, j + 2, k + 22, Blocks.snow);
		world.setBlock(i + 1, j + 2, k + 23, Blocks.snow);
		world.setBlock(i + 1, j + 2, k + 24, Blocks.snow);
		world.setBlock(i + 1, j + 2, k + 25, Blocks.snow);
		world.setBlock(i + 1, j + 2, k + 26, Blocks.snow);
		world.setBlock(i + 1, j + 2, k + 27, Blocks.snow);
		world.setBlock(i + 1, j + 2, k + 28, Blocks.snow);
		world.setBlock(i + 1, j + 2, k + 29, Blocks.snow);
		world.setBlock(i + 1, j + 2, k + 30, Blocks.snow);
		world.setBlock(i + 1, j + 2, k + 31, Blocks.snow);
		world.setBlock(i + 1, j + 2, k + 32, Blocks.snow);
		world.setBlock(i + 1, j + 3, k + 0, Blocks.snow);
		world.setBlock(i + 1, j + 3, k + 1, Blocks.snow);
		world.setBlock(i + 1, j + 3, k + 2, Blocks.snow);
		world.setBlock(i + 1, j + 3, k + 3, Blocks.snow);
		world.setBlock(i + 1, j + 3, k + 4, Blocks.snow);
		world.setBlock(i + 1, j + 3, k + 5, Blocks.snow);
		world.setBlock(i + 1, j + 3, k + 6, Blocks.snow);
		world.setBlock(i + 1, j + 3, k + 7, Blocks.snow);
		world.setBlock(i + 1, j + 3, k + 8, Blocks.snow);
		world.setBlock(i + 1, j + 3, k + 9, Blocks.snow);
		world.setBlock(i + 1, j + 3, k + 10, Blocks.snow);
		world.setBlock(i + 1, j + 3, k + 11, Blocks.snow);
		world.setBlock(i + 1, j + 3, k + 12, Blocks.snow);
		world.setBlock(i + 1, j + 3, k + 13, Blocks.snow);
		world.setBlock(i + 1, j + 3, k + 14, Blocks.snow);
		world.setBlock(i + 1, j + 3, k + 15, Blocks.snow);
		world.setBlock(i + 1, j + 3, k + 16, Blocks.snow);
		world.setBlock(i + 1, j + 3, k + 17, Blocks.snow);
		world.setBlock(i + 1, j + 3, k + 18, Blocks.snow);
		world.setBlock(i + 1, j + 3, k + 19, Blocks.snow);
		world.setBlock(i + 1, j + 3, k + 20, Blocks.snow);
		world.setBlock(i + 1, j + 3, k + 21, Blocks.snow);
		world.setBlock(i + 1, j + 3, k + 22, Blocks.snow);
		world.setBlock(i + 1, j + 3, k + 23, Blocks.snow);
		world.setBlock(i + 1, j + 3, k + 24, Blocks.snow);
		world.setBlock(i + 1, j + 3, k + 25, Blocks.snow);
		world.setBlock(i + 1, j + 3, k + 26, Blocks.snow);
		world.setBlock(i + 1, j + 3, k + 27, Blocks.snow);
		world.setBlock(i + 1, j + 3, k + 28, Blocks.snow);
		world.setBlock(i + 1, j + 3, k + 29, Blocks.snow);
		world.setBlock(i + 1, j + 3, k + 30, Blocks.snow);
		world.setBlock(i + 1, j + 3, k + 31, Blocks.snow);
		world.setBlock(i + 1, j + 3, k + 32, Blocks.snow);
		world.setBlock(i + 1, j + 4, k + 0, Blocks.snow);
		world.setBlock(i + 1, j + 4, k + 1, Blocks.snow);
		world.setBlock(i + 1, j + 4, k + 2, Blocks.snow);
		world.setBlock(i + 1, j + 4, k + 3, Blocks.snow);
		world.setBlock(i + 1, j + 4, k + 4, Blocks.snow);
		world.setBlock(i + 1, j + 4, k + 5, Blocks.snow);
		world.setBlock(i + 1, j + 4, k + 6, Blocks.snow);
		world.setBlock(i + 1, j + 4, k + 7, Blocks.snow);
		world.setBlock(i + 1, j + 4, k + 8, Blocks.snow);
		world.setBlock(i + 1, j + 4, k + 9, Blocks.snow);
		world.setBlock(i + 1, j + 4, k + 10, Blocks.snow);
		world.setBlock(i + 1, j + 4, k + 11, Blocks.snow);
		world.setBlock(i + 1, j + 4, k + 12, Blocks.snow);
		world.setBlock(i + 1, j + 4, k + 13, Blocks.snow);
		world.setBlock(i + 1, j + 4, k + 14, Blocks.snow);
		world.setBlock(i + 1, j + 4, k + 15, Blocks.snow);
		world.setBlock(i + 1, j + 4, k + 16, Blocks.snow);
		world.setBlock(i + 1, j + 4, k + 17, Blocks.snow);
		world.setBlock(i + 1, j + 4, k + 18, Blocks.snow);
		world.setBlock(i + 1, j + 4, k + 19, Blocks.snow);
		world.setBlock(i + 1, j + 4, k + 20, Blocks.snow);
		world.setBlock(i + 1, j + 4, k + 21, Blocks.snow);
		world.setBlock(i + 1, j + 4, k + 22, Blocks.snow);
		world.setBlock(i + 1, j + 4, k + 23, Blocks.snow);
		world.setBlock(i + 1, j + 4, k + 24, Blocks.snow);
		world.setBlock(i + 1, j + 4, k + 25, Blocks.snow);
		world.setBlock(i + 1, j + 4, k + 26, Blocks.snow);
		world.setBlock(i + 1, j + 4, k + 27, Blocks.snow);
		world.setBlock(i + 1, j + 4, k + 28, Blocks.snow);
		world.setBlock(i + 1, j + 4, k + 29, Blocks.snow);
		world.setBlock(i + 1, j + 4, k + 30, Blocks.snow);
		world.setBlock(i + 1, j + 4, k + 31, Blocks.snow);
		world.setBlock(i + 1, j + 4, k + 32, Blocks.snow);
		world.setBlock(i + 1, j + 5, k + 9, Blocks.ice);
		world.setBlock(i + 1, j + 5, k + 10, Blocks.ice);
		world.setBlock(i + 1, j + 5, k + 11, Blocks.ice);
		world.setBlock(i + 1, j + 5, k + 21, Blocks.ice);
		world.setBlock(i + 1, j + 5, k + 22, Blocks.ice);
		world.setBlock(i + 1, j + 5, k + 23, Blocks.ice);
		world.setBlock(i + 1, j + 6, k + 9, Blocks.ice);
		world.setBlock(i + 1, j + 6, k + 10, Blocks.ice);
		world.setBlock(i + 1, j + 6, k + 11, Blocks.ice);
		world.setBlock(i + 1, j + 6, k + 21, Blocks.ice);
		world.setBlock(i + 1, j + 6, k + 22, Blocks.ice);
		world.setBlock(i + 1, j + 6, k + 23, Blocks.ice);
		world.setBlock(i + 1, j + 7, k + 9, Blocks.ice);
		world.setBlock(i + 1, j + 7, k + 10, Blocks.ice);
		world.setBlock(i + 1, j + 7, k + 11, Blocks.ice);
		world.setBlock(i + 1, j + 7, k + 21, Blocks.ice);
		world.setBlock(i + 1, j + 7, k + 22, Blocks.ice);
		world.setBlock(i + 1, j + 7, k + 23, Blocks.ice);
		world.setBlock(i + 1, j + 8, k + 9, Blocks.ice);
		world.setBlock(i + 1, j + 8, k + 10, Blocks.ice);
		world.setBlock(i + 1, j + 8, k + 11, Blocks.ice);
		world.setBlock(i + 1, j + 8, k + 12, Blocks.ice);
		world.setBlock(i + 1, j + 8, k + 17, Blocks.ice);
		world.setBlock(i + 1, j + 8, k + 21, Blocks.ice);
		world.setBlock(i + 1, j + 8, k + 22, Blocks.ice);
		world.setBlock(i + 1, j + 8, k + 23, Blocks.ice);
		world.setBlock(i + 1, j + 9, k + 12, Blocks.ice);
		world.setBlock(i + 1, j + 9, k + 13, Blocks.ice);
		world.setBlock(i + 1, j + 9, k + 14, Blocks.ice);
		world.setBlock(i + 1, j + 9, k + 15, Blocks.ice);
		world.setBlock(i + 1, j + 9, k + 16, Blocks.ice);
		world.setBlock(i + 1, j + 9, k + 17, Blocks.ice);
		world.setBlock(i + 1, j + 9, k + 18, Blocks.ice);
		world.setBlock(i + 1, j + 9, k + 19, Blocks.ice);
		world.setBlock(i + 1, j + 9, k + 20, Blocks.ice);
		world.setBlock(i + 2, j + 0, k + 0, Blocks.stone);
		world.setBlock(i + 2, j + 0, k + 1, Blocks.stone);
		world.setBlock(i + 2, j + 0, k + 2, Blocks.stone);
		world.setBlock(i + 2, j + 0, k + 3, Blocks.stone);
		world.setBlock(i + 2, j + 0, k + 4, Blocks.stone);
		world.setBlock(i + 2, j + 0, k + 5, Blocks.stone);
		world.setBlock(i + 2, j + 0, k + 6, Blocks.stone);
		world.setBlock(i + 2, j + 0, k + 7, Blocks.stone);
		world.setBlock(i + 2, j + 0, k + 8, Blocks.stone);
		world.setBlock(i + 2, j + 0, k + 9, Blocks.stone);
		world.setBlock(i + 2, j + 0, k + 10, Blocks.stone);
		world.setBlock(i + 2, j + 0, k + 11, Blocks.stone);
		world.setBlock(i + 2, j + 0, k + 12, Blocks.stone);
		world.setBlock(i + 2, j + 0, k + 13, Blocks.stone);
		world.setBlock(i + 2, j + 0, k + 14, Blocks.stone);
		world.setBlock(i + 2, j + 0, k + 15, Blocks.stone);
		world.setBlock(i + 2, j + 0, k + 16, Blocks.stone);
		world.setBlock(i + 2, j + 0, k + 17, Blocks.stone);
		world.setBlock(i + 2, j + 0, k + 18, Blocks.stone);
		world.setBlock(i + 2, j + 0, k + 19, Blocks.stone);
		world.setBlock(i + 2, j + 0, k + 20, Blocks.stone);
		world.setBlock(i + 2, j + 0, k + 21, Blocks.stone);
		world.setBlock(i + 2, j + 0, k + 22, Blocks.stone);
		world.setBlock(i + 2, j + 0, k + 23, Blocks.stone);
		world.setBlock(i + 2, j + 0, k + 24, Blocks.stone);
		world.setBlock(i + 2, j + 0, k + 25, Blocks.stone);
		world.setBlock(i + 2, j + 0, k + 26, Blocks.stone);
		world.setBlock(i + 2, j + 0, k + 27, Blocks.stone);
		world.setBlock(i + 2, j + 0, k + 28, Blocks.stone);
		world.setBlock(i + 2, j + 0, k + 29, Blocks.stone);
		world.setBlock(i + 2, j + 0, k + 30, Blocks.stone);
		world.setBlock(i + 2, j + 0, k + 31, Blocks.stone);
		world.setBlock(i + 2, j + 0, k + 32, Blocks.stone);
		world.setBlock(i + 2, j + 1, k + 0, Blocks.snow);
		world.setBlock(i + 2, j + 1, k + 1, Blocks.snow);
		world.setBlock(i + 2, j + 1, k + 2, Blocks.snow);
		world.setBlock(i + 2, j + 1, k + 3, Blocks.snow);
		world.setBlock(i + 2, j + 1, k + 4, Blocks.snow);
		world.setBlock(i + 2, j + 1, k + 5, Blocks.snow);
		world.setBlock(i + 2, j + 1, k + 6, Blocks.snow);
		world.setBlock(i + 2, j + 1, k + 7, Blocks.snow);
		world.setBlock(i + 2, j + 1, k + 8, Blocks.snow);
		world.setBlock(i + 2, j + 1, k + 9, Blocks.snow);
		world.setBlock(i + 2, j + 1, k + 10, Blocks.snow);
		world.setBlock(i + 2, j + 1, k + 11, Blocks.snow);
		world.setBlock(i + 2, j + 1, k + 12, Blocks.snow);
		world.setBlock(i + 2, j + 1, k + 13, Blocks.snow);
		world.setBlock(i + 2, j + 1, k + 14, Blocks.snow);
		world.setBlock(i + 2, j + 1, k + 15, Blocks.snow);
		world.setBlock(i + 2, j + 1, k + 16, Blocks.snow);
		world.setBlock(i + 2, j + 1, k + 17, Blocks.snow);
		world.setBlock(i + 2, j + 1, k + 18, Blocks.snow);
		world.setBlock(i + 2, j + 1, k + 19, Blocks.snow);
		world.setBlock(i + 2, j + 1, k + 20, Blocks.snow);
		world.setBlock(i + 2, j + 1, k + 21, Blocks.snow);
		world.setBlock(i + 2, j + 1, k + 22, Blocks.snow);
		world.setBlock(i + 2, j + 1, k + 23, Blocks.snow);
		world.setBlock(i + 2, j + 1, k + 24, Blocks.snow);
		world.setBlock(i + 2, j + 1, k + 25, Blocks.snow);
		world.setBlock(i + 2, j + 1, k + 26, Blocks.snow);
		world.setBlock(i + 2, j + 1, k + 27, Blocks.snow);
		world.setBlock(i + 2, j + 1, k + 28, Blocks.snow);
		world.setBlock(i + 2, j + 1, k + 29, Blocks.snow);
		world.setBlock(i + 2, j + 1, k + 30, Blocks.snow);
		world.setBlock(i + 2, j + 1, k + 31, Blocks.snow);
		world.setBlock(i + 2, j + 1, k + 32, Blocks.snow);
		world.setBlock(i + 2, j + 2, k + 0, Blocks.snow);
		world.setBlock(i + 2, j + 2, k + 1, Blocks.snow);
		world.setBlock(i + 2, j + 2, k + 2, Blocks.snow);
		world.setBlock(i + 2, j + 2, k + 3, Blocks.snow);
		world.setBlock(i + 2, j + 2, k + 4, Blocks.snow);
		world.setBlock(i + 2, j + 2, k + 5, Blocks.snow);
		world.setBlock(i + 2, j + 2, k + 6, Blocks.snow);
		world.setBlock(i + 2, j + 2, k + 7, Blocks.snow);
		world.setBlock(i + 2, j + 2, k + 8, Blocks.snow);
		world.setBlock(i + 2, j + 2, k + 9, Blocks.snow);
		world.setBlock(i + 2, j + 2, k + 10, Blocks.snow);
		world.setBlock(i + 2, j + 2, k + 11, Blocks.snow);
		world.setBlock(i + 2, j + 2, k + 12, Blocks.snow);
		world.setBlock(i + 2, j + 2, k + 13, Blocks.snow);
		world.setBlock(i + 2, j + 2, k + 14, Blocks.snow);
		world.setBlock(i + 2, j + 2, k + 15, Blocks.snow);
		world.setBlock(i + 2, j + 2, k + 16, Blocks.snow);
		world.setBlock(i + 2, j + 2, k + 17, Blocks.snow);
		world.setBlock(i + 2, j + 2, k + 18, Blocks.snow);
		world.setBlock(i + 2, j + 2, k + 19, Blocks.snow);
		world.setBlock(i + 2, j + 2, k + 20, Blocks.snow);
		world.setBlock(i + 2, j + 2, k + 21, Blocks.snow);
		world.setBlock(i + 2, j + 2, k + 22, Blocks.snow);
		world.setBlock(i + 2, j + 2, k + 23, Blocks.snow);
		world.setBlock(i + 2, j + 2, k + 24, Blocks.snow);
		world.setBlock(i + 2, j + 2, k + 25, Blocks.snow);
		world.setBlock(i + 2, j + 2, k + 26, Blocks.snow);
		world.setBlock(i + 2, j + 2, k + 27, Blocks.snow);
		world.setBlock(i + 2, j + 2, k + 28, Blocks.snow);
		world.setBlock(i + 2, j + 2, k + 29, Blocks.snow);
		world.setBlock(i + 2, j + 2, k + 30, Blocks.snow);
		world.setBlock(i + 2, j + 2, k + 31, Blocks.snow);
		world.setBlock(i + 2, j + 2, k + 32, Blocks.snow);
		world.setBlock(i + 2, j + 3, k + 0, Blocks.snow);
		world.setBlock(i + 2, j + 3, k + 1, Blocks.snow);
		world.setBlock(i + 2, j + 3, k + 2, Blocks.snow);
		world.setBlock(i + 2, j + 3, k + 3, Blocks.snow);
		world.setBlock(i + 2, j + 3, k + 4, Blocks.snow);
		world.setBlock(i + 2, j + 3, k + 5, Blocks.snow);
		world.setBlock(i + 2, j + 3, k + 6, Blocks.snow);
		world.setBlock(i + 2, j + 3, k + 7, Blocks.snow);
		world.setBlock(i + 2, j + 3, k + 8, Blocks.snow);
		world.setBlock(i + 2, j + 3, k + 9, Blocks.snow);
		world.setBlock(i + 2, j + 3, k + 10, Blocks.snow);
		world.setBlock(i + 2, j + 3, k + 11, Blocks.snow);
		world.setBlock(i + 2, j + 3, k + 12, Blocks.snow);
		world.setBlock(i + 2, j + 3, k + 13, Blocks.snow);
		world.setBlock(i + 2, j + 3, k + 14, Blocks.snow);
		world.setBlock(i + 2, j + 3, k + 15, Blocks.snow);
		world.setBlock(i + 2, j + 3, k + 16, Blocks.snow);
		world.setBlock(i + 2, j + 3, k + 17, Blocks.snow);
		world.setBlock(i + 2, j + 3, k + 18, Blocks.snow);
		world.setBlock(i + 2, j + 3, k + 19, Blocks.snow);
		world.setBlock(i + 2, j + 3, k + 20, Blocks.snow);
		world.setBlock(i + 2, j + 3, k + 21, Blocks.snow);
		world.setBlock(i + 2, j + 3, k + 22, Blocks.snow);
		world.setBlock(i + 2, j + 3, k + 23, Blocks.snow);
		world.setBlock(i + 2, j + 3, k + 24, Blocks.snow);
		world.setBlock(i + 2, j + 3, k + 25, Blocks.snow);
		world.setBlock(i + 2, j + 3, k + 26, Blocks.snow);
		world.setBlock(i + 2, j + 3, k + 27, Blocks.snow);
		world.setBlock(i + 2, j + 3, k + 28, Blocks.snow);
		world.setBlock(i + 2, j + 3, k + 29, Blocks.snow);
		world.setBlock(i + 2, j + 3, k + 30, Blocks.snow);
		world.setBlock(i + 2, j + 3, k + 31, Blocks.snow);
		world.setBlock(i + 2, j + 3, k + 32, Blocks.snow);
		world.setBlock(i + 2, j + 4, k + 0, Blocks.snow);
		world.setBlock(i + 2, j + 4, k + 1, Blocks.snow);
		world.setBlock(i + 2, j + 4, k + 2, Blocks.snow);
		world.setBlock(i + 2, j + 4, k + 3, Blocks.snow);
		world.setBlock(i + 2, j + 4, k + 4, Blocks.snow);
		world.setBlock(i + 2, j + 4, k + 5, Blocks.snow);
		world.setBlock(i + 2, j + 4, k + 6, Blocks.snow);
		world.setBlock(i + 2, j + 4, k + 7, Blocks.snow);
		world.setBlock(i + 2, j + 4, k + 8, Blocks.snow);
		world.setBlock(i + 2, j + 4, k + 9, Blocks.snow);
		world.setBlock(i + 2, j + 4, k + 10, Blocks.snow);
		world.setBlock(i + 2, j + 4, k + 11, Blocks.snow);
		world.setBlock(i + 2, j + 4, k + 12, Blocks.snow);
		world.setBlock(i + 2, j + 4, k + 13, Blocks.snow);
		world.setBlock(i + 2, j + 4, k + 14, Blocks.snow);
		world.setBlock(i + 2, j + 4, k + 15, Blocks.snow);
		world.setBlock(i + 2, j + 4, k + 16, Blocks.snow);
		world.setBlock(i + 2, j + 4, k + 17, Blocks.snow);
		world.setBlock(i + 2, j + 4, k + 18, Blocks.snow);
		world.setBlock(i + 2, j + 4, k + 19, Blocks.snow);
		world.setBlock(i + 2, j + 4, k + 20, Blocks.snow);
		world.setBlock(i + 2, j + 4, k + 21, Blocks.snow);
		world.setBlock(i + 2, j + 4, k + 22, Blocks.snow);
		world.setBlock(i + 2, j + 4, k + 23, Blocks.snow);
		world.setBlock(i + 2, j + 4, k + 24, Blocks.snow);
		world.setBlock(i + 2, j + 4, k + 25, Blocks.snow);
		world.setBlock(i + 2, j + 4, k + 26, Blocks.snow);
		world.setBlock(i + 2, j + 4, k + 27, Blocks.snow);
		world.setBlock(i + 2, j + 4, k + 28, Blocks.snow);
		world.setBlock(i + 2, j + 4, k + 29, Blocks.snow);
		world.setBlock(i + 2, j + 4, k + 30, Blocks.snow);
		world.setBlock(i + 2, j + 4, k + 31, Blocks.snow);
		world.setBlock(i + 2, j + 4, k + 32, Blocks.snow);
		world.setBlock(i + 2, j + 5, k + 7, Blocks.ice);
		world.setBlock(i + 2, j + 5, k + 8, Blocks.ice);
		world.setBlock(i + 2, j + 5, k + 12, Blocks.ice);
		world.setBlock(i + 2, j + 5, k + 13, Blocks.ice);
		world.setBlock(i + 2, j + 5, k + 14, Blocks.ice);
		world.setBlock(i + 2, j + 5, k + 15, Blocks.ice);
		world.setBlock(i + 2, j + 5, k + 16, Blocks.ice);
		world.setBlock(i + 2, j + 5, k + 17, Blocks.ice);
		world.setBlock(i + 2, j + 5, k + 18, Blocks.ice);
		world.setBlock(i + 2, j + 5, k + 19, Blocks.ice);
		world.setBlock(i + 2, j + 5, k + 20, Blocks.ice);
		world.setBlock(i + 2, j + 5, k + 24, Blocks.ice);
		world.setBlock(i + 2, j + 5, k + 25, Blocks.ice);
		world.setBlock(i + 2, j + 6, k + 7, Blocks.ice);
		world.setBlock(i + 2, j + 6, k + 8, Blocks.ice);
		world.setBlock(i + 2, j + 6, k + 12, Blocks.ice);
		world.setBlock(i + 2, j + 6, k + 13, Blocks.ice);
		world.setBlock(i + 2, j + 6, k + 14, Blocks.ice);
		world.setBlock(i + 2, j + 6, k + 15, Blocks.ice);
		world.setBlock(i + 2, j + 6, k + 16, Blocks.ice);
		world.setBlock(i + 2, j + 6, k + 17, Blocks.ice);
		world.setBlock(i + 2, j + 6, k + 18, Blocks.ice);
		world.setBlock(i + 2, j + 6, k + 19, Blocks.ice);
		world.setBlock(i + 2, j + 6, k + 20, Blocks.ice);
		world.setBlock(i + 2, j + 6, k + 24, Blocks.ice);
		world.setBlock(i + 2, j + 6, k + 25, Blocks.ice);
		world.setBlock(i + 2, j + 7, k + 7, Blocks.ice);
		world.setBlock(i + 2, j + 7, k + 8, Blocks.ice);
		world.setBlock(i + 2, j + 7, k + 12, Blocks.ice);
		world.setBlock(i + 2, j + 7, k + 13, Blocks.ice);
		world.setBlock(i + 2, j + 7, k + 14, Blocks.ice);
		world.setBlock(i + 2, j + 7, k + 15, Blocks.ice);
		world.setBlock(i + 2, j + 7, k + 16, Blocks.ice);
		world.setBlock(i + 2, j + 7, k + 17, Blocks.ice);
		world.setBlock(i + 2, j + 7, k + 18, Blocks.ice);
		world.setBlock(i + 2, j + 7, k + 19, Blocks.ice);
		world.setBlock(i + 2, j + 7, k + 20, Blocks.ice);
		world.setBlock(i + 2, j + 7, k + 24, Blocks.ice);
		world.setBlock(i + 2, j + 7, k + 25, Blocks.ice);
		world.setBlock(i + 2, j + 8, k + 7, Blocks.ice);
		world.setBlock(i + 2, j + 8, k + 8, Blocks.ice);
		world.setBlock(i + 2, j + 8, k + 9, Blocks.ice);
		world.setBlock(i + 2, j + 8, k + 12, Blocks.ice);
		world.setBlock(i + 2, j + 8, k + 13, Blocks.ice);
		world.setBlock(i + 2, j + 8, k + 14, Blocks.ice);
		world.setBlock(i + 2, j + 8, k + 15, Blocks.ice);
		world.setBlock(i + 2, j + 8, k + 16, Blocks.ice);
		world.setBlock(i + 2, j + 8, k + 17, Blocks.ice);
		world.setBlock(i + 2, j + 8, k + 18, Blocks.ice);
		world.setBlock(i + 2, j + 8, k + 19, Blocks.ice);
		world.setBlock(i + 2, j + 8, k + 20, Blocks.ice);
		world.setBlock(i + 2, j + 8, k + 21, Blocks.ice);
		world.setBlock(i + 2, j + 8, k + 24, Blocks.ice);
		world.setBlock(i + 2, j + 8, k + 25, Blocks.ice);
		world.setBlock(i + 2, j + 9, k + 9, Blocks.ice);
		world.setBlock(i + 2, j + 9, k + 10, Blocks.ice);
		world.setBlock(i + 2, j + 9, k + 11, Blocks.ice);
		world.setBlock(i + 2, j + 9, k + 21, Blocks.ice);
		world.setBlock(i + 2, j + 9, k + 22, Blocks.ice);
		world.setBlock(i + 2, j + 9, k + 23, Blocks.ice);
		world.setBlock(i + 3, j + 0, k + 0, Blocks.stone);
		world.setBlock(i + 3, j + 0, k + 1, Blocks.stone);
		world.setBlock(i + 3, j + 0, k + 2, Blocks.stone);
		world.setBlock(i + 3, j + 0, k + 3, Blocks.stone);
		world.setBlock(i + 3, j + 0, k + 4, Blocks.stone);
		world.setBlock(i + 3, j + 0, k + 5, Blocks.stone);
		world.setBlock(i + 3, j + 0, k + 6, Blocks.stone);
		world.setBlock(i + 3, j + 0, k + 7, Blocks.stone);
		world.setBlock(i + 3, j + 0, k + 8, Blocks.stone);
		world.setBlock(i + 3, j + 0, k + 9, Blocks.stone);
		world.setBlock(i + 3, j + 0, k + 10, Blocks.stone);
		world.setBlock(i + 3, j + 0, k + 11, Blocks.stone);
		world.setBlock(i + 3, j + 0, k + 12, Blocks.stone);
		world.setBlock(i + 3, j + 0, k + 13, Blocks.stone);
		world.setBlock(i + 3, j + 0, k + 14, Blocks.stone);
		world.setBlock(i + 3, j + 0, k + 15, Blocks.stone);
		world.setBlock(i + 3, j + 0, k + 16, Blocks.stone);
		world.setBlock(i + 3, j + 0, k + 17, Blocks.stone);
		world.setBlock(i + 3, j + 0, k + 18, Blocks.stone);
		world.setBlock(i + 3, j + 0, k + 19, Blocks.stone);
		world.setBlock(i + 3, j + 0, k + 20, Blocks.stone);
		world.setBlock(i + 3, j + 0, k + 21, Blocks.stone);
		world.setBlock(i + 3, j + 0, k + 22, Blocks.stone);
		world.setBlock(i + 3, j + 0, k + 23, Blocks.stone);
		world.setBlock(i + 3, j + 0, k + 24, Blocks.stone);
		world.setBlock(i + 3, j + 0, k + 25, Blocks.stone);
		world.setBlock(i + 3, j + 0, k + 26, Blocks.stone);
		world.setBlock(i + 3, j + 0, k + 27, Blocks.stone);
		world.setBlock(i + 3, j + 0, k + 28, Blocks.stone);
		world.setBlock(i + 3, j + 0, k + 29, Blocks.stone);
		world.setBlock(i + 3, j + 0, k + 30, Blocks.stone);
		world.setBlock(i + 3, j + 0, k + 31, Blocks.stone);
		world.setBlock(i + 3, j + 0, k + 32, Blocks.stone);
		world.setBlock(i + 3, j + 1, k + 0, Blocks.snow);
		world.setBlock(i + 3, j + 1, k + 1, Blocks.snow);
		world.setBlock(i + 3, j + 1, k + 2, Blocks.snow);
		world.setBlock(i + 3, j + 1, k + 3, Blocks.snow);
		world.setBlock(i + 3, j + 1, k + 4, Blocks.snow);
		world.setBlock(i + 3, j + 1, k + 5, Blocks.snow);
		world.setBlock(i + 3, j + 1, k + 6, Blocks.snow);
		world.setBlock(i + 3, j + 1, k + 7, Blocks.snow);
		world.setBlock(i + 3, j + 1, k + 8, Blocks.snow);
		world.setBlock(i + 3, j + 1, k + 9, Blocks.snow);
		world.setBlock(i + 3, j + 1, k + 10, Blocks.snow);
		world.setBlock(i + 3, j + 1, k + 11, Blocks.snow);
		world.setBlock(i + 3, j + 1, k + 12, Blocks.snow);
		world.setBlock(i + 3, j + 1, k + 13, Blocks.snow);
		world.setBlock(i + 3, j + 1, k + 14, Blocks.snow);
		world.setBlock(i + 3, j + 1, k + 15, Blocks.snow);
		world.setBlock(i + 3, j + 1, k + 16, Blocks.snow);
		world.setBlock(i + 3, j + 1, k + 17, Blocks.snow);
		world.setBlock(i + 3, j + 1, k + 18, Blocks.snow);
		world.setBlock(i + 3, j + 1, k + 19, Blocks.snow);
		world.setBlock(i + 3, j + 1, k + 20, Blocks.snow);
		world.setBlock(i + 3, j + 1, k + 21, Blocks.snow);
		world.setBlock(i + 3, j + 1, k + 22, Blocks.snow);
		world.setBlock(i + 3, j + 1, k + 23, Blocks.snow);
		world.setBlock(i + 3, j + 1, k + 24, Blocks.snow);
		world.setBlock(i + 3, j + 1, k + 25, Blocks.snow);
		world.setBlock(i + 3, j + 1, k + 26, Blocks.snow);
		world.setBlock(i + 3, j + 1, k + 27, Blocks.snow);
		world.setBlock(i + 3, j + 1, k + 28, Blocks.snow);
		world.setBlock(i + 3, j + 1, k + 29, Blocks.snow);
		world.setBlock(i + 3, j + 1, k + 30, Blocks.snow);
		world.setBlock(i + 3, j + 1, k + 31, Blocks.snow);
		world.setBlock(i + 3, j + 1, k + 32, Blocks.snow);
		world.setBlock(i + 3, j + 2, k + 0, Blocks.snow);
		world.setBlock(i + 3, j + 2, k + 1, Blocks.snow);
		world.setBlock(i + 3, j + 2, k + 2, Blocks.snow);
		world.setBlock(i + 3, j + 2, k + 3, Blocks.snow);
		world.setBlock(i + 3, j + 2, k + 4, Blocks.snow);
		world.setBlock(i + 3, j + 2, k + 5, Blocks.snow);
		world.setBlock(i + 3, j + 2, k + 6, Blocks.snow);
		world.setBlock(i + 3, j + 2, k + 7, Blocks.snow);
		world.setBlock(i + 3, j + 2, k + 8, Blocks.snow);
		world.setBlock(i + 3, j + 2, k + 9, Blocks.snow);
		world.setBlock(i + 3, j + 2, k + 10, Blocks.snow);
		world.setBlock(i + 3, j + 2, k + 11, Blocks.snow);
		world.setBlock(i + 3, j + 2, k + 12, Blocks.snow);
		world.setBlock(i + 3, j + 2, k + 13, Blocks.snow);
		world.setBlock(i + 3, j + 2, k + 14, Blocks.snow);
		world.setBlock(i + 3, j + 2, k + 15, Blocks.snow);
		world.setBlock(i + 3, j + 2, k + 16, Blocks.snow);
		world.setBlock(i + 3, j + 2, k + 17, Blocks.snow);
		world.setBlock(i + 3, j + 2, k + 18, Blocks.snow);
		world.setBlock(i + 3, j + 2, k + 19, Blocks.snow);
		world.setBlock(i + 3, j + 2, k + 20, Blocks.snow);
		world.setBlock(i + 3, j + 2, k + 21, Blocks.snow);
		world.setBlock(i + 3, j + 2, k + 22, Blocks.snow);
		world.setBlock(i + 3, j + 2, k + 23, Blocks.snow);
		world.setBlock(i + 3, j + 2, k + 24, Blocks.snow);
		world.setBlock(i + 3, j + 2, k + 25, Blocks.snow);
		world.setBlock(i + 3, j + 2, k + 26, Blocks.snow);
		world.setBlock(i + 3, j + 2, k + 27, Blocks.snow);
		world.setBlock(i + 3, j + 2, k + 28, Blocks.snow);
		world.setBlock(i + 3, j + 2, k + 29, Blocks.snow);
		world.setBlock(i + 3, j + 2, k + 30, Blocks.snow);
		world.setBlock(i + 3, j + 2, k + 31, Blocks.snow);
		world.setBlock(i + 3, j + 2, k + 32, Blocks.snow);
		world.setBlock(i + 3, j + 3, k + 0, Blocks.snow);
		world.setBlock(i + 3, j + 3, k + 1, Blocks.snow);
		world.setBlock(i + 3, j + 3, k + 2, Blocks.snow);
		world.setBlock(i + 3, j + 3, k + 3, Blocks.snow);
		world.setBlock(i + 3, j + 3, k + 4, Blocks.snow);
		world.setBlock(i + 3, j + 3, k + 5, Blocks.snow);
		world.setBlock(i + 3, j + 3, k + 6, Blocks.snow);
		world.setBlock(i + 3, j + 3, k + 7, Blocks.snow);
		world.setBlock(i + 3, j + 3, k + 8, Blocks.snow);
		world.setBlock(i + 3, j + 3, k + 9, Blocks.snow);
		world.setBlock(i + 3, j + 3, k + 10, Blocks.snow);
		world.setBlock(i + 3, j + 3, k + 11, Blocks.snow);
		world.setBlock(i + 3, j + 3, k + 12, Blocks.snow);
		world.setBlock(i + 3, j + 3, k + 13, Blocks.snow);
		world.setBlock(i + 3, j + 3, k + 14, Blocks.snow);
		world.setBlock(i + 3, j + 3, k + 15, Blocks.snow);
		world.setBlock(i + 3, j + 3, k + 16, Blocks.snow);
		world.setBlock(i + 3, j + 3, k + 17, Blocks.snow);
		world.setBlock(i + 3, j + 3, k + 18, Blocks.snow);
		world.setBlock(i + 3, j + 3, k + 19, Blocks.snow);
		world.setBlock(i + 3, j + 3, k + 20, Blocks.snow);
		world.setBlock(i + 3, j + 3, k + 21, Blocks.snow);
		world.setBlock(i + 3, j + 3, k + 22, Blocks.snow);
		world.setBlock(i + 3, j + 3, k + 23, Blocks.snow);
		world.setBlock(i + 3, j + 3, k + 24, Blocks.snow);
		world.setBlock(i + 3, j + 3, k + 25, Blocks.snow);
		world.setBlock(i + 3, j + 3, k + 26, Blocks.snow);
		world.setBlock(i + 3, j + 3, k + 27, Blocks.snow);
		world.setBlock(i + 3, j + 3, k + 28, Blocks.snow);
		world.setBlock(i + 3, j + 3, k + 29, Blocks.snow);
		world.setBlock(i + 3, j + 3, k + 30, Blocks.snow);
		world.setBlock(i + 3, j + 3, k + 31, Blocks.snow);
		world.setBlock(i + 3, j + 3, k + 32, Blocks.snow);
		world.setBlock(i + 3, j + 4, k + 0, Blocks.snow);
		world.setBlock(i + 3, j + 4, k + 1, Blocks.snow);
		world.setBlock(i + 3, j + 4, k + 2, Blocks.snow);
		world.setBlock(i + 3, j + 4, k + 3, Blocks.snow);
		world.setBlock(i + 3, j + 4, k + 4, Blocks.snow);
		world.setBlock(i + 3, j + 4, k + 5, Blocks.snow);
		world.setBlock(i + 3, j + 4, k + 6, Blocks.snow);
		world.setBlock(i + 3, j + 4, k + 7, Blocks.snow);
		world.setBlock(i + 3, j + 4, k + 8, Blocks.snow);
		world.setBlock(i + 3, j + 4, k + 9, Blocks.snow);
		world.setBlock(i + 3, j + 4, k + 10, Blocks.snow);
		world.setBlock(i + 3, j + 4, k + 11, Blocks.snow);
		world.setBlock(i + 3, j + 4, k + 12, Blocks.snow);
		world.setBlock(i + 3, j + 4, k + 13, Blocks.snow);
		world.setBlock(i + 3, j + 4, k + 14, Blocks.snow);
		world.setBlock(i + 3, j + 4, k + 15, Blocks.snow);
		world.setBlock(i + 3, j + 4, k + 16, Blocks.snow);
		world.setBlock(i + 3, j + 4, k + 17, Blocks.snow);
		world.setBlock(i + 3, j + 4, k + 18, Blocks.snow);
		world.setBlock(i + 3, j + 4, k + 19, Blocks.snow);
		world.setBlock(i + 3, j + 4, k + 20, Blocks.snow);
		world.setBlock(i + 3, j + 4, k + 21, Blocks.snow);
		world.setBlock(i + 3, j + 4, k + 22, Blocks.snow);
		world.setBlock(i + 3, j + 4, k + 23, Blocks.snow);
		world.setBlock(i + 3, j + 4, k + 24, Blocks.snow);
		world.setBlock(i + 3, j + 4, k + 25, Blocks.snow);
		world.setBlock(i + 3, j + 4, k + 26, Blocks.snow);
		world.setBlock(i + 3, j + 4, k + 27, Blocks.snow);
		world.setBlock(i + 3, j + 4, k + 28, Blocks.snow);
		world.setBlock(i + 3, j + 4, k + 29, Blocks.snow);
		world.setBlock(i + 3, j + 4, k + 30, Blocks.snow);
		world.setBlock(i + 3, j + 4, k + 31, Blocks.snow);
		world.setBlock(i + 3, j + 4, k + 32, Blocks.snow);
		world.setBlock(i + 3, j + 5, k + 6, Blocks.ice);
		world.setBlock(i + 3, j + 5, k + 9, Blocks.ice);
		world.setBlock(i + 3, j + 5, k + 10, Blocks.ice);
		world.setBlock(i + 3, j + 5, k + 11, Blocks.ice);
		world.setBlock(i + 3, j + 5, k + 14, Blocks.snow);
		world.setBlock(i + 3, j + 5, k + 15, Blocks.snow);
		world.setBlock(i + 3, j + 5, k + 16, Blocks.snow);
		world.setBlock(i + 3, j + 5, k + 17, Blocks.snow);
		world.setBlock(i + 3, j + 5, k + 18, Blocks.snow);
		world.setBlock(i + 3, j + 5, k + 21, Blocks.ice);
		world.setBlock(i + 3, j + 5, k + 22, Blocks.ice);
		world.setBlock(i + 3, j + 5, k + 23, Blocks.ice);
		world.setBlock(i + 3, j + 5, k + 26, Blocks.ice);
		world.setBlock(i + 3, j + 6, k + 6, Blocks.ice);
		world.setBlock(i + 3, j + 6, k + 9, Blocks.ice);
		world.setBlock(i + 3, j + 6, k + 10, Blocks.ice);
		world.setBlock(i + 3, j + 6, k + 11, Blocks.ice);
		world.setBlock(i + 3, j + 6, k + 14, Blocks.snow);
		world.setBlock(i + 3, j + 6, k + 15, Blocks.snow);
		world.setBlock(i + 3, j + 6, k + 16, Blocks.snow);
		world.setBlock(i + 3, j + 6, k + 17, Blocks.snow);
		world.setBlock(i + 3, j + 6, k + 18, Blocks.snow);
		world.setBlock(i + 3, j + 6, k + 21, Blocks.ice);
		world.setBlock(i + 3, j + 6, k + 22, Blocks.ice);
		world.setBlock(i + 3, j + 6, k + 23, Blocks.ice);
		world.setBlock(i + 3, j + 6, k + 26, Blocks.ice);
		world.setBlock(i + 3, j + 7, k + 6, Blocks.ice);
		world.setBlock(i + 3, j + 7, k + 9, Blocks.ice);
		world.setBlock(i + 3, j + 7, k + 10, Blocks.ice);
		world.setBlock(i + 3, j + 7, k + 11, Blocks.ice);
		world.setBlock(i + 3, j + 7, k + 14, Blocks.snow);
		world.setBlock(i + 3, j + 7, k + 15, Blocks.snow);
		world.setBlock(i + 3, j + 7, k + 16, Blocks.snow);
		world.setBlock(i + 3, j + 7, k + 17, Blocks.snow);
		world.setBlock(i + 3, j + 7, k + 18, Blocks.snow);
		world.setBlock(i + 3, j + 7, k + 21, Blocks.ice);
		world.setBlock(i + 3, j + 7, k + 22, Blocks.ice);
		world.setBlock(i + 3, j + 7, k + 23, Blocks.ice);
		world.setBlock(i + 3, j + 7, k + 26, Blocks.ice);
		world.setBlock(i + 3, j + 8, k + 6, Blocks.ice);
		world.setBlock(i + 3, j + 8, k + 7, Blocks.ice);
		world.setBlock(i + 3, j + 8, k + 9, Blocks.ice);
		world.setBlock(i + 3, j + 8, k + 10, Blocks.ice);
		world.setBlock(i + 3, j + 8, k + 11, Blocks.ice);
		world.setBlock(i + 3, j + 8, k + 21, Blocks.ice);
		world.setBlock(i + 3, j + 8, k + 22, Blocks.ice);
		world.setBlock(i + 3, j + 8, k + 23, Blocks.ice);
		world.setBlock(i + 3, j + 8, k + 24, Blocks.ice);
		world.setBlock(i + 3, j + 8, k + 25, Blocks.ice);
		world.setBlock(i + 3, j + 8, k + 26, Blocks.ice);
		world.setBlock(i + 3, j + 9, k + 7, Blocks.ice);
		world.setBlock(i + 3, j + 9, k + 8, Blocks.ice);
		world.setBlock(i + 3, j + 9, k + 24, Blocks.ice);
		world.setBlock(i + 3, j + 9, k + 25, Blocks.ice);
		world.setBlock(i + 4, j + 0, k + 0, Blocks.stone);
		world.setBlock(i + 4, j + 0, k + 1, Blocks.stone);
		world.setBlock(i + 4, j + 0, k + 2, Blocks.stone);
		world.setBlock(i + 4, j + 0, k + 3, Blocks.stone);
		world.setBlock(i + 4, j + 0, k + 4, Blocks.stone);
		world.setBlock(i + 4, j + 0, k + 5, Blocks.stone);
		world.setBlock(i + 4, j + 0, k + 6, Blocks.stone);
		world.setBlock(i + 4, j + 0, k + 7, Blocks.stone);
		world.setBlock(i + 4, j + 0, k + 8, Blocks.stone);
		world.setBlock(i + 4, j + 0, k + 9, Blocks.stone);
		world.setBlock(i + 4, j + 0, k + 10, Blocks.stone);
		world.setBlock(i + 4, j + 0, k + 11, Blocks.stone);
		world.setBlock(i + 4, j + 0, k + 12, Blocks.stone);
		world.setBlock(i + 4, j + 0, k + 13, Blocks.stone);
		world.setBlock(i + 4, j + 0, k + 14, Blocks.stone);
		world.setBlock(i + 4, j + 0, k + 15, Blocks.stone);
		world.setBlock(i + 4, j + 0, k + 16, Blocks.stone);
		world.setBlock(i + 4, j + 0, k + 17, Blocks.stone);
		world.setBlock(i + 4, j + 0, k + 18, Blocks.stone);
		world.setBlock(i + 4, j + 0, k + 19, Blocks.stone);
		world.setBlock(i + 4, j + 0, k + 20, Blocks.stone);
		world.setBlock(i + 4, j + 0, k + 21, Blocks.stone);
		world.setBlock(i + 4, j + 0, k + 22, Blocks.stone);
		world.setBlock(i + 4, j + 0, k + 23, Blocks.stone);
		world.setBlock(i + 4, j + 0, k + 24, Blocks.stone);
		world.setBlock(i + 4, j + 0, k + 25, Blocks.stone);
		world.setBlock(i + 4, j + 0, k + 26, Blocks.stone);
		world.setBlock(i + 4, j + 0, k + 27, Blocks.stone);
		world.setBlock(i + 4, j + 0, k + 28, Blocks.stone);
		world.setBlock(i + 4, j + 0, k + 29, Blocks.stone);
		world.setBlock(i + 4, j + 0, k + 30, Blocks.stone);
		world.setBlock(i + 4, j + 0, k + 31, Blocks.stone);
		world.setBlock(i + 4, j + 0, k + 32, Blocks.stone);
		world.setBlock(i + 4, j + 1, k + 0, Blocks.snow);
		world.setBlock(i + 4, j + 1, k + 1, Blocks.snow);
		world.setBlock(i + 4, j + 1, k + 2, Blocks.snow);
		world.setBlock(i + 4, j + 1, k + 3, Blocks.snow);
		world.setBlock(i + 4, j + 1, k + 4, Blocks.snow);
		world.setBlock(i + 4, j + 1, k + 5, Blocks.snow);
		world.setBlock(i + 4, j + 1, k + 6, Blocks.snow);
		world.setBlock(i + 4, j + 1, k + 7, Blocks.snow);
		world.setBlock(i + 4, j + 1, k + 8, Blocks.snow);
		world.setBlock(i + 4, j + 1, k + 9, Blocks.snow);
		world.setBlock(i + 4, j + 1, k + 10, Blocks.snow);
		world.setBlock(i + 4, j + 1, k + 11, Blocks.snow);
		world.setBlock(i + 4, j + 1, k + 12, Blocks.snow);
		world.setBlock(i + 4, j + 1, k + 13, Blocks.snow);
		world.setBlock(i + 4, j + 1, k + 14, Blocks.snow);
		world.setBlock(i + 4, j + 1, k + 15, Blocks.snow);
		world.setBlock(i + 4, j + 1, k + 16, Blocks.snow);
		world.setBlock(i + 4, j + 1, k + 17, Blocks.snow);
		world.setBlock(i + 4, j + 1, k + 18, Blocks.snow);
		world.setBlock(i + 4, j + 1, k + 19, Blocks.snow);
		world.setBlock(i + 4, j + 1, k + 20, Blocks.snow);
		world.setBlock(i + 4, j + 1, k + 21, Blocks.snow);
		world.setBlock(i + 4, j + 1, k + 22, Blocks.snow);
		world.setBlock(i + 4, j + 1, k + 23, Blocks.snow);
		world.setBlock(i + 4, j + 1, k + 24, Blocks.snow);
		world.setBlock(i + 4, j + 1, k + 25, Blocks.snow);
		world.setBlock(i + 4, j + 1, k + 26, Blocks.snow);
		world.setBlock(i + 4, j + 1, k + 27, Blocks.snow);
		world.setBlock(i + 4, j + 1, k + 28, Blocks.snow);
		world.setBlock(i + 4, j + 1, k + 29, Blocks.snow);
		world.setBlock(i + 4, j + 1, k + 30, Blocks.snow);
		world.setBlock(i + 4, j + 1, k + 31, Blocks.snow);
		world.setBlock(i + 4, j + 1, k + 32, Blocks.snow);
		world.setBlock(i + 4, j + 2, k + 0, Blocks.snow);
		world.setBlock(i + 4, j + 2, k + 1, Blocks.snow);
		world.setBlock(i + 4, j + 2, k + 2, Blocks.snow);
		world.setBlock(i + 4, j + 2, k + 3, Blocks.snow);
		world.setBlock(i + 4, j + 2, k + 4, Blocks.snow);
		world.setBlock(i + 4, j + 2, k + 5, Blocks.snow);
		world.setBlock(i + 4, j + 2, k + 6, Blocks.snow);
		world.setBlock(i + 4, j + 2, k + 7, Blocks.snow);
		world.setBlock(i + 4, j + 2, k + 8, Blocks.snow);
		world.setBlock(i + 4, j + 2, k + 9, Blocks.snow);
		world.setBlock(i + 4, j + 2, k + 10, Blocks.snow);
		world.setBlock(i + 4, j + 2, k + 11, Blocks.snow);
		world.setBlock(i + 4, j + 2, k + 12, Blocks.snow);
		world.setBlock(i + 4, j + 2, k + 13, Blocks.snow);
		world.setBlock(i + 4, j + 2, k + 14, Blocks.snow);
		world.setBlock(i + 4, j + 2, k + 15, Blocks.snow);
		world.setBlock(i + 4, j + 2, k + 16, Blocks.snow);
		world.setBlock(i + 4, j + 2, k + 17, Blocks.snow);
		world.setBlock(i + 4, j + 2, k + 18, Blocks.snow);
		world.setBlock(i + 4, j + 2, k + 19, Blocks.snow);
		world.setBlock(i + 4, j + 2, k + 20, Blocks.snow);
		world.setBlock(i + 4, j + 2, k + 21, Blocks.snow);
		world.setBlock(i + 4, j + 2, k + 22, Blocks.snow);
		world.setBlock(i + 4, j + 2, k + 23, Blocks.snow);
		world.setBlock(i + 4, j + 2, k + 24, Blocks.snow);
		world.setBlock(i + 4, j + 2, k + 25, Blocks.snow);
		world.setBlock(i + 4, j + 2, k + 26, Blocks.snow);
		world.setBlock(i + 4, j + 2, k + 27, Blocks.snow);
		world.setBlock(i + 4, j + 2, k + 28, Blocks.snow);
		world.setBlock(i + 4, j + 2, k + 29, Blocks.snow);
		world.setBlock(i + 4, j + 2, k + 30, Blocks.snow);
		world.setBlock(i + 4, j + 2, k + 31, Blocks.snow);
		world.setBlock(i + 4, j + 2, k + 32, Blocks.snow);
		world.setBlock(i + 4, j + 3, k + 0, Blocks.snow);
		world.setBlock(i + 4, j + 3, k + 1, Blocks.snow);
		world.setBlock(i + 4, j + 3, k + 2, Blocks.snow);
		world.setBlock(i + 4, j + 3, k + 3, Blocks.snow);
		world.setBlock(i + 4, j + 3, k + 4, Blocks.snow);
		world.setBlock(i + 4, j + 3, k + 5, Blocks.snow);
		world.setBlock(i + 4, j + 3, k + 6, Blocks.snow);
		world.setBlock(i + 4, j + 3, k + 7, Blocks.snow);
		world.setBlock(i + 4, j + 3, k + 8, Blocks.snow);
		world.setBlock(i + 4, j + 3, k + 9, Blocks.snow);
		world.setBlock(i + 4, j + 3, k + 10, Blocks.snow);
		world.setBlock(i + 4, j + 3, k + 11, Blocks.snow);
		world.setBlock(i + 4, j + 3, k + 12, Blocks.snow);
		world.setBlock(i + 4, j + 3, k + 13, Blocks.snow);
		world.setBlock(i + 4, j + 3, k + 14, Blocks.snow);
		world.setBlock(i + 4, j + 3, k + 15, Blocks.snow);
		world.setBlock(i + 4, j + 3, k + 16, Blocks.snow);
		world.setBlock(i + 4, j + 3, k + 17, Blocks.snow);
		world.setBlock(i + 4, j + 3, k + 18, Blocks.snow);
		world.setBlock(i + 4, j + 3, k + 19, Blocks.snow);
		world.setBlock(i + 4, j + 3, k + 20, Blocks.snow);
		world.setBlock(i + 4, j + 3, k + 21, Blocks.snow);
		world.setBlock(i + 4, j + 3, k + 22, Blocks.snow);
		world.setBlock(i + 4, j + 3, k + 23, Blocks.snow);
		world.setBlock(i + 4, j + 3, k + 24, Blocks.snow);
		world.setBlock(i + 4, j + 3, k + 25, Blocks.snow);
		world.setBlock(i + 4, j + 3, k + 26, Blocks.snow);
		world.setBlock(i + 4, j + 3, k + 27, Blocks.snow);
		world.setBlock(i + 4, j + 3, k + 28, Blocks.snow);
		world.setBlock(i + 4, j + 3, k + 29, Blocks.snow);
		world.setBlock(i + 4, j + 3, k + 30, Blocks.snow);
		world.setBlock(i + 4, j + 3, k + 31, Blocks.snow);
		world.setBlock(i + 4, j + 3, k + 32, Blocks.snow);
		world.setBlock(i + 4, j + 4, k + 0, Blocks.snow);
		world.setBlock(i + 4, j + 4, k + 1, Blocks.snow);
		world.setBlock(i + 4, j + 4, k + 2, Blocks.snow);
		world.setBlock(i + 4, j + 4, k + 3, Blocks.snow);
		world.setBlock(i + 4, j + 4, k + 4, Blocks.snow);
		world.setBlock(i + 4, j + 4, k + 5, Blocks.snow);
		world.setBlock(i + 4, j + 4, k + 6, Blocks.snow);
		world.setBlock(i + 4, j + 4, k + 7, Blocks.snow);
		world.setBlock(i + 4, j + 4, k + 8, Blocks.snow);
		world.setBlock(i + 4, j + 4, k + 9, Blocks.snow);
		world.setBlock(i + 4, j + 4, k + 10, Blocks.snow);
		world.setBlock(i + 4, j + 4, k + 11, Blocks.snow);
		world.setBlock(i + 4, j + 4, k + 12, Blocks.snow);
		world.setBlock(i + 4, j + 4, k + 13, Blocks.snow);
		world.setBlock(i + 4, j + 4, k + 14, Blocks.snow);
		world.setBlock(i + 4, j + 4, k + 15, Blocks.snow);
		world.setBlock(i + 4, j + 4, k + 16, Blocks.snow);
		world.setBlock(i + 4, j + 4, k + 17, Blocks.snow);
		world.setBlock(i + 4, j + 4, k + 18, Blocks.snow);
		world.setBlock(i + 4, j + 4, k + 19, Blocks.snow);
		world.setBlock(i + 4, j + 4, k + 20, Blocks.snow);
		world.setBlock(i + 4, j + 4, k + 21, Blocks.snow);
		world.setBlock(i + 4, j + 4, k + 22, Blocks.snow);
		world.setBlock(i + 4, j + 4, k + 23, Blocks.snow);
		world.setBlock(i + 4, j + 4, k + 24, Blocks.snow);
		world.setBlock(i + 4, j + 4, k + 25, Blocks.snow);
		world.setBlock(i + 4, j + 4, k + 26, Blocks.snow);
		world.setBlock(i + 4, j + 4, k + 27, Blocks.snow);
		world.setBlock(i + 4, j + 4, k + 28, Blocks.snow);
		world.setBlock(i + 4, j + 4, k + 29, Blocks.snow);
		world.setBlock(i + 4, j + 4, k + 30, Blocks.snow);
		world.setBlock(i + 4, j + 4, k + 31, Blocks.snow);
		world.setBlock(i + 4, j + 4, k + 32, Blocks.snow);
		world.setBlock(i + 4, j + 5, k + 5, Blocks.ice);
		world.setBlock(i + 4, j + 5, k + 7, Blocks.ice);
		world.setBlock(i + 4, j + 5, k + 8, Blocks.ice);
		world.setBlock(i + 4, j + 5, k + 13, Blocks.snow);
		world.setBlock(i + 4, j + 5, k + 14, Blocks.bookshelf);
		world.setBlock(i + 4, j + 5, k + 15, Blocks.bookshelf);
		world.setBlock(i + 4, j + 5, k + 16, Blocks.fence);
		world.setBlock(i + 4, j + 5, k + 17, Blocks.bookshelf);
		world.setBlock(i + 4, j + 5, k + 18, Blocks.bookshelf);
		world.setBlock(i + 4, j + 5, k + 19, Blocks.snow);
		world.setBlock(i + 4, j + 5, k + 24, Blocks.ice);
		world.setBlock(i + 4, j + 5, k + 25, Blocks.ice);
		world.setBlock(i + 4, j + 5, k + 27, Blocks.ice);
		world.setBlock(i + 4, j + 6, k + 5, Blocks.ice);
		world.setBlock(i + 4, j + 6, k + 7, Blocks.ice);
		world.setBlock(i + 4, j + 6, k + 8, Blocks.ice);
		world.setBlock(i + 4, j + 6, k + 13, Blocks.snow);
		world.setBlock(i + 4, j + 6, k + 14, Blocks.bookshelf);
		world.setBlock(i + 4, j + 6, k + 15, Blocks.bookshelf);
		world.setBlock(i + 4, j + 6, k + 16, Blocks.fence);
		world.setBlock(i + 4, j + 6, k + 17, Blocks.bookshelf);
		world.setBlock(i + 4, j + 6, k + 18, Blocks.bookshelf);
		world.setBlock(i + 4, j + 6, k + 19, Blocks.snow);
		world.setBlock(i + 4, j + 6, k + 24, Blocks.ice);
		world.setBlock(i + 4, j + 6, k + 25, Blocks.ice);
		world.setBlock(i + 4, j + 6, k + 27, Blocks.ice);
		world.setBlock(i + 4, j + 7, k + 5, Blocks.ice);
		world.setBlock(i + 4, j + 7, k + 7, Blocks.ice);
		world.setBlock(i + 4, j + 7, k + 8, Blocks.ice);
		world.setBlock(i + 4, j + 7, k + 13, Blocks.snow);
		world.setBlock(i + 4, j + 7, k + 14, Blocks.bookshelf);
		world.setBlock(i + 4, j + 7, k + 15, Blocks.bookshelf);
		world.setBlock(i + 4, j + 7, k + 16, Blocks.fence);
		world.setBlock(i + 4, j + 7, k + 17, Blocks.bookshelf);
		world.setBlock(i + 4, j + 7, k + 18, Blocks.bookshelf);
		world.setBlock(i + 4, j + 7, k + 19, Blocks.snow);
		world.setBlock(i + 4, j + 7, k + 24, Blocks.ice);
		world.setBlock(i + 4, j + 7, k + 25, Blocks.ice);
		world.setBlock(i + 4, j + 7, k + 27, Blocks.ice);
		world.setBlock(i + 4, j + 8, k + 5, Blocks.ice);
		world.setBlock(i + 4, j + 8, k + 6, Blocks.ice);
		world.setBlock(i + 4, j + 8, k + 7, Blocks.ice);
		world.setBlock(i + 4, j + 8, k + 8, Blocks.ice);
		world.setBlock(i + 4, j + 8, k + 14, Blocks.snow);
		world.setBlock(i + 4, j + 8, k + 15, Blocks.snow);
		world.setBlock(i + 4, j + 8, k + 16, Blocks.snow);
		world.setBlock(i + 4, j + 8, k + 17, Blocks.snow);
		world.setBlock(i + 4, j + 8, k + 18, Blocks.snow);
		world.setBlock(i + 4, j + 8, k + 24, Blocks.ice);
		world.setBlock(i + 4, j + 8, k + 25, Blocks.ice);
		world.setBlock(i + 4, j + 8, k + 26, Blocks.ice);
		world.setBlock(i + 4, j + 8, k + 27, Blocks.ice);
		world.setBlock(i + 4, j + 9, k + 6, Blocks.ice);
		world.setBlock(i + 4, j + 9, k + 26, Blocks.ice);
		world.setBlock(i + 5, j + 0, k + 0, Blocks.stone);
		world.setBlock(i + 5, j + 0, k + 1, Blocks.stone);
		world.setBlock(i + 5, j + 0, k + 2, Blocks.stone);
		world.setBlock(i + 5, j + 0, k + 3, Blocks.stone);
		world.setBlock(i + 5, j + 0, k + 4, Blocks.stone);
		world.setBlock(i + 5, j + 0, k + 5, Blocks.stone);
		world.setBlock(i + 5, j + 0, k + 6, Blocks.stone);
		world.setBlock(i + 5, j + 0, k + 7, Blocks.stone);
		world.setBlock(i + 5, j + 0, k + 8, Blocks.stone);
		world.setBlock(i + 5, j + 0, k + 9, Blocks.stone);
		world.setBlock(i + 5, j + 0, k + 10, Blocks.stone);
		world.setBlock(i + 5, j + 0, k + 11, Blocks.stone);
		world.setBlock(i + 5, j + 0, k + 12, Blocks.stone);
		world.setBlock(i + 5, j + 0, k + 13, Blocks.stone);
		world.setBlock(i + 5, j + 0, k + 14, Blocks.stone);
		world.setBlock(i + 5, j + 0, k + 15, Blocks.stone);
		world.setBlock(i + 5, j + 0, k + 16, Blocks.stone);
		world.setBlock(i + 5, j + 0, k + 17, Blocks.stone);
		world.setBlock(i + 5, j + 0, k + 18, Blocks.stone);
		world.setBlock(i + 5, j + 0, k + 19, Blocks.stone);
		world.setBlock(i + 5, j + 0, k + 20, Blocks.stone);
		world.setBlock(i + 5, j + 0, k + 21, Blocks.stone);
		world.setBlock(i + 5, j + 0, k + 22, Blocks.stone);
		world.setBlock(i + 5, j + 0, k + 23, Blocks.stone);
		world.setBlock(i + 5, j + 0, k + 24, Blocks.stone);
		world.setBlock(i + 5, j + 0, k + 25, Blocks.stone);
		world.setBlock(i + 5, j + 0, k + 26, Blocks.stone);
		world.setBlock(i + 5, j + 0, k + 27, Blocks.stone);
		world.setBlock(i + 5, j + 0, k + 28, Blocks.stone);
		world.setBlock(i + 5, j + 0, k + 29, Blocks.stone);
		world.setBlock(i + 5, j + 0, k + 30, Blocks.stone);
		world.setBlock(i + 5, j + 0, k + 31, Blocks.stone);
		world.setBlock(i + 5, j + 0, k + 32, Blocks.stone);
		world.setBlock(i + 5, j + 1, k + 0, Blocks.snow);
		world.setBlock(i + 5, j + 1, k + 1, Blocks.snow);
		world.setBlock(i + 5, j + 1, k + 2, Blocks.snow);
		world.setBlock(i + 5, j + 1, k + 3, Blocks.snow);
		world.setBlock(i + 5, j + 1, k + 4, Blocks.snow);
		world.setBlock(i + 5, j + 1, k + 5, Blocks.snow);
		world.setBlock(i + 5, j + 1, k + 6, Blocks.snow);
		world.setBlock(i + 5, j + 1, k + 7, Blocks.snow);
		world.setBlock(i + 5, j + 1, k + 8, Blocks.snow);
		world.setBlock(i + 5, j + 1, k + 9, Blocks.snow);
		world.setBlock(i + 5, j + 1, k + 10, Blocks.snow);
		world.setBlock(i + 5, j + 1, k + 11, Blocks.snow);
		world.setBlock(i + 5, j + 1, k + 12, Blocks.snow);
		world.setBlock(i + 5, j + 1, k + 13, Blocks.snow);
		world.setBlock(i + 5, j + 1, k + 14, Blocks.snow);
		world.setBlock(i + 5, j + 1, k + 15, Blocks.snow);
		world.setBlock(i + 5, j + 1, k + 16, Blocks.snow);
		world.setBlock(i + 5, j + 1, k + 17, Blocks.snow);
		world.setBlock(i + 5, j + 1, k + 18, Blocks.snow);
		world.setBlock(i + 5, j + 1, k + 19, Blocks.snow);
		world.setBlock(i + 5, j + 1, k + 20, Blocks.snow);
		world.setBlock(i + 5, j + 1, k + 21, Blocks.snow);
		world.setBlock(i + 5, j + 1, k + 22, Blocks.snow);
		world.setBlock(i + 5, j + 1, k + 23, Blocks.snow);
		world.setBlock(i + 5, j + 1, k + 24, Blocks.snow);
		world.setBlock(i + 5, j + 1, k + 25, Blocks.snow);
		world.setBlock(i + 5, j + 1, k + 26, Blocks.snow);
		world.setBlock(i + 5, j + 1, k + 27, Blocks.snow);
		world.setBlock(i + 5, j + 1, k + 28, Blocks.snow);
		world.setBlock(i + 5, j + 1, k + 29, Blocks.snow);
		world.setBlock(i + 5, j + 1, k + 30, Blocks.snow);
		world.setBlock(i + 5, j + 1, k + 31, Blocks.snow);
		world.setBlock(i + 5, j + 1, k + 32, Blocks.snow);
		world.setBlock(i + 5, j + 2, k + 0, Blocks.snow);
		world.setBlock(i + 5, j + 2, k + 1, Blocks.snow);
		world.setBlock(i + 5, j + 2, k + 2, Blocks.snow);
		world.setBlock(i + 5, j + 2, k + 3, Blocks.snow);
		world.setBlock(i + 5, j + 2, k + 4, Blocks.snow);
		world.setBlock(i + 5, j + 2, k + 5, Blocks.snow);
		world.setBlock(i + 5, j + 2, k + 6, Blocks.snow);
		world.setBlock(i + 5, j + 2, k + 7, Blocks.snow);
		world.setBlock(i + 5, j + 2, k + 8, Blocks.snow);
		world.setBlock(i + 5, j + 2, k + 9, Blocks.snow);
		world.setBlock(i + 5, j + 2, k + 10, Blocks.snow);
		world.setBlock(i + 5, j + 2, k + 11, Blocks.snow);
		world.setBlock(i + 5, j + 2, k + 12, Blocks.snow);
		world.setBlock(i + 5, j + 2, k + 13, Blocks.snow);
		world.setBlock(i + 5, j + 2, k + 14, Blocks.snow);
		world.setBlock(i + 5, j + 2, k + 15, Blocks.snow);
		world.setBlock(i + 5, j + 2, k + 16, Blocks.snow);
		world.setBlock(i + 5, j + 2, k + 17, Blocks.snow);
		world.setBlock(i + 5, j + 2, k + 18, Blocks.snow);
		world.setBlock(i + 5, j + 2, k + 19, Blocks.snow);
		world.setBlock(i + 5, j + 2, k + 20, Blocks.snow);
		world.setBlock(i + 5, j + 2, k + 21, Blocks.snow);
		world.setBlock(i + 5, j + 2, k + 22, Blocks.snow);
		world.setBlock(i + 5, j + 2, k + 23, Blocks.snow);
		world.setBlock(i + 5, j + 2, k + 24, Blocks.snow);
		world.setBlock(i + 5, j + 2, k + 25, Blocks.snow);
		world.setBlock(i + 5, j + 2, k + 26, Blocks.snow);
		world.setBlock(i + 5, j + 2, k + 27, Blocks.snow);
		world.setBlock(i + 5, j + 2, k + 28, Blocks.snow);
		world.setBlock(i + 5, j + 2, k + 29, Blocks.snow);
		world.setBlock(i + 5, j + 2, k + 30, Blocks.snow);
		world.setBlock(i + 5, j + 2, k + 31, Blocks.snow);
		world.setBlock(i + 5, j + 2, k + 32, Blocks.snow);
		world.setBlock(i + 5, j + 3, k + 0, Blocks.snow);
		world.setBlock(i + 5, j + 3, k + 1, Blocks.snow);
		world.setBlock(i + 5, j + 3, k + 2, Blocks.snow);
		world.setBlock(i + 5, j + 3, k + 3, Blocks.snow);
		world.setBlock(i + 5, j + 3, k + 4, Blocks.snow);
		world.setBlock(i + 5, j + 3, k + 5, Blocks.snow);
		world.setBlock(i + 5, j + 3, k + 6, Blocks.snow);
		world.setBlock(i + 5, j + 3, k + 7, Blocks.snow);
		world.setBlock(i + 5, j + 3, k + 8, Blocks.snow);
		world.setBlock(i + 5, j + 3, k + 9, Blocks.snow);
		world.setBlock(i + 5, j + 3, k + 10, Blocks.snow);
		world.setBlock(i + 5, j + 3, k + 11, Blocks.snow);
		world.setBlock(i + 5, j + 3, k + 12, Blocks.snow);
		world.setBlock(i + 5, j + 3, k + 13, Blocks.snow);
		world.setBlock(i + 5, j + 3, k + 14, Blocks.snow);
		world.setBlock(i + 5, j + 3, k + 15, Blocks.snow);
		world.setBlock(i + 5, j + 3, k + 16, Blocks.snow);
		world.setBlock(i + 5, j + 3, k + 17, Blocks.snow);
		world.setBlock(i + 5, j + 3, k + 18, Blocks.snow);
		world.setBlock(i + 5, j + 3, k + 19, Blocks.snow);
		world.setBlock(i + 5, j + 3, k + 20, Blocks.snow);
		world.setBlock(i + 5, j + 3, k + 21, Blocks.snow);
		world.setBlock(i + 5, j + 3, k + 22, Blocks.snow);
		world.setBlock(i + 5, j + 3, k + 23, Blocks.snow);
		world.setBlock(i + 5, j + 3, k + 24, Blocks.snow);
		world.setBlock(i + 5, j + 3, k + 25, Blocks.snow);
		world.setBlock(i + 5, j + 3, k + 26, Blocks.snow);
		world.setBlock(i + 5, j + 3, k + 27, Blocks.snow);
		world.setBlock(i + 5, j + 3, k + 28, Blocks.snow);
		world.setBlock(i + 5, j + 3, k + 29, Blocks.snow);
		world.setBlock(i + 5, j + 3, k + 30, Blocks.snow);
		world.setBlock(i + 5, j + 3, k + 31, Blocks.snow);
		world.setBlock(i + 5, j + 3, k + 32, Blocks.snow);
		world.setBlock(i + 5, j + 4, k + 0, Blocks.snow);
		world.setBlock(i + 5, j + 4, k + 1, Blocks.snow);
		world.setBlock(i + 5, j + 4, k + 2, Blocks.snow);
		world.setBlock(i + 5, j + 4, k + 3, Blocks.snow);
		world.setBlock(i + 5, j + 4, k + 4, Blocks.snow);
		world.setBlock(i + 5, j + 4, k + 5, Blocks.snow);
		world.setBlock(i + 5, j + 4, k + 6, Blocks.snow);
		world.setBlock(i + 5, j + 4, k + 7, Blocks.snow);
		world.setBlock(i + 5, j + 4, k + 8, Blocks.snow);
		world.setBlock(i + 5, j + 4, k + 9, Blocks.snow);
		world.setBlock(i + 5, j + 4, k + 10, Blocks.snow);
		world.setBlock(i + 5, j + 4, k + 11, Blocks.snow);
		world.setBlock(i + 5, j + 4, k + 12, Blocks.snow);
		world.setBlock(i + 5, j + 4, k + 13, Blocks.snow);
		world.setBlock(i + 5, j + 4, k + 14, Blocks.snow);
		world.setBlock(i + 5, j + 4, k + 15, Blocks.snow);
		world.setBlock(i + 5, j + 4, k + 16, Blocks.snow);
		world.setBlock(i + 5, j + 4, k + 17, Blocks.snow);
		world.setBlock(i + 5, j + 4, k + 18, Blocks.snow);
		world.setBlock(i + 5, j + 4, k + 19, Blocks.snow);
		world.setBlock(i + 5, j + 4, k + 20, Blocks.snow);
		world.setBlock(i + 5, j + 4, k + 21, Blocks.snow);
		world.setBlock(i + 5, j + 4, k + 22, Blocks.snow);
		world.setBlock(i + 5, j + 4, k + 23, Blocks.snow);
		world.setBlock(i + 5, j + 4, k + 24, Blocks.snow);
		world.setBlock(i + 5, j + 4, k + 25, Blocks.snow);
		world.setBlock(i + 5, j + 4, k + 26, Blocks.snow);
		world.setBlock(i + 5, j + 4, k + 27, Blocks.snow);
		world.setBlock(i + 5, j + 4, k + 28, Blocks.snow);
		world.setBlock(i + 5, j + 4, k + 29, Blocks.snow);
		world.setBlock(i + 5, j + 4, k + 30, Blocks.snow);
		world.setBlock(i + 5, j + 4, k + 31, Blocks.snow);
		world.setBlock(i + 5, j + 4, k + 32, Blocks.snow);
		world.setBlock(i + 5, j + 5, k + 4, Blocks.ice);
		world.setBlock(i + 5, j + 5, k + 6, Blocks.ice);
		world.setBlock(i + 5, j + 5, k + 12, Blocks.snow);
		world.setBlock(i + 5, j + 5, k + 13, Blocks.crafting_table);
		world.setBlock(i + 5, j + 5, k + 19, Blocks.crafting_table);
		world.setBlock(i + 5, j + 5, k + 20, Blocks.snow);
		world.setBlock(i + 5, j + 5, k + 24, Blocks.wool, 11, 0x02);
		world.setBlock(i + 5, j + 5, k + 25, Blocks.wool, 11, 0x02);
		world.setBlock(i + 5, j + 5, k + 26, Blocks.ice);
		world.setBlock(i + 5, j + 5, k + 28, Blocks.ice);
		world.setBlock(i + 5, j + 6, k + 4, Blocks.ice);
		world.setBlock(i + 5, j + 6, k + 6, Blocks.ice);
		world.setBlock(i + 5, j + 6, k + 12, Blocks.snow);
		world.setBlock(i + 5, j + 6, k + 20, Blocks.snow);
		world.setBlock(i + 5, j + 6, k + 24, Blocks.wool, 3, 0x02);
		world.setBlock(i + 5, j + 6, k + 25, Blocks.wool, 3, 0x02);
		world.setBlock(i + 5, j + 6, k + 26, Blocks.ice);
		world.setBlock(i + 5, j + 6, k + 28, Blocks.ice);
		world.setBlock(i + 5, j + 7, k + 4, Blocks.ice);
		world.setBlock(i + 5, j + 7, k + 6, Blocks.ice);
		world.setBlock(i + 5, j + 7, k + 12, Blocks.snow);
		world.setBlock(i + 5, j + 7, k + 20, Blocks.snow);
		world.setBlock(i + 5, j + 7, k + 24, Blocks.wool, 11, 0x02);
		world.setBlock(i + 5, j + 7, k + 25, Blocks.wool, 11, 0x02);
		world.setBlock(i + 5, j + 7, k + 26, Blocks.ice);
		world.setBlock(i + 5, j + 7, k + 28, Blocks.ice);
		world.setBlock(i + 5, j + 8, k + 4, Blocks.ice);
		world.setBlock(i + 5, j + 8, k + 5, Blocks.ice);
		world.setBlock(i + 5, j + 8, k + 6, Blocks.ice);
		world.setBlock(i + 5, j + 8, k + 13, Blocks.snow);
		world.setBlock(i + 5, j + 8, k + 19, Blocks.snow);
		world.setBlock(i + 5, j + 8, k + 26, Blocks.ice);
		world.setBlock(i + 5, j + 8, k + 27, Blocks.ice);
		world.setBlock(i + 5, j + 8, k + 28, Blocks.ice);
		world.setBlock(i + 5, j + 9, k + 5, Blocks.ice);
		world.setBlock(i + 5, j + 9, k + 14, Blocks.snow);
		world.setBlock(i + 5, j + 9, k + 15, Blocks.snow);
		world.setBlock(i + 5, j + 9, k + 16, Blocks.snow);
		world.setBlock(i + 5, j + 9, k + 17, Blocks.snow);
		world.setBlock(i + 5, j + 9, k + 18, Blocks.snow);
		world.setBlock(i + 5, j + 9, k + 27, Blocks.ice);
		world.setBlock(i + 6, j + 0, k + 0, Blocks.stone);
		world.setBlock(i + 6, j + 0, k + 1, Blocks.stone);
		world.setBlock(i + 6, j + 0, k + 2, Blocks.stone);
		world.setBlock(i + 6, j + 0, k + 3, Blocks.stone);
		world.setBlock(i + 6, j + 0, k + 4, Blocks.stone);
		world.setBlock(i + 6, j + 0, k + 5, Blocks.stone);
		world.setBlock(i + 6, j + 0, k + 6, Blocks.stone);
		world.setBlock(i + 6, j + 0, k + 7, Blocks.stone);
		world.setBlock(i + 6, j + 0, k + 8, Blocks.stone);
		world.setBlock(i + 6, j + 0, k + 9, Blocks.stone);
		world.setBlock(i + 6, j + 0, k + 10, Blocks.stone);
		world.setBlock(i + 6, j + 0, k + 11, Blocks.stone);
		world.setBlock(i + 6, j + 0, k + 12, Blocks.stone);
		world.setBlock(i + 6, j + 0, k + 13, Blocks.stone);
		world.setBlock(i + 6, j + 0, k + 14, Blocks.stone);
		world.setBlock(i + 6, j + 0, k + 15, Blocks.stone);
		world.setBlock(i + 6, j + 0, k + 16, Blocks.stone);
		world.setBlock(i + 6, j + 0, k + 17, Blocks.stone);
		world.setBlock(i + 6, j + 0, k + 18, Blocks.stone);
		world.setBlock(i + 6, j + 0, k + 19, Blocks.stone);
		world.setBlock(i + 6, j + 0, k + 20, Blocks.stone);
		world.setBlock(i + 6, j + 0, k + 21, Blocks.stone);
		world.setBlock(i + 6, j + 0, k + 22, Blocks.stone);
		world.setBlock(i + 6, j + 0, k + 23, Blocks.stone);
		world.setBlock(i + 6, j + 0, k + 24, Blocks.stone);
		world.setBlock(i + 6, j + 0, k + 25, Blocks.stone);
		world.setBlock(i + 6, j + 0, k + 26, Blocks.stone);
		world.setBlock(i + 6, j + 0, k + 27, Blocks.stone);
		world.setBlock(i + 6, j + 0, k + 28, Blocks.stone);
		world.setBlock(i + 6, j + 0, k + 29, Blocks.stone);
		world.setBlock(i + 6, j + 0, k + 30, Blocks.stone);
		world.setBlock(i + 6, j + 0, k + 31, Blocks.stone);
		world.setBlock(i + 6, j + 0, k + 32, Blocks.stone);
		world.setBlock(i + 6, j + 1, k + 0, Blocks.snow);
		world.setBlock(i + 6, j + 1, k + 1, Blocks.snow);
		world.setBlock(i + 6, j + 1, k + 2, Blocks.snow);
		world.setBlock(i + 6, j + 1, k + 3, Blocks.snow);
		world.setBlock(i + 6, j + 1, k + 4, Blocks.snow);
		world.setBlock(i + 6, j + 1, k + 5, Blocks.snow);
		world.setBlock(i + 6, j + 1, k + 6, Blocks.snow);
		world.setBlock(i + 6, j + 1, k + 7, Blocks.snow);
		world.setBlock(i + 6, j + 1, k + 8, Blocks.snow);
		world.setBlock(i + 6, j + 1, k + 9, Blocks.snow);
		world.setBlock(i + 6, j + 1, k + 10, Blocks.snow);
		world.setBlock(i + 6, j + 1, k + 11, Blocks.snow);
		world.setBlock(i + 6, j + 1, k + 12, Blocks.snow);
		world.setBlock(i + 6, j + 1, k + 13, Blocks.snow);
		world.setBlock(i + 6, j + 1, k + 14, Blocks.snow);
		world.setBlock(i + 6, j + 1, k + 15, Blocks.snow);
		world.setBlock(i + 6, j + 1, k + 16, Blocks.snow);
		world.setBlock(i + 6, j + 1, k + 17, Blocks.snow);
		world.setBlock(i + 6, j + 1, k + 18, Blocks.snow);
		world.setBlock(i + 6, j + 1, k + 19, Blocks.snow);
		world.setBlock(i + 6, j + 1, k + 20, Blocks.snow);
		world.setBlock(i + 6, j + 1, k + 21, Blocks.snow);
		world.setBlock(i + 6, j + 1, k + 22, Blocks.snow);
		world.setBlock(i + 6, j + 1, k + 23, Blocks.snow);
		world.setBlock(i + 6, j + 1, k + 24, Blocks.snow);
		world.setBlock(i + 6, j + 1, k + 25, Blocks.snow);
		world.setBlock(i + 6, j + 1, k + 26, Blocks.snow);
		world.setBlock(i + 6, j + 1, k + 27, Blocks.snow);
		world.setBlock(i + 6, j + 1, k + 28, Blocks.snow);
		world.setBlock(i + 6, j + 1, k + 29, Blocks.snow);
		world.setBlock(i + 6, j + 1, k + 30, Blocks.snow);
		world.setBlock(i + 6, j + 1, k + 31, Blocks.snow);
		world.setBlock(i + 6, j + 1, k + 32, Blocks.snow);
		world.setBlock(i + 6, j + 2, k + 0, Blocks.snow);
		world.setBlock(i + 6, j + 2, k + 1, Blocks.snow);
		world.setBlock(i + 6, j + 2, k + 2, Blocks.snow);
		world.setBlock(i + 6, j + 2, k + 3, Blocks.snow);
		world.setBlock(i + 6, j + 2, k + 4, Blocks.snow);
		world.setBlock(i + 6, j + 2, k + 5, Blocks.snow);
		world.setBlock(i + 6, j + 2, k + 6, Blocks.snow);
		world.setBlock(i + 6, j + 2, k + 7, Blocks.snow);
		world.setBlock(i + 6, j + 2, k + 8, Blocks.snow);
		world.setBlock(i + 6, j + 2, k + 9, Blocks.snow);
		world.setBlock(i + 6, j + 2, k + 10, Blocks.snow);
		world.setBlock(i + 6, j + 2, k + 11, Blocks.snow);
		world.setBlock(i + 6, j + 2, k + 12, Blocks.snow);
		world.setBlock(i + 6, j + 2, k + 13, Blocks.snow);
		world.setBlock(i + 6, j + 2, k + 14, Blocks.snow);
		world.setBlock(i + 6, j + 2, k + 15, Blocks.snow);
		world.setBlock(i + 6, j + 2, k + 16, Blocks.snow);
		world.setBlock(i + 6, j + 2, k + 17, Blocks.snow);
		world.setBlock(i + 6, j + 2, k + 18, Blocks.snow);
		world.setBlock(i + 6, j + 2, k + 19, Blocks.snow);
		world.setBlock(i + 6, j + 2, k + 20, Blocks.snow);
		world.setBlock(i + 6, j + 2, k + 21, Blocks.snow);
		world.setBlock(i + 6, j + 2, k + 22, Blocks.snow);
		world.setBlock(i + 6, j + 2, k + 23, Blocks.snow);
		world.setBlock(i + 6, j + 2, k + 24, Blocks.snow);
		world.setBlock(i + 6, j + 2, k + 25, Blocks.snow);
		world.setBlock(i + 6, j + 2, k + 26, Blocks.snow);
		world.setBlock(i + 6, j + 2, k + 27, Blocks.snow);
		world.setBlock(i + 6, j + 2, k + 28, Blocks.snow);
		world.setBlock(i + 6, j + 2, k + 29, Blocks.snow);
		world.setBlock(i + 6, j + 2, k + 30, Blocks.snow);
		world.setBlock(i + 6, j + 2, k + 31, Blocks.snow);
		world.setBlock(i + 6, j + 2, k + 32, Blocks.snow);
		world.setBlock(i + 6, j + 3, k + 0, Blocks.snow);
		world.setBlock(i + 6, j + 3, k + 1, Blocks.snow);
		world.setBlock(i + 6, j + 3, k + 2, Blocks.snow);
		world.setBlock(i + 6, j + 3, k + 3, Blocks.snow);
		world.setBlock(i + 6, j + 3, k + 4, Blocks.snow);
		world.setBlock(i + 6, j + 3, k + 5, Blocks.snow);
		world.setBlock(i + 6, j + 3, k + 6, Blocks.snow);
		world.setBlock(i + 6, j + 3, k + 7, Blocks.snow);
		world.setBlock(i + 6, j + 3, k + 8, Blocks.snow);
		world.setBlock(i + 6, j + 3, k + 9, Blocks.snow);
		world.setBlock(i + 6, j + 3, k + 10, Blocks.snow);
		world.setBlock(i + 6, j + 3, k + 11, Blocks.snow);
		world.setBlock(i + 6, j + 3, k + 12, Blocks.snow);
		world.setBlock(i + 6, j + 3, k + 13, Blocks.snow);
		world.setBlock(i + 6, j + 3, k + 14, Blocks.snow);
		world.setBlock(i + 6, j + 3, k + 15, Blocks.snow);
		world.setBlock(i + 6, j + 3, k + 16, Blocks.snow);
		world.setBlock(i + 6, j + 3, k + 17, Blocks.snow);
		world.setBlock(i + 6, j + 3, k + 18, Blocks.snow);
		world.setBlock(i + 6, j + 3, k + 19, Blocks.snow);
		world.setBlock(i + 6, j + 3, k + 20, Blocks.snow);
		world.setBlock(i + 6, j + 3, k + 21, Blocks.snow);
		world.setBlock(i + 6, j + 3, k + 22, Blocks.snow);
		world.setBlock(i + 6, j + 3, k + 23, Blocks.snow);
		world.setBlock(i + 6, j + 3, k + 24, Blocks.snow);
		world.setBlock(i + 6, j + 3, k + 25, Blocks.snow);
		world.setBlock(i + 6, j + 3, k + 26, Blocks.snow);
		world.setBlock(i + 6, j + 3, k + 27, Blocks.snow);
		world.setBlock(i + 6, j + 3, k + 28, Blocks.snow);
		world.setBlock(i + 6, j + 3, k + 29, Blocks.snow);
		world.setBlock(i + 6, j + 3, k + 30, Blocks.snow);
		world.setBlock(i + 6, j + 3, k + 31, Blocks.snow);
		world.setBlock(i + 6, j + 3, k + 32, Blocks.snow);
		world.setBlock(i + 6, j + 4, k + 0, Blocks.snow);
		world.setBlock(i + 6, j + 4, k + 1, Blocks.snow);
		world.setBlock(i + 6, j + 4, k + 2, Blocks.snow);
		world.setBlock(i + 6, j + 4, k + 3, Blocks.snow);
		world.setBlock(i + 6, j + 4, k + 4, Blocks.snow);
		world.setBlock(i + 6, j + 4, k + 5, Blocks.snow);
		world.setBlock(i + 6, j + 4, k + 6, Blocks.snow);
		world.setBlock(i + 6, j + 4, k + 7, Blocks.snow);
		world.setBlock(i + 6, j + 4, k + 8, Blocks.snow);
		world.setBlock(i + 6, j + 4, k + 9, Blocks.snow);
		world.setBlock(i + 6, j + 4, k + 10, Blocks.snow);
		world.setBlock(i + 6, j + 4, k + 11, Blocks.snow);
		world.setBlock(i + 6, j + 4, k + 12, Blocks.snow);
		world.setBlock(i + 6, j + 4, k + 13, Blocks.snow);
		world.setBlock(i + 6, j + 4, k + 14, Blocks.snow);
		world.setBlock(i + 6, j + 4, k + 15, Blocks.snow);
		world.setBlock(i + 6, j + 4, k + 16, Blocks.snow);
		world.setBlock(i + 6, j + 4, k + 17, Blocks.snow);
		world.setBlock(i + 6, j + 4, k + 18, Blocks.snow);
		world.setBlock(i + 6, j + 4, k + 19, Blocks.snow);
		world.setBlock(i + 6, j + 4, k + 20, Blocks.snow);
		world.setBlock(i + 6, j + 4, k + 21, Blocks.snow);
		world.setBlock(i + 6, j + 4, k + 22, Blocks.snow);
		world.setBlock(i + 6, j + 4, k + 23, Blocks.snow);
		world.setBlock(i + 6, j + 4, k + 24, Blocks.planks, 1, 0x02);
		world.setBlock(i + 6, j + 4, k + 25, Blocks.planks, 1, 0x02);
		world.setBlock(i + 6, j + 4, k + 26, Blocks.snow);
		world.setBlock(i + 6, j + 4, k + 27, Blocks.snow);
		world.setBlock(i + 6, j + 4, k + 28, Blocks.snow);
		world.setBlock(i + 6, j + 4, k + 29, Blocks.snow);
		world.setBlock(i + 6, j + 4, k + 30, Blocks.snow);
		world.setBlock(i + 6, j + 4, k + 31, Blocks.snow);
		world.setBlock(i + 6, j + 4, k + 32, Blocks.snow);
		world.setBlock(i + 6, j + 5, k + 3, Blocks.ice);
		world.setBlock(i + 6, j + 5, k + 5, Blocks.ice);
		world.setBlock(i + 6, j + 5, k + 6, Blocks.wool, 12, 0x02);
		world.setBlock(i + 6, j + 5, k + 7, Blocks.wool, 12, 0x02);
		world.setBlock(i + 6, j + 5, k + 8, Blocks.wool, 12, 0x02);
		world.setBlock(i + 6, j + 5, k + 11, Blocks.snow);
		world.setBlock(i + 6, j + 5, k + 12, Blocks.furnace, 3, 0x02);
		world.setBlock(i + 6, j + 5, k + 20, Blocks.furnace, 2, 0x02);
		world.setBlock(i + 6, j + 5, k + 21, Blocks.snow);
		world.setBlock(i + 6, j + 5, k + 23, Blocks.wool, 11, 0x02);
		world.setBlock(i + 6, j + 5, k + 24, Blocks.fence);
		world.setBlock(i + 6, j + 5, k + 25, Blocks.fence);
		world.setBlock(i + 6, j + 5, k + 26, Blocks.wool, 11, 0x02);
		world.setBlock(i + 6, j + 5, k + 27, Blocks.ice);
		world.setBlock(i + 6, j + 5, k + 29, Blocks.ice);
		world.setBlock(i + 6, j + 6, k + 3, Blocks.ice);
		world.setBlock(i + 6, j + 6, k + 5, Blocks.ice);
		world.setBlock(i + 6, j + 6, k + 6, Blocks.wool, 12, 0x02);
		world.setBlock(i + 6, j + 6, k + 7, Blocks.wool, 12, 0x02);
		world.setBlock(i + 6, j + 6, k + 8, Blocks.wool, 12, 0x02);
		world.setBlock(i + 6, j + 6, k + 11, Blocks.snow);
		world.setBlock(i + 6, j + 6, k + 21, Blocks.snow);
		world.setBlock(i + 6, j + 6, k + 23, Blocks.wool, 3, 0x02);
		world.setBlock(i + 6, j + 6, k + 24, Blocks.fence);
		world.setBlock(i + 6, j + 6, k + 25, Blocks.fence);
		world.setBlock(i + 6, j + 6, k + 26, Blocks.wool, 3, 0x02);
		world.setBlock(i + 6, j + 6, k + 27, Blocks.ice);
		world.setBlock(i + 6, j + 6, k + 29, Blocks.ice);
		world.setBlock(i + 6, j + 7, k + 3, Blocks.ice);
		world.setBlock(i + 6, j + 7, k + 5, Blocks.ice);
		world.setBlock(i + 6, j + 7, k + 6, Blocks.wool, 12, 0x02);
		world.setBlock(i + 6, j + 7, k + 7, Blocks.wool, 12, 0x02);
		world.setBlock(i + 6, j + 7, k + 8, Blocks.wool, 12, 0x02);
		world.setBlock(i + 6, j + 7, k + 11, Blocks.snow);
		world.setBlock(i + 6, j + 7, k + 21, Blocks.snow);
		world.setBlock(i + 6, j + 7, k + 23, Blocks.wool, 11, 0x02);
		world.setBlock(i + 6, j + 7, k + 24, Blocks.fence);
		world.setBlock(i + 6, j + 7, k + 25, Blocks.fence);
		world.setBlock(i + 6, j + 7, k + 26, Blocks.wool, 11, 0x02);
		world.setBlock(i + 6, j + 7, k + 27, Blocks.ice);
		world.setBlock(i + 6, j + 7, k + 29, Blocks.ice);
		world.setBlock(i + 6, j + 8, k + 3, Blocks.ice);
		world.setBlock(i + 6, j + 8, k + 4, Blocks.ice);
		world.setBlock(i + 6, j + 8, k + 5, Blocks.ice);
		world.setBlock(i + 6, j + 8, k + 6, Blocks.wool, 12, 0x02);
		world.setBlock(i + 6, j + 8, k + 7, Blocks.wool, 12, 0x02);
		world.setBlock(i + 6, j + 8, k + 8, Blocks.wool, 12, 0x02);
		world.setBlock(i + 6, j + 8, k + 12, Blocks.snow);
		world.setBlock(i + 6, j + 8, k + 20, Blocks.snow);
		world.setBlock(i + 6, j + 8, k + 24, Blocks.wool, 3, 0x02);
		world.setBlock(i + 6, j + 8, k + 25, Blocks.wool, 3, 0x02);
		world.setBlock(i + 6, j + 8, k + 27, Blocks.ice);
		world.setBlock(i + 6, j + 8, k + 28, Blocks.ice);
		world.setBlock(i + 6, j + 8, k + 29, Blocks.ice);
		world.setBlock(i + 6, j + 9, k + 4, Blocks.ice);
		world.setBlock(i + 6, j + 9, k + 8, Blocks.wool, 12, 0x02);
		world.setBlock(i + 6, j + 9, k + 13, Blocks.snow);
		world.setBlock(i + 6, j + 9, k + 19, Blocks.snow);
		world.setBlock(i + 6, j + 9, k + 28, Blocks.ice);
		world.setBlock(i + 6, j + 10, k + 14, Blocks.snow);
		world.setBlock(i + 6, j + 10, k + 15, Blocks.snow);
		world.setBlock(i + 6, j + 10, k + 16, Blocks.snow);
		world.setBlock(i + 6, j + 10, k + 17, Blocks.snow);
		world.setBlock(i + 6, j + 10, k + 18, Blocks.snow);
		world.setBlock(i + 7, j + 0, k + 0, Blocks.stone);
		world.setBlock(i + 7, j + 0, k + 1, Blocks.stone);
		world.setBlock(i + 7, j + 0, k + 2, Blocks.stone);
		world.setBlock(i + 7, j + 0, k + 3, Blocks.stone);
		world.setBlock(i + 7, j + 0, k + 4, Blocks.stone);
		world.setBlock(i + 7, j + 0, k + 5, Blocks.stone);
		world.setBlock(i + 7, j + 0, k + 6, Blocks.stone);
		world.setBlock(i + 7, j + 0, k + 7, Blocks.stone);
		world.setBlock(i + 7, j + 0, k + 8, Blocks.stone);
		world.setBlock(i + 7, j + 0, k + 9, Blocks.stone);
		world.setBlock(i + 7, j + 0, k + 10, Blocks.stone);
		world.setBlock(i + 7, j + 0, k + 11, Blocks.stone);
		world.setBlock(i + 7, j + 0, k + 12, Blocks.stone);
		world.setBlock(i + 7, j + 0, k + 13, Blocks.stone);
		world.setBlock(i + 7, j + 0, k + 14, Blocks.stone);
		world.setBlock(i + 7, j + 0, k + 15, Blocks.stone);
		world.setBlock(i + 7, j + 0, k + 16, Blocks.stone);
		world.setBlock(i + 7, j + 0, k + 17, Blocks.stone);
		world.setBlock(i + 7, j + 0, k + 18, Blocks.stone);
		world.setBlock(i + 7, j + 0, k + 19, Blocks.stone);
		world.setBlock(i + 7, j + 0, k + 20, Blocks.stone);
		world.setBlock(i + 7, j + 0, k + 21, Blocks.stone);
		world.setBlock(i + 7, j + 0, k + 22, Blocks.stone);
		world.setBlock(i + 7, j + 0, k + 23, Blocks.stone);
		world.setBlock(i + 7, j + 0, k + 24, Blocks.stone);
		world.setBlock(i + 7, j + 0, k + 25, Blocks.stone);
		world.setBlock(i + 7, j + 0, k + 26, Blocks.stone);
		world.setBlock(i + 7, j + 0, k + 27, Blocks.stone);
		world.setBlock(i + 7, j + 0, k + 28, Blocks.stone);
		world.setBlock(i + 7, j + 0, k + 29, Blocks.stone);
		world.setBlock(i + 7, j + 0, k + 30, Blocks.stone);
		world.setBlock(i + 7, j + 0, k + 31, Blocks.stone);
		world.setBlock(i + 7, j + 0, k + 32, Blocks.stone);
		world.setBlock(i + 7, j + 1, k + 0, Blocks.snow);
		world.setBlock(i + 7, j + 1, k + 1, Blocks.snow);
		world.setBlock(i + 7, j + 1, k + 2, Blocks.snow);
		world.setBlock(i + 7, j + 1, k + 3, Blocks.snow);
		world.setBlock(i + 7, j + 1, k + 4, Blocks.snow);
		world.setBlock(i + 7, j + 1, k + 5, Blocks.snow);
		world.setBlock(i + 7, j + 1, k + 6, Blocks.snow);
		world.setBlock(i + 7, j + 1, k + 7, Blocks.snow);
		world.setBlock(i + 7, j + 1, k + 8, Blocks.snow);
		world.setBlock(i + 7, j + 1, k + 9, Blocks.snow);
		world.setBlock(i + 7, j + 1, k + 10, Blocks.snow);
		world.setBlock(i + 7, j + 1, k + 11, Blocks.snow);
		world.setBlock(i + 7, j + 1, k + 12, Blocks.snow);
		world.setBlock(i + 7, j + 1, k + 13, Blocks.snow);
		world.setBlock(i + 7, j + 1, k + 14, Blocks.snow);
		world.setBlock(i + 7, j + 1, k + 15, Blocks.snow);
		world.setBlock(i + 7, j + 1, k + 16, Blocks.snow);
		world.setBlock(i + 7, j + 1, k + 17, Blocks.snow);
		world.setBlock(i + 7, j + 1, k + 18, Blocks.snow);
		world.setBlock(i + 7, j + 1, k + 19, Blocks.snow);
		world.setBlock(i + 7, j + 1, k + 20, Blocks.snow);
		world.setBlock(i + 7, j + 1, k + 21, Blocks.snow);
		world.setBlock(i + 7, j + 1, k + 22, Blocks.snow);
		world.setBlock(i + 7, j + 1, k + 23, Blocks.snow);
		world.setBlock(i + 7, j + 1, k + 24, Blocks.snow);
		world.setBlock(i + 7, j + 1, k + 25, Blocks.snow);
		world.setBlock(i + 7, j + 1, k + 26, Blocks.snow);
		world.setBlock(i + 7, j + 1, k + 27, Blocks.snow);
		world.setBlock(i + 7, j + 1, k + 28, Blocks.snow);
		world.setBlock(i + 7, j + 1, k + 29, Blocks.snow);
		world.setBlock(i + 7, j + 1, k + 30, Blocks.snow);
		world.setBlock(i + 7, j + 1, k + 31, Blocks.snow);
		world.setBlock(i + 7, j + 1, k + 32, Blocks.snow);
		world.setBlock(i + 7, j + 2, k + 0, Blocks.snow);
		world.setBlock(i + 7, j + 2, k + 1, Blocks.snow);
		world.setBlock(i + 7, j + 2, k + 2, Blocks.snow);
		world.setBlock(i + 7, j + 2, k + 3, Blocks.snow);
		world.setBlock(i + 7, j + 2, k + 4, Blocks.snow);
		world.setBlock(i + 7, j + 2, k + 5, Blocks.snow);
		world.setBlock(i + 7, j + 2, k + 6, Blocks.snow);
		world.setBlock(i + 7, j + 2, k + 7, Blocks.snow);
		world.setBlock(i + 7, j + 2, k + 8, Blocks.snow);
		world.setBlock(i + 7, j + 2, k + 9, Blocks.snow);
		world.setBlock(i + 7, j + 2, k + 10, Blocks.snow);
		world.setBlock(i + 7, j + 2, k + 11, Blocks.snow);
		world.setBlock(i + 7, j + 2, k + 12, Blocks.snow);
		world.setBlock(i + 7, j + 2, k + 13, Blocks.snow);
		world.setBlock(i + 7, j + 2, k + 14, Blocks.snow);
		world.setBlock(i + 7, j + 2, k + 15, Blocks.snow);
		world.setBlock(i + 7, j + 2, k + 16, Blocks.snow);
		world.setBlock(i + 7, j + 2, k + 17, Blocks.snow);
		world.setBlock(i + 7, j + 2, k + 18, Blocks.snow);
		world.setBlock(i + 7, j + 2, k + 19, Blocks.snow);
		world.setBlock(i + 7, j + 2, k + 20, Blocks.snow);
		world.setBlock(i + 7, j + 2, k + 21, Blocks.snow);
		world.setBlock(i + 7, j + 2, k + 22, Blocks.snow);
		world.setBlock(i + 7, j + 2, k + 23, Blocks.snow);
		world.setBlock(i + 7, j + 2, k + 24, Blocks.snow);
		world.setBlock(i + 7, j + 2, k + 25, Blocks.snow);
		world.setBlock(i + 7, j + 2, k + 26, Blocks.snow);
		world.setBlock(i + 7, j + 2, k + 27, Blocks.snow);
		world.setBlock(i + 7, j + 2, k + 28, Blocks.snow);
		world.setBlock(i + 7, j + 2, k + 29, Blocks.snow);
		world.setBlock(i + 7, j + 2, k + 30, Blocks.snow);
		world.setBlock(i + 7, j + 2, k + 31, Blocks.snow);
		world.setBlock(i + 7, j + 2, k + 32, Blocks.snow);
		world.setBlock(i + 7, j + 3, k + 0, Blocks.snow);
		world.setBlock(i + 7, j + 3, k + 1, Blocks.snow);
		world.setBlock(i + 7, j + 3, k + 2, Blocks.snow);
		world.setBlock(i + 7, j + 3, k + 3, Blocks.snow);
		world.setBlock(i + 7, j + 3, k + 4, Blocks.snow);
		world.setBlock(i + 7, j + 3, k + 5, Blocks.snow);
		world.setBlock(i + 7, j + 3, k + 6, Blocks.snow);
		world.setBlock(i + 7, j + 3, k + 7, Blocks.snow);
		world.setBlock(i + 7, j + 3, k + 8, Blocks.snow);
		world.setBlock(i + 7, j + 3, k + 9, Blocks.snow);
		world.setBlock(i + 7, j + 3, k + 10, Blocks.snow);
		world.setBlock(i + 7, j + 3, k + 11, Blocks.snow);
		world.setBlock(i + 7, j + 3, k + 12, Blocks.snow);
		world.setBlock(i + 7, j + 3, k + 13, Blocks.snow);
		world.setBlock(i + 7, j + 3, k + 14, Blocks.snow);
		world.setBlock(i + 7, j + 3, k + 15, Blocks.snow);
		world.setBlock(i + 7, j + 3, k + 16, Blocks.snow);
		world.setBlock(i + 7, j + 3, k + 17, Blocks.snow);
		world.setBlock(i + 7, j + 3, k + 18, Blocks.snow);
		world.setBlock(i + 7, j + 3, k + 19, Blocks.snow);
		world.setBlock(i + 7, j + 3, k + 20, Blocks.snow);
		world.setBlock(i + 7, j + 3, k + 21, Blocks.snow);
		world.setBlock(i + 7, j + 3, k + 22, Blocks.snow);
		world.setBlock(i + 7, j + 3, k + 23, Blocks.snow);
		world.setBlock(i + 7, j + 3, k + 24, Blocks.snow);
		world.setBlock(i + 7, j + 3, k + 25, Blocks.snow);
		world.setBlock(i + 7, j + 3, k + 26, Blocks.snow);
		world.setBlock(i + 7, j + 3, k + 27, Blocks.snow);
		world.setBlock(i + 7, j + 3, k + 28, Blocks.snow);
		world.setBlock(i + 7, j + 3, k + 29, Blocks.snow);
		world.setBlock(i + 7, j + 3, k + 30, Blocks.snow);
		world.setBlock(i + 7, j + 3, k + 31, Blocks.snow);
		world.setBlock(i + 7, j + 3, k + 32, Blocks.snow);
		world.setBlock(i + 7, j + 4, k + 0, Blocks.snow);
		world.setBlock(i + 7, j + 4, k + 1, Blocks.snow);
		world.setBlock(i + 7, j + 4, k + 2, Blocks.snow);
		world.setBlock(i + 7, j + 4, k + 3, Blocks.snow);
		world.setBlock(i + 7, j + 4, k + 4, Blocks.snow);
		world.setBlock(i + 7, j + 4, k + 5, Blocks.snow);
		world.setBlock(i + 7, j + 4, k + 6, Blocks.planks, 1, 0x02);
		world.setBlock(i + 7, j + 4, k + 7, Blocks.planks, 1, 0x02);
		world.setBlock(i + 7, j + 4, k + 8, Blocks.planks, 1, 0x02);
		world.setBlock(i + 7, j + 4, k + 9, Blocks.snow);
		world.setBlock(i + 7, j + 4, k + 10, Blocks.snow);
		world.setBlock(i + 7, j + 4, k + 11, Blocks.snow);
		world.setBlock(i + 7, j + 4, k + 12, Blocks.snow);
		world.setBlock(i + 7, j + 4, k + 13, Blocks.snow);
		world.setBlock(i + 7, j + 4, k + 14, Blocks.snow);
		world.setBlock(i + 7, j + 4, k + 15, Blocks.snow);
		world.setBlock(i + 7, j + 4, k + 16, Blocks.cobblestone);
		world.setBlock(i + 7, j + 4, k + 17, Blocks.snow);
		world.setBlock(i + 7, j + 4, k + 18, Blocks.snow);
		world.setBlock(i + 7, j + 4, k + 19, Blocks.snow);
		world.setBlock(i + 7, j + 4, k + 20, Blocks.snow);
		world.setBlock(i + 7, j + 4, k + 21, Blocks.snow);
		world.setBlock(i + 7, j + 4, k + 22, Blocks.snow);
		world.setBlock(i + 7, j + 4, k + 23, Blocks.snow);
		world.setBlock(i + 7, j + 4, k + 24, Blocks.planks, 1, 0x02);
		world.setBlock(i + 7, j + 4, k + 25, Blocks.planks, 1, 0x02);
		world.setBlock(i + 7, j + 4, k + 26, Blocks.planks, 1, 0x02);
		world.setBlock(i + 7, j + 4, k + 27, Blocks.snow);
		world.setBlock(i + 7, j + 4, k + 28, Blocks.snow);
		world.setBlock(i + 7, j + 4, k + 29, Blocks.snow);
		world.setBlock(i + 7, j + 4, k + 30, Blocks.snow);
		world.setBlock(i + 7, j + 4, k + 31, Blocks.snow);
		world.setBlock(i + 7, j + 4, k + 32, Blocks.snow);
		world.setBlock(i + 7, j + 5, k + 2, Blocks.ice);
		world.setBlock(i + 7, j + 5, k + 4, Blocks.ice);
		world.setBlock(i + 7, j + 5, k + 5, Blocks.wool, 12, 0x02);
		world.setBlock(i + 7, j + 5, k + 6, Blocks.fence);
		world.setBlock(i + 7, j + 5, k + 8, Blocks.fence);
		world.setBlock(i + 7, j + 5, k + 9, Blocks.wool, 12, 0x02);
		world.setBlock(i + 7, j + 5, k + 10, Blocks.snow);
		world.setBlock(i + 7, j + 5, k + 11, Blocks.chest, 3, 0x02);
		world.setBlock(i + 7, j + 5, k + 16, Blocks.cobblestone_wall);
		world.setBlock(i + 7, j + 5, k + 21, Blocks.chest, 2, 0x02);
		world.setBlock(i + 7, j + 5, k + 22, Blocks.snow);
		world.setBlock(i + 7, j + 5, k + 23, Blocks.wool, 11, 0x02);
		world.setBlock(i + 7, j + 5, k + 26, Blocks.fence);
		world.setBlock(i + 7, j + 5, k + 27, Blocks.wool, 11, 0x02);
		world.setBlock(i + 7, j + 5, k + 28, Blocks.ice);
		world.setBlock(i + 7, j + 5, k + 30, Blocks.ice);
		world.setBlock(i + 7, j + 6, k + 2, Blocks.ice);
		world.setBlock(i + 7, j + 6, k + 4, Blocks.ice);
		world.setBlock(i + 7, j + 6, k + 5, Blocks.wool, 12, 0x02);
		world.setBlock(i + 7, j + 6, k + 6, Blocks.fence);
		world.setBlock(i + 7, j + 6, k + 8, Blocks.fence);
		world.setBlock(i + 7, j + 6, k + 9, Blocks.wool, 12, 0x02);
		world.setBlock(i + 7, j + 6, k + 10, Blocks.snow);
		world.setBlock(i + 7, j + 6, k + 22, Blocks.snow);
		world.setBlock(i + 7, j + 6, k + 23, Blocks.wool, 3, 0x02);
		world.setBlock(i + 7, j + 6, k + 26, Blocks.fence);
		world.setBlock(i + 7, j + 6, k + 27, Blocks.wool, 3, 0x02);
		world.setBlock(i + 7, j + 6, k + 28, Blocks.ice);
		world.setBlock(i + 7, j + 6, k + 30, Blocks.ice);
		world.setBlock(i + 7, j + 7, k + 2, Blocks.ice);
		world.setBlock(i + 7, j + 7, k + 4, Blocks.ice);
		world.setBlock(i + 7, j + 7, k + 5, Blocks.wool, 12, 0x02);
		world.setBlock(i + 7, j + 7, k + 6, Blocks.fence);
		world.setBlock(i + 7, j + 7, k + 8, Blocks.fence);
		world.setBlock(i + 7, j + 7, k + 9, Blocks.wool, 12, 0x02);
		world.setBlock(i + 7, j + 7, k + 10, Blocks.snow);
		world.setBlock(i + 7, j + 7, k + 22, Blocks.snow);
		world.setBlock(i + 7, j + 7, k + 23, Blocks.wool, 11, 0x02);
		world.setBlock(i + 7, j + 7, k + 26, Blocks.fence);
		world.setBlock(i + 7, j + 7, k + 27, Blocks.wool, 11, 0x02);
		world.setBlock(i + 7, j + 7, k + 28, Blocks.ice);
		world.setBlock(i + 7, j + 7, k + 30, Blocks.ice);
		world.setBlock(i + 7, j + 8, k + 2, Blocks.ice);
		world.setBlock(i + 7, j + 8, k + 3, Blocks.ice);
		world.setBlock(i + 7, j + 8, k + 4, Blocks.ice);
		world.setBlock(i + 7, j + 8, k + 5, Blocks.wool, 12, 0x02);
		world.setBlock(i + 7, j + 8, k + 6, Blocks.fence);
		world.setBlock(i + 7, j + 8, k + 7, Blocks.fence);
		world.setBlock(i + 7, j + 8, k + 8, Blocks.fence);
		world.setBlock(i + 7, j + 8, k + 9, Blocks.wool, 12, 0x02);
		world.setBlock(i + 7, j + 8, k + 11, Blocks.snow);
		world.setBlock(i + 7, j + 8, k + 21, Blocks.snow);
		world.setBlock(i + 7, j + 8, k + 24, Blocks.wool, 3, 0x02);
		world.setBlock(i + 7, j + 8, k + 26, Blocks.wool, 3, 0x02);
		world.setBlock(i + 7, j + 8, k + 28, Blocks.ice);
		world.setBlock(i + 7, j + 8, k + 30, Blocks.ice);
		world.setBlock(i + 7, j + 9, k + 3, Blocks.ice);
		world.setBlock(i + 7, j + 9, k + 6, Blocks.wool, 12, 0x02);
		world.setBlock(i + 7, j + 9, k + 7, Blocks.wool, 12, 0x02);
		world.setBlock(i + 7, j + 9, k + 8, Blocks.fence);
		world.setBlock(i + 7, j + 9, k + 9, Blocks.wool, 12, 0x02);
		world.setBlock(i + 7, j + 9, k + 12, Blocks.snow);
		world.setBlock(i + 7, j + 9, k + 20, Blocks.snow);
		world.setBlock(i + 7, j + 9, k + 25, Blocks.wool, 11, 0x02);
		world.setBlock(i + 7, j + 9, k + 29, Blocks.ice);
		world.setBlock(i + 7, j + 10, k + 8, Blocks.wool, 12, 0x02);
		world.setBlock(i + 7, j + 10, k + 13, Blocks.snow);
		world.setBlock(i + 7, j + 10, k + 14, Blocks.snow);
		world.setBlock(i + 7, j + 10, k + 18, Blocks.snow);
		world.setBlock(i + 7, j + 10, k + 19, Blocks.snow);
		world.setBlock(i + 7, j + 11, k + 15, Blocks.snow);
		world.setBlock(i + 7, j + 11, k + 16, Blocks.snow);
		world.setBlock(i + 7, j + 11, k + 17, Blocks.snow);
		world.setBlock(i + 8, j + 0, k + 0, Blocks.stone);
		world.setBlock(i + 8, j + 0, k + 1, Blocks.stone);
		world.setBlock(i + 8, j + 0, k + 2, Blocks.stone);
		world.setBlock(i + 8, j + 0, k + 3, Blocks.stone);
		world.setBlock(i + 8, j + 0, k + 4, Blocks.stone);
		world.setBlock(i + 8, j + 0, k + 5, Blocks.stone);
		world.setBlock(i + 8, j + 0, k + 6, Blocks.stone);
		world.setBlock(i + 8, j + 0, k + 7, Blocks.stone);
		world.setBlock(i + 8, j + 0, k + 8, Blocks.stone);
		world.setBlock(i + 8, j + 0, k + 9, Blocks.stone);
		world.setBlock(i + 8, j + 0, k + 10, Blocks.stone);
		world.setBlock(i + 8, j + 0, k + 11, Blocks.stone);
		world.setBlock(i + 8, j + 0, k + 12, Blocks.stone);
		world.setBlock(i + 8, j + 0, k + 13, Blocks.stone);
		world.setBlock(i + 8, j + 0, k + 14, Blocks.stone);
		world.setBlock(i + 8, j + 0, k + 15, Blocks.stone);
		world.setBlock(i + 8, j + 0, k + 16, Blocks.stone);
		world.setBlock(i + 8, j + 0, k + 17, Blocks.stone);
		world.setBlock(i + 8, j + 0, k + 18, Blocks.stone);
		world.setBlock(i + 8, j + 0, k + 19, Blocks.stone);
		world.setBlock(i + 8, j + 0, k + 20, Blocks.stone);
		world.setBlock(i + 8, j + 0, k + 21, Blocks.stone);
		world.setBlock(i + 8, j + 0, k + 22, Blocks.stone);
