package kieranvs.avatar.generation;

import java.util.Random;

import kieranvs.avatar.mod_Avatar;
import kieranvs.avatar.bending.ElementManager;
import kieranvs.avatar.entity.EntityPolarBearDog;
import kieranvs.avatar.entity.EntityWaterMan;
import kieranvs.avatar.entity.EntityWaterWoman;
import kieranvs.avatar.util.GenerationUtils;

import net.minecraft.block.Block;
import net.minecraft.init.Blocks;
import net.minecraft.item.ItemStack;
import net.minecraft.tileentity.TileEntity;
import net.minecraft.tileentity.TileEntityChest;
import net.minecraft.world.World;
import net.minecraft.world.biome.BiomeGenBase;
import net.minecraft.world.chunk.IChunkProvider;
import cpw.mods.fml.common.IWorldGenerator;

public class WorldGenWaterSouthTribeVillage implements IWorldGenerator {

	private static BiomeGenBase[] biomes = {BiomeGenBase.icePlains, BiomeGenBase.coldTaiga, BiomeGenBase.icePlains, BiomeGenBase.frozenOcean, BiomeGenBase.iceMountains};
	
	public void generate(Random random, int chunkX, int chunkZ, World world, IChunkProvider chunkGenerator, IChunkProvider chunkProvider) {
		int[] result = GenerationUtils.shouldSpawnHere(random, chunkX, chunkZ, world, 20, 2, 25, biomes);
		if(result[0] == 0){
			this.generate(world, result[1], result[2] - 4, result[3]);
			this.generateEntities(world, result[1], result[2] - 4, result[3], random);
			this.generateLoot(world, result[1], result[2] - 4, result[3], random);
		}
	}
	
	public void generateLoot(World world, int i, int j, int k, Random random){
		for(int x = i; x < i + 20; x++){
			for (int z = k; z < k + 20; z++) {
				for (int y = j; y < j + 5; y++) {
						TileEntity e = world.getTileEntity(x, y, z);
						if(e != null && e instanceof TileEntityChest){
							GenerationUtils.generateScrolls(random, (TileEntityChest) e, ElementManager.WATER, 1);
							GenerationUtils.generateRandomMoney(random, (TileEntityChest) e, ElementManager.WATER, 2);
							int ran = random.nextInt(10);
							for(int r = 0; r < random.nextInt(3); r++){
								switch (ran){
								case 1:
									((TileEntityChest) e).setInventorySlotContents(random.nextInt(27), new ItemStack(mod_Avatar.SeaPruneItem, random.nextInt(5), 0));	
									break;
								case 2:
									((TileEntityChest) e).setInventorySlotContents(random.nextInt(27), new ItemStack(mod_Avatar.SeaSquidItem, random.nextInt(5), 0));	
									break;
								case 3:
									((TileEntityChest) e).setInventorySlotContents(random.nextInt(27), new ItemStack(mod_Avatar.SeaSquidSoupItem, 1, 0));	
									break;
								case 4:
									((TileEntityChest) e).setInventorySlotContents(random.nextInt(27), new ItemStack(mod_Avatar.SeaweedBreadItem, random.nextInt(5), 0));	
									break;
								case 5:
									((TileEntityChest) e).setInventorySlotContents(random.nextInt(27), new ItemStack(mod_Avatar.SeaweedSoupItem, 1, 0));	
									break;
								}	
							}
							
						}
				}
			}
		}
	}
	
	public void generateEntities(World world, int i, int j, int k, Random random) {
		int numM = random.nextInt(3) + 1;
		int numW = random.nextInt(3) + 1;

		for (int x = 0; x < numM; x++) {
			EntityWaterMan waterMan = new EntityWaterMan(world, i + 10, j + 7, k + 10, 9);
			waterMan.setPositionAndRotation(i + 10, j + 7, k + 10, 1.0F, 1.0F);
			world.spawnEntityInWorld(waterMan);
		}

		for (int x = 0; x < numW; x++) {
			EntityWaterWoman waterWoman = new EntityWaterWoman(world, i + 10, j + 7, k + 10, 9);
			waterWoman.setPositionAndRotation(i + 10, j + 7, k + 10, 1.0F, 1.0F);
			world.spawnEntityInWorld(waterWoman);
		}

		EntityPolarBearDog polarDog = new EntityPolarBearDog(world);
		polarDog.setPositionAndRotation(i + 30, j + 7, k + 30, 1.0F, 1.0F);
		world.spawnEntityInWorld(polarDog);

	}

	public boolean generate(World world, int i, int j, int k) {

		for (int x = 0; x <= 20; x++) {
			for (int z = 0; z <= 20; z++) {
				for (int y = 0; y < 20; y++) {
					world.setBlock(i + x, j + y, k + z, Blocks.air);
				}
			}
		}
		
		world.setBlock(i + 4, j + 4, k + 14, Blocks.bed, 9, 0x02);
		world.setBlock(i + 4, j + 4, k + 15, Blocks.bed, 9, 0x02);
		world.setBlock(i + 5, j + 4, k + 3, Blocks.bed, 9, 0x02);
		world.setBlock(i + 5, j + 4, k + 7, Blocks.bed, 9, 0x02);
		world.setBlock(i + 5, j + 4, k + 14, Blocks.bed, 1, 0x02);
		world.setBlock(i + 5, j + 4, k + 15, Blocks.bed, 1, 0x02);
		world.setBlock(i + 6, j + 4, k + 3, Blocks.bed, 1, 0x02);
		world.setBlock(i + 6, j + 4, k + 7, Blocks.bed, 1, 0x02);

		world.setBlock(i + 0, j + 0, k + 0, Blocks.dirt);
		world.setBlock(i + 0, j + 0, k + 1, Blocks.dirt);
		world.setBlock(i + 0, j + 0, k + 2, Blocks.dirt);
		world.setBlock(i + 0, j + 0, k + 3, Blocks.dirt);
		world.setBlock(i + 0, j + 0, k + 4, Blocks.dirt);
		world.setBlock(i + 0, j + 0, k + 5, Blocks.dirt);
		world.setBlock(i + 0, j + 0, k + 6, Blocks.dirt);
		world.setBlock(i + 0, j + 0, k + 7, Blocks.dirt);
		world.setBlock(i + 0, j + 0, k + 8, Blocks.dirt);
		world.setBlock(i + 0, j + 0, k + 9, Blocks.dirt);
		world.setBlock(i + 0, j + 0, k + 10, Blocks.dirt);
		world.setBlock(i + 0, j + 0, k + 11, Blocks.dirt);
		world.setBlock(i + 0, j + 0, k + 12, Blocks.dirt);
		world.setBlock(i + 0, j + 0, k + 13, Blocks.dirt);
		world.setBlock(i + 0, j + 0, k + 14, Blocks.dirt);
		world.setBlock(i + 0, j + 0, k + 15, Blocks.dirt);
		world.setBlock(i + 0, j + 0, k + 16, Blocks.dirt);
		world.setBlock(i + 0, j + 0, k + 17, Blocks.dirt);
		world.setBlock(i + 0, j + 0, k + 18, Blocks.dirt);
		world.setBlock(i + 0, j + 0, k + 19, Blocks.dirt);
		world.setBlock(i + 0, j + 0, k + 20, Blocks.dirt);
		world.setBlock(i + 0, j + 1, k + 0, Blocks.dirt);
		world.setBlock(i + 0, j + 1, k + 1, Blocks.dirt);
		world.setBlock(i + 0, j + 1, k + 2, Blocks.dirt);
		world.setBlock(i + 0, j + 1, k + 3, Blocks.dirt);
		world.setBlock(i + 0, j + 1, k + 4, Blocks.dirt);
		world.setBlock(i + 0, j + 1, k + 5, Blocks.dirt);
		world.setBlock(i + 0, j + 1, k + 6, Blocks.dirt);
		world.setBlock(i + 0, j + 1, k + 7, Blocks.dirt);
		world.setBlock(i + 0, j + 1, k + 8, Blocks.dirt);
		world.setBlock(i + 0, j + 1, k + 9, Blocks.dirt);
		world.setBlock(i + 0, j + 1, k + 10, Blocks.dirt);
		world.setBlock(i + 0, j + 1, k + 11, Blocks.dirt);
		world.setBlock(i + 0, j + 1, k + 12, Blocks.dirt);
		world.setBlock(i + 0, j + 1, k + 13, Blocks.dirt);
		world.setBlock(i + 0, j + 1, k + 14, Blocks.dirt);
		world.setBlock(i + 0, j + 1, k + 15, Blocks.dirt);
		world.setBlock(i + 0, j + 1, k + 16, Blocks.dirt);
		world.setBlock(i + 0, j + 1, k + 17, Blocks.dirt);
		world.setBlock(i + 0, j + 1, k + 18, Blocks.dirt);
		world.setBlock(i + 0, j + 1, k + 19, Blocks.dirt);
		world.setBlock(i + 0, j + 1, k + 20, Blocks.dirt);
		world.setBlock(i + 0, j + 2, k + 0, Blocks.dirt);
		world.setBlock(i + 0, j + 2, k + 1, Blocks.dirt);
		world.setBlock(i + 0, j + 2, k + 2, Blocks.dirt);
		world.setBlock(i + 0, j + 2, k + 3, Blocks.dirt);
		world.setBlock(i + 0, j + 2, k + 4, Blocks.dirt);
		world.setBlock(i + 0, j + 2, k + 5, Blocks.dirt);
		world.setBlock(i + 0, j + 2, k + 6, Blocks.dirt);
		world.setBlock(i + 0, j + 2, k + 7, Blocks.dirt);
		world.setBlock(i + 0, j + 2, k + 8, Blocks.dirt);
		world.setBlock(i + 0, j + 2, k + 9, Blocks.dirt);
		world.setBlock(i + 0, j + 2, k + 10, Blocks.dirt);
		world.setBlock(i + 0, j + 2, k + 11, Blocks.dirt);
		world.setBlock(i + 0, j + 2, k + 12, Blocks.dirt);
		world.setBlock(i + 0, j + 2, k + 13, Blocks.dirt);
		world.setBlock(i + 0, j + 2, k + 14, Blocks.dirt);
		world.setBlock(i + 0, j + 2, k + 15, Blocks.dirt);
		world.setBlock(i + 0, j + 2, k + 16, Blocks.dirt);
		world.setBlock(i + 0, j + 2, k + 17, Blocks.dirt);
		world.setBlock(i + 0, j + 2, k + 18, Blocks.dirt);
		world.setBlock(i + 0, j + 2, k + 19, Blocks.dirt);
		world.setBlock(i + 0, j + 2, k + 20, Blocks.dirt);
		world.setBlock(i + 0, j + 3, k + 0, Blocks.grass);
		world.setBlock(i + 0, j + 3, k + 1, Blocks.grass);
		world.setBlock(i + 0, j + 3, k + 2, Blocks.grass);
		world.setBlock(i + 0, j + 3, k + 3, Blocks.grass);
		world.setBlock(i + 0, j + 3, k + 4, Blocks.grass);
		world.setBlock(i + 0, j + 3, k + 5, Blocks.grass);
		world.setBlock(i + 0, j + 3, k + 6, Blocks.dirt);
		world.setBlock(i + 0, j + 3, k + 7, Blocks.snow);
		world.setBlock(i + 0, j + 3, k + 8, Blocks.snow);
		world.setBlock(i + 0, j + 3, k + 9, Blocks.snow);
		world.setBlock(i + 0, j + 3, k + 10, Blocks.snow);
		world.setBlock(i + 0, j + 3, k + 11, Blocks.snow);
		world.setBlock(i + 0, j + 3, k + 12, Blocks.snow);
		world.setBlock(i + 0, j + 3, k + 13, Blocks.dirt);
		world.setBlock(i + 0, j + 3, k + 14, Blocks.dirt);
		world.setBlock(i + 0, j + 3, k + 15, Blocks.grass);
		world.setBlock(i + 0, j + 3, k + 16, Blocks.grass);
		world.setBlock(i + 0, j + 3, k + 17, Blocks.grass);
		world.setBlock(i + 0, j + 3, k + 18, Blocks.grass);
		world.setBlock(i + 0, j + 3, k + 19, Blocks.grass);
		world.setBlock(i + 0, j + 3, k + 20, Blocks.grass);
		world.setBlock(i + 0, j + 4, k + 6, Blocks.snow);
		world.setBlock(i + 0, j + 4, k + 7, Blocks.snow);
		world.setBlock(i + 0, j + 4, k + 8, Blocks.snow);
		world.setBlock(i + 0, j + 4, k + 12, Blocks.snow);
		world.setBlock(i + 0, j + 4, k + 13, Blocks.snow);
		world.setBlock(i + 0, j + 4, k + 14, Blocks.snow);
		world.setBlock(i + 1, j + 0, k + 0, Blocks.dirt);
		world.setBlock(i + 1, j + 0, k + 1, Blocks.dirt);
		world.setBlock(i + 1, j + 0, k + 2, Blocks.dirt);
		world.setBlock(i + 1, j + 0, k + 3, Blocks.dirt);
		world.setBlock(i + 1, j + 0, k + 4, Blocks.dirt);
		world.setBlock(i + 1, j + 0, k + 5, Blocks.dirt);
		world.setBlock(i + 1, j + 0, k + 6, Blocks.dirt);
		world.setBlock(i + 1, j + 0, k + 7, Blocks.dirt);
		world.setBlock(i + 1, j + 0, k + 8, Blocks.dirt);
		world.setBlock(i + 1, j + 0, k + 9, Blocks.dirt);
		world.setBlock(i + 1, j + 0, k + 10, Blocks.dirt);
		world.setBlock(i + 1, j + 0, k + 11, Blocks.dirt);
		world.setBlock(i + 1, j + 0, k + 12, Blocks.dirt);
		world.setBlock(i + 1, j + 0, k + 13, Blocks.dirt);
		world.setBlock(i + 1, j + 0, k + 14, Blocks.dirt);
		world.setBlock(i + 1, j + 0, k + 15, Blocks.dirt);
		world.setBlock(i + 1, j + 0, k + 16, Blocks.dirt);
		world.setBlock(i + 1, j + 0, k + 17, Blocks.dirt);
		world.setBlock(i + 1, j + 0, k + 18, Blocks.dirt);
		world.setBlock(i + 1, j + 0, k + 19, Blocks.dirt);
		world.setBlock(i + 1, j + 0, k + 20, Blocks.dirt);
		world.setBlock(i + 1, j + 1, k + 0, Blocks.dirt);
		world.setBlock(i + 1, j + 1, k + 1, Blocks.dirt);
		world.setBlock(i + 1, j + 1, k + 2, Blocks.dirt);
		world.setBlock(i + 1, j + 1, k + 3, Blocks.dirt);
		world.setBlock(i + 1, j + 1, k + 4, Blocks.dirt);
		world.setBlock(i + 1, j + 1, k + 5, Blocks.dirt);
		world.setBlock(i + 1, j + 1, k + 6, Blocks.dirt);
		world.setBlock(i + 1, j + 1, k + 7, Blocks.dirt);
		world.setBlock(i + 1, j + 1, k + 8, Blocks.dirt);
		world.setBlock(i + 1, j + 1, k + 9, Blocks.dirt);
		world.setBlock(i + 1, j + 1, k + 10, Blocks.dirt);
		world.setBlock(i + 1, j + 1, k + 11, Blocks.dirt);
		world.setBlock(i + 1, j + 1, k + 12, Blocks.dirt);
		world.setBlock(i + 1, j + 1, k + 13, Blocks.dirt);
		world.setBlock(i + 1, j + 1, k + 14, Blocks.dirt);
		world.setBlock(i + 1, j + 1, k + 15, Blocks.dirt);
		world.setBlock(i + 1, j + 1, k + 16, Blocks.dirt);
		world.setBlock(i + 1, j + 1, k + 17, Blocks.dirt);
		world.setBlock(i + 1, j + 1, k + 18, Blocks.dirt);
		world.setBlock(i + 1, j + 1, k + 19, Blocks.dirt);
		world.setBlock(i + 1, j + 1, k + 20, Blocks.dirt);
		world.setBlock(i + 1, j + 2, k + 0, Blocks.dirt);
		world.setBlock(i + 1, j + 2, k + 1, Blocks.dirt);
		world.setBlock(i + 1, j + 2, k + 2, Blocks.dirt);
		world.setBlock(i + 1, j + 2, k + 3, Blocks.dirt);
		world.setBlock(i + 1, j + 2, k + 4, Blocks.dirt);
		world.setBlock(i + 1, j + 2, k + 5, Blocks.dirt);
		world.setBlock(i + 1, j + 2, k + 6, Blocks.dirt);
		world.setBlock(i + 1, j + 2, k + 7, Blocks.dirt);
		world.setBlock(i + 1, j + 2, k + 8, Blocks.dirt);
		world.setBlock(i + 1, j + 2, k + 9, Blocks.dirt);
		world.setBlock(i + 1, j + 2, k + 10, Blocks.dirt);
		world.setBlock(i + 1, j + 2, k + 11, Blocks.dirt);
		world.setBlock(i + 1, j + 2, k + 12, Blocks.dirt);
		world.setBlock(i + 1, j + 2, k + 13, Blocks.dirt);
		world.setBlock(i + 1, j + 2, k + 14, Blocks.dirt);
		world.setBlock(i + 1, j + 2, k + 15, Blocks.dirt);
		world.setBlock(i + 1, j + 2, k + 16, Blocks.dirt);
		world.setBlock(i + 1, j + 2, k + 17, Blocks.dirt);
		world.setBlock(i + 1, j + 2, k + 18, Blocks.dirt);
		world.setBlock(i + 1, j + 2, k + 19, Blocks.dirt);
		world.setBlock(i + 1, j + 2, k + 20, Blocks.dirt);
		world.setBlock(i + 1, j + 3, k + 0, Blocks.grass);
		world.setBlock(i + 1, j + 3, k + 1, Blocks.grass);
		world.setBlock(i + 1, j + 3, k + 2, Blocks.grass);
		world.setBlock(i + 1, j + 3, k + 3, Blocks.grass);
		world.setBlock(i + 1, j + 3, k + 4, Blocks.dirt);
		world.setBlock(i + 1, j + 3, k + 5, Blocks.snow);
		world.setBlock(i + 1, j + 3, k + 6, Blocks.snow);
		world.setBlock(i + 1, j + 3, k + 7, Blocks.snow);
		world.setBlock(i + 1, j + 3, k + 8, Blocks.snow);
		world.setBlock(i + 1, j + 3, k + 9, Blocks.snow);
		world.setBlock(i + 1, j + 3, k + 10, Blocks.snow);
		world.setBlock(i + 1, j + 3, k + 11, Blocks.snow);
		world.setBlock(i + 1, j + 3, k + 12, Blocks.snow);
		world.setBlock(i + 1, j + 3, k + 13, Blocks.dirt);
		world.setBlock(i + 1, j + 3, k + 14, Blocks.dirt);
		world.setBlock(i + 1, j + 3, k + 15, Blocks.dirt);
		world.setBlock(i + 1, j + 3, k + 16, Blocks.dirt);
		world.setBlock(i + 1, j + 3, k + 17, Blocks.grass);
		world.setBlock(i + 1, j + 3, k + 18, Blocks.grass);
		world.setBlock(i + 1, j + 3, k + 19, Blocks.grass);
		world.setBlock(i + 1, j + 3, k + 20, Blocks.grass);
		world.setBlock(i + 1, j + 4, k + 4, Blocks.snow);
		world.setBlock(i + 1, j + 4, k + 5, Blocks.snow);
		world.setBlock(i + 1, j + 4, k + 6, Blocks.snow);
		world.setBlock(i + 1, j + 4, k + 7, Blocks.snow);
		world.setBlock(i + 1, j + 4, k + 8, Blocks.snow);
		world.setBlock(i + 1, j + 4, k + 12, Blocks.snow);
		world.setBlock(i + 1, j + 4, k + 13, Blocks.snow);
		world.setBlock(i + 1, j + 4, k + 14, Blocks.snow);
		world.setBlock(i + 1, j + 4, k + 15, Blocks.snow);
		world.setBlock(i + 1, j + 4, k + 16, Blocks.snow);
		world.setBlock(i + 1, j + 5, k + 6, Blocks.snow);
		world.setBlock(i + 1, j + 5, k + 7, Blocks.snow);
		world.setBlock(i + 1, j + 5, k + 8, Blocks.snow);
		world.setBlock(i + 1, j + 5, k + 12, Blocks.snow);
		world.setBlock(i + 1, j + 5, k + 13, Blocks.snow);
		world.setBlock(i + 1, j + 5, k + 14, Blocks.snow);
		world.setBlock(i + 1, j + 6, k + 6, Blocks.snow);
		world.setBlock(i + 1, j + 6, k + 7, Blocks.snow);
		world.setBlock(i + 1, j + 6, k + 8, Blocks.snow);
		world.setBlock(i + 1, j + 6, k + 12, Blocks.snow);
		world.setBlock(i + 1, j + 6, k + 13, Blocks.snow);
		world.setBlock(i + 1, j + 6, k + 14, Blocks.snow);
		world.setBlock(i + 1, j + 7, k + 8, Blocks.snow);
		world.setBlock(i + 1, j + 7, k + 9, Blocks.snow);
		world.setBlock(i + 1, j + 7, k + 11, Blocks.snow);
		world.setBlock(i + 1, j + 7, k + 12, Blocks.snow);
		world.setBlock(i + 1, j + 8, k + 9, Blocks.snow);
		world.setBlock(i + 1, j + 8, k + 10, Blocks.snow);
		world.setBlock(i + 1, j + 8, k + 11, Blocks.snow);
		world.setBlock(i + 1, j + 9, k + 8, Blocks.glowstone);
		world.setBlock(i + 1, j + 9, k + 9, Blocks.fence);
		world.setBlock(i + 1, j + 9, k + 10, Blocks.snow);
		world.setBlock(i + 1, j + 9, k + 11, Blocks.fence);
		world.setBlock(i + 1, j + 9, k + 12, Blocks.glowstone);
		world.setBlock(i + 1, j + 10, k + 8, Blocks.fence);
		world.setBlock(i + 1, j + 10, k + 9, Blocks.fence);
		world.setBlock(i + 1, j + 10, k + 11, Blocks.fence);
		world.setBlock(i + 1, j + 10, k + 12, Blocks.fence);
		world.setBlock(i + 2, j + 0, k + 0, Blocks.dirt);
		world.setBlock(i + 2, j + 0, k + 1, Blocks.dirt);
		world.setBlock(i + 2, j + 0, k + 2, Blocks.dirt);
		world.setBlock(i + 2, j + 0, k + 3, Blocks.dirt);
		world.setBlock(i + 2, j + 0, k + 4, Blocks.dirt);
		world.setBlock(i + 2, j + 0, k + 5, Blocks.dirt);
		world.setBlock(i + 2, j + 0, k + 6, Blocks.dirt);
		world.setBlock(i + 2, j + 0, k + 7, Blocks.dirt);
		world.setBlock(i + 2, j + 0, k + 8, Blocks.dirt);
		world.setBlock(i + 2, j + 0, k + 9, Blocks.dirt);
		world.setBlock(i + 2, j + 0, k + 10, Blocks.dirt);
		world.setBlock(i + 2, j + 0, k + 11, Blocks.dirt);
		world.setBlock(i + 2, j + 0, k + 12, Blocks.dirt);
		world.setBlock(i + 2, j + 0, k + 13, Blocks.dirt);
		world.setBlock(i + 2, j + 0, k + 14, Blocks.dirt);
		world.setBlock(i + 2, j + 0, k + 15, Blocks.dirt);
		world.setBlock(i + 2, j + 0, k + 16, Blocks.dirt);
		world.setBlock(i + 2, j + 0, k + 17, Blocks.dirt);
		world.setBlock(i + 2, j + 0, k + 18, Blocks.dirt);
		world.setBlock(i + 2, j + 0, k + 19, Blocks.dirt);
		world.setBlock(i + 2, j + 0, k + 20, Blocks.dirt);
		world.setBlock(i + 2, j + 1, k + 0, Blocks.dirt);
		world.setBlock(i + 2, j + 1, k + 1, Blocks.dirt);
		world.setBlock(i + 2, j + 1, k + 2, Blocks.dirt);
		world.setBlock(i + 2, j + 1, k + 3, Blocks.dirt);
		world.setBlock(i + 2, j + 1, k + 4, Blocks.dirt);
		world.setBlock(i + 2, j + 1, k + 5, Blocks.dirt);
		world.setBlock(i + 2, j + 1, k + 6, Blocks.dirt);
		world.setBlock(i + 2, j + 1, k + 7, Blocks.dirt);
		world.setBlock(i + 2, j + 1, k + 8, Blocks.dirt);
		world.setBlock(i + 2, j + 1, k + 9, Blocks.dirt);
		world.setBlock(i + 2, j + 1, k + 10, Blocks.dirt);
		world.setBlock(i + 2, j + 1, k + 11, Blocks.dirt);
		world.setBlock(i + 2, j + 1, k + 12, Blocks.dirt);
		world.setBlock(i + 2, j + 1, k + 13, Blocks.dirt);
		world.setBlock(i + 2, j + 1, k + 14, Blocks.dirt);
		world.setBlock(i + 2, j + 1, k + 15, Blocks.dirt);
		world.setBlock(i + 2, j + 1, k + 16, Blocks.dirt);
		world.setBlock(i + 2, j + 1, k + 17, Blocks.dirt);
		world.setBlock(i + 2, j + 1, k + 18, Blocks.dirt);
		world.setBlock(i + 2, j + 1, k + 19, Blocks.dirt);
		world.setBlock(i + 2, j + 1, k + 20, Blocks.dirt);
		world.setBlock(i + 2, j + 2, k + 0, Blocks.dirt);
		world.setBlock(i + 2, j + 2, k + 1, Blocks.dirt);
		world.setBlock(i + 2, j + 2, k + 2, Blocks.dirt);
		world.setBlock(i + 2, j + 2, k + 3, Blocks.dirt);
		world.setBlock(i + 2, j + 2, k + 4, Blocks.dirt);
		world.setBlock(i + 2, j + 2, k + 5, Blocks.dirt);
		world.setBlock(i + 2, j + 2, k + 6, Blocks.dirt);
		world.setBlock(i + 2, j + 2, k + 7, Blocks.dirt);
		world.setBlock(i + 2, j + 2, k + 8, Blocks.dirt);
		world.setBlock(i + 2, j + 2, k + 9, Blocks.dirt);
		world.setBlock(i + 2, j + 2, k + 10, Blocks.dirt);
		world.setBlock(i + 2, j + 2, k + 11, Blocks.dirt);
		world.setBlock(i + 2, j + 2, k + 12, Blocks.dirt);
		world.setBlock(i + 2, j + 2, k + 13, Blocks.dirt);
		world.setBlock(i + 2, j + 2, k + 14, Blocks.dirt);
		world.setBlock(i + 2, j + 2, k + 15, Blocks.dirt);
		world.setBlock(i + 2, j + 2, k + 16, Blocks.dirt);
		world.setBlock(i + 2, j + 2, k + 17, Blocks.dirt);
		world.setBlock(i + 2, j + 2, k + 18, Blocks.dirt);
		world.setBlock(i + 2, j + 2, k + 19, Blocks.dirt);
		world.setBlock(i + 2, j + 2, k + 20, Blocks.dirt);
		world.setBlock(i + 2, j + 3, k + 0, Blocks.grass);
		world.setBlock(i + 2, j + 3, k + 1, Blocks.grass);
		world.setBlock(i + 2, j + 3, k + 2, Blocks.grass);
		world.setBlock(i + 2, j + 3, k + 3, Blocks.dirt);
		world.setBlock(i + 2, j + 3, k + 4, Blocks.dirt);
		world.setBlock(i + 2, j + 3, k + 5, Blocks.snow);
		world.setBlock(i + 2, j + 3, k + 6, Blocks.snow);
		world.setBlock(i + 2, j + 3, k + 7, Blocks.snow);
		world.setBlock(i + 2, j + 3, k + 8, Blocks.snow);
		world.setBlock(i + 2, j + 3, k + 9, Blocks.snow);
		world.setBlock(i + 2, j + 3, k + 10, Blocks.snow);
		world.setBlock(i + 2, j + 3, k + 11, Blocks.snow);
		world.setBlock(i + 2, j + 3, k + 12, Blocks.snow);
		world.setBlock(i + 2, j + 3, k + 13, Blocks.snow);
		world.setBlock(i + 2, j + 3, k + 14, Blocks.snow);
		world.setBlock(i + 2, j + 3, k + 15, Blocks.snow);
		world.setBlock(i + 2, j + 3, k + 16, Blocks.dirt);
		world.setBlock(i + 2, j + 3, k + 17, Blocks.dirt);
		world.setBlock(i + 2, j + 3, k + 18, Blocks.grass);
		world.setBlock(i + 2, j + 3, k + 19, Blocks.grass);
		world.setBlock(i + 2, j + 3, k + 20, Blocks.grass);
		world.setBlock(i + 2, j + 4, k + 3, Blocks.snow);
		world.setBlock(i + 2, j + 4, k + 4, Blocks.snow);
		world.setBlock(i + 2, j + 4, k + 5, Blocks.snow);
		world.setBlock(i + 2, j + 4, k + 13, Blocks.snow);
		world.setBlock(i + 2, j + 4, k + 14, Blocks.snow);
		world.setBlock(i + 2, j + 4, k + 15, Blocks.snow);
		world.setBlock(i + 2, j + 4, k + 16, Blocks.snow);
		world.setBlock(i + 2, j + 4, k + 17, Blocks.snow);
		world.setBlock(i + 2, j + 5, k + 4, Blocks.snow);
		world.setBlock(i + 2, j + 5, k + 5, Blocks.snow);
		world.setBlock(i + 2, j + 5, k + 15, Blocks.snow);
		world.setBlock(i + 2, j + 5, k + 16, Blocks.snow);
		world.setBlock(i + 2, j + 6, k + 4, Blocks.snow);
		world.setBlock(i + 2, j + 6, k + 5, Blocks.snow);
		world.setBlock(i + 2, j + 6, k + 15, Blocks.snow);
		world.setBlock(i + 2, j + 6, k + 16, Blocks.snow);
		world.setBlock(i + 3, j + 0, k + 0, Blocks.dirt);
		world.setBlock(i + 3, j + 0, k + 1, Blocks.dirt);
		world.setBlock(i + 3, j + 0, k + 2, Blocks.dirt);
		world.setBlock(i + 3, j + 0, k + 3, Blocks.dirt);
		world.setBlock(i + 3, j + 0, k + 4, Blocks.dirt);
		world.setBlock(i + 3, j + 0, k + 5, Blocks.dirt);
		world.setBlock(i + 3, j + 0, k + 6, Blocks.dirt);
		world.setBlock(i + 3, j + 0, k + 7, Blocks.dirt);
		world.setBlock(i + 3, j + 0, k + 8, Blocks.dirt);
		world.setBlock(i + 3, j + 0, k + 9, Blocks.dirt);
		world.setBlock(i + 3, j + 0, k + 10, Blocks.dirt);
		world.setBlock(i + 3, j + 0, k + 11, Blocks.dirt);
		world.setBlock(i + 3, j + 0, k + 12, Blocks.dirt);
		world.setBlock(i + 3, j + 0, k + 13, Blocks.dirt);
		world.setBlock(i + 3, j + 0, k + 14, Blocks.dirt);
		world.setBlock(i + 3, j + 0, k + 15, Blocks.dirt);
		world.setBlock(i + 3, j + 0, k + 16, Blocks.dirt);
		world.setBlock(i + 3, j + 0, k + 17, Blocks.dirt);
		world.setBlock(i + 3, j + 0, k + 18, Blocks.dirt);
		world.setBlock(i + 3, j + 0, k + 19, Blocks.dirt);
		world.setBlock(i + 3, j + 0, k + 20, Blocks.dirt);
		world.setBlock(i + 3, j + 1, k + 0, Blocks.dirt);
		world.setBlock(i + 3, j + 1, k + 1, Blocks.dirt);
		world.setBlock(i + 3, j + 1, k + 2, Blocks.dirt);
		world.setBlock(i + 3, j + 1, k + 3, Blocks.dirt);
		world.setBlock(i + 3, j + 1, k + 4, Blocks.dirt);
		world.setBlock(i + 3, j + 1, k + 5, Blocks.dirt);
		world.setBlock(i + 3, j + 1, k + 6, Blocks.dirt);
		world.setBlock(i + 3, j + 1, k + 7, Blocks.dirt);
		world.setBlock(i + 3, j + 1, k + 8, Blocks.dirt);
		world.setBlock(i + 3, j + 1, k + 9, Blocks.dirt);
		world.setBlock(i + 3, j + 1, k + 10, Blocks.dirt);
		world.setBlock(i + 3, j + 1, k + 11, Blocks.dirt);
		world.setBlock(i + 3, j + 1, k + 12, Blocks.dirt);
		world.setBlock(i + 3, j + 1, k + 13, Blocks.dirt);
		world.setBlock(i + 3, j + 1, k + 14, Blocks.dirt);
		world.setBlock(i + 3, j + 1, k + 15, Blocks.dirt);
		world.setBlock(i + 3, j + 1, k + 16, Blocks.dirt);
		world.setBlock(i + 3, j + 1, k + 17, Blocks.dirt);
		world.setBlock(i + 3, j + 1, k + 18, Blocks.dirt);
		world.setBlock(i + 3, j + 1, k + 19, Blocks.dirt);
		world.setBlock(i + 3, j + 1, k + 20, Blocks.dirt);
		world.setBlock(i + 3, j + 2, k + 0, Blocks.dirt);
		world.setBlock(i + 3, j + 2, k + 1, Blocks.dirt);
		world.setBlock(i + 3, j + 2, k + 2, Blocks.dirt);
		world.setBlock(i + 3, j + 2, k + 3, Blocks.dirt);
		world.setBlock(i + 3, j + 2, k + 4, Blocks.dirt);
		world.setBlock(i + 3, j + 2, k + 5, Blocks.dirt);
		world.setBlock(i + 3, j + 2, k + 6, Blocks.dirt);
		world.setBlock(i + 3, j + 2, k + 7, Blocks.dirt);
		world.setBlock(i + 3, j + 2, k + 8, Blocks.dirt);
		world.setBlock(i + 3, j + 2, k + 9, Blocks.dirt);
		world.setBlock(i + 3, j + 2, k + 10, Blocks.dirt);
		world.setBlock(i + 3, j + 2, k + 11, Blocks.dirt);
		world.setBlock(i + 3, j + 2, k + 12, Blocks.dirt);
		world.setBlock(i + 3, j + 2, k + 13, Blocks.dirt);
		world.setBlock(i + 3, j + 2, k + 14, Blocks.dirt);
		world.setBlock(i + 3, j + 2, k + 15, Blocks.dirt);
		world.setBlock(i + 3, j + 2, k + 16, Blocks.dirt);
		world.setBlock(i + 3, j + 2, k + 17, Blocks.dirt);
		world.setBlock(i + 3, j + 2, k + 18, Blocks.dirt);
		world.setBlock(i + 3, j + 2, k + 19, Blocks.dirt);
		world.setBlock(i + 3, j + 2, k + 20, Blocks.dirt);
		world.setBlock(i + 3, j + 3, k + 0, Blocks.grass);
		world.setBlock(i + 3, j + 3, k + 1, Blocks.grass);
		world.setBlock(i + 3, j + 3, k + 2, Blocks.snow);
		world.setBlock(i + 3, j + 3, k + 3, Blocks.snow);
		world.setBlock(i + 3, j + 3, k + 4, Blocks.dirt);
		world.setBlock(i + 3, j + 3, k + 5, Blocks.snow);
		world.setBlock(i + 3, j + 3, k + 6, Blocks.snow);
		world.setBlock(i + 3, j + 3, k + 7, Blocks.snow);
		world.setBlock(i + 3, j + 3, k + 8, Blocks.snow);
		world.setBlock(i + 3, j + 3, k + 9, Blocks.snow);
		world.setBlock(i + 3, j + 3, k + 10, Blocks.snow);
		world.setBlock(i + 3, j + 3, k + 11, Blocks.snow);
		world.setBlock(i + 3, j + 3, k + 12, Blocks.snow);
		world.setBlock(i + 3, j + 3, k + 13, Blocks.snow);
		world.setBlock(i + 3, j + 3, k + 14, Blocks.snow);
		world.setBlock(i + 3, j + 3, k + 15, Blocks.snow);
		world.setBlock(i + 3, j + 3, k + 16, Blocks.dirt);
		world.setBlock(i + 3, j + 3, k + 17, Blocks.dirt);
		world.setBlock(i + 3, j + 3, k + 18, Blocks.dirt);
		world.setBlock(i + 3, j + 3, k + 19, Blocks.grass);
		world.setBlock(i + 3, j + 3, k + 20, Blocks.grass);
		world.setBlock(i + 3, j + 4, k + 2, Blocks.snow);
		world.setBlock(i + 3, j + 4, k + 3, Blocks.snow);
		world.setBlock(i + 3, j + 4, k + 4, Blocks.snow);
		world.setBlock(i + 3, j + 4, k + 5, Blocks.snow);
		world.setBlock(i + 3, j + 4, k + 6, Blocks.snow);
		world.setBlock(i + 3, j + 4, k + 12, Blocks.snow);
		world.setBlock(i + 3, j + 4, k + 13, Blocks.snow);
		world.setBlock(i + 3, j + 4, k + 14, Blocks.snow);
		world.setBlock(i + 3, j + 4, k + 15, Blocks.snow);
		world.setBlock(i + 3, j + 4, k + 16, Blocks.snow);
		world.setBlock(i + 3, j + 4, k + 17, Blocks.snow);
		world.setBlock(i + 3, j + 4, k + 18, Blocks.snow);
		world.setBlock(i + 3, j + 5, k + 3, Blocks.snow);
		world.setBlock(i + 3, j + 5, k + 4, Blocks.snow);
		world.setBlock(i + 3, j + 5, k + 5, Blocks.snow);
		world.setBlock(i + 3, j + 5, k + 6, Blocks.snow);
		world.setBlock(i + 3, j + 5, k + 13, Blocks.snow);
		world.setBlock(i + 3, j + 5, k + 14, Blocks.snow);
		world.setBlock(i + 3, j + 5, k + 15, Blocks.snow);
		world.setBlock(i + 3, j + 5, k + 16, Blocks.snow);
		world.setBlock(i + 3, j + 5, k + 17, Blocks.snow);
		world.setBlock(i + 3, j + 6, k + 3, Blocks.snow);
		world.setBlock(i + 3, j + 6, k + 13, Blocks.snow);
		world.setBlock(i + 3, j + 6, k + 14, Blocks.snow);
		world.setBlock(i + 3, j + 6, k + 15, Blocks.snow);
		world.setBlock(i + 3, j + 6, k + 16, Blocks.snow);
		world.setBlock(i + 3, j + 6, k + 17, Blocks.snow);
		world.setBlock(i + 4, j + 0, k + 0, Blocks.dirt);
		world.setBlock(i + 4, j + 0, k + 1, Blocks.dirt);
		world.setBlock(i + 4, j + 0, k + 2, Blocks.dirt);
		world.setBlock(i + 4, j + 0, k + 3, Blocks.dirt);
		world.setBlock(i + 4, j + 0, k + 4, Blocks.dirt);
		world.setBlock(i + 4, j + 0, k + 5, Blocks.dirt);
		world.setBlock(i + 4, j + 0, k + 6, Blocks.dirt);
		world.setBlock(i + 4, j + 0, k + 7, Blocks.dirt);
		world.setBlock(i + 4, j + 0, k + 8, Blocks.dirt);
		world.setBlock(i + 4, j + 0, k + 9, Blocks.dirt);
		world.setBlock(i + 4, j + 0, k + 10, Blocks.dirt);
		world.setBlock(i + 4, j + 0, k + 11, Blocks.dirt);
		world.setBlock(i + 4, j + 0, k + 12, Blocks.dirt);
		world.setBlock(i + 4, j + 0, k + 13, Blocks.dirt);
		world.setBlock(i + 4, j + 0, k + 14, Blocks.dirt);
		world.setBlock(i + 4, j + 0, k + 15, Blocks.dirt);
		world.setBlock(i + 4, j + 0, k + 16, Blocks.dirt);
		world.setBlock(i + 4, j + 0, k + 17, Blocks.dirt);
		world.setBlock(i + 4, j + 0, k + 18, Blocks.dirt);
		world.setBlock(i + 4, j + 0, k + 19, Blocks.dirt);
		world.setBlock(i + 4, j + 0, k + 20, Blocks.dirt);
		world.setBlock(i + 4, j + 1, k + 0, Blocks.dirt);
		world.setBlock(i + 4, j + 1, k + 1, Blocks.dirt);
		world.setBlock(i + 4, j + 1, k + 2, Blocks.dirt);
		world.setBlock(i + 4, j + 1, k + 3, Blocks.dirt);
		world.setBlock(i + 4, j + 1, k + 4, Blocks.dirt);
		world.setBlock(i + 4, j + 1, k + 5, Blocks.dirt);
		world.setBlock(i + 4, j + 1, k + 6, Blocks.dirt);
		world.setBlock(i + 4, j + 1, k + 7, Blocks.dirt);
		world.setBlock(i + 4, j + 1, k + 8, Blocks.dirt);
		world.setBlock(i + 4, j + 1, k + 9, Blocks.dirt);
		world.setBlock(i + 4, j + 1, k + 10, Blocks.dirt);
		world.setBlock(i + 4, j + 1, k + 11, Blocks.dirt);
		world.setBlock(i + 4, j + 1, k + 12, Blocks.dirt);
		world.setBlock(i + 4, j + 1, k + 13, Blocks.dirt);
		world.setBlock(i + 4, j + 1, k + 14, Blocks.dirt);
		world.setBlock(i + 4, j + 1, k + 15, Blocks.dirt);
		world.setBlock(i + 4, j + 1, k + 16, Blocks.dirt);
		world.setBlock(i + 4, j + 1, k + 17, Blocks.dirt);
		world.setBlock(i + 4, j + 1, k + 18, Blocks.dirt);
		world.setBlock(i + 4, j + 1, k + 19, Blocks.dirt);
		world.setBlock(i + 4, j + 1, k + 20, Blocks.dirt);
		world.setBlock(i + 4, j + 2, k + 0, Blocks.dirt);
		world.setBlock(i + 4, j + 2, k + 1, Blocks.dirt);
		world.setBlock(i + 4, j + 2, k + 2, Blocks.dirt);
		world.setBlock(i + 4, j + 2, k + 3, Blocks.dirt);
		world.setBlock(i + 4, j + 2, k + 4, Blocks.dirt);
		world.setBlock(i + 4, j + 2, k + 5, Blocks.dirt);
		world.setBlock(i + 4, j + 2, k + 6, Blocks.dirt);
		world.setBlock(i + 4, j + 2, k + 7, Blocks.dirt);
		world.setBlock(i + 4, j + 2, k + 8, Blocks.dirt);
		world.setBlock(i + 4, j + 2, k + 9, Blocks.dirt);
		world.setBlock(i + 4, j + 2, k + 10, Blocks.dirt);
		world.setBlock(i + 4, j + 2, k + 11, Blocks.dirt);
		world.setBlock(i + 4, j + 2, k + 12, Blocks.dirt);
		world.setBlock(i + 4, j + 2, k + 13, Blocks.dirt);
		world.setBlock(i + 4, j + 2, k + 14, Blocks.dirt);
		world.setBlock(i + 4, j + 2, k + 15, Blocks.dirt);
		world.setBlock(i + 4, j + 2, k + 16, Blocks.dirt);
		world.setBlock(i + 4, j + 2, k + 17, Blocks.dirt);
		world.setBlock(i + 4, j + 2, k + 18, Blocks.dirt);
		world.setBlock(i + 4, j + 2, k + 19, Blocks.dirt);
		world.setBlock(i + 4, j + 2, k + 20, Blocks.dirt);
		world.setBlock(i + 4, j + 3, k + 0, Blocks.grass);
		world.setBlock(i + 4, j + 3, k + 1, Blocks.dirt);
		world.setBlock(i + 4, j + 3, k + 2, Blocks.snow);
		world.setBlock(i + 4, j + 3, k + 3, Blocks.snow);
		world.setBlock(i + 4, j + 3, k + 4, Blocks.glowstone);
		world.setBlock(i + 4, j + 3, k + 5, Blocks.wool, 11, 0x02);
		world.setBlock(i + 4, j + 3, k + 6, Blocks.glowstone);
		world.setBlock(i + 4, j + 3, k + 7, Blocks.snow);
		world.setBlock(i + 4, j + 3, k + 8, Blocks.snow);
		world.setBlock(i + 4, j + 3, k + 9, Blocks.snow);
		world.setBlock(i + 4, j + 3, k + 10, Blocks.snow);
		world.setBlock(i + 4, j + 3, k + 11, Blocks.snow);
		world.setBlock(i + 4, j + 3, k + 12, Blocks.snow);
		world.setBlock(i + 4, j + 3, k + 13, Blocks.glowstone);
		world.setBlock(i + 4, j + 3, k + 14, Blocks.wool, 11, 0x02);
		world.setBlock(i + 4, j + 3, k + 15, Blocks.wool, 11, 0x02);
		world.setBlock(i + 4, j + 3, k + 16, Blocks.glowstone);
		world.setBlock(i + 4, j + 3, k + 17, Blocks.dirt);
		world.setBlock(i + 4, j + 3, k + 18, Blocks.dirt);
		world.setBlock(i + 4, j + 3, k + 19, Blocks.dirt);
		world.setBlock(i + 4, j + 3, k + 20, Blocks.grass);
		world.setBlock(i + 4, j + 4, k + 1, Blocks.snow);
		world.setBlock(i + 4, j + 4, k + 2, Blocks.snow);
		world.setBlock(i + 4, j + 4, k + 3, Blocks.snow);
		world.setBlock(i + 4, j + 4, k + 4, Blocks.chest, 5, 0x02);
		world.setBlock(i + 4, j + 4, k + 6, Blocks.chest, 5, 0x02);
		world.setBlock(i + 4, j + 4, k + 7, Blocks.snow);
		world.setBlock(i + 4, j + 4, k + 11, Blocks.snow);
		world.setBlock(i + 4, j + 4, k + 12, Blocks.snow);
		world.setBlock(i + 4, j + 4, k + 16, Blocks.chest, 5, 0x02);
		world.setBlock(i + 4, j + 4, k + 17, Blocks.snow);
		world.setBlock(i + 4, j + 4, k + 18, Blocks.snow);
		world.setBlock(i + 4, j + 4, k + 19, Blocks.snow);
		world.setBlock(i + 4, j + 5, k + 2, Blocks.snow);
		world.setBlock(i + 4, j + 5, k + 3, Blocks.snow);
		world.setBlock(i + 4, j + 5, k + 7, Blocks.snow);
		world.setBlock(i + 4, j + 5, k + 12, Blocks.snow);
		world.setBlock(i + 4, j + 5, k + 17, Blocks.snow);
		world.setBlock(i + 4, j + 5, k + 18, Blocks.snow);
		world.setBlock(i + 4, j + 6, k + 2, Blocks.snow);
		world.setBlock(i + 4, j + 6, k + 4, Blocks.snow);
		world.setBlock(i + 4, j + 6, k + 5, Blocks.snow);
		world.setBlock(i + 4, j + 6, k + 6, Blocks.snow);
		world.setBlock(i + 4, j + 6, k + 12, Blocks.snow);
		world.setBlock(i + 4, j + 6, k + 16, Blocks.snow);
		world.setBlock(i + 4, j + 6, k + 17, Blocks.snow);
		world.setBlock(i + 4, j + 6, k + 18, Blocks.snow);
		world.setBlock(i + 4, j + 7, k + 13, Blocks.snow);
		world.setBlock(i + 4, j + 7, k + 14, Blocks.snow);
		world.setBlock(i + 4, j + 7, k + 15, Blocks.snow);
		world.setBlock(i + 5, j + 0, k + 0, Blocks.dirt);
		world.setBlock(i + 5, j + 0, k + 1, Blocks.dirt);
		world.setBlock(i + 5, j + 0, k + 2, Blocks.dirt);
		world.setBlock(i + 5, j + 0, k + 3, Blocks.dirt);
		world.setBlock(i + 5, j + 0, k + 4, Blocks.dirt);
		world.setBlock(i + 5, j + 0, k + 5, Blocks.dirt);
		world.setBlock(i + 5, j + 0, k + 6, Blocks.dirt);
		world.setBlock(i + 5, j + 0, k + 7, Blocks.dirt);
		world.setBlock(i + 5, j + 0, k + 8, Blocks.dirt);
		world.setBlock(i + 5, j + 0, k + 9, Blocks.dirt);
		world.setBlock(i + 5, j + 0, k + 10, Blocks.dirt);
		world.setBlock(i + 5, j + 0, k + 11, Blocks.dirt);
		world.setBlock(i + 5, j + 0, k + 12, Blocks.dirt);
		world.setBlock(i + 5, j + 0, k + 13, Blocks.dirt);
		world.setBlock(i + 5, j + 0, k + 14, Blocks.dirt);
		world.setBlock(i + 5, j + 0, k + 15, Blocks.dirt);
		world.setBlock(i + 5, j + 0, k + 16, Blocks.dirt);
		world.setBlock(i + 5, j + 0, k + 17, Blocks.dirt);
		world.setBlock(i + 5, j + 0, k + 18, Blocks.dirt);
		world.setBlock(i + 5, j + 0, k + 19, Blocks.dirt);
		world.setBlock(i + 5, j + 0, k + 20, Blocks.dirt);
		world.setBlock(i + 5, j + 1, k + 0, Blocks.dirt);
		world.setBlock(i + 5, j + 1, k + 1, Blocks.dirt);
		world.setBlock(i + 5, j + 1, k + 2, Blocks.dirt);
		world.setBlock(i + 5, j + 1, k + 3, Blocks.dirt);
		world.setBlock(i + 5, j + 1, k + 4, Blocks.dirt);
		world.setBlock(i + 5, j + 1, k + 5, Blocks.dirt);
		world.setBlock(i + 5, j + 1, k + 6, Blocks.dirt);
		world.setBlock(i + 5, j + 1, k + 7, Blocks.dirt);
		world.setBlock(i + 5, j + 1, k + 8, Blocks.dirt);
		world.setBlock(i + 5, j + 1, k + 9, Blocks.dirt);
		world.setBlock(i + 5, j + 1, k + 10, Blocks.dirt);
		world.setBlock(i + 5, j + 1, k + 11, Blocks.dirt);
		world.setBlock(i + 5, j + 1, k + 12, Blocks.dirt);
		world.setBlock(i + 5, j + 1, k + 13, Blocks.dirt);
		world.setBlock(i + 5, j + 1, k + 14, Blocks.dirt);
		world.setBlock(i + 5, j + 1, k + 15, Blocks.dirt);
		world.setBlock(i + 5, j + 1, k + 16, Blocks.dirt);
		world.setBlock(i + 5, j + 1, k + 17, Blocks.dirt);
		world.setBlock(i + 5, j + 1, k + 18, Blocks.dirt);
		world.setBlock(i + 5, j + 1, k + 19, Blocks.dirt);
		world.setBlock(i + 5, j + 1, k + 20, Blocks.dirt);
		world.setBlock(i + 5, j + 2, k + 0, Blocks.dirt);
		world.setBlock(i + 5, j + 2, k + 1, Blocks.dirt);
		world.setBlock(i + 5, j + 2, k + 2, Blocks.dirt);
		world.setBlock(i + 5, j + 2, k + 3, Blocks.dirt);
		world.setBlock(i + 5, j + 2, k + 4, Blocks.dirt);
		world.setBlock(i + 5, j + 2, k + 5, Blocks.dirt);
		world.setBlock(i + 5, j + 2, k + 6, Blocks.dirt);
		world.setBlock(i + 5, j + 2, k + 7, Blocks.dirt);
		world.setBlock(i + 5, j + 2, k + 8, Blocks.dirt);
		world.setBlock(i + 5, j + 2, k + 9, Blocks.dirt);
		world.setBlock(i + 5, j + 2, k + 10, Blocks.dirt);
		world.setBlock(i + 5, j + 2, k + 11, Blocks.dirt);
		world.setBlock(i + 5, j + 2, k + 12, Blocks.dirt);
		world.setBlock(i + 5, j + 2, k + 13, Blocks.dirt);
		world.setBlock(i + 5, j + 2, k + 14, Blocks.dirt);
		world.setBlock(i + 5, j + 2, k + 15, Blocks.dirt);
		world.setBlock(i + 5, j + 2, k + 16, Blocks.dirt);
		world.setBlock(i + 5, j + 2, k + 17, Blocks.dirt);
		world.setBlock(i + 5, j + 2, k + 18, Blocks.dirt);
		world.setBlock(i + 5, j + 2, k + 19, Blocks.dirt);
		world.setBlock(i + 5, j + 2, k + 20, Blocks.dirt);
		world.setBlock(i + 5, j + 3, k + 0, Blocks.grass);
		world.setBlock(i + 5, j + 3, k + 1, Blocks.dirt);
		world.setBlock(i + 5, j + 3, k + 2, Blocks.snow);
		world.setBlock(i + 5, j + 3, k + 3, Blocks.wool, 11, 0x02);
		world.setBlock(i + 5, j + 3, k + 4, Blocks.wool, 3, 0x02);
		world.setBlock(i + 5, j + 3, k + 5, Blocks.wool, 3, 0x02);
		world.setBlock(i + 5, j + 3, k + 6, Blocks.wool, 3, 0x02);
		world.setBlock(i + 5, j + 3, k + 7, Blocks.wool, 11, 0x02);
		world.setBlock(i + 5, j + 3, k + 8, Blocks.snow);
		world.setBlock(i + 5, j + 3, k + 9, Blocks.snow);
		world.setBlock(i + 5, j + 3, k + 10, Blocks.snow);
		world.setBlock(i + 5, j + 3, k + 11, Blocks.snow);
		world.setBlock(i + 5, j + 3, k + 12, Blocks.snow);
		world.setBlock(i + 5, j + 3, k + 13, Blocks.wool, 11, 0x02);
		world.setBlock(i + 5, j + 3, k + 14, Blocks.wool, 3, 0x02);
		world.setBlock(i + 5, j + 3, k + 15, Blocks.wool, 3, 0x02);
		world.setBlock(i + 5, j + 3, k + 16, Blocks.wool, 11, 0x02);
		world.setBlock(i + 5, j + 3, k + 17, Blocks.dirt);
		world.setBlock(i + 5, j + 3, k + 18, Blocks.dirt);
		world.setBlock(i + 5, j + 3, k + 19, Blocks.dirt);
		world.setBlock(i + 5, j + 3, k + 20, Blocks.grass);
		world.setBlock(i + 5, j + 4, k + 1, Blocks.snow);
		world.setBlock(i + 5, j + 4, k + 2, Blocks.snow);
		world.setBlock(i + 5, j + 4, k + 8, Blocks.snow);
		world.setBlock(i + 5, j + 4, k + 11, Blocks.snow);
		world.setBlock(i + 5, j + 4, k + 12, Blocks.snow);
		world.setBlock(i + 5, j + 4, k + 17, Blocks.snow);
		world.setBlock(i + 5, j + 4, k + 18, Blocks.snow);
		world.setBlock(i + 5, j + 4, k + 19, Blocks.snow);
		world.setBlock(i + 5, j + 5, k + 2, Blocks.snow);
		world.setBlock(i + 5, j + 5, k + 8, Blocks.snow);
		world.setBlock(i + 5, j + 5, k + 12, Blocks.snow);
		world.setBlock(i + 5, j + 5, k + 17, Blocks.snow);
		world.setBlock(i + 5, j + 5, k + 18, Blocks.snow);
		world.setBlock(i + 5, j + 6, k + 2, Blocks.snow);
		world.setBlock(i + 5, j + 6, k + 3, Blocks.snow);
		world.setBlock(i + 5, j + 6, k + 7, Blocks.snow);
		world.setBlock(i + 5, j + 6, k + 12, Blocks.snow);
		world.setBlock(i + 5, j + 6, k + 17, Blocks.snow);
		world.setBlock(i + 5, j + 6, k + 18, Blocks.snow);
		world.setBlock(i + 5, j + 7, k + 4, Blocks.snow);
		world.setBlock(i + 5, j + 7, k + 5, Blocks.snow);
		world.setBlock(i + 5, j + 7, k + 6, Blocks.snow);
		world.setBlock(i + 5, j + 7, k + 13, Blocks.snow);
		world.setBlock(i + 5, j + 7, k + 15, Blocks.snow);
		world.setBlock(i + 5, j + 7, k + 16, Blocks.snow);
		world.setBlock(i + 5, j + 8, k + 14, Blocks.snow);
		world.setBlock(i + 6, j + 0, k + 0, Blocks.dirt);
		world.setBlock(i + 6, j + 0, k + 1, Blocks.dirt);
		world.setBlock(i + 6, j + 0, k + 2, Blocks.dirt);
		world.setBlock(i + 6, j + 0, k + 3, Blocks.dirt);
		world.setBlock(i + 6, j + 0, k + 4, Blocks.dirt);
		world.setBlock(i + 6, j + 0, k + 5, Blocks.dirt);
		world.setBlock(i + 6, j + 0, k + 6, Blocks.dirt);
		world.setBlock(i + 6, j + 0, k + 7, Blocks.dirt);
		world.setBlock(i + 6, j + 0, k + 8, Blocks.dirt);
		world.setBlock(i + 6, j + 0, k + 9, Blocks.dirt);
		world.setBlock(i + 6, j + 0, k + 10, Blocks.dirt);
		world.setBlock(i + 6, j + 0, k + 11, Blocks.dirt);
		world.setBlock(i + 6, j + 0, k + 12, Blocks.dirt);
		world.setBlock(i + 6, j + 0, k + 13, Blocks.dirt);
		world.setBlock(i + 6, j + 0, k + 14, Blocks.dirt);
		world.setBlock(i + 6, j + 0, k + 15, Blocks.dirt);
		world.setBlock(i + 6, j + 0, k + 16, Blocks.dirt);
		world.setBlock(i + 6, j + 0, k + 17, Blocks.dirt);
		world.setBlock(i + 6, j + 0, k + 18, Blocks.dirt);
		world.setBlock(i + 6, j + 0, k + 19, Blocks.dirt);
		world.setBlock(i + 6, j + 0, k + 20, Blocks.dirt);
		world.setBlock(i + 6, j + 1, k + 0, Blocks.dirt);
		world.setBlock(i + 6, j + 1, k + 1, Blocks.dirt);
		world.setBlock(i + 6, j + 1, k + 2, Blocks.dirt);
		world.setBlock(i + 6, j + 1, k + 3, Blocks.dirt);
		world.setBlock(i + 6, j + 1, k + 4, Blocks.dirt);
		world.setBlock(i + 6, j + 1, k + 5, Blocks.dirt);
		world.setBlock(i + 6, j + 1, k + 6, Blocks.dirt);
		world.setBlock(i + 6, j + 1, k + 7, Blocks.dirt);
		world.setBlock(i + 6, j + 1, k + 8, Blocks.dirt);
		world.setBlock(i + 6, j + 1, k + 9, Blocks.dirt);
		world.setBlock(i + 6, j + 1, k + 10, Blocks.dirt);
		world.setBlock(i + 6, j + 1, k + 11, Blocks.dirt);
		world.setBlock(i + 6, j + 1, k + 12, Blocks.dirt);
		world.setBlock(i + 6, j + 1, k + 13, Blocks.dirt);
		world.setBlock(i + 6, j + 1, k + 14, Blocks.dirt);
		world.setBlock(i + 6, j + 1, k + 15, Blocks.dirt);
		world.setBlock(i + 6, j + 1, k + 16, Blocks.dirt);
		world.setBlock(i + 6, j + 1, k + 17, Blocks.dirt);
		world.setBlock(i + 6, j + 1, k + 18, Blocks.dirt);
		world.setBlock(i + 6, j + 1, k + 19, Blocks.dirt);
		world.setBlock(i + 6, j + 1, k + 20, Blocks.dirt);
		world.setBlock(i + 6, j + 2, k + 0, Blocks.dirt);
		world.setBlock(i + 6, j + 2, k + 1, Blocks.dirt);
		world.setBlock(i + 6, j + 2, k + 2, Blocks.dirt);
		world.setBlock(i + 6, j + 2, k + 3, Blocks.dirt);
		world.setBlock(i + 6, j + 2, k + 4, Blocks.dirt);
		world.setBlock(i + 6, j + 2, k + 5, Blocks.dirt);
		world.setBlock(i + 6, j + 2, k + 6, Blocks.dirt);
		world.setBlock(i + 6, j + 2, k + 7, Blocks.dirt);
		world.setBlock(i + 6, j + 2, k + 8, Blocks.dirt);
		world.setBlock(i + 6, j + 2, k + 9, Blocks.dirt);
		world.setBlock(i + 6, j + 2, k + 10, Blocks.dirt);
		world.setBlock(i + 6, j + 2, k + 11, Blocks.dirt);
		world.setBlock(i + 6, j + 2, k + 12, Blocks.dirt);
		world.setBlock(i + 6, j + 2, k + 13, Blocks.dirt);
		world.setBlock(i + 6, j + 2, k + 14, Blocks.dirt);
		world.setBlock(i + 6, j + 2, k + 15, Blocks.dirt);
		world.setBlock(i + 6, j + 2, k + 16, Blocks.dirt);
		world.setBlock(i + 6, j + 2, k + 17, Blocks.dirt);
		world.setBlock(i + 6, j + 2, k + 18, Blocks.dirt);
		world.setBlock(i + 6, j + 2, k + 19, Blocks.dirt);
		world.setBlock(i + 6, j + 2, k + 20, Blocks.dirt);
		world.setBlock(i + 6, j + 3, k + 0, Blocks.dirt);
		world.setBlock(i + 6, j + 3, k + 1, Blocks.dirt);
		world.setBlock(i + 6, j + 3, k + 2, Blocks.snow);
		world.setBlock(i + 6, j + 3, k + 3, Blocks.wool, 11, 0x02);
		world.setBlock(i + 6, j + 3, k + 4, Blocks.wool, 3, 0x02);
		world.setBlock(i + 6, j + 3, k + 5, Blocks.wool, 3, 0x02);
		world.setBlock(i + 6, j + 3, k + 6, Blocks.wool, 3, 0x02);
		world.setBlock(i + 6, j + 3, k + 7, Blocks.wool, 11, 0x02);
		world.setBlock(i + 6, j + 3, k + 8, Blocks.snow);
		world.setBlock(i + 6, j + 3, k + 9, Blocks.snow);
		world.setBlock(i + 6, j + 3, k + 10, Blocks.snow);
		world.setBlock(i + 6, j + 3, k + 11, Blocks.snow);
		world.setBlock(i + 6, j + 3, k + 12, Blocks.dirt);
		world.setBlock(i + 6, j + 3, k + 13, Blocks.wool, 11, 0x02);
		world.setBlock(i + 6, j + 3, k + 14, Blocks.wool, 3, 0x02);
		world.setBlock(i + 6, j + 3, k + 15, Blocks.wool, 3, 0x02);
		world.setBlock(i + 6, j + 3, k + 16, Blocks.wool, 11, 0x02);
		world.setBlock(i + 6, j + 3, k + 17, Blocks.dirt);
		world.setBlock(i + 6, j + 3, k + 18, Blocks.dirt);
		world.setBlock(i + 6, j + 3, k + 19, Blocks.dirt);
		world.setBlock(i + 6, j + 3, k + 20, Blocks.dirt);
		world.setBlock(i + 6, j + 4, k + 0, Blocks.snow);
		world.setBlock(i + 6, j + 4, k + 1, Blocks.snow);
		world.setBlock(i + 6, j + 4, k + 2, Blocks.snow);
		world.setBlock(i + 6, j + 4, k + 8, Blocks.snow);
		world.setBlock(i + 6, j + 4, k + 11, Blocks.snow);
		world.setBlock(i + 6, j + 4, k + 12, Blocks.snow);
		world.setBlock(i + 6, j + 4, k + 17, Blocks.snow);
		world.setBlock(i + 6, j + 4, k + 18, Blocks.snow);
		world.setBlock(i + 6, j + 4, k + 19, Blocks.snow);
		world.setBlock(i + 6, j + 4, k + 20, Blocks.snow);
		world.setBlock(i + 6, j + 5, k + 1, Blocks.snow);
		world.setBlock(i + 6, j + 5, k + 2, Blocks.snow);
		world.setBlock(i + 6, j + 5, k + 8, Blocks.snow);
		world.setBlock(i + 6, j + 5, k + 12, Blocks.snow);
		world.setBlock(i + 6, j + 5, k + 17, Blocks.snow);
		world.setBlock(i + 6, j + 5, k + 19, Blocks.snow);
		world.setBlock(i + 6, j + 6, k + 1, Blocks.snow);
		world.setBlock(i + 6, j + 6, k + 3, Blocks.snow);
		world.setBlock(i + 6, j + 6, k + 7, Blocks.snow);
		world.setBlock(i + 6, j + 6, k + 12, Blocks.snow);
		world.setBlock(i + 6, j + 6, k + 17, Blocks.snow);
		world.setBlock(i + 6, j + 6, k + 19, Blocks.snow);
		world.setBlock(i + 6, j + 7, k + 4, Blocks.snow);
		world.setBlock(i + 6, j + 7, k + 5, Blocks.glass);
		world.setBlock(i + 6, j + 7, k + 6, Blocks.snow);
		world.setBlock(i + 6, j + 7, k + 13, Blocks.snow);
		world.setBlock(i + 6, j + 7, k + 16, Blocks.snow);
		world.setBlock(i + 6, j + 8, k + 5, Blocks.fence);
		world.setBlock(i + 6, j + 8, k + 13, Blocks.snow);
		world.setBlock(i + 6, j + 8, k + 14, Blocks.glass);
		world.setBlock(i + 6, j + 8, k + 15, Blocks.snow);
		world.setBlock(i + 6, j + 9, k + 14, Blocks.fence);
		world.setBlock(i + 7, j + 0, k + 0, Blocks.dirt);
		world.setBlock(i + 7, j + 0, k + 1, Blocks.dirt);
		world.setBlock(i + 7, j + 0, k + 2, Blocks.dirt);
		world.setBlock(i + 7, j + 0, k + 3, Blocks.dirt);
		world.setBlock(i + 7, j + 0, k + 4, Blocks.dirt);
		world.setBlock(i + 7, j + 0, k + 5, Blocks.dirt);
		world.setBlock(i + 7, j + 0, k + 6, Blocks.dirt);
		world.setBlock(i + 7, j + 0, k + 7, Blocks.dirt);
		world.setBlock(i + 7, j + 0, k + 8, Blocks.dirt);
		world.setBlock(i + 7, j + 0, k + 9, Blocks.dirt);
		world.setBlock(i + 7, j + 0, k + 10, Blocks.dirt);
		world.setBlock(i + 7, j + 0, k + 11, Blocks.dirt);
		world.setBlock(i + 7, j + 0, k + 12, Blocks.dirt);
		world.setBlock(i + 7, j + 0, k + 13, Blocks.dirt);
		world.setBlock(i + 7, j + 0, k + 14, Blocks.dirt);
		world.setBlock(i + 7, j + 0, k + 15, Blocks.dirt);
		world.setBlock(i + 7, j + 0, k + 16, Blocks.dirt);
		world.setBlock(i + 7, j + 0, k + 17, Blocks.dirt);
		world.setBlock(i + 7, j + 0, k + 18, Blocks.dirt);
		world.setBlock(i + 7, j + 0, k + 19, Blocks.dirt);
		world.setBlock(i + 7, j + 0, k + 20, Blocks.dirt);
		world.setBlock(i + 7, j + 1, k + 0, Blocks.dirt);
		world.setBlock(i + 7, j + 1, k + 1, Blocks.dirt);
		world.setBlock(i + 7, j + 1, k + 2, Blocks.dirt);
		world.setBlock(i + 7, j + 1, k + 3, Blocks.dirt);
		world.setBlock(i + 7, j + 1, k + 4, Blocks.dirt);
		world.setBlock(i + 7, j + 1, k + 5, Blocks.dirt);
		world.setBlock(i + 7, j + 1, k + 6, Blocks.dirt);
		world.setBlock(i + 7, j + 1, k + 7, Blocks.dirt);
		world.setBlock(i + 7, j + 1, k + 8, Blocks.dirt);
		world.setBlock(i + 7, j + 1, k + 9, Blocks.dirt);
		world.setBlock(i + 7, j + 1, k + 10, Blocks.dirt);
		world.setBlock(i + 7, j + 1, k + 11, Blocks.dirt);
		world.setBlock(i + 7, j + 1, k + 12, Blocks.dirt);
		world.setBlock(i + 7, j + 1, k + 13, Blocks.dirt);
		world.setBlock(i + 7, j + 1, k + 14, Blocks.dirt);
		world.setBlock(i + 7, j + 1, k + 15, Blocks.dirt);
		world.setBlock(i + 7, j + 1, k + 16, Blocks.dirt);
		world.setBlock(i + 7, j + 1, k + 17, Blocks.dirt);
		world.setBlock(i + 7, j + 1, k + 18, Blocks.dirt);
		world.setBlock(i + 7, j + 1, k + 19, Blocks.dirt);
		world.setBlock(i + 7, j + 1, k + 20, Blocks.dirt);
		world.setBlock(i + 7, j + 2, k + 0, Blocks.dirt);
		world.setBlock(i + 7, j + 2, k + 1, Blocks.dirt);
		world.setBlock(i + 7, j + 2, k + 2, Blocks.dirt);
		world.setBlock(i + 7, j + 2, k + 3, Blocks.dirt);
		world.setBlock(i + 7, j + 2, k + 4, Blocks.dirt);
		world.setBlock(i + 7, j + 2, k + 5, Blocks.dirt);
		world.setBlock(i + 7, j + 2, k + 6, Blocks.dirt);
		world.setBlock(i + 7, j + 2, k + 7, Blocks.dirt);
		world.setBlock(i + 7, j + 2, k + 8, Blocks.dirt);
		world.setBlock(i + 7, j + 2, k + 9, Blocks.dirt);
		world.setBlock(i + 7, j + 2, k + 10, Blocks.dirt);
		world.setBlock(i + 7, j + 2, k + 11, Blocks.dirt);
		world.setBlock(i + 7, j + 2, k + 12, Blocks.dirt);
		world.setBlock(i + 7, j + 2, k + 13, Blocks.dirt);
		world.setBlock(i + 7, j + 2, k + 14, Blocks.dirt);
		world.setBlock(i + 7, j + 2, k + 15, Blocks.dirt);
		world.setBlock(i + 7, j + 2, k + 16, Blocks.dirt);
		world.setBlock(i + 7, j + 2, k + 17, Blocks.dirt);
		world.setBlock(i + 7, j + 2, k + 18, Blocks.dirt);
		world.setBlock(i + 7, j + 2, k + 19, Blocks.dirt);
		world.setBlock(i + 7, j + 2, k + 20, Blocks.dirt);
		world.setBlock(i + 7, j + 3, k + 0, Blocks.dirt);
		world.setBlock(i + 7, j + 3, k + 1, Blocks.dirt);
		world.setBlock(i + 7, j + 3, k + 2, Blocks.snow);
		world.setBlock(i + 7, j + 3, k + 3, Blocks.wool, 11, 0x02);
		world.setBlock(i + 7, j + 3, k + 4, Blocks.wool, 3, 0x02);
		world.setBlock(i + 7, j + 3, k + 5, Blocks.wool, 3, 0x02);
		world.setBlock(i + 7, j + 3, k + 6, Blocks.wool, 3, 0x02);
		world.setBlock(i + 7, j + 3, k + 7, Blocks.wool, 11, 0x02);
		world.setBlock(i + 7, j + 3, k + 8, Blocks.snow);
		world.setBlock(i + 7, j + 3, k + 9, Blocks.snow);
		world.setBlock(i + 7, j + 3, k + 10, Blocks.snow);
		world.setBlock(i + 7, j + 3, k + 11, Blocks.snow);
		world.setBlock(i + 7, j + 3, k + 12, Blocks.snow);
		world.setBlock(i + 7, j + 3, k + 13, Blocks.wool, 11, 0x02);
		world.setBlock(i + 7, j + 3, k + 14, Blocks.wool, 11, 0x02);
		world.setBlock(i + 7, j + 3, k + 15, Blocks.wool, 11, 0x02);
		world.setBlock(i + 7, j + 3, k + 16, Blocks.glowstone);
		world.setBlock(i + 7, j + 3, k + 17, Blocks.snow);
		world.setBlock(i + 7, j + 3, k + 18, Blocks.snow);
		world.setBlock(i + 7, j + 3, k + 19, Blocks.dirt);
		world.setBlock(i + 7, j + 3, k + 20, Blocks.dirt);
		world.setBlock(i + 7, j + 4, k + 0, Blocks.snow);
		world.setBlock(i + 7, j + 4, k + 1, Blocks.snow);
		world.setBlock(i + 7, j + 4, k + 2, Blocks.snow);
		world.setBlock(i + 7, j + 4, k + 8, Blocks.snow);
		world.setBlock(i + 7, j + 4, k + 15, Blocks.fence);
		world.setBlock(i + 7, j + 4, k + 16, Blocks.fence);
		world.setBlock(i + 7, j + 4, k + 17, Blocks.snow);
		world.setBlock(i + 7, j + 4, k + 18, Blocks.snow);
		world.setBlock(i + 7, j + 4, k + 19, Blocks.snow);
		world.setBlock(i + 7, j + 4, k + 20, Blocks.snow);
		world.setBlock(i + 7, j + 5, k + 1, Blocks.snow);
		world.setBlock(i + 7, j + 5, k + 2, Blocks.snow);
		world.setBlock(i + 7, j + 5, k + 8, Blocks.snow);
		world.setBlock(i + 7, j + 5, k + 17, Blocks.snow);
		world.setBlock(i + 7, j + 5, k + 19, Blocks.snow);
		world.setBlock(i + 7, j + 6, k + 1, Blocks.snow);
		world.setBlock(i + 7, j + 6, k + 3, Blocks.snow);
		world.setBlock(i + 7, j + 6, k + 7, Blocks.snow);
		world.setBlock(i + 7, j + 6, k + 12, Blocks.snow);
		world.setBlock(i + 7, j + 6, k + 13, Blocks.snow);
		world.setBlock(i + 7, j + 6, k + 17, Blocks.snow);
		world.setBlock(i + 7, j + 6, k + 19, Blocks.snow);
		world.setBlock(i + 7, j + 7, k + 4, Blocks.snow);
		world.setBlock(i + 7, j + 7, k + 5, Blocks.snow);
		world.setBlock(i + 7, j + 7, k + 6, Blocks.snow);
		world.setBlock(i + 7, j + 7, k + 14, Blocks.snow);
		world.setBlock(i + 7, j + 7, k + 15, Blocks.snow);
		world.setBlock(i + 7, j + 7, k + 16, Blocks.snow);
		world.setBlock(i + 7, j + 8, k + 14, Blocks.snow);
		world.setBlock(i + 8, j + 0, k + 0, Blocks.dirt);
		world.setBlock(i + 8, j + 0, k + 1, Blocks.dirt);
		world.setBlock(i + 8, j + 0, k + 2, Blocks.dirt);
		world.setBlock(i + 8, j + 0, k + 3, Blocks.dirt);
		world.setBlock(i + 8, j + 0, k + 4, Blocks.dirt);
		world.setBlock(i + 8, j + 0, k + 5, Blocks.dirt);
		world.setBlock(i + 8, j + 0, k + 6, Blocks.dirt);
		world.setBlock(i + 8, j + 0, k + 7, Blocks.dirt);
		world.setBlock(i + 8, j + 0, k + 8, Blocks.dirt);
		world.setBlock(i + 8, j + 0, k + 9, Blocks.dirt);
		world.setBlock(i + 8, j + 0, k + 10, Blocks.dirt);
		world.setBlock(i + 8, j + 0, k + 11, Blocks.dirt);
		world.setBlock(i + 8, j + 0, k + 12, Blocks.dirt);
		world.setBlock(i + 8, j + 0, k + 13, Blocks.dirt);
		world.setBlock(i + 8, j + 0, k + 14, Blocks.dirt);
		world.setBlock(i + 8, j + 0, k + 15, Blocks.dirt);
		world.setBlock(i + 8, j + 0, k + 16, Blocks.dirt);
		world.setBlock(i + 8, j + 0, k + 17, Blocks.dirt);
		world.setBlock(i + 8, j + 0, k + 18, Blocks.dirt);
		world.setBlock(i + 8, j + 0, k + 19, Blocks.dirt);
		world.setBlock(i + 8, j + 0, k + 20, Blocks.dirt);
		world.setBlock(i + 8, j + 1, k + 0, Blocks.dirt);
		world.setBlock(i + 8, j + 1, k + 1, Blocks.dirt);
		world.setBlock(i + 8, j + 1, k + 2, Blocks.dirt);
		world.setBlock(i + 8, j + 1, k + 3, Blocks.dirt);
		world.setBlock(i + 8, j + 1, k + 4, Blocks.dirt);
		world.setBlock(i + 8, j + 1, k + 5, Blocks.dirt);
		world.setBlock(i + 8, j + 1, k + 6, Blocks.dirt);
		world.setBlock(i + 8, j + 1, k + 7, Blocks.dirt);
		world.setBlock(i + 8, j + 1, k + 8, Blocks.dirt);
		world.setBlock(i + 8, j + 1, k + 9, Blocks.dirt);
		world.setBlock(i + 8, j + 1, k + 10, Blocks.dirt);
		world.setBlock(i + 8, j + 1, k + 11, Blocks.dirt);
		world.setBlock(i + 8, j + 1, k + 12, Blocks.dirt);
		world.setBlock(i + 8, j + 1, k + 13, Blocks.dirt);
		world.setBlock(i + 8, j + 1, k + 14, Blocks.dirt);
		world.setBlock(i + 8, j + 1, k + 15, Blocks.dirt);
		world.setBlock(i + 8, j + 1, k + 16, Blocks.dirt);
		world.setBlock(i + 8, j + 1, k + 17, Blocks.dirt);
		world.setBlock(i + 8, j + 1, k + 18, Blocks.dirt);
		world.setBlock(i + 8, j + 1, k + 19, Blocks.dirt);
		world.setBlock(i + 8, j + 1, k + 20, Blocks.dirt);
		world.setBlock(i + 8, j + 2, k + 0, Blocks.dirt);
		world.setBlock(i + 8, j + 2, k + 1, Blocks.dirt);
		world.setBlock(i + 8, j + 2, k + 2, Blocks.dirt);
		world.setBlock(i + 8, j + 2, k + 3, Blocks.dirt);
		world.setBlock(i + 8, j + 2, k + 4, Blocks.dirt);
		world.setBlock(i + 8, j + 2, k + 5, Blocks.dirt);
		world.setBlock(i + 8, j + 2, k + 6, Blocks.dirt);
		world.setBlock(i + 8, j + 2, k + 7, Blocks.dirt);
		world.setBlock(i + 8, j + 2, k + 8, Blocks.dirt);
		world.setBlock(i + 8, j + 2, k + 9, Blocks.dirt);
		world.setBlock(i + 8, j + 2, k + 10, Blocks.dirt);
		world.setBlock(i + 8, j + 2, k + 11, Blocks.dirt);
		world.setBlock(i + 8, j + 2, k + 12, Blocks.dirt);
		world.setBlock(i + 8, j + 2, k + 13, Blocks.dirt);
		world.setBlock(i + 8, j + 2, k + 14, Blocks.dirt);
		world.setBlock(i + 8, j + 2, k + 15, Blocks.dirt);
		world.setBlock(i + 8, j + 2, k + 16, Blocks.dirt);
		world.setBlock(i + 8, j + 2, k + 17, Blocks.dirt);
		world.setBlock(i + 8, j + 2, k + 18, Blocks.dirt);
		world.setBlock(i + 8, j + 2, k + 19, Blocks.dirt);
		world.setBlock(i + 8, j + 2, k + 20, Blocks.dirt);
		world.setBlock(i + 8, j + 3, k + 0, Blocks.dirt);
		world.setBlock(i + 8, j + 3, k + 1, Blocks.dirt);
		world.setBlock(i + 8, j + 3, k + 2, Blocks.snow);
		world.setBlock(i + 8, j + 3, k + 3, Blocks.snow);
		world.setBlock(i + 8, j + 3, k + 4, Blocks.glowstone);
		world.setBlock(i + 8, j + 3, k + 5, Blocks.wool, 11, 0x02);
		world.setBlock(i + 8, j + 3, k + 6, Blocks.glowstone);
		world.setBlock(i + 8, j + 3, k + 7, Blocks.snow);
		world.setBlock(i + 8, j + 3, k + 8, Blocks.snow);
		world.setBlock(i + 8, j + 3, k + 9, Blocks.snow);
		world.setBlock(i + 8, j + 3, k + 10, Blocks.snow);
		world.setBlock(i + 8, j + 3, k + 11, Blocks.snow);
		world.setBlock(i + 8, j + 3, k + 12, Blocks.snow);
		world.setBlock(i + 8, j + 3, k + 13, Blocks.snow);
		world.setBlock(i + 8, j + 3, k + 14, Blocks.dirt);
		world.setBlock(i + 8, j + 3, k + 15, Blocks.dirt);
		world.setBlock(i + 8, j + 3, k + 16, Blocks.dirt);
		world.setBlock(i + 8, j + 3, k + 17, Blocks.snow);
		world.setBlock(i + 8, j + 3, k + 18, Blocks.snow);
		world.setBlock(i + 8, j + 3, k + 19, Blocks.snow);
		world.setBlock(i + 8, j + 3, k + 20, Blocks.snow);
		world.setBlock(i + 8, j + 4, k + 0, Blocks.snow);
		world.setBlock(i + 8, j + 4, k + 1, Blocks.snow);
		world.setBlock(i + 8, j + 4, k + 3, Blocks.snow);
		world.setBlock(i + 8, j + 4, k + 4, Blocks.fence);
		world.setBlock(i + 8, j + 4, k + 6, Blocks.fence);
		world.setBlock(i + 8, j + 4, k + 7, Blocks.snow);
		world.setBlock(i + 8, j + 4, k + 14, Blocks.snow);
		world.setBlock(i + 8, j + 4, k + 15, Blocks.snow);
		world.setBlock(i + 8, j + 4, k + 16, Blocks.snow);
		world.setBlock(i + 8, j + 4, k + 17, Blocks.snow);
		world.setBlock(i + 8, j + 4, k + 19, Blocks.snow);
		world.setBlock(i + 8, j + 4, k + 20, Blocks.snow);
		world.setBlock(i + 8, j + 5, k + 1, Blocks.snow);
		world.setBlock(i + 8, j + 5, k + 3, Blocks.snow);
		world.setBlock(i + 8, j + 5, k + 7, Blocks.snow);
		world.setBlock(i + 8, j + 5, k + 14, Blocks.snow);
		world.setBlock(i + 8, j + 5, k + 15, Blocks.snow);
		world.setBlock(i + 8, j + 5, k + 16, Blocks.snow);
		world.setBlock(i + 8, j + 5, k + 19, Blocks.snow);
		world.setBlock(i + 8, j + 6, k + 1, Blocks.snow);
		world.setBlock(i + 8, j + 6, k + 4, Blocks.snow);
		world.setBlock(i + 8, j + 6, k + 5, Blocks.snow);
		world.setBlock(i + 8, j + 6, k + 6, Blocks.snow);
		world.setBlock(i + 8, j + 6, k + 13, Blocks.snow);
		world.setBlock(i + 8, j + 6, k + 14, Blocks.snow);
		world.setBlock(i + 8, j + 6, k + 15, Blocks.snow);
		world.setBlock(i + 8, j + 6, k + 16, Blocks.snow);
		world.setBlock(i + 8, j + 6, k + 19, Blocks.snow);
		world.setBlock(i + 8, j + 7, k + 1, Blocks.snow);
		world.setBlock(i + 8, j + 7, k + 19, Blocks.snow);
		world.setBlock(i + 8, j + 9, k + 1, Blocks.glowstone);
		world.setBlock(i + 8, j + 9, k + 19, Blocks.glowstone);
		world.setBlock(i + 8, j + 10, k + 1, Blocks.fence);
		world.setBlock(i + 8, j + 10, k + 19, Blocks.fence);
		world.setBlock(i + 9, j + 0, k + 0, Blocks.dirt);
		world.setBlock(i + 9, j + 0, k + 1, Blocks.dirt);
		world.setBlock(i + 9, j + 0, k + 2, Blocks.dirt);
		world.setBlock(i + 9, j + 0, k + 3, Blocks.dirt);
		world.setBlock(i + 9, j + 0, k + 4, Blocks.dirt);
		world.setBlock(i + 9, j + 0, k + 5, Blocks.dirt);
		world.setBlock(i + 9, j + 0, k + 6, Blocks.dirt);
		world.setBlock(i + 9, j + 0, k + 7, Blocks.dirt);
		world.setBlock(i + 9, j + 0, k + 8, Blocks.dirt);
		world.setBlock(i + 9, j + 0, k + 9, Blocks.dirt);
		world.setBlock(i + 9, j + 0, k + 10, Blocks.dirt);
		world.setBlock(i + 9, j + 0, k + 11, Blocks.dirt);
		world.setBlock(i + 9, j + 0, k + 12, Blocks.dirt);
		world.setBlock(i + 9, j + 0, k + 13, Blocks.dirt);
		world.setBlock(i + 9, j + 0, k + 14, Blocks.dirt);
		world.setBlock(i + 9, j + 0, k + 15, Blocks.dirt);
		world.setBlock(i + 9, j + 0, k + 16, Blocks.dirt);
		world.setBlock(i + 9, j + 0, k + 17, Blocks.dirt);
		world.setBlock(i + 9, j + 0, k + 18, Blocks.dirt);
		world.setBlock(i + 9, j + 0, k + 19, Blocks.dirt);
		world.setBlock(i + 9, j + 0, k + 20, Blocks.dirt);
		world.setBlock(i + 9, j + 1, k + 0, Blocks.dirt);
		world.setBlock(i + 9, j + 1, k + 1, Blocks.dirt);
		world.setBlock(i + 9, j + 1, k + 2, Blocks.dirt);
		world.setBlock(i + 9, j + 1, k + 3, Blocks.dirt);
		world.setBlock(i + 9, j + 1, k + 4, Blocks.dirt);
		world.setBlock(i + 9, j + 1, k + 5, Blocks.dirt);
		world.setBlock(i + 9, j + 1, k + 6, Blocks.dirt);
		world.setBlock(i + 9, j + 1, k + 7, Blocks.dirt);
		world.setBlock(i + 9, j + 1, k + 8, Blocks.dirt);
		world.setBlock(i + 9, j + 1, k + 9, Blocks.dirt);
		world.setBlock(i + 9, j + 1, k + 10, Blocks.dirt);
		world.setBlock(i + 9, j + 1, k + 11, Blocks.dirt);
		world.setBlock(i + 9, j + 1, k + 12, Blocks.dirt);
		world.setBlock(i + 9, j + 1, k + 13, Blocks.dirt);
		world.setBlock(i + 9, j + 1, k + 14, Blocks.dirt);
		world.setBlock(i + 9, j + 1, k + 15, Blocks.dirt);
		world.setBlock(i + 9, j + 1, k + 16, Blocks.dirt);
		world.setBlock(i + 9, j + 1, k + 17, Blocks.dirt);
		world.setBlock(i + 9, j + 1, k + 18, Blocks.dirt);
		world.setBlock(i + 9, j + 1, k + 19, Blocks.dirt);
		world.setBlock(i + 9, j + 1, k + 20, Blocks.dirt);
		world.setBlock(i + 9, j + 2, k + 0, Blocks.dirt);
		world.setBlock(i + 9, j + 2, k + 1, Blocks.dirt);
		world.setBlock(i + 9, j + 2, k + 2, Blocks.dirt);
		world.setBlock(i + 9, j + 2, k + 3, Blocks.dirt);
		world.setBlock(i + 9, j + 2, k + 4, Blocks.dirt);
		world.setBlock(i + 9, j + 2, k + 5, Blocks.dirt);
		world.setBlock(i + 9, j + 2, k + 6, Blocks.dirt);
		world.setBlock(i + 9, j + 2, k + 7, Blocks.dirt);
		world.setBlock(i + 9, j + 2, k + 8, Blocks.dirt);
		world.setBlock(i + 9, j + 2, k + 9, Blocks.dirt);
		world.setBlock(i + 9, j + 2, k + 10, Blocks.dirt);
		world.setBlock(i + 9, j + 2, k + 11, Blocks.dirt);
		world.setBlock(i + 9, j + 2, k + 12, Blocks.dirt);
		world.setBlock(i + 9, j + 2, k + 13, Blocks.dirt);
		world.setBlock(i + 9, j + 2, k + 14, Blocks.dirt);
		world.setBlock(i + 9, j + 2, k + 15, Blocks.dirt);
		world.setBlock(i + 9, j + 2, k + 16, Blocks.dirt);
		world.setBlock(i + 9, j + 2, k + 17, Blocks.dirt);
		world.setBlock(i + 9, j + 2, k + 18, Blocks.dirt);
		world.setBlock(i + 9, j + 2, k + 19, Blocks.dirt);
		world.setBlock(i + 9, j + 2, k + 20, Blocks.dirt);
		world.setBlock(i + 9, j + 3, k + 0, Blocks.snow);
		world.setBlock(i + 9, j + 3, k + 1, Blocks.snow);
		world.setBlock(i + 9, j + 3, k + 2, Blocks.snow);
		world.setBlock(i + 9, j + 3, k + 3, Blocks.snow);
		world.setBlock(i + 9, j + 3, k + 4, Blocks.snow);
		world.setBlock(i + 9, j + 3, k + 5, Blocks.wool, 11, 0x02);
		world.setBlock(i + 9, j + 3, k + 6, Blocks.snow);
		world.setBlock(i + 9, j + 3, k + 7, Blocks.snow);
		world.setBlock(i + 9, j + 3, k + 8, Blocks.snow);
		world.setBlock(i + 9, j + 3, k + 9, Blocks.snow);
		world.setBlock(i + 9, j + 3, k + 10, Blocks.snow);
		world.setBlock(i + 9, j + 3, k + 11, Blocks.snow);
		world.setBlock(i + 9, j + 3, k + 12, Blocks.snow);
		world.setBlock(i + 9, j + 3, k + 13, Blocks.snow);
		world.setBlock(i + 9, j + 3, k + 14, Blocks.snow);
		world.setBlock(i + 9, j + 3, k + 15, Blocks.snow);
		world.setBlock(i + 9, j + 3, k + 16, Blocks.snow);
		world.setBlock(i + 9, j + 3, k + 17, Blocks.snow);
		world.setBlock(i + 9, j + 3, k + 18, Blocks.snow);
		world.setBlock(i + 9, j + 3, k + 19, Blocks.snow);
		world.setBlock(i + 9, j + 3, k + 20, Blocks.snow);
		world.setBlock(i + 9, j + 4, k + 4, Blocks.snow);
		world.setBlock(i + 9, j + 4, k + 6, Blocks.snow);
		world.setBlock(i + 9, j + 4, k + 14, Blocks.snow);
		world.setBlock(i + 9, j + 4, k + 15, Blocks.snow);
		world.setBlock(i + 9, j + 4, k + 16, Blocks.snow);
		world.setBlock(i + 9, j + 5, k + 4, Blocks.snow);
		world.setBlock(i + 9, j + 5, k + 6, Blocks.snow);
		world.setBlock(i + 9, j + 6, k + 5, Blocks.snow);
		world.setBlock(i + 9, j + 7, k + 1, Blocks.snow);
		world.setBlock(i + 9, j + 7, k + 19, Blocks.snow);
		world.setBlock(i + 9, j + 8, k + 1, Blocks.snow);
		world.setBlock(i + 9, j + 8, k + 19, Blocks.snow);
		world.setBlock(i + 9, j + 9, k + 1, Blocks.fence);
		world.setBlock(i + 9, j + 9, k + 19, Blocks.fence);
		world.setBlock(i + 9, j + 10, k + 1, Blocks.fence);
		world.setBlock(i + 9, j + 10, k + 19, Blocks.fence);
		world.setBlock(i + 10, j + 0, k + 0, Blocks.dirt);
		world.setBlock(i + 10, j + 0, k + 1, Blocks.dirt);
		world.setBlock(i + 10, j + 0, k + 2, Blocks.dirt);
		world.setBlock(i + 10, j + 0, k + 3, Blocks.dirt);
		world.setBlock(i + 10, j + 0, k + 4, Blocks.dirt);
		world.setBlock(i + 10, j + 0, k + 5, Blocks.dirt);
		world.setBlock(i + 10, j + 0, k + 6, Blocks.dirt);
		world.setBlock(i + 10, j + 0, k + 7, Blocks.dirt);
		world.setBlock(i + 10, j + 0, k + 8, Blocks.dirt);
		world.setBlock(i + 10, j + 0, k + 9, Blocks.dirt);
		world.setBlock(i + 10, j + 0, k + 10, Blocks.dirt);
		world.setBlock(i + 10, j + 0, k + 11, Blocks.dirt);
		world.setBlock(i + 10, j + 0, k + 12, Blocks.dirt);
		world.setBlock(i + 10, j + 0, k + 13, Blocks.dirt);
		world.setBlock(i + 10, j + 0, k + 14, Blocks.dirt);
		world.setBlock(i + 10, j + 0, k + 15, Blocks.dirt);
		world.setBlock(i + 10, j + 0, k + 16, Blocks.dirt);
		world.setBlock(i + 10, j + 0, k + 17, Blocks.dirt);
		world.setBlock(i + 10, j + 0, k + 18, Blocks.dirt);
		world.setBlock(i + 10, j + 0, k + 19, Blocks.dirt);
		world.setBlock(i + 10, j + 0, k + 20, Blocks.dirt);
		world.setBlock(i + 10, j + 1, k + 0, Blocks.dirt);
		world.setBlock(i + 10, j + 1, k + 1, Blocks.dirt);
		world.setBlock(i + 10, j + 1, k + 2, Blocks.dirt);
		world.setBlock(i + 10, j + 1, k + 3, Blocks.dirt);
		world.setBlock(i + 10, j + 1, k + 4, Blocks.dirt);
		world.setBlock(i + 10, j + 1, k + 5, Blocks.dirt);
		world.setBlock(i + 10, j + 1, k + 6, Blocks.dirt);
		world.setBlock(i + 10, j + 1, k + 7, Blocks.dirt);
		world.setBlock(i + 10, j + 1, k + 8, Blocks.dirt);
		world.setBlock(i + 10, j + 1, k + 9, Blocks.dirt);
		world.setBlock(i + 10, j + 1, k + 10, Blocks.dirt);
		world.setBlock(i + 10, j + 1, k + 11, Blocks.dirt);
		world.setBlock(i + 10, j + 1, k + 12, Blocks.dirt);
		world.setBlock(i + 10, j + 1, k + 13, Blocks.dirt);
		world.setBlock(i + 10, j + 1, k + 14, Blocks.dirt);
		world.setBlock(i + 10, j + 1, k + 15, Blocks.dirt);
		world.setBlock(i + 10, j + 1, k + 16, Blocks.dirt);
		world.setBlock(i + 10, j + 1, k + 17, Blocks.dirt);
		world.setBlock(i + 10, j + 1, k + 18, Blocks.dirt);
		world.setBlock(i + 10, j + 1, k + 19, Blocks.dirt);
		world.setBlock(i + 10, j + 1, k + 20, Blocks.dirt);
		world.setBlock(i + 10, j + 2, k + 0, Blocks.dirt);
		world.setBlock(i + 10, j + 2, k + 1, Blocks.dirt);
		world.setBlock(i + 10, j + 2, k + 2, Blocks.dirt);
		world.setBlock(i + 10, j + 2, k + 3, Blocks.dirt);
		world.setBlock(i + 10, j + 2, k + 4, Blocks.dirt);
		world.setBlock(i + 10, j + 2, k + 5, Blocks.dirt);
		world.setBlock(i + 10, j + 2, k + 6, Blocks.dirt);
		world.setBlock(i + 10, j + 2, k + 7, Blocks.dirt);
		world.setBlock(i + 10, j + 2, k + 8, Blocks.dirt);
		world.setBlock(i + 10, j + 2, k + 9, Blocks.dirt);
		world.setBlock(i + 10, j + 2, k + 10, Blocks.dirt);
		world.setBlock(i + 10, j + 2, k + 11, Blocks.dirt);
		world.setBlock(i + 10, j + 2, k + 12, Blocks.dirt);
		world.setBlock(i + 10, j + 2, k + 13, Blocks.dirt);
		world.setBlock(i + 10, j + 2, k + 14, Blocks.dirt);
		world.setBlock(i + 10, j + 2, k + 15, Blocks.dirt);
		world.setBlock(i + 10, j + 2, k + 16, Blocks.dirt);
		world.setBlock(i + 10, j + 2, k + 17, Blocks.dirt);
		world.setBlock(i + 10, j + 2, k + 18, Blocks.dirt);
		world.setBlock(i + 10, j + 2, k + 19, Blocks.dirt);
		world.setBlock(i + 10, j + 2, k + 20, Blocks.dirt);
		world.setBlock(i + 10, j + 3, k + 0, Blocks.snow);
		world.setBlock(i + 10, j + 3, k + 1, Blocks.snow);
		world.setBlock(i + 10, j + 3, k + 2, Blocks.snow);
		world.setBlock(i + 10, j + 3, k + 3, Blocks.snow);
		world.setBlock(i + 10, j + 3, k + 4, Blocks.snow);
		world.setBlock(i + 10, j + 3, k + 5, Blocks.snow);
		world.setBlock(i + 10, j + 3, k + 6, Blocks.snow);
		world.setBlock(i + 10, j + 3, k + 7, Blocks.snow);
		world.setBlock(i + 10, j + 3, k + 8, Blocks.snow);
		world.setBlock(i + 10, j + 3, k + 9, Blocks.snow);
		world.setBlock(i + 10, j + 3, k + 11, Blocks.snow);
		world.setBlock(i + 10, j + 3, k + 12, Blocks.snow);
		world.setBlock(i + 10, j + 3, k + 13, Blocks.snow);
		world.setBlock(i + 10, j + 3, k + 14, Blocks.snow);
		world.setBlock(i + 10, j + 3, k + 15, Blocks.snow);
		world.setBlock(i + 10, j + 3, k + 16, Blocks.snow);
		world.setBlock(i + 10, j + 3, k + 17, Blocks.snow);
		world.setBlock(i + 10, j + 3, k + 18, Blocks.snow);
		world.setBlock(i + 10, j + 3, k + 19, Blocks.snow);
		world.setBlock(i + 10, j + 3, k + 20, Blocks.snow);
		world.setBlock(i + 10, j + 4, k + 4, Blocks.snow);
		world.setBlock(i + 10, j + 4, k + 6, Blocks.snow);
		world.setBlock(i + 10, j + 5, k + 4, Blocks.snow);
		world.setBlock(i + 10, j + 5, k + 6, Blocks.snow);
		world.setBlock(i + 10, j + 6, k + 5, Blocks.snow);
		world.setBlock(i + 10, j + 8, k + 1, Blocks.snow);
		world.setBlock(i + 10, j + 8, k + 19, Blocks.snow);
		world.setBlock(i + 10, j + 9, k + 1, Blocks.snow);
		world.setBlock(i + 10, j + 9, k + 19, Blocks.snow);
		world.setBlock(i + 11, j + 0, k + 0, Blocks.dirt);
		world.setBlock(i + 11, j + 0, k + 1, Blocks.dirt);
		world.setBlock(i + 11, j + 0, k + 2, Blocks.dirt);
		world.setBlock(i + 11, j + 0, k + 3, Blocks.dirt);
		world.setBlock(i + 11, j + 0, k + 4, Blocks.dirt);
		world.setBlock(i + 11, j + 0, k + 5, Blocks.dirt);
		world.setBlock(i + 11, j + 0, k + 6, Blocks.dirt);
		world.setBlock(i + 11, j + 0, k + 7, Blocks.dirt);
		world.setBlock(i + 11, j + 0, k + 8, Blocks.dirt);
		world.setBlock(i + 11, j + 0, k + 9, Blocks.dirt);
		world.setBlock(i + 11, j + 0, k + 10, Blocks.dirt);
		world.setBlock(i + 11, j + 0, k + 11, Blocks.dirt);
		world.setBlock(i + 11, j + 0, k + 12, Blocks.dirt);
		world.setBlock(i + 11, j + 0, k + 13, Blocks.dirt);
		world.setBlock(i + 11, j + 0, k + 14, Blocks.dirt);
		world.setBlock(i + 11, j + 0, k + 15, Blocks.dirt);
		world.setBlock(i + 11, j + 0, k + 16, Blocks.dirt);
		world.setBlock(i + 11, j + 0, k + 17, Blocks.dirt);
		world.setBlock(i + 11, j + 0, k + 18, Blocks.dirt);
		world.setBlock(i + 11, j + 0, k + 19, Blocks.dirt);
		world.setBlock(i + 11, j + 0, k + 20, Blocks.dirt);
		world.setBlock(i + 11, j + 1, k + 0, Blocks.dirt);
		world.setBlock(i + 11, j + 1, k + 1, Blocks.dirt);
		world.setBlock(i + 11, j + 1, k + 2, Blocks.dirt);
		world.setBlock(i + 11, j + 1, k + 3, Blocks.dirt);
		world.setBlock(i + 11, j + 1, k + 4, Blocks.dirt);
		world.setBlock(i + 11, j + 1, k + 5, Blocks.dirt);
		world.setBlock(i + 11, j + 1, k + 6, Blocks.dirt);
		world.setBlock(i + 11, j + 1, k + 7, Blocks.dirt);
		world.setBlock(i + 11, j + 1, k + 8, Blocks.dirt);
		world.setBlock(i + 11, j + 1, k + 9, Blocks.dirt);
		world.setBlock(i + 11, j + 1, k + 10, Blocks.dirt);
		world.setBlock(i + 11, j + 1, k + 11, Blocks.dirt);
		world.setBlock(i + 11, j + 1, k + 12, Blocks.dirt);
		world.setBlock(i + 11, j + 1, k + 13, Blocks.dirt);
		world.setBlock(i + 11, j + 1, k + 14, Blocks.dirt);
		world.setBlock(i + 11, j + 1, k + 15, Blocks.dirt);
		world.setBlock(i + 11, j + 1, k + 16, Blocks.dirt);
		world.setBlock(i + 11, j + 1, k + 17, Blocks.dirt);
		world.setBlock(i + 11, j + 1, k + 18, Blocks.dirt);
		world.setBlock(i + 11, j + 1, k + 19, Blocks.dirt);
		world.setBlock(i + 11, j + 1, k + 20, Blocks.dirt);
		world.setBlock(i + 11, j + 2, k + 0, Blocks.dirt);
		world.setBlock(i + 11, j + 2, k + 1, Blocks.dirt);
		world.setBlock(i + 11, j + 2, k + 2, Blocks.dirt);
		world.setBlock(i + 11, j + 2, k + 3, Blocks.dirt);
		world.setBlock(i + 11, j + 2, k + 4, Blocks.dirt);
		world.setBlock(i + 11, j + 2, k + 5, Blocks.dirt);
		world.setBlock(i + 11, j + 2, k + 6, Blocks.dirt);
		world.setBlock(i + 11, j + 2, k + 7, Blocks.dirt);
		world.setBlock(i + 11, j + 2, k + 8, Blocks.dirt);
		world.setBlock(i + 11, j + 2, k + 9, Blocks.dirt);
		world.setBlock(i + 11, j + 2, k + 10, Blocks.dirt);
		world.setBlock(i + 11, j + 2, k + 11, Blocks.dirt);
		world.setBlock(i + 11, j + 2, k + 12, Blocks.dirt);
		world.setBlock(i + 11, j + 2, k + 13, Blocks.dirt);
		world.setBlock(i + 11, j + 2, k + 14, Blocks.dirt);
		world.setBlock(i + 11, j + 2, k + 15, Blocks.dirt);
		world.setBlock(i + 11, j + 2, k + 16, Blocks.dirt);
		world.setBlock(i + 11, j + 2, k + 17, Blocks.dirt);
		world.setBlock(i + 11, j + 2, k + 18, Blocks.dirt);
		world.setBlock(i + 11, j + 2, k + 19, Blocks.dirt);
		world.setBlock(i + 11, j + 2, k + 20, Blocks.dirt);
		world.setBlock(i + 11, j + 3, k + 0, Blocks.snow);
		world.setBlock(i + 11, j + 3, k + 1, Blocks.snow);
		world.setBlock(i + 11, j + 3, k + 2, Blocks.snow);
		world.setBlock(i + 11, j + 3, k + 3, Blocks.snow);
		world.setBlock(i + 11, j + 3, k + 4, Blocks.snow);
		world.setBlock(i + 11, j + 3, k + 5, Blocks.snow);
		world.setBlock(i + 11, j + 3, k + 6, Blocks.snow);
		world.setBlock(i + 11, j + 3, k + 7, Blocks.snow);
		world.setBlock(i + 11, j + 3, k + 8, Blocks.snow);
		world.setBlock(i + 11, j + 3, k + 9, Blocks.snow);
		world.setBlock(i + 11, j + 3, k + 10, Blocks.snow);
		world.setBlock(i + 11, j + 3, k + 11, Blocks.snow);
		world.setBlock(i + 11, j + 3, k + 12, Blocks.snow);
		world.setBlock(i + 11, j + 3, k + 13, Blocks.snow);
		world.setBlock(i + 11, j + 3, k + 14, Blocks.snow);
		world.setBlock(i + 11, j + 3, k + 15, Blocks.snow);
		world.setBlock(i + 11, j + 3, k + 16, Blocks.snow);
		world.setBlock(i + 11, j + 3, k + 17, Blocks.snow);
		world.setBlock(i + 11, j + 3, k + 18, Blocks.snow);
		world.setBlock(i + 11, j + 3, k + 19, Blocks.snow);
		world.setBlock(i + 11, j + 3, k + 20, Blocks.snow);
		world.setBlock(i + 11, j + 7, k + 1, Blocks.snow);
		world.setBlock(i + 11, j + 7, k + 19, Blocks.snow);
		world.setBlock(i + 11, j + 8, k + 1, Blocks.snow);
		world.setBlock(i + 11, j + 8, k + 19, Blocks.snow);
		world.setBlock(i + 11, j + 9, k + 1, Blocks.fence);
		world.setBlock(i + 11, j + 9, k + 19, Blocks.fence);
		world.setBlock(i + 11, j + 10, k + 1, Blocks.fence);
		world.setBlock(i + 11, j + 10, k + 19, Blocks.fence);
		world.setBlock(i + 12, j + 0, k + 0, Blocks.dirt);
		world.setBlock(i + 12, j + 0, k + 1, Blocks.dirt);
		world.setBlock(i + 12, j + 0, k + 2, Blocks.dirt);
		world.setBlock(i + 12, j + 0, k + 3, Blocks.dirt);
		world.setBlock(i + 12, j + 0, k + 4, Blocks.dirt);
		world.setBlock(i + 12, j + 0, k + 5, Blocks.dirt);
		world.setBlock(i + 12, j + 0, k + 6, Blocks.dirt);
		world.setBlock(i + 12, j + 0, k + 7, Blocks.dirt);
		world.setBlock(i + 12, j + 0, k + 8, Blocks.dirt);
		world.setBlock(i + 12, j + 0, k + 9, Blocks.dirt);
		world.setBlock(i + 12, j + 0, k + 10, Blocks.dirt);
		world.setBlock(i + 12, j + 0, k + 11, Blocks.dirt);
		world.setBlock(i + 12, j + 0, k + 12, Blocks.dirt);
		world.setBlock(i + 12, j + 0, k + 13, Blocks.dirt);
		world.setBlock(i + 12, j + 0, k + 14, Blocks.dirt);
		world.setBlock(i + 12, j + 0, k + 15, Blocks.dirt);
		world.setBlock(i + 12, j + 0, k + 16, Blocks.dirt);
		world.setBlock(i + 12, j + 0, k + 17, Blocks.dirt);
		world.setBlock(i + 12, j + 0, k + 18, Blocks.dirt);
		world.setBlock(i + 12, j + 0, k + 19, Blocks.dirt);
		world.setBlock(i + 12, j + 0, k + 20, Blocks.dirt);
		world.setBlock(i + 12, j + 1, k + 0, Blocks.dirt);
		world.setBlock(i + 12, j + 1, k + 1, Blocks.dirt);
		world.setBlock(i + 12, j + 1, k + 2, Blocks.dirt);
		world.setBlock(i + 12, j + 1, k + 3, Blocks.dirt);
		world.setBlock(i + 12, j + 1, k + 4, Blocks.dirt);
		world.setBlock(i + 12, j + 1, k + 5, Blocks.dirt);
		world.setBlock(i + 12, j + 1, k + 6, Blocks.dirt);
		world.setBlock(i + 12, j + 1, k + 7, Blocks.dirt);
		world.setBlock(i + 12, j + 1, k + 8, Blocks.dirt);
		world.setBlock(i + 12, j + 1, k + 9, Blocks.dirt);
		world.setBlock(i + 12, j + 1, k + 10, Blocks.dirt);
		world.setBlock(i + 12, j + 1, k + 11, Blocks.dirt);
		world.setBlock(i + 12, j + 1, k + 12, Blocks.dirt);
		world.setBlock(i + 12, j + 1, k + 13, Blocks.dirt);
		world.setBlock(i + 12, j + 1, k + 14, Blocks.dirt);
		world.setBlock(i + 12, j + 1, k + 15, Blocks.dirt);
		world.setBlock(i + 12, j + 1, k + 16, Blocks.dirt);
		world.setBlock(i + 12, j + 1, k + 17, Blocks.dirt);
		world.setBlock(i + 12, j + 1, k + 18, Blocks.dirt);
		world.setBlock(i + 12, j + 1, k + 19, Blocks.dirt);
		world.setBlock(i + 12, j + 1, k + 20, Blocks.dirt);
		world.setBlock(i + 12, j + 2, k + 0, Blocks.dirt);
		world.setBlock(i + 12, j + 2, k + 1, Blocks.dirt);
		world.setBlock(i + 12, j + 2, k + 2, Blocks.dirt);
		world.setBlock(i + 12, j + 2, k + 3, Blocks.dirt);
		world.setBlock(i + 12, j + 2, k + 4, Blocks.dirt);
		world.setBlock(i + 12, j + 2, k + 5, Blocks.dirt);
		world.setBlock(i + 12, j + 2, k + 6, Blocks.dirt);
		world.setBlock(i + 12, j + 2, k + 7, Blocks.dirt);
		world.setBlock(i + 12, j + 2, k + 8, Blocks.dirt);
		world.setBlock(i + 12, j + 2, k + 9, Blocks.dirt);
		world.setBlock(i + 12, j + 2, k + 10, Blocks.dirt);
		world.setBlock(i + 12, j + 2, k + 11, Blocks.dirt);
		world.setBlock(i + 12, j + 2, k + 12, Blocks.dirt);
		world.setBlock(i + 12, j + 2, k + 13, Blocks.dirt);
		world.setBlock(i + 12, j + 2, k + 14, Blocks.dirt);
		world.setBlock(i + 12, j + 2, k + 15, Blocks.dirt);
		world.setBlock(i + 12, j + 2, k + 16, Blocks.dirt);
		world.setBlock(i + 12, j + 2, k + 17, Blocks.dirt);
		world.setBlock(i + 12, j + 2, k + 18, Blocks.dirt);
		world.setBlock(i + 12, j + 2, k + 19, Blocks.dirt);
		world.setBlock(i + 12, j + 2, k + 20, Blocks.dirt);
		world.setBlock(i + 12, j + 3, k + 0, Blocks.dirt);
		world.setBlock(i + 12, j + 3, k + 1, Blocks.dirt);
		world.setBlock(i + 12, j + 3, k + 2, Blocks.snow);
		world.setBlock(i + 12, j + 3, k + 3, Blocks.snow);
		world.setBlock(i + 12, j + 3, k + 4, Blocks.snow);
		world.setBlock(i + 12, j + 3, k + 5, Blocks.snow);
		world.setBlock(i + 12, j + 3, k + 6, Blocks.snow);
		world.setBlock(i + 12, j + 3, k + 7, Blocks.snow);
		world.setBlock(i + 12, j + 3, k + 8, Blocks.snow);
		world.setBlock(i + 12, j + 3, k + 9, Blocks.snow);
		world.setBlock(i + 12, j + 3, k + 10, Blocks.snow);
		world.setBlock(i + 12, j + 3, k + 11, Blocks.snow);
		world.setBlock(i + 12, j + 3, k + 12, Blocks.stonebrick);
		world.setBlock(i + 12, j + 3, k + 13, Blocks.stonebrick);
		world.setBlock(i + 12, j + 3, k + 14, Blocks.stonebrick);
		world.setBlock(i + 12, j + 3, k + 15, Blocks.stonebrick);
		world.setBlock(i + 12, j + 3, k + 16, Blocks.stonebrick);
		world.setBlock(i + 12, j + 3, k + 17, Blocks.stonebrick);
		world.setBlock(i + 12, j + 3, k + 18, Blocks.snow);
		world.setBlock(i + 12, j + 3, k + 19, Blocks.snow);
		world.setBlock(i + 12, j + 3, k + 20, Blocks.snow);
		world.setBlock(i + 12, j + 4, k + 0, Blocks.snow);
		world.setBlock(i + 12, j + 4, k + 1, Blocks.snow);
		world.setBlock(i + 12, j + 4, k + 12, Blocks.stone_brick_stairs, 2, 0x02);
		world.setBlock(i + 12, j + 4, k + 13, Blocks.stone_brick_stairs, 2, 0x02);
		world.setBlock(i + 12, j + 4, k + 14, Blocks.stone_brick_stairs, 2, 0x02);
		world.setBlock(i + 12, j + 4, k + 15, Blocks.stone_brick_stairs, 2, 0x02);
		world.setBlock(i + 12, j + 4, k + 16, Blocks.stone_brick_stairs, 2, 0x02);
		world.setBlock(i + 12, j + 4, k + 17, Blocks.stone_brick_stairs, 2, 0x02);
		world.setBlock(i + 12, j + 4, k + 19, Blocks.snow);
		world.setBlock(i + 12, j + 4, k + 20, Blocks.snow);
		world.setBlock(i + 12, j + 5, k + 1, Blocks.snow);
		world.setBlock(i + 12, j + 5, k + 19, Blocks.snow);
		world.setBlock(i + 12, j + 6, k + 1, Blocks.snow);
		world.setBlock(i + 12, j + 6, k + 19, Blocks.snow);
		world.setBlock(i + 12, j + 7, k + 1, Blocks.snow);
		world.setBlock(i + 12, j + 7, k + 19, Blocks.snow);
		world.setBlock(i + 12, j + 9, k + 1, Blocks.glowstone);
		world.setBlock(i + 12, j + 9, k + 19, Blocks.glowstone);
		world.setBlock(i + 12, j + 10, k + 1, Blocks.fence);
		world.setBlock(i + 12, j + 10, k + 19, Blocks.fence);
		world.setBlock(i + 13, j + 0, k + 0, Blocks.dirt);
		world.setBlock(i + 13, j + 0, k + 1, Blocks.dirt);
		world.setBlock(i + 13, j + 0, k + 2, Blocks.dirt);
		world.setBlock(i + 13, j + 0, k + 3, Blocks.dirt);
		world.setBlock(i + 13, j + 0, k + 4, Blocks.dirt);
		world.setBlock(i + 13, j + 0, k + 5, Blocks.dirt);
		world.setBlock(i + 13, j + 0, k + 6, Blocks.dirt);
		world.setBlock(i + 13, j + 0, k + 7, Blocks.dirt);
		world.setBlock(i + 13, j + 0, k + 8, Blocks.dirt);
		world.setBlock(i + 13, j + 0, k + 9, Blocks.dirt);
		world.setBlock(i + 13, j + 0, k + 10, Blocks.dirt);
		world.setBlock(i + 13, j + 0, k + 11, Blocks.dirt);
		world.setBlock(i + 13, j + 0, k + 12, Blocks.dirt);
		world.setBlock(i + 13, j + 0, k + 13, Blocks.dirt);
		world.setBlock(i + 13, j + 0, k + 14, Blocks.dirt);
		world.setBlock(i + 13, j + 0, k + 15, Blocks.dirt);
		world.setBlock(i + 13, j + 0, k + 16, Blocks.dirt);
		world.setBlock(i + 13, j + 0, k + 17, Blocks.dirt);
		world.setBlock(i + 13, j + 0, k + 18, Blocks.dirt);
		world.setBlock(i + 13, j + 0, k + 19, Blocks.dirt);
		world.setBlock(i + 13, j + 0, k + 20, Blocks.dirt);
		world.setBlock(i + 13, j + 1, k + 0, Blocks.dirt);
		world.setBlock(i + 13, j + 1, k + 1, Blocks.dirt);
		world.setBlock(i + 13, j + 1, k + 2, Blocks.dirt);
		world.setBlock(i + 13, j + 1, k + 3, Blocks.dirt);
		world.setBlock(i + 13, j + 1, k + 4, Blocks.dirt);
		world.setBlock(i + 13, j + 1, k + 5, Blocks.dirt);
		world.setBlock(i + 13, j + 1, k + 6, Blocks.dirt);
		world.setBlock(i + 13, j + 1, k + 7, Blocks.dirt);
		world.setBlock(i + 13, j + 1, k + 8, Blocks.dirt);
		world.setBlock(i + 13, j + 1, k + 9, Blocks.dirt);
		world.setBlock(i + 13, j + 1, k + 10, Blocks.dirt);
		world.setBlock(i + 13, j + 1, k + 11, Blocks.dirt);
		world.setBlock(i + 13, j + 1, k + 12, Blocks.dirt);
		world.setBlock(i + 13, j + 1, k + 13, Blocks.dirt);
		world.setBlock(i + 13, j + 1, k + 14, Blocks.dirt);
		world.setBlock(i + 13, j + 1, k + 15, Blocks.dirt);
		world.setBlock(i + 13, j + 1, k + 16, Blocks.dirt);
		world.setBlock(i + 13, j + 1, k + 17, Blocks.dirt);
		world.setBlock(i + 13, j + 1, k + 18, Blocks.dirt);
		world.setBlock(i + 13, j + 1, k + 19, Blocks.dirt);
		world.setBlock(i + 13, j + 1, k + 20, Blocks.dirt);
		world.setBlock(i + 13, j + 2, k + 0, Blocks.dirt);
		world.setBlock(i + 13, j + 2, k + 1, Blocks.dirt);
		world.setBlock(i + 13, j + 2, k + 2, Blocks.dirt);
		world.setBlock(i + 13, j + 2, k + 3, Blocks.dirt);
		world.setBlock(i + 13, j + 2, k + 4, Blocks.dirt);
		world.setBlock(i + 13, j + 2, k + 5, Blocks.dirt);
		world.setBlock(i + 13, j + 2, k + 6, Blocks.dirt);
		world.setBlock(i + 13, j + 2, k + 7, Blocks.dirt);
		world.setBlock(i + 13, j + 2, k + 8, Blocks.dirt);
		world.setBlock(i + 13, j + 2, k + 9, Blocks.dirt);
		world.setBlock(i + 13, j + 2, k + 10, Blocks.dirt);
		world.setBlock(i + 13, j + 2, k + 11, Blocks.dirt);
		world.setBlock(i + 13, j + 2, k + 12, Blocks.dirt);
		world.setBlock(i + 13, j + 2, k + 13, Blocks.glowstone);
		world.setBlock(i + 13, j + 2, k + 14, Blocks.stonebrick);
		world.setBlock(i + 13, j + 2, k + 15, Blocks.stonebrick);
		world.setBlock(i + 13, j + 2, k + 16, Blocks.glowstone);
		world.setBlock(i + 13, j + 2, k + 17, Blocks.dirt);
		world.setBlock(i + 13, j + 2, k + 18, Blocks.dirt);
		world.setBlock(i + 13, j + 2, k + 19, Blocks.dirt);
		world.setBlock(i + 13, j + 2, k + 20, Blocks.dirt);
		world.setBlock(i + 13, j + 3, k + 0, Blocks.dirt);
		world.setBlock(i + 13, j + 3, k + 1, Blocks.dirt);
		world.setBlock(i + 13, j + 3, k + 2, Blocks.snow);
		world.setBlock(i + 13, j + 3, k + 3, Blocks.snow);
		world.setBlock(i + 13, j + 3, k + 4, Blocks.stonebrick);
		world.setBlock(i + 13, j + 3, k + 5, Blocks.stonebrick);
		world.setBlock(i + 13, j + 3, k + 6, Blocks.stonebrick);
		world.setBlock(i + 13, j + 3, k + 7, Blocks.stonebrick);
		world.setBlock(i + 13, j + 3, k + 8, Blocks.snow);
		world.setBlock(i + 13, j + 3, k + 9, Blocks.snow);
		world.setBlock(i + 13, j + 3, k + 10, Blocks.snow);
		world.setBlock(i + 13, j + 3, k + 11, Blocks.snow);
		world.setBlock(i + 13, j + 3, k + 12, Blocks.stonebrick);
		world.setBlock(i + 13, j + 3, k + 13, Blocks.stonebrick);
		world.setBlock(i + 13, j + 3, k + 14, Blocks.snow);
		world.setBlock(i + 13, j + 3, k + 15, Blocks.snow);
		world.setBlock(i + 13, j + 3, k + 16, Blocks.stonebrick);
		world.setBlock(i + 13, j + 3, k + 17, Blocks.stonebrick);
		world.setBlock(i + 13, j + 3, k + 18, Blocks.snow);
		world.setBlock(i + 13, j + 3, k + 19, Blocks.dirt);
		world.setBlock(i + 13, j + 3, k + 20, Blocks.dirt);
		world.setBlock(i + 13, j + 4, k + 0, Blocks.snow);
		world.setBlock(i + 13, j + 4, k + 1, Blocks.snow);
		world.setBlock(i + 13, j + 4, k + 2, Blocks.chest, 3, 0x02);
		world.setBlock(i + 13, j + 4, k + 4, Blocks.stone_brick_stairs, 2, 0x02);
		world.setBlock(i + 13, j + 4, k + 5, Blocks.stone_brick_stairs, 2, 0x02);
		world.setBlock(i + 13, j + 4, k + 6, Blocks.stone_brick_stairs, 2, 0x02);
		world.setBlock(i + 13, j + 4, k + 7, Blocks.stone_brick_stairs, 2, 0x02);
		world.setBlock(i + 13, j + 4, k + 12, Blocks.stone_brick_stairs, 2, 0x02);
		world.setBlock(i + 13, j + 4, k + 13, Blocks.stonebrick);
		world.setBlock(i + 13, j + 4, k + 16, Blocks.stonebrick);
		world.setBlock(i + 13, j + 4, k + 17, Blocks.stone_brick_stairs, 2, 0x02);
		world.setBlock(i + 13, j + 4, k + 19, Blocks.snow);
		world.setBlock(i + 13, j + 4, k + 20, Blocks.snow);
		world.setBlock(i + 13, j + 5, k + 1, Blocks.snow);
		world.setBlock(i + 13, j + 5, k + 4, Blocks.stone_slab, 5, 0x02);
		world.setBlock(i + 13, j + 5, k + 5, Blocks.stone_slab, 5, 0x02);
		world.setBlock(i + 13, j + 5, k + 6, Blocks.stone_slab, 5, 0x02);
		world.setBlock(i + 13, j + 5, k + 7, Blocks.stone_slab, 5, 0x02);
		world.setBlock(i + 13, j + 5, k + 19, Blocks.snow);
		world.setBlock(i + 13, j + 6, k + 1, Blocks.snow);
		world.setBlock(i + 13, j + 6, k + 19, Blocks.snow);
		world.setBlock(i + 14, j + 0, k + 0, Blocks.dirt);
		world.setBlock(i + 14, j + 0, k + 1, Blocks.dirt);
		world.setBlock(i + 14, j + 0, k + 2, Blocks.dirt);
		world.setBlock(i + 14, j + 0, k + 3, Blocks.dirt);
		world.setBlock(i + 14, j + 0, k + 4, Blocks.dirt);
		world.setBlock(i + 14, j + 0, k + 5, Blocks.dirt);
		world.setBlock(i + 14, j + 0, k + 6, Blocks.dirt);
		world.setBlock(i + 14, j + 0, k + 7, Blocks.dirt);
		world.setBlock(i + 14, j + 0, k + 8, Blocks.dirt);
		world.setBlock(i + 14, j + 0, k + 9, Blocks.dirt);
		world.setBlock(i + 14, j + 0, k + 10, Blocks.dirt);
		world.setBlock(i + 14, j + 0, k + 11, Blocks.dirt);
		world.setBlock(i + 14, j + 0, k + 12, Blocks.dirt);
		world.setBlock(i + 14, j + 0, k + 13, Blocks.dirt);
		world.setBlock(i + 14, j + 0, k + 14, Blocks.dirt);
		world.setBlock(i + 14, j + 0, k + 15, Blocks.dirt);
		world.setBlock(i + 14, j + 0, k + 16, Blocks.dirt);
		world.setBlock(i + 14, j + 0, k + 17, Blocks.dirt);
		world.setBlock(i + 14, j + 0, k + 18, Blocks.dirt);
		world.setBlock(i + 14, j + 0, k + 19, Blocks.dirt);
		world.setBlock(i + 14, j + 0, k + 20, Blocks.dirt);
		world.setBlock(i + 14, j + 1, k + 0, Blocks.dirt);
		world.setBlock(i + 14, j + 1, k + 1, Blocks.dirt);
		world.setBlock(i + 14, j + 1, k + 2, Blocks.dirt);
		world.setBlock(i + 14, j + 1, k + 3, Blocks.dirt);
		world.setBlock(i + 14, j + 1, k + 4, Blocks.dirt);
		world.setBlock(i + 14, j + 1, k + 5, Blocks.dirt);
		world.setBlock(i + 14, j + 1, k + 6, Blocks.dirt);
		world.setBlock(i + 14, j + 1, k + 7, Blocks.dirt);
		world.setBlock(i + 14, j + 1, k + 8, Blocks.dirt);
		world.setBlock(i + 14, j + 1, k + 9, Blocks.dirt);
		world.setBlock(i + 14, j + 1, k + 10, Blocks.dirt);
		world.setBlock(i + 14, j + 1, k + 11, Blocks.dirt);
		world.setBlock(i + 14, j + 1, k + 12, Blocks.dirt);
		world.setBlock(i + 14, j + 1, k + 13, Blocks.dirt);
		world.setBlock(i + 14, j + 1, k + 14, Blocks.dirt);
		world.setBlock(i + 14, j + 1, k + 15, Blocks.dirt);
		world.setBlock(i + 14, j + 1, k + 16, Blocks.dirt);
		world.setBlock(i + 14, j + 1, k + 17, Blocks.dirt);
		world.setBlock(i + 14, j + 1, k + 18, Blocks.dirt);
		world.setBlock(i + 14, j + 1, k + 19, Blocks.dirt);
		world.setBlock(i + 14, j + 1, k + 20, Blocks.dirt);
		world.setBlock(i + 14, j + 2, k + 0, Blocks.dirt);
		world.setBlock(i + 14, j + 2, k + 1, Blocks.dirt);
		world.setBlock(i + 14, j + 2, k + 2, Blocks.dirt);
		world.setBlock(i + 14, j + 2, k + 3, Blocks.dirt);
		world.setBlock(i + 14, j + 2, k + 4, Blocks.dirt);
		world.setBlock(i + 14, j + 2, k + 5, Blocks.dirt);
		world.setBlock(i + 14, j + 2, k + 6, Blocks.dirt);
		world.setBlock(i + 14, j + 2, k + 7, Blocks.dirt);
		world.setBlock(i + 14, j + 2, k + 8, Blocks.dirt);
		world.setBlock(i + 14, j + 2, k + 9, Blocks.dirt);
		world.setBlock(i + 14, j + 2, k + 10, Blocks.dirt);
		world.setBlock(i + 14, j + 2, k + 11, Blocks.dirt);
		world.setBlock(i + 14, j + 2, k + 12, Blocks.dirt);
		world.setBlock(i + 14, j + 2, k + 13, Blocks.stonebrick);
		world.setBlock(i + 14, j + 2, k + 14, Blocks.stonebrick);
		world.setBlock(i + 14, j + 2, k + 15, Blocks.stonebrick);
		world.setBlock(i + 14, j + 2, k + 16, Blocks.stonebrick);
		world.setBlock(i + 14, j + 2, k + 17, Blocks.dirt);
		world.setBlock(i + 14, j + 2, k + 18, Blocks.dirt);
		world.setBlock(i + 14, j + 2, k + 19, Blocks.dirt);
		world.setBlock(i + 14, j + 2, k + 20, Blocks.dirt);
		world.setBlock(i + 14, j + 3, k + 0, Blocks.dirt);
		world.setBlock(i + 14, j + 3, k + 1, Blocks.dirt);
		world.setBlock(i + 14, j + 3, k + 2, Blocks.snow);
		world.setBlock(i + 14, j + 3, k + 3, Blocks.snow);
		world.setBlock(i + 14, j + 3, k + 4, Blocks.stonebrick);
		world.setBlock(i + 14, j + 3, k + 5, Blocks.netherrack);
		world.setBlock(i + 14, j + 3, k + 6, Blocks.netherrack);
		world.setBlock(i + 14, j + 3, k + 7, Blocks.stonebrick);
		world.setBlock(i + 14, j + 3, k + 8, Blocks.snow);
		world.setBlock(i + 14, j + 3, k + 9, Blocks.snow);
		world.setBlock(i + 14, j + 3, k + 10, Blocks.snow);
		world.setBlock(i + 14, j + 3, k + 11, Blocks.snow);
		world.setBlock(i + 14, j + 3, k + 12, Blocks.stonebrick);
		world.setBlock(i + 14, j + 3, k + 13, Blocks.snow);
		world.setBlock(i + 14, j + 3, k + 14, Blocks.snow);
		world.setBlock(i + 14, j + 3, k + 15, Blocks.snow);
		world.setBlock(i + 14, j + 3, k + 16, Blocks.snow);
		world.setBlock(i + 14, j + 3, k + 17, Blocks.stonebrick);
		world.setBlock(i + 14, j + 3, k + 18, Blocks.snow);
		world.setBlock(i + 14, j + 3, k + 19, Blocks.dirt);
		world.setBlock(i + 14, j + 3, k + 20, Blocks.dirt);
		world.setBlock(i + 14, j + 4, k + 0, Blocks.snow);
		world.setBlock(i + 14, j + 4, k + 1, Blocks.snow);
		world.setBlock(i + 14, j + 4, k + 2, Blocks.chest, 3, 0x02);
		world.setBlock(i + 14, j + 4, k + 4, Blocks.stone_brick_stairs, 2, 0x02);
		world.setBlock(i + 14, j + 4, k + 5, Blocks.fire, 15, 0x02);
		world.setBlock(i + 14, j + 4, k + 6, Blocks.fire, 15, 0x02);
		world.setBlock(i + 14, j + 4, k + 7, Blocks.stone_brick_stairs, 2, 0x02);
		world.setBlock(i + 14, j + 4, k + 12, Blocks.stone_brick_stairs, 2, 0x02);
		world.setBlock(i + 14, j + 4, k + 15, Blocks.ice);
		world.setBlock(i + 14, j + 4, k + 17, Blocks.stone_brick_stairs, 2, 0x02);
		world.setBlock(i + 14, j + 4, k + 19, Blocks.snow);
		world.setBlock(i + 14, j + 4, k + 20, Blocks.snow);
		world.setBlock(i + 14, j + 5, k + 1, Blocks.snow);
		world.setBlock(i + 14, j + 5, k + 4, Blocks.stone_slab, 5, 0x02);
		world.setBlock(i + 14, j + 5, k + 7, Blocks.stone_slab, 5, 0x02);
		world.setBlock(i + 14, j + 5, k + 19, Blocks.snow);
		world.setBlock(i + 14, j + 6, k + 1, Blocks.snow);
		world.setBlock(i + 14, j + 6, k + 19, Blocks.snow);
		world.setBlock(i + 15, j + 0, k + 0, Blocks.dirt);
		world.setBlock(i + 15, j + 0, k + 1, Blocks.dirt);
		world.setBlock(i + 15, j + 0, k + 2, Blocks.dirt);
		world.setBlock(i + 15, j + 0, k + 3, Blocks.dirt);
		world.setBlock(i + 15, j + 0, k + 4, Blocks.dirt);
		world.setBlock(i + 15, j + 0, k + 5, Blocks.dirt);
		world.setBlock(i + 15, j + 0, k + 6, Blocks.dirt);
		world.setBlock(i + 15, j + 0, k + 7, Blocks.dirt);
		world.setBlock(i + 15, j + 0, k + 8, Blocks.dirt);
		world.setBlock(i + 15, j + 0, k + 9, Blocks.dirt);
		world.setBlock(i + 15, j + 0, k + 10, Blocks.dirt);
		world.setBlock(i + 15, j + 0, k + 11, Blocks.dirt);
		world.setBlock(i + 15, j + 0, k + 12, Blocks.dirt);
		world.setBlock(i + 15, j + 0, k + 13, Blocks.dirt);
		world.setBlock(i + 15, j + 0, k + 14, Blocks.dirt);
		world.setBlock(i + 15, j + 0, k + 15, Blocks.dirt);
		world.setBlock(i + 15, j + 0, k + 16, Blocks.dirt);
		world.setBlock(i + 15, j + 0, k + 17, Blocks.dirt);
		world.setBlock(i + 15, j + 0, k + 18, Blocks.dirt);
		world.setBlock(i + 15, j + 0, k + 19, Blocks.dirt);
		world.setBlock(i + 15, j + 0, k + 20, Blocks.dirt);
		world.setBlock(i + 15, j + 1, k + 0, Blocks.dirt);
		world.setBlock(i + 15, j + 1, k + 1, Blocks.dirt);
		world.setBlock(i + 15, j + 1, k + 2, Blocks.dirt);
		world.setBlock(i + 15, j + 1, k + 3, Blocks.dirt);
		world.setBlock(i + 15, j + 1, k + 4, Blocks.dirt);
		world.setBlock(i + 15, j + 1, k + 5, Blocks.dirt);
		world.setBlock(i + 15, j + 1, k + 6, Blocks.dirt);
		world.setBlock(i + 15, j + 1, k + 7, Blocks.dirt);
		world.setBlock(i + 15, j + 1, k + 8, Blocks.dirt);
		world.setBlock(i + 15, j + 1, k + 9, Blocks.dirt);
		world.setBlock(i + 15, j + 1, k + 10, Blocks.dirt);
		world.setBlock(i + 15, j + 1, k + 11, Blocks.dirt);
		world.setBlock(i + 15, j + 1, k + 12, Blocks.dirt);
		world.setBlock(i + 15, j + 1, k + 13, Blocks.dirt);
		world.setBlock(i + 15, j + 1, k + 14, Blocks.dirt);
		world.setBlock(i + 15, j + 1, k + 15, Blocks.dirt);
		world.setBlock(i + 15, j + 1, k + 16, Blocks.dirt);
		world.setBlock(i + 15, j + 1, k + 17, Blocks.dirt);
		world.setBlock(i + 15, j + 1, k + 18, Blocks.dirt);
		world.setBlock(i + 15, j + 1, k + 19, Blocks.dirt);
		world.setBlock(i + 15, j + 1, k + 20, Blocks.dirt);
		world.setBlock(i + 15, j + 2, k + 0, Blocks.dirt);
		world.setBlock(i + 15, j + 2, k + 1, Blocks.dirt);
		world.setBlock(i + 15, j + 2, k + 2, Blocks.dirt);
		world.setBlock(i + 15, j + 2, k + 3, Blocks.dirt);
		world.setBlock(i + 15, j + 2, k + 4, Blocks.dirt);
		world.setBlock(i + 15, j + 2, k + 5, Blocks.dirt);
		world.setBlock(i + 15, j + 2, k + 6, Blocks.dirt);
		world.setBlock(i + 15, j + 2, k + 7, Blocks.dirt);
		world.setBlock(i + 15, j + 2, k + 8, Blocks.dirt);
		world.setBlock(i + 15, j + 2, k + 9, Blocks.dirt);
		world.setBlock(i + 15, j + 2, k + 10, Blocks.dirt);
		world.setBlock(i + 15, j + 2, k + 11, Blocks.dirt);
		world.setBlock(i + 15, j + 2, k + 12, Blocks.dirt);
		world.setBlock(i + 15, j + 2, k + 13, Blocks.stonebrick);
		world.setBlock(i + 15, j + 2, k + 14, Blocks.stonebrick);
		world.setBlock(i + 15, j + 2, k + 15, Blocks.glowstone);
		world.setBlock(i + 15, j + 2, k + 16, Blocks.dirt);
		world.setBlock(i + 15, j + 2, k + 17, Blocks.dirt);
		world.setBlock(i + 15, j + 2, k + 18, Blocks.dirt);
		world.setBlock(i + 15, j + 2, k + 19, Blocks.dirt);
		world.setBlock(i + 15, j + 2, k + 20, Blocks.dirt);
		world.setBlock(i + 15, j + 3, k + 0, Blocks.grass);
		world.setBlock(i + 15, j + 3, k + 1, Blocks.dirt);
		world.setBlock(i + 15, j + 3, k + 2, Blocks.dirt);
		world.setBlock(i + 15, j + 3, k + 3, Blocks.snow);
		world.setBlock(i + 15, j + 3, k + 4, Blocks.stonebrick);
		world.setBlock(i + 15, j + 3, k + 5, Blocks.netherrack);
		world.setBlock(i + 15, j + 3, k + 6, Blocks.netherrack);
		world.setBlock(i + 15, j + 3, k + 7, Blocks.stonebrick);
		world.setBlock(i + 15, j + 3, k + 8, Blocks.snow);
		world.setBlock(i + 15, j + 3, k + 9, Blocks.snow);
		world.setBlock(i + 15, j + 3, k + 10, Blocks.snow);
		world.setBlock(i + 15, j + 3, k + 11, Blocks.snow);
		world.setBlock(i + 15, j + 3, k + 12, Blocks.stonebrick);
		world.setBlock(i + 15, j + 3, k + 13, Blocks.snow);
		world.setBlock(i + 15, j + 3, k + 14, Blocks.snow);
		world.setBlock(i + 15, j + 3, k + 15, Blocks.snow);
		world.setBlock(i + 15, j + 3, k + 16, Blocks.stonebrick);
		world.setBlock(i + 15, j + 3, k + 17, Blocks.dirt);
		world.setBlock(i + 15, j + 3, k + 18, Blocks.dirt);
		world.setBlock(i + 15, j + 3, k + 19, Blocks.dirt);
		world.setBlock(i + 15, j + 3, k + 20, Blocks.grass);
		world.setBlock(i + 15, j + 4, k + 1, Blocks.snow);
		world.setBlock(i + 15, j + 4, k + 2, Blocks.snow);
		world.setBlock(i + 15, j + 4, k + 4, Blocks.stone_brick_stairs, 2, 0x02);
		world.setBlock(i + 15, j + 4, k + 5, Blocks.fire, 15, 0x02);
		world.setBlock(i + 15, j + 4, k + 6, Blocks.fire, 15, 0x02);
		world.setBlock(i + 15, j + 4, k + 7, Blocks.stone_brick_stairs, 2, 0x02);
		world.setBlock(i + 15, j + 4, k + 12, Blocks.stone_brick_stairs, 2, 0x02);
		world.setBlock(i + 15, j + 4, k + 15, Blocks.ice);
		world.setBlock(i + 15, j + 4, k + 16, Blocks.stone_brick_stairs, 2, 0x02);
		world.setBlock(i + 15, j + 4, k + 17, Blocks.stone_brick_stairs, 2, 0x02);
		world.setBlock(i + 15, j + 4, k + 18, Blocks.snow);
		world.setBlock(i + 15, j + 4, k + 19, Blocks.snow);
		world.setBlock(i + 15, j + 5, k + 2, Blocks.snow);
		world.setBlock(i + 15, j + 5, k + 4, Blocks.stone_slab, 5, 0x02);
		world.setBlock(i + 15, j + 5, k + 7, Blocks.stone_slab, 5, 0x02);
		world.setBlock(i + 15, j + 5, k + 18, Blocks.snow);
		world.setBlock(i + 15, j + 6, k + 2, Blocks.snow);
		world.setBlock(i + 15, j + 6, k + 18, Blocks.snow);
		world.setBlock(i + 16, j + 0, k + 0, Blocks.dirt);
		world.setBlock(i + 16, j + 0, k + 1, Blocks.dirt);
		world.setBlock(i + 16, j + 0, k + 2, Blocks.dirt);
		world.setBlock(i + 16, j + 0, k + 3, Blocks.dirt);
		world.setBlock(i + 16, j + 0, k + 4, Blocks.dirt);
		world.setBlock(i + 16, j + 0, k + 5, Blocks.dirt);
		world.setBlock(i + 16, j + 0, k + 6, Blocks.dirt);
		world.setBlock(i + 16, j + 0, k + 7, Blocks.dirt);
		world.setBlock(i + 16, j + 0, k + 8, Blocks.dirt);
		world.setBlock(i + 16, j + 0, k + 9, Blocks.dirt);
		world.setBlock(i + 16, j + 0, k + 10, Blocks.dirt);
		world.setBlock(i + 16, j + 0, k + 11, Blocks.dirt);
		world.setBlock(i + 16, j + 0, k + 12, Blocks.dirt);
		world.setBlock(i + 16, j + 0, k + 13, Blocks.dirt);
		world.setBlock(i + 16, j + 0, k + 14, Blocks.dirt);
		world.setBlock(i + 16, j + 0, k + 15, Blocks.dirt);
		world.setBlock(i + 16, j + 0, k + 16, Blocks.dirt);
		world.setBlock(i + 16, j + 0, k + 17, Blocks.dirt);
		world.setBlock(i + 16, j + 0, k + 18, Blocks.dirt);
		world.setBlock(i + 16, j + 0, k + 19, Blocks.dirt);
		world.setBlock(i + 16, j + 0, k + 20, Blocks.dirt);
		world.setBlock(i + 16, j + 1, k + 0, Blocks.dirt);
		world.setBlock(i + 16, j + 1, k + 1, Blocks.dirt);
		world.setBlock(i + 16, j + 1, k + 2, Blocks.dirt);
		world.setBlock(i + 16, j + 1, k + 3, Blocks.dirt);
		world.setBlock(i + 16, j + 1, k + 4, Blocks.dirt);
		world.setBlock(i + 16, j + 1, k + 5, Blocks.dirt);
		world.setBlock(i + 16, j + 1, k + 6, Blocks.dirt);
		world.setBlock(i + 16, j + 1, k + 7, Blocks.dirt);
		world.setBlock(i + 16, j + 1, k + 8, Blocks.dirt);
		world.setBlock(i + 16, j + 1, k + 9, Blocks.dirt);
		world.setBlock(i + 16, j + 1, k + 10, Blocks.dirt);
		world.setBlock(i + 16, j + 1, k + 11, Blocks.dirt);
		world.setBlock(i + 16, j + 1, k + 12, Blocks.dirt);
		world.setBlock(i + 16, j + 1, k + 13, Blocks.dirt);
		world.setBlock(i + 16, j + 1, k + 14, Blocks.dirt);
		world.setBlock(i + 16, j + 1, k + 15, Blocks.dirt);
		world.setBlock(i + 16, j + 1, k + 16, Blocks.dirt);
		world.setBlock(i + 16, j + 1, k + 17, Blocks.dirt);
		world.setBlock(i + 16, j + 1, k + 18, Blocks.dirt);
		world.setBlock(i + 16, j + 1, k + 19, Blocks.dirt);
		world.setBlock(i + 16, j + 1, k + 20, Blocks.dirt);
		world.setBlock(i + 16, j + 2, k + 0, Blocks.dirt);
		world.setBlock(i + 16, j + 2, k + 1, Blocks.dirt);
		world.setBlock(i + 16, j + 2, k + 2, Blocks.dirt);
		world.setBlock(i + 16, j + 2, k + 3, Blocks.dirt);
		world.setBlock(i + 16, j + 2, k + 4, Blocks.dirt);
		world.setBlock(i + 16, j + 2, k + 5, Blocks.dirt);
		world.setBlock(i + 16, j + 2, k + 6, Blocks.dirt);
		world.setBlock(i + 16, j + 2, k + 7, Blocks.dirt);
		world.setBlock(i + 16, j + 2, k + 8, Blocks.dirt);
		world.setBlock(i + 16, j + 2, k + 9, Blocks.dirt);
		world.setBlock(i + 16, j + 2, k + 10, Blocks.dirt);
		world.setBlock(i + 16, j + 2, k + 11, Blocks.dirt);
		world.setBlock(i + 16, j + 2, k + 12, Blocks.dirt);
