package kieranvs.avatar.generation;

import java.util.Random;

import kieranvs.avatar.mod_Avatar;
import kieranvs.avatar.bending.ElementManager;
import kieranvs.avatar.entity.EntityAirMan;
import kieranvs.avatar.entity.EntityAirWoman;
import kieranvs.avatar.entity.EntityBison;
import kieranvs.avatar.util.GenerationUtils;
import net.minecraft.block.Block;
import net.minecraft.init.Blocks;
import net.minecraft.item.ItemStack;
import net.minecraft.tileentity.TileEntity;
import net.minecraft.tileentity.TileEntityChest;
import net.minecraft.world.World;
import net.minecraft.world.biome.BiomeGenBase;
import net.minecraft.world.chunk.IChunkProvider;
import cpw.mods.fml.common.IWorldGenerator;

public class WorldGenAirNomadVillageTwo implements IWorldGenerator {
	
	private static BiomeGenBase[] biomes = {BiomeGenBase.extremeHills, BiomeGenBase.extremeHillsPlus, BiomeGenBase.stoneBeach};
	
	public void generate(Random random, int chunkX, int chunkZ, World world, IChunkProvider chunkGenerator, IChunkProvider chunkProvider) {
		int[] result = GenerationUtils.shouldSpawnHere(random, chunkX, chunkZ, world, 20, 5, 8, biomes);
		if(result[0] == 0){
			this.masterGenerate(world, result[1], result[2] - 5, result[3]);
			this.generateEntities(world, result[1], result[2] - 5, result[3], random);
			this.generateLoot(world, result[1], result[2] - 5, result[3], random);
		}
	}

	public boolean masterGenerate(World world, int i, int j, int k) {

		generate(world, i, j, k);
		generate2(world, i, j, k);
		
		return true;
	}

	public void generateEntities(World world, int i, int j, int k, Random random) {
		int numM = random.nextInt(3) + 1;
		int numW = random.nextInt(1) + 1;
		int[] yCoord = new int[2];
		yCoord[0] = 15;
		yCoord[1] = 7;
		int y = random.nextInt(1);

		for (int x = 0; x < numM; x++) {
			EntityAirMan airMan = new EntityAirMan(world, i + 10, j + 7, k + 10, 9);
			airMan.setPositionAndRotation(i + 7, j + yCoord[y], k + 7, 1.0F, 1.0F);
			world.spawnEntityInWorld(airMan);
		}

		for (int x = 0; x < numW; x++) {
			EntityAirWoman airWoman = new EntityAirWoman(world, i + 10, j + 7, k + 10, 9);
			airWoman.setPositionAndRotation(i + 7, j + yCoord[y], k + 7, 1.0F, 1.0F);
			world.spawnEntityInWorld(airWoman);
		}

		EntityBison bison = new EntityBison(world);
		bison.setPositionAndRotation(i + 20, j + 7, k + 20, 1.0F, 1.0F);
		world.spawnEntityInWorld(bison);

	}
	
	public void generateLoot(World world, int i, int j, int k, Random random){
		for(int x = i; x < i + 20; x++){
			for (int z = k; z < k + 20; z++) {
				for (int y = j; y < j + 17; y++) {
						TileEntity e = world.getTileEntity(x, y, z);
						if(e != null && e instanceof TileEntityChest){
							GenerationUtils.generateScrolls(random, (TileEntityChest) e, ElementManager.AIR, 3);
							int ran = random.nextInt(8);
							for(int r = 0; r < random.nextInt(5); r++){
								switch (ran){
								case 0:
									((TileEntityChest) e).setInventorySlotContents(random.nextInt(27), new ItemStack(GenerationUtils.gliders.get(random.nextInt(GenerationUtils.gliders.size())), 1, 0));
									break;
								case 1:
									((TileEntityChest) e).setInventorySlotContents(random.nextInt(27), new ItemStack(mod_Avatar.CustardTartItem, random.nextInt(2), 0));	
									break;
								case 2:
									((TileEntityChest) e).setInventorySlotContents(random.nextInt(27), new ItemStack(mod_Avatar.FruitPieItem, random.nextInt(5), 0));
									break;
								case 3:
									((TileEntityChest) e).setInventorySlotContents(random.nextInt(27), new ItemStack(mod_Avatar.RiceGrainItem, random.nextInt(32), 0));	
									((TileEntityChest) e).setInventorySlotContents(random.nextInt(27), new ItemStack(GenerationUtils.gliders.get(random.nextInt(GenerationUtils.gliders.size())), 1, 0));
									break;
								case 4:
									((TileEntityChest) e).setInventorySlotContents(random.nextInt(27), new ItemStack(mod_Avatar.RiceGrainItem, random.nextInt(32), 0));	
									break;
								case 5:
									((TileEntityChest) e).setInventorySlotContents(random.nextInt(27), new ItemStack(mod_Avatar.RiceBowlItem, 1, 0));	
									break;
								case 6:
									((TileEntityChest) e).setInventorySlotContents(random.nextInt(27), new ItemStack(GenerationUtils.gliders.get(random.nextInt(GenerationUtils.gliders.size())), 1, 0));
									break;
								case 7:
									((TileEntityChest) e).setInventorySlotContents(random.nextInt(27), new ItemStack(mod_Avatar.MoonPeachItem, random.nextInt(16), 0));	
									break;
								}	
							}
							
						}
				}
			}
		}
	}

	public void generate(World world, int i, int j, int k) {

		for (int x = 0; x <= 20; x++) {
			for (int z = 0; z <= 20; z++) {
				for (int y = 0; y < 17; y++) {
					world.setBlock(i + x, j + 6 + y, k + z, Blocks.air);
				}
			}
		}

		world.setBlock(i + 0, j + 2, k + 13, Blocks.sandstone);
		world.setBlock(i + 0, j + 3, k + 13, Blocks.sandstone);
		world.setBlock(i + 0, j + 4, k + 9, Blocks.sandstone);
		world.setBlock(i + 0, j + 4, k + 10, Blocks.sandstone);
		world.setBlock(i + 0, j + 4, k + 13, Blocks.sandstone);
		world.setBlock(i + 0, j + 5, k + 4, Blocks.sandstone);
		world.setBlock(i + 0, j + 5, k + 5, Blocks.sandstone);
		world.setBlock(i + 0, j + 5, k + 6, Blocks.sandstone);
		world.setBlock(i + 0, j + 5, k + 7, Blocks.sandstone);
		world.setBlock(i + 0, j + 5, k + 8, Blocks.sandstone);
		world.setBlock(i + 0, j + 5, k + 9, Blocks.sandstone);
		world.setBlock(i + 0, j + 5, k + 10, Blocks.sandstone);
		world.setBlock(i + 0, j + 5, k + 11, Blocks.sandstone);
		world.setBlock(i + 0, j + 5, k + 12, Blocks.sandstone);
		world.setBlock(i + 0, j + 5, k + 13, Blocks.sandstone);
		world.setBlock(i + 0, j + 5, k + 14, Blocks.sandstone);
		world.setBlock(i + 0, j + 5, k + 15, Blocks.sandstone);
		world.setBlock(i + 1, j + 1, k + 9, Blocks.sandstone);
		world.setBlock(i + 1, j + 2, k + 6, Blocks.sandstone);
		world.setBlock(i + 1, j + 2, k + 9, Blocks.sandstone);
		world.setBlock(i + 1, j + 3, k + 6, Blocks.sandstone);
		world.setBlock(i + 1, j + 3, k + 8, Blocks.sandstone);
		world.setBlock(i + 1, j + 3, k + 9, Blocks.sandstone);
		world.setBlock(i + 1, j + 3, k + 10, Blocks.sandstone);
		world.setBlock(i + 1, j + 3, k + 11, Blocks.sandstone);
		world.setBlock(i + 1, j + 4, k + 5, Blocks.sandstone);
		world.setBlock(i + 1, j + 4, k + 6, Blocks.sandstone);
		world.setBlock(i + 1, j + 4, k + 7, Blocks.sandstone);
		world.setBlock(i + 1, j + 4, k + 8, Blocks.sandstone);
		world.setBlock(i + 1, j + 4, k + 9, Blocks.sandstone);
		world.setBlock(i + 1, j + 4, k + 10, Blocks.sandstone);
		world.setBlock(i + 1, j + 4, k + 11, Blocks.sandstone);
		world.setBlock(i + 1, j + 4, k + 12, Blocks.sandstone);
		world.setBlock(i + 1, j + 4, k + 13, Blocks.sandstone);
		world.setBlock(i + 1, j + 4, k + 14, Blocks.sandstone);
		world.setBlock(i + 1, j + 5, k + 2, Blocks.sandstone);
		world.setBlock(i + 1, j + 5, k + 3, Blocks.sandstone);
		world.setBlock(i + 1, j + 5, k + 4, Blocks.sandstone);
		world.setBlock(i + 1, j + 5, k + 5, Blocks.sandstone);
		world.setBlock(i + 1, j + 5, k + 6, Blocks.sandstone);
		world.setBlock(i + 1, j + 5, k + 7, Blocks.sandstone);
		world.setBlock(i + 1, j + 5, k + 8, Blocks.sandstone);
		world.setBlock(i + 1, j + 5, k + 9, Blocks.sandstone);
		world.setBlock(i + 1, j + 5, k + 10, Blocks.sandstone);
		world.setBlock(i + 1, j + 5, k + 11, Blocks.sandstone);
		world.setBlock(i + 1, j + 5, k + 12, Blocks.sandstone);
		world.setBlock(i + 1, j + 5, k + 13, Blocks.sandstone);
		world.setBlock(i + 1, j + 5, k + 14, Blocks.sandstone);
		world.setBlock(i + 1, j + 5, k + 15, Blocks.sandstone);
		world.setBlock(i + 1, j + 5, k + 16, Blocks.sandstone);
		world.setBlock(i + 1, j + 5, k + 17, Blocks.sandstone);
		world.setBlock(i + 1, j + 11, k + 2, Blocks.wooden_slab, 1, 0x02);
		world.setBlock(i + 1, j + 11, k + 3, Blocks.wooden_slab, 1, 0x02);
		world.setBlock(i + 1, j + 11, k + 4, Blocks.wooden_slab, 1, 0x02);
		world.setBlock(i + 1, j + 11, k + 5, Blocks.wooden_slab, 1, 0x02);
		world.setBlock(i + 1, j + 11, k + 6, Blocks.wooden_slab, 1, 0x02);
		world.setBlock(i + 1, j + 11, k + 7, Blocks.wooden_slab, 1, 0x02);
		world.setBlock(i + 1, j + 11, k + 8, Blocks.wooden_slab, 1, 0x02);
		world.setBlock(i + 1, j + 11, k + 9, Blocks.wooden_slab, 1, 0x02);
		world.setBlock(i + 1, j + 11, k + 10, Blocks.wooden_slab, 1, 0x02);
		world.setBlock(i + 2, j + 0, k + 12, Blocks.sandstone);
		world.setBlock(i + 2, j + 1, k + 12, Blocks.sandstone);
		world.setBlock(i + 2, j + 2, k + 8, Blocks.sandstone);
		world.setBlock(i + 2, j + 2, k + 9, Blocks.sandstone);
		world.setBlock(i + 2, j + 2, k + 10, Blocks.sandstone);
		world.setBlock(i + 2, j + 2, k + 11, Blocks.sandstone);
		world.setBlock(i + 2, j + 2, k + 12, Blocks.sandstone);
		world.setBlock(i + 2, j + 3, k + 6, Blocks.sandstone);
		world.setBlock(i + 2, j + 3, k + 7, Blocks.sandstone);
		world.setBlock(i + 2, j + 3, k + 8, Blocks.sandstone);
		world.setBlock(i + 2, j + 3, k + 9, Blocks.sandstone);
		world.setBlock(i + 2, j + 3, k + 10, Blocks.sandstone);
		world.setBlock(i + 2, j + 3, k + 11, Blocks.sandstone);
		world.setBlock(i + 2, j + 3, k + 12, Blocks.sandstone);
		world.setBlock(i + 2, j + 3, k + 13, Blocks.sandstone);
		world.setBlock(i + 2, j + 4, k + 4, Blocks.sandstone);
		world.setBlock(i + 2, j + 4, k + 5, Blocks.sandstone);
		world.setBlock(i + 2, j + 4, k + 6, Blocks.sandstone);
		world.setBlock(i + 2, j + 4, k + 7, Blocks.sandstone);
		world.setBlock(i + 2, j + 4, k + 8, Blocks.sandstone);
		world.setBlock(i + 2, j + 4, k + 9, Blocks.sandstone);
		world.setBlock(i + 2, j + 4, k + 10, Blocks.sandstone);
		world.setBlock(i + 2, j + 4, k + 11, Blocks.sandstone);
		world.setBlock(i + 2, j + 4, k + 12, Blocks.sandstone);
		world.setBlock(i + 2, j + 4, k + 13, Blocks.sandstone);
		world.setBlock(i + 2, j + 4, k + 14, Blocks.sandstone);
		world.setBlock(i + 2, j + 4, k + 15, Blocks.sandstone);
		world.setBlock(i + 2, j + 5, k + 1, Blocks.sandstone);
		world.setBlock(i + 2, j + 5, k + 2, Blocks.sandstone);
		world.setBlock(i + 2, j + 5, k + 3, Blocks.dirt);
		world.setBlock(i + 2, j + 5, k + 4, Blocks.dirt);
		world.setBlock(i + 2, j + 5, k + 5, Blocks.dirt);
		world.setBlock(i + 2, j + 5, k + 6, Blocks.dirt);
		world.setBlock(i + 2, j + 5, k + 7, Blocks.dirt);
		world.setBlock(i + 2, j + 5, k + 8, Blocks.dirt);
		world.setBlock(i + 2, j + 5, k + 9, Blocks.dirt);
		world.setBlock(i + 2, j + 5, k + 10, Blocks.grass);
		world.setBlock(i + 2, j + 5, k + 11, Blocks.grass);
		world.setBlock(i + 2, j + 5, k + 12, Blocks.grass);
		world.setBlock(i + 2, j + 5, k + 13, Blocks.grass);
		world.setBlock(i + 2, j + 5, k + 14, Blocks.grass);
		world.setBlock(i + 2, j + 5, k + 15, Blocks.grass);
		world.setBlock(i + 2, j + 5, k + 16, Blocks.grass);
		world.setBlock(i + 2, j + 5, k + 17, Blocks.sandstone);
		world.setBlock(i + 2, j + 5, k + 18, Blocks.sandstone);
		world.setBlock(i + 2, j + 6, k + 3, Blocks.sandstone_stairs, 2, 0x02);
		world.setBlock(i + 2, j + 6, k + 4, Blocks.sandstone_stairs);
		world.setBlock(i + 2, j + 6, k + 5, Blocks.sandstone_stairs);
		world.setBlock(i + 2, j + 6, k + 6, Blocks.sandstone_stairs);
		world.setBlock(i + 2, j + 6, k + 7, Blocks.sandstone_stairs);
		world.setBlock(i + 2, j + 6, k + 8, Blocks.sandstone_stairs);
		world.setBlock(i + 2, j + 6, k + 9, Blocks.sandstone_stairs);
		world.setBlock(i + 2, j + 6, k + 11, Blocks.cobblestone_wall);
		world.setBlock(i + 2, j + 6, k + 12, Blocks.cobblestone_wall);
		world.setBlock(i + 2, j + 6, k + 13, Blocks.cobblestone_wall);
		world.setBlock(i + 2, j + 6, k + 14, Blocks.cobblestone_wall);
		world.setBlock(i + 2, j + 6, k + 15, Blocks.cobblestone_wall);
		world.setBlock(i + 2, j + 6, k + 16, Blocks.cobblestone_wall);
		world.setBlock(i + 2, j + 6, k + 17, Blocks.cobblestone_wall);
		world.setBlock(i + 2, j + 7, k + 11, Blocks.fence);
		world.setBlock(i + 2, j + 7, k + 17, Blocks.fence);
		world.setBlock(i + 2, j + 8, k + 11, Blocks.fence);
		world.setBlock(i + 2, j + 8, k + 17, Blocks.fence);
		world.setBlock(i + 2, j + 9, k + 11, Blocks.fence);
		world.setBlock(i + 2, j + 9, k + 17, Blocks.fence);
		world.setBlock(i + 2, j + 10, k + 11, Blocks.fence);
		world.setBlock(i + 2, j + 10, k + 12, Blocks.fence);
		world.setBlock(i + 2, j + 10, k + 16, Blocks.fence);
		world.setBlock(i + 2, j + 10, k + 17, Blocks.fence);
		world.setBlock(i + 2, j + 11, k + 2, Blocks.wooden_slab, 1, 0x02);
		world.setBlock(i + 2, j + 11, k + 3, Blocks.spruce_stairs);
		world.setBlock(i + 2, j + 11, k + 4, Blocks.spruce_stairs);
		world.setBlock(i + 2, j + 11, k + 5, Blocks.spruce_stairs);
		world.setBlock(i + 2, j + 11, k + 6, Blocks.spruce_stairs);
		world.setBlock(i + 2, j + 11, k + 7, Blocks.spruce_stairs);
		world.setBlock(i + 2, j + 11, k + 8, Blocks.spruce_stairs);
		world.setBlock(i + 2, j + 11, k + 9, Blocks.spruce_stairs, 3, 0x02);
		world.setBlock(i + 2, j + 11, k + 10, Blocks.wooden_slab, 1, 0x02);
		world.setBlock(i + 3, j + 0, k + 4, Blocks.sandstone);
		world.setBlock(i + 3, j + 1, k + 4, Blocks.sandstone);
		world.setBlock(i + 3, j + 1, k + 8, Blocks.sandstone);
		world.setBlock(i + 3, j + 1, k + 9, Blocks.sandstone);
		world.setBlock(i + 3, j + 1, k + 10, Blocks.sandstone);
		world.setBlock(i + 3, j + 1, k + 11, Blocks.sandstone);
		world.setBlock(i + 3, j + 1, k + 15, Blocks.sandstone);
		world.setBlock(i + 3, j + 2, k + 2, Blocks.sandstone);
		world.setBlock(i + 3, j + 2, k + 4, Blocks.sandstone);
		world.setBlock(i + 3, j + 2, k + 6, Blocks.sandstone);
		world.setBlock(i + 3, j + 2, k + 7, Blocks.sandstone);
		world.setBlock(i + 3, j + 2, k + 8, Blocks.sandstone);
		world.setBlock(i + 3, j + 2, k + 9, Blocks.sandstone);
		world.setBlock(i + 3, j + 2, k + 10, Blocks.sandstone);
		world.setBlock(i + 3, j + 2, k + 11, Blocks.sandstone);
		world.setBlock(i + 3, j + 2, k + 12, Blocks.sandstone);
		world.setBlock(i + 3, j + 2, k + 13, Blocks.sandstone);
		world.setBlock(i + 3, j + 2, k + 15, Blocks.sandstone);
		world.setBlock(i + 3, j + 2, k + 17, Blocks.sandstone);
		world.setBlock(i + 3, j + 3, k + 2, Blocks.sandstone);
		world.setBlock(i + 3, j + 3, k + 4, Blocks.sandstone);
		world.setBlock(i + 3, j + 3, k + 5, Blocks.sandstone);
		world.setBlock(i + 3, j + 3, k + 6, Blocks.sandstone);
		world.setBlock(i + 3, j + 3, k + 7, Blocks.sandstone);
		world.setBlock(i + 3, j + 3, k + 8, Blocks.sandstone);
		world.setBlock(i + 3, j + 3, k + 9, Blocks.sandstone);
		world.setBlock(i + 3, j + 3, k + 10, Blocks.sandstone);
		world.setBlock(i + 3, j + 3, k + 11, Blocks.sandstone);
		world.setBlock(i + 3, j + 3, k + 12, Blocks.sandstone);
		world.setBlock(i + 3, j + 3, k + 13, Blocks.sandstone);
		world.setBlock(i + 3, j + 3, k + 14, Blocks.sandstone);
		world.setBlock(i + 3, j + 3, k + 15, Blocks.sandstone);
		world.setBlock(i + 3, j + 3, k + 17, Blocks.sandstone);
		world.setBlock(i + 3, j + 4, k + 2, Blocks.sandstone);
		world.setBlock(i + 3, j + 4, k + 3, Blocks.sandstone);
		world.setBlock(i + 3, j + 4, k + 4, Blocks.sandstone);
		world.setBlock(i + 3, j + 4, k + 5, Blocks.sandstone);
		world.setBlock(i + 3, j + 4, k + 6, Blocks.sandstone);
		world.setBlock(i + 3, j + 4, k + 7, Blocks.sandstone);
		world.setBlock(i + 3, j + 4, k + 8, Blocks.sandstone);
		world.setBlock(i + 3, j + 4, k + 9, Blocks.sandstone);
		world.setBlock(i + 3, j + 4, k + 10, Blocks.sandstone);
		world.setBlock(i + 3, j + 4, k + 11, Blocks.sandstone);
		world.setBlock(i + 3, j + 4, k + 12, Blocks.sandstone);
		world.setBlock(i + 3, j + 4, k + 13, Blocks.sandstone);
		world.setBlock(i + 3, j + 4, k + 14, Blocks.sandstone);
		world.setBlock(i + 3, j + 4, k + 15, Blocks.sandstone);
		world.setBlock(i + 3, j + 4, k + 16, Blocks.sandstone);
		world.setBlock(i + 3, j + 4, k + 17, Blocks.sandstone);
		world.setBlock(i + 3, j + 5, k + 1, Blocks.sandstone);
		world.setBlock(i + 3, j + 5, k + 2, Blocks.sandstone);
		world.setBlock(i + 3, j + 5, k + 3, Blocks.dirt);
		world.setBlock(i + 3, j + 5, k + 4, Blocks.dirt);
		world.setBlock(i + 3, j + 5, k + 5, Blocks.dirt);
		world.setBlock(i + 3, j + 5, k + 6, Blocks.dirt);
		world.setBlock(i + 3, j + 5, k + 7, Blocks.dirt);
		world.setBlock(i + 3, j + 5, k + 8, Blocks.dirt);
		world.setBlock(i + 3, j + 5, k + 9, Blocks.dirt);
		world.setBlock(i + 3, j + 5, k + 10, Blocks.grass);
		world.setBlock(i + 3, j + 5, k + 11, Blocks.grass);
		world.setBlock(i + 3, j + 5, k + 12, Blocks.grass);
		world.setBlock(i + 3, j + 5, k + 13, Blocks.grass);
		world.setBlock(i + 3, j + 5, k + 14, Blocks.grass);
		world.setBlock(i + 3, j + 5, k + 15, Blocks.grass);
		world.setBlock(i + 3, j + 5, k + 16, Blocks.grass);
		world.setBlock(i + 3, j + 5, k + 17, Blocks.sandstone);
		world.setBlock(i + 3, j + 5, k + 18, Blocks.sandstone);
		world.setBlock(i + 3, j + 6, k + 3, Blocks.sandstone_stairs, 2, 0x02);
		world.setBlock(i + 3, j + 6, k + 4, Blocks.planks, 1, 0x02);
		world.setBlock(i + 3, j + 6, k + 5, Blocks.planks, 1, 0x02);
		world.setBlock(i + 3, j + 6, k + 6, Blocks.planks, 1, 0x02);
		world.setBlock(i + 3, j + 6, k + 7, Blocks.planks, 1, 0x02);
		world.setBlock(i + 3, j + 6, k + 8, Blocks.planks, 1, 0x02);
		world.setBlock(i + 3, j + 6, k + 9, Blocks.sandstone_stairs, 3, 0x02);
		world.setBlock(i + 3, j + 6, k + 11, Blocks.cobblestone_wall);
		world.setBlock(i + 3, j + 6, k + 13, Blocks.fence);
		world.setBlock(i + 3, j + 6, k + 15, Blocks.fence);
		world.setBlock(i + 3, j + 6, k + 17, Blocks.cobblestone_wall);
		world.setBlock(i + 3, j + 7, k + 4, Blocks.log, 1, 0x02);
		world.setBlock(i + 3, j + 7, k + 5, Blocks.cobblestone);
		world.setBlock(i + 3, j + 7, k + 6, Blocks.cobblestone);
		world.setBlock(i + 3, j + 7, k + 7, Blocks.cobblestone);
		world.setBlock(i + 3, j + 7, k + 8, Blocks.log, 1, 0x02);
		world.setBlock(i + 3, j + 7, k + 15, Blocks.fence);
		world.setBlock(i + 3, j + 8, k + 4, Blocks.log, 1, 0x02);
		world.setBlock(i + 3, j + 8, k + 5, Blocks.cobblestone);
		world.setBlock(i + 3, j + 8, k + 6, Blocks.glass_pane);
		world.setBlock(i + 3, j + 8, k + 7, Blocks.cobblestone);
		world.setBlock(i + 3, j + 8, k + 8, Blocks.log, 1, 0x02);
		world.setBlock(i + 3, j + 9, k + 4, Blocks.log, 1, 0x02);
		world.setBlock(i + 3, j + 9, k + 5, Blocks.cobblestone);
		world.setBlock(i + 3, j + 9, k + 6, Blocks.glass_pane);
		world.setBlock(i + 3, j + 9, k + 7, Blocks.cobblestone);
		world.setBlock(i + 3, j + 9, k + 8, Blocks.log, 1, 0x02);
		world.setBlock(i + 3, j + 9, k + 12, Blocks.glowstone);
		world.setBlock(i + 3, j + 9, k + 16, Blocks.glowstone);
		world.setBlock(i + 3, j + 10, k + 4, Blocks.log, 1, 0x02);
		world.setBlock(i + 3, j + 10, k + 5, Blocks.cobblestone);
		world.setBlock(i + 3, j + 10, k + 6, Blocks.cobblestone);
		world.setBlock(i + 3, j + 10, k + 7, Blocks.cobblestone);
		world.setBlock(i + 3, j + 10, k + 8, Blocks.log, 1, 0x02);
		world.setBlock(i + 3, j + 10, k + 11, Blocks.fence);
		world.setBlock(i + 3, j + 10, k + 12, Blocks.fence);
		world.setBlock(i + 3, j + 10, k + 16, Blocks.fence);
		world.setBlock(i + 3, j + 10, k + 17, Blocks.fence);
		world.setBlock(i + 3, j + 11, k + 2, Blocks.wooden_slab, 1, 0x02);
		world.setBlock(i + 3, j + 11, k + 3, Blocks.spruce_stairs, 2, 0x02);
		world.setBlock(i + 3, j + 11, k + 4, Blocks.log, 1, 0x02);
		world.setBlock(i + 3, j + 11, k + 5, Blocks.log, 5, 0x02);
		world.setBlock(i + 3, j + 11, k + 6, Blocks.log, 5, 0x02);
		world.setBlock(i + 3, j + 11, k + 7, Blocks.log, 5, 0x02);
		world.setBlock(i + 3, j + 11, k + 8, Blocks.log, 1, 0x02);
		world.setBlock(i + 3, j + 11, k + 9, Blocks.spruce_stairs, 3, 0x02);
		world.setBlock(i + 3, j + 11, k + 10, Blocks.wooden_slab, 1, 0x02);
		world.setBlock(i + 3, j + 12, k + 4, Blocks.fence);
		world.setBlock(i + 3, j + 12, k + 5, Blocks.fence);
		world.setBlock(i + 3, j + 12, k + 6, Blocks.fence);
		world.setBlock(i + 3, j + 12, k + 7, Blocks.fence);
		world.setBlock(i + 3, j + 12, k + 8, Blocks.fence);
		world.setBlock(i + 3, j + 13, k + 4, Blocks.fence);
		world.setBlock(i + 3, j + 13, k + 8, Blocks.fence);
		world.setBlock(i + 3, j + 14, k + 4, Blocks.fence);
		world.setBlock(i + 3, j + 14, k + 5, Blocks.fence);
		world.setBlock(i + 3, j + 14, k + 7, Blocks.fence);
		world.setBlock(i + 3, j + 14, k + 8, Blocks.fence);
		world.setBlock(i + 3, j + 15, k + 4, Blocks.fence);
		world.setBlock(i + 3, j + 15, k + 5, Blocks.fence);
		world.setBlock(i + 3, j + 15, k + 6, Blocks.fence);
		world.setBlock(i + 3, j + 15, k + 7, Blocks.fence);
		world.setBlock(i + 3, j + 15, k + 8, Blocks.fence);
		world.setBlock(i + 3, j + 16, k + 4, Blocks.birch_stairs, 2, 0x02);
		world.setBlock(i + 3, j + 16, k + 5, Blocks.birch_stairs);
		world.setBlock(i + 3, j + 16, k + 6, Blocks.birch_stairs);
		world.setBlock(i + 3, j + 16, k + 7, Blocks.birch_stairs);
		world.setBlock(i + 3, j + 16, k + 8, Blocks.birch_stairs, 3, 0x02);
		world.setBlock(i + 4, j + 0, k + 9, Blocks.sandstone);
		world.setBlock(i + 4, j + 0, k + 10, Blocks.sandstone);
		world.setBlock(i + 4, j + 1, k + 6, Blocks.sandstone);
		world.setBlock(i + 4, j + 1, k + 7, Blocks.sandstone);
		world.setBlock(i + 4, j + 1, k + 8, Blocks.sandstone);
		world.setBlock(i + 4, j + 1, k + 9, Blocks.sandstone);
		world.setBlock(i + 4, j + 1, k + 10, Blocks.sandstone);
		world.setBlock(i + 4, j + 1, k + 11, Blocks.sandstone);
		world.setBlock(i + 4, j + 1, k + 12, Blocks.sandstone);
		world.setBlock(i + 4, j + 1, k + 13, Blocks.sandstone);
		world.setBlock(i + 4, j + 2, k + 5, Blocks.sandstone);
		world.setBlock(i + 4, j + 2, k + 6, Blocks.sandstone);
		world.setBlock(i + 4, j + 2, k + 7, Blocks.sandstone);
		world.setBlock(i + 4, j + 2, k + 8, Blocks.sandstone);
		world.setBlock(i + 4, j + 2, k + 9, Blocks.sandstone);
		world.setBlock(i + 4, j + 2, k + 10, Blocks.sandstone);
		world.setBlock(i + 4, j + 2, k + 11, Blocks.sandstone);
		world.setBlock(i + 4, j + 2, k + 12, Blocks.sandstone);
		world.setBlock(i + 4, j + 2, k + 13, Blocks.sandstone);
		world.setBlock(i + 4, j + 2, k + 14, Blocks.sandstone);
		world.setBlock(i + 4, j + 3, k + 4, Blocks.sandstone);
		world.setBlock(i + 4, j + 3, k + 5, Blocks.sandstone);
		world.setBlock(i + 4, j + 3, k + 6, Blocks.sandstone);
		world.setBlock(i + 4, j + 3, k + 7, Blocks.sandstone);
		world.setBlock(i + 4, j + 3, k + 8, Blocks.sandstone);
		world.setBlock(i + 4, j + 3, k + 9, Blocks.sandstone);
		world.setBlock(i + 4, j + 3, k + 10, Blocks.sandstone);
		world.setBlock(i + 4, j + 3, k + 11, Blocks.sandstone);
		world.setBlock(i + 4, j + 3, k + 12, Blocks.sandstone);
		world.setBlock(i + 4, j + 3, k + 13, Blocks.sandstone);
		world.setBlock(i + 4, j + 3, k + 14, Blocks.sandstone);
		world.setBlock(i + 4, j + 3, k + 15, Blocks.sandstone);
		world.setBlock(i + 4, j + 4, k + 2, Blocks.sandstone);
		world.setBlock(i + 4, j + 4, k + 3, Blocks.sandstone);
		world.setBlock(i + 4, j + 4, k + 4, Blocks.sandstone);
		world.setBlock(i + 4, j + 4, k + 5, Blocks.sandstone);
		world.setBlock(i + 4, j + 4, k + 6, Blocks.sandstone);
		world.setBlock(i + 4, j + 4, k + 7, Blocks.sandstone);
		world.setBlock(i + 4, j + 4, k + 8, Blocks.sandstone);
		world.setBlock(i + 4, j + 4, k + 9, Blocks.sandstone);
		world.setBlock(i + 4, j + 4, k + 10, Blocks.sandstone);
		world.setBlock(i + 4, j + 4, k + 11, Blocks.sandstone);
		world.setBlock(i + 4, j + 4, k + 12, Blocks.sandstone);
		world.setBlock(i + 4, j + 4, k + 13, Blocks.sandstone);
		world.setBlock(i + 4, j + 4, k + 14, Blocks.sandstone);
		world.setBlock(i + 4, j + 4, k + 15, Blocks.sandstone);
		world.setBlock(i + 4, j + 4, k + 16, Blocks.sandstone);
		world.setBlock(i + 4, j + 4, k + 17, Blocks.sandstone);
		world.setBlock(i + 4, j + 5, k + 1, Blocks.sandstone);
		world.setBlock(i + 4, j + 5, k + 2, Blocks.sandstone);
		world.setBlock(i + 4, j + 5, k + 3, Blocks.dirt);
		world.setBlock(i + 4, j + 5, k + 4, Blocks.dirt);
		world.setBlock(i + 4, j + 5, k + 5, Blocks.dirt);
		world.setBlock(i + 4, j + 5, k + 6, Blocks.dirt);
		world.setBlock(i + 4, j + 5, k + 7, Blocks.dirt);
		world.setBlock(i + 4, j + 5, k + 8, Blocks.dirt);
		world.setBlock(i + 4, j + 5, k + 9, Blocks.dirt);
		world.setBlock(i + 4, j + 5, k + 10, Blocks.grass);
		world.setBlock(i + 4, j + 5, k + 11, Blocks.grass);
		world.setBlock(i + 4, j + 5, k + 12, Blocks.grass);
		world.setBlock(i + 4, j + 5, k + 13, Blocks.grass);
		world.setBlock(i + 4, j + 5, k + 14, Blocks.grass);
		world.setBlock(i + 4, j + 5, k + 15, Blocks.grass);
		world.setBlock(i + 4, j + 5, k + 16, Blocks.grass);
		world.setBlock(i + 4, j + 5, k + 17, Blocks.sandstone);
		world.setBlock(i + 4, j + 5, k + 18, Blocks.sandstone);
		world.setBlock(i + 4, j + 6, k + 3, Blocks.sandstone_stairs, 2, 0x02);
		world.setBlock(i + 4, j + 6, k + 4, Blocks.planks, 1, 0x02);
		world.setBlock(i + 4, j + 6, k + 5, Blocks.planks, 1, 0x02);
		world.setBlock(i + 4, j + 6, k + 6, Blocks.planks, 1, 0x02);
		world.setBlock(i + 4, j + 6, k + 7, Blocks.planks, 1, 0x02);
		world.setBlock(i + 4, j + 6, k + 8, Blocks.planks, 1, 0x02);
		world.setBlock(i + 4, j + 6, k + 9, Blocks.sandstone_stairs, 3, 0x02);
		world.setBlock(i + 4, j + 6, k + 11, Blocks.cobblestone_wall);
		world.setBlock(i + 4, j + 6, k + 14, Blocks.fence);
		world.setBlock(i + 4, j + 6, k + 16, Blocks.fence);
		world.setBlock(i + 4, j + 6, k + 17, Blocks.cobblestone_wall);
		world.setBlock(i + 4, j + 7, k + 4, Blocks.cobblestone);
		world.setBlock(i + 4, j + 7, k + 6, Blocks.furnace, 5, 0x02);
		world.setBlock(i + 4, j + 7, k + 7, Blocks.furnace, 5, 0x02);
		world.setBlock(i + 4, j + 7, k + 8, Blocks.cobblestone);
		world.setBlock(i + 4, j + 7, k + 14, Blocks.fence);
		world.setBlock(i + 4, j + 7, k + 16, Blocks.fence);
		world.setBlock(i + 4, j + 8, k + 4, Blocks.cobblestone);
		world.setBlock(i + 4, j + 8, k + 8, Blocks.cobblestone);
		world.setBlock(i + 4, j + 8, k + 14, Blocks.fence);
		world.setBlock(i + 4, j + 8, k + 16, Blocks.fence);
		world.setBlock(i + 4, j + 9, k + 4, Blocks.cobblestone);
		world.setBlock(i + 4, j + 9, k + 8, Blocks.cobblestone);
		world.setBlock(i + 4, j + 9, k + 14, Blocks.fence);
		world.setBlock(i + 4, j + 10, k + 4, Blocks.cobblestone);
		world.setBlock(i + 4, j + 10, k + 8, Blocks.cobblestone);
		world.setBlock(i + 4, j + 11, k + 2, Blocks.wooden_slab, 1, 0x02);
		world.setBlock(i + 4, j + 11, k + 3, Blocks.spruce_stairs, 2, 0x02);
		world.setBlock(i + 4, j + 11, k + 4, Blocks.log, 9, 0x02);
		world.setBlock(i + 4, j + 11, k + 6, Blocks.planks, 1, 0x02);
		world.setBlock(i + 4, j + 11, k + 7, Blocks.planks, 1, 0x02);
		world.setBlock(i + 4, j + 11, k + 8, Blocks.log, 9, 0x02);
		world.setBlock(i + 4, j + 11, k + 9, Blocks.spruce_stairs, 3, 0x02);
		world.setBlock(i + 4, j + 11, k + 10, Blocks.wooden_slab, 1, 0x02);
		world.setBlock(i + 4, j + 12, k + 4, Blocks.fence);
		world.setBlock(i + 4, j + 12, k + 7, Blocks.bed, 9, 0x02);
		world.setBlock(i + 4, j + 12, k + 8, Blocks.fence);
		world.setBlock(i + 4, j + 14, k + 4, Blocks.fence);
		world.setBlock(i + 4, j + 14, k + 8, Blocks.fence);
		world.setBlock(i + 4, j + 15, k + 4, Blocks.fence);
		world.setBlock(i + 4, j + 15, k + 8, Blocks.fence);
		world.setBlock(i + 4, j + 16, k + 4, Blocks.birch_stairs, 2, 0x02);
		world.setBlock(i + 4, j + 16, k + 8, Blocks.birch_stairs, 3, 0x02);
		world.setBlock(i + 4, j + 17, k + 5, Blocks.birch_stairs);
		world.setBlock(i + 4, j + 17, k + 6, Blocks.birch_stairs);
		world.setBlock(i + 4, j + 17, k + 7, Blocks.birch_stairs);
		world.setBlock(i + 5, j + 0, k + 7, Blocks.sandstone);
		world.setBlock(i + 5, j + 0, k + 8, Blocks.sandstone);
		world.setBlock(i + 5, j + 0, k + 9, Blocks.sandstone);
		world.setBlock(i + 5, j + 0, k + 10, Blocks.sandstone);
		world.setBlock(i + 5, j + 0, k + 11, Blocks.sandstone);
		world.setBlock(i + 5, j + 0, k + 12, Blocks.sandstone);
		world.setBlock(i + 5, j + 1, k + 5, Blocks.sandstone);
		world.setBlock(i + 5, j + 1, k + 6, Blocks.sandstone);
		world.setBlock(i + 5, j + 1, k + 7, Blocks.sandstone);
		world.setBlock(i + 5, j + 1, k + 8, Blocks.sandstone);
		world.setBlock(i + 5, j + 1, k + 9, Blocks.sandstone);
		world.setBlock(i + 5, j + 1, k + 10, Blocks.sandstone);
		world.setBlock(i + 5, j + 1, k + 11, Blocks.sandstone);
		world.setBlock(i + 5, j + 1, k + 12, Blocks.sandstone);
		world.setBlock(i + 5, j + 1, k + 13, Blocks.sandstone);
		world.setBlock(i + 5, j + 1, k + 14, Blocks.sandstone);
		world.setBlock(i + 5, j + 2, k + 4, Blocks.sandstone);
		world.setBlock(i + 5, j + 2, k + 5, Blocks.sandstone);
		world.setBlock(i + 5, j + 2, k + 6, Blocks.sandstone);
		world.setBlock(i + 5, j + 2, k + 7, Blocks.sandstone);
		world.setBlock(i + 5, j + 2, k + 8, Blocks.sandstone);
		world.setBlock(i + 5, j + 2, k + 9, Blocks.sandstone);
		world.setBlock(i + 5, j + 2, k + 10, Blocks.sandstone);
		world.setBlock(i + 5, j + 2, k + 11, Blocks.sandstone);
		world.setBlock(i + 5, j + 2, k + 12, Blocks.sandstone);
		world.setBlock(i + 5, j + 2, k + 13, Blocks.sandstone);
		world.setBlock(i + 5, j + 2, k + 14, Blocks.sandstone);
		world.setBlock(i + 5, j + 2, k + 15, Blocks.sandstone);
		world.setBlock(i + 5, j + 3, k + 0, Blocks.sandstone);
		world.setBlock(i + 5, j + 3, k + 3, Blocks.sandstone);
		world.setBlock(i + 5, j + 3, k + 4, Blocks.sandstone);
		world.setBlock(i + 5, j + 3, k + 5, Blocks.sandstone);
		world.setBlock(i + 5, j + 3, k + 6, Blocks.sandstone);
		world.setBlock(i + 5, j + 3, k + 7, Blocks.sandstone);
		world.setBlock(i + 5, j + 3, k + 8, Blocks.sandstone);
		world.setBlock(i + 5, j + 3, k + 9, Blocks.sandstone);
		world.setBlock(i + 5, j + 3, k + 10, Blocks.sandstone);
		world.setBlock(i + 5, j + 3, k + 11, Blocks.sandstone);
		world.setBlock(i + 5, j + 3, k + 12, Blocks.sandstone);
		world.setBlock(i + 5, j + 3, k + 13, Blocks.sandstone);
		world.setBlock(i + 5, j + 3, k + 14, Blocks.sandstone);
		world.setBlock(i + 5, j + 3, k + 15, Blocks.sandstone);
		world.setBlock(i + 5, j + 3, k + 16, Blocks.sandstone);
		world.setBlock(i + 5, j + 4, k + 0, Blocks.sandstone);
		world.setBlock(i + 5, j + 4, k + 2, Blocks.sandstone);
		world.setBlock(i + 5, j + 4, k + 3, Blocks.sandstone);
		world.setBlock(i + 5, j + 4, k + 4, Blocks.sandstone);
		world.setBlock(i + 5, j + 4, k + 5, Blocks.sandstone);
		world.setBlock(i + 5, j + 4, k + 6, Blocks.sandstone);
		world.setBlock(i + 5, j + 4, k + 7, Blocks.sandstone);
		world.setBlock(i + 5, j + 4, k + 8, Blocks.sandstone);
		world.setBlock(i + 5, j + 4, k + 9, Blocks.sandstone);
		world.setBlock(i + 5, j + 4, k + 10, Blocks.sandstone);
		world.setBlock(i + 5, j + 4, k + 11, Blocks.sandstone);
		world.setBlock(i + 5, j + 4, k + 12, Blocks.sandstone);
		world.setBlock(i + 5, j + 4, k + 13, Blocks.sandstone);
		world.setBlock(i + 5, j + 4, k + 14, Blocks.sandstone);
		world.setBlock(i + 5, j + 4, k + 15, Blocks.sandstone);
		world.setBlock(i + 5, j + 4, k + 16, Blocks.sandstone);
		world.setBlock(i + 5, j + 4, k + 17, Blocks.sandstone);
		world.setBlock(i + 5, j + 5, k + 0, Blocks.sandstone);
		world.setBlock(i + 5, j + 5, k + 1, Blocks.sandstone);
		world.setBlock(i + 5, j + 5, k + 2, Blocks.sandstone);
		world.setBlock(i + 5, j + 5, k + 3, Blocks.dirt);
		world.setBlock(i + 5, j + 5, k + 4, Blocks.dirt);
		world.setBlock(i + 5, j + 5, k + 5, Blocks.dirt);
		world.setBlock(i + 5, j + 5, k + 6, Blocks.dirt);
		world.setBlock(i + 5, j + 5, k + 7, Blocks.dirt);
		world.setBlock(i + 5, j + 5, k + 8, Blocks.dirt);
		world.setBlock(i + 5, j + 5, k + 9, Blocks.dirt);
		world.setBlock(i + 5, j + 5, k + 10, Blocks.grass);
		world.setBlock(i + 5, j + 5, k + 11, Blocks.grass);
		world.setBlock(i + 5, j + 5, k + 12, Blocks.grass);
		world.setBlock(i + 5, j + 5, k + 13, Blocks.grass);
		world.setBlock(i + 5, j + 5, k + 14, Blocks.grass);
		world.setBlock(i + 5, j + 5, k + 15, Blocks.grass);
		world.setBlock(i + 5, j + 5, k + 16, Blocks.grass);
		world.setBlock(i + 5, j + 5, k + 17, Blocks.sandstone);
		world.setBlock(i + 5, j + 5, k + 18, Blocks.sandstone);
		world.setBlock(i + 5, j + 5, k + 19, Blocks.sandstone);
		world.setBlock(i + 5, j + 6, k + 3, Blocks.sandstone_stairs, 2, 0x02);
		world.setBlock(i + 5, j + 6, k + 4, Blocks.planks, 1, 0x02);
		world.setBlock(i + 5, j + 6, k + 5, Blocks.planks, 1, 0x02);
		world.setBlock(i + 5, j + 6, k + 6, Blocks.planks, 1, 0x02);
		world.setBlock(i + 5, j + 6, k + 7, Blocks.planks, 1, 0x02);
		world.setBlock(i + 5, j + 6, k + 8, Blocks.planks, 1, 0x02);
		world.setBlock(i + 5, j + 6, k + 9, Blocks.sandstone_stairs, 3, 0x02);
		world.setBlock(i + 5, j + 6, k + 11, Blocks.cobblestone_wall);
		world.setBlock(i + 5, j + 6, k + 12, Blocks.fence);
		world.setBlock(i + 5, j + 6, k + 17, Blocks.cobblestone_wall);
		world.setBlock(i + 5, j + 7, k + 4, Blocks.cobblestone);
		world.setBlock(i + 5, j + 7, k + 8, Blocks.cobblestone);
		world.setBlock(i + 5, j + 7, k + 12, Blocks.fence);
		world.setBlock(i + 5, j + 8, k + 4, Blocks.glass_pane);
		world.setBlock(i + 5, j + 8, k + 8, Blocks.glass_pane);
		world.setBlock(i + 5, j + 9, k + 4, Blocks.glass_pane);
		world.setBlock(i + 5, j + 9, k + 8, Blocks.glass_pane);
		world.setBlock(i + 5, j + 10, k + 4, Blocks.cobblestone);
		world.setBlock(i + 5, j + 10, k + 8, Blocks.cobblestone);
		world.setBlock(i + 5, j + 11, k + 2, Blocks.wooden_slab, 1, 0x02);
		world.setBlock(i + 5, j + 11, k + 3, Blocks.spruce_stairs, 2, 0x02);
		world.setBlock(i + 5, j + 11, k + 4, Blocks.log, 9, 0x02);
		world.setBlock(i + 5, j + 11, k + 5, Blocks.planks, 1, 0x02);
		world.setBlock(i + 5, j + 11, k + 6, Blocks.planks, 1, 0x02);
		world.setBlock(i + 5, j + 11, k + 7, Blocks.planks, 1, 0x02);
		world.setBlock(i + 5, j + 11, k + 8, Blocks.log, 9, 0x02);
		world.setBlock(i + 5, j + 11, k + 9, Blocks.spruce_stairs, 3, 0x02);
		world.setBlock(i + 5, j + 11, k + 10, Blocks.wooden_slab, 1, 0x02);
		world.setBlock(i + 5, j + 12, k + 4, Blocks.fence);
		world.setBlock(i + 5, j + 12, k + 7, Blocks.bed, 1, 0x02);
		world.setBlock(i + 5, j + 12, k + 8, Blocks.fence);
		world.setBlock(i + 5, j + 15, k + 4, Blocks.fence);
		world.setBlock(i + 5, j + 15, k + 8, Blocks.fence);
		world.setBlock(i + 5, j + 16, k + 4, Blocks.birch_stairs, 2, 0x02);
		world.setBlock(i + 5, j + 16, k + 8, Blocks.birch_stairs, 3, 0x02);
		world.setBlock(i + 5, j + 17, k + 5, Blocks.birch_stairs, 2, 0x02);
		world.setBlock(i + 5, j + 17, k + 6, mod_Avatar.AirNomadsBlock);
		world.setBlock(i + 5, j + 17, k + 7, Blocks.birch_stairs, 3, 0x02);
		world.setBlock(i + 5, j + 18, k + 6, Blocks.glowstone);
		world.setBlock(i + 6, j + 0, k + 6, Blocks.sandstone);
		world.setBlock(i + 6, j + 0, k + 7, Blocks.sandstone);
		world.setBlock(i + 6, j + 0, k + 8, Blocks.sandstone);
		world.setBlock(i + 6, j + 0, k + 9, Blocks.sandstone);
		world.setBlock(i + 6, j + 0, k + 10, Blocks.sandstone);
		world.setBlock(i + 6, j + 0, k + 11, Blocks.sandstone);
		world.setBlock(i + 6, j + 0, k + 12, Blocks.sandstone);
		world.setBlock(i + 6, j + 0, k + 13, Blocks.sandstone);
		world.setBlock(i + 6, j + 1, k + 2, Blocks.sandstone);
		world.setBlock(i + 6, j + 1, k + 5, Blocks.sandstone);
		world.setBlock(i + 6, j + 1, k + 6, Blocks.sandstone);
		world.setBlock(i + 6, j + 1, k + 7, Blocks.sandstone);
		world.setBlock(i + 6, j + 1, k + 8, Blocks.sandstone);
		world.setBlock(i + 6, j + 1, k + 9, Blocks.sandstone);
		world.setBlock(i + 6, j + 1, k + 10, Blocks.sandstone);
		world.setBlock(i + 6, j + 1, k + 11, Blocks.sandstone);
		world.setBlock(i + 6, j + 1, k + 12, Blocks.sandstone);
		world.setBlock(i + 6, j + 1, k + 13, Blocks.sandstone);
		world.setBlock(i + 6, j + 1, k + 14, Blocks.sandstone);
		world.setBlock(i + 6, j + 2, k + 2, Blocks.sandstone);
		world.setBlock(i + 6, j + 2, k + 4, Blocks.sandstone);
		world.setBlock(i + 6, j + 2, k + 5, Blocks.sandstone);
		world.setBlock(i + 6, j + 2, k + 6, Blocks.sandstone);
		world.setBlock(i + 6, j + 2, k + 7, Blocks.sandstone);
		world.setBlock(i + 6, j + 2, k + 8, Blocks.sandstone);
		world.setBlock(i + 6, j + 2, k + 9, Blocks.sandstone);
		world.setBlock(i + 6, j + 2, k + 10, Blocks.sandstone);
		world.setBlock(i + 6, j + 2, k + 11, Blocks.sandstone);
		world.setBlock(i + 6, j + 2, k + 12, Blocks.sandstone);
		world.setBlock(i + 6, j + 2, k + 13, Blocks.sandstone);
		world.setBlock(i + 6, j + 2, k + 14, Blocks.sandstone);
		world.setBlock(i + 6, j + 2, k + 15, Blocks.sandstone);
		world.setBlock(i + 6, j + 2, k + 19, Blocks.sandstone);
		world.setBlock(i + 6, j + 3, k + 2, Blocks.sandstone);
		world.setBlock(i + 6, j + 3, k + 3, Blocks.sandstone);
		world.setBlock(i + 6, j + 3, k + 4, Blocks.sandstone);
		world.setBlock(i + 6, j + 3, k + 5, Blocks.sandstone);
		world.setBlock(i + 6, j + 3, k + 6, Blocks.sandstone);
		world.setBlock(i + 6, j + 3, k + 7, Blocks.sandstone);
		world.setBlock(i + 6, j + 3, k + 8, Blocks.sandstone);
		world.setBlock(i + 6, j + 3, k + 9, Blocks.sandstone);
		world.setBlock(i + 6, j + 3, k + 10, Blocks.sandstone);
		world.setBlock(i + 6, j + 3, k + 11, Blocks.sandstone);
		world.setBlock(i + 6, j + 3, k + 12, Blocks.sandstone);
		world.setBlock(i + 6, j + 3, k + 13, Blocks.sandstone);
		world.setBlock(i + 6, j + 3, k + 14, Blocks.sandstone);
		world.setBlock(i + 6, j + 3, k + 15, Blocks.sandstone);
		world.setBlock(i + 6, j + 3, k + 16, Blocks.sandstone);
		world.setBlock(i + 6, j + 3, k + 19, Blocks.sandstone);
		world.setBlock(i + 6, j + 4, k + 2, Blocks.sandstone);
		world.setBlock(i + 6, j + 4, k + 3, Blocks.sandstone);
		world.setBlock(i + 6, j + 4, k + 4, Blocks.sandstone);
		world.setBlock(i + 6, j + 4, k + 5, Blocks.sandstone);
		world.setBlock(i + 6, j + 4, k + 6, Blocks.sandstone);
		world.setBlock(i + 6, j + 4, k + 7, Blocks.sandstone);
		world.setBlock(i + 6, j + 4, k + 8, Blocks.sandstone);
		world.setBlock(i + 6, j + 4, k + 9, Blocks.sandstone);
		world.setBlock(i + 6, j + 4, k + 10, Blocks.sandstone);
		world.setBlock(i + 6, j + 4, k + 11, Blocks.sandstone);
		world.setBlock(i + 6, j + 4, k + 12, Blocks.sandstone);
		world.setBlock(i + 6, j + 4, k + 13, Blocks.sandstone);
		world.setBlock(i + 6, j + 4, k + 14, Blocks.sandstone);
		world.setBlock(i + 6, j + 4, k + 15, Blocks.sandstone);
		world.setBlock(i + 6, j + 4, k + 16, Blocks.sandstone);
		world.setBlock(i + 6, j + 4, k + 17, Blocks.sandstone);
		world.setBlock(i + 6, j + 4, k + 19, Blocks.sandstone);
		world.setBlock(i + 6, j + 5, k + 0, Blocks.sandstone);
		world.setBlock(i + 6, j + 5, k + 1, Blocks.sandstone);
		world.setBlock(i + 6, j + 5, k + 2, Blocks.sandstone);
		world.setBlock(i + 6, j + 5, k + 3, Blocks.dirt);
		world.setBlock(i + 6, j + 5, k + 4, Blocks.dirt);
		world.setBlock(i + 6, j + 5, k + 5, Blocks.dirt);
		world.setBlock(i + 6, j + 5, k + 6, Blocks.dirt);
		world.setBlock(i + 6, j + 5, k + 7, Blocks.dirt);
		world.setBlock(i + 6, j + 5, k + 8, Blocks.dirt);
		world.setBlock(i + 6, j + 5, k + 9, Blocks.dirt);
		world.setBlock(i + 6, j + 5, k + 10, Blocks.grass);
		world.setBlock(i + 6, j + 5, k + 11, Blocks.grass);
		world.setBlock(i + 6, j + 5, k + 12, Blocks.grass);
		world.setBlock(i + 6, j + 5, k + 13, Blocks.grass);
		world.setBlock(i + 6, j + 5, k + 14, Blocks.grass);
		world.setBlock(i + 6, j + 5, k + 15, Blocks.grass);
		world.setBlock(i + 6, j + 5, k + 16, Blocks.grass);
		world.setBlock(i + 6, j + 5, k + 17, Blocks.sandstone);
		world.setBlock(i + 6, j + 5, k + 18, Blocks.sandstone);
		world.setBlock(i + 6, j + 5, k + 19, Blocks.sandstone);
		world.setBlock(i + 6, j + 6, k + 3, Blocks.sandstone_stairs, 2, 0x02);
		world.setBlock(i + 6, j + 6, k + 4, Blocks.planks, 1, 0x02);
		world.setBlock(i + 6, j + 6, k + 5, Blocks.planks, 1, 0x02);
		world.setBlock(i + 6, j + 6, k + 6, Blocks.planks, 1, 0x02);
		world.setBlock(i + 6, j + 6, k + 7, Blocks.planks, 1, 0x02);
		world.setBlock(i + 6, j + 6, k + 8, Blocks.planks, 1, 0x02);
		world.setBlock(i + 6, j + 6, k + 9, Blocks.sandstone_stairs, 3, 0x02);
		world.setBlock(i + 6, j + 6, k + 11, Blocks.cobblestone_wall);
		world.setBlock(i + 6, j + 6, k + 13, Blocks.fence);
		world.setBlock(i + 6, j + 6, k + 15, Blocks.fence);
		world.setBlock(i + 6, j + 6, k + 17, Blocks.cobblestone_wall);
		world.setBlock(i + 6, j + 7, k + 4, Blocks.cobblestone);
		world.setBlock(i + 6, j + 7, k + 8, Blocks.cobblestone);
		world.setBlock(i + 6, j + 7, k + 13, Blocks.fence);
		world.setBlock(i + 6, j + 7, k + 15, Blocks.fence);
		world.setBlock(i + 6, j + 8, k + 4, Blocks.cobblestone);
		world.setBlock(i + 6, j + 8, k + 8, Blocks.cobblestone);
		world.setBlock(i + 6, j + 8, k + 13, Blocks.fence);
		world.setBlock(i + 6, j + 9, k + 4, Blocks.cobblestone);
		world.setBlock(i + 6, j + 9, k + 8, Blocks.cobblestone);
		world.setBlock(i + 6, j + 10, k + 4, Blocks.cobblestone);
		world.setBlock(i + 6, j + 10, k + 8, Blocks.cobblestone);
		world.setBlock(i + 6, j + 11, k + 2, Blocks.wooden_slab, 1, 0x02);
		world.setBlock(i + 6, j + 11, k + 3, Blocks.spruce_stairs, 2, 0x02);
		world.setBlock(i + 6, j + 11, k + 4, Blocks.log, 9, 0x02);
		world.setBlock(i + 6, j + 11, k + 5, Blocks.planks, 1, 0x02);
		world.setBlock(i + 6, j + 11, k + 6, Blocks.planks, 1, 0x02);
		world.setBlock(i + 6, j + 11, k + 7, Blocks.planks, 1, 0x02);
		world.setBlock(i + 6, j + 11, k + 8, Blocks.log, 9, 0x02);
		world.setBlock(i + 6, j + 11, k + 9, Blocks.spruce_stairs, 3, 0x02);
		world.setBlock(i + 6, j + 11, k + 10, Blocks.wooden_slab, 1, 0x02);
		world.setBlock(i + 6, j + 12, k + 4, Blocks.fence);
		world.setBlock(i + 6, j + 12, k + 8, Blocks.fence);
		world.setBlock(i + 6, j + 14, k + 4, Blocks.fence);
		world.setBlock(i + 6, j + 14, k + 8, Blocks.fence);
		world.setBlock(i + 6, j + 15, k + 4, Blocks.fence);
		world.setBlock(i + 6, j + 15, k + 8, Blocks.fence);
		world.setBlock(i + 6, j + 16, k + 4, Blocks.birch_stairs, 2, 0x02);
		world.setBlock(i + 6, j + 16, k + 8, Blocks.birch_stairs, 3, 0x02);
		world.setBlock(i + 6, j + 17, k + 5, Blocks.birch_stairs, 1, 0x02);
		world.setBlock(i + 6, j + 17, k + 6, Blocks.birch_stairs, 1, 0x02);
		world.setBlock(i + 6, j + 17, k + 7, Blocks.birch_stairs, 3, 0x02);
		world.setBlock(i + 7, j + 0, k + 6, Blocks.sandstone);
		world.setBlock(i + 7, j + 0, k + 7, Blocks.sandstone);
		world.setBlock(i + 7, j + 0, k + 8, Blocks.sandstone);
		world.setBlock(i + 7, j + 0, k + 9, Blocks.sandstone);
		world.setBlock(i + 7, j + 0, k + 10, Blocks.sandstone);
		world.setBlock(i + 7, j + 0, k + 11, Blocks.sandstone);
		world.setBlock(i + 7, j + 0, k + 12, Blocks.sandstone);
		world.setBlock(i + 7, j + 0, k + 13, Blocks.sandstone);
		world.setBlock(i + 7, j + 0, k + 16, Blocks.sandstone);
		world.setBlock(i + 7, j + 1, k + 4, Blocks.sandstone);
		world.setBlock(i + 7, j + 1, k + 5, Blocks.sandstone);
		world.setBlock(i + 7, j + 1, k + 6, Blocks.sandstone);
		world.setBlock(i + 7, j + 1, k + 7, Blocks.sandstone);
		world.setBlock(i + 7, j + 1, k + 8, Blocks.sandstone);
		world.setBlock(i + 7, j + 1, k + 9, Blocks.sandstone);
		world.setBlock(i + 7, j + 1, k + 10, Blocks.sandstone);
		world.setBlock(i + 7, j + 1, k + 11, Blocks.sandstone);
		world.setBlock(i + 7, j + 1, k + 12, Blocks.sandstone);
		world.setBlock(i + 7, j + 1, k + 13, Blocks.sandstone);
		world.setBlock(i + 7, j + 1, k + 14, Blocks.sandstone);
		world.setBlock(i + 7, j + 1, k + 15, Blocks.sandstone);
		world.setBlock(i + 7, j + 1, k + 16, Blocks.sandstone);
		world.setBlock(i + 7, j + 2, k + 3, Blocks.sandstone);
		world.setBlock(i + 7, j + 2, k + 4, Blocks.sandstone);
		world.setBlock(i + 7, j + 2, k + 5, Blocks.sandstone);
		world.setBlock(i + 7, j + 2, k + 6, Blocks.sandstone);
		world.setBlock(i + 7, j + 2, k + 7, Blocks.sandstone);
		world.setBlock(i + 7, j + 2, k + 8, Blocks.sandstone);
		world.setBlock(i + 7, j + 2, k + 9, Blocks.sandstone);
		world.setBlock(i + 7, j + 2, k + 10, Blocks.sandstone);
		world.setBlock(i + 7, j + 2, k + 11, Blocks.sandstone);
		world.setBlock(i + 7, j + 2, k + 12, Blocks.sandstone);
		world.setBlock(i + 7, j + 2, k + 13, Blocks.sandstone);
		world.setBlock(i + 7, j + 2, k + 14, Blocks.sandstone);
		world.setBlock(i + 7, j + 2, k + 15, Blocks.sandstone);
		world.setBlock(i + 7, j + 2, k + 16, Blocks.sandstone);
		world.setBlock(i + 7, j + 3, k + 2, Blocks.sandstone);
		world.setBlock(i + 7, j + 3, k + 3, Blocks.sandstone);
		world.setBlock(i + 7, j + 3, k + 4, Blocks.sandstone);
		world.setBlock(i + 7, j + 3, k + 5, Blocks.sandstone);
		world.setBlock(i + 7, j + 3, k + 6, Blocks.sandstone);
		world.setBlock(i + 7, j + 3, k + 7, Blocks.sandstone);
		world.setBlock(i + 7, j + 3, k + 8, Blocks.sandstone);
		world.setBlock(i + 7, j + 3, k + 9, Blocks.sandstone);
		world.setBlock(i + 7, j + 3, k + 10, Blocks.sandstone);
		world.setBlock(i + 7, j + 3, k + 11, Blocks.sandstone);
		world.setBlock(i + 7, j + 3, k + 12, Blocks.sandstone);
		world.setBlock(i + 7, j + 3, k + 13, Blocks.sandstone);
		world.setBlock(i + 7, j + 3, k + 14, Blocks.sandstone);
		world.setBlock(i + 7, j + 3, k + 15, Blocks.sandstone);
		world.setBlock(i + 7, j + 3, k + 16, Blocks.sandstone);
		world.setBlock(i + 7, j + 3, k + 17, Blocks.sandstone);
		world.setBlock(i + 7, j + 4, k + 2, Blocks.sandstone);
		world.setBlock(i + 7, j + 4, k + 3, Blocks.sandstone);
		world.setBlock(i + 7, j + 4, k + 4, Blocks.sandstone);
		world.setBlock(i + 7, j + 4, k + 5, Blocks.sandstone);
		world.setBlock(i + 7, j + 4, k + 6, Blocks.sandstone);
		world.setBlock(i + 7, j + 4, k + 7, Blocks.sandstone);
		world.setBlock(i + 7, j + 4, k + 8, Blocks.sandstone);
		world.setBlock(i + 7, j + 4, k + 9, Blocks.sandstone);
		world.setBlock(i + 7, j + 4, k + 10, Blocks.sandstone);
		world.setBlock(i + 7, j + 4, k + 11, Blocks.sandstone);
		world.setBlock(i + 7, j + 4, k + 12, Blocks.sandstone);
		world.setBlock(i + 7, j + 4, k + 13, Blocks.sandstone);
		world.setBlock(i + 7, j + 4, k + 14, Blocks.sandstone);
		world.setBlock(i + 7, j + 4, k + 15, Blocks.sandstone);
		world.setBlock(i + 7, j + 4, k + 16, Blocks.sandstone);
		world.setBlock(i + 7, j + 4, k + 17, Blocks.sandstone);
		world.setBlock(i + 7, j + 5, k + 0, Blocks.sandstone);
		world.setBlock(i + 7, j + 5, k + 1, Blocks.sandstone);
		world.setBlock(i + 7, j + 5, k + 2, Blocks.sandstone);
		world.setBlock(i + 7, j + 5, k + 3, Blocks.dirt);
		world.setBlock(i + 7, j + 5, k + 4, Blocks.dirt);
		world.setBlock(i + 7, j + 5, k + 5, Blocks.dirt);
		world.setBlock(i + 7, j + 5, k + 6, Blocks.dirt);
		world.setBlock(i + 7, j + 5, k + 7, Blocks.dirt);
		world.setBlock(i + 7, j + 5, k + 8, Blocks.dirt);
		world.setBlock(i + 7, j + 5, k + 9, Blocks.dirt);
		world.setBlock(i + 7, j + 5, k + 10, Blocks.grass);
		world.setBlock(i + 7, j + 5, k + 11, Blocks.grass);
		world.setBlock(i + 7, j + 5, k + 12, Blocks.grass);
		world.setBlock(i + 7, j + 5, k + 13, Blocks.grass);
		world.setBlock(i + 7, j + 5, k + 14, Blocks.grass);
		world.setBlock(i + 7, j + 5, k + 15, Blocks.grass);
		world.setBlock(i + 7, j + 5, k + 16, Blocks.grass);
		world.setBlock(i + 7, j + 5, k + 17, Blocks.sandstone);
		world.setBlock(i + 7, j + 5, k + 18, Blocks.sandstone);
		world.setBlock(i + 7, j + 5, k + 19, Blocks.sandstone);
		world.setBlock(i + 7, j + 6, k + 3, Blocks.sandstone_stairs, 2, 0x02);
		world.setBlock(i + 7, j + 6, k + 4, Blocks.planks, 1, 0x02);
		world.setBlock(i + 7, j + 6, k + 5, Blocks.planks, 1, 0x02);
		world.setBlock(i + 7, j + 6, k + 6, Blocks.planks, 1, 0x02);
		world.setBlock(i + 7, j + 6, k + 7, Blocks.planks, 1, 0x02);
		world.setBlock(i + 7, j + 6, k + 8, Blocks.planks, 1, 0x02);
		world.setBlock(i + 7, j + 6, k + 9, Blocks.sandstone_stairs, 3, 0x02);
		world.setBlock(i + 7, j + 6, k + 11, Blocks.cobblestone_wall);
		world.setBlock(i + 7, j + 6, k + 14, Blocks.fence);
		world.setBlock(i + 7, j + 6, k + 16, Blocks.fence);
		world.setBlock(i + 7, j + 6, k + 17, Blocks.cobblestone_wall);
		world.setBlock(i + 7, j + 7, k + 4, Blocks.log, 1, 0x02);
		world.setBlock(i + 7, j + 7, k + 8, Blocks.log, 1, 0x02);
		world.setBlock(i + 7, j + 7, k + 14, Blocks.fence);
		world.setBlock(i + 7, j + 7, k + 16, Blocks.fence);
		world.setBlock(i + 7, j + 8, k + 4, Blocks.log, 1, 0x02);
		world.setBlock(i + 7, j + 8, k + 8, Blocks.log, 1, 0x02);
		world.setBlock(i + 7, j + 8, k + 16, Blocks.fence);
		world.setBlock(i + 7, j + 9, k + 4, Blocks.log, 1, 0x02);
		world.setBlock(i + 7, j + 9, k + 5, Blocks.stone_stairs, 7, 0x02);
		world.setBlock(i + 7, j + 9, k + 7, Blocks.stone_stairs, 6, 0x02);
		world.setBlock(i + 7, j + 9, k + 8, Blocks.log, 1, 0x02);
		world.setBlock(i + 7, j + 10, k + 4, Blocks.log, 1, 0x02);
		world.setBlock(i + 7, j + 10, k + 5, Blocks.stone_stairs, 5, 0x02);
		world.setBlock(i + 7, j + 10, k + 6, Blocks.cobblestone);
		world.setBlock(i + 7, j + 10, k + 7, Blocks.stone_stairs, 5, 0x02);
		world.setBlock(i + 7, j + 10, k + 8, Blocks.log, 1, 0x02);
		world.setBlock(i + 7, j + 11, k + 2, Blocks.wooden_slab, 1, 0x02);
		world.setBlock(i + 7, j + 11, k + 3, Blocks.spruce_stairs, 2, 0x02);
		world.setBlock(i + 7, j + 11, k + 4, Blocks.log, 1, 0x02);
		world.setBlock(i + 7, j + 11, k + 5, Blocks.log, 5, 0x02);
		world.setBlock(i + 7, j + 11, k + 6, Blocks.log, 5, 0x02);
		world.setBlock(i + 7, j + 11, k + 7, Blocks.log, 5, 0x02);
		world.setBlock(i + 7, j + 11, k + 8, Blocks.log, 1, 0x02);
		world.setBlock(i + 7, j + 11, k + 9, Blocks.spruce_stairs, 3, 0x02);
		world.setBlock(i + 7, j + 11, k + 10, Blocks.wooden_slab, 1, 0x02);
		world.setBlock(i + 7, j + 12, k + 4, Blocks.fence);
		world.setBlock(i + 7, j + 12, k + 8, Blocks.fence);
		world.setBlock(i + 7, j + 13, k + 4, Blocks.fence);
		world.setBlock(i + 7, j + 13, k + 8, Blocks.fence);
		world.setBlock(i + 7, j + 14, k + 4, Blocks.fence);
		world.setBlock(i + 7, j + 14, k + 5, Blocks.fence);
		world.setBlock(i + 7, j + 14, k + 7, Blocks.fence);
		world.setBlock(i + 7, j + 14, k + 8, Blocks.fence);
		world.setBlock(i + 7, j + 15, k + 4, Blocks.fence);
		world.setBlock(i + 7, j + 15, k + 5, Blocks.fence);
		world.setBlock(i + 7, j + 15, k + 6, Blocks.fence);
		world.setBlock(i + 7, j + 15, k + 7, Blocks.fence);
		world.setBlock(i + 7, j + 15, k + 8, Blocks.fence);
		world.setBlock(i + 7, j + 16, k + 4, Blocks.birch_stairs, 1, 0x02);
		world.setBlock(i + 7, j + 16, k + 5, Blocks.birch_stairs, 1, 0x02);
		world.setBlock(i + 7, j + 16, k + 6, Blocks.birch_stairs, 1, 0x02);
		world.setBlock(i + 7, j + 16, k + 7, Blocks.birch_stairs, 1, 0x02);
		world.setBlock(i + 7, j + 16, k + 8, Blocks.birch_stairs, 1, 0x02);
		world.setBlock(i + 8, j + 0, k + 5, Blocks.sandstone);
		world.setBlock(i + 8, j + 0, k + 6, Blocks.sandstone);
		world.setBlock(i + 8, j + 0, k + 7, Blocks.sandstone);
		world.setBlock(i + 8, j + 0, k + 8, Blocks.sandstone);
		world.setBlock(i + 8, j + 0, k + 9, Blocks.sandstone);
		world.setBlock(i + 8, j + 0, k + 10, Blocks.sandstone);
		world.setBlock(i + 8, j + 0, k + 11, Blocks.sandstone);
		world.setBlock(i + 8, j + 0, k + 12, Blocks.sandstone);
		world.setBlock(i + 8, j + 0, k + 13, Blocks.sandstone);
		world.setBlock(i + 8, j + 0, k + 14, Blocks.sandstone);
		world.setBlock(i + 8, j + 1, k + 4, Blocks.sandstone);
		world.setBlock(i + 8, j + 1, k + 5, Blocks.sandstone);
		world.setBlock(i + 8, j + 1, k + 6, Blocks.sandstone);
		world.setBlock(i + 8, j + 1, k + 7, Blocks.sandstone);
		world.setBlock(i + 8, j + 1, k + 8, Blocks.sandstone);
		world.setBlock(i + 8, j + 1, k + 9, Blocks.sandstone);
		world.setBlock(i + 8, j + 1, k + 10, Blocks.sandstone);
		world.setBlock(i + 8, j + 1, k + 11, Blocks.sandstone);
		world.setBlock(i + 8, j + 1, k + 12, Blocks.sandstone);
		world.setBlock(i + 8, j + 1, k + 13, Blocks.sandstone);
		world.setBlock(i + 8, j + 1, k + 14, Blocks.sandstone);
		world.setBlock(i + 8, j + 1, k + 15, Blocks.sandstone);
		world.setBlock(i + 8, j + 2, k + 3, Blocks.sandstone);
		world.setBlock(i + 8, j + 2, k + 4, Blocks.sandstone);
		world.setBlock(i + 8, j + 2, k + 5, Blocks.sandstone);
		world.setBlock(i + 8, j + 2, k + 6, Blocks.sandstone);
		world.setBlock(i + 8, j + 2, k + 7, Blocks.sandstone);
		world.setBlock(i + 8, j + 2, k + 8, Blocks.sandstone);
		world.setBlock(i + 8, j + 2, k + 9, Blocks.sandstone);
		world.setBlock(i + 8, j + 2, k + 10, Blocks.sandstone);
		world.setBlock(i + 8, j + 2, k + 11, Blocks.sandstone);
		world.setBlock(i + 8, j + 2, k + 12, Blocks.sandstone);
		world.setBlock(i + 8, j + 2, k + 13, Blocks.sandstone);
		world.setBlock(i + 8, j + 2, k + 14, Blocks.sandstone);
		world.setBlock(i + 8, j + 2, k + 15, Blocks.sandstone);
		world.setBlock(i + 8, j + 2, k + 16, Blocks.sandstone);
		world.setBlock(i + 8, j + 3, k + 2, Blocks.sandstone);
		world.setBlock(i + 8, j + 3, k + 3, Blocks.sandstone);
		world.setBlock(i + 8, j + 3, k + 4, Blocks.sandstone);
		world.setBlock(i + 8, j + 3, k + 5, Blocks.sandstone);
		world.setBlock(i + 8, j + 3, k + 6, Blocks.sandstone);
		world.setBlock(i + 8, j + 3, k + 7, Blocks.sandstone);
		world.setBlock(i + 8, j + 3, k + 8, Blocks.sandstone);
		world.setBlock(i + 8, j + 3, k + 9, Blocks.sandstone);
		world.setBlock(i + 8, j + 3, k + 10, Blocks.sandstone);
		world.setBlock(i + 8, j + 3, k + 11, Blocks.sandstone);
		world.setBlock(i + 8, j + 3, k + 12, Blocks.sandstone);
		world.setBlock(i + 8, j + 3, k + 13, Blocks.sandstone);
		world.setBlock(i + 8, j + 3, k + 14, Blocks.sandstone);
		world.setBlock(i + 8, j + 3, k + 15, Blocks.sandstone);
		world.setBlock(i + 8, j + 3, k + 16, Blocks.sandstone);
		world.setBlock(i + 8, j + 3, k + 17, Blocks.sandstone);
		world.setBlock(i + 8, j + 4, k + 1, Blocks.sandstone);
		world.setBlock(i + 8, j + 4, k + 2, Blocks.sandstone);
		world.setBlock(i + 8, j + 4, k + 3, Blocks.sandstone);
		world.setBlock(i + 8, j + 4, k + 4, Blocks.sandstone);
		world.setBlock(i + 8, j + 4, k + 5, Blocks.sandstone);
		world.setBlock(i + 8, j + 4, k + 6, Blocks.sandstone);
		world.setBlock(i + 8, j + 4, k + 7, Blocks.sandstone);
		world.setBlock(i + 8, j + 4, k + 8, Blocks.sandstone);
		world.setBlock(i + 8, j + 4, k + 9, Blocks.sandstone);
		world.setBlock(i + 8, j + 4, k + 10, Blocks.sandstone);
		world.setBlock(i + 8, j + 4, k + 11, Blocks.sandstone);
		world.setBlock(i + 8, j + 4, k + 12, Blocks.sandstone);
		world.setBlock(i + 8, j + 4, k + 13, Blocks.sandstone);
		world.setBlock(i + 8, j + 4, k + 14, Blocks.sandstone);
		world.setBlock(i + 8, j + 4, k + 15, Blocks.sandstone);
		world.setBlock(i + 8, j + 4, k + 16, Blocks.sandstone);
		world.setBlock(i + 8, j + 4, k + 17, Blocks.sandstone);
		world.setBlock(i + 8, j + 4, k + 18, Blocks.sandstone);
		world.setBlock(i + 8, j + 5, k + 0, Blocks.sandstone);
		world.setBlock(i + 8, j + 5, k + 1, Blocks.sandstone);
		world.setBlock(i + 8, j + 5, k + 2, Blocks.sandstone);
		world.setBlock(i + 8, j + 5, k + 3, Blocks.dirt);
		world.setBlock(i + 8, j + 5, k + 4, Blocks.dirt);
		world.setBlock(i + 8, j + 5, k + 5, Blocks.dirt);
		world.setBlock(i + 8, j + 5, k + 6, Blocks.dirt);
		world.setBlock(i + 8, j + 5, k + 7, Blocks.dirt);
		world.setBlock(i + 8, j + 5, k + 8, Blocks.dirt);
		world.setBlock(i + 8, j + 5, k + 9, Blocks.dirt);
		world.setBlock(i + 8, j + 5, k + 10, Blocks.grass);
		world.setBlock(i + 8, j + 5, k + 11, Blocks.grass);
		world.setBlock(i + 8, j + 5, k + 12, Blocks.grass);
		world.setBlock(i + 8, j + 5, k + 13, Blocks.grass);
		world.setBlock(i + 8, j + 5, k + 14, Blocks.grass);
		world.setBlock(i + 8, j + 5, k + 15, Blocks.grass);
		world.setBlock(i + 8, j + 5, k + 16, Blocks.grass);
		world.setBlock(i + 8, j + 5, k + 17, Blocks.sandstone);
		world.setBlock(i + 8, j + 5, k + 18, Blocks.sandstone);
		world.setBlock(i + 8, j + 5, k + 19, Blocks.sandstone);
		world.setBlock(i + 8, j + 6, k + 3, Blocks.sandstone_stairs, 1, 0x02);
		world.setBlock(i + 8, j + 6, k + 4, Blocks.sandstone_stairs, 1, 0x02);
		world.setBlock(i + 8, j + 6, k + 5, Blocks.sandstone_stairs, 1, 0x02);
		world.setBlock(i + 8, j + 6, k + 6, Blocks.sandstone_stairs, 1, 0x02);
		world.setBlock(i + 8, j + 6, k + 7, Blocks.sandstone_stairs, 1, 0x02);
		world.setBlock(i + 8, j + 6, k + 8, Blocks.sandstone_stairs, 1, 0x02);
		world.setBlock(i + 8, j + 6, k + 9, Blocks.sandstone_stairs, 1, 0x02);
		world.setBlock(i + 8, j + 6, k + 11, Blocks.cobblestone_wall);
		world.setBlock(i + 8, j + 6, k + 12, Blocks.fence);
		world.setBlock(i + 8, j + 6, k + 15, Blocks.fence);
		world.setBlock(i + 8, j + 6, k + 17, Blocks.cobblestone_wall);
		world.setBlock(i + 8, j + 7, k + 12, Blocks.fence);
		world.setBlock(i + 8, j + 8, k + 12, Blocks.fence);
		world.setBlock(i + 8, j + 9, k + 12, Blocks.fence);
		world.setBlock(i + 8, j + 11, k + 2, Blocks.wooden_slab, 1, 0x02);
		world.setBlock(i + 8, j + 11, k + 3, Blocks.spruce_stairs, 2, 0x02);
		world.setBlock(i + 8, j + 11, k + 4, Blocks.spruce_stairs, 1, 0x02);
		world.setBlock(i + 8, j + 11, k + 5, Blocks.fence);
		world.setBlock(i + 8, j + 11, k + 6, Blocks.wooden_slab, 9, 0x02);
		world.setBlock(i + 8, j + 11, k + 7, Blocks.fence);
		world.setBlock(i + 8, j + 11, k + 8, Blocks.spruce_stairs, 1, 0x02);
		world.setBlock(i + 8, j + 11, k + 9, Blocks.spruce_stairs, 1, 0x02);
		world.setBlock(i + 8, j + 11, k + 10, Blocks.wooden_slab, 1, 0x02);
		world.setBlock(i + 8, j + 12, k + 5, Blocks.fence);
		world.setBlock(i + 8, j + 12, k + 7, Blocks.fence);
		world.setBlock(i + 9, j + 0, k + 3, Blocks.sandstone);
		world.setBlock(i + 9, j + 0, k + 5, Blocks.sandstone);
		world.setBlock(i + 9, j + 0, k + 6, Blocks.sandstone);
		world.setBlock(i + 9, j + 0, k + 7, Blocks.sandstone);
		world.setBlock(i + 9, j + 0, k + 8, Blocks.sandstone);
		world.setBlock(i + 9, j + 0, k + 9, Blocks.sandstone);
		world.setBlock(i + 9, j + 0, k + 10, Blocks.sandstone);
		world.setBlock(i + 9, j + 0, k + 11, Blocks.sandstone);
		world.setBlock(i + 9, j + 0, k + 12, Blocks.sandstone);
		world.setBlock(i + 9, j + 0, k + 13, Blocks.sandstone);
		world.setBlock(i + 9, j + 0, k + 14, Blocks.sandstone);
		world.setBlock(i + 9, j + 1, k + 3, Blocks.sandstone);
		world.setBlock(i + 9, j + 1, k + 4, Blocks.sandstone);
		world.setBlock(i + 9, j + 1, k + 5, Blocks.sandstone);
		world.setBlock(i + 9, j + 1, k + 6, Blocks.sandstone);
		world.setBlock(i + 9, j + 1, k + 7, Blocks.sandstone);
		world.setBlock(i + 9, j + 1, k + 8, Blocks.sandstone);
		world.setBlock(i + 9, j + 1, k + 9, Blocks.sandstone);
		world.setBlock(i + 9, j + 1, k + 10, Blocks.sandstone);
		world.setBlock(i + 9, j + 1, k + 11, Blocks.sandstone);
		world.setBlock(i + 9, j + 1, k + 12, Blocks.sandstone);
		world.setBlock(i + 9, j + 1, k + 13, Blocks.sandstone);
		world.setBlock(i + 9, j + 1, k + 14, Blocks.sandstone);
		world.setBlock(i + 9, j + 1, k + 15, Blocks.sandstone);
		world.setBlock(i + 9, j + 2, k + 2, Blocks.sandstone);
		world.setBlock(i + 9, j + 2, k + 3, Blocks.sandstone);
		world.setBlock(i + 9, j + 2, k + 4, Blocks.sandstone);
		world.setBlock(i + 9, j + 2, k + 5, Blocks.sandstone);
		world.setBlock(i + 9, j + 2, k + 6, Blocks.sandstone);
		world.setBlock(i + 9, j + 2, k + 7, Blocks.sandstone);
		world.setBlock(i + 9, j + 2, k + 8, Blocks.sandstone);
		world.setBlock(i + 9, j + 2, k + 9, Blocks.sandstone);
		world.setBlock(i + 9, j + 2, k + 10, Blocks.sandstone);
		world.setBlock(i + 9, j + 2, k + 11, Blocks.sandstone);
		world.setBlock(i + 9, j + 2, k + 12, Blocks.sandstone);
		world.setBlock(i + 9, j + 2, k + 13, Blocks.sandstone);
		world.setBlock(i + 9, j + 2, k + 14, Blocks.sandstone);
		world.setBlock(i + 9, j + 2, k + 15, Blocks.sandstone);
		world.setBlock(i + 9, j + 2, k + 16, Blocks.sandstone);
		world.setBlock(i + 9, j + 2, k + 17, Blocks.sandstone);
		world.setBlock(i + 9, j + 3, k + 1, Blocks.sandstone);
		world.setBlock(i + 9, j + 3, k + 2, Blocks.sandstone);
		world.setBlock(i + 9, j + 3, k + 3, Blocks.sandstone);
		world.setBlock(i + 9, j + 3, k + 4, Blocks.sandstone);
		world.setBlock(i + 9, j + 3, k + 5, Blocks.sandstone);
		world.setBlock(i + 9, j + 3, k + 6, Blocks.sandstone);
		world.setBlock(i + 9, j + 3, k + 7, Blocks.sandstone);
		world.setBlock(i + 9, j + 3, k + 8, Blocks.sandstone);
		world.setBlock(i + 9, j + 3, k + 9, Blocks.sandstone);
		world.setBlock(i + 9, j + 3, k + 10, Blocks.sandstone);
		world.setBlock(i + 9, j + 3, k + 11, Blocks.sandstone);
		world.setBlock(i + 9, j + 3, k + 12, Blocks.sandstone);
		world.setBlock(i + 9, j + 3, k + 13, Blocks.sandstone);
		world.setBlock(i + 9, j + 3, k + 14, Blocks.sandstone);
		world.setBlock(i + 9, j + 3, k + 15, Blocks.sandstone);
		world.setBlock(i + 9, j + 3, k + 16, Blocks.sandstone);
		world.setBlock(i + 9, j + 3, k + 17, Blocks.sandstone);
		world.setBlock(i + 9, j + 3, k + 18, Blocks.sandstone);
		world.setBlock(i + 9, j + 4, k + 0, Blocks.sandstone);
		world.setBlock(i + 9, j + 4, k + 1, Blocks.sandstone);
		world.setBlock(i + 9, j + 4, k + 2, Blocks.sandstone);
		world.setBlock(i + 9, j + 4, k + 3, Blocks.sandstone);
		world.setBlock(i + 9, j + 4, k + 4, Blocks.sandstone);
		world.setBlock(i + 9, j + 4, k + 5, Blocks.sandstone);
		world.setBlock(i + 9, j + 4, k + 6, Blocks.sandstone);
		world.setBlock(i + 9, j + 4, k + 7, Blocks.sandstone);
		world.setBlock(i + 9, j + 4, k + 8, Blocks.sandstone);
		world.setBlock(i + 9, j + 4, k + 9, Blocks.sandstone);
		world.setBlock(i + 9, j + 4, k + 10, Blocks.sandstone);
		world.setBlock(i + 9, j + 4, k + 11, Blocks.sandstone);
		world.setBlock(i + 9, j + 4, k + 12, Blocks.sandstone);
		world.setBlock(i + 9, j + 4, k + 13, Blocks.sandstone);
		world.setBlock(i + 9, j + 4, k + 14, Blocks.sandstone);
		world.setBlock(i + 9, j + 4, k + 15, Blocks.sandstone);
		world.setBlock(i + 9, j + 4, k + 16, Blocks.sandstone);
		world.setBlock(i + 9, j + 4, k + 17, Blocks.sandstone);
		world.setBlock(i + 9, j + 4, k + 18, Blocks.sandstone);
		world.setBlock(i + 9, j + 4, k + 19, Blocks.sandstone);
		world.setBlock(i + 9, j + 5, k + 0, Blocks.sandstone);
		world.setBlock(i + 9, j + 5, k + 1, Blocks.sandstone);
		world.setBlock(i + 9, j + 5, k + 10, Blocks.sandstone);
		world.setBlock(i + 9, j + 5, k + 18, Blocks.sandstone);
		world.setBlock(i + 9, j + 5, k + 19, Blocks.sandstone);
		world.setBlock(i + 9, j + 11, k + 2, Blocks.wooden_slab, 1, 0x02);
		world.setBlock(i + 9, j + 11, k + 3, Blocks.wooden_slab, 1, 0x02);
		world.setBlock(i + 9, j + 11, k + 4, Blocks.wooden_slab, 1, 0x02);
		world.setBlock(i + 9, j + 11, k + 5, Blocks.fence);
		world.setBlock(i + 9, j + 11, k + 6, Blocks.wooden_slab, 1, 0x02);
		world.setBlock(i + 9, j + 11, k + 7, Blocks.fence);
		world.setBlock(i + 9, j + 11, k + 8, Blocks.wooden_slab, 1, 0x02);
		world.setBlock(i + 9, j + 11, k + 9, Blocks.wooden_slab, 1, 0x02);
		world.setBlock(i + 9, j + 11, k + 10, Blocks.wooden_slab, 1, 0x02);
		world.setBlock(i + 9, j + 12, k + 5, Blocks.fence);
		world.setBlock(i + 9, j + 12, k + 7, Blocks.fence);
		world.setBlock(i + 10, j + 0, k + 5, Blocks.sandstone);
		world.setBlock(i + 10, j + 0, k + 6, Blocks.sandstone);
		world.setBlock(i + 10, j + 0, k + 7, Blocks.sandstone);
		world.setBlock(i + 10, j + 0, k + 8, Blocks.sandstone);
		world.setBlock(i + 10, j + 0, k + 9, Blocks.sandstone);
		world.setBlock(i + 10, j + 0, k + 10, Blocks.sandstone);
		world.setBlock(i + 10, j + 0, k + 11, Blocks.sandstone);
		world.setBlock(i + 10, j + 0, k + 12, Blocks.sandstone);
		world.setBlock(i + 10, j + 0, k + 13, Blocks.sandstone);
		world.setBlock(i + 10, j + 0, k + 14, Blocks.sandstone);
		world.setBlock(i + 10, j + 1, k + 3, Blocks.sandstone);
		world.setBlock(i + 10, j + 1, k + 4, Blocks.sandstone);
		world.setBlock(i + 10, j + 1, k + 5, Blocks.sandstone);
		world.setBlock(i + 10, j + 1, k + 6, Blocks.sandstone);
		world.setBlock(i + 10, j + 1, k + 7, Blocks.sandstone);
		world.setBlock(i + 10, j + 1, k + 8, Blocks.sandstone);
		world.setBlock(i + 10, j + 1, k + 9, Blocks.sandstone);
		world.setBlock(i + 10, j + 1, k + 10, Blocks.sandstone);
		world.setBlock(i + 10, j + 1, k + 11, Blocks.sandstone);
		world.setBlock(i + 10, j + 1, k + 12, Blocks.sandstone);
		world.setBlock(i + 10, j + 1, k + 13, Blocks.sandstone);
		world.setBlock(i + 10, j + 1, k + 14, Blocks.sandstone);
		world.setBlock(i + 10, j + 1, k + 15, Blocks.sandstone);
		world.setBlock(i + 10, j + 1, k + 16, Blocks.sandstone);
		world.setBlock(i + 10, j + 2, k + 2, Blocks.sandstone);
		world.setBlock(i + 10, j + 2, k + 3, Blocks.sandstone);
		world.setBlock(i + 10, j + 2, k + 4, Blocks.sandstone);
		world.setBlock(i + 10, j + 2, k + 5, Blocks.sandstone);
		world.setBlock(i + 10, j + 2, k + 6, Blocks.sandstone);
		world.setBlock(i + 10, j + 2, k + 7, Blocks.sandstone);
		world.setBlock(i + 10, j + 2, k + 8, Blocks.sandstone);
		world.setBlock(i + 10, j + 2, k + 9, Blocks.sandstone);
		world.setBlock(i + 10, j + 2, k + 10, Blocks.sandstone);
		world.setBlock(i + 10, j + 2, k + 11, Blocks.sandstone);
		world.setBlock(i + 10, j + 2, k + 12, Blocks.sandstone);
		world.setBlock(i + 10, j + 2, k + 13, Blocks.sandstone);
		world.setBlock(i + 10, j + 2, k + 14, Blocks.sandstone);
		world.setBlock(i + 10, j + 2, k + 15, Blocks.sandstone);
		world.setBlock(i + 10, j + 2, k + 16, Blocks.sandstone);
		world.setBlock(i + 10, j + 2, k + 17, Blocks.sandstone);
		world.setBlock(i + 10, j + 3, k + 1, Blocks.sandstone);
		world.setBlock(i + 10, j + 3, k + 2, Blocks.sandstone);
		world.setBlock(i + 10, j + 3, k + 3, Blocks.sandstone);
		world.setBlock(i + 10, j + 3, k + 4, Blocks.sandstone);
		world.setBlock(i + 10, j + 3, k + 5, Blocks.sandstone);
		world.setBlock(i + 10, j + 3, k + 6, Blocks.sandstone);
		world.setBlock(i + 10, j + 3, k + 7, Blocks.sandstone);
		world.setBlock(i + 10, j + 3, k + 8, Blocks.sandstone);
		world.setBlock(i + 10, j + 3, k + 9, Blocks.sandstone);
		world.setBlock(i + 10, j + 3, k + 10, Blocks.sandstone);
		world.setBlock(i + 10, j + 3, k + 11, Blocks.sandstone);
		world.setBlock(i + 10, j + 3, k + 12, Blocks.sandstone);
		world.setBlock(i + 10, j + 3, k + 13, Blocks.sandstone);
		world.setBlock(i + 10, j + 3, k + 14, Blocks.sandstone);
		world.setBlock(i + 10, j + 3, k + 15, Blocks.sandstone);
		world.setBlock(i + 10, j + 3, k + 16, Blocks.sandstone);
		world.setBlock(i + 10, j + 3, k + 17, Blocks.sandstone);
		world.setBlock(i + 10, j + 3, k + 18, Blocks.sandstone);
		world.setBlock(i + 10, j + 4, k + 0, Blocks.sandstone);
		world.setBlock(i + 10, j + 4, k + 1, Blocks.sandstone);
		world.setBlock(i + 10, j + 4, k + 2, Blocks.sandstone);
		world.setBlock(i + 10, j + 4, k + 3, Blocks.sandstone);
		world.setBlock(i + 10, j + 4, k + 4, Blocks.sandstone);
		world.setBlock(i + 10, j + 4, k + 5, Blocks.sandstone);
		world.setBlock(i + 10, j + 4, k + 6, Blocks.sandstone);
		world.setBlock(i + 10, j + 4, k + 7, Blocks.sandstone);
		world.setBlock(i + 10, j + 4, k + 8, Blocks.sandstone);
		world.setBlock(i + 10, j + 4, k + 9, Blocks.sandstone);
		world.setBlock(i + 10, j + 4, k + 10, Blocks.sandstone);
		world.setBlock(i + 10, j + 4, k + 11, Blocks.sandstone);
		world.setBlock(i + 10, j + 4, k + 12, Blocks.sandstone);
		world.setBlock(i + 10, j + 4, k + 13, Blocks.sandstone);
		world.setBlock(i + 10, j + 4, k + 14, Blocks.sandstone);
		world.setBlock(i + 10, j + 4, k + 15, Blocks.sandstone);
		world.setBlock(i + 10, j + 4, k + 16, Blocks.sandstone);
		world.setBlock(i + 10, j + 4, k + 17, Blocks.sandstone);
		world.setBlock(i + 10, j + 4, k + 18, Blocks.sandstone);
		world.setBlock(i + 10, j + 4, k + 19, Blocks.sandstone);
		world.setBlock(i + 10, j + 5, k + 0, Blocks.sandstone);
		world.setBlock(i + 10, j + 5, k + 1, Blocks.sandstone);
		world.setBlock(i + 10, j + 5, k + 9, Blocks.sandstone);
		world.setBlock(i + 10, j + 5, k + 10, mod_Avatar.AirBlock);
		world.setBlock(i + 10, j + 5, k + 11, Blocks.sandstone);
		world.setBlock(i + 10, j + 5, k + 18, Blocks.sandstone);
		world.setBlock(i + 10, j + 5, k + 19, Blocks.sandstone);
		world.setBlock(i + 10, j + 10, k + 6, Blocks.wooden_slab, 9, 0x02);
		world.setBlock(i + 10, j + 11, k + 5, Blocks.fence);
		world.setBlock(i + 10, j + 11, k + 7, Blocks.fence);
		world.setBlock(i + 10, j + 11, k + 8, mod_Avatar.AirNomadsBlock);
		world.setBlock(i + 10, j + 12, k + 5, Blocks.fence);
		world.setBlock(i + 10, j + 12, k + 7, Blocks.fence);
		world.setBlock(i + 10, j + 12, k + 8, Blocks.fence);
		world.setBlock(i + 11, j + 0, k + 5, Blocks.sandstone);
		world.setBlock(i + 11, j + 0, k + 6, Blocks.sandstone);
		world.setBlock(i + 11, j + 0, k + 7, Blocks.sandstone);
		world.setBlock(i + 11, j + 0, k + 8, Blocks.sandstone);
		world.setBlock(i + 11, j + 0, k + 9, Blocks.sandstone);
		world.setBlock(i + 11, j + 0, k + 10, Blocks.sandstone);
		world.setBlock(i + 11, j + 0, k + 11, Blocks.sandstone);
		world.setBlock(i + 11, j + 0, k + 12, Blocks.sandstone);
		world.setBlock(i + 11, j + 0, k + 13, Blocks.sandstone);
		world.setBlock(i + 11, j + 0, k + 14, Blocks.sandstone);
		world.setBlock(i + 11, j + 1, k + 4, Blocks.sandstone);
		world.setBlock(i + 11, j + 1, k + 5, Blocks.sandstone);
		world.setBlock(i + 11, j + 1, k + 6, Blocks.sandstone);
		world.setBlock(i + 11, j + 1, k + 7, Blocks.sandstone);
		world.setBlock(i + 11, j + 1, k + 8, Blocks.sandstone);
		world.setBlock(i + 11, j + 1, k + 9, Blocks.sandstone);
		world.setBlock(i + 11, j + 1, k + 10, Blocks.sandstone);
		world.setBlock(i + 11, j + 1, k + 11, Blocks.sandstone);
		world.setBlock(i + 11, j + 1, k + 12, Blocks.sandstone);
		world.setBlock(i + 11, j + 1, k + 13, Blocks.sandstone);
		world.setBlock(i + 11, j + 1, k + 14, Blocks.sandstone);
		world.setBlock(i + 11, j + 1, k + 15, Blocks.sandstone);
		world.setBlock(i + 11, j + 2, k + 2, Blocks.sandstone);
		world.setBlock(i + 11, j + 2, k + 3, Blocks.sandstone);
		world.setBlock(i + 11, j + 2, k + 4, Blocks.sandstone);
		world.setBlock(i + 11, j + 2, k + 5, Blocks.sandstone);
		world.setBlock(i + 11, j + 2, k + 6, Blocks.sandstone);
		world.setBlock(i + 11, j + 2, k + 7, Blocks.sandstone);
		world.setBlock(i + 11, j + 2, k + 8, Blocks.sandstone);
		world.setBlock(i + 11, j + 2, k + 9, Blocks.sandstone);
		world.setBlock(i + 11, j + 2, k + 10, Blocks.sandstone);
		world.setBlock(i + 11, j + 2, k + 11, Blocks.sandstone);
		world.setBlock(i + 11, j + 2, k + 12, Blocks.sandstone);
		world.setBlock(i + 11, j + 2, k + 13, Blocks.sandstone);
		world.setBlock(i + 11, j + 2, k + 14, Blocks.sandstone);
		world.setBlock(i + 11, j + 2, k + 15, Blocks.sandstone);
		world.setBlock(i + 11, j + 2, k + 16, Blocks.sandstone);
		world.setBlock(i + 11, j + 2, k + 17, Blocks.sandstone);
		world.setBlock(i + 11, j + 3, k + 1, Blocks.sandstone);
		world.setBlock(i + 11, j + 3, k + 2, Blocks.sandstone);
		world.setBlock(i + 11, j + 3, k + 3, Blocks.sandstone);
		world.setBlock(i + 11, j + 3, k + 4, Blocks.sandstone);
		world.setBlock(i + 11, j + 3, k + 5, Blocks.sandstone);
		world.setBlock(i + 11, j + 3, k + 6, Blocks.sandstone);
		world.setBlock(i + 11, j + 3, k + 7, Blocks.sandstone);
		world.setBlock(i + 11, j + 3, k + 8, Blocks.sandstone);
		world.setBlock(i + 11, j + 3, k + 9, Blocks.sandstone);
		world.setBlock(i + 11, j + 3, k + 10, Blocks.sandstone);
		world.setBlock(i + 11, j + 3, k + 11, Blocks.sandstone);
		world.setBlock(i + 11, j + 3, k + 12, Blocks.sandstone);
		world.setBlock(i + 11, j + 3, k + 13, Blocks.sandstone);
		world.setBlock(i + 11, j + 3, k + 14, Blocks.sandstone);
		world.setBlock(i + 11, j + 3, k + 15, Blocks.sandstone);
		world.setBlock(i + 11, j + 3, k + 16, Blocks.sandstone);
		world.setBlock(i + 11, j + 3, k + 17, Blocks.sandstone);
		world.setBlock(i + 11, j + 3, k + 18, Blocks.sandstone);
		world.setBlock(i + 11, j + 4, k + 0, Blocks.sandstone);
		world.setBlock(i + 11, j + 4, k + 1, Blocks.sandstone);
		world.setBlock(i + 11, j + 4, k + 2, Blocks.sandstone);
		world.setBlock(i + 11, j + 4, k + 3, Blocks.sandstone);
		world.setBlock(i + 11, j + 4, k + 4, Blocks.sandstone);
		world.setBlock(i + 11, j + 4, k + 5, Blocks.sandstone);
		world.setBlock(i + 11, j + 4, k + 6, Blocks.sandstone);
		world.setBlock(i + 11, j + 4, k + 7, Blocks.sandstone);
		world.setBlock(i + 11, j + 4, k + 8, Blocks.sandstone);
		world.setBlock(i + 11, j + 4, k + 9, Blocks.sandstone);
		world.setBlock(i + 11, j + 4, k + 10, Blocks.sandstone);
		world.setBlock(i + 11, j + 4, k + 11, Blocks.sandstone);
		world.setBlock(i + 11, j + 4, k + 12, Blocks.sandstone);
		world.setBlock(i + 11, j + 4, k + 13, Blocks.sandstone);
		world.setBlock(i + 11, j + 4, k + 14, Blocks.sandstone);
		world.setBlock(i + 11, j + 4, k + 15, Blocks.sandstone);
		world.setBlock(i + 11, j + 4, k + 16, Blocks.sandstone);
		world.setBlock(i + 11, j + 4, k + 17, Blocks.sandstone);
		world.setBlock(i + 11, j + 4, k + 18, Blocks.sandstone);
		world.setBlock(i + 11, j + 4, k + 19, Blocks.sandstone);
		world.setBlock(i + 11, j + 5, k + 0, Blocks.sandstone);
		world.setBlock(i + 11, j + 5, k + 1, Blocks.sandstone);
		world.setBlock(i + 11, j + 5, k + 10, Blocks.sandstone);
		world.setBlock(i + 11, j + 5, k + 18, Blocks.sandstone);
		world.setBlock(i + 11, j + 5, k + 19, Blocks.sandstone);
		world.setBlock(i + 11, j + 11, k + 2, Blocks.wooden_slab, 1, 0x02);
		world.setBlock(i + 11, j + 11, k + 3, Blocks.wooden_slab, 1, 0x02);
		world.setBlock(i + 11, j + 11, k + 4, Blocks.wooden_slab, 1, 0x02);
		world.setBlock(i + 11, j + 11, k + 5, Blocks.fence);
		world.setBlock(i + 11, j + 11, k + 6, Blocks.wooden_slab, 1, 0x02);
		world.setBlock(i + 11, j + 11, k + 7, Blocks.fence);
		world.setBlock(i + 11, j + 11, k + 8, Blocks.wooden_slab, 1, 0x02);
		world.setBlock(i + 11, j + 11, k + 9, Blocks.wooden_slab, 1, 0x02);
		world.setBlock(i + 11, j + 11, k + 10, Blocks.wooden_slab, 1, 0x02);
		world.setBlock(i + 11, j + 12, k + 5, Blocks.fence);
		world.setBlock(i + 11, j + 12, k + 7, Blocks.fence);
		world.setBlock(i + 12, j + 0, k + 2, Blocks.sandstone);
		world.setBlock(i + 12, j + 0, k + 5, Blocks.sandstone);
		world.setBlock(i + 12, j + 0, k + 6, Blocks.sandstone);
		world.setBlock(i + 12, j + 0, k + 7, Blocks.sandstone);
		world.setBlock(i + 12, j + 0, k + 8, Blocks.sandstone);
		world.setBlock(i + 12, j + 0, k + 9, Blocks.sandstone);
		world.setBlock(i + 12, j + 0, k + 10, Blocks.sandstone);
		world.setBlock(i + 12, j + 0, k + 11, Blocks.sandstone);
		world.setBlock(i + 12, j + 0, k + 12, Blocks.sandstone);
		world.setBlock(i + 12, j + 0, k + 13, Blocks.sandstone);
		world.setBlock(i + 12, j + 0, k + 14, Blocks.sandstone);
		world.setBlock(i + 12, j + 1, k + 2, Blocks.sandstone);
		world.setBlock(i + 12, j + 1, k + 4, Blocks.sandstone);
		world.setBlock(i + 12, j + 1, k + 5, Blocks.sandstone);
		world.setBlock(i + 12, j + 1, k + 6, Blocks.sandstone);
		world.setBlock(i + 12, j + 1, k + 7, Blocks.sandstone);
		world.setBlock(i + 12, j + 1, k + 8, Blocks.sandstone);
		world.setBlock(i + 12, j + 1, k + 9, Blocks.sandstone);
		world.setBlock(i + 12, j + 1, k + 10, Blocks.sandstone);
		world.setBlock(i + 12, j + 1, k + 11, Blocks.sandstone);
		world.setBlock(i + 12, j + 1, k + 12, Blocks.sandstone);
		world.setBlock(i + 12, j + 1, k + 13, Blocks.sandstone);
		world.setBlock(i + 12, j + 1, k + 14, Blocks.sandstone);
		world.setBlock(i + 12, j + 1, k + 15, Blocks.sandstone);
		world.setBlock(i + 12, j + 1, k + 17, Blocks.sandstone);
		world.setBlock(i + 12, j + 2, k + 2, Blocks.sandstone);
		world.setBlock(i + 12, j + 2, k + 3, Blocks.sandstone);
		world.setBlock(i + 12, j + 2, k + 4, Blocks.sandstone);
		world.setBlock(i + 12, j + 2, k + 5, Blocks.sandstone);
		world.setBlock(i + 12, j + 2, k + 6, Blocks.sandstone);
		world.setBlock(i + 12, j + 2, k + 7, Blocks.sandstone);
		world.setBlock(i + 12, j + 2, k + 8, Blocks.sandstone);
		world.setBlock(i + 12, j + 2, k + 9, Blocks.sandstone);
		world.setBlock(i + 12, j + 2, k + 10, Blocks.sandstone);
		world.setBlock(i + 12, j + 2, k + 11, Blocks.sandstone);
		world.setBlock(i + 12, j + 2, k + 12, Blocks.sandstone);
		world.setBlock(i + 12, j + 2, k + 13, Blocks.sandstone);
		world.setBlock(i + 12, j + 2, k + 14, Blocks.sandstone);
		world.setBlock(i + 12, j + 2, k + 15, Blocks.sandstone);
		world.setBlock(i + 12, j + 2, k + 16, Blocks.sandstone);
		world.setBlock(i + 12, j + 2, k + 17, Blocks.sandstone);
		world.setBlock(i + 12, j + 3, k + 2, Blocks.sandstone);
		world.setBlock(i + 12, j + 3, k + 3, Blocks.sandstone);
		world.setBlock(i + 12, j + 3, k + 4, Blocks.sandstone);
		world.setBlock(i + 12, j + 3, k + 5, Blocks.sandstone);
		world.setBlock(i + 12, j + 3, k + 6, Blocks.sandstone);
		world.setBlock(i + 12, j + 3, k + 7, Blocks.sandstone);
		world.setBlock(i + 12, j + 3, k + 8, Blocks.sandstone);
		world.setBlock(i + 12, j + 3, k + 9, Blocks.sandstone);
		world.setBlock(i + 12, j + 3, k + 10, Blocks.sandstone);
		world.setBlock(i + 12, j + 3, k + 11, Blocks.sandstone);
		world.setBlock(i + 12, j + 3, k + 12, Blocks.sandstone);
		world.setBlock(i + 12, j + 3, k + 13, Blocks.sandstone);
		world.setBlock(i + 12, j + 3, k + 14, Blocks.sandstone);
		world.setBlock(i + 12, j + 3, k + 15, Blocks.sandstone);
		world.setBlock(i + 12, j + 3, k + 16, Blocks.sandstone);
		world.setBlock(i + 12, j + 3, k + 17, Blocks.sandstone);
		world.setBlock(i + 12, j + 4, k + 1, Blocks.sandstone);
		world.setBlock(i + 12, j + 4, k + 2, Blocks.sandstone);
		world.setBlock(i + 12, j + 4, k + 3, Blocks.sandstone);
		world.setBlock(i + 12, j + 4, k + 4, Blocks.sandstone);
		world.setBlock(i + 12, j + 4, k + 5, Blocks.sandstone);
		world.setBlock(i + 12, j + 4, k + 6, Blocks.sandstone);
		world.setBlock(i + 12, j + 4, k + 7, Blocks.sandstone);
		world.setBlock(i + 12, j + 4, k + 8, Blocks.sandstone);
		world.setBlock(i + 12, j + 4, k + 9, Blocks.sandstone);
		world.setBlock(i + 12, j + 4, k + 10, Blocks.sandstone);
		world.setBlock(i + 12, j + 4, k + 11, Blocks.sandstone);
		world.setBlock(i + 12, j + 4, k + 12, Blocks.sandstone);
		world.setBlock(i + 12, j + 4, k + 13, Blocks.sandstone);
		world.setBlock(i + 12, j + 4, k + 14, Blocks.sandstone);
		world.setBlock(i + 12, j + 4, k + 15, Blocks.sandstone);
		world.setBlock(i + 12, j + 4, k + 16, Blocks.sandstone);
		world.setBlock(i + 12, j + 4, k + 17, Blocks.sandstone);
		world.setBlock(i + 12, j + 4, k + 18, Blocks.sandstone);
		world.setBlock(i + 12, j + 5, k + 0, Blocks.sandstone);
		world.setBlock(i + 12, j + 5, k + 1, Blocks.sandstone);
		world.setBlock(i + 12, j + 5, k + 2, Blocks.sandstone);
		world.setBlock(i + 12, j + 5, k + 3, Blocks.dirt);
		world.setBlock(i + 12, j + 5, k + 4, Blocks.dirt);
		world.setBlock(i + 12, j + 5, k + 5, Blocks.dirt);
		world.setBlock(i + 12, j + 5, k + 6, Blocks.dirt);
		world.setBlock(i + 12, j + 5, k + 7, Blocks.dirt);
		world.setBlock(i + 12, j + 5, k + 8, Blocks.dirt);
		world.setBlock(i + 12, j + 5, k + 9, Blocks.dirt);
		world.setBlock(i + 12, j + 5, k + 10, Blocks.grass);
		world.setBlock(i + 12, j + 5, k + 11, Blocks.grass);
		world.setBlock(i + 12, j + 5, k + 12, Blocks.grass);
		world.setBlock(i + 12, j + 5, k + 13, Blocks.grass);
		world.setBlock(i + 12, j + 5, k + 14, Blocks.grass);
		world.setBlock(i + 12, j + 5, k + 15, Blocks.grass);
		world.setBlock(i + 12, j + 5, k + 16, Blocks.grass);
		world.setBlock(i + 12, j + 5, k + 17, Blocks.sandstone);
		world.setBlock(i + 12, j + 5, k + 18, Blocks.sandstone);
		world.setBlock(i + 12, j + 5, k + 19, Blocks.sandstone);
		world.setBlock(i + 12, j + 6, k + 3, Blocks.sandstone_stairs, 2, 0x02);
		world.setBlock(i + 12, j + 6, k + 4, Blocks.sandstone_stairs);
		world.setBlock(i + 12, j + 6, k + 5, Blocks.sandstone_stairs);
		world.setBlock(i + 12, j + 6, k + 6, Blocks.sandstone_stairs);
		world.setBlock(i + 12, j + 6, k + 7, Blocks.sandstone_stairs);
		world.setBlock(i + 12, j + 6, k + 8, Blocks.sandstone_stairs);
		world.setBlock(i + 12, j + 6, k + 9, Blocks.sandstone_stairs, 3, 0x02);
		world.setBlock(i + 12, j + 6, k + 11, Blocks.cobblestone_wall);
		world.setBlock(i + 12, j + 6, k + 17, Blocks.cobblestone_wall);
		world.setBlock(i + 12, j + 11, k + 2, Blocks.wooden_slab, 1, 0x02);
		world.setBlock(i + 12, j + 11, k + 3, Blocks.spruce_stairs);
		world.setBlock(i + 12, j + 11, k + 4, Blocks.spruce_stairs);
		world.setBlock(i + 12, j + 11, k + 5, Blocks.fence);
		world.setBlock(i + 12, j + 11, k + 6, Blocks.wooden_slab, 9, 0x02);
		world.setBlock(i + 12, j + 11, k + 7, Blocks.fence);
		world.setBlock(i + 12, j + 11, k + 8, Blocks.spruce_stairs);
		world.setBlock(i + 12, j + 11, k + 9, Blocks.spruce_stairs);
		world.setBlock(i + 12, j + 11, k + 10, Blocks.wooden_slab, 1, 0x02);
		world.setBlock(i + 12, j + 12, k + 5, Blocks.fence);
		world.setBlock(i + 12, j + 12, k + 7, Blocks.fence);
		world.setBlock(i + 13, j + 0, k + 6, Blocks.sandstone);
		world.setBlock(i + 13, j + 0, k + 7, Blocks.sandstone);
		world.setBlock(i + 13, j + 0, k + 8, Blocks.sandstone);
		world.setBlock(i + 13, j + 0, k + 9, Blocks.sandstone);
		world.setBlock(i + 13, j + 0, k + 10, Blocks.sandstone);
		world.setBlock(i + 13, j + 0, k + 11, Blocks.sandstone);
		world.setBlock(i + 13, j + 0, k + 12, Blocks.sandstone);
		world.setBlock(i + 13, j + 0, k + 13, Blocks.sandstone);
		world.setBlock(i + 13, j + 1, k + 4, Blocks.sandstone);
		world.setBlock(i + 13, j + 1, k + 5, Blocks.sandstone);
		world.setBlock(i + 13, j + 1, k + 6, Blocks.sandstone);
		world.setBlock(i + 13, j + 1, k + 7, Blocks.sandstone);
		world.setBlock(i + 13, j + 1, k + 8, Blocks.sandstone);
		world.setBlock(i + 13, j + 1, k + 9, Blocks.sandstone);
		world.setBlock(i + 13, j + 1, k + 10, Blocks.sandstone);
		world.setBlock(i + 13, j + 1, k + 11, Blocks.sandstone);
		world.setBlock(i + 13, j + 1, k + 12, Blocks.sandstone);
		world.setBlock(i + 13, j + 1, k + 13, Blocks.sandstone);
		world.setBlock(i + 13, j + 1, k + 14, Blocks.sandstone);
		world.setBlock(i + 13, j + 1, k + 15, Blocks.sandstone);
		world.setBlock(i + 13, j + 2, k + 3, Blocks.sandstone);
		world.setBlock(i + 13, j + 2, k + 4, Blocks.sandstone);
		world.setBlock(i + 13, j + 2, k + 5, Blocks.sandstone);
		world.setBlock(i + 13, j + 2, k + 6, Blocks.sandstone);
		world.setBlock(i + 13, j + 2, k + 7, Blocks.sandstone);
		world.setBlock(i + 13, j + 2, k + 8, Blocks.sandstone);
		world.setBlock(i + 13, j + 2, k + 9, Blocks.sandstone);
		world.setBlock(i + 13, j + 2, k + 10, Blocks.sandstone);
		world.setBlock(i + 13, j + 2, k + 11, Blocks.sandstone);
		world.setBlock(i + 13, j + 2, k + 12, Blocks.sandstone);
		world.setBlock(i + 13, j + 2, k + 13, Blocks.sandstone);
		world.setBlock(i + 13, j + 2, k + 14, Blocks.sandstone);
		world.setBlock(i + 13, j + 2, k + 15, Blocks.sandstone);
		world.setBlock(i + 13, j + 2, k + 16, Blocks.sandstone);
		world.setBlock(i + 13, j + 3, k + 0, Blocks.sandstone);
		world.setBlock(i + 13, j + 3, k + 2, Blocks.sandstone);
		world.setBlock(i + 13, j + 3, k + 3, Blocks.sandstone);
		world.setBlock(i + 13, j + 3, k + 4, Blocks.sandstone);
		world.setBlock(i + 13, j + 3, k + 5, Blocks.sandstone);
		world.setBlock(i + 13, j + 3, k + 6, Blocks.sandstone);
		world.setBlock(i + 13, j + 3, k + 7, Blocks.sandstone);
		world.setBlock(i + 13, j + 3, k + 8, Blocks.sandstone);
		world.setBlock(i + 13, j + 3, k + 9, Blocks.sandstone);
		world.setBlock(i + 13, j + 3, k + 10, Blocks.sandstone);
		world.setBlock(i + 13, j + 3, k + 11, Blocks.sandstone);
		world.setBlock(i + 13, j + 3, k + 12, Blocks.sandstone);
		world.setBlock(i + 13, j + 3, k + 13, Blocks.sandstone);
		world.setBlock(i + 13, j + 3, k + 14, Blocks.sandstone);
		world.setBlock(i + 13, j + 3, k + 15, Blocks.sandstone);
		world.setBlock(i + 13, j + 3, k + 16, Blocks.sandstone);
		world.setBlock(i + 13, j + 3, k + 17, Blocks.sandstone);
		world.setBlock(i + 13, j + 4, k + 0, Blocks.sandstone);
		world.setBlock(i + 13, j + 4, k + 2, Blocks.sandstone);
		world.setBlock(i + 13, j + 4, k + 3, Blocks.sandstone);
		world.setBlock(i + 13, j + 4, k + 4, Blocks.sandstone);
		world.setBlock(i + 13, j + 4, k + 5, Blocks.sandstone);
		world.setBlock(i + 13, j + 4, k + 6, Blocks.sandstone);
		world.setBlock(i + 13, j + 4, k + 7, Blocks.sandstone);
		world.setBlock(i + 13, j + 4, k + 8, Blocks.sandstone);
		world.setBlock(i + 13, j + 4, k + 9, Blocks.sandstone);
		world.setBlock(i + 13, j + 4, k + 10, Blocks.sandstone);
		world.setBlock(i + 13, j + 4, k + 11, Blocks.sandstone);
		world.setBlock(i + 13, j + 4, k + 12, Blocks.sandstone);
		world.setBlock(i + 13, j + 4, k + 13, Blocks.sandstone);
		world.setBlock(i + 13, j + 4, k + 14, Blocks.sandstone);
		world.setBlock(i + 13, j + 4, k + 15, Blocks.sandstone);
		world.setBlock(i + 13, j + 4, k + 16, Blocks.sandstone);
		world.setBlock(i + 13, j + 4, k + 17, Blocks.sandstone);
		world.setBlock(i + 13, j + 5, k + 0, Blocks.sandstone);
		world.setBlock(i + 13, j + 5, k + 1, Blocks.sandstone);
		world.setBlock(i + 13, j + 5, k + 2, Blocks.sandstone);
		world.setBlock(i + 13, j + 5, k + 3, Blocks.dirt);
		world.setBlock(i + 13, j + 5, k + 4, Blocks.dirt);
		world.setBlock(i + 13, j + 5, k + 5, Blocks.dirt);
		world.setBlock(i + 13, j + 5, k + 6, Blocks.dirt);
		world.setBlock(i + 13, j + 5, k + 7, Blocks.dirt);
		world.setBlock(i + 13, j + 5, k + 8, Blocks.dirt);
		world.setBlock(i + 13, j + 5, k + 9, Blocks.dirt);
		world.setBlock(i + 13, j + 5, k + 10, Blocks.grass);
		world.setBlock(i + 13, j + 5, k + 11, Blocks.grass);
		world.setBlock(i + 13, j + 5, k + 12, Blocks.dirt);
		world.setBlock(i + 13, j + 5, k + 13, Blocks.dirt);
		world.setBlock(i + 13, j + 5, k + 14, Blocks.dirt);
		world.setBlock(i + 13, j + 5, k + 15, Blocks.dirt);
		world.setBlock(i + 13, j + 5, k + 16, Blocks.dirt);
		world.setBlock(i + 13, j + 5, k + 17, Blocks.sandstone);
		world.setBlock(i + 13, j + 5, k + 18, Blocks.sandstone);
		world.setBlock(i + 13, j + 5, k + 19, Blocks.sandstone);
		world.setBlock(i + 13, j + 6, k + 3, Blocks.sandstone_stairs, 2, 0x02);
		world.setBlock(i + 13, j + 6, k + 4, Blocks.planks, 1, 0x02);
		world.setBlock(i + 13, j + 6, k + 5, Blocks.planks, 1, 0x02);
		world.setBlock(i + 13, j + 6, k + 6, Blocks.planks, 1, 0x02);
		world.setBlock(i + 13, j + 6, k + 7, Blocks.planks, 1, 0x02);
		world.setBlock(i + 13, j + 6, k + 8, Blocks.planks, 1, 0x02);
		world.setBlock(i + 13, j + 6, k + 9, Blocks.sandstone_stairs, 3, 0x02);
		world.setBlock(i + 13, j + 6, k + 11, Blocks.cobblestone_wall);
		world.setBlock(i + 13, j + 6, k + 12, Blocks.spruce_stairs);
		world.setBlock(i + 13, j + 6, k + 13, Blocks.spruce_stairs);
		world.setBlock(i + 13, j + 6, k + 14, Blocks.spruce_stairs);
		world.setBlock(i + 13, j + 6, k + 15, Blocks.spruce_stairs);
		world.setBlock(i + 13, j + 6, k + 16, Blocks.spruce_stairs);
		world.setBlock(i + 13, j + 6, k + 17, Blocks.cobblestone_wall);
		world.setBlock(i + 13, j + 7, k + 4, Blocks.log, 1, 0x02);
		world.setBlock(i + 13, j + 7, k + 8, Blocks.log, 1, 0x02);
		world.setBlock(i + 13, j + 8, k + 4, Blocks.log, 1, 0x02);
		world.setBlock(i + 13, j + 8, k + 8, Blocks.log, 1, 0x02);
		world.setBlock(i + 13, j + 9, k + 4, Blocks.log, 1, 0x02);
		world.setBlock(i + 13, j + 9, k + 5, Blocks.stone_stairs, 7, 0x02);
		world.setBlock(i + 13, j + 9, k + 7, Blocks.stone_stairs, 6, 0x02);
		world.setBlock(i + 13, j + 9, k + 8, Blocks.log, 1, 0x02);
		world.setBlock(i + 13, j + 10, k + 4, Blocks.log, 1, 0x02);
		world.setBlock(i + 13, j + 10, k + 5, Blocks.stone_stairs, 4, 0x02);
		world.setBlock(i + 13, j + 10, k + 6, Blocks.cobblestone);
		world.setBlock(i + 13, j + 10, k + 7, Blocks.stone_stairs, 4, 0x02);
		world.setBlock(i + 13, j + 10, k + 8, Blocks.log, 1, 0x02);
		world.setBlock(i + 13, j + 11, k + 2, Blocks.wooden_slab, 1, 0x02);
		world.setBlock(i + 13, j + 11, k + 3, Blocks.spruce_stairs, 2, 0x02);
		world.setBlock(i + 13, j + 11, k + 4, Blocks.log, 1, 0x02);
		world.setBlock(i + 13, j + 11, k + 5, Blocks.log, 5, 0x02);
		world.setBlock(i + 13, j + 11, k + 6, Blocks.log, 5, 0x02);
		world.setBlock(i + 13, j + 11, k + 7, Blocks.log, 5, 0x02);
		world.setBlock(i + 13, j + 11, k + 8, Blocks.log, 1, 0x02);
		world.setBlock(i + 13, j + 11, k + 9, Blocks.spruce_stairs, 3, 0x02);
		world.setBlock(i + 13, j + 11, k + 10, Blocks.wooden_slab, 1, 0x02);
		world.setBlock(i + 13, j + 12, k + 4, Blocks.fence);
		world.setBlock(i + 13, j + 12, k + 8, Blocks.fence);
		world.setBlock(i + 13, j + 13, k + 4, Blocks.fence);
		world.setBlock(i + 13, j + 13, k + 8, Blocks.fence);
		world.setBlock(i + 13, j + 14, k + 4, Blocks.fence);
		world.setBlock(i + 13, j + 14, k + 5, Blocks.fence);
		world.setBlock(i + 13, j + 14, k + 7, Blocks.fence);
		world.setBlock(i + 13, j + 14, k + 8, Blocks.fence);
		world.setBlock(i + 13, j + 15, k + 4, Blocks.fence);
		world.setBlock(i + 13, j + 15, k + 5, Blocks.fence);
		world.setBlock(i + 13, j + 15, k + 6, Blocks.fence);
		world.setBlock(i + 13, j + 15, k + 7, Blocks.fence);
		world.setBlock(i + 13, j + 15, k + 8, Blocks.fence);
		world.setBlock(i + 13, j + 16, k + 4, Blocks.birch_stairs);
		world.setBlock(i + 13, j + 16, k + 5, Blocks.birch_stairs);
		world.setBlock(i + 13, j + 16, k + 6, Blocks.birch_stairs);
		world.setBlock(i + 13, j + 16, k + 7, Blocks.birch_stairs);
		world.setBlock(i + 13, j + 16, k + 8, Blocks.birch_stairs, 3, 0x02);
		world.setBlock(i + 14, j + 0, k + 6, Blocks.sandstone);
		world.setBlock(i + 14, j + 0, k + 7, Blocks.sandstone);
		world.setBlock(i + 14, j + 0, k + 8, Blocks.sandstone);
		world.setBlock(i + 14, j + 0, k + 9, Blocks.sandstone);
		world.setBlock(i + 14, j + 0, k + 10, Blocks.sandstone);
		world.setBlock(i + 14, j + 0, k + 11, Blocks.sandstone);
		world.setBlock(i + 14, j + 0, k + 12, Blocks.sandstone);
		world.setBlock(i + 14, j + 0, k + 13, Blocks.sandstone);
		world.setBlock(i + 14, j + 1, k + 5, Blocks.sandstone);
		world.setBlock(i + 14, j + 1, k + 6, Blocks.sandstone);
		world.setBlock(i + 14, j + 1, k + 7, Blocks.sandstone);
		world.setBlock(i + 14, j + 1, k + 8, Blocks.sandstone);
		world.setBlock(i + 14, j + 1, k + 9, Blocks.sandstone);
		world.setBlock(i + 14, j + 1, k + 10, Blocks.sandstone);
		world.setBlock(i + 14, j + 1, k + 11, Blocks.sandstone);
		world.setBlock(i + 14, j + 1, k + 12, Blocks.sandstone);
		world.setBlock(i + 14, j + 1, k + 13, Blocks.sandstone);
		world.setBlock(i + 14, j + 1, k + 14, Blocks.sandstone);
		world.setBlock(i + 14, j + 2, k + 4, Blocks.sandstone);
		world.setBlock(i + 14, j + 2, k + 5, Blocks.sandstone);
		world.setBlock(i + 14, j + 2, k + 6, Blocks.sandstone);
		world.setBlock(i + 14, j + 2, k + 7, Blocks.sandstone);
		world.setBlock(i + 14, j + 2, k + 8, Blocks.sandstone);
		world.setBlock(i + 14, j + 2, k + 9, Blocks.sandstone);
		world.setBlock(i + 14, j + 2, k + 10, Blocks.sandstone);
		world.setBlock(i + 14, j + 2, k + 11, Blocks.sandstone);
		world.setBlock(i + 14, j + 2, k + 12, Blocks.sandstone);
		world.setBlock(i + 14, j + 2, k + 13, Blocks.sandstone);
		world.setBlock(i + 14, j + 2, k + 14, Blocks.sandstone);
		world.setBlock(i + 14, j + 2, k + 15, Blocks.sandstone);
		world.setBlock(i + 14, j + 3, k + 3, Blocks.sandstone);
		world.setBlock(i + 14, j + 3, k + 4, Blocks.sandstone);
		world.setBlock(i + 14, j + 3, k + 5, Blocks.sandstone);
		world.setBlock(i + 14, j + 3, k + 6, Blocks.sandstone);
		world.setBlock(i + 14, j + 3, k + 7, Blocks.sandstone);
		world.setBlock(i + 14, j + 3, k + 8, Blocks.sandstone);
		world.setBlock(i + 14, j + 3, k + 9, Blocks.sandstone);
		world.setBlock(i + 14, j + 3, k + 10, Blocks.sandstone);
		world.setBlock(i + 14, j + 3, k + 11, Blocks.sandstone);
		world.setBlock(i + 14, j + 3, k + 12, Blocks.sandstone);
		world.setBlock(i + 14, j + 3, k + 13, Blocks.sandstone);
		world.setBlock(i + 14, j + 3, k + 14, Blocks.sandstone);
		world.setBlock(i + 14, j + 3, k + 15, Blocks.sandstone);
		world.setBlock(i + 14, j + 3, k + 16, Blocks.sandstone);
		world.setBlock(i + 14, j + 4, k + 2, Blocks.sandstone);
		world.setBlock(i + 14, j + 4, k + 3, Blocks.sandstone);
		world.setBlock(i + 14, j + 4, k + 4, Blocks.sandstone);
		world.setBlock(i + 14, j + 4, k + 5, Blocks.sandstone);
		world.setBlock(i + 14, j + 4, k + 6, Blocks.sandstone);
		world.setBlock(i + 14, j + 4, k + 7, Blocks.sandstone);
		world.setBlock(i + 14, j + 4, k + 8, Blocks.sandstone);
		world.setBlock(i + 14, j + 4, k + 9, Blocks.sandstone);
		world.setBlock(i + 14, j + 4, k + 10, Blocks.sandstone);
		world.setBlock(i + 14, j + 4, k + 11, Blocks.sandstone);
		world.setBlock(i + 14, j + 4, k + 12, Blocks.sandstone);
		world.setBlock(i + 14, j + 4, k + 13, Blocks.sandstone);
		world.setBlock(i + 14, j + 4, k + 14, Blocks.sandstone);
		world.setBlock(i + 14, j + 4, k + 15, Blocks.sandstone);
		world.setBlock(i + 14, j + 4, k + 16, Blocks.sandstone);
		world.setBlock(i + 14, j + 4, k + 17, Blocks.sandstone);
		world.setBlock(i + 14, j + 5, k + 0, Blocks.sandstone);
		world.setBlock(i + 14, j + 5, k + 1, Blocks.sandstone);
		world.setBlock(i + 14, j + 5, k + 2, Blocks.sandstone);
		world.setBlock(i + 14, j + 5, k + 3, Blocks.dirt);
		world.setBlock(i + 14, j + 5, k + 4, Blocks.dirt);
		world.setBlock(i + 14, j + 5, k + 5, Blocks.dirt);
		world.setBlock(i + 14, j + 5, k + 6, Blocks.dirt);
		world.setBlock(i + 14, j + 5, k + 7, Blocks.dirt);
		world.setBlock(i + 14, j + 5, k + 8, Blocks.dirt);
		world.setBlock(i + 14, j + 5, k + 9, Blocks.dirt);
		world.setBlock(i + 14, j + 5, k + 10, Blocks.grass);
		world.setBlock(i + 14, j + 5, k + 11, Blocks.grass);
		world.setBlock(i + 14, j + 5, k + 12, Blocks.dirt);
		world.setBlock(i + 14, j + 5, k + 13, Blocks.dirt);
		world.setBlock(i + 14, j + 5, k + 14, Blocks.dirt);
		world.setBlock(i + 14, j + 5, k + 15, Blocks.dirt);
	}

	public void generate2(World world, int i, int j, int k) {
		world.setBlock(i + 14, j + 5, k + 16, Blocks.dirt);
		world.setBlock(i + 14, j + 5, k + 17, Blocks.sandstone);
		world.setBlock(i + 14, j + 5, k + 18, Blocks.sandstone);
		world.setBlock(i + 14, j + 5, k + 19, Blocks.sandstone);
		world.setBlock(i + 14, j + 6, k + 3, Blocks.sandstone_stairs, 2, 0x02);
		world.setBlock(i + 14, j + 6, k + 4, Blocks.planks, 1, 0x02);
		world.setBlock(i + 14, j + 6, k + 5, Blocks.planks, 1, 0x02);
		world.setBlock(i + 14, j + 6, k + 6, Blocks.planks, 1, 0x02);
		world.setBlock(i + 14, j + 6, k + 7, Blocks.planks, 1, 0x02);
		world.setBlock(i + 14, j + 6, k + 8, Blocks.planks, 1, 0x02);
		world.setBlock(i + 14, j + 6, k + 9, Blocks.sandstone_stairs, 3, 0x02);
		world.setBlock(i + 14, j + 6, k + 11, Blocks.cobblestone_wall);
		world.setBlock(i + 14, j + 6, k + 12, Blocks.planks, 1, 0x02);
		world.setBlock(i + 14, j + 6, k + 13, Blocks.wool, 15, 0x02);
		world.setBlock(i + 14, j + 6, k + 14, Blocks.wool, 15, 0x02);
		world.setBlock(i + 14, j + 6, k + 15, Blocks.wool, 15, 0x02);
		world.setBlock(i + 14, j + 6, k + 16, Blocks.planks, 1, 0x02);
		world.setBlock(i + 14, j + 6, k + 17, Blocks.cobblestone_wall);
		world.setBlock(i + 14, j + 7, k + 4, Blocks.cobblestone);
		world.setBlock(i + 14, j + 7, k + 8, Blocks.cobblestone);
		world.setBlock(i + 14, j + 8, k + 4, Blocks.cobblestone);
		world.setBlock(i + 14, j + 8, k + 8, Blocks.cobblestone);
		world.setBlock(i + 14, j + 9, k + 4, Blocks.cobblestone);
		world.setBlock(i + 14, j + 9, k + 8, Blocks.cobblestone);
		world.setBlock(i + 14, j + 10, k + 4, Blocks.cobblestone);
		world.setBlock(i + 14, j + 10, k + 8, Blocks.cobblestone);
		world.setBlock(i + 14, j + 11, k + 2, Blocks.wooden_slab, 1, 0x02);
		world.setBlock(i + 14, j + 11, k + 3, Blocks.spruce_stairs, 2, 0x02);
		world.setBlock(i + 14, j + 11, k + 4, Blocks.log, 9, 0x02);
		world.setBlock(i + 14, j + 11, k + 5, Blocks.planks, 1, 0x02);
		world.setBlock(i + 14, j + 11, k + 6, Blocks.planks, 1, 0x02);
		world.setBlock(i + 14, j + 11, k + 7, Blocks.planks, 1, 0x02);
		world.setBlock(i + 14, j + 11, k + 8, Blocks.log, 9, 0x02);
		world.setBlock(i + 14, j + 11, k + 9, Blocks.spruce_stairs, 3, 0x02);
		world.setBlock(i + 14, j + 11, k + 10, Blocks.wooden_slab, 1, 0x02);
		world.setBlock(i + 14, j + 12, k + 4, Blocks.fence);
		world.setBlock(i + 14, j + 12, k + 8, Blocks.fence);
		world.setBlock(i + 14, j + 14, k + 4, Blocks.fence);
		world.setBlock(i + 14, j + 14, k + 8, Blocks.fence);
		world.setBlock(i + 14, j + 15, k + 4, Blocks.fence);
		world.setBlock(i + 14, j + 15, k + 8, Blocks.fence);
		world.setBlock(i + 14, j + 16, k + 4, Blocks.birch_stairs, 2, 0x02);
		world.setBlock(i + 14, j + 16, k + 8, Blocks.birch_stairs, 3, 0x02);
		world.setBlock(i + 14, j + 17, k + 5, Blocks.birch_stairs, 2, 0x02);
		world.setBlock(i + 14, j + 17, k + 6, Blocks.birch_stairs);
		world.setBlock(i + 14, j + 17, k + 7, Blocks.birch_stairs);
		world.setBlock(i + 15, j + 0, k + 2, Blocks.sandstone);
		world.setBlock(i + 15, j + 0, k + 7, Blocks.sandstone);
		world.setBlock(i + 15, j + 0, k + 8, Blocks.sandstone);
		world.setBlock(i + 15, j + 0, k + 9, Blocks.sandstone);
		world.setBlock(i + 15, j + 0, k + 10, Blocks.sandstone);
		world.setBlock(i + 15, j + 0, k + 11, Blocks.sandstone);
		world.setBlock(i + 15, j + 0, k + 12, Blocks.sandstone);
		world.setBlock(i + 15, j + 0, k + 16, Blocks.sandstone);
		world.setBlock(i + 15, j + 1, k + 2, Blocks.sandstone);
		world.setBlock(i + 15, j + 1, k + 5, Blocks.sandstone);
		world.setBlock(i + 15, j + 1, k + 6, Blocks.sandstone);
		world.setBlock(i + 15, j + 1, k + 7, Blocks.sandstone);
		world.setBlock(i + 15, j + 1, k + 8, Blocks.sandstone);
		world.setBlock(i + 15, j + 1, k + 9, Blocks.sandstone);
		world.setBlock(i + 15, j + 1, k + 10, Blocks.sandstone);
		world.setBlock(i + 15, j + 1, k + 11, Blocks.sandstone);
		world.setBlock(i + 15, j + 1, k + 12, Blocks.sandstone);
		world.setBlock(i + 15, j + 1, k + 13, Blocks.sandstone);
		world.setBlock(i + 15, j + 1, k + 14, Blocks.sandstone);
		world.setBlock(i + 15, j + 1, k + 16, Blocks.sandstone);
		world.setBlock(i + 15, j + 2, k + 2, Blocks.sandstone);
		world.setBlock(i + 15, j + 2, k + 4, Blocks.sandstone);
		world.setBlock(i + 15, j + 2, k + 5, Blocks.sandstone);
		world.setBlock(i + 15, j + 2, k + 6, Blocks.sandstone);
		world.setBlock(i + 15, j + 2, k + 7, Blocks.sandstone);
		world.setBlock(i + 15, j + 2, k + 8, Blocks.sandstone);
		world.setBlock(i + 15, j + 2, k + 9, Blocks.sandstone);
		world.setBlock(i + 15, j + 2, k + 10, Blocks.sandstone);
		world.setBlock(i + 15, j + 2, k + 11, Blocks.sandstone);
		world.setBlock(i + 15, j + 2, k + 12, Blocks.sandstone);
		world.setBlock(i + 15, j + 2, k + 13, Blocks.sandstone);
		world.setBlock(i + 15, j + 2, k + 14, Blocks.sandstone);
		world.setBlock(i + 15, j + 2, k + 15, Blocks.sandstone);
		world.setBlock(i + 15, j + 2, k + 16, Blocks.sandstone);
		world.setBlock(i + 15, j + 3, k + 2, Blocks.sandstone);
		world.setBlock(i + 15, j + 3, k + 3, Blocks.sandstone);
		world.setBlock(i + 15, j + 3, k + 4, Blocks.sandstone);
		world.setBlock(i + 15, j + 3, k + 5, Blocks.sandstone);
		world.setBlock(i + 15, j + 3, k + 6, Blocks.sandstone);
		world.setBlock(i + 15, j + 3, k + 7, Blocks.sandstone);
		world.setBlock(i + 15, j + 3, k + 8, Blocks.sandstone);
		world.setBlock(i + 15, j + 3, k + 9, Blocks.sandstone);
		world.setBlock(i + 15, j + 3, k + 10, Blocks.sandstone);
		world.setBlock(i + 15, j + 3, k + 11, Blocks.sandstone);
