package kieranvs.avatar.generation;

import java.util.Random;

import kieranvs.avatar.mod_Avatar;
import kieranvs.avatar.bending.ElementManager;
import kieranvs.avatar.entity.EntityPolarBearDog;
import kieranvs.avatar.entity.EntityWaterMan;
import kieranvs.avatar.entity.EntityWaterWoman;
import kieranvs.avatar.util.GenerationUtils;

import net.minecraft.block.Block;
import net.minecraft.init.Blocks;
import net.minecraft.item.ItemStack;
import net.minecraft.tileentity.TileEntity;
import net.minecraft.tileentity.TileEntityChest;
import net.minecraft.world.World;
import net.minecraft.world.biome.BiomeGenBase;
import net.minecraft.world.chunk.IChunkProvider;
import cpw.mods.fml.common.IWorldGenerator;

public class WorldGenWaterSouthWatchTower implements IWorldGenerator {

	private static BiomeGenBase[] biomes = {BiomeGenBase.icePlains, BiomeGenBase.coldTaiga, BiomeGenBase.icePlains, BiomeGenBase.frozenOcean, BiomeGenBase.iceMountains};
	
	public void generate(Random random, int chunkX, int chunkZ, World world, IChunkProvider chunkGenerator, IChunkProvider chunkProvider) {
		int[] result = GenerationUtils.shouldSpawnHere(random, chunkX, chunkZ, world, 10, 2, 20, biomes);
		if(result[0] == 0){
			this.generate(world, result[1], result[2] - 4, result[3]);
			this.generateEntities(world, result[1], result[2] - 4, result[3], random);
			this.generateLoot(world, result[1], result[2] - 4, result[3], random);
		}
	}

	public void generateLoot(World world, int i, int j, int k, Random random){
		for(int x = i; x < i + 10; x++){
			for (int z = k; z < k + 10; z++) {
				for (int y = j; y < j + 25; y++) {
						TileEntity e = world.getTileEntity(x, y, z);
						if(e != null && e instanceof TileEntityChest){
							GenerationUtils.generateScrolls(random, (TileEntityChest) e, ElementManager.WATER, 2);
							GenerationUtils.generateRandomMoney(random, (TileEntityChest) e, ElementManager.WATER, 1);	
						}
				}
			}
		}
	}

	public void generateEntities(World world, int i, int j, int k, Random random) {
		int numM = random.nextInt(2) + 2;

		for (int x = 0; x < numM; x++) {
			EntityWaterMan waterMan = new EntityWaterMan(world, i + 5, j + 5, k + 5, 5);
			waterMan.setPositionAndRotation(i + 6, j + 5, k + 6, 1.0F, 1.0F);
			world.spawnEntityInWorld(waterMan);
		}
	}

	
	public boolean generate(World world, int i, int j, int k) {

		for (int x = 0; x <= 10; x++) {
			for (int z = 0; z <= 10; z++) {
				for (int y = 0; y < 25; y++) {
					world.setBlock(i + x, j + y, k + z, Blocks.air);
				}
			}
		}

		world.setBlock(i + 0, j + 0, k + 0, Blocks.snow);
		world.setBlock(i + 0, j + 0, k + 1, Blocks.snow);
		world.setBlock(i + 0, j + 0, k + 2, Blocks.snow);
		world.setBlock(i + 0, j + 0, k + 3, Blocks.snow);
		world.setBlock(i + 0, j + 0, k + 4, Blocks.snow);
		world.setBlock(i + 0, j + 0, k + 5, Blocks.snow);
		world.setBlock(i + 0, j + 0, k + 6, Blocks.snow);
		world.setBlock(i + 0, j + 0, k + 7, Blocks.snow);
		world.setBlock(i + 0, j + 0, k + 8, Blocks.snow);
		world.setBlock(i + 0, j + 0, k + 9, Blocks.snow);
		world.setBlock(i + 0, j + 0, k + 10, Blocks.snow);
		world.setBlock(i + 0, j + 1, k + 0, Blocks.snow);
		world.setBlock(i + 0, j + 1, k + 1, Blocks.snow);
		world.setBlock(i + 0, j + 1, k + 2, Blocks.snow);
		world.setBlock(i + 0, j + 1, k + 3, Blocks.snow);
		world.setBlock(i + 0, j + 1, k + 4, Blocks.snow);
		world.setBlock(i + 0, j + 1, k + 5, Blocks.snow);
		world.setBlock(i + 0, j + 1, k + 6, Blocks.snow);
		world.setBlock(i + 0, j + 1, k + 7, Blocks.snow);
		world.setBlock(i + 0, j + 1, k + 8, Blocks.snow);
		world.setBlock(i + 0, j + 1, k + 9, Blocks.snow);
		world.setBlock(i + 0, j + 1, k + 10, Blocks.snow);
		world.setBlock(i + 0, j + 2, k + 0, Blocks.grass);
		world.setBlock(i + 0, j + 2, k + 1, Blocks.grass);
		world.setBlock(i + 0, j + 2, k + 2, Blocks.grass);
		world.setBlock(i + 0, j + 2, k + 3, Blocks.grass);
		world.setBlock(i + 0, j + 2, k + 4, Blocks.snow);
		world.setBlock(i + 0, j + 2, k + 5, Blocks.snow);
		world.setBlock(i + 0, j + 2, k + 6, Blocks.snow);
		world.setBlock(i + 0, j + 2, k + 7, Blocks.grass);
		world.setBlock(i + 0, j + 2, k + 8, Blocks.grass);
		world.setBlock(i + 0, j + 2, k + 9, Blocks.grass);
		world.setBlock(i + 0, j + 2, k + 10, Blocks.grass);
		world.setBlock(i + 0, j + 3, k + 4, Blocks.snow);
		world.setBlock(i + 0, j + 3, k + 5, Blocks.snow);
		world.setBlock(i + 0, j + 3, k + 6, Blocks.snow);
		world.setBlock(i + 1, j + 0, k + 0, Blocks.snow);
		world.setBlock(i + 1, j + 0, k + 1, Blocks.snow);
		world.setBlock(i + 1, j + 0, k + 2, Blocks.snow);
		world.setBlock(i + 1, j + 0, k + 3, Blocks.snow);
		world.setBlock(i + 1, j + 0, k + 4, Blocks.snow);
		world.setBlock(i + 1, j + 0, k + 5, Blocks.snow);
		world.setBlock(i + 1, j + 0, k + 6, Blocks.snow);
		world.setBlock(i + 1, j + 0, k + 7, Blocks.snow);
		world.setBlock(i + 1, j + 0, k + 8, Blocks.snow);
		world.setBlock(i + 1, j + 0, k + 9, Blocks.snow);
		world.setBlock(i + 1, j + 0, k + 10, Blocks.snow);
		world.setBlock(i + 1, j + 1, k + 0, Blocks.snow);
		world.setBlock(i + 1, j + 1, k + 1, Blocks.snow);
		world.setBlock(i + 1, j + 1, k + 2, Blocks.snow);
		world.setBlock(i + 1, j + 1, k + 3, Blocks.snow);
		world.setBlock(i + 1, j + 1, k + 4, Blocks.snow);
		world.setBlock(i + 1, j + 1, k + 5, Blocks.snow);
		world.setBlock(i + 1, j + 1, k + 6, Blocks.snow);
		world.setBlock(i + 1, j + 1, k + 7, Blocks.snow);
		world.setBlock(i + 1, j + 1, k + 8, Blocks.snow);
		world.setBlock(i + 1, j + 1, k + 9, Blocks.snow);
		world.setBlock(i + 1, j + 1, k + 10, Blocks.snow);
		world.setBlock(i + 1, j + 2, k + 0, Blocks.grass);
		world.setBlock(i + 1, j + 2, k + 1, Blocks.grass);
		world.setBlock(i + 1, j + 2, k + 2, Blocks.grass);
		world.setBlock(i + 1, j + 2, k + 3, Blocks.snow);
		world.setBlock(i + 1, j + 2, k + 4, Blocks.snow);
		world.setBlock(i + 1, j + 2, k + 5, Blocks.snow);
		world.setBlock(i + 1, j + 2, k + 6, Blocks.snow);
		world.setBlock(i + 1, j + 2, k + 7, Blocks.snow);
		world.setBlock(i + 1, j + 2, k + 8, Blocks.grass);
		world.setBlock(i + 1, j + 2, k + 9, Blocks.grass);
		world.setBlock(i + 1, j + 2, k + 10, Blocks.grass);
		world.setBlock(i + 1, j + 3, k + 3, Blocks.snow);
		world.setBlock(i + 1, j + 3, k + 4, Blocks.snow);
		world.setBlock(i + 1, j + 3, k + 5, Blocks.snow);
		world.setBlock(i + 1, j + 3, k + 6, Blocks.snow);
		world.setBlock(i + 1, j + 3, k + 7, Blocks.snow);
		world.setBlock(i + 1, j + 4, k + 4, Blocks.snow);
		world.setBlock(i + 1, j + 4, k + 5, Blocks.fence);
		world.setBlock(i + 1, j + 4, k + 6, Blocks.snow);
		world.setBlock(i + 1, j + 5, k + 4, Blocks.snow);
		world.setBlock(i + 1, j + 5, k + 5, Blocks.fence);
		world.setBlock(i + 1, j + 5, k + 6, Blocks.snow);
		world.setBlock(i + 1, j + 6, k + 4, Blocks.snow);
		world.setBlock(i + 1, j + 6, k + 5, Blocks.snow);
		world.setBlock(i + 1, j + 6, k + 6, Blocks.snow);
		world.setBlock(i + 2, j + 0, k + 0, Blocks.snow);
		world.setBlock(i + 2, j + 0, k + 1, Blocks.snow);
		world.setBlock(i + 2, j + 0, k + 2, Blocks.snow);
		world.setBlock(i + 2, j + 0, k + 3, Blocks.snow);
		world.setBlock(i + 2, j + 0, k + 4, Blocks.snow);
		world.setBlock(i + 2, j + 0, k + 5, Blocks.snow);
		world.setBlock(i + 2, j + 0, k + 6, Blocks.snow);
		world.setBlock(i + 2, j + 0, k + 7, Blocks.snow);
		world.setBlock(i + 2, j + 0, k + 8, Blocks.snow);
		world.setBlock(i + 2, j + 0, k + 9, Blocks.snow);
		world.setBlock(i + 2, j + 0, k + 10, Blocks.snow);
		world.setBlock(i + 2, j + 1, k + 0, Blocks.snow);
		world.setBlock(i + 2, j + 1, k + 1, Blocks.snow);
		world.setBlock(i + 2, j + 1, k + 2, Blocks.snow);
		world.setBlock(i + 2, j + 1, k + 3, Blocks.snow);
		world.setBlock(i + 2, j + 1, k + 4, Blocks.snow);
		world.setBlock(i + 2, j + 1, k + 5, Blocks.snow);
		world.setBlock(i + 2, j + 1, k + 6, Blocks.snow);
		world.setBlock(i + 2, j + 1, k + 7, Blocks.snow);
		world.setBlock(i + 2, j + 1, k + 8, Blocks.snow);
		world.setBlock(i + 2, j + 1, k + 9, Blocks.snow);
		world.setBlock(i + 2, j + 1, k + 10, Blocks.snow);
		world.setBlock(i + 2, j + 2, k + 0, Blocks.grass);
		world.setBlock(i + 2, j + 2, k + 1, Blocks.grass);
		world.setBlock(i + 2, j + 2, k + 2, Blocks.snow);
		world.setBlock(i + 2, j + 2, k + 3, Blocks.snow);
		world.setBlock(i + 2, j + 2, k + 4, Blocks.planks, 1, 0x02);
		world.setBlock(i + 2, j + 2, k + 5, Blocks.glowstone);
		world.setBlock(i + 2, j + 2, k + 6, Blocks.planks, 1, 0x02);
		world.setBlock(i + 2, j + 2, k + 7, Blocks.snow);
		world.setBlock(i + 2, j + 2, k + 8, Blocks.snow);
		world.setBlock(i + 2, j + 2, k + 9, Blocks.grass);
		world.setBlock(i + 2, j + 2, k + 10, Blocks.grass);
		world.setBlock(i + 2, j + 3, k + 2, Blocks.snow);
		world.setBlock(i + 2, j + 3, k + 3, Blocks.snow);
		world.setBlock(i + 2, j + 3, k + 7, Blocks.snow);
		world.setBlock(i + 2, j + 3, k + 8, Blocks.snow);
		world.setBlock(i + 2, j + 4, k + 3, Blocks.snow);
		world.setBlock(i + 2, j + 4, k + 7, Blocks.snow);
		world.setBlock(i + 2, j + 5, k + 3, Blocks.snow);
		world.setBlock(i + 2, j + 5, k + 7, Blocks.snow);
		world.setBlock(i + 2, j + 6, k + 3, Blocks.snow);
		world.setBlock(i + 2, j + 6, k + 7, Blocks.snow);
		world.setBlock(i + 2, j + 7, k + 4, Blocks.snow);
		world.setBlock(i + 2, j + 7, k + 5, Blocks.snow);
		world.setBlock(i + 2, j + 7, k + 6, Blocks.snow);
		world.setBlock(i + 2, j + 8, k + 4, Blocks.snow);
		world.setBlock(i + 2, j + 8, k + 5, Blocks.fence);
		world.setBlock(i + 2, j + 8, k + 6, Blocks.snow);
		world.setBlock(i + 2, j + 9, k + 4, Blocks.snow);
		world.setBlock(i + 2, j + 9, k + 5, Blocks.fence);
		world.setBlock(i + 2, j + 9, k + 6, Blocks.snow);
		world.setBlock(i + 2, j + 10, k + 4, Blocks.snow);
		world.setBlock(i + 2, j + 10, k + 5, Blocks.snow);
		world.setBlock(i + 2, j + 10, k + 6, Blocks.snow);
		world.setBlock(i + 3, j + 0, k + 0, Blocks.snow);
		world.setBlock(i + 3, j + 0, k + 1, Blocks.snow);
		world.setBlock(i + 3, j + 0, k + 2, Blocks.snow);
		world.setBlock(i + 3, j + 0, k + 3, Blocks.snow);
		world.setBlock(i + 3, j + 0, k + 4, Blocks.snow);
		world.setBlock(i + 3, j + 0, k + 5, Blocks.snow);
		world.setBlock(i + 3, j + 0, k + 6, Blocks.snow);
		world.setBlock(i + 3, j + 0, k + 7, Blocks.snow);
		world.setBlock(i + 3, j + 0, k + 8, Blocks.snow);
		world.setBlock(i + 3, j + 0, k + 9, Blocks.snow);
		world.setBlock(i + 3, j + 0, k + 10, Blocks.snow);
		world.setBlock(i + 3, j + 1, k + 0, Blocks.snow);
		world.setBlock(i + 3, j + 1, k + 1, Blocks.snow);
		world.setBlock(i + 3, j + 1, k + 2, Blocks.snow);
		world.setBlock(i + 3, j + 1, k + 3, Blocks.snow);
		world.setBlock(i + 3, j + 1, k + 4, Blocks.snow);
		world.setBlock(i + 3, j + 1, k + 5, Blocks.snow);
		world.setBlock(i + 3, j + 1, k + 6, Blocks.snow);
		world.setBlock(i + 3, j + 1, k + 7, Blocks.snow);
		world.setBlock(i + 3, j + 1, k + 8, Blocks.snow);
		world.setBlock(i + 3, j + 1, k + 9, Blocks.snow);
		world.setBlock(i + 3, j + 1, k + 10, Blocks.snow);
		world.setBlock(i + 3, j + 2, k + 0, Blocks.grass);
		world.setBlock(i + 3, j + 2, k + 1, Blocks.snow);
		world.setBlock(i + 3, j + 2, k + 2, Blocks.snow);
		world.setBlock(i + 3, j + 2, k + 3, Blocks.planks, 1, 0x02);
		world.setBlock(i + 3, j + 2, k + 4, Blocks.planks, 1, 0x02);
		world.setBlock(i + 3, j + 2, k + 5, Blocks.planks, 1, 0x02);
		world.setBlock(i + 3, j + 2, k + 6, Blocks.planks, 1, 0x02);
		world.setBlock(i + 3, j + 2, k + 7, Blocks.planks, 1, 0x02);
		world.setBlock(i + 3, j + 2, k + 8, Blocks.snow);
		world.setBlock(i + 3, j + 2, k + 9, Blocks.snow);
		world.setBlock(i + 3, j + 2, k + 10, Blocks.grass);
		world.setBlock(i + 3, j + 3, k + 1, Blocks.snow);
		world.setBlock(i + 3, j + 3, k + 2, Blocks.snow);
		world.setBlock(i + 3, j + 3, k + 8, Blocks.snow);
		world.setBlock(i + 3, j + 3, k + 9, Blocks.snow);
		world.setBlock(i + 3, j + 4, k + 2, Blocks.snow);
		world.setBlock(i + 3, j + 4, k + 8, Blocks.snow);
		world.setBlock(i + 3, j + 5, k + 2, Blocks.snow);
		world.setBlock(i + 3, j + 5, k + 8, Blocks.snow);
		world.setBlock(i + 3, j + 6, k + 2, Blocks.snow);
		world.setBlock(i + 3, j + 6, k + 8, Blocks.snow);
		world.setBlock(i + 3, j + 7, k + 3, Blocks.snow);
		world.setBlock(i + 3, j + 7, k + 4, Blocks.snow);
		world.setBlock(i + 3, j + 7, k + 5, Blocks.snow);
		world.setBlock(i + 3, j + 7, k + 6, Blocks.snow);
		world.setBlock(i + 3, j + 7, k + 7, Blocks.snow);
		world.setBlock(i + 3, j + 8, k + 3, Blocks.snow);
		world.setBlock(i + 3, j + 8, k + 7, Blocks.snow);
		world.setBlock(i + 3, j + 9, k + 3, Blocks.snow);
		world.setBlock(i + 3, j + 9, k + 7, Blocks.snow);
		world.setBlock(i + 3, j + 10, k + 3, Blocks.snow);
		world.setBlock(i + 3, j + 10, k + 7, Blocks.snow);
		world.setBlock(i + 3, j + 11, k + 4, Blocks.snow);
		world.setBlock(i + 3, j + 11, k + 5, Blocks.snow);
		world.setBlock(i + 3, j + 11, k + 6, Blocks.snow);
		world.setBlock(i + 3, j + 12, k + 4, Blocks.snow);
		world.setBlock(i + 3, j + 12, k + 5, Blocks.fence);
		world.setBlock(i + 3, j + 12, k + 6, Blocks.snow);
		world.setBlock(i + 3, j + 13, k + 4, Blocks.snow);
		world.setBlock(i + 3, j + 13, k + 5, Blocks.fence);
		world.setBlock(i + 3, j + 13, k + 6, Blocks.snow);
		world.setBlock(i + 3, j + 14, k + 4, Blocks.snow);
		world.setBlock(i + 3, j + 14, k + 5, Blocks.snow);
		world.setBlock(i + 3, j + 14, k + 6, Blocks.snow);
		world.setBlock(i + 4, j + 0, k + 0, Blocks.snow);
		world.setBlock(i + 4, j + 0, k + 1, Blocks.snow);
		world.setBlock(i + 4, j + 0, k + 2, Blocks.snow);
		world.setBlock(i + 4, j + 0, k + 3, Blocks.snow);
		world.setBlock(i + 4, j + 0, k + 4, Blocks.snow);
		world.setBlock(i + 4, j + 0, k + 5, Blocks.snow);
		world.setBlock(i + 4, j + 0, k + 6, Blocks.snow);
		world.setBlock(i + 4, j + 0, k + 7, Blocks.snow);
		world.setBlock(i + 4, j + 0, k + 8, Blocks.snow);
		world.setBlock(i + 4, j + 0, k + 9, Blocks.snow);
		world.setBlock(i + 4, j + 0, k + 10, Blocks.snow);
		world.setBlock(i + 4, j + 1, k + 0, Blocks.snow);
		world.setBlock(i + 4, j + 1, k + 1, Blocks.snow);
		world.setBlock(i + 4, j + 1, k + 2, Blocks.snow);
		world.setBlock(i + 4, j + 1, k + 3, Blocks.snow);
		world.setBlock(i + 4, j + 1, k + 4, Blocks.snow);
		world.setBlock(i + 4, j + 1, k + 5, Blocks.snow);
		world.setBlock(i + 4, j + 1, k + 6, Blocks.snow);
		world.setBlock(i + 4, j + 1, k + 7, Blocks.snow);
		world.setBlock(i + 4, j + 1, k + 8, Blocks.snow);
		world.setBlock(i + 4, j + 1, k + 9, Blocks.snow);
		world.setBlock(i + 4, j + 1, k + 10, Blocks.snow);
		world.setBlock(i + 4, j + 2, k + 0, Blocks.snow);
		world.setBlock(i + 4, j + 2, k + 1, Blocks.snow);
		world.setBlock(i + 4, j + 2, k + 2, Blocks.planks, 1, 0x02);
		world.setBlock(i + 4, j + 2, k + 3, Blocks.planks, 1, 0x02);
		world.setBlock(i + 4, j + 2, k + 4, Blocks.planks, 1, 0x02);
		world.setBlock(i + 4, j + 2, k + 5, Blocks.planks, 1, 0x02);
		world.setBlock(i + 4, j + 2, k + 6, Blocks.planks, 1, 0x02);
		world.setBlock(i + 4, j + 2, k + 7, Blocks.planks, 1, 0x02);
		world.setBlock(i + 4, j + 2, k + 8, Blocks.planks, 1, 0x02);
		world.setBlock(i + 4, j + 2, k + 9, Blocks.snow);
		world.setBlock(i + 4, j + 2, k + 10, Blocks.snow);
		world.setBlock(i + 4, j + 3, k + 0, Blocks.snow);
		world.setBlock(i + 4, j + 3, k + 1, Blocks.snow);
		world.setBlock(i + 4, j + 3, k + 9, Blocks.snow);
		world.setBlock(i + 4, j + 3, k + 10, Blocks.snow);
		world.setBlock(i + 4, j + 4, k + 1, Blocks.snow);
		world.setBlock(i + 4, j + 4, k + 9, Blocks.snow);
		world.setBlock(i + 4, j + 5, k + 1, Blocks.snow);
		world.setBlock(i + 4, j + 5, k + 9, Blocks.snow);
		world.setBlock(i + 4, j + 6, k + 1, Blocks.snow);
		world.setBlock(i + 4, j + 6, k + 9, Blocks.snow);
		world.setBlock(i + 4, j + 7, k + 2, Blocks.snow);
		world.setBlock(i + 4, j + 7, k + 3, Blocks.snow);
		world.setBlock(i + 4, j + 7, k + 4, Blocks.snow);
		world.setBlock(i + 4, j + 7, k + 6, Blocks.snow);
		world.setBlock(i + 4, j + 7, k + 7, Blocks.snow);
		world.setBlock(i + 4, j + 7, k + 8, Blocks.snow);
		world.setBlock(i + 4, j + 8, k + 2, Blocks.snow);
		world.setBlock(i + 4, j + 8, k + 8, Blocks.snow);
		world.setBlock(i + 4, j + 9, k + 2, Blocks.snow);
		world.setBlock(i + 4, j + 9, k + 8, Blocks.snow);
		world.setBlock(i + 4, j + 10, k + 2, Blocks.snow);
		world.setBlock(i + 4, j + 10, k + 8, Blocks.snow);
		world.setBlock(i + 4, j + 11, k + 3, Blocks.snow);
		world.setBlock(i + 4, j + 11, k + 4, Blocks.snow);
		world.setBlock(i + 4, j + 11, k + 6, Blocks.snow);
		world.setBlock(i + 4, j + 11, k + 7, Blocks.snow);
		world.setBlock(i + 4, j + 12, k + 3, Blocks.snow);
		world.setBlock(i + 4, j + 12, k + 7, Blocks.snow);
		world.setBlock(i + 4, j + 13, k + 3, Blocks.snow);
		world.setBlock(i + 4, j + 13, k + 7, Blocks.snow);
		world.setBlock(i + 4, j + 14, k + 3, Blocks.snow);
		world.setBlock(i + 4, j + 14, k + 7, Blocks.snow);
		world.setBlock(i + 4, j + 15, k + 4, Blocks.snow);
		world.setBlock(i + 4, j + 15, k + 5, Blocks.snow);
		world.setBlock(i + 4, j + 15, k + 6, Blocks.snow);
		world.setBlock(i + 4, j + 16, k + 4, Blocks.snow);
		world.setBlock(i + 4, j + 16, k + 5, Blocks.fence);
		world.setBlock(i + 4, j + 16, k + 6, Blocks.snow);
		world.setBlock(i + 4, j + 17, k + 4, Blocks.snow);
		world.setBlock(i + 4, j + 17, k + 5, Blocks.snow);
		world.setBlock(i + 4, j + 17, k + 6, Blocks.snow);
		world.setBlock(i + 5, j + 0, k + 0, Blocks.snow);
		world.setBlock(i + 5, j + 0, k + 1, Blocks.snow);
		world.setBlock(i + 5, j + 0, k + 2, Blocks.snow);
		world.setBlock(i + 5, j + 0, k + 3, Blocks.snow);
		world.setBlock(i + 5, j + 0, k + 4, Blocks.snow);
		world.setBlock(i + 5, j + 0, k + 5, Blocks.snow);
		world.setBlock(i + 5, j + 0, k + 6, Blocks.snow);
		world.setBlock(i + 5, j + 0, k + 7, Blocks.snow);
		world.setBlock(i + 5, j + 0, k + 8, Blocks.snow);
		world.setBlock(i + 5, j + 0, k + 9, Blocks.snow);
		world.setBlock(i + 5, j + 0, k + 10, Blocks.snow);
		world.setBlock(i + 5, j + 1, k + 0, Blocks.snow);
		world.setBlock(i + 5, j + 1, k + 1, Blocks.snow);
		world.setBlock(i + 5, j + 1, k + 2, Blocks.snow);
		world.setBlock(i + 5, j + 1, k + 3, Blocks.snow);
		world.setBlock(i + 5, j + 1, k + 4, Blocks.snow);
		world.setBlock(i + 5, j + 1, k + 5, Blocks.snow);
		world.setBlock(i + 5, j + 1, k + 6, Blocks.snow);
		world.setBlock(i + 5, j + 1, k + 7, Blocks.snow);
		world.setBlock(i + 5, j + 1, k + 8, Blocks.snow);
		world.setBlock(i + 5, j + 1, k + 9, Blocks.snow);
		world.setBlock(i + 5, j + 1, k + 10, Blocks.snow);
		world.setBlock(i + 5, j + 2, k + 0, Blocks.snow);
		world.setBlock(i + 5, j + 2, k + 1, Blocks.snow);
		world.setBlock(i + 5, j + 2, k + 2, Blocks.glowstone);
		world.setBlock(i + 5, j + 2, k + 3, Blocks.planks, 1, 0x02);
		world.setBlock(i + 5, j + 2, k + 4, Blocks.planks, 1, 0x02);
		world.setBlock(i + 5, j + 2, k + 5, Blocks.planks, 1, 0x02);
		world.setBlock(i + 5, j + 2, k + 6, mod_Avatar.WaterBlock);
		world.setBlock(i + 5, j + 2, k + 7, Blocks.planks, 1, 0x02);
		world.setBlock(i + 5, j + 2, k + 8, Blocks.glowstone);
		world.setBlock(i + 5, j + 2, k + 9, Blocks.planks, 1, 0x02);
		world.setBlock(i + 5, j + 2, k + 10, Blocks.grass);
		world.setBlock(i + 5, j + 3, k + 0, Blocks.snow);
		world.setBlock(i + 5, j + 3, k + 1, Blocks.snow);
		world.setBlock(i + 5, j + 3, k + 5, Blocks.planks, 1, 0x02);
		world.setBlock(i + 5, j + 4, k + 1, Blocks.fence);
		world.setBlock(i + 5, j + 4, k + 5, Blocks.planks, 1, 0x02);
		world.setBlock(i + 5, j + 5, k + 1, Blocks.fence);
		world.setBlock(i + 5, j + 5, k + 5, Blocks.planks, 1, 0x02);
		world.setBlock(i + 5, j + 5, k + 9, Blocks.snow);
		world.setBlock(i + 5, j + 6, k + 1, Blocks.snow);
		world.setBlock(i + 5, j + 6, k + 5, Blocks.planks, 1, 0x02);
		world.setBlock(i + 5, j + 6, k + 9, mod_Avatar.WaterTribeBlock);
		world.setBlock(i + 5, j + 7, k + 2, Blocks.snow);
		world.setBlock(i + 5, j + 7, k + 3, Blocks.snow);
		world.setBlock(i + 5, j + 7, k + 5, Blocks.planks, 1, 0x02);
		world.setBlock(i + 5, j + 7, k + 7, Blocks.snow);
		world.setBlock(i + 5, j + 7, k + 8, Blocks.snow);
		world.setBlock(i + 5, j + 7, k + 9, Blocks.snow);
		world.setBlock(i + 5, j + 8, k + 2, Blocks.fence);
		world.setBlock(i + 5, j + 8, k + 5, Blocks.planks, 1, 0x02);
		world.setBlock(i + 5, j + 8, k + 8, Blocks.fence);
		world.setBlock(i + 5, j + 9, k + 2, Blocks.fence);
		world.setBlock(i + 5, j + 9, k + 5, Blocks.planks, 1, 0x02);
		world.setBlock(i + 5, j + 9, k + 8, Blocks.fence);
		world.setBlock(i + 5, j + 10, k + 2, Blocks.snow);
		world.setBlock(i + 5, j + 10, k + 5, Blocks.planks, 1, 0x02);
		world.setBlock(i + 5, j + 10, k + 8, Blocks.snow);
		world.setBlock(i + 5, j + 11, k + 3, Blocks.snow);
		world.setBlock(i + 5, j + 11, k + 5, Blocks.planks, 1, 0x02);
		world.setBlock(i + 5, j + 11, k + 7, Blocks.snow);
		world.setBlock(i + 5, j + 12, k + 3, Blocks.fence);
		world.setBlock(i + 5, j + 12, k + 5, Blocks.planks, 1, 0x02);
		world.setBlock(i + 5, j + 12, k + 7, Blocks.fence);
		world.setBlock(i + 5, j + 13, k + 3, Blocks.fence);
		world.setBlock(i + 5, j + 13, k + 5, Blocks.planks, 1, 0x02);
		world.setBlock(i + 5, j + 13, k + 7, Blocks.fence);
		world.setBlock(i + 5, j + 14, k + 3, mod_Avatar.WaterTribeBlock);
		world.setBlock(i + 5, j + 14, k + 5, Blocks.planks, 1, 0x02);
		world.setBlock(i + 5, j + 14, k + 7, Blocks.snow);
		world.setBlock(i + 5, j + 15, k + 3, Blocks.snow);
		world.setBlock(i + 5, j + 15, k + 4, Blocks.snow);
		world.setBlock(i + 5, j + 15, k + 6, Blocks.snow);
		world.setBlock(i + 5, j + 16, k + 4, Blocks.fence);
		world.setBlock(i + 5, j + 16, k + 6, Blocks.fence);
		world.setBlock(i + 5, j + 17, k + 4, Blocks.snow);
		world.setBlock(i + 5, j + 17, k + 5, Blocks.snow);
		world.setBlock(i + 5, j + 17, k + 6, Blocks.snow);
		world.setBlock(i + 5, j + 18, k + 5, Blocks.snow);
		world.setBlock(i + 5, j + 19, k + 5, Blocks.snow);
		world.setBlock(i + 6, j + 0, k + 0, Blocks.snow);
		world.setBlock(i + 6, j + 0, k + 1, Blocks.snow);
		world.setBlock(i + 6, j + 0, k + 2, Blocks.snow);
		world.setBlock(i + 6, j + 0, k + 3, Blocks.snow);
		world.setBlock(i + 6, j + 0, k + 4, Blocks.snow);
		world.setBlock(i + 6, j + 0, k + 5, Blocks.snow);
		world.setBlock(i + 6, j + 0, k + 6, Blocks.snow);
		world.setBlock(i + 6, j + 0, k + 7, Blocks.snow);
		world.setBlock(i + 6, j + 0, k + 8, Blocks.snow);
		world.setBlock(i + 6, j + 0, k + 9, Blocks.snow);
		world.setBlock(i + 6, j + 0, k + 10, Blocks.snow);
		world.setBlock(i + 6, j + 1, k + 0, Blocks.snow);
		world.setBlock(i + 6, j + 1, k + 1, Blocks.snow);
		world.setBlock(i + 6, j + 1, k + 2, Blocks.snow);
		world.setBlock(i + 6, j + 1, k + 3, Blocks.snow);
		world.setBlock(i + 6, j + 1, k + 4, Blocks.snow);
		world.setBlock(i + 6, j + 1, k + 5, Blocks.snow);
		world.setBlock(i + 6, j + 1, k + 6, Blocks.snow);
		world.setBlock(i + 6, j + 1, k + 7, Blocks.snow);
		world.setBlock(i + 6, j + 1, k + 8, Blocks.snow);
		world.setBlock(i + 6, j + 1, k + 9, Blocks.snow);
		world.setBlock(i + 6, j + 1, k + 10, Blocks.snow);
		world.setBlock(i + 6, j + 2, k + 0, Blocks.snow);
		world.setBlock(i + 6, j + 2, k + 1, Blocks.snow);
		world.setBlock(i + 6, j + 2, k + 2, Blocks.planks, 1, 0x02);
		world.setBlock(i + 6, j + 2, k + 3, Blocks.planks, 1, 0x02);
		world.setBlock(i + 6, j + 2, k + 4, Blocks.planks, 1, 0x02);
		world.setBlock(i + 6, j + 2, k + 5, Blocks.planks, 1, 0x02);
		world.setBlock(i + 6, j + 2, k + 6, Blocks.planks, 1, 0x02);
		world.setBlock(i + 6, j + 2, k + 7, Blocks.planks, 1, 0x02);
		world.setBlock(i + 6, j + 2, k + 8, Blocks.planks, 1, 0x02);
		world.setBlock(i + 6, j + 2, k + 9, Blocks.snow);
		world.setBlock(i + 6, j + 2, k + 10, Blocks.snow);
		world.setBlock(i + 6, j + 3, k + 0, Blocks.snow);
		world.setBlock(i + 6, j + 3, k + 1, Blocks.snow);
		world.setBlock(i + 6, j + 3, k + 9, Blocks.snow);
		world.setBlock(i + 6, j + 3, k + 10, Blocks.snow);
		world.setBlock(i + 6, j + 4, k + 1, Blocks.snow);
		world.setBlock(i + 6, j + 4, k + 9, Blocks.snow);
		world.setBlock(i + 6, j + 5, k + 1, Blocks.snow);
		world.setBlock(i + 6, j + 5, k + 9, Blocks.snow);
		world.setBlock(i + 6, j + 6, k + 1, Blocks.snow);
		world.setBlock(i + 6, j + 6, k + 9, Blocks.snow);
		world.setBlock(i + 6, j + 7, k + 2, Blocks.snow);
		world.setBlock(i + 6, j + 7, k + 3, Blocks.snow);
		world.setBlock(i + 6, j + 7, k + 4, Blocks.snow);
		world.setBlock(i + 6, j + 7, k + 6, Blocks.snow);
		world.setBlock(i + 6, j + 7, k + 7, Blocks.snow);
		world.setBlock(i + 6, j + 7, k + 8, Blocks.snow);
		world.setBlock(i + 6, j + 8, k + 2, Blocks.snow);
		world.setBlock(i + 6, j + 8, k + 8, Blocks.snow);
		world.setBlock(i + 6, j + 9, k + 2, Blocks.snow);
		world.setBlock(i + 6, j + 9, k + 8, Blocks.snow);
		world.setBlock(i + 6, j + 10, k + 2, Blocks.snow);
		world.setBlock(i + 6, j + 10, k + 8, Blocks.snow);
		world.setBlock(i + 6, j + 11, k + 3, Blocks.snow);
		world.setBlock(i + 6, j + 11, k + 4, Blocks.snow);
		world.setBlock(i + 6, j + 11, k + 6, Blocks.snow);
		world.setBlock(i + 6, j + 11, k + 7, Blocks.snow);
		world.setBlock(i + 6, j + 12, k + 3, Blocks.snow);
		world.setBlock(i + 6, j + 12, k + 7, Blocks.snow);
		world.setBlock(i + 6, j + 13, k + 3, Blocks.snow);
		world.setBlock(i + 6, j + 13, k + 7, Blocks.snow);
		world.setBlock(i + 6, j + 14, k + 3, Blocks.snow);
		world.setBlock(i + 6, j + 14, k + 7, Blocks.snow);
		world.setBlock(i + 6, j + 15, k + 4, Blocks.snow);
		world.setBlock(i + 6, j + 15, k + 6, Blocks.snow);
		world.setBlock(i + 6, j + 16, k + 4, Blocks.fence);
		world.setBlock(i + 6, j + 16, k + 6, Blocks.fence);
		world.setBlock(i + 6, j + 17, k + 4, Blocks.snow);
		world.setBlock(i + 6, j + 17, k + 6, Blocks.snow);
		world.setBlock(i + 6, j + 18, k + 4, Blocks.snow);
		world.setBlock(i + 6, j + 18, k + 5, Blocks.glowstone);
		world.setBlock(i + 6, j + 18, k + 6, Blocks.snow);
		world.setBlock(i + 6, j + 19, k + 4, Blocks.snow);
		world.setBlock(i + 6, j + 19, k + 5, Blocks.snow);
		world.setBlock(i + 6, j + 19, k + 6, Blocks.snow);
		world.setBlock(i + 6, j + 20, k + 5, Blocks.snow);
		world.setBlock(i + 7, j + 0, k + 0, Blocks.snow);
		world.setBlock(i + 7, j + 0, k + 1, Blocks.snow);
		world.setBlock(i + 7, j + 0, k + 2, Blocks.snow);
		world.setBlock(i + 7, j + 0, k + 3, Blocks.snow);
		world.setBlock(i + 7, j + 0, k + 4, Blocks.snow);
		world.setBlock(i + 7, j + 0, k + 5, Blocks.snow);
		world.setBlock(i + 7, j + 0, k + 6, Blocks.snow);
		world.setBlock(i + 7, j + 0, k + 7, Blocks.snow);
		world.setBlock(i + 7, j + 0, k + 8, Blocks.snow);
		world.setBlock(i + 7, j + 0, k + 9, Blocks.snow);
		world.setBlock(i + 7, j + 0, k + 10, Blocks.snow);
		world.setBlock(i + 7, j + 1, k + 0, Blocks.snow);
		world.setBlock(i + 7, j + 1, k + 1, Blocks.snow);
		world.setBlock(i + 7, j + 1, k + 2, Blocks.snow);
		world.setBlock(i + 7, j + 1, k + 3, Blocks.snow);
		world.setBlock(i + 7, j + 1, k + 4, Blocks.snow);
		world.setBlock(i + 7, j + 1, k + 5, Blocks.snow);
		world.setBlock(i + 7, j + 1, k + 6, Blocks.snow);
		world.setBlock(i + 7, j + 1, k + 7, Blocks.snow);
		world.setBlock(i + 7, j + 1, k + 8, Blocks.snow);
		world.setBlock(i + 7, j + 1, k + 9, Blocks.snow);
		world.setBlock(i + 7, j + 1, k + 10, Blocks.snow);
		world.setBlock(i + 7, j + 2, k + 0, Blocks.grass);
		world.setBlock(i + 7, j + 2, k + 1, Blocks.snow);
		world.setBlock(i + 7, j + 2, k + 2, Blocks.snow);
		world.setBlock(i + 7, j + 2, k + 3, Blocks.planks, 1, 0x02);
		world.setBlock(i + 7, j + 2, k + 4, Blocks.planks, 1, 0x02);
		world.setBlock(i + 7, j + 2, k + 5, Blocks.planks, 1, 0x02);
		world.setBlock(i + 7, j + 2, k + 6, Blocks.planks, 1, 0x02);
		world.setBlock(i + 7, j + 2, k + 7, Blocks.planks, 1, 0x02);
		world.setBlock(i + 7, j + 2, k + 8, Blocks.snow);
		world.setBlock(i + 7, j + 2, k + 9, Blocks.snow);
		world.setBlock(i + 7, j + 2, k + 10, Blocks.grass);
		world.setBlock(i + 7, j + 3, k + 1, Blocks.snow);
		world.setBlock(i + 7, j + 3, k + 2, Blocks.snow);
		world.setBlock(i + 7, j + 3, k + 8, Blocks.snow);
		world.setBlock(i + 7, j + 3, k + 9, Blocks.snow);
		world.setBlock(i + 7, j + 4, k + 2, Blocks.snow);
		world.setBlock(i + 7, j + 4, k + 8, Blocks.snow);
		world.setBlock(i + 7, j + 5, k + 2, Blocks.snow);
		world.setBlock(i + 7, j + 5, k + 8, Blocks.snow);
		world.setBlock(i + 7, j + 6, k + 2, Blocks.snow);
		world.setBlock(i + 7, j + 6, k + 8, Blocks.snow);
		world.setBlock(i + 7, j + 7, k + 3, Blocks.snow);
		world.setBlock(i + 7, j + 7, k + 4, Blocks.snow);
		world.setBlock(i + 7, j + 7, k + 5, Blocks.snow);
		world.setBlock(i + 7, j + 7, k + 6, Blocks.snow);
		world.setBlock(i + 7, j + 7, k + 7, Blocks.snow);
		world.setBlock(i + 7, j + 8, k + 3, Blocks.snow);
		world.setBlock(i + 7, j + 8, k + 7, Blocks.snow);
		world.setBlock(i + 7, j + 9, k + 3, Blocks.snow);
		world.setBlock(i + 7, j + 9, k + 7, Blocks.snow);
		world.setBlock(i + 7, j + 10, k + 3, Blocks.snow);
		world.setBlock(i + 7, j + 10, k + 7, Blocks.snow);
		world.setBlock(i + 7, j + 11, k + 4, Blocks.snow);
		world.setBlock(i + 7, j + 11, k + 5, Blocks.snow);
		world.setBlock(i + 7, j + 11, k + 6, Blocks.snow);
		world.setBlock(i + 7, j + 12, k + 4, Blocks.snow);
		world.setBlock(i + 7, j + 12, k + 5, Blocks.fence);
		world.setBlock(i + 7, j + 12, k + 6, Blocks.snow);
		world.setBlock(i + 7, j + 13, k + 4, Blocks.snow);
		world.setBlock(i + 7, j + 13, k + 5, Blocks.fence);
		world.setBlock(i + 7, j + 13, k + 6, Blocks.snow);
		world.setBlock(i + 7, j + 14, k + 4, Blocks.snow);
		world.setBlock(i + 7, j + 14, k + 5, Blocks.snow);
		world.setBlock(i + 7, j + 14, k + 6, Blocks.snow);
		world.setBlock(i + 7, j + 15, k + 4, Blocks.snow);
		world.setBlock(i + 7, j + 15, k + 5, Blocks.snow);
		world.setBlock(i + 7, j + 15, k + 6, Blocks.snow);
		world.setBlock(i + 7, j + 16, k + 4, Blocks.snow);
		world.setBlock(i + 7, j + 16, k + 5, Blocks.fence);
		world.setBlock(i + 7, j + 16, k + 6, Blocks.snow);
		world.setBlock(i + 7, j + 17, k + 4, Blocks.snow);
		world.setBlock(i + 7, j + 17, k + 5, Blocks.snow);
		world.setBlock(i + 7, j + 17, k + 6, Blocks.snow);
		world.setBlock(i + 7, j + 18, k + 5, Blocks.snow);
		world.setBlock(i + 7, j + 19, k + 5, Blocks.snow);
		world.setBlock(i + 7, j + 20, k + 5, Blocks.snow);
		world.setBlock(i + 7, j + 21, k + 5, Blocks.snow);
		world.setBlock(i + 8, j + 0, k + 0, Blocks.snow);
		world.setBlock(i + 8, j + 0, k + 1, Blocks.snow);
		world.setBlock(i + 8, j + 0, k + 2, Blocks.snow);
		world.setBlock(i + 8, j + 0, k + 3, Blocks.snow);
		world.setBlock(i + 8, j + 0, k + 4, Blocks.snow);
		world.setBlock(i + 8, j + 0, k + 5, Blocks.snow);
		world.setBlock(i + 8, j + 0, k + 6, Blocks.snow);
		world.setBlock(i + 8, j + 0, k + 7, Blocks.snow);
		world.setBlock(i + 8, j + 0, k + 8, Blocks.snow);
		world.setBlock(i + 8, j + 0, k + 9, Blocks.snow);
		world.setBlock(i + 8, j + 0, k + 10, Blocks.snow);
		world.setBlock(i + 8, j + 1, k + 0, Blocks.snow);
		world.setBlock(i + 8, j + 1, k + 1, Blocks.snow);
		world.setBlock(i + 8, j + 1, k + 2, Blocks.snow);
		world.setBlock(i + 8, j + 1, k + 3, Blocks.snow);
		world.setBlock(i + 8, j + 1, k + 4, Blocks.snow);
		world.setBlock(i + 8, j + 1, k + 5, Blocks.snow);
		world.setBlock(i + 8, j + 1, k + 6, Blocks.snow);
		world.setBlock(i + 8, j + 1, k + 7, Blocks.snow);
		world.setBlock(i + 8, j + 1, k + 8, Blocks.snow);
		world.setBlock(i + 8, j + 1, k + 9, Blocks.snow);
		world.setBlock(i + 8, j + 1, k + 10, Blocks.snow);
		world.setBlock(i + 8, j + 2, k + 0, Blocks.grass);
		world.setBlock(i + 8, j + 2, k + 1, Blocks.grass);
		world.setBlock(i + 8, j + 2, k + 2, Blocks.snow);
		world.setBlock(i + 8, j + 2, k + 3, Blocks.snow);
		world.setBlock(i + 8, j + 2, k + 4, Blocks.planks, 1, 0x02);
		world.setBlock(i + 8, j + 2, k + 5, Blocks.glowstone);
		world.setBlock(i + 8, j + 2, k + 6, Blocks.planks, 1, 0x02);
		world.setBlock(i + 8, j + 2, k + 7, Blocks.snow);
		world.setBlock(i + 8, j + 2, k + 8, Blocks.snow);
		world.setBlock(i + 8, j + 2, k + 9, Blocks.grass);
		world.setBlock(i + 8, j + 2, k + 10, Blocks.grass);
		world.setBlock(i + 8, j + 3, k + 2, Blocks.snow);
		world.setBlock(i + 8, j + 3, k + 3, Blocks.snow);
		world.setBlock(i + 8, j + 3, k + 7, Blocks.snow);
		world.setBlock(i + 8, j + 3, k + 8, Blocks.snow);
		world.setBlock(i + 8, j + 4, k + 3, Blocks.snow);
		world.setBlock(i + 8, j + 4, k + 7, Blocks.snow);
		world.setBlock(i + 8, j + 5, k + 3, Blocks.snow);
		world.setBlock(i + 8, j + 5, k + 7, Blocks.snow);
		world.setBlock(i + 8, j + 6, k + 3, Blocks.snow);
		world.setBlock(i + 8, j + 6, k + 7, Blocks.snow);
		world.setBlock(i + 8, j + 7, k + 4, Blocks.snow);
		world.setBlock(i + 8, j + 7, k + 5, Blocks.snow);
		world.setBlock(i + 8, j + 7, k + 6, Blocks.snow);
		world.setBlock(i + 8, j + 8, k + 4, Blocks.snow);
		world.setBlock(i + 8, j + 8, k + 5, Blocks.fence);
		world.setBlock(i + 8, j + 8, k + 6, Blocks.snow);
		world.setBlock(i + 8, j + 9, k + 4, Blocks.snow);
		world.setBlock(i + 8, j + 9, k + 5, Blocks.fence);
		world.setBlock(i + 8, j + 9, k + 6, Blocks.snow);
		world.setBlock(i + 8, j + 10, k + 4, Blocks.snow);
		world.setBlock(i + 8, j + 10, k + 5, Blocks.snow);
		world.setBlock(i + 8, j + 10, k + 6, Blocks.snow);
		world.setBlock(i + 9, j + 0, k + 0, Blocks.snow);
		world.setBlock(i + 9, j + 0, k + 1, Blocks.snow);
		world.setBlock(i + 9, j + 0, k + 2, Blocks.snow);
		world.setBlock(i + 9, j + 0, k + 3, Blocks.snow);
		world.setBlock(i + 9, j + 0, k + 4, Blocks.snow);
		world.setBlock(i + 9, j + 0, k + 5, Blocks.snow);
		world.setBlock(i + 9, j + 0, k + 6, Blocks.snow);
		world.setBlock(i + 9, j + 0, k + 7, Blocks.snow);
		world.setBlock(i + 9, j + 0, k + 8, Blocks.snow);
		world.setBlock(i + 9, j + 0, k + 9, Blocks.snow);
		world.setBlock(i + 9, j + 0, k + 10, Blocks.snow);
		world.setBlock(i + 9, j + 1, k + 0, Blocks.snow);
		world.setBlock(i + 9, j + 1, k + 1, Blocks.snow);
		world.setBlock(i + 9, j + 1, k + 2, Blocks.snow);
		world.setBlock(i + 9, j + 1, k + 3, Blocks.snow);
		world.setBlock(i + 9, j + 1, k + 4, Blocks.snow);
		world.setBlock(i + 9, j + 1, k + 5, Blocks.snow);
		world.setBlock(i + 9, j + 1, k + 6, Blocks.snow);
		world.setBlock(i + 9, j + 1, k + 7, Blocks.snow);
		world.setBlock(i + 9, j + 1, k + 8, Blocks.snow);
		world.setBlock(i + 9, j + 1, k + 9, Blocks.snow);
		world.setBlock(i + 9, j + 1, k + 10, Blocks.snow);
		world.setBlock(i + 9, j + 2, k + 0, Blocks.grass);
		world.setBlock(i + 9, j + 2, k + 1, Blocks.grass);
		world.setBlock(i + 9, j + 2, k + 2, Blocks.grass);
		world.setBlock(i + 9, j + 2, k + 3, Blocks.snow);
		world.setBlock(i + 9, j + 2, k + 4, Blocks.snow);
		world.setBlock(i + 9, j + 2, k + 5, Blocks.snow);
		world.setBlock(i + 9, j + 2, k + 6, Blocks.snow);
		world.setBlock(i + 9, j + 2, k + 7, Blocks.snow);
		world.setBlock(i + 9, j + 2, k + 8, Blocks.grass);
		world.setBlock(i + 9, j + 2, k + 9, Blocks.grass);
		world.setBlock(i + 9, j + 2, k + 10, Blocks.grass);
		world.setBlock(i + 9, j + 3, k + 3, Blocks.snow);
		world.setBlock(i + 9, j + 3, k + 4, Blocks.snow);
		world.setBlock(i + 9, j + 3, k + 5, Blocks.snow);
		world.setBlock(i + 9, j + 3, k + 6, Blocks.snow);
		world.setBlock(i + 9, j + 3, k + 7, Blocks.snow);
		world.setBlock(i + 9, j + 4, k + 4, Blocks.snow);
		world.setBlock(i + 9, j + 4, k + 5, Blocks.fence);
		world.setBlock(i + 9, j + 4, k + 6, Blocks.snow);
		world.setBlock(i + 9, j + 5, k + 4, Blocks.snow);
		world.setBlock(i + 9, j + 5, k + 5, Blocks.fence);
		world.setBlock(i + 9, j + 5, k + 6, Blocks.snow);
		world.setBlock(i + 9, j + 6, k + 4, Blocks.snow);
		world.setBlock(i + 9, j + 6, k + 5, Blocks.snow);
		world.setBlock(i + 9, j + 6, k + 6, Blocks.snow);
		world.setBlock(i + 10, j + 0, k + 0, Blocks.snow);
		world.setBlock(i + 10, j + 0, k + 1, Blocks.snow);
		world.setBlock(i + 10, j + 0, k + 2, Blocks.snow);
		world.setBlock(i + 10, j + 0, k + 3, Blocks.snow);
		world.setBlock(i + 10, j + 0, k + 4, Blocks.snow);
		world.setBlock(i + 10, j + 0, k + 5, Blocks.snow);
		world.setBlock(i + 10, j + 0, k + 6, Blocks.snow);
		world.setBlock(i + 10, j + 0, k + 7, Blocks.snow);
		world.setBlock(i + 10, j + 0, k + 8, Blocks.snow);
		world.setBlock(i + 10, j + 0, k + 9, Blocks.snow);
		world.setBlock(i + 10, j + 0, k + 10, Blocks.snow);
		world.setBlock(i + 10, j + 1, k + 0, Blocks.snow);
		world.setBlock(i + 10, j + 1, k + 1, Blocks.snow);
		world.setBlock(i + 10, j + 1, k + 2, Blocks.snow);
		world.setBlock(i + 10, j + 1, k + 3, Blocks.snow);
		world.setBlock(i + 10, j + 1, k + 4, Blocks.snow);
		world.setBlock(i + 10, j + 1, k + 5, Blocks.snow);
		world.setBlock(i + 10, j + 1, k + 6, Blocks.snow);
		world.setBlock(i + 10, j + 1, k + 7, Blocks.snow);
		world.setBlock(i + 10, j + 1, k + 8, Blocks.snow);
		world.setBlock(i + 10, j + 1, k + 9, Blocks.snow);
		world.setBlock(i + 10, j + 1, k + 10, Blocks.snow);
		world.setBlock(i + 10, j + 2, k + 0, Blocks.grass);
		world.setBlock(i + 10, j + 2, k + 1, Blocks.grass);
		world.setBlock(i + 10, j + 2, k + 2, Blocks.grass);
		world.setBlock(i + 10, j + 2, k + 3, Blocks.grass);
		world.setBlock(i + 10, j + 2, k + 4, Blocks.snow);
		world.setBlock(i + 10, j + 2, k + 5, Blocks.snow);
		world.setBlock(i + 10, j + 2, k + 6, Blocks.snow);
		world.setBlock(i + 10, j + 2, k + 7, Blocks.grass);
		world.setBlock(i + 10, j + 2, k + 8, Blocks.grass);
		world.setBlock(i + 10, j + 2, k + 9, Blocks.grass);
		world.setBlock(i + 10, j + 2, k + 10, Blocks.grass);
		world.setBlock(i + 10, j + 3, k + 4, Blocks.snow);
		world.setBlock(i + 10, j + 3, k + 5, Blocks.snow);
		world.setBlock(i + 10, j + 3, k + 6, Blocks.snow);
		world.setBlock(i + 0, j + 3, k + 0, Blocks.snow_layer);
		world.setBlock(i + 0, j + 3, k + 1, Blocks.snow_layer);
		world.setBlock(i + 0, j + 3, k + 2, Blocks.snow_layer);
		world.setBlock(i + 0, j + 3, k + 3, Blocks.snow_layer);
		world.setBlock(i + 0, j + 3, k + 7, Blocks.snow_layer);
		world.setBlock(i + 0, j + 3, k + 8, Blocks.snow_layer);
		world.setBlock(i + 0, j + 3, k + 9, Blocks.snow_layer);
		world.setBlock(i + 0, j + 3, k + 10, Blocks.snow_layer);
		world.setBlock(i + 1, j + 3, k + 0, Blocks.snow_layer);
		world.setBlock(i + 1, j + 3, k + 1, Blocks.snow_layer);
		world.setBlock(i + 1, j + 3, k + 2, Blocks.snow_layer);
		world.setBlock(i + 1, j + 3, k + 8, Blocks.snow_layer);
		world.setBlock(i + 1, j + 3, k + 9, Blocks.snow_layer);
		world.setBlock(i + 1, j + 3, k + 10, Blocks.snow_layer);
		world.setBlock(i + 1, j + 4, k + 3, Blocks.snow_layer);
		world.setBlock(i + 1, j + 4, k + 7, Blocks.snow_layer);
		world.setBlock(i + 1, j + 7, k + 4, Blocks.snow_layer);
		world.setBlock(i + 1, j + 7, k + 5, Blocks.snow_layer);
		world.setBlock(i + 1, j + 7, k + 6, Blocks.snow_layer);
		world.setBlock(i + 2, j + 3, k + 0, Blocks.snow_layer);
		world.setBlock(i + 2, j + 3, k + 1, Blocks.snow_layer);
		world.setBlock(i + 2, j + 3, k + 9, Blocks.snow_layer);
		world.setBlock(i + 2, j + 3, k + 10, Blocks.snow_layer);
		world.setBlock(i + 2, j + 4, k + 2, Blocks.snow_layer);
		world.setBlock(i + 2, j + 7, k + 3, Blocks.snow_layer);
		world.setBlock(i + 2, j + 7, k + 7, Blocks.snow_layer);
		world.setBlock(i + 2, j + 11, k + 4, Blocks.snow_layer);
		world.setBlock(i + 2, j + 11, k + 5, Blocks.snow_layer);
		world.setBlock(i + 2, j + 11, k + 6, Blocks.snow_layer);
		world.setBlock(i + 3, j + 3, k + 0, Blocks.snow_layer);
		world.setBlock(i + 3, j + 3, k + 10, Blocks.snow_layer);
		world.setBlock(i + 3, j + 4, k + 1, Blocks.snow_layer);
		world.setBlock(i + 3, j + 4, k + 9, Blocks.snow_layer);
		world.setBlock(i + 3, j + 7, k + 2, Blocks.snow_layer);
		world.setBlock(i + 3, j + 7, k + 8, Blocks.snow_layer);
		world.setBlock(i + 3, j + 11, k + 3, Blocks.snow_layer);
		world.setBlock(i + 3, j + 11, k + 7, Blocks.snow_layer);
		world.setBlock(i + 3, j + 15, k + 4, Blocks.snow_layer);
		world.setBlock(i + 3, j + 15, k + 5, Blocks.snow_layer);
		world.setBlock(i + 3, j + 15, k + 6, Blocks.snow_layer);
		world.setBlock(i + 4, j + 3, k + 5, Blocks.ladder, 4, 0x02);
		world.setBlock(i + 4, j + 4, k + 5, Blocks.ladder, 4, 0x02);
		world.setBlock(i + 4, j + 5, k + 5, Blocks.ladder, 4, 0x02);
		world.setBlock(i + 4, j + 6, k + 5, Blocks.ladder, 4, 0x02);
		world.setBlock(i + 4, j + 7, k + 1, Blocks.snow_layer);
		world.setBlock(i + 4, j + 7, k + 5, Blocks.ladder, 4, 0x02);
		world.setBlock(i + 4, j + 7, k + 9, Blocks.snow_layer);
		world.setBlock(i + 4, j + 8, k + 5, Blocks.ladder, 4, 0x02);
		world.setBlock(i + 4, j + 9, k + 5, Blocks.ladder, 4, 0x02);
		world.setBlock(i + 4, j + 10, k + 5, Blocks.ladder, 4, 0x02);
		world.setBlock(i + 4, j + 11, k + 2, Blocks.snow_layer);
		world.setBlock(i + 4, j + 11, k + 5, Blocks.ladder, 4, 0x02);
		world.setBlock(i + 4, j + 11, k + 8, Blocks.snow_layer);
		world.setBlock(i + 4, j + 12, k + 5, Blocks.ladder, 4, 0x02);
		world.setBlock(i + 4, j + 13, k + 5, Blocks.ladder, 4, 0x02);
		world.setBlock(i + 4, j + 14, k + 5, Blocks.ladder, 4, 0x02);
		world.setBlock(i + 4, j + 15, k + 3, Blocks.snow_layer);
		world.setBlock(i + 4, j + 15, k + 7, Blocks.snow_layer);
		world.setBlock(i + 4, j + 18, k + 4, Blocks.snow_layer);
		world.setBlock(i + 4, j + 18, k + 5, Blocks.snow_layer);
		world.setBlock(i + 4, j + 18, k + 6, Blocks.snow_layer);
		world.setBlock(i + 5, j + 3, k + 4, Blocks.ladder, 2, 0x02);
		world.setBlock(i + 5, j + 3, k + 6, Blocks.ladder, 3, 0x02);
		world.setBlock(i + 5, j + 4, k + 4, Blocks.ladder, 2, 0x02);
		world.setBlock(i + 5, j + 4, k + 6, Blocks.ladder, 3, 0x02);
		world.setBlock(i + 5, j + 5, k + 4, Blocks.ladder, 2, 0x02);
		world.setBlock(i + 5, j + 5, k + 6, Blocks.ladder, 3, 0x02);
		world.setBlock(i + 5, j + 6, k + 4, Blocks.ladder, 2, 0x02);
		world.setBlock(i + 5, j + 6, k + 6, Blocks.ladder, 3, 0x02);
		world.setBlock(i + 5, j + 7, k + 1, Blocks.snow_layer);
		world.setBlock(i + 5, j + 7, k + 4, Blocks.ladder, 2, 0x02);
		world.setBlock(i + 5, j + 7, k + 6, Blocks.ladder, 3, 0x02);
		world.setBlock(i + 5, j + 8, k + 4, Blocks.ladder, 2, 0x02);
		world.setBlock(i + 5, j + 8, k + 6, Blocks.ladder, 3, 0x02);
		world.setBlock(i + 5, j + 9, k + 4, Blocks.ladder, 2, 0x02);
		world.setBlock(i + 5, j + 9, k + 6, Blocks.ladder, 3, 0x02);
		world.setBlock(i + 5, j + 10, k + 4, Blocks.ladder, 2, 0x02);
		world.setBlock(i + 5, j + 10, k + 6, Blocks.ladder, 3, 0x02);
		world.setBlock(i + 5, j + 11, k + 2, Blocks.snow_layer);
		world.setBlock(i + 5, j + 11, k + 4, Blocks.ladder, 2, 0x02);
		world.setBlock(i + 5, j + 11, k + 6, Blocks.ladder, 3, 0x02);
		world.setBlock(i + 5, j + 12, k + 4, Blocks.ladder, 2, 0x02);
		world.setBlock(i + 5, j + 12, k + 6, Blocks.ladder, 3, 0x02);
		world.setBlock(i + 5, j + 13, k + 4, Blocks.ladder, 2, 0x02);
		world.setBlock(i + 5, j + 13, k + 6, Blocks.ladder, 3, 0x02);
		world.setBlock(i + 5, j + 14, k + 4, Blocks.ladder, 2, 0x02);
		world.setBlock(i + 5, j + 14, k + 6, Blocks.ladder, 3, 0x02);
		world.setBlock(i + 5, j + 15, k + 7, Blocks.snow_layer);
		world.setBlock(i + 5, j + 18, k + 4, Blocks.snow_layer);
		world.setBlock(i + 5, j + 18, k + 6, Blocks.snow_layer);
		world.setBlock(i + 5, j + 20, k + 5, Blocks.snow_layer);
		world.setBlock(i + 6, j + 3, k + 5, Blocks.ladder, 5, 0x02);
		world.setBlock(i + 6, j + 4, k + 5, Blocks.ladder, 5, 0x02);
		world.setBlock(i + 6, j + 5, k + 5, Blocks.ladder, 5, 0x02);
		world.setBlock(i + 6, j + 6, k + 5, Blocks.ladder, 5, 0x02);
		world.setBlock(i + 6, j + 7, k + 1, Blocks.snow_layer);
		world.setBlock(i + 6, j + 7, k + 5, Blocks.ladder, 5, 0x02);
		world.setBlock(i + 6, j + 7, k + 9, Blocks.snow_layer);
		world.setBlock(i + 6, j + 8, k + 5, Blocks.ladder, 5, 0x02);
		world.setBlock(i + 6, j + 9, k + 5, Blocks.ladder, 5, 0x02);
		world.setBlock(i + 6, j + 10, k + 5, Blocks.ladder, 5, 0x02);
		world.setBlock(i + 6, j + 11, k + 2, Blocks.snow_layer);
		world.setBlock(i + 6, j + 11, k + 5, Blocks.ladder, 5, 0x02);
		world.setBlock(i + 6, j + 11, k + 8, Blocks.snow_layer);
		world.setBlock(i + 6, j + 12, k + 5, Blocks.ladder, 5, 0x02);
		world.setBlock(i + 6, j + 13, k + 5, Blocks.ladder, 5, 0x02);
		world.setBlock(i + 6, j + 14, k + 5, Blocks.ladder, 5, 0x02);
		world.setBlock(i + 6, j + 20, k + 4, Blocks.snow_layer);
		world.setBlock(i + 6, j + 21, k + 5, Blocks.snow_layer);
		world.setBlock(i + 7, j + 3, k + 0, Blocks.snow_layer);
		world.setBlock(i + 7, j + 3, k + 10, Blocks.snow_layer);
		world.setBlock(i + 7, j + 4, k + 1, Blocks.snow_layer);
		world.setBlock(i + 7, j + 4, k + 9, Blocks.snow_layer);
		world.setBlock(i + 7, j + 7, k + 2, Blocks.snow_layer);
		world.setBlock(i + 7, j + 7, k + 8, Blocks.snow_layer);
		world.setBlock(i + 7, j + 11, k + 3, Blocks.snow_layer);
		world.setBlock(i + 7, j + 11, k + 7, Blocks.snow_layer);
		world.setBlock(i + 7, j + 18, k + 4, Blocks.snow_layer);
		world.setBlock(i + 7, j + 18, k + 6, Blocks.snow_layer);
		world.setBlock(i + 7, j + 22, k + 5, Blocks.snow_layer);
		world.setBlock(i + 8, j + 3, k + 0, Blocks.snow_layer);
		world.setBlock(i + 8, j + 3, k + 1, Blocks.snow_layer);
		world.setBlock(i + 8, j + 3, k + 9, Blocks.snow_layer);
		world.setBlock(i + 8, j + 3, k + 10, Blocks.snow_layer);
		world.setBlock(i + 8, j + 4, k + 2, Blocks.snow_layer);
		world.setBlock(i + 8, j + 4, k + 8, Blocks.snow_layer);
		world.setBlock(i + 8, j + 7, k + 3, Blocks.snow_layer);
		world.setBlock(i + 8, j + 7, k + 7, Blocks.snow_layer);
		world.setBlock(i + 8, j + 11, k + 4, Blocks.snow_layer);
		world.setBlock(i + 8, j + 11, k + 5, Blocks.snow_layer);
		world.setBlock(i + 8, j + 11, k + 6, Blocks.snow_layer);
		world.setBlock(i + 9, j + 3, k + 0, Blocks.snow_layer);
		world.setBlock(i + 9, j + 3, k + 1, Blocks.snow_layer);
		world.setBlock(i + 9, j + 3, k + 2, Blocks.snow_layer);
		world.setBlock(i + 9, j + 3, k + 8, Blocks.snow_layer);
		world.setBlock(i + 9, j + 3, k + 9, Blocks.snow_layer);
		world.setBlock(i + 9, j + 3, k + 10, Blocks.snow_layer);
		world.setBlock(i + 9, j + 4, k + 3, Blocks.snow_layer);
		world.setBlock(i + 9, j + 7, k + 4, Blocks.snow_layer);
		world.setBlock(i + 9, j + 7, k + 5, Blocks.snow_layer);
		world.setBlock(i + 9, j + 7, k + 6, Blocks.snow_layer);
		world.setBlock(i + 10, j + 3, k + 0, Blocks.snow_layer);
		world.setBlock(i + 10, j + 3, k + 1, Blocks.snow_layer);
		world.setBlock(i + 10, j + 3, k + 2, Blocks.snow_layer);
		world.setBlock(i + 10, j + 3, k + 3, Blocks.snow_layer);
		world.setBlock(i + 10, j + 3, k + 7, Blocks.snow_layer);
		world.setBlock(i + 10, j + 3, k + 8, Blocks.snow_layer);
		world.setBlock(i + 10, j + 3, k + 9, Blocks.snow_layer);
		world.setBlock(i + 10, j + 3, k + 10, Blocks.snow_layer);

		return true;
	}

}
